Workbook
Name CSV_HDRNUM2: [1]設定情報!#REF!
Name HDR_ITEM2: [1]設定情報!#REF!
Name HOSOKU_5: [1]設定情報!#REF!
Name HOSOKU_6: [1]設定情報!#REF!

Sheet 給付集計表
B1: 令和３年度(令和3年度4月～3月実績)
B2: 保険者別 国保連合会業務統計表（確定給付統計）
B4: 保険者番号：075226 保険者名：小野町
B6: 保険給付額
B7: 種別 | F7: 合計 | G7: 4月審査分 | H7: 5月審査分 | I7: 6月審査分 | J7: 7月審査分 | K7: 8月審査分 | L7: 9月審査分 | M7: 10月審査分 | N7: 11月審査分 | O7: 12月審査分 | P7: 1月審査分 | Q7: 2月審査分 | R7: 3月審査分
B8: 合計 | F8: =SUM(G8:R8) -> 1132820019 | G8: 96591402 | H8: 75359537 | I8: 111188543 | J8: 97717191 | K8: 98043777 | L8: 92327066 | M8: 95412939 | N8: 94169161 | O8: 99048819 | P8: 94960577 | Q8: 91871335 | R8: 86129672
B9: 居宅サービス計 | F9: =SUM(G9:R9) -> 343075198 | G9: 30935574 | H9: 24936042 | I9: 32800578 | J9: 29691128 | K9: 30379498 | L9: 27795639 | M9: 30272251 | N9: 29922968 | O9: 29118373 | P9: 27842370 | Q9: 24739422 | R9: 24641355
C10: 訪問通所小計 | F10: =SUM(G10:R10) -> 283807637 | G10: 23493874 | H10: 19427347 | I10: 26977293 | J10: 24452264 | K10: 24393270 | L10: 22734253 | M10: 24458263 | N10: 25136112 | O10: 25336859 | P10: 24427232 | Q10: 21556327 | R10: 21414543
D11: 11訪問介護 | F11: =SUM(G11:R11) -> 29881789 | G11: 2537800 | H11: 2614875 | I11: 2458056 | J11: 2197580 | K11: 2214058 | L11: 2102258 | M11: 2304188 | N11: 2459167 | O11: 2666309 | P11: 2832952 | Q11: 2913158 | R11: 2581388
D12: 12訪問入浴介護 | F12: =SUM(G12:R12) -> 2412189 | G12: 107640 | H12: 292734 | I12: 206946 | J12: 206757 | K12: 232155 | L12: 240201 | M12: 292239 | N12: 217854 | O12: 179955 | P12: 143964 | Q12: 157869 | R12: 133875
D13: 13訪問看護 | F13: =SUM(G13:R13) -> 23321027 | G13: 1719641 | H13: 1813758 | I13: 1771836 | J13: 2012050 | K13: 2065963 | L13: 1986025 | M13: 2105968 | N13: 2001612 | O13: 1968874 | P13: 1989580 | Q13: 1915223 | R13: 1970497
D14: 14訪問リハビリテーション | F14: =SUM(G14:R14) -> 0 | G14: 0 | H14: 0 | I14: 0 | J14: 0 | K14: 0 | L14: 0 | M14: 0 | N14: 0 | O14: 0 | P14: 0 | Q14: 0 | R14: 0
D15: 15通所介護 | F15: =SUM(G15:R15) -> 172155079 | G15: 14134762 | H15: 9917486 | I15: 17727023 | J15: 15329830 | K15: 15289300 | L15: 13701154 | M15: 14788164 | N15: 15448673 | O15: 15614772 | P15: 15106164 | Q15: 12521334 | R15: 12576417
D16: 16通所リハビリテーション | F16: =SUM(G16:R16) -> 17145749 | G16: 1886819 | H16: 1663205 | I16: 1585293 | J16: 1461075 | K16: 1355952 | L16: 1386366 | M16: 1574522 | N16: 1703326 | O16: 1469875 | P16: 1138419 | Q16: 937777 | R16: 983120
D17: 17福祉用具貸与 | F17: =SUM(G17:R17) -> 28071122 | G17: 2147191 | H17: 2278407 | I17: 2379817 | J17: 2373871 | K17: 2334960 | L17: 2414199 | M17: 2439128 | N17: 2421086 | O17: 2432179 | P17: 2298369 | Q17: 2219507 | R17: 2332408
D18: 61介護予防訪問介護 | F18: =SUM(G18:R18) -> 0 | G18: 0 | H18: 0 | I18: 0 | J18: 0 | K18: 0 | L18: 0 | M18: 0 | N18: 0 | O18: 0 | P18: 0 | Q18: 0 | R18: 0
D19: 62介護予防訪問入浴介護 | F19: =SUM(G19:R19) -> 0 | G19: 0 | H19: 0 | I19: 0 | J19: 0 | K19: 0 | L19: 0 | M19: 0 | N19: 0 | O19: 0 | P19: 0 | Q19: 0 | R19: 0
D20: 63介護予防訪問看護 | F20: =SUM(G20:R20) -> 1244052 | G20: 171252 | H20: 92637 | I20: 81387 | J20: 102906 | K20: 93888 | L20: 86751 | M20: 110826 | N20: 112086 | O20: 114399 | P20: 108036 | Q20: 81378 | R20: 88506
D21: 64介護予防訪問リハビリテーション | F21: =SUM(G21:R21) -> 0 | G21: 0 | H21: 0 | I21: 0 | J21: 0 | K21: 0 | L21: 0 | M21: 0 | N21: 0 | O21: 0 | P21: 0 | Q21: 0 | R21: 0
D22: 65介護予防通所介護 | F22: =SUM(G22:R22) -> 0 | G22: 0 | H22: 0 | I22: 0 | J22: 0 | K22: 0 | L22: 0 | M22: 0 | N22: 0 | O22: 0 | P22: 0 | Q22: 0 | R22: 0
... D24: 67介護予防福祉用具貸与 | F24: =SUM(G24:R24) -> 3365118 | G24: 247761 | H24: 258840 | I24: 271530 | J24: 272790 | K24: 270090 | L24: 280395 | M24: 306324 | N24: 275679 | O24: 318627 | P24: 284400 | Q24: 299484 | R24: 279198
C25: 短期入所小計 | F25: =SUM(G25:R25) -> 49144012 | G25: 6418637 | H25: 4518755 | I25: 4513431 | J25: 4393302 | K25: 5121433 | L25: 4202477 | M25: 4951911 | N25: 4028647 | O25: 3172561 | P25: 2665974 | Q25: 2522829 | R25: 2634055
D26: 21短期入所生活介護 | F26: =SUM(G26:R26) -> 43747121 | G26: 5931325 | H26: 4127467 | I26: 4093145 | J26: 3881404 | K26: 4626370 | L26: 3713126 | M26: 4430703 | N26: 3167246 | O26: 2593879 | P26: 2402454 | Q26: 2247267 | R26: 2532735
D27: 22短期入所療養介護（老健） | F27: =SUM(G27:R27) -> 5094932 | G27: 450457 | H27: 362826 | I27: 400686 | J27: 511898 | K27: 495063 | L27: 460551 | M27: 521208 | N27: 861401 | O27: 578682 | P27: 217197 | Q27: 195579 | R27: 39384
D28: 2A短期入所療養介護（介護医療院） | F28: =SUM(G28:R28) -> 0 | G28: 0 | H28: 0 | I28: 0 | J28: 0 | K28: 0 | L28: 0 | M28: 0 | N28: 0 | O28: 0 | P28: 0 | Q28: 0 | R28: 0
D29: 23短期入所療養介護（病院等） | F29: =SUM(G29:R29) -> 0 | G29: 0 | H29: 0 | I29: 0 | J29: 0 | K29: 0 | L29: 0 | M29: 0 | N29: 0 | O29: 0 | P29: 0 | Q29: 0 | R29: 0
D30: 24介護予防短期入所生活介護 | F30: =SUM(G30:R30) -> 255636 | G30: 36855 | H30: 28462 | I30: 19600 | J30: 0 | K30: 0 | L30: 28800 | M30: 0 | N30: 0 | O30: 0 | P30: 0 | Q30: 79983 | R30: 61936
D31: 25介護予防短期入所療養介護（老健） | F31: =SUM(G31:R31) -> 46323 | G31: 0 | H31: 0 | I31: 0 | J31: 0 | K31: 0 | L31: 0 | M31: 0 | N31: 0 | O31: 0 | P31: 46323 | Q31: 0 | R31: 0
D32: 2B介護予防短期入所療養介護（介護医療院） | F32: =SUM(G32:R32) -> 0 | G32: 0 | H32: 0 | I32: 0 | J32: 0 | K32: 0 | L32: 0 | M32: 0 | N32: 0 | O32: 0 | P32: 0 | Q32: 0 | R32: 0
D33: 26介護予防短期入所療養介護（病院等） | F33: =SUM(G33:R33) -> 0 | G33: 0 | H33: 0 | I33: 0 | J33: 0 | K33: 0 | L33: 0 | M33: 0 | N33: 0 | O33: 0 | P33: 0 | Q33: 0 | R33: 0
D34: 22特定治療（再掲） | F34: =SUM(G34:R34) -> 0 | G34: 0 | H34: 0 | I34: 0 | J34: 0 | K34: 0 | L34: 0 | M34: 0 | N34: 0 | O34: 0 | P34: 0 | Q34: 0 | R34: 0
D35: 22特別療養費（再掲） | F35: =SUM(G35:R35) -> 0 | G35: 0 | H35: 0 | I35: 0 | J35: 0 | K35: 0 | L35: 0 | M35: 0 | N35: 0 | O35: 0 | P35: 0 | Q35: 0 | R35: 0
D36: 2A特定治療（再掲） | F36: =SUM(G36:R36) -> 0 | G36: 0 | H36: 0 | I36: 0 | J36: 0 | K36: 0 | L36: 0 | M36: 0 | N36: 0 | O36: 0 | P36: 0 | Q36: 0 | R36: 0
D37: 2A特別診療費（再掲） | F37: =SUM(G37:R37) -> 0 | G37: 0 | H37: 0 | I37: 0 | J37: 0 | K37: 0 | L37: 0 | M37: 0 | N37: 0 | O37: 0 | P37: 0 | Q37: 0 | R37: 0
... D51: 81市町村特別給付 | F51: =SUM(G51:R51) -> 0 | G51: 0 | H51: 0 | I51: 0 | J51: 0 | K51: 0 | L51: 0 | M51: 0 | N51: 0 | O51: 0 | P51: 0 | Q51: 0 | R51: 0
B52: 地域密着型サービス計 | F52: =SUM(G52:R52) -> 394128624 | G52: 33302377 | H52: 23266806 | I52: 40279271 | J52: 35258972 | K52: 34232912 | L52: 32327222 | M52: 31507974 | N52: 29697003 | O52: 37003775 | P52: 33368557 | Q52: 33346113 | R52: 30537642
D53: 76定期巡回・随時対応型訪問介護看護 | F53: =SUM(G53:R53) -> 9632988 | G53: 1032768 | H53: 997596 | I53: 1086246 | J53: 1089099 | K53: 978003 | L53: 905004 | M53: 556353 | N53: 1048338 | O53: 862272 | P53: 282294 | Q53: 491085 | R53: 303930
D54: 71夜間対応型訪問介護 | F54: =SUM(G54:R54) -> 0 | G54: 0 | H54: 0 | I54: 0 | J54: 0 | K54: 0 | L54: 0 | M54: 0 | N54: 0 | O54: 0 | P54: 0 | Q54: 0 | R54: 0
D55: 78地域密着型通所介護 | F55: =SUM(G55:R55) -> 1159839 | G55: 150957 | H55: 29331 | I55: 179910 | J55: 81414 | K55: 96147 | L55: 91467 | M55: 91467 | N55: 90711 | O55: 91377 | P55: 88362 | Q55: 84348 | R55: 84348
D56: 72認知症対応型通所介護 | F56: =SUM(G56:R56) -> 20971566 | G56: 1737450 | H56: 448605 | I56: 0 | J56: 4826277 | K56: 1571805 | L56: 1323189 | M56: 1655325 | N56: 1769706 | O56: 2298411 | P56: 2007450 | Q56: 1902681 | R56: 1430667
...

Sheet 特定入所
F1: 令和３年度
B2: 保険者別 国保連合会業務統計表（確定給付統計）
B3: 特定入所者介護サービス費の給付状況その３
B4: 保険者番号：075226 保険者名：小野町
B6: 種別 | G6: 計 | H6: 4月審査分 | I6: 5月審査分 | J6: 6月審査分 | K6: 7月審査分 | L6: 8月審査分 | M6: 9月審査分 | N6: 10月審査分 | O6: 11月審査分 | P6: 12月審査分 | Q6: 1月審査分 | R6: 2月審査分 | S6: 3月審査分 | T6: 平均
B7: 保険給付額 | C7: 合計 | G7: =SUM(H7:S7) -> 49127526 | H7: 4324614 | I7: 3189535 | J7: 5404624 | K7: 4230446 | L7: 4617344 | M7: 3978231 | N7: 4197952 | O7: 4027966 | P7: 3699330 | Q7: 3843504 | R7: 4034510 | S7: 3579470 | T7: =AVERAGE(H7:M7) -> 4290799
F8: 食費 | G8: =SUM(H8:S8) -> 30375904 | H8: 2738345 | I8: 1971421 | J8: 3444635 | K8: 2680041 | L8: 2922930 | M8: 2434087 | N8: 2534820 | O8: 2453503 | P8: 2234671 | Q8: 2358893 | R8: 2429871 | S8: 2172687 | T8: =AVERAGE(H8:M8) -> 2698576.5
F9: 居住費 | G9: =SUM(H9:S9) -> 18751622 | H9: 1586269 | I9: 1218114 | J9: 1959989 | K9: 1550405 | L9: 1694414 | M9: 1544144 | N9: 1663132 | O9: 1574463 | P9: 1464659 | Q9: 1484611 | R9: 1604639 | S9: 1406783 | T9: =AVERAGE(H9:M9) -> 1592222.5
C10: 短期入所サービス計 | G10: =SUM(H10:S10) -> 1850831 | H10: 279838 | I10: 217561 | J10: 117887 | K10: 205102 | L10: 244107 | M10: 92297 | N10: 250727 | O10: 166990 | P10: 38477 | Q10: 76642 | R10: 70769 | S10: 90434 | T10: =AVERAGE(H10:M10) -> 192798.67
F11: 食費 | G11: =SUM(H11:S11) -> 1010310 | H11: 163823 | I11: 124549 | J11: 74091 | K11: 133537 | L11: 159466 | M11: 42684 | N11: 121915 | O11: 79233 | P11: 11876 | Q11: 38448 | R11: 26776 | S11: 33912 | T11: =AVERAGE(H11:M11) -> 116358.33
F12: 滞在費 | G12: =SUM(H12:S12) -> 840521 | H12: 116015 | I12: 93012 | J12: 43796 | K12: 71565 | L12: 84641 | M12: 49613 | N12: 128812 | O12: 87757 | P12: 26601 | Q12: 38194 | R12: 43993 | S12: 56522 | T12: =AVERAGE(H12:M12) -> 76440.333
D13: 21短期入所生活介護 | G13: =SUM(H13:S13) -> 1762457 | H13: 268914 | I13: 217561 | J13: 114128 | K13: 184451 | L13: 225090 | M13: 80990 | N13: 238523 | O13: 158402 | P13: 38477 | Q13: 76642 | R13: 70769 | S13: 88510 | T13: =AVERAGE(H13:M13) -> 181855.67
F14: 食費 | G14: =SUM(H14:S14) -> 927980 | H14: 156529 | I14: 124549 | J14: 70381 | K14: 113103 | L14: 140638 | M14: 31559 | N14: 109900 | O14: 70778 | P14: 11876 | Q14: 38448 | R14: 26776 | S14: 33443 | T14: =AVERAGE(H14:M14) -> 106126.5
F15: 滞在費 | G15: =SUM(H15:S15) -> 834477 | H15: 112385 | I15: 93012 | J15: 43747 | K15: 71348 | L15: 84452 | M15: 49431 | N15: 128623 | O15: 87624 | P15: 26601 | Q15: 38194 | R15: 43993 | S15: 55067 | T15: =AVERAGE(H15:M15) -> 75729.167
D16: 22短期入所療養介護（老健） | G16: =SUM(H16:S16) -> 86450 | H16: 10924 | I16: 0 | J16: 3759 | K16: 20651 | L16: 19017 | M16: 11307 | N16: 12204 | O16: 8588 | P16: 0 | Q16: 0 | R16: 0 | S16: 0 | T16: =AVERAGE(H16:M16) -> 10943
F17: 食費 | G17: =SUM(H17:S17) -> 81861 | H17: 7294 | I17: 0 | J17: 3710 | K17: 20434 | L17: 18828 | M17: 11125 | N17: 12015 | O17: 8455 | P17: 0 | Q17: 0 | R17: 0 | S17: 0 | T17: =AVERAGE(H17:M17) -> 10231.833
F18: 滞在費 | G18: =SUM(H18:S18) -> 4589 | H18: 3630 | I18: 0 | J18: 49 | K18: 217 | L18: 189 | M18: 182 | N18: 189 | O18: 133 | P18: 0 | Q18: 0 | R18: 0 | S18: 0 | T18: =AVERAGE(H18:M18) -> 711.16667
D19: 2A短期入所療養介護（介護医療院） | G19: =SUM(H19:S19) -> 0 | H19: 0 | I19: 0 | J19: 0 | K19: 0 | L19: 0 | M19: 0 | N19: 0 | O19: 0 | P19: 0 | Q19: 0 | R19: 0 | S19: 0 | T19: =AVERAGE(H19:M19) -> 0
F20: 食費 | G20: =SUM(H20:S20) -> 0 | H20: 0 | I20: 0 | J20: 0 | K20: 0 | L20: 0 | M20: 0 | N20: 0 | O20: 0 | P20: 0 | Q20: 0 | R20: 0 | S20: 0 | T20: =AVERAGE(H20:M20) -> 0
F21: 滞在費 | G21: =SUM(H21:S21) -> 0 | H21: 0 | I21: 0 | J21: 0 | K21: 0 | L21: 0 | M21: 0 | N21: 0 | O21: 0 | P21: 0 | Q21: 0 | R21: 0 | S21: 0 | T21: =AVERAGE(H21:M21) -> 0
D22: 23短期入所療養介護（病院等） | G22: =SUM(H22:S22) -> 0 | H22: 0 | I22: 0 | J22: 0 | K22: 0 | L22: 0 | M22: 0 | N22: 0 | O22: 0 | P22: 0 | Q22: 0 | R22: 0 | S22: 0 | T22: =AVERAGE(H22:M22) -> 0
F23: 食費 | G23: =SUM(H23:S23) -> 0 | H23: 0 | I23: 0 | J23: 0 | K23: 0 | L23: 0 | M23: 0 | N23: 0 | O23: 0 | P23: 0 | Q23: 0 | R23: 0 | S23: 0 | T23: =AVERAGE(H23:M23) -> 0
F24: 滞在費 | G24: =SUM(H24:S24) -> 0 | H24: 0 | I24: 0 | J24: 0 | K24: 0 | L24: 0 | M24: 0 | N24: 0 | O24: 0 | P24: 0 | Q24: 0 | R24: 0 | S24: 0 | T24: =AVERAGE(H24:M24) -> 0
D25: 24介護予防短期入所生活介護 | G25: =SUM(H25:S25) -> 1924 | H25: 0 | I25: 0 | J25: 0 | K25: 0 | L25: 0 | M25: 0 | N25: 0 | O25: 0 | P25: 0 | Q25: 0 | R25: 0 | S25: 1924 | T25: =AVERAGE(H25:M25) -> 0
F26: 食費 | G26: =SUM(H26:S26) -> 469 | H26: 0 | I26: 0 | J26: 0 | K26: 0 | L26: 0 | M26: 0 | N26: 0 | O26: 0 | P26: 0 | Q26: 0 | R26: 0 | S26: 469 | T26: =AVERAGE(H26:M26) -> 0
F27: 滞在費 | G27: =SUM(H27:S27) -> 1455 | H27: 0 | I27: 0 | J27: 0 | K27: 0 | L27: 0 | M27: 0 | N27: 0 | O27: 0 | P27: 0 | Q27: 0 | R27: 0 | S27: 1455 | T27: =AVERAGE(H27:M27) -> 0
D28: 25介護予防短期入所療養介護（老健） | G28: =SUM(H28:S28) -> 0 | H28: 0 | I28: 0 | J28: 0 | K28: 0 | L28: 0 | M28: 0 | N28: 0 | O28: 0 | P28: 0 | Q28: 0 | R28: 0 | S28: 0 | T28: =AVERAGE(H28:M28) -> 0
F29: 食費 | G29: =SUM(H29:S29) -> 0 | H29: 0 | I29: 0 | J29: 0 | K29: 0 | L29: 0 | M29: 0 | N29: 0 | O29: 0 | P29: 0 | Q29: 0 | R29: 0 | S29: 0 | T29: =AVERAGE(H29:M29) -> 0
F30: 滞在費 | G30: =SUM(H30:S30) -> 0 | H30: 0 | I30: 0 | J30: 0 | K30: 0 | L30: 0 | M30: 0 | N30: 0 | O30: 0 | P30: 0 | Q30: 0 | R30: 0 | S30: 0 | T30: =AVERAGE(H30:M30) -> 0
D31: 2B介護予防短期入所療養介護（介護医療院） | G31: =SUM(H31:S31) -> 0 | H31: 0 | I31: 0 | J31: 0 | K31: 0 | L31: 0 | M31: 0 | N31: 0 | O31: 0 | P31: 0 | Q31: 0 | R31: 0 | S31: 0 | T31: =AVERAGE(H31:M31) -> 0
F32: 食費 | G32: =SUM(H32:S32) -> 0 | H32: 0 | I32: 0 | J32: 0 | K32: 0 | L32: 0 | M32: 0 | N32: 0 | O32: 0 | P32: 0 | Q32: 0 | R32: 0 | S32: 0 | T32: =AVERAGE(H32:M32) -> 0
F33: 滞在費 | G33: =SUM(H33:S33) -> 0 | H33: 0 | I33: 0 | J33: 0 | K33: 0 | L33: 0 | M33: 0 | N33: 0 | O33: 0 | P33: 0 | Q33: 0 | R33: 0 | S33: 0 | T33: =AVERAGE(H33:M33) -> 0
D34: 26介護予防短期入所療養介護（病院等） | G34: =SUM(H34:S34) -> 0 | H34: 0 | I34: 0 | J34: 0 | K34: 0 | L34: 0 | M34: 0 | N34: 0 | O34: 0 | P34: 0 | Q34: 0 | R34: 0 | S34: 0 | T34: =AVERAGE(H34:M34) -> 0
F35: 食費 | G35: =SUM(H35:S35) -> 0 | H35: 0 | I35: 0 | J35: 0 | K35: 0 | L35: 0 | M35: 0 | N35: 0 | O35: 0 | P35: 0 | Q35: 0 | R35: 0 | S35: 0 | T35: =AVERAGE(H35:M35) -> 0
F36: 滞在費 | G36: =SUM(H36:S36) -> 0 | H36: 0 | I36: 0 | J36: 0 | K36: 0 | L36: 0 | M36: 0 | N36: 0 | O36: 0 | P36: 0 | Q36: 0 | R36: 0 | S36: 0 | T36: =AVERAGE(H36:M36) -> 0
C37: 地域密着型サービス計 | G37: =SUM(H37:S37) -> 17678526 | H37: 1594350 | I37: 695366 | J37: 2513367 | K37: 1454634 | L37: 1641640 | M37: 1503565 | N37: 1465119 | O37: 1372156 | P37: 1376270 | Q37: 1334739 | R37: 1431464 | S37: 1295856 | T37: =AVERAGE(H37:M37) -> 1567153.7
F38: 食費 | G38: =SUM(H38:S38) -> 9918966 | H38: 923228 | I38: 335726 | J38: 1517336 | K38: 838604 | L38: 943338 | M38: 837529 | N38: 818030 | O38: 749285 | P38: 747020 | Q38: 733150 | R38: 770690 | S38: 705030 | T38: =AVERAGE(H38:M38) -> 899293.5
F39: 居住費 | G39: =SUM(H39:S39) -> 7759560 | H39: 671122 | I39: 359640 | J39: 996031 | K39: 616030 | L39: 698302 | M39: 666036 | N39: 647089 | O39: 622871 | P39: 629250 | Q39: 601589 | R39: 660774 | S39: 590826 | T39: =AVERAGE(H39:M39) -> 667860.17
D40: 54地域密着型介護老人福祉施設入所者生活介護 | G40: =SUM(H40:S40) -> 17678526 | H40: 1594350 | I40: 695366 | J40: 2513367 | K40: 1454634 | L40: 1641640 | M40: 1503565 | N40: 1465119 | O40: 1372156 | P40: 1376270 | Q40: 1334739 | R40: 1431464 | S40: 1295856 | T40: =AVERAGE(H40:M40) -> 1567153.7
F41: 食費 | G41: =SUM(H41:S41) -> 9918966 | H41: 923228 | I41: 335726 | J41: 1517336 | K41: 838604 | L41: 943338 | M41: 837529 | N41: 818030 | O41: 749285 | P41: 747020 | Q41: 733150 | R41: 770690 | S41: 705030 | T41: =AVERAGE(H41:M41) -> 899293.5
...

Sheet 試算シート
B1: 令和３年度介護給付費サービス別給付額調査表 試算シート
A3: 市町村名
A4: 小野町 | BK4: （単位：円）
A5: 区 分 | B5: 居宅サービス | S5: 地域密着型サービス | AE5: 施設サービス | AK5: 高額（医療合算） 介護サービス（D) | AL5: 介護給付計（E)＝（A+B+C+D) | AM5: 介護予防居宅サービス | BD5: 地域密着型介護予防サービス | BH5: 高額（医療合算） 介護予防サービス（Ｈ） | BI5: 予防給付計（I)＝（F+G+H） | BJ5: 審査支払手数料 （J) | BK5: 合計（K)=(E+I+J)
B6: 訪問介護 | C6: 訪問入浴介護 | D6: 訪問看護 | E6: 訪問リハビリテーション | F6: 通所介護 | G6: 通所リハビリテーション | H6: 福祉用具貸与 | I6: 短期入所生活介護 | J6: 短期入所療養介護 （特別療養費、特定診療費含む） | K6: 居宅療養管理指導 | L6: 特定施設入居者生活介護 | M6: 福祉用具購入費 | N6: 住宅改修費 | O6: 居宅介護支援 | P6: 特定入所者介護 （食費） | Q6: 特定入所者介護 （居住費） | R6: 居宅サービス 計（A) | S6: 定期巡回・随時対応型訪問介護看護 | T6: 夜間対応型訪問介護 | U6: 地域密着型通所介護 | V6: 認知症対応型通所介護 | W6: 小規模多機能型居宅介護 | X6: 認知症対応型共同生活介護 | Y6: 地域密着型特定施設入居者生活介護 | Z6: 地域密着型介護老人福祉施設 | AA6: 複合型サービス | AB6: 特定入所者介護 （食費） | AC6: 特定入所者介護 （居住費） | AD6: 地域密着型サービス 計（B) | AE6: 介護老人福祉施設 | AF6: 介護老人保健施設 （特定治療、特別療養費含む） | AG6: 介護療養型医療施設 （特定診療費含む） | AH6: 特定入所者介護 （食費） | AI6: 特定入所者介護 （居住費） | AJ6: 施設サービス計（C) | AM6: 介護予防訪問介護 | AN6: 介護予防訪問入浴介護 | AO6: 介護予防訪問看護 | AP6: 介護予防訪問リハビリテーション | AQ6: 介護予防通所介護 | AR6: 介護予防通所リハビリテーション | AS6: 介護予防福祉用具貸与 | AT6: 介護予防短期入所生活介護 | AU6: 介護予防短期入所療養介護 （特別療養費、特定診療費含む） | AV6: 介護予防居宅療養管理指導 | AW6: 介護予防特定施設入居者生活介護 | AX6: 介護予防福祉用具購入費 | AY6: 介護予防住宅改修費 | AZ6: 介護予防支援 | BA6: 特定入所者介護予防（食費） | BB6: 特定入所者介護予防（居住費） | BC6: 予防居宅サービス計（F) | BD6: 介護予防認知症対応型通所介護 | BE6: 介護予防小規模多機能型居宅介護 | BF6: 介護予防認知症対応型共同生活介護 | BG6: 地域密着型予防 計（G)
A7: ３月サービス分 | B7: =給付集計表!G11 -> 2537800 | C7: =給付集計表!G12 -> 107640 | D7: =給付集計表!G13 -> 1719641 | E7: =給付集計表!G14 -> 0 | F7: =給付集計表!G15 -> 14134762 | G7: =給付集計表!G16 -> 1886819 | H7: =給付集計表!G17 -> 2147191 | I7: =給付集計表!G26-特定入所!H13 -> 5662411 | J7: =特定入所!H76 -> 439533 | K7: =給付集計表!G44 -> 151503 | L7: =給付集計表!G45 -> 871560 | M7: 342960 | N7: 253800 | O7: =給付集計表!G49 -> 4265429 | P7: =特定入所!H59 -> 163823 | Q7: =特定入所!H60 -> 116015 | R7: =SUM(B7:Q7) -> 34800887 | S7: =給付集計表!G53 -> 1032768 | T7: =給付集計表!G54 -> 0 | U7: =給付集計表!G55 -> 150957 | V7: =給付集計表!G56 -> 1737450 | W7: =給付集計表!G101 -> 5537751 | X7: =給付集計表!G102 -> 11554185 | Y7: =給付集計表!G103 -> 0 | Z7: =給付集計表!G63-AB7-AC7 -> 11285416 | AA7: =給付集計表!G104 -> 0 | AB7: =特定入所!H38 -> 923228 | AC7: =特定入所!H39 -> 671122 | AD7: =SUM(S7:AC7) -> 32892877 | AE7: =特定入所!H61 -> 14608001 | AF7: =特定入所!H62 -> 8082639 | AG7: =特定入所!H63 -> 355752 | AH7: =特定入所!H44 -> 1651294 | AI7: =特定入所!H45 -> 799132 | AJ7: =SUM(AE7:AI7) -> 25496818 | AK7: 1879196 | AL7: =R7+AD7+AJ7+AK7 -> 95069778 | AM7: =給付集計表!G18 -> 0 | AN7: =給付集計表!G19 -> 0 | AO7: =給付集計表!G20 -> 171252 | AP7: =給付集計表!G21 -> 0 | AQ7: =給付集計表!G22 -> 0 | AR7: =給付集計表!G23 -> 541008 | AS7: =給付集計表!G24 -> 247761 | AT7: =特定入所!H64 -> 36855 | AU7: =特定入所!H65 -> 0 | AV7: =給付集計表!G47 -> 0 | AW7: =給付集計表!G48 -> 0 | AX7: 0 | AY7: 240300 | AZ7: =給付集計表!G50 -> 201260 | BA7: =特定入所!H66 -> 0 | BB7: =特定入所!H67 -> 0 | BC7: =SUM(AM7:BB7) -> 1438436 | BD7: =給付集計表!G66 -> 0 | BE7: =給付集計表!G105 -> 409500 | BF7: =給付集計表!G106 -> 0 | BG7: =SUM(BD7:BF7) -> 409500 | BH7: 8741 | BI7: =BC7+BG7+BH7 -> 1856677 | BJ7: 75632 | BK7: =AL7+BI7+BJ7 -> 97002087
A8: ４月サービス分 | B8: =給付集計表!H11 -> 2614875 | C8: =給付集計表!H12 -> 292734 | D8: =給付集計表!H13 -> 1813758 | E8: =給付集計表!H14 -> 0 | F8: =給付集計表!H15 -> 9917486 | G8: =給付集計表!H16 -> 1663205 | H8: =給付集計表!H17 -> 2278407 | I8: =給付集計表!H26-特定入所!I13 -> 3909906 | J8: =特定入所!I76 -> 362826 | K8: =給付集計表!H44 -> 61779 | L8: =給付集計表!H45 -> 928161 | M8: 21600 | N8: 135108 | O8: =給付集計表!H49 -> 2159791 | P8: =特定入所!I59 -> 124549 | Q8: =特定入所!I60 -> 93012 | R8: =SUM(B8:Q8) -> 26377197 | S8: =給付集計表!H53 -> 997596 | T8: =給付集計表!H54 -> 0 | U8: =給付集計表!H55 -> 29331 | V8: =給付集計表!H56 -> 448605 | W8: =給付集計表!H101 -> 4943549 | X8: =給付集計表!H102 -> 11138126 | Y8: =給付集計表!H103 -> 0 | Z8: =給付集計表!H63-AB8-AC8 -> 4602393 | AA8: =給付集計表!H104 -> 0 | AB8: =特定入所!I38 -> 335726 | AC8: =特定入所!I39 -> 359640 | AD8: =SUM(S8:AC8) -> 22854966 | AE8: =特定入所!I61 -> 12857805 | AF8: =特定入所!I62 -> 7521893 | AG8: =特定入所!I63 -> 0 | AH8: =特定入所!I44 -> 1511146 | AI8: =特定入所!I45 -> 765462 | AJ8: =SUM(AE8:AI8) -> 22656306 | AK8: 1907300 | AL8: =R8+AD8+AJ8+AK8 -> 73795769 | AM8: =給付集計表!H18 -> 0 | AN8: =給付集計表!H19 -> 0 | AO8: =給付集計表!H20 -> 92637 | AP8: =給付集計表!H21 -> 0 | AQ8: =給付集計表!H22 -> 0 | AR8: =給付集計表!H23 -> 495405 | AS8: =給付集計表!H24 -> 258840 | AT8: =特定入所!I64 -> 28462 | AU8: =特定入所!I65 -> 0 | AV8: =給付集計表!H47 -> 0 | AW8: =給付集計表!H48 -> 0 | AX8: 19800 | AY8: 314100 | AZ8: =給付集計表!H50 -> 201940 | BA8: =特定入所!I66 -> 0 | BB8: =特定入所!I67 -> 0 | BC8: =SUM(AM8:BB8) -> 1411184 | BD8: =給付集計表!H66 -> 0 | BE8: =給付集計表!H105 -> 411840 | BF8: =給付集計表!H106 -> 0 | BG8: =SUM(BD8:BF8) -> 411840 | BH8: 11937 | BI8: =BC8+BG8+BH8 -> 1834961 | BJ8: 74008 | BK8: =AL8+BI8+BJ8 -> 75704738
A9: ５月サービス分 | B9: =給付集計表!I11 -> 2458056 | C9: =給付集計表!I12 -> 206946 | D9: =給付集計表!I13 -> 1771836 | E9: =給付集計表!I14 -> 0 | F9: =給付集計表!I15 -> 17727023 | G9: =給付集計表!I16 -> 1585293 | H9: =給付集計表!I17 -> 2379817 | I9: =給付集計表!I26-特定入所!J13 -> 3979017 | J9: =特定入所!J76 -> 396927 | K9: =給付集計表!I44 -> 75099 | L9: =給付集計表!I45 -> 1204416 | M9: 103680 | N9: 19008 | O9: =給付集計表!I49 -> 6523351 | P9: =特定入所!J59 -> 74091 | Q9: =特定入所!J60 -> 43796 | R9: =SUM(B9:Q9) -> 38548356 | S9: =給付集計表!I53 -> 1086246 | T9: =給付集計表!I54 -> 0 | U9: =給付集計表!I55 -> 179910 | V9: =給付集計表!I56 -> 0 | W9: =給付集計表!I101 -> 6244443 | X9: =給付集計表!I102 -> 11824422 | Y9: =給付集計表!I103 -> 0 | Z9: =給付集計表!I63-AB9-AC9 -> 18019043 | AA9: =給付集計表!I104 -> 0 | AB9: =特定入所!J38 -> 1517336 | AC9: =特定入所!J39 -> 996031 | AD9: =SUM(S9:AC9) -> 39867431 | AE9: =特定入所!J61 -> 17134439 | AF9: =特定入所!J62 -> 8706666 | AG9: =特定入所!J63 -> 572868 | AH9: =特定入所!J44 -> 1853208 | AI9: =特定入所!J45 -> 920162 | AJ9: =SUM(AE9:AI9) -> 29187343 | AK9: 1676355 | AL9: =R9+AD9+AJ9+AK9 -> 109279485 | AM9: =給付集計表!I18 -> 0 | AN9: =給付集計表!I19 -> 0 | AO9: =給付集計表!I20 -> 81387 | AP9: =給付集計表!I21 -> 0 | AQ9: =給付集計表!I22 -> 0 | AR9: =給付集計表!I23 -> 495405 | AS9: =給付集計表!I24 -> 271530 | AT9: =特定入所!J64 -> 19600 | AU9: =特定入所!J65 -> 0 | AV9: =給付集計表!I47 -> 0 | AW9: =給付集計表!I48 -> 30339 | AX9: 10800 | AY9: 0 | AZ9: =給付集計表!I50 -> 204940 | BA9: =特定入所!J66 -> 0 | BB9: =特定入所!J67 -> 0 | BC9: =SUM(AM9:BB9) -> 1114001 | BD9: =給付集計表!I66 -> 0 | BE9: =給付集計表!I105 -> 411840 | BF9: =給付集計表!I106 -> 0 | BG9: =SUM(BD9:BF9) -> 411840 | BH9: 11163 | BI9: =BC9+BG9+BH9 -> 1537004 | BJ9: 74240 | BK9: =AL9+BI9+BJ9 -> 110890729
A10: ６月サービス分 | B10: =給付集計表!J11 -> 2197580 | C10: =給付集計表!J12 -> 206757 | D10: =給付集計表!J13 -> 2012050 | E10: =給付集計表!J14 -> 0 | F10: =給付集計表!J15 -> 15329830 | G10: =給付集計表!J16 -> 1461075 | H10: =給付集計表!J17 -> 2373871 | I10: =給付集計表!J26-特定入所!K13 -> 3696953 | J10: =特定入所!K76 -> 491247 | K10: =給付集計表!J44 -> 78168 | L10: =給付集計表!J45 -> 767394 | M10: 16830 | N10: 16232 | O10: =給付集計表!J49 -> 4403701 | P10: =特定入所!K59 -> 133537 | Q10: =特定入所!K60 -> 71565 | R10: =SUM(B10:Q10) -> 33256790 | S10: =給付集計表!J53 -> 1089099 | T10: =給付集計表!J54 -> 0 | U10: =給付集計表!J55 -> 81414 | V10: =給付集計表!J56 -> 4826277 | W10: =給付集計表!J101 -> 5063013 | X10: =給付集計表!J102 -> 11828498 | Y10: =給付集計表!J103 -> 0 | Z10: =給付集計表!J63-AB10-AC10 -> 10504197 | AA10: =給付集計表!J104 -> 0 | AB10: =特定入所!K38 -> 838604 | AC10: =特定入所!K39 -> 616030 | AD10: =SUM(S10:AC10) -> 34847132 | AE10: =特定入所!K61 -> 15678971 | AF10: =特定入所!K62 -> 7372746 | AG10: =特定入所!K63 -> 281736 | AH10: =特定入所!K44 -> 1707900 | AI10: =特定入所!K45 -> 862810 | AJ10: =SUM(AE10:AI10) -> 25904163 | AK10: 1626294 | AL10: =R10+AD10+AJ10+AK10 -> 95634379 | AM10: =給付集計表!J18 -> 0 | AN10: =給付集計表!J19 -> 0 | AO10: =給付集計表!J20 -> 102906 | AP10: =給付集計表!J21 -> 0 | AQ10: =給付集計表!J22 -> 0 | AR10: =給付集計表!J23 -> 495405 | AS10: =給付集計表!J24 -> 272790 | AT10: =特定入所!K64 -> 0 | AU10: =特定入所!K65 -> 0 | AV10: =給付集計表!J47 -> 0 | AW10: =給付集計表!J48 -> 0 | AX10: 13200 | AY10: 0 | AZ10: =給付集計表!J50 -> 200550 | BA10: =特定入所!K66 -> 0 | BB10: =特定入所!K67 -> 0 | BC10: =SUM(AM10:BB10) -> 1084851 | BD10: =給付集計表!J66 -> 0 | BE10: =給付集計表!J105 -> 411840 | BF10: =給付集計表!J106 -> 0 | BG10: =SUM(BD10:BF10) -> 411840 | BH10: 11902 | BI10: =BC10+BG10+BH10 -> 1508593 | BJ10: 75226 | BK10: =AL10+BI10+BJ10 -> 97218198
A11: ７月サービス分 | B11: =給付集計表!K11 -> 2214058 | C11: =給付集計表!K12 -> 232155 | D11: =給付集計表!K13 -> 2065963 | E11: =給付集計表!K14 -> 0 | F11: =給付集計表!K15 -> 15289300 | G11: =給付集計表!K16 -> 1355952 | H11: =給付集計表!K17 -> 2334960 | I11: =給付集計表!K26-特定入所!L13 -> 4401280 | J11: =特定入所!L76 -> 476046 | K11: =給付集計表!K44 -> 71877 | L11: =給付集計表!K45 -> 792918 | M11: 39600 | N11: 406260 | O11: =給付集計表!K49 -> 4257841 | P11: =特定入所!L59 -> 159466 | Q11: =特定入所!L60 -> 84641 | R11: =SUM(B11:Q11) -> 34182317 | S11: =給付集計表!K53 -> 978003 | T11: =給付集計表!K54 -> 0 | U11: =給付集計表!K55 -> 96147 | V11: =給付集計表!K56 -> 1571805 | W11: =給付集計表!K101 -> 5928507 | X11: =給付集計表!K102 -> 11897099 | Y11: =給付集計表!K103 -> 0 | Z11: =給付集計表!K63-AB11-AC11 -> 11707871 | AA11: =給付集計表!K104 -> 0 | AB11: =特定入所!L38 -> 943338 | AC11: =特定入所!L39 -> 698302 | AD11: =SUM(S11:AC11) -> 33821072 | AE11: =特定入所!L61 -> 16326981 | AF11: =特定入所!L62 -> 7111610 | AG11: =特定入所!L63 -> 419769 | AH11: =特定入所!L44 -> 1820126 | AI11: =特定入所!L45 -> 911471 | AJ11: =SUM(AE11:AI11) -> 26589957 | AK11: 2158518 | AL11: =R11+AD11+AJ11+AK11 -> 96751864 | AM11: =給付集計表!K18 -> 0 | AN11: =給付集計表!K19 -> 0 | AO11: =給付集計表!K20 -> 93888 | AP11: =給付集計表!K21 -> 0 | AQ11: =給付集計表!K22 -> 0 | AR11: =給付集計表!K23 -> 536904 | AS11: =給付集計表!K24 -> 270090 | AT11: =特定入所!L64 -> 0 | AU11: =特定入所!L65 -> 0 | AV11: =給付集計表!K47 -> 0 | AW11: =給付集計表!K48 -> 0 | AX11: 61767 | AY11: 0 | AZ11: =給付集計表!K50 -> 207940 | BA11: =特定入所!L66 -> 0 | BB11: =特定入所!L67 -> 0 | BC11: =SUM(AM11:BB11) -> 1170589 | BD11: =給付集計表!K66 -> 0 | BE11: =給付集計表!K105 -> 411840 | BF11: =給付集計表!K106 -> 0 | BG11: =SUM(BD11:BF11) -> 411840 | BH11: 17717 | BI11: =BC11+BG11+BH11 -> 1600146 | BJ11: 74066 | BK11: =AL11+BI11+BJ11 -> 98426076
A12: ８月サービス分 | B12: =給付集計表!L11 -> 2102258 | C12: =給付集計表!L12 -> 240201 | D12: =給付集計表!L13 -> 1986025 | E12: =給付集計表!L14 -> 0 | F12: =給付集計表!L15 -> 13701154 | G12: =給付集計表!L16 -> 1386366 | H12: =給付集計表!L17 -> 2414199 | I12: =給付集計表!L26-特定入所!M13 -> 3632136 | J12: =特定入所!M76 -> 449244 | K12: =給付集計表!L44 -> 44787 | L12: =給付集計表!L45 -> 814122 | M12: 31680 | N12: 323684 | O12: =給付集計表!L49 -> 4320471 | P12: =特定入所!M59 -> 42684 | Q12: =特定入所!M60 -> 49613 | R12: =SUM(B12:Q12) -> 31538624 | S12: =給付集計表!L53 -> 905004 | T12: =給付集計表!L54 -> 0 | U12: =給付集計表!L55 -> 91467 | V12: =給付集計表!L56 -> 1323189 | W12: =給付集計表!L101 -> 5697666 | X12: =給付集計表!L102 -> 11005590 | Y12: =給付集計表!L103 -> 0 | Z12: =給付集計表!L63-AB12-AC12 -> 11428321 | AA12: =給付集計表!L104 -> 0 | AB12: =特定入所!M38 -> 837529 | AC12: =特定入所!M39 -> 666036 | AD12: =SUM(S12:AC12) -> 31954802 | AE12: =特定入所!M61 -> 15181281 | AF12: =特定入所!M62 -> 7823385 | AG12: =特定入所!M63 -> 653130 | AH12: =特定入所!M44 -> 1553874 | AI12: =特定入所!M45 -> 828495 | AJ12: =SUM(AE12:AI12) -> 26040165 | AK12: 1847398 | AL12: =R12+AD12+AJ12+AK12 -> 91380989 | AM12: =給付集計表!L18 -> 0 | AN12: =給付集計表!L19 -> 0 | AO12: =給付集計表!L20 -> 86751 | AP12: =給付集計表!L21 -> 0 | AQ12: =給付集計表!L22 -> 0 | AR12: =給付集計表!L23 -> 536904 | AS12: =給付集計表!L24 -> 280395 | AT12: =特定入所!M64 -> 28800 | AU12: =特定入所!M65 -> 0 | AV12: =給付集計表!L47 -> 0 | AW12: =給付集計表!L48 -> 0 | AX12: 0 | AY12: 0 | AZ12: =給付集計表!L50 -> 209330 | BA12: =特定入所!M66 -> 0 | BB12: =特定入所!M67 -> 0 | BC12: =SUM(AM12:BB12) -> 1142180 | BD12: =給付集計表!L66 -> 0 | BE12: =給付集計表!L105 -> 372420 | BF12: =給付集計表!L106 -> 0 | BG12: =SUM(BD12:BF12) -> 372420 | BH12: 10877 | BI12: =BC12+BG12+BH12 -> 1525477 | BJ12: 79808 | BK12: =AL12+BI12+BJ12 -> 92986274
A13: ９月サービス分 | B13: =給付集計表!M11 -> 2304188 | C13: =給付集計表!M12 -> 292239 | D13: =給付集計表!M13 -> 2105968 | E13: =給付集計表!M14 -> 0 | F13: =給付集計表!M15 -> 14788164 | G13: =給付集計表!M16 -> 1574522 | H13: =給付集計表!M17 -> 2439128 | I13: =給付集計表!M26-特定入所!N13 -> 4192180 | J13: =特定入所!N76 -> 509004 | K13: =給付集計表!M44 -> 73965 | L13: =給付集計表!M45 -> 788112 | M13: 17280 | N13: 70020 | O13: =給付集計表!M49 -> 4301711 | P13: =特定入所!N59 -> 121915 | Q13: =特定入所!N60 -> 128812 | R13: =SUM(B13:Q13) -> 33707208 | S13: =給付集計表!M53 -> 556353 | T13: =給付集計表!M54 -> 0 | U13: =給付集計表!M55 -> 91467 | V13: =給付集計表!M56 -> 1655325 | W13: =給付集計表!M101 -> 5349762 | X13: =給付集計表!M102 -> 10870570 | Y13: =給付集計表!M103 -> 0 | Z13: =給付集計表!M63-AB13-AC13 -> 11141027 | AA13: =給付集計表!M104 -> 0 | AB13: =特定入所!N38 -> 818030 | AC13: =特定入所!N39 -> 647089 | AD13: =SUM(S13:AC13) -> 31129623 | AE13: =特定入所!N61 -> 15312624 | AF13: =特定入所!N62 -> 7474347 | AG13: =特定入所!N63 -> 632709 | AH13: =特定入所!N44 -> 1594875 | AI13: =特定入所!N45 -> 887231 | AJ13: =SUM(AE13:AI13) -> 25901786 | AK13: 4483473 | AL13: =R13+AD13+AJ13+AK13 -> 95222090 | AM13: =給付集計表!M18 -> 0 | AN13: =給付集計表!M19 -> 0 | AO13: =給付集計表!M20 -> 110826 | AP13: =給付集計表!M21 -> 0 | AQ13: =給付集計表!M22 -> 0 | AR13: =給付集計表!M23 -> 536904 | AS13: =給付集計表!M24 -> 306324 | AT13: =特定入所!N64 -> 0 | AU13: =特定入所!N65 -> 0 | AV13: =給付集計表!M47 -> 0 | AW13: =給付集計表!M48 -> 0 | AX13: 10800 | AY13: 0 | AZ13: =給付集計表!M50 -> 225500 | BA13: =特定入所!N66 -> 0 | BB13: =特定入所!N67 -> 0 | BC13: =SUM(AM13:BB13) -> 1190354 | BD13: =給付集計表!M66 -> 0 | BE13: =給付集計表!M105 -> 378351 | BF13: =給付集計表!M106 -> 0 | BG13: =SUM(BD13:BF13) -> 378351 | BH13: 0 | BI13: =BC13+BG13+BH13 -> 1568705 | BJ13: 65656 | BK13: =AL13+BI13+BJ13 -> 96856451
A14: １０月サービス分 | B14: =給付集計表!N11 -> 2459167 | C14: =給付集計表!N12 -> 217854 | D14: =給付集計表!N13 -> 2001612 | E14: =給付集計表!N14 -> 0 | F14: =給付集計表!N15 -> 15448673 | G14: =給付集計表!N16 -> 1703326 | H14: =給付集計表!N17 -> 2421086 | I14: =給付集計表!N26-特定入所!HO13 -> 3167246 | J14: =特定入所!O76 -> 852813 | K14: =給付集計表!N44 -> 70141 | L14: =給付集計表!N45 -> 688068 | M14: 69300 | N14: 0 | O14: =給付集計表!N49 -> 4313791 | P14: =特定入所!O59 -> 79233 | Q14: =特定入所!O60 -> 87757 | R14: =SUM(B14:Q14) -> 33580067 | S14: =給付集計表!N53 -> 1048338 | T14: =給付集計表!N54 -> 0 | U14: =給付集計表!N55 -> 90711 | V14: =給付集計表!N56 -> 1769706 | W14: =給付集計表!N101 -> 4884354 | X14: =給付集計表!N102 -> 9064172 | Y14: =給付集計表!N103 -> 0 | Z14: =給付集計表!N63-AB14-AC14 -> 11171700 | AA14: =給付集計表!N104 -> 0 | AB14: =特定入所!O38 -> 749285 | AC14: =特定入所!O39 -> 622871 | AD14: =SUM(S14:AC14) -> 29401137 | AE14: =特定入所!O61 -> 15527145 | AF14: =特定入所!O62 -> 8880984 | AG14: =特定入所!O63 -> 654759 | AH14: =特定入所!O44 -> 1624985 | AI14: =特定入所!O45 -> 863835 | AJ14: =SUM(AE14:AI14) -> 27551708 | AK14: 1637759 | AL14: =R14+AD14+AJ14+AK14 -> 92170671 | AM14: =給付集計表!N18 -> 0 | AN14: =給付集計表!N19 -> 0 | AO14: =給付集計表!N20 -> 112086 | AP14: =給付集計表!N21 -> 0 | AQ14: =給付集計表!N22 -> 0 | AR14: =給付集計表!N23 -> 496629 | AS14: =給付集計表!N24 -> 275679 | AT14: =特定入所!O64 -> 0 | AU14: =特定入所!O65 -> 0 | AV14: =給付集計表!N47 -> 0 | AW14: =給付集計表!N48 -> 0 | AX14: 0 | AY14: 67500 | AZ14: =給付集計表!N50 -> 213240 | BA14: =特定入所!O66 -> 0 | BB14: =特定入所!O67 -> 0 | BC14: =SUM(AM14:BB14) -> 1165134 | BD14: =給付集計表!N66 -> 0 | BE14: =給付集計表!N105 -> 295866 | BF14: =給付集計表!N106 -> 0 | BG14: =SUM(BD14:BF14) -> 295866 | BH14: 0 | BI14: =BC14+BG14+BH14 -> 1461000 | BJ14: 73892 | BK14: =AL14+BI14+BJ14 -> 93705563
A15: １０月までの平均値 | B15: =AVERAGE(B7:B12) -> 2354104.5 | C15: =AVERAGE(C7:C12) -> 214405.5 | D15: =AVERAGE(D7:D12) -> 1894878.8 | E15: =AVERAGE(E7:E12) -> 0 | F15: =AVERAGE(F7:F12) -> 14349926 | G15: =AVERAGE(G7:G12) -> 1556451.7 | H15: =AVERAGE(H7:H12) -> 2321407.5 | I15: =AVERAGE(I7:I12) -> 4213617.2 | ... Q15: =AVERAGE(Q7:Q12) -> 76440.333 | R15: =SUM(B15:Q15) -> 33117362 | S15: =AVERAGE(S7:S12) -> 1014786 | T15: =AVERAGE(T7:T12) -> 0 | U15: =AVERAGE(U7:U12) -> 104871 | V15: =AVERAGE(V7:V12) -> 1651221 | W15: =AVERAGE(W7:W12) -> 5569154.8 | X15: =AVERAGE(X7:X12) -> 11541320 | Y15: =AVERAGE(Y7:Y12) -> 0 | Z15: =AVERAGE(Z7:Z12) -> 11257874 | ... AC15: =AVERAGE(AC7:AC12) -> 667860.17 | AD15: =SUM(S12:AC15) -> 125191942 | AE15: =AVERAGE(AE7:AE12) -> 15297913 | AF15: =AVERAGE(AF7:AF12) -> 7769823.2 | AG15: =AVERAGE(AG7:AG12) -> 380542.5 | AH15: =AVERAGE(AH7:AH12) -> 1682924.7 | AI15: =AVERAGE(AI7:AI12) -> 847922 | AJ15: =SUM(AE15:AI15) -> 25979125 | AK15: =AVERAGE(AK7:AK12) -> 1849176.8 | AL15: =R15+AD15+AJ15+AK15 -> 1.8613761e+08 | AM15: =AVERAGE(AM7:AM14) -> 0 | AN15: =AVERAGE(AN7:AN14) -> 0 | AO15: =給付集計表!O20 -> 114399 | AP15: =給付集計表!O21 -> 0 | AQ15: =給付集計表!O22 -> 0 | AR15: =給付集計表!O23 -> 571869 | AS15: =給付集計表!O24 -> 318627 | AT15: =特定入所!P64 -> 0 | AU15: =特定入所!P65 -> 0 | AV15: =給付集計表!O47 -> 0 | AW15: =給付集計表!O48 -> 0 | AX15: =AVERAGE(AX7:AX12) -> 17594.5 | AY15: =AVERAGE(AY7:AY12) -> 92400 | AZ15: =AVERAGE(AZ7:AZ12) -> 204326.67 | BA15: =AVERAGE(BA7:BA14) -> 0 | BB15: =AVERAGE(BB7:BB14) -> 0 | BC15: =SUM(AM15:BB15) -> 1319216.2 | BD15: =AVERAGE(BD7:BD12) -> 0 | BE15: =AVERAGE(BE7:BE12) -> 404880 | BF15: =AVERAGE(BF7:BF12) -> 0 | BG15: =SUM(BD15:BF15) -> 404880 | BH15: =AVERAGE(BH7:BH12) -> 12056.167 | BI15: =BC15+BG15+BH15 -> 1736152.3 | BJ15: =AVERAGE(BJ7:BJ12) -> 75496.667 | BK15: =AL15+BI15+BJ15 -> 1.8794926e+08
A16: 最高値 | B16: =MAX(B7:B14) -> 2614875 | C16: =MAX(C7:C14) -> 292734 | D16: =MAX(D7:D14) -> 2105968 | E16: =MAX(E7:E14) -> 0 | F16: =MAX(F7:F14) -> 17727023 | G16: =MAX(G7:G14) -> 1886819 | H16: =MAX(H7:H14) -> 2439128 | I16: =MAX(I7:I14) -> 5662411 | ... Q16: =MAX(Q7:Q14) -> 128812 | R16: =SUM(B16:Q16) -> 42502896 | S16: =MAX(S7:S14) -> 1089099 | T16: =MAX(T7:T14) -> 0 | U16: =MAX(U7:U14) -> 179910 | V16: =MAX(V7:V14) -> 4826277 | W16: =MAX(W7:W14) -> 6244443 | X16: =MAX(X7:X14) -> 11897099 | Y16: =MAX(Y7:Y14) -> 0 | Z16: =MAX(Z7:Z14) -> 18019043 | ... AC16: =MAX(AC7:AC14) -> 996031 | AD16: =SUM(S16:AC16) -> 44769238 | AE16: =MAX(AE7:AE14) -> 17134439 | AF16: =MAX(AF7:AF14) -> 8880984 | AG16: =MAX(AG7:AG14) -> 654759 | AH16: =MAX(AH7:AH14) -> 1853208 | AI16: =MAX(AI7:AI14) -> 920162 | AJ16: =SUM(AE16:AI16) -> 29443552 | AK16: =MAX(AK7:AK14) -> 4483473 | AL16: =R16+AD16+AJ16+AK16 -> 121199159 | AM16: =MAX(AM7:AM14) -> 0 | AN16: =MAX(AN7:AN14) -> 0 | AO16: =給付集計表!P20 -> 108036 | AP16: =給付集計表!P21 -> 0 | AQ16: =給付集計表!P22 -> 0 | AR16: =給付集計表!P23 -> 525348 | AS16: =給付集計表!P24 -> 284400 | AT16: =特定入所!Q64 -> 0 | AU16: =特定入所!Q65 -> 46323 | AV16: =給付集計表!P47 -> 0 | AW16: =給付集計表!P48 -> 0 | AX16: =MAX(AX7:AX14) -> 61767 | AY16: =MAX(AY7:AY14) -> 314100 | AZ16: =MAX(AZ7:AZ14) -> 225500 | BA16: =MAX(BA7:BA14) -> 0 | BB16: =MAX(BB7:BB14) -> 0 | BC16: =SUM(AM16:BB16) -> 1565474 | BD16: =MAX(BD7:BD14) -> 0 | BE16: =MAX(BE7:BE14) -> 411840 | BF16: =MAX(BF7:BF14) -> 0 | BG16: =SUM(BD16:BF16) -> 411840 | BH16: =MAX(BH7:BH14) -> 17717 | BI16: =BC16+BG16+BH16 -> 1995031 | BJ16: =MAX(BJ7:BJ14) -> 79808 | BK16: =AL16+BI16+BJ16 -> 123273998
A17: 平均値と最高値の平均値 | B17: =AVERAGE(B15:B16) -> 2484489.8 | C17: =AVERAGE(C15:C16) -> 253569.75 | D17: =AVERAGE(D15:D16) -> 2000423.4 | E17: =AVERAGE(E15:E16) -> 0 | F17: =AVERAGE(F15:F16) -> 16038474 | G17: =AVERAGE(G15:G16) -> 1721635.3 | H17: =AVERAGE(H15:H16) -> 2380267.8 | I17: =AVERAGE(I15:I16) -> 4938014.1 | ... Q17: =AVERAGE(Q15:Q16) -> 102626.17 | R17: =SUM(B17:Q17) -> 37810129 | S17: =AVERAGE(S15:S16) -> 1051942.5 | T17: =AVERAGE(T15:T16) -> 0 | U17: =AVERAGE(U15:U16) -> 142390.5 | V17: =AVERAGE(V15:V16) -> 3238749 | W17: =AVERAGE(W15:W16) -> 5906798.9 | X17: =AVERAGE(X15:X16) -> 11719210 | Y17: =AVERAGE(Y15:Y16) -> 0 | Z17: =AVERAGE(Z15:Z16) -> 14638458 | ... AC17: =AVERAGE(AC15:AC16) -> 831945.58 | AD17: =SUM(S17:AC17) -> 38737809 | AE17: =AVERAGE(AE15:AE16) -> 16216176 | AF17: =AVERAGE(AF15:AF16) -> 8325403.6 | AG17: =AVERAGE(AG15:AG16) -> 517650.75 | AH17: =AVERAGE(AH15:AH16) -> 1768066.3 | AI17: =AVERAGE(AI15:AI16) -> 884042 | AJ17: =SUM(AE17:AI17) -> 27711339 | AK17: =AVERAGE(AK15:AK16) -> 3166324.9 | AL17: =R17+AD17+AJ17+AK17 -> 1.074256e+08 | AM17: =AVERAGE(AM15:AM16) -> 0 | AN17: =AVERAGE(AN15:AN16) -> 0 | AO17: =給付集計表!Q20 -> 81378 | AP17: =給付集計表!Q21 -> 0 | AQ17: =給付集計表!Q22 -> 0 | AR17: =給付集計表!Q23 -> 510597 | AS17: =給付集計表!Q24 -> 299484 | AT17: =特定入所!R64 -> 79983 | AU17: =特定入所!R65 -> 0 | AV17: =給付集計表!Q47 -> 0 | AW17: =給付集計表!Q48 -> 0 | AX17: =AVERAGE(AX15:AX16) -> 39680.75 | AY17: =AVERAGE(AY15:AY16) -> 203250 | AZ17: =AVERAGE(AZ15:AZ16) -> 214913.33 | BA17: =AVERAGE(BA15:BA16) -> 0 | BB17: =AVERAGE(BB15:BB16) -> 0 | BC17: =SUM(AM17:BB17) -> 1429286.1 | BD17: =AVERAGE(BD15:BD16) -> 0 | BE17: =AVERAGE(BE15:BE16) -> 408360 | BF17: =AVERAGE(BF15:BF16) -> 0 | BG17: =SUM(BD17:BF17) -> 408360 | BH17: =AVERAGE(BH15:BH16) -> 14886.583 | BI17: =BC17+BG17+BH17 -> 1852532.7 | BJ17: =AVERAGE(BJ15:BJ16) -> 77652.333 | BK17: =AL17+BI17+BJ17 -> 1.0935579e+08
R18: =SUM(B18:Q18) -> 0 | AD18: =SUM(S18:AC18) -> 0 | AJ18: =SUM(AE18:AI18) -> 0 | AL18: =R18+AD18+AJ18+AK18 -> 0 | AO18: =給付集計表!R20 -> 88506 | AP18: =給付集計表!R21 -> 0 | AQ18: =給付集計表!R22 -> 0 | AR18: =給付集計表!R23 -> 469134 | AS18: =給付集計表!R24 -> 279198 | AT18: =特定入所!S64 -> 60012 | AU18: =特定入所!S65 -> 0 | AV18: =給付集計表!R47 -> 0 | AW18: =給付集計表!R48 -> 0 | BC18: =SUM(AM18:BB18) -> 896850 | BG18: =SUM(BD18:BF18) -> 0 | BI18: =BC18+BG18+BH18 -> 896850 | BK18: =AL18+BI18+BJ18 -> 896850
A19: 合 計 | B19: =SUM(B7:B18) -> 26341451 | C19: =SUM(C7:C18) -> 2557235.2 | D19: =SUM(D7:D18) -> 21478123 | E19: =SUM(E7:E18) -> 0 | F19: =SUM(F7:F18) -> 1.6445182e+08 | G19: =SUM(G7:G18) -> 17781464 | H19: =SUM(H7:H18) -> 25929462 | I19: =SUM(I7:I18) -> 47455171 | ... T19: =SUM(T7:T18) -> 0 | V19: =SUM(V7:V18) -> 23048604 | W19: =SUM(W7:W18) -> 61369442 | X19: =SUM(X7:X18) -> 1.2434029e+08 | Y19: =SUM(Y7:Y18) -> 0 | Z19: =SUM(Z7:Z18) -> 1.3377534e+08 | AA19: =SUM(AA7:AA18) -> 0 | AB19: =SUM(AB7:AB18) -> 10588020 | AC19: =SUM(AC7:AC18) -> 7772957.8 | ... BK19: =SUM(BK7:BK18) -> 1.184266e+09
B21: ①施設等分（施設サービス計＋特定施設入居者生活介護＋介護予防特定施設入居者生活介護） | G21: =L19+AJ19+AW19 -> 3.0249862e+08 | J21: 県費負担金の所要見込額 | K21: ①×１７．５％ | L21: =INT(G21*17.5%) -> 52937258 | AO21: =AVERAGE(AO7:AO12) -> 104803.5 | AP21: =AVERAGE(AP7:AP12) -> 0 | AQ21: =AVERAGE(AQ7:AQ12) -> 0 | AR21: =AVERAGE(AR7:AR12) -> 516838.5 | AS21: =AVERAGE(AS7:AS12) -> 266901 | AT21: =AVERAGE(AT7:AT12) -> 18952.833 | AU21: =AVERAGE(AU7:AU12) -> 0 | AV21: =AVERAGE(AV7:AV12) -> 0 | AW21: =AVERAGE(AW7:AW12) -> 5056.5
B22: ②その他分 | G22: =BK19-G21 -> 8.8176739e+08 | K22: ②×１２．５％ | L22: =INT(G22*12.5%) -> 110220923 | AN22: 合計 | AO22: =SUM(AO21:AW21) -> 912552.33
AN23: 平均 | AO23: =AVERAGE(AO21:AW21) -> 101394.7
B25: 記入上の注意事項
B26: １ 本表は、福島県国民健康保険団体連合会から提出される業務統計表等を基に作成すること。
B27: ２ 給付額には、災害臨時特例補助金（災害臨時特例補助金および特別調整交付金）により支援される予定の額（原子力事故による避難地域等に住所のある（あった）被保険者の利用料減免分）は除くこと。
B28: ３ 給付額には、特別調整交付金の交付対象となる額（避難地域等以外に住所のある（あった）被保険者の利用料減免分）を含めること。
B29: ４ 本表に記入する数値のうち見込に係るもので関数を使用するときは、＠INT又は＠ROUNDを用い、小数点以下の計算がなされないようにすること。（単純に月数で除する計算式は入力しないこと）
