Workbook
Name CSV_HDRNUM2: [1]設定情報!#REF!
Name HDR_ITEM2: [1]設定情報!#REF!
Name HOSOKU_5: [1]設定情報!#REF!
Name HOSOKU_6: [1]設定情報!#REF!

Sheet 給付集計表
B2: 保険者別 国保連合会業務統計表（確定給付統計）
B4: 保険者番号：075226 保険者名：小野町
B6: 保険給付額
B7: 種別 | F7: 合計 | G7: 4月審査分 | H7: 5月審査分 | I7: 6月審査分 | J7: 7月審査分 | K7: 8月審査分 | L7: 9月審査分 | M7: 10月審査分 | N7: 11月審査分 | O7: 12月審査分 | P7: 1月審査分 | Q7: 2月審査分 | R7: 3月審査分
B8: 合計 | F8: =SUM(G8:R8) -> 1121975667 | G8: 95134738 | H8: 93308010 | I8: 95374738 | J8: 91823359 | K8: 95244054 | L8: 88905785 | M8: 96297574 | N8: 98019249 | O8: 91922907 | P8: 95848394 | Q8: 90871425 | R8: 89225434
B9: 居宅サービス計 | F9: =SUM(G9:R9) -> 375669202 | G9: 30242179 | H9: 31458117 | I9: 31525286 | J9: 30487150 | K9: 33469705 | L9: 32491144 | M9: 31921773 | N9: 32225681 | O9: 31129425 | P9: 31626379 | Q9: 28913940 | R9: 30178423
C10: 訪問通所小計 | F10: =SUM(G10:R10) -> 303173639 | G10: 25166606 | H10: 26009449 | I10: 25712315 | J10: 25301546 | K10: 27586001 | L10: 25711787 | M10: 25275024 | N10: 25817909 | O10: 24533992 | P10: 25238395 | Q10: 22624034 | R10: 24196581
D11: 11訪問介護 | F11: =SUM(G11:R11) -> 25741921 | G11: 1948052 | H11: 2304852 | I11: 2128544 | J11: 1840649 | K11: 2502034 | L11: 2271709 | M11: 1996491 | N11: 2074915 | O11: 1992195 | P11: 2288467 | Q11: 2217585 | R11: 2176428
D12: 12訪問入浴介護 | F12: =SUM(G12:R12) -> 2171358 | G12: 187101 | H12: 177894 | I12: 212301 | J12: 247347 | K12: 259911 | L12: 316809 | M12: 176589 | N12: 142209 | O12: 71109 | P12: 130248 | Q12: 106983 | R12: 142857
D13: 13訪問看護 | F13: =SUM(G13:R13) -> 18363579 | G13: 1625653 | H13: 1585396 | I13: 1531918 | J13: 1495656 | K13: 1648644 | L13: 1607261 | M13: 1499350 | N13: 1645356 | O13: 1445241 | P13: 1496514 | Q13: 1387443 | R13: 1395147
D14: 14訪問リハビリテーション | F14: =SUM(G14:R14) -> 23157 | G14: 23157 | H14: 0 | I14: 0 | J14: 0 | K14: 0 | L14: 0 | M14: 0 | N14: 0 | O14: 0 | P14: 0 | Q14: 0 | R14: 0
D15: 15通所介護 | F15: =SUM(G15:R15) -> 201432713 | G15: 17054894 | H15: 17421799 | I15: 17498471 | J15: 16903868 | K15: 18089677 | L15: 16788297 | M15: 16873030 | N15: 17217561 | O15: 16410404 | P15: 16660620 | Q15: 14504861 | R15: 16009231
D16: 16通所リハビリテーション | F16: =SUM(G16:R16) -> 22722207 | G16: 1701695 | H16: 1791784 | I16: 1746461 | J16: 2040295 | K16: 2200980 | L16: 1936333 | M16: 1895863 | N16: 2056285 | O16: 1868551 | P16: 1931516 | Q16: 1761470 | R16: 1790974
D17: 17福祉用具貸与 | F17: =SUM(G17:R17) -> 23749913 | G17: 1875541 | H17: 1922368 | I17: 1862641 | J17: 1997724 | K17: 2096130 | L17: 2098594 | M17: 2081724 | N17: 1933593 | O17: 1986577 | P17: 1974175 | Q17: 1942495 | R17: 1978351
D18: 61介護予防訪問介護 | F18: =SUM(G18:R18) -> 0 | G18: 0 | H18: 0 | I18: 0 | J18: 0 | K18: 0 | L18: 0 | M18: 0 | N18: 0 | O18: 0 | P18: 0 | Q18: 0 | R18: 0
D19: 62介護予防訪問入浴介護 | F19: =SUM(G19:R19) -> 0 | G19: 0 | H19: 0 | I19: 0 | J19: 0 | K19: 0 | L19: 0 | M19: 0 | N19: 0 | O19: 0 | P19: 0 | Q19: 0 | R19: 0
D20: 63介護予防訪問看護 | F20: =SUM(G20:R20) -> 1116963 | G20: 96039 | H20: 96750 | I20: 89667 | J20: 89667 | K20: 104598 | L20: 89613 | M20: 90378 | N20: 87687 | O20: 97812 | P20: 90702 | Q20: 90702 | R20: 93348
D21: 64介護予防訪問リハビリテーション | F21: =SUM(G21:R21) -> 0 | G21: 0 | H21: 0 | I21: 0 | J21: 0 | K21: 0 | L21: 0 | M21: 0 | N21: 0 | O21: 0 | P21: 0 | Q21: 0 | R21: 0
D22: 65介護予防通所介護 | F22: =SUM(G22:R22) -> 0 | G22: 0 | H22: 0 | I22: 0 | J22: 0 | K22: 0 | L22: 0 | M22: 0 | N22: 0 | O22: 0 | P22: 0 | Q22: 0 | R22: 0
... D24: 67介護予防福祉用具貸与 | F24: =SUM(G24:R24) -> 1217964 | G24: 101847 | H24: 110997 | I24: 107622 | J24: 111222 | K24: 90072 | L24: 90072 | M24: 108072 | N24: 101412 | O24: 103212 | P24: 107262 | Q24: 94212 | R24: 91962
C25: 短期入所小計 | F25: =SUM(G25:R25) -> 58730876 | G25: 4138578 | H25: 4503375 | I25: 4751767 | J25: 4287201 | K25: 4863729 | L25: 5614208 | M25: 5673048 | N25: 5049581 | O25: 5372352 | P25: 4854452 | Q25: 4944510 | R25: 4678075
D26: 21短期入所生活介護 | F26: =SUM(G26:R26) -> 56263296 | G26: 3974489 | H26: 4282428 | I26: 4433207 | J26: 4126788 | K26: 4627887 | L26: 5487461 | M26: 5500654 | N26: 4637967 | O26: 5186583 | P26: 4613211 | Q26: 4746658 | R26: 4645963
D27: 22短期入所療養介護（老健） | F27: =SUM(G27:R27) -> 2438060 | G27: 149329 | H27: 220947 | I27: 318560 | J27: 145653 | K27: 235842 | L27: 126747 | M27: 172394 | N27: 411614 | O27: 185769 | P27: 241241 | Q27: 197852 | R27: 32112
D28: 2A短期入所療養介護（介護医療院） | F28: =SUM(G28:R28) -> 0 | G28: 0 | H28: 0 | I28: 0 | J28: 0 | K28: 0 | L28: 0 | M28: 0 | N28: 0 | O28: 0 | P28: 0 | Q28: 0 | R28: 0
D29: 23短期入所療養介護（病院等） | F29: =SUM(G29:R29) -> 0 | G29: 0 | H29: 0 | I29: 0 | J29: 0 | K29: 0 | L29: 0 | M29: 0 | N29: 0 | O29: 0 | P29: 0 | Q29: 0 | R29: 0
D30: 24介護予防短期入所生活介護 | F30: =SUM(G30:R30) -> 29520 | G30: 14760 | H30: 0 | I30: 0 | J30: 14760 | K30: 0 | L30: 0 | M30: 0 | N30: 0 | O30: 0 | P30: 0 | Q30: 0 | R30: 0
D31: 25介護予防短期入所療養介護（老健） | F31: =SUM(G31:R31) -> 0 | G31: 0 | H31: 0 | I31: 0 | J31: 0 | K31: 0 | L31: 0 | M31: 0 | N31: 0 | O31: 0 | P31: 0 | Q31: 0 | R31: 0
D32: 2B介護予防短期入所療養介護（介護医療院） | F32: =SUM(G32:R32) -> 0 | G32: 0 | H32: 0 | I32: 0 | J32: 0 | K32: 0 | L32: 0 | M32: 0 | N32: 0 | O32: 0 | P32: 0 | Q32: 0 | R32: 0
D33: 26介護予防短期入所療養介護（病院等） | F33: =SUM(G33:R33) -> 0 | G33: 0 | H33: 0 | I33: 0 | J33: 0 | K33: 0 | L33: 0 | M33: 0 | N33: 0 | O33: 0 | P33: 0 | Q33: 0 | R33: 0
D34: 22特定治療（再掲） | F34: =SUM(G34:R34) -> 0 | G34: 0 | H34: 0 | I34: 0 | J34: 0 | K34: 0 | L34: 0 | M34: 0 | N34: 0 | O34: 0 | P34: 0 | Q34: 0 | R34: 0
D35: 22特別療養費（再掲） | F35: =SUM(G35:R35) -> 0 | G35: 0 | H35: 0 | I35: 0 | J35: 0 | K35: 0 | L35: 0 | M35: 0 | N35: 0 | O35: 0 | P35: 0 | Q35: 0 | R35: 0
D36: 2A特定治療（再掲） | F36: =SUM(G36:R36) -> 0 | G36: 0 | H36: 0 | I36: 0 | J36: 0 | K36: 0 | L36: 0 | M36: 0 | N36: 0 | O36: 0 | P36: 0 | Q36: 0 | R36: 0
D37: 2A特別診療費（再掲） | F37: =SUM(G37:R37) -> 0 | G37: 0 | H37: 0 | I37: 0 | J37: 0 | K37: 0 | L37: 0 | M37: 0 | N37: 0 | O37: 0 | P37: 0 | Q37: 0 | R37: 0
... D51: 81市町村特別給付 | F51: =SUM(G51:R51) -> 0 | G51: 0 | H51: 0 | I51: 0 | J51: 0 | K51: 0 | L51: 0 | M51: 0 | N51: 0 | O51: 0 | P51: 0 | Q51: 0 | R51: 0
B52: 地域密着型サービス計 | F52: =SUM(G52:R52) -> 310106690 | G52: 24368929 | H52: 23347164 | I52: 24900977 | J52: 24024051 | K52: 24255485 | L52: 19127163 | M52: 27902954 | N52: 28998822 | O52: 26819215 | P52: 29505654 | Q52: 28884045 | R52: 27972231
D53: 76定期巡回・随時対応型訪問介護看護 | F53: =SUM(G53:R53) -> 11789901 | G53: 1110366 | H53: 976392 | I53: 845253 | J53: 732753 | K53: 562041 | L53: 725328 | M53: 859266 | N53: 1109925 | O53: 1220598 | P53: 1172277 | Q53: 1160721 | R53: 1314981
D54: 71夜間対応型訪問介護 | F54: =SUM(G54:R54) -> 0 | G54: 0 | H54: 0 | I54: 0 | J54: 0 | K54: 0 | L54: 0 | M54: 0 | N54: 0 | O54: 0 | P54: 0 | Q54: 0 | R54: 0
D55: 78地域密着型通所介護 | F55: =SUM(G55:R55) -> 1306818 | G55: 104823 | H55: 67626 | I55: 0 | J55: 0 | K55: 0 | L55: 462501 | M55: 137322 | N55: 131958 | O55: 52308 | P55: 119556 | Q55: 118638 | R55: 112086
D56: 72認知症対応型通所介護 | F56: =SUM(G56:R56) -> 20397672 | G56: 1551942 | H56: 1232280 | I56: 2029635 | J56: 1929852 | K56: 1832787 | L56: 1854297 | M56: 1870245 | N56: 1812996 | O56: 1682667 | P56: 1538865 | Q56: 1518273 | R56: 1543833
D57: 73小規模多機能型居宅介護 | F57: =SUM(G57:R57) -> 48696597 | G57: 3926691 | H57: 4340241 | I57: 4338711 | J57: 4251285 | K57: 4235391 | L57: 3897711 | M57: 4047192 | N57: 4051026 | O57: 3759138 | P57: 4055400 | Q57: 4009923 | R57: 3783888
...

Sheet 特定入所
B2: 保険者別 国保連合会業務統計表（確定給付統計）
B3: 特定入所者介護サービス費の給付状況その３
B4: 保険者番号：075226 保険者名：小野町
B6: 種別 | G6: 計 | H6: 4月審査分 | I6: 5月審査分 | J6: 6月審査分 | K6: 7月審査分 | L6: 8月審査分 | M6: 9月審査分 | N6: 10月審査分 | O6: 11月審査分 | P6: 12月審査分 | Q6: 1月審査分 | R6: 2月審査分 | S6: 3月審査分
B7: 保険給付額 | C7: 合計 | G7: =SUM(H7:S7) -> 51692990 | H7: 4486470 | I7: 4220930 | J7: 4415340 | K7: 4296680 | L7: 4272100 | M7: 4081620 | N7: 4130930 | O7: 4556263 | P7: 4308169 | Q7: 4737010 | R7: 4191331 | S7: 3996147
F8: 食費 | G8: =SUM(H8:S8) -> 34073911 | H8: 3024140 | I8: 2845510 | J8: 2908960 | K8: 2836630 | L8: 2828720 | M8: 2746120 | N8: 2758360 | O8: 2966885 | P8: 2793063 | Q8: 3048257 | R8: 2739222 | S8: 2578044
F9: 居住費 | G9: =SUM(H9:S9) -> 17619079 | H9: 1462330 | I9: 1375420 | J9: 1506380 | K9: 1460050 | L9: 1443380 | M9: 1335500 | N9: 1372570 | O9: 1589378 | P9: 1515106 | Q9: 1688753 | R9: 1452109 | S9: 1418103
C10: 短期入所サービス計 | G10: =SUM(H10:S10) -> 2352168 | H10: 249180 | I10: 171630 | J10: 215920 | K10: 165780 | L10: 135700 | M10: 178010 | N10: 190900 | O10: 196063 | P10: 184140 | Q10: 274829 | R10: 204489 | S10: 185527
F11: 食費 | G11: =SUM(H11:S11) -> 1361581 | H11: 137420 | I11: 95680 | J11: 124520 | K11: 92280 | L11: 71970 | M11: 128890 | N11: 108850 | O11: 116965 | P11: 98121 | Q11: 158143 | R11: 124104 | S11: 104638
F12: 滞在費 | G12: =SUM(H12:S12) -> 990587 | H12: 111760 | I12: 75950 | J12: 91400 | K12: 73500 | L12: 63730 | M12: 49120 | N12: 82050 | O12: 79098 | P12: 86019 | Q12: 116686 | R12: 80385 | S12: 80889
D13: 21短期入所生活介護 | G13: =SUM(H13:S13) -> 2157259 | H13: 236300 | I13: 148170 | J13: 178790 | K13: 146460 | L13: 118990 | M13: 178010 | N13: 174980 | O13: 164384 | P13: 176598 | Q13: 258399 | R13: 190651 | S13: 185527
F14: 食費 | G14: =SUM(H14:S14) -> 1197085 | H14: 124540 | I14: 78970 | J14: 98220 | K14: 78140 | L14: 58890 | M14: 128890 | N14: 94250 | O14: 86999 | P14: 91569 | Q14: 141713 | R14: 110266 | S14: 104638
F15: 滞在費 | G15: =SUM(H15:S15) -> 960174 | H15: 111760 | I15: 69200 | J15: 80570 | K15: 68320 | L15: 60100 | M15: 49120 | N15: 80730 | O15: 77385 | P15: 85029 | Q15: 116686 | R15: 80385 | S15: 80889
D16: 22短期入所療養介護（老健） | G16: =SUM(H16:S16) -> 194909 | H16: 12880 | I16: 23460 | J16: 37130 | K16: 19320 | L16: 16710 | M16: 0 | N16: 15920 | O16: 31679 | P16: 7542 | Q16: 16430 | R16: 13838 | S16: 0
F17: 食費 | G17: =SUM(H17:S17) -> 164496 | H17: 12880 | I17: 16710 | J17: 26300 | K17: 14140 | L17: 13080 | M17: 0 | N17: 14600 | O17: 29966 | P17: 6552 | Q17: 16430 | R17: 13838 | S17: 0
F18: 滞在費 | G18: =SUM(H18:S18) -> 30413 | H18: 0 | I18: 6750 | J18: 10830 | K18: 5180 | L18: 3630 | M18: 0 | N18: 1320 | O18: 1713 | P18: 990 | Q18: 0 | R18: 0 | S18: 0
D19: 2A短期入所療養介護（介護医療院） | G19: =SUM(H19:S19) -> 0 | H19: 0 | I19: 0 | J19: 0 | K19: 0 | L19: 0 | M19: 0 | N19: 0 | O19: 0 | P19: 0 | Q19: 0 | R19: 0 | S19: 0
F20: 食費 | G20: =SUM(H20:S20) -> 0 | H20: 0 | I20: 0 | J20: 0 | K20: 0 | L20: 0 | M20: 0 | N20: 0 | O20: 0 | P20: 0 | Q20: 0 | R20: 0 | S20: 0
F21: 滞在費 | G21: =SUM(H21:S21) -> 0 | H21: 0 | I21: 0 | J21: 0 | K21: 0 | L21: 0 | M21: 0 | N21: 0 | O21: 0 | P21: 0 | Q21: 0 | R21: 0 | S21: 0
D22: 23短期入所療養介護（病院等） | G22: =SUM(H22:S22) -> 0 | H22: 0 | I22: 0 | J22: 0 | K22: 0 | L22: 0 | M22: 0 | N22: 0 | O22: 0 | P22: 0 | Q22: 0 | R22: 0 | S22: 0
F23: 食費 | G23: =SUM(H23:S23) -> 0 | H23: 0 | I23: 0 | J23: 0 | K23: 0 | L23: 0 | M23: 0 | N23: 0 | O23: 0 | P23: 0 | Q23: 0 | R23: 0 | S23: 0
F24: 滞在費 | G24: =SUM(H24:S24) -> 0 | H24: 0 | I24: 0 | J24: 0 | K24: 0 | L24: 0 | M24: 0 | N24: 0 | O24: 0 | P24: 0 | Q24: 0 | R24: 0 | S24: 0
D25: 24介護予防短期入所生活介護 | G25: =SUM(H25:S25) -> 0 | H25: 0 | I25: 0 | J25: 0 | K25: 0 | L25: 0 | M25: 0 | N25: 0 | O25: 0 | P25: 0 | Q25: 0 | R25: 0 | S25: 0
F26: 食費 | G26: =SUM(H26:S26) -> 0 | H26: 0 | I26: 0 | J26: 0 | K26: 0 | L26: 0 | M26: 0 | N26: 0 | O26: 0 | P26: 0 | Q26: 0 | R26: 0 | S26: 0
F27: 滞在費 | G27: =SUM(H27:S27) -> 0 | H27: 0 | I27: 0 | J27: 0 | K27: 0 | L27: 0 | M27: 0 | N27: 0 | O27: 0 | P27: 0 | Q27: 0 | R27: 0 | S27: 0
D28: 25介護予防短期入所療養介護（老健） | G28: =SUM(H28:S28) -> 0 | H28: 0 | I28: 0 | J28: 0 | K28: 0 | L28: 0 | M28: 0 | N28: 0 | O28: 0 | P28: 0 | Q28: 0 | R28: 0 | S28: 0
F29: 食費 | G29: =SUM(H29:S29) -> 0 | H29: 0 | I29: 0 | J29: 0 | K29: 0 | L29: 0 | M29: 0 | N29: 0 | O29: 0 | P29: 0 | Q29: 0 | R29: 0 | S29: 0
F30: 滞在費 | G30: =SUM(H30:S30) -> 0 | H30: 0 | I30: 0 | J30: 0 | K30: 0 | L30: 0 | M30: 0 | N30: 0 | O30: 0 | P30: 0 | Q30: 0 | R30: 0 | S30: 0
D31: 2B介護予防短期入所療養介護（介護医療院） | G31: =SUM(H31:S31) -> 0 | H31: 0 | I31: 0 | J31: 0 | K31: 0 | L31: 0 | M31: 0 | N31: 0 | O31: 0 | P31: 0 | Q31: 0 | R31: 0 | S31: 0
F32: 食費 | G32: =SUM(H32:S32) -> 0 | H32: 0 | I32: 0 | J32: 0 | K32: 0 | L32: 0 | M32: 0 | N32: 0 | O32: 0 | P32: 0 | Q32: 0 | R32: 0 | S32: 0
F33: 滞在費 | G33: =SUM(H33:S33) -> 0 | H33: 0 | I33: 0 | J33: 0 | K33: 0 | L33: 0 | M33: 0 | N33: 0 | O33: 0 | P33: 0 | Q33: 0 | R33: 0 | S33: 0
D34: 26介護予防短期入所療養介護（病院等） | G34: =SUM(H34:S34) -> 0 | H34: 0 | I34: 0 | J34: 0 | K34: 0 | L34: 0 | M34: 0 | N34: 0 | O34: 0 | P34: 0 | Q34: 0 | R34: 0 | S34: 0
F35: 食費 | G35: =SUM(H35:S35) -> 0 | H35: 0 | I35: 0 | J35: 0 | K35: 0 | L35: 0 | M35: 0 | N35: 0 | O35: 0 | P35: 0 | Q35: 0 | R35: 0 | S35: 0
F36: 滞在費 | G36: =SUM(H36:S36) -> 0 | H36: 0 | I36: 0 | J36: 0 | K36: 0 | L36: 0 | M36: 0 | N36: 0 | O36: 0 | P36: 0 | Q36: 0 | R36: 0 | S36: 0
C37: 地域密着型サービス計 | G37: =SUM(H37:S37) -> 11525498 | H37: 858490 | I37: 777000 | J37: 885980 | K37: 876330 | L37: 823710 | M37: 762330 | N37: 801220 | O37: 1086640 | P37: 1107934 | Q37: 1331313 | R37: 1078083 | S37: 1136468
F38: 食費 | G38: =SUM(H38:S38) -> 7169386 | H38: 552200 | I38: 504870 | J38: 580010 | K38: 570830 | L38: 535600 | M38: 493960 | N38: 522980 | O38: 670828 | P38: 665394 | Q38: 771198 | R38: 632950 | S38: 668566
F39: 居住費 | G39: =SUM(H39:S39) -> 4356112 | H39: 306290 | I39: 272130 | J39: 305970 | K39: 305500 | L39: 288110 | M39: 268370 | N39: 278240 | O39: 415812 | P39: 442540 | Q39: 560115 | R39: 445133 | S39: 467902
D40: 54地域密着型介護老人福祉施設入所者生活介護 | G40: =SUM(H40:S40) -> 11525498 | H40: 858490 | I40: 777000 | J40: 885980 | K40: 876330 | L40: 823710 | M40: 762330 | N40: 801220 | O40: 1086640 | P40: 1107934 | Q40: 1331313 | R40: 1078083 | S40: 1136468
F41: 食費 | G41: =SUM(H41:S41) -> 7169386 | H41: 552200 | I41: 504870 | J41: 580010 | K41: 570830 | L41: 535600 | M41: 493960 | N41: 522980 | O41: 670828 | P41: 665394 | Q41: 771198 | R41: 632950 | S41: 668566
F42: 居住費 | G42: =SUM(H42:S42) -> 4356112 | H42: 306290 | I42: 272130 | J42: 305970 | K42: 305500 | L42: 288110 | M42: 268370 | N42: 278240 | O42: 415812 | P42: 442540 | Q42: 560115 | R42: 445133 | S42: 467902
...
