Workbook

Sheet 00_使い方
A1: 川崎町 サービス別 計画値・実績値 対比表
B5: 1．この表の目的
C6: 第9期計画（令和6年3月）に定めた各サービス・事業の見込量（計画値）と、実績値を対比する表です。
C7: 仕様書6（4）の現行施策の検証に用いるとともに、保険者機能強化推進交付金の評価指標
C8: 目標Ⅰ-2「介護保険事業計画の進捗状況（計画値と実績値の乖離状況）を分析しているか」に対応します。
C9: 同指標は、単に数値を把握しただけでは非該当とされ、乖離の要因の考察までが求められます。
C10: このため N列「乖離の要因・対応」の記入が評価上も重要です。
B12: 2．色の意味
B13: 緑（計画値） | C13: 第9期計画書から転記した確定値です。編集しないでください。
B14: 黄（記入欄） | C14: 町にご記入いただく欄です。青字で入力してください。
B15: 白（達成率） | C15: 実績÷計画で自動計算されます。
B17: 3．シート構成
B18: 01_居宅サービス | C18: 訪問・通所・短期入所・福祉用具・住宅改修・居宅介護支援（介護予防を含む）
B19: 02_地域密着型サービス | C19: 認知症対応型共同生活介護ほか。第9期に見込量表がないサービスも一覧に含めています。
B20: 03_施設サービス | C20: 介護老人福祉施設・介護老人保健施設ほか
B21: 04_総合事業・一般介護予防 | C21: 訪問型／通所型サービス、介護予防教室、地域リハビリテーション活動支援
B22: 05_包括的支援事業・任意事業 | C22: 認知症関係、介護用品の支給、配食サービス、見守り
B23: 06_高齢者福祉サービス | C23: 移送・会食・緊急通報・老人クラブ・敬老会
B24: 07_記入状況 | C24: 各シートの記入状況を自動集計します。
B26: 4．実績を記入済みの箇所
C27: 令和8年9月1日にご提供いただいた実績データから転記できたものは、あらかじめ記入しています。
C28: ただし次のものは実績として扱っていません。
C29: ・02シート（総合事業・介護予防）の教室関係は、出典欄が「第9期計画」であり計画値が転記されているため
C30: （確認事項No.42）。空欄のままとしています。
C31: ・12〜14シート（サービス見込量）の実績欄はほぼ全面的に未記入のため（確認事項No.40）。
B33: 5．留意点
C34: ・計画値の「延利用人数」と実績データの「利用者数・利用量」は定義が一致するか確認が必要です。
C35: ・実績データのR7は見込、R8は当初・見込であり、確定値ではありません（仮試算扱い）。
C36: ・確定値をいただき次第、本表を更新します。

Sheet 01_居宅サービス
A1: サービス別 計画値・実績値 対比表 居宅サービス
A2: 計画値：第9期計画書（令和6年3月）／実績：町提供実績データ（令和8年9月1日受領・仮試算）
A4: 区分 | B4: サービス・事業名 | C4: 指標 | D4: 単位 | E4: R6計画 | F4: R6実績 | G4: 達成率 | H4: R7計画 | I4: R7実績 | J4: 達成率 | K4: R8計画 | L4: R8見込 | M4: 達成率 | N4: 乖離の要因・対応 | O4: 出典・記入担当
A5: 居宅 | B5: 訪問介護（ホームヘルプサービス） | C5: 延利用人数 | D5: 人／年 | E5: 312 | F5: 434 | G5: =IF(OR(E5="",E5=0,F5=""),"",F5/E5) | H5: 312 | I5: 407 | J5: =IF(OR(H5="",H5=0,I5=""),"",I5/H5) | K5: 312 | L5: 411 | M5: =IF(OR(K5="",K5=0,L5=""),"",L5/K5) | O5: 計画書／実績データ 04シート
A6: 居宅 | B6: 訪問介護（ホームヘルプサービス） | C6: 給付費 | D6: 千円／年 | E6: 35448 | F6: 40912 | G6: =IF(OR(E6="",E6=0,F6=""),"",F6/E6) | H6: 35646 | I6: 27779 | J6: =IF(OR(H6="",H6=0,I6=""),"",I6/H6) | K6: 35763 | L6: 28334 | M6: =IF(OR(K6="",K6=0,L6=""),"",L6/K6) | N6: 令和6年度40,912千円から令和7年度27,779千円へ急減。訪問介護の実働ヘルパー数（登録21名・実働4名）との関係を含め確認が必要 | O6: 計画書／実績データ 04シート
A7: 居宅 | B7: 訪問入浴介護 | C7: 延利用人数 | D7: 人／年 | E7: 108 | G7: =IF(OR(E7="",E7=0,F7=""),"",F7/E7) | H7: 108 | J7: =IF(OR(H7="",H7=0,I7=""),"",I7/H7) | K7: 108 | M7: =IF(OR(K7="",K7=0,L7=""),"",L7/K7) | O7: 第9期計画書
A8: 居宅 | B8: 訪問入浴介護 | C8: 給付費 | D8: 千円／年 | E8: 6906 | G8: =IF(OR(E8="",E8=0,F8=""),"",F8/E8) | H8: 6951 | J8: =IF(OR(H8="",H8=0,I8=""),"",I8/H8) | K8: 6986 | M8: =IF(OR(K8="",K8=0,L8=""),"",L8/K8) | O8: 第9期計画書
A9: 居宅 | B9: 介護予防訪問入浴介護 | C9: 延利用人数 | D9: 人／年 | E9: 0 | G9: =IF(OR(E9="",E9=0,F9=""),"",F9/E9) | H9: 0 | J9: =IF(OR(H9="",H9=0,I9=""),"",I9/H9) | K9: 0 | M9: =IF(OR(K9="",K9=0,L9=""),"",L9/K9) | O9: 第9期計画書
A10: 居宅 | B10: 介護予防訪問入浴介護 | C10: 給付費 | D10: 千円／年 | E10: 0 | G10: =IF(OR(E10="",E10=0,F10=""),"",F10/E10) | H10: 0 | J10: =IF(OR(H10="",H10=0,I10=""),"",I10/H10) | K10: 0 | M10: =IF(OR(K10="",K10=0,L10=""),"",L10/K10) | O10: 第9期計画書
A11: 居宅 | B11: 訪問看護 | C11: 延利用人数 | D11: 人／年 | E11: 60 | F11: 65 | G11: =IF(OR(E11="",E11=0,F11=""),"",F11/E11) | H11: 60 | I11: 99 | J11: =IF(OR(H11="",H11=0,I11=""),"",I11/H11) | K11: 60 | L11: 100 | M11: =IF(OR(K11="",K11=0,L11=""),"",L11/K11) | O11: 計画書／実績データ 04シート
A12: 居宅 | B12: 訪問看護 | C12: 給付費 | D12: 千円／年 | E12: 1149 | F12: 1585 | G12: =IF(OR(E12="",E12=0,F12=""),"",F12/E12) | H12: 1151 | I12: 3151 | J12: =IF(OR(H12="",H12=0,I12=""),"",I12/H12) | K12: 1151 | L12: 3214 | M12: =IF(OR(K12="",K12=0,L12=""),"",L12/K12) | O12: 計画書／実績データ 04シート
A13: 居宅 | B13: 介護予防訪問看護 | C13: 延利用人数 | D13: 人／年 | E13: 0 | G13: =IF(OR(E13="",E13=0,F13=""),"",F13/E13) | H13: 0 | J13: =IF(OR(H13="",H13=0,I13=""),"",I13/H13) | K13: 0 | M13: =IF(OR(K13="",K13=0,L13=""),"",L13/K13) | O13: 第9期計画書
A14: 居宅 | B14: 介護予防訪問看護 | C14: 給付費 | D14: 千円／年 | E14: 0 | G14: =IF(OR(E14="",E14=0,F14=""),"",F14/E14) | H14: 0 | J14: =IF(OR(H14="",H14=0,I14=""),"",I14/H14) | K14: 0 | M14: =IF(OR(K14="",K14=0,L14=""),"",L14/K14) | O14: 第9期計画書
A15: 居宅 | B15: 訪問リハビリテーション | C15: 延利用人数 | D15: 人／年 | E15: 192 | G15: =IF(OR(E15="",E15=0,F15=""),"",F15/E15) | H15: 192 | J15: =IF(OR(H15="",H15=0,I15=""),"",I15/H15) | K15: 192 | M15: =IF(OR(K15="",K15=0,L15=""),"",L15/K15) | O15: 第9期計画書
A16: 居宅 | B16: 訪問リハビリテーション | C16: 給付費 | D16: 千円／年 | E16: 7227 | G16: =IF(OR(E16="",E16=0,F16=""),"",F16/E16) | H16: 7340 | J16: =IF(OR(H16="",H16=0,I16=""),"",I16/H16) | K16: 7443 | M16: =IF(OR(K16="",K16=0,L16=""),"",L16/K16) | O16: 第9期計画書
A17: 居宅 | B17: 介護予防訪問リハビリテーション | C17: 延利用人数 | D17: 人／年 | E17: 108 | G17: =IF(OR(E17="",E17=0,F17=""),"",F17/E17) | H17: 108 | J17: =IF(OR(H17="",H17=0,I17=""),"",I17/H17) | K17: 108 | M17: =IF(OR(K17="",K17=0,L17=""),"",L17/K17) | O17: 第9期計画書
A18: 居宅 | B18: 介護予防訪問リハビリテーション | C18: 給付費 | D18: 千円／年 | E18: 3539 | G18: =IF(OR(E18="",E18=0,F18=""),"",F18/E18) | H18: 3611 | J18: =IF(OR(H18="",H18=0,I18=""),"",I18/H18) | K18: 3678 | M18: =IF(OR(K18="",K18=0,L18=""),"",L18/K18) | O18: 第9期計画書
A19: 居宅 | B19: 居宅療養管理指導 | C19: 延利用人数 | D19: 人／年 | E19: 36 | G19: =IF(OR(E19="",E19=0,F19=""),"",F19/E19) | H19: 36 | J19: =IF(OR(H19="",H19=0,I19=""),"",I19/H19) | K19: 36 | M19: =IF(OR(K19="",K19=0,L19=""),"",L19/K19) | O19: 第9期計画書
A20: 居宅 | B20: 居宅療養管理指導 | C20: 給付費 | D20: 千円／年 | E20: 650 | G20: =IF(OR(E20="",E20=0,F20=""),"",F20/E20) | H20: 651 | J20: =IF(OR(H20="",H20=0,I20=""),"",I20/H20) | K20: 651 | M20: =IF(OR(K20="",K20=0,L20=""),"",L20/K20) | O20: 第9期計画書
A21: 居宅 | B21: 介護予防居宅療養管理指導 | C21: 延利用人数 | D21: 人／年 | E21: 0 | G21: =IF(OR(E21="",E21=0,F21=""),"",F21/E21) | H21: 0 | J21: =IF(OR(H21="",H21=0,I21=""),"",I21/H21) | K21: 0 | M21: =IF(OR(K21="",K21=0,L21=""),"",L21/K21) | O21: 第9期計画書
A22: 居宅 | B22: 介護予防居宅療養管理指導 | C22: 給付費 | D22: 千円／年 | E22: 0 | G22: =IF(OR(E22="",E22=0,F22=""),"",F22/E22) | H22: 0 | J22: =IF(OR(H22="",H22=0,I22=""),"",I22/H22) | K22: 0 | M22: =IF(OR(K22="",K22=0,L22=""),"",L22/K22) | O22: 第9期計画書
A23: 居宅 | B23: 通所介護（デイサービス） | C23: 延利用人数 | D23: 人／年 | E23: 660 | F23: 711 | G23: =IF(OR(E23="",E23=0,F23=""),"",F23/E23) | H23: 660 | I23: 648 | J23: =IF(OR(H23="",H23=0,I23=""),"",I23/H23) | K23: 660 | L23: 654 | M23: =IF(OR(K23="",K23=0,L23=""),"",L23/K23) | O23: 計画書／実績データ 04シート
A24: 居宅 | B24: 通所介護（デイサービス） | C24: 給付費 | D24: 千円／年 | E24: 59538 | F24: 64270 | G24: =IF(OR(E24="",E24=0,F24=""),"",F24/E24) | H24: 59859 | I24: 62331 | J24: =IF(OR(H24="",H24=0,I24=""),"",I24/H24) | K24: 60182 | L24: 63577 | M24: =IF(OR(K24="",K24=0,L24=""),"",L24/K24) | O24: 計画書／実績データ 04シート
A25: 居宅 | B25: 通所リハビリテーション | C25: 延利用人数 | D25: 人／年 | E25: 1080 | G25: =IF(OR(E25="",E25=0,F25=""),"",F25/E25) | H25: 1080 | J25: =IF(OR(H25="",H25=0,I25=""),"",I25/H25) | K25: 1080 | M25: =IF(OR(K25="",K25=0,L25=""),"",L25/K25) | O25: 第9期計画書
A26: 居宅 | B26: 通所リハビリテーション | C26: 給付費 | D26: 千円／年 | E26: 102875 | G26: =IF(OR(E26="",E26=0,F26=""),"",F26/E26) | H26: 103005 | J26: =IF(OR(H26="",H26=0,I26=""),"",I26/H26) | K26: 103005 | M26: =IF(OR(K26="",K26=0,L26=""),"",L26/K26) | O26: 第9期計画書
A27: 居宅 | B27: 介護予防通所リハビリテーション | C27: 延利用人数 | D27: 人／年 | E27: 408 | G27: =IF(OR(E27="",E27=0,F27=""),"",F27/E27) | H27: 408 | J27: =IF(OR(H27="",H27=0,I27=""),"",I27/H27) | K27: 408 | M27: =IF(OR(K27="",K27=0,L27=""),"",L27/K27) | O27: 第9期計画書
A28: 居宅 | B28: 介護予防通所リハビリテーション | C28: 給付費 | D28: 千円／年 | E28: 17687 | G28: =IF(OR(E28="",E28=0,F28=""),"",F28/E28) | H28: 17709 | J28: =IF(OR(H28="",H28=0,I28=""),"",I28/H28) | K28: 17709 | M28: =IF(OR(K28="",K28=0,L28=""),"",L28/K28) | O28: 第9期計画書
A29: 居宅 | B29: 短期入所生活介護（ショートステイ） | C29: 延利用人数 | D29: 人／年 | E29: 168 | F29: 135 | G29: =IF(OR(E29="",E29=0,F29=""),"",F29/E29) | H29: 168 | I29: 146 | J29: =IF(OR(H29="",H29=0,I29=""),"",I29/H29) | K29: 168 | L29: 147 | M29: =IF(OR(K29="",K29=0,L29=""),"",L29/K29) | O29: 計画書／実績データ 04シート
A30: 居宅 | B30: 短期入所生活介護（ショートステイ） | C30: 給付費 | D30: 千円／年 | E30: 23974 | F30: 12218 | G30: =IF(OR(E30="",E30=0,F30=""),"",F30/E30) | H30: 24124 | I30: 15832 | J30: =IF(OR(H30="",H30=0,I30=""),"",I30/H30) | K30: 24244 | L30: 16148 | M30: =IF(OR(K30="",K30=0,L30=""),"",L30/K30) | O30: 計画書／実績データ 04シート
A31: 居宅 | B31: 介護予防短期入所生活介護（ショートステイ） | C31: 延利用人数 | D31: 人／年 | E31: 0 | G31: =IF(OR(E31="",E31=0,F31=""),"",F31/E31) | H31: 0 | J31: =IF(OR(H31="",H31=0,I31=""),"",I31/H31) | K31: 0 | M31: =IF(OR(K31="",K31=0,L31=""),"",L31/K31) | O31: 第9期計画書
A32: 居宅 | B32: 介護予防短期入所生活介護（ショートステイ） | C32: 給付費 | D32: 千円／年 | E32: 0 | G32: =IF(OR(E32="",E32=0,F32=""),"",F32/E32) | H32: 0 | J32: =IF(OR(H32="",H32=0,I32=""),"",I32/H32) | K32: 0 | M32: =IF(OR(K32="",K32=0,L32=""),"",L32/K32) | O32: 第9期計画書
A33: 居宅 | B33: 短期入所療養介護（ショートステイ） | C33: 延利用人数 | D33: 人／年 | E33: 168 | G33: =IF(OR(E33="",E33=0,F33=""),"",F33/E33) | H33: 168 | J33: =IF(OR(H33="",H33=0,I33=""),"",I33/H33) | K33: 168 | M33: =IF(OR(K33="",K33=0,L33=""),"",L33/K33) | O33: 第9期計画書
A34: 居宅 | B34: 短期入所療養介護（ショートステイ） | C34: 給付費 | D34: 千円／年 | E34: 16697 | G34: =IF(OR(E34="",E34=0,F34=""),"",F34/E34) | H34: 16905 | J34: =IF(OR(H34="",H34=0,I34=""),"",I34/H34) | K34: 17238 | M34: =IF(OR(K34="",K34=0,L34=""),"",L34/K34) | O34: 第9期計画書
A35: 居宅 | B35: 介護予防短期療養生活介護（ショートステイ） | C35: 延利用人数 | D35: 人／年 | E35: 0 | G35: =IF(OR(E35="",E35=0,F35=""),"",F35/E35) | H35: 0 | J35: =IF(OR(H35="",H35=0,I35=""),"",I35/H35) | K35: 0 | M35: =IF(OR(K35="",K35=0,L35=""),"",L35/K35) | O35: 第9期計画書
A36: 居宅 | B36: 介護予防短期療養生活介護（ショートステイ） | C36: 給付費 | D36: 千円／年 | E36: 0 | G36: =IF(OR(E36="",E36=0,F36=""),"",F36/E36) | H36: 0 | J36: =IF(OR(H36="",H36=0,I36=""),"",I36/H36) | K36: 0 | M36: =IF(OR(K36="",K36=0,L36=""),"",L36/K36) | O36: 第9期計画書
A37: 居宅 | B37: 特定施設入居者生活介護 | C37: 延利用人数 | D37: 人／年 | E37: 12 | G37: =IF(OR(E37="",E37=0,F37=""),"",F37/E37) | H37: 12 | J37: =IF(OR(H37="",H37=0,I37=""),"",I37/H37) | K37: 12 | M37: =IF(OR(K37="",K37=0,L37=""),"",L37/K37) | O37: 第9期計画書
A38: 居宅 | B38: 特定施設入居者生活介護 | C38: 給付費 | D38: 千円／年 | E38: 2129 | G38: =IF(OR(E38="",E38=0,F38=""),"",F38/E38) | H38: 2132 | J38: =IF(OR(H38="",H38=0,I38=""),"",I38/H38) | K38: 2132 | M38: =IF(OR(K38="",K38=0,L38=""),"",L38/K38) | O38: 第9期計画書
A39: 居宅 | B39: 介護予防特定施設入居者生活介護 | C39: 延利用人数 | D39: 人／年 | E39: 0 | G39: =IF(OR(E39="",E39=0,F39=""),"",F39/E39) | H39: 0 | J39: =IF(OR(H39="",H39=0,I39=""),"",I39/H39) | K39: 0 | M39: =IF(OR(K39="",K39=0,L39=""),"",L39/K39) | O39: 第9期計画書
A40: 居宅 | B40: 介護予防特定施設入居者生活介護 | C40: 給付費 | D40: 千円／年 | E40: 0 | G40: =IF(OR(E40="",E40=0,F40=""),"",F40/E40) | H40: 0 | J40: =IF(OR(H40="",H40=0,I40=""),"",I40/H40) | K40: 0 | M40: =IF(OR(K40="",K40=0,L40=""),"",L40/K40) | O40: 第9期計画書
A41: 居宅 | B41: 福祉用具貸与 | C41: 延利用人数 | D41: 人／年 | E41: 1488 | G41: =IF(OR(E41="",E41=0,F41=""),"",F41/E41) | H41: 1488 | J41: =IF(OR(H41="",H41=0,I41=""),"",I41/H41) | K41: 1476 | M41: =IF(OR(K41="",K41=0,L41=""),"",L41/K41) | O41: 第9期計画書
...

Sheet 02_地域密着型サービス
A1: サービス別 計画値・実績値 対比表 地域密着型サービス
A2: 計画値：第9期計画書（令和6年3月）／実績：町提供実績データ（令和8年9月1日受領・仮試算）
A4: 区分 | B4: サービス・事業名 | C4: 指標 | D4: 単位 | E4: R6計画 | F4: R6実績 | G4: 達成率 | H4: R7計画 | I4: R7実績 | J4: 達成率 | K4: R8計画 | L4: R8見込 | M4: 達成率 | N4: 乖離の要因・対応 | O4: 出典・記入担当
A5: 地域密着型 | B5: 認知症対応型共同生活介護 | C5: 延利用人数 | D5: 人／年 | E5: 324 | F5: 323 | G5: =IF(OR(E5="",E5=0,F5=""),"",F5/E5) | H5: 324 | I5: 312 | J5: =IF(OR(H5="",H5=0,I5=""),"",I5/H5) | K5: 324 | L5: 315 | M5: =IF(OR(K5="",K5=0,L5=""),"",L5/K5) | O5: 計画書／実績データ 04シート
A6: 地域密着型 | B6: 認知症対応型共同生活介護 | C6: 給付費 | D6: 千円／年 | E6: 87350 | F6: 88245 | G6: =IF(OR(E6="",E6=0,F6=""),"",F6/E6) | H6: 87460 | I6: 84407 | J6: =IF(OR(H6="",H6=0,I6=""),"",I6/H6) | K6: 87460 | L6: 86095 | M6: =IF(OR(K6="",K6=0,L6=""),"",L6/K6) | O6: 計画書／実績データ 04シート
A7: 地域密着型 | B7: 介護予防認知症対応型共同生活介護 | C7: 延利用人数 | D7: 人／年 | E7: 0 | G7: =IF(OR(E7="",E7=0,F7=""),"",F7/E7) | H7: 0 | J7: =IF(OR(H7="",H7=0,I7=""),"",I7/H7) | K7: 0 | M7: =IF(OR(K7="",K7=0,L7=""),"",L7/K7) | O7: 第9期計画書
A8: 地域密着型 | B8: 介護予防認知症対応型共同生活介護 | C8: 給付費 | D8: 千円／年 | E8: 0 | G8: =IF(OR(E8="",E8=0,F8=""),"",F8/E8) | H8: 0 | J8: =IF(OR(H8="",H8=0,I8=""),"",I8/H8) | K8: 0 | M8: =IF(OR(K8="",K8=0,L8=""),"",L8/K8) | O8: 第9期計画書
A9: 地域密着型 | B9: 地域密着型介護老人福祉施設入居者生活介護 | C9: 延利用人数 | D9: 人／年 | E9: 300 | G9: =IF(OR(E9="",E9=0,F9=""),"",F9/E9) | H9: 300 | J9: =IF(OR(H9="",H9=0,I9=""),"",I9/H9) | K9: 300 | M9: =IF(OR(K9="",K9=0,L9=""),"",L9/K9) | O9: 第9期計画書
A10: 地域密着型 | B10: 地域密着型介護老人福祉施設入居者生活介護 | C10: 給付費 | D10: 千円／年 | E10: 92307 | G10: =IF(OR(E10="",E10=0,F10=""),"",F10/E10) | H10: 92424 | J10: =IF(OR(H10="",H10=0,I10=""),"",I10/H10) | K10: 92424 | M10: =IF(OR(K10="",K10=0,L10=""),"",L10/K10) | O10: 第9期計画書
A11: 地域密着型 | B11: 定期巡回・随時対応型訪問介護看護 | C11: ― | D11: ― | G11: =IF(OR(E11="",E11=0,F11=""),"",F11/E11) | J11: =IF(OR(H11="",H11=0,I11=""),"",I11/H11) | M11: =IF(OR(K11="",K11=0,L11=""),"",L11/K11) | N11: 第9期計画に見込量表なし（「今後のサービスニーズの動向を勘案し検討」） | O11: 第9期計画書
A12: 地域密着型 | B12: 夜間対応型訪問介護 | C12: ― | D12: ― | G12: =IF(OR(E12="",E12=0,F12=""),"",F12/E12) | J12: =IF(OR(H12="",H12=0,I12=""),"",I12/H12) | M12: =IF(OR(K12="",K12=0,L12=""),"",L12/K12) | N12: 同上 | O12: 第9期計画書
A13: 地域密着型 | B13: 認知症対応型通所介護・介護予防認知症対応型通所介護 | C13: ― | D13: ― | G13: =IF(OR(E13="",E13=0,F13=""),"",F13/E13) | J13: =IF(OR(H13="",H13=0,I13=""),"",I13/H13) | M13: =IF(OR(K13="",K13=0,L13=""),"",L13/K13) | N13: 同上 | O13: 第9期計画書
A14: 地域密着型 | B14: 小規模多機能型居宅介護・介護予防小規模多機能型居宅介護 | C14: 延利用人数 | D14: 人／年 | F14: 323 | G14: =IF(OR(E14="",E14=0,F14=""),"",F14/E14) | I14: 10 | J14: =IF(OR(H14="",H14=0,I14=""),"",I14/H14) | L14: 10 | M14: =IF(OR(K14="",K14=0,L14=""),"",L14/K14) | N14: 同上。ただし実績データでは令和6年度以降に給付実績がある | O14: 実績データ 04シート
A15: 地域密着型 | B15: 小規模多機能型居宅介護・介護予防小規模多機能型居宅介護 | C15: 給付費 | D15: 千円／年 | F15: 3466 | G15: =IF(OR(E15="",E15=0,F15=""),"",F15/E15) | I15: 808 | J15: =IF(OR(H15="",H15=0,I15=""),"",I15/H15) | L15: 791 | M15: =IF(OR(K15="",K15=0,L15=""),"",L15/K15) | N15: 同上。ただし実績データでは令和6年度以降に給付実績がある | O15: 実績データ 04シート
A16: 地域密着型 | B16: 地域密着型特定施設入居者生活介護 | C16: ― | D16: ― | G16: =IF(OR(E16="",E16=0,F16=""),"",F16/E16) | J16: =IF(OR(H16="",H16=0,I16=""),"",I16/H16) | M16: =IF(OR(K16="",K16=0,L16=""),"",L16/K16) | N16: 同上 | O16: 第9期計画書
A17: 地域密着型 | B17: 看護小規模多機能型居宅介護（複合型サービス） | C17: ― | D17: ― | G17: =IF(OR(E17="",E17=0,F17=""),"",F17/E17) | J17: =IF(OR(H17="",H17=0,I17=""),"",I17/H17) | M17: =IF(OR(K17="",K17=0,L17=""),"",L17/K17) | N17: 同上 | O17: 第9期計画書
A18: 地域密着型 | B18: 地域密着型通所介護（小規模デイ） | C18: 延利用人数 | D18: 人／年 | F18: 11 | G18: =IF(OR(E18="",E18=0,F18=""),"",F18/E18) | I18: 11 | J18: =IF(OR(H18="",H18=0,I18=""),"",I18/H18) | L18: 11 | M18: =IF(OR(K18="",K18=0,L18=""),"",L18/K18) | N18: 同上。ただし実績データでは令和4年度以降に給付実績がある | O18: 実績データ 04シート
A19: 地域密着型 | B19: 地域密着型通所介護（小規模デイ） | C19: 給付費 | D19: 千円／年 | F19: 324 | G19: =IF(OR(E19="",E19=0,F19=""),"",F19/E19) | I19: 377 | J19: =IF(OR(H19="",H19=0,I19=""),"",I19/H19) | L19: 380 | M19: =IF(OR(K19="",K19=0,L19=""),"",L19/K19) | N19: 同上。ただし実績データでは令和4年度以降に給付実績がある | O19: 実績データ 04シート

Sheet 03_施設サービス
A1: サービス別 計画値・実績値 対比表 施設サービス
A2: 計画値：第9期計画書（令和6年3月）／実績：町提供実績データ（令和8年9月1日受領・仮試算）
A4: 区分 | B4: サービス・事業名 | C4: 指標 | D4: 単位 | E4: R6計画 | F4: R6実績 | G4: 達成率 | H4: R7計画 | I4: R7実績 | J4: 達成率 | K4: R8計画 | L4: R8見込 | M4: 達成率 | N4: 乖離の要因・対応 | O4: 出典・記入担当
A5: 施設 | B5: 介護老人福祉施設（特別養護老人施設） | C5: 延利用人数 | D5: 人／年 | E5: 780 | F5: 827 | G5: =IF(OR(E5="",E5=0,F5=""),"",F5/E5) | H5: 780 | I5: 830 | J5: =IF(OR(H5="",H5=0,I5=""),"",I5/H5) | K5: 780 | L5: 830 | M5: =IF(OR(K5="",K5=0,L5=""),"",L5/K5) | O5: 計画書／実績データ 04シート
A6: 施設 | B6: 介護老人福祉施設（特別養護老人施設） | C6: 給付費 | D6: 千円／年 | E6: 222271 | F6: 232501 | G6: =IF(OR(E6="",E6=0,F6=""),"",F6/E6) | H6: 222552 | I6: 232975 | J6: =IF(OR(H6="",H6=0,I6=""),"",I6/H6) | K6: 222552 | L6: 237634 | M6: =IF(OR(K6="",K6=0,L6=""),"",L6/K6) | O6: 計画書／実績データ 04シート
A7: 施設 | B7: 介護老人保健施設（老人保健施設） | C7: 延利用人数 | D7: 人／年 | E7: 816 | F7: 773 | G7: =IF(OR(E7="",E7=0,F7=""),"",F7/E7) | H7: 816 | I7: 810 | J7: =IF(OR(H7="",H7=0,I7=""),"",I7/H7) | K7: 828 | L7: 810 | M7: =IF(OR(K7="",K7=0,L7=""),"",L7/K7) | O7: 計画書／実績データ 04シート
A8: 施設 | B8: 介護老人保健施設（老人保健施設） | C8: 給付費 | D8: 千円／年 | E8: 254611 | F8: 249357 | G8: =IF(OR(E8="",E8=0,F8=""),"",F8/E8) | H8: 254933 | I8: 260376 | J8: =IF(OR(H8="",H8=0,I8=""),"",I8/H8) | K8: 258976 | L8: 265583 | M8: =IF(OR(K8="",K8=0,L8=""),"",L8/K8) | O8: 計画書／実績データ 04シート
A9: 施設 | B9: 介護療養型医療施設 | C9: ― | D9: ― | G9: =IF(OR(E9="",E9=0,F9=""),"",F9/E9) | J9: =IF(OR(H9="",H9=0,I9=""),"",I9/H9) | M9: =IF(OR(K9="",K9=0,L9=""),"",L9/K9) | N9: 令和5年度末に制度廃止 | O9: 第9期計画書
A10: 施設 | B10: 介護医療院 | C10: ― | D10: ― | G10: =IF(OR(E10="",E10=0,F10=""),"",F10/E10) | J10: =IF(OR(H10="",H10=0,I10=""),"",I10/H10) | M10: =IF(OR(K10="",K10=0,L10=""),"",L10/K10) | N10: 第9期計画に記載なし。実績データにも計上なし | O10: 第9期計画書

Sheet 04_総合事業・一般介護予防
A1: サービス別 計画値・実績値 対比表 総合事業・一般介護予防
A2: 計画値：第9期計画書（令和6年3月）／実績：町提供実績データ（令和8年9月1日受領・仮試算）
A4: 区分 | B4: サービス・事業名 | C4: 指標 | D4: 単位 | E4: R6計画 | F4: R6実績 | G4: 達成率 | H4: R7計画 | I4: R7実績 | J4: 達成率 | K4: R8計画 | L4: R8見込 | M4: 達成率 | N4: 乖離の要因・対応 | O4: 出典・記入担当
A5: 地域支援事業 | B5: 訪問型サービス（指定事業所による訪問介護サービス） | C5: 延利用人数 | D5: 人／年 | E5: 96 | G5: =IF(OR(E5="",E5=0,F5=""),"",F5/E5) | H5: 96 | J5: =IF(OR(H5="",H5=0,I5=""),"",I5/H5) | K5: 96 | M5: =IF(OR(K5="",K5=0,L5=""),"",L5/K5) | N5: 実績データ02シートに訪問型サービスの利用実人数481〜534人の記載があるが、計画の延利用人数96人と定義が一致しないため転記していない | O5: 第9期計画書
A6: 地域支援事業 | B6: 訪問型サービス（指定事業所による訪問介護サービス） | C6: 給付費 | D6: 千円／年 | E6: 400 | G6: =IF(OR(E6="",E6=0,F6=""),"",F6/E6) | H6: 400 | J6: =IF(OR(H6="",H6=0,I6=""),"",I6/H6) | K6: 400 | M6: =IF(OR(K6="",K6=0,L6=""),"",L6/K6) | O6: 第9期計画書
A7: 地域支援事業 | B7: 訪問型サービス B（住民主体のサービス） | C7: 実利用人数 | D7: 人／年 | E7: 16 | G7: =IF(OR(E7="",E7=0,F7=""),"",F7/E7) | H7: 17 | J7: =IF(OR(H7="",H7=0,I7=""),"",I7/H7) | K7: 18 | M7: =IF(OR(K7="",K7=0,L7=""),"",L7/K7) | O7: 第9期計画書
A8: 地域支援事業 | B8: 訪問型サービス B（住民主体のサービス） | C8: 延利用人数 | D8: 人／年 | E8: 590 | G8: =IF(OR(E8="",E8=0,F8=""),"",F8/E8) | H8: 620 | J8: =IF(OR(H8="",H8=0,I8=""),"",I8/H8) | K8: 650 | M8: =IF(OR(K8="",K8=0,L8=""),"",L8/K8) | O8: 第9期計画書
A9: 地域支援事業 | B9: 訪問型サービス C（短期集中予防サービス） | C9: 実利用人数 | D9: 人／年 | E9: 10 | G9: =IF(OR(E9="",E9=0,F9=""),"",F9/E9) | H9: 10 | J9: =IF(OR(H9="",H9=0,I9=""),"",I9/H9) | K9: 10 | M9: =IF(OR(K9="",K9=0,L9=""),"",L9/K9) | O9: 第9期計画書
A10: 地域支援事業 | B10: 通所型サービス（指定事業所による通所サービス） | C10: 延利用人数 | D10: 人／年 | E10: 300 | G10: =IF(OR(E10="",E10=0,F10=""),"",F10/E10) | H10: 300 | J10: =IF(OR(H10="",H10=0,I10=""),"",I10/H10) | K10: 300 | M10: =IF(OR(K10="",K10=0,L10=""),"",L10/K10) | N10: 実績データ02シートに通所型サービスの利用実人数647〜786人の記載があるが、計画の延利用人数300人と定義が一致しないため転記していない | O10: 第9期計画書
A11: 地域支援事業 | B11: 通所型サービス（指定事業所による通所サービス） | C11: 給付費 | D11: 千円／年 | E11: 2400 | G11: =IF(OR(E11="",E11=0,F11=""),"",F11/E11) | H11: 2400 | J11: =IF(OR(H11="",H11=0,I11=""),"",I11/H11) | K11: 2400 | M11: =IF(OR(K11="",K11=0,L11=""),"",L11/K11) | O11: 第9期計画書
A12: 地域支援事業 | B12: 通所型サービス B（住民主体のサービス） | C12: 実利用人数 | D12: 人／年 | E12: 21 | G12: =IF(OR(E12="",E12=0,F12=""),"",F12/E12) | H12: 22 | J12: =IF(OR(H12="",H12=0,I12=""),"",I12/H12) | K12: 23 | M12: =IF(OR(K12="",K12=0,L12=""),"",L12/K12) | O12: 第9期計画書
A13: 地域支援事業 | B13: 通所型サービス B（住民主体のサービス） | C13: 延利用人数 | D13: 人／年 | E13: 540 | G13: =IF(OR(E13="",E13=0,F13=""),"",F13/E13) | H13: 550 | J13: =IF(OR(H13="",H13=0,I13=""),"",I13/H13) | K13: 560 | M13: =IF(OR(K13="",K13=0,L13=""),"",L13/K13) | O13: 第9期計画書
A14: 地域支援事業 | B14: 介護予防支援事業（ケアマネジメント） | C14: 給付費 | D14: 千円／年 | E14: 730 | G14: =IF(OR(E14="",E14=0,F14=""),"",F14/E14) | H14: 740 | J14: =IF(OR(H14="",H14=0,I14=""),"",I14/H14) | K14: 750 | M14: =IF(OR(K14="",K14=0,L14=""),"",L14/K14) | O14: 第9期計画書
A15: 地域支援事業 | B15: 介護予防フェスティバル | C15: 参加人数 | E15: 250 | G15: =IF(OR(E15="",E15=0,F15=""),"",F15/E15) | H15: 250 | J15: =IF(OR(H15="",H15=0,I15=""),"",I15/H15) | K15: 250 | M15: =IF(OR(K15="",K15=0,L15=""),"",L15/K15) | O15: 第9期計画書
A16: 地域支援事業 | B16: 地域リハビリテーション活動支援事業 | C16: 訪問件数 | D16: 件／年 | E16: 10 | G16: =IF(OR(E16="",E16=0,F16=""),"",F16/E16) | H16: 10 | J16: =IF(OR(H16="",H16=0,I16=""),"",I16/H16) | K16: 10 | M16: =IF(OR(K16="",K16=0,L16=""),"",L16/K16) | O16: 第9期計画書
A17: 地域支援事業 | B17: 元気まんてん介護予防教室 | C17: 開催回数 | D17: 回／年 | E17: 51 | G17: =IF(OR(E17="",E17=0,F17=""),"",F17/E17) | H17: 51 | J17: =IF(OR(H17="",H17=0,I17=""),"",I17/H17) | K17: 51 | M17: =IF(OR(K17="",K17=0,L17=""),"",L17/K17) | N17: 実績データ02シートの出典欄は「第9期計画」であり計画値。実績のご記入が必要（確認事項No.42） | O17: 実績データ 02シート（計画値）
A18: 地域支援事業 | B18: 元気まんてん介護予防教室 | C18: 延参加者 | D18: 人／年 | E18: 1238 | G18: =IF(OR(E18="",E18=0,F18=""),"",F18/E18) | H18: 1238 | J18: =IF(OR(H18="",H18=0,I18=""),"",I18/H18) | K18: 1238 | M18: =IF(OR(K18="",K18=0,L18=""),"",L18/K18) | N18: 実績データ02シートの出典欄は「第9期計画」であり計画値。実績のご記入が必要（確認事項No.42） | O18: 実績データ 02シート（計画値）
A19: 地域支援事業 | B19: 元気いきいきセミナー | C19: 開催回数 | D19: 回／年 | E19: 7 | G19: =IF(OR(E19="",E19=0,F19=""),"",F19/E19) | H19: 7 | J19: =IF(OR(H19="",H19=0,I19=""),"",I19/H19) | K19: 7 | M19: =IF(OR(K19="",K19=0,L19=""),"",L19/K19) | N19: 実績データ02シートの出典欄は「第9期計画」であり計画値。実績のご記入が必要（確認事項No.42） | O19: 実績データ 02シート（計画値）
A20: 地域支援事業 | B20: 元気いきいきセミナー | C20: 延参加者 | D20: 人／年 | E20: 51 | G20: =IF(OR(E20="",E20=0,F20=""),"",F20/E20) | H20: 51 | J20: =IF(OR(H20="",H20=0,I20=""),"",I20/H20) | K20: 51 | M20: =IF(OR(K20="",K20=0,L20=""),"",L20/K20) | N20: 実績データ02シートの出典欄は「第9期計画」であり計画値。実績のご記入が必要（確認事項No.42） | O20: 実績データ 02シート（計画値）
A21: 地域支援事業 | B21: パドル体操教室 | C21: 開催回数 | D21: 回／年 | E21: 7 | G21: =IF(OR(E21="",E21=0,F21=""),"",F21/E21) | H21: 7 | J21: =IF(OR(H21="",H21=0,I21=""),"",I21/H21) | K21: 7 | M21: =IF(OR(K21="",K21=0,L21=""),"",L21/K21) | N21: 実績データ02シートの出典欄は「第9期計画」であり計画値。実績のご記入が必要（確認事項No.42） | O21: 実績データ 02シート（計画値）
A22: 地域支援事業 | B22: パドル体操教室 | C22: 延参加者 | D22: 人／年 | E22: 69 | G22: =IF(OR(E22="",E22=0,F22=""),"",F22/E22) | H22: 69 | J22: =IF(OR(H22="",H22=0,I22=""),"",I22/H22) | K22: 69 | M22: =IF(OR(K22="",K22=0,L22=""),"",L22/K22) | N22: 実績データ02シートの出典欄は「第9期計画」であり計画値。実績のご記入が必要（確認事項No.42） | O22: 実績データ 02シート（計画値）
A23: 地域支援事業 | B23: ノルディックウォーキング教室 | C23: 開催回数 | D23: 回／年 | E23: 10 | G23: =IF(OR(E23="",E23=0,F23=""),"",F23/E23) | H23: 10 | J23: =IF(OR(H23="",H23=0,I23=""),"",I23/H23) | K23: 10 | M23: =IF(OR(K23="",K23=0,L23=""),"",L23/K23) | N23: 実績データ02シートの出典欄は「第9期計画」であり計画値。実績のご記入が必要（確認事項No.42） | O23: 実績データ 02シート（計画値）
A24: 地域支援事業 | B24: ノルディックウォーキング教室 | C24: 延参加者 | D24: 人／年 | E24: 165 | G24: =IF(OR(E24="",E24=0,F24=""),"",F24/E24) | H24: 165 | J24: =IF(OR(H24="",H24=0,I24=""),"",I24/H24) | K24: 165 | M24: =IF(OR(K24="",K24=0,L24=""),"",L24/K24) | N24: 実績データ02シートの出典欄は「第9期計画」であり計画値。実績のご記入が必要（確認事項No.42） | O24: 実績データ 02シート（計画値）
A25: 地域支援事業 | B25: 介護予防サロン | C25: 設置か所 | D25: か所 | E25: 34 | G25: =IF(OR(E25="",E25=0,F25=""),"",F25/E25) | H25: 34 | J25: =IF(OR(H25="",H25=0,I25=""),"",I25/H25) | K25: 35 | M25: =IF(OR(K25="",K25=0,L25=""),"",L25/K25) | N25: 実績データ02シートの出典欄は「第9期計画」であり計画値。実績のご記入が必要（確認事項No.42） | O25: 実績データ 02シート（計画値）
A26: 地域支援事業 | B26: ヨーガ教室 | C26: 開催回数 | D26: 回／年 | E26: 36 | G26: =IF(OR(E26="",E26=0,F26=""),"",F26/E26) | H26: 36 | J26: =IF(OR(H26="",H26=0,I26=""),"",I26/H26) | K26: 36 | M26: =IF(OR(K26="",K26=0,L26=""),"",L26/K26) | N26: 実績データ02シートの出典欄は「第9期計画」であり計画値。実績のご記入が必要（確認事項No.42） | O26: 実績データ 02シート（計画値）
A27: 地域支援事業 | B27: ヨーガ教室 | C27: 延参加者 | D27: 人／年 | E27: 300 | G27: =IF(OR(E27="",E27=0,F27=""),"",F27/E27) | H27: 300 | J27: =IF(OR(H27="",H27=0,I27=""),"",I27/H27) | K27: 300 | M27: =IF(OR(K27="",K27=0,L27=""),"",L27/K27) | N27: 実績データ02シートの出典欄は「第9期計画」であり計画値。実績のご記入が必要（確認事項No.42） | O27: 実績データ 02シート（計画値）

Sheet 05_包括的支援事業・任意事業
A1: サービス別 計画値・実績値 対比表 包括的支援事業・任意事業
A2: 計画値：第9期計画書（令和6年3月）／実績：町提供実績データ（令和8年9月1日受領・仮試算）
A4: 区分 | B4: サービス・事業名 | C4: 指標 | D4: 単位 | E4: R6計画 | F4: R6実績 | G4: 達成率 | H4: R7計画 | I4: R7実績 | J4: 達成率 | K4: R8計画 | L4: R8見込 | M4: 達成率 | N4: 乖離の要因・対応 | O4: 出典・記入担当
A5: 地域支援事業 | B5: もの忘れ相談事業 | C5: 開催数 | D5: 回／年 | E5: 12 | F5: 12 | G5: =IF(OR(E5="",E5=0,F5=""),"",F5/E5) | H5: 12 | I5: 12 | J5: =IF(OR(H5="",H5=0,I5=""),"",I5/H5) | K5: 12 | L5: 12 | M5: =IF(OR(K5="",K5=0,L5=""),"",L5/K5) | O5: 計画書／実績データ 08シート
A6: 地域支援事業 | B6: 認知症初期集中支援事業 | C6: チーム員会議開催数 | D6: 回／年 | E6: 12 | F6: 12 | G6: =IF(OR(E6="",E6=0,F6=""),"",F6/E6) | H6: 12 | I6: 12 | J6: =IF(OR(H6="",H6=0,I6=""),"",I6/H6) | K6: 12 | L6: 12 | M6: =IF(OR(K6="",K6=0,L6=""),"",L6/K6) | O6: 計画書／実績データ 08シート
A7: 地域支援事業 | B7: 認知症サポーター養成講座事業 | C7: 受講者数 | D7: 人／年 | E7: 5 | F7: 5 | G7: =IF(OR(E7="",E7=0,F7=""),"",F7/E7) | H7: 5 | I7: 5 | J7: =IF(OR(H7="",H7=0,I7=""),"",I7/H7) | K7: 5 | L7: 5 | M7: =IF(OR(K7="",K7=0,L7=""),"",L7/K7) | O7: 計画書／実績データ 08シート
A8: 地域支援事業 | B8: 認知症サポーター養成講座事業 | C8: 受講累積人数 | E8: 554 | G8: =IF(OR(E8="",E8=0,F8=""),"",F8/E8) | H8: 559 | J8: =IF(OR(H8="",H8=0,I8=""),"",I8/H8) | K8: 564 | M8: =IF(OR(K8="",K8=0,L8=""),"",L8/K8) | O8: 第9期計画書
A9: 地域支援事業 | B9: 認知症地域支援推進員・キャラバンメイト | C9: 地域支援推進員数 | D9: 人／年 | E9: 0 | G9: =IF(OR(E9="",E9=0,F9=""),"",F9/E9) | H9: 0 | J9: =IF(OR(H9="",H9=0,I9=""),"",I9/H9) | K9: 1 | M9: =IF(OR(K9="",K9=0,L9=""),"",L9/K9) | O9: 第9期計画書
A10: 地域支援事業 | B10: 認知症地域支援推進員・キャラバンメイト | C10: キャラバンメイト 研修修了者数 | D10: 人／年 | E10: 1 | G10: =IF(OR(E10="",E10=0,F10=""),"",F10/E10) | H10: 1 | J10: =IF(OR(H10="",H10=0,I10=""),"",I10/H10) | K10: 1 | M10: =IF(OR(K10="",K10=0,L10=""),"",L10/K10) | O10: 第9期計画書
A11: 地域支援事業 | B11: 認知症地域支援推進員・キャラバンメイト | C11: キャラバンメイト 研修修了者延人数 | D11: 人／年 | E11: 74 | G11: =IF(OR(E11="",E11=0,F11=""),"",F11/E11) | H11: 75 | J11: =IF(OR(H11="",H11=0,I11=""),"",I11/H11) | K11: 76 | M11: =IF(OR(K11="",K11=0,L11=""),"",L11/K11) | O11: 第9期計画書
A12: 地域支援事業 | B12: 認知症カフェ（喫茶みかん）開催事業 | C12: カフェ開催数 | D12: 人／年 | E12: 47 | F12: 47 | G12: =IF(OR(E12="",E12=0,F12=""),"",F12/E12) | H12: 47 | I12: 47 | J12: =IF(OR(H12="",H12=0,I12=""),"",I12/H12) | K12: 47 | L12: 47 | M12: =IF(OR(K12="",K12=0,L12=""),"",L12/K12) | N12: 計画書の単位表記は「人／年」だが、開催数であり「回／年」の誤記と思われる | O12: 計画書／実績データ 08シート
A13: 地域支援事業 | B13: 認知症カフェ（喫茶みかん）開催事業 | C13: 延利用者数 | D13: 人／年 | E13: 235 | F13: 235 | G13: =IF(OR(E13="",E13=0,F13=""),"",F13/E13) | H13: 235 | I13: 235 | J13: =IF(OR(H13="",H13=0,I13=""),"",I13/H13) | K13: 235 | L13: 235 | M13: =IF(OR(K13="",K13=0,L13=""),"",L13/K13) | O13: 計画書／実績データ 08シート
A14: 地域支援事業 | B14: 高齢者見守りネットワーク協力機関事業所 | C14: 登録事業所・団体数 | E14: 63 | G14: =IF(OR(E14="",E14=0,F14=""),"",F14/E14) | H14: 64 | J14: =IF(OR(H14="",H14=0,I14=""),"",I14/H14) | K14: 65 | M14: =IF(OR(K14="",K14=0,L14=""),"",L14/K14) | O14: 第9期計画書
A15: 地域支援事業 | B15: 介護用品支給（非課税世帯 要介護度１～３） | C15: 延利用人数 | D15: 人／年 | E15: 17 | G15: =IF(OR(E15="",E15=0,F15=""),"",F15/E15) | H15: 22 | J15: =IF(OR(H15="",H15=0,I15=""),"",I15/H15) | K15: 22 | M15: =IF(OR(K15="",K15=0,L15=""),"",L15/K15) | O15: 第9期計画書
A16: 地域支援事業 | B16: 介護用品支給（非課税世帯 要介護度１～３） | C16: 利用実人数 | D16: 人／年 | E16: 6 | G16: =IF(OR(E16="",E16=0,F16=""),"",F16/E16) | H16: 8 | J16: =IF(OR(H16="",H16=0,I16=""),"",I16/H16) | K16: 8 | M16: =IF(OR(K16="",K16=0,L16=""),"",L16/K16) | O16: 第9期計画書
A17: 地域支援事業 | B17: 介護用品支給（非課税世帯 要介護度４・５） | C17: 延利用人数 | D17: 人／年 | E17: 36 | G17: =IF(OR(E17="",E17=0,F17=""),"",F17/E17) | H17: 31 | J17: =IF(OR(H17="",H17=0,I17=""),"",I17/H17) | K17: 31 | M17: =IF(OR(K17="",K17=0,L17=""),"",L17/K17) | O17: 第9期計画書
A18: 地域支援事業 | B18: 介護用品支給（非課税世帯 要介護度４・５） | C18: 利用実人数 | D18: 人／年 | E18: 12 | G18: =IF(OR(E18="",E18=0,F18=""),"",F18/E18) | H18: 11 | J18: =IF(OR(H18="",H18=0,I18=""),"",I18/H18) | K18: 11 | M18: =IF(OR(K18="",K18=0,L18=""),"",L18/K18) | O18: 第9期計画書
A19: 地域支援事業 | B19: 介護用品支給（課税世帯要 介護度４・５） | C19: 延利用人数 | D19: 人／年 | E19: 8 | G19: =IF(OR(E19="",E19=0,F19=""),"",F19/E19) | H19: 7 | J19: =IF(OR(H19="",H19=0,I19=""),"",I19/H19) | K19: 6 | M19: =IF(OR(K19="",K19=0,L19=""),"",L19/K19) | O19: 第9期計画書
A20: 地域支援事業 | B20: 介護用品支給（課税世帯要 介護度４・５） | C20: 利用実人数 | D20: 人／年 | E20: 8 | G20: =IF(OR(E20="",E20=0,F20=""),"",F20/E20) | H20: 7 | J20: =IF(OR(H20="",H20=0,I20=""),"",I20/H20) | K20: 6 | M20: =IF(OR(K20="",K20=0,L20=""),"",L20/K20) | O20: 第9期計画書
A21: 地域支援事業 | B21: 「食」の自立支援事業（配食サービス） | C21: 延利用人数 | D21: 人／年 | E21: 3972 | F21: 3060 | G21: =IF(OR(E21="",E21=0,F21=""),"",F21/E21) | H21: 4116 | I21: 3078 | J21: =IF(OR(H21="",H21=0,I21=""),"",I21/H21) | K21: 4260 | L21: 3078 | M21: =IF(OR(K21="",K21=0,L21=""),"",L21/K21) | N21: 計画3,972人に対し実績3,060人（令和6年度・77％） | O21: 計画書／実績データ 07シート
A22: 地域支援事業 | B22: 「食」の自立支援事業（配食サービス） | C22: 利用実人数 | D22: 人／年 | E22: 43 | F22: 48 | G22: =IF(OR(E22="",E22=0,F22=""),"",F22/E22) | H22: 38 | I22: 52 | J22: =IF(OR(H22="",H22=0,I22=""),"",I22/H22) | K22: 33 | L22: 52 | M22: =IF(OR(K22="",K22=0,L22=""),"",L22/K22) | O22: 計画書／実績データ 07シート
A23: 地域支援事業 | B23: 認知症高齢者見守りＱＲコード活用事業 | C23: 延利用人数 | D23: 人／年 | E23: 1 | F23: 0 | G23: =IF(OR(E23="",E23=0,F23=""),"",F23/E23) | H23: 1 | I23: 0 | J23: =IF(OR(H23="",H23=0,I23=""),"",I23/H23) | K23: 1 | L23: 1 | M23: =IF(OR(K23="",K23=0,L23=""),"",L23/K23) | O23: 計画書／実績データ 07シート

Sheet 06_高齢者福祉サービス
A1: サービス別 計画値・実績値 対比表 高齢者福祉サービス
A2: 計画値：第9期計画書（令和6年3月）／実績：町提供実績データ（令和8年9月1日受領・仮試算）
A4: 区分 | B4: サービス・事業名 | C4: 指標 | D4: 単位 | E4: R6計画 | F4: R6実績 | G4: 達成率 | H4: R7計画 | I4: R7実績 | J4: 達成率 | K4: R8計画 | L4: R8見込 | M4: 達成率 | N4: 乖離の要因・対応 | O4: 出典・記入担当
A5: 高齢者福祉 | B5: 移送サービス事業 | C5: 延利用人数 | D5: 人／年 | E5: 320 | F5: 1074 | G5: =IF(OR(E5="",E5=0,F5=""),"",F5/E5) | H5: 325 | I5: 1114 | J5: =IF(OR(H5="",H5=0,I5=""),"",I5/H5) | K5: 330 | L5: 1188 | M5: =IF(OR(K5="",K5=0,L5=""),"",L5/K5) | N5: 計画は「延利用人数（人）」、実績データは「延利用回数（回）」。定義の確認が必要 | O5: 計画書／実績データ 06シート
A6: 高齢者福祉 | B6: 移送サービス事業 | C6: 実利用人数 | D6: 人／年 | E6: 55 | F6: 214 | G6: =IF(OR(E6="",E6=0,F6=""),"",F6/E6) | H6: 60 | I6: 307 | J6: =IF(OR(H6="",H6=0,I6=""),"",I6/H6) | K6: 65 | L6: 264 | M6: =IF(OR(K6="",K6=0,L6=""),"",L6/K6) | O6: 計画書／実績データ 06シート
A7: 高齢者福祉 | B7: 移送サービス事業 | C7: 給付費 | D7: 千円／年 | E7: 3150 | F7: 1551 | G7: =IF(OR(E7="",E7=0,F7=""),"",F7/E7) | H7: 3200 | I7: 1612 | J7: =IF(OR(H7="",H7=0,I7=""),"",I7/H7) | K7: 3250 | L7: 2457 | M7: =IF(OR(K7="",K7=0,L7=""),"",L7/K7) | N7: 計画3,150千円に対し実績1,551千円（令和6年度・49％）。事業費の範囲の確認が必要 | O7: 計画書／実績データ 06シート
A8: 高齢者福祉 | B8: タクシー利用助成事業 | C8: 利用実人数 | D8: 人／年 | E8: 395 | G8: =IF(OR(E8="",E8=0,F8=""),"",F8/E8) | H8: 400 | J8: =IF(OR(H8="",H8=0,I8=""),"",I8/H8) | K8: 405 | M8: =IF(OR(K8="",K8=0,L8=""),"",L8/K8) | O8: 第9期計画書
A9: 高齢者福祉 | B9: 会食サービス事業 | C9: 実利用人数 | D9: 人／年 | E9: 600 | G9: =IF(OR(E9="",E9=0,F9=""),"",F9/E9) | H9: 600 | J9: =IF(OR(H9="",H9=0,I9=""),"",I9/H9) | K9: 600 | M9: =IF(OR(K9="",K9=0,L9=""),"",L9/K9) | O9: 第9期計画書
A10: 高齢者福祉 | B10: 会食サービス事業 | C10: 給付費 | D10: 千円／年 | E10: 360 | G10: =IF(OR(E10="",E10=0,F10=""),"",F10/E10) | H10: 360 | J10: =IF(OR(H10="",H10=0,I10=""),"",I10/H10) | K10: 360 | M10: =IF(OR(K10="",K10=0,L10=""),"",L10/K10) | O10: 第9期計画書
A11: 高齢者福祉 | B11: 緊急通報システム事業 | C11: 実利用人数 | D11: 人／年 | E11: 40 | F11: 393 | G11: =IF(OR(E11="",E11=0,F11=""),"",F11/E11) | H11: 45 | I11: 427 | J11: =IF(OR(H11="",H11=0,I11=""),"",I11/H11) | K11: 50 | L11: 432 | M11: =IF(OR(K11="",K11=0,L11=""),"",L11/K11) | N11: 計画40人に対し実績393人。実績は設置台数の累計の可能性。定義の確認が必要 | O11: 計画書／実績データ 07シート
A12: 高齢者福祉 | B12: 緊急通報システム事業 | C12: 設置費用 | D12: 千円／年 | E12: 7 | G12: =IF(OR(E12="",E12=0,F12=""),"",F12/E12) | H12: 10 | J12: =IF(OR(H12="",H12=0,I12=""),"",I12/H12) | K12: 13 | M12: =IF(OR(K12="",K12=0,L12=""),"",L12/K12) | O12: 第9期計画書
A13: 高齢者福祉 | B13: 老人クラブ助成事業 | C13: 老人クラブ数 | D13: 単位数 | E13: 16 | G13: =IF(OR(E13="",E13=0,F13=""),"",F13/E13) | H13: 16 | J13: =IF(OR(H13="",H13=0,I13=""),"",I13/H13) | K13: 16 | M13: =IF(OR(K13="",K13=0,L13=""),"",L13/K13) | O13: 第9期計画書
A14: 高齢者福祉 | B14: 敬老会開催事業 | C14: 対象人数 | D14: 人／年 | E14: 1770 | G14: =IF(OR(E14="",E14=0,F14=""),"",F14/E14) | H14: 1965 | J14: =IF(OR(H14="",H14=0,I14=""),"",I14/H14) | K14: 2141 | M14: =IF(OR(K14="",K14=0,L14=""),"",L14/K14) | O14: 第9期計画書
A15: 高齢者福祉 | B15: 敬老会開催事業 | C15: 開催地区数 | E15: 25 | G15: =IF(OR(E15="",E15=0,F15=""),"",F15/E15) | H15: 25 | J15: =IF(OR(H15="",H15=0,I15=""),"",I15/H15) | K15: 25 | M15: =IF(OR(K15="",K15=0,L15=""),"",L15/K15) | O15: 第9期計画書

Sheet 07_記入状況
A1: 記入状況
A2: 実績欄（F・I・L列）の記入済み件数を自動集計します。
A4: シート | B4: 行数 | C4: 計画値のある行 | D4: 実績を記入済み（当社転記分） | E4: R6実績の記入済み | F4: R7実績の記入済み | G4: R8見込の記入済み
A5: 01_居宅サービス | B5: 52 | C5: 52 | D5: 8 | E5: =COUNT('01_居宅サービス'!F5:F56) | F5: =COUNT('01_居宅サービス'!I5:I56) | G5: =COUNT('01_居宅サービス'!L5:L56)
A6: 02_地域密着型サービス | B6: 15 | C6: 10 | D6: 6 | E6: =COUNT('02_地域密着型サービス'!F5:F19) | F6: =COUNT('02_地域密着型サービス'!I5:I19) | G6: =COUNT('02_地域密着型サービス'!L5:L19)
A7: 03_施設サービス | B7: 6 | C7: 4 | D7: 4 | E7: =COUNT('03_施設サービス'!F5:F10) | F7: =COUNT('03_施設サービス'!I5:I10) | G7: =COUNT('03_施設サービス'!L5:L10)
A8: 04_総合事業・一般介護予防 | B8: 23 | C8: 23 | D8: 0 | E8: =COUNT('04_総合事業・一般介護予防'!F5:F27) | F8: =COUNT('04_総合事業・一般介護予防'!I5:I27) | G8: =COUNT('04_総合事業・一般介護予防'!L5:L27)
A9: 05_包括的支援事業・任意事業 | B9: 19 | C9: 19 | D9: 8 | E9: =COUNT('05_包括的支援事業・任意事業'!F5:F23) | F9: =COUNT('05_包括的支援事業・任意事業'!I5:I23) | G9: =COUNT('05_包括的支援事業・任意事業'!L5:L23)
A10: 06_高齢者福祉サービス | B10: 11 | C10: 11 | D10: 4 | E10: =COUNT('06_高齢者福祉サービス'!F5:F15) | F10: =COUNT('06_高齢者福祉サービス'!I5:I15) | G10: =COUNT('06_高齢者福祉サービス'!L5:L15)
A12: ※「実績を記入済み（当社転記分）」は、令和8年9月1日提供の実績データから転記できた指標の数です。
A13: ※ 空欄の実績欄は、町にご記入いただく必要があります（確認事項No.40・No.42）。
