Workbook

Sheet 00_ダッシュボード
A1: 小野町 高齢者保健福祉計画・第10期介護保険事業計画 業務進捗管理表
A2: 基準日：令和8年9月8日
A4: 全体進捗 | B4: ='02_段階サマリ'!H12 | D4: 作業数 | E4: ='02_段階サマリ'!B12 | G4: 完了 | H4: ='02_段階サマリ'!C12
A6: 段階 | B6: 作業数 | C6: 加重進捗率 | D6: 律速要因
A7: ='02_段階サマリ'!A2 | B7: ='02_段階サマリ'!B2 | C7: ='02_段階サマリ'!H2 | D7: ='02_段階サマリ'!K2
A8: ='02_段階サマリ'!A3 | B8: ='02_段階サマリ'!B3 | C8: ='02_段階サマリ'!H3 | D8: ='02_段階サマリ'!K3
A9: ='02_段階サマリ'!A4 | B9: ='02_段階サマリ'!B4 | C9: ='02_段階サマリ'!H4 | D9: ='02_段階サマリ'!K4
A10: ='02_段階サマリ'!A5 | B10: ='02_段階サマリ'!B5 | C10: ='02_段階サマリ'!H5 | D10: ='02_段階サマリ'!K5
A11: ='02_段階サマリ'!A6 | B11: ='02_段階サマリ'!B6 | C11: ='02_段階サマリ'!H6 | D11: ='02_段階サマリ'!K6
A12: ='02_段階サマリ'!A7 | B12: ='02_段階サマリ'!B7 | C12: ='02_段階サマリ'!H7 | D12: ='02_段階サマリ'!K7
A13: ='02_段階サマリ'!A8 | B13: ='02_段階サマリ'!B8 | C13: ='02_段階サマリ'!H8 | D13: ='02_段階サマリ'!K8
A14: ='02_段階サマリ'!A9 | B14: ='02_段階サマリ'!B9 | C14: ='02_段階サマリ'!H9 | D14: ='02_段階サマリ'!K9
A15: ='02_段階サマリ'!A10 | B15: ='02_段階サマリ'!B10 | C15: ='02_段階サマリ'!H10 | D15: ='02_段階サマリ'!K10
A16: ='02_段階サマリ'!A11 | B16: ='02_段階サマリ'!B11 | C16: ='02_段階サマリ'!H11 | D16: ='02_段階サマリ'!K11
A18: ■ 仕様書の業務ブロック別
A19: 仕様書ブロック | B19: 作業数 | C19: 加重進捗率 | D19: 現況・律速
A20: ='10_ブロック別進捗'!A2 | B20: ='10_ブロック別進捗'!C2 | C20: ='10_ブロック別進捗'!I2 | D20: ='10_ブロック別進捗'!J2
A21: ='10_ブロック別進捗'!A3 | B21: ='10_ブロック別進捗'!C3 | C21: ='10_ブロック別進捗'!I3 | D21: ='10_ブロック別進捗'!J3
A22: ='10_ブロック別進捗'!A4 | B22: ='10_ブロック別進捗'!C4 | C22: ='10_ブロック別進捗'!I4 | D22: ='10_ブロック別進捗'!J4
A23: ='10_ブロック別進捗'!A5 | B23: ='10_ブロック別進捗'!C5 | C23: ='10_ブロック別進捗'!I5 | D23: ='10_ブロック別進捗'!J5
A24: ='10_ブロック別進捗'!A6 | B24: ='10_ブロック別進捗'!C6 | C24: ='10_ブロック別進捗'!I6 | D24: ='10_ブロック別進捗'!J6
A25: ='10_ブロック別進捗'!A7 | B25: ='10_ブロック別進捗'!C7 | C25: ='10_ブロック別進捗'!I7 | D25: ='10_ブロック別進捗'!J7
A26: ='10_ブロック別進捗'!A8 | B26: ='10_ブロック別進捗'!C8 | C26: ='10_ブロック別進捗'!I8 | D26: ='10_ブロック別進捗'!J8
A27: ='10_ブロック別進捗'!A9 | B27: ='10_ブロック別進捗'!C9 | C27: ='10_ブロック別進捗'!I9 | D27: ='10_ブロック別進捗'!J9
A28: ='10_ブロック別進捗'!A10 | B28: ='10_ブロック別進捗'!C10 | C28: ='10_ブロック別進捗'!I10 | D28: ='10_ブロック別進捗'!J10
A29: ='10_ブロック別進捗'!A11 | B29: ='10_ブロック別進捗'!C11 | C29: ='10_ブロック別進捗'!I11 | D29: ='10_ブロック別進捗'!J11
A30: ='10_ブロック別進捗'!A12 | B30: ='10_ブロック別進捗'!C12 | C30: ='10_ブロック別進捗'!I12 | D30: ='10_ブロック別進捗'!J12
A32: ■ 現況
A33: 見える化システムによる分析は12分野135ファイルを取り込み、実質的に完了した。認定者数は平成19年3月末〜令和8年3月末の20期分を、要介護度別・年齢階層別・被保険者区分別で確定させた。
A34: 成果品6件のうち3件（①第5版・③第3版・④第2版）が初稿段階に達し、②は算定シートの構築まで進んだ。
A35: **令和8年9月8日、町から介護保険事業状況報告（年報）令和3〜7年度（各47様式）、国保連合会業務統計表（月報）28か月分、第10期将来推計用推計人口を受領した。**これにより依頼35項目の主要部分が一括で解決し、見込量推計・保険料算定に着手できる状態になった。
A36: **最大の律速だった令和8年3月末の認定者数792人は、介護保険事業状況報告（年報）様式1の5で裏付けられた（第1号783＋第2号9）。**さらに国保連月報28か月により、減少が令和7年9月審査分の1か月に集中していること（961人→862人・▲10.3％）と、**同じ月に給付件数がまったく減っていないこと（1,303件→1,365件）**が判明した。減少は要介護2以上に集中し、要支援1はむしろ増えている。死亡171人は平年並みである。
A37: **認定者だけが落ちて給付が落ちていないため、実態の変化ではなく計上の変更とみるのが最も整合的である。**年度でみても、令和7年度は認定者▲16.1％に対し受給者延▲4.6％・給付費▲7.4％で、認定者の減り方は給付の減り方の2倍以上ある。**したがって見込量は認定者数ベースではなく、受給者数と給付費の実績を基礎に組む。**
A38: **あわせて、介護給付費準備基金の保有額が12.0百万円しかないことが判明した。**第9期は基金取崩35.0百万円を見込んでいた。歳入歳出差引残額は144.2百万円あるため、繰越金として滞留している。令和4年度末の基金は120.0百万円で、令和5年度末に1桁減っており、確認を要する。
A39: 令和7年度調査の結果は集計結果・分析報告書として取りまとめ、素案第2版に反映した。**在宅の要介護認定者の42.1％がサービスを利用しておらず、その理由の92.9％が需要側の要因で、供給制約は0.6％であった。**これにより第10期の施策方向を、供給確保から認定運用の確認・利用意向への働きかけ・レスパイトへ組み替えた。
A40: 算定シートには受領した実績を投入した。人口推計（令和9〜11年）、令和7年度の年齢階層別認定率（65〜74歳3.92％／75〜84歳18.72％／85歳以上71.63％）、所得段階別被保険者数13段階と小野町が定める保険料率、収納率99.35％を入力済みで、**残る入力欄はサービス別の見込量、地域支援事業費、調整交付金見込額、基金取崩額である。**
A42: ■ 警戒事項
A43: # | B43: 内容 | C43: 影響 | D43: 対応
A44: 1 | B44: 認定者数の減少は計上の変更の可能性が高い | C44: 認定者数ベースで給付費を推計すると過小になる（令和7年度は認定者▲16.1％に対し給付費▲7.4％） | D44: **令和7年9月審査分の1か月に▲99人が集中し、同月の給付件数は減っていない。令和7年8〜9月の計上方法の変更を町に確認する。見込量は受給者数・給付費の実績を基礎に組む**
A45: 2 | B45: 介護給付費準備基金の保有額が12.0百万円しかない | C45: 第9期が見込んだ基金取崩35.0百万円は実行できない。保険料水準の判断に直結する | D45: **令和4年度末120.0百万円から令和5年度末12.0百万円へ1桁減っている。取崩実績か入力誤りかを町に確認する。繰越金144.2百万円の基金積立も選択肢**
...

Sheet 01_WBS
A1: 段階 | B1: No | C1: 作業 | D1: 内容 | E1: 仕様書ブロック | F1: 仕様書 条項 | G1: 仕様書の記載内容（原文） | H1: 担当 | I1: 予定開始 | J1: 予定完了 | K1: 状態 | L1: 進捗率 | M1: 重み | N1: 実績・根拠 | O1: 前提条件・ブロッカー
A2: P1 準備・現状把握 | B2: 1-1 | C2: 契約・体制の確立、キックオフ | D2: 実施体制、役割分担、連絡系統 | E2: B10 業務管理・計画の基本的な考え方 | F2: 公告10⑥（技術者の配置） | G2: 【公告10⑥】研究員は「見える化」システムやニーズ調査など各種データから介護給付費の統計分析により将来のサービス量を推計し計画化できる者（公告第1-19号 10⑥） | H2: 受託者 | I2: 2026-06 | J2: 2026-07 | K2: 完了 | L2: 100 | M2: 2 | N2: キックオフ資料・業務計画書（02_キックオフ・業務計画） | O2: ―
A3: P1 準備・現状把握 | B3: 1-2 | C3: 引継ぎ資料の整理 | D3: 前受託者からの引継ぎ資料の棚卸しと索引化 | E3: B10 業務管理・計画の基本的な考え方 | F3: 仕様書全般 | G3: 【全般】委託仕様書及び公告の全体（成果品要件・工程・作業分担の確認） | H3: 受託者 | I3: 2026-07 | J3: 2026-07 | K3: 完了 | L3: 100 | M3: 2 | N3: manifest_全ファイル（207ファイル） | O3: ―
A4: P1 準備・現状把握 | B4: 1-3 | C4: 委託仕様書の確認と適合性チェック | D4: 原典4件（公告・仕様書×2計画）を読み、成果品要件・工程・作業分担を確定 | E4: B10 業務管理・計画の基本的な考え方 | F4: 仕様書全般 | G4: 【全般】委託仕様書及び公告の全体（成果品要件・工程・作業分担の確認） | H4: 受託者 | I4: 2026-08 | J4: 2026-08 | K4: 完了 | L4: 100 | M4: 3 | N4: 仕様書適合性チェック 第2版（00_引継ぎ）。初版8/3、第2版8/13 | O4: ―
A5: P1 準備・現状把握 | B5: 1-4 | C5: 第9期計画本文の確認 | D5: 5章構成・基本理念・3基本目標・14施策、標準給付費3,566,486千円、保険料6,600円の算定根拠 | E5: B1 現状分析（基礎データ・資料の整理分析） | F5: 仕様書4(1) | G5: 【4(1)】基礎的な地域データ及び資料の整理分析（現状分析）。高齢者福祉・介護保険をめぐる施策の動向、小野町の概要及び社会経済的特性、地域福祉資源の整備状況、高齢者の現況動向及びサービスの利用状況等について、小野町が提供するデータをもとに整理分析を行う。（計画策定の検討資料として活用するため、各種事項の将来推計を行う。なお、推計にあたっては、可能な限り細分化する） | H5: 受託者 | I5: 2026-08 | J5: 2026-08 | K5: 完了 | L5: 100 | M5: 3 | N5: 第9期計画本文（13_関連計画）。骨子案第3版・成果品①第5版に反映 | O5: ―
A6: P1 準備・現状把握 | B6: 1-5 | C6: 第3期地域福祉計画との役割分担の整理 | D6: 重複5施策を特定。成年後見は移管、虐待防止・災害対応・支え合いは連携 | E6: B10 業務管理・計画の基本的な考え方 | F6: 仕様書2(2) | G6: 【2(2)】国が示す第10期計画に関する基本的な考え方を踏まえた上で、本町の特性を活かした計画とする。 | H6: 受託者 | I6: 2026-08 | J6: 2026-08 | K6: 完了 | L6: 100 | M6: 2 | N6: 地域福祉計画との整合確認メモ（03_計画素案） | O6: ―
A7: P1 準備・現状把握 | B7: 1-6 | C7: 町への資料依頼票の作成 | D7: 依頼35項目＋確認事項12件。基準日・年度範囲・単位・様式まで指定 | E7: B10 業務管理・計画の基本的な考え方 | F7: 仕様書5(1)（資料は町が貸与） | G7: 【5(1)】本業務の実施に必要な資料等は、小野町が受託者に貸与するものとする。 | H7: 受託者 | I7: 2026-08 | J7: 2026-08 | K7: 完了 | L7: 100 | M7: 2 | N7: 小野町_データ依頼票（16_町データ依頼） | O7: ―
A8: P1 準備・現状把握 | B8: 1-7 | C8: 町データの受領 | D8: 依頼票に基づく資料・データの受領 | E8: B10 業務管理・計画の基本的な考え方 | F8: 仕様書5(1) | G8: 【5(1)】本業務の実施に必要な資料等は、小野町が受託者に貸与するものとする。 | H8: 町 | I8: 2026-08 | J8: 2026-09 | K8: 進行中 | L8: 70 | M8: 4 | N8: **9月8日に介護保険事業状況報告（年報）令和3〜7年度（各47様式）、国保連合会業務統計表（月報）28か月分、第10期将来推計用推計人口を受領。**依頼票のN1・S1〜S5が解決し、S7は令和6年度分のみ解決 | O8: 残るのは地域支援事業費の内訳（S6）、令和7年度決算（S7）、成果指標の現状値17項目（H1〜H17）
A9: P1 準備・現状把握 | B9: 1-8 | C9: 工程・協議会日程の合意と確認事項の照会 | D9: 高齢者計画の仕様書には工程表がないため、業務期間から逆算した工程と協議会の回数・時期を町と合意する。あわせて仕様書の疑義4件を照会する | E9: B10 業務管理・計画の基本的な考え方 | F9: 仕様書5(3) | G9: 【5(3)】本仕様書に定めのない事項及び疑義が生じた場合は、小野町と受託者で協議するものとする。 | H9: 受託者・町 | I9: 2026-08 | J9: 2026-09 | K9: 要対応 | L9: 30 | M9: 2 | N9: **工程変更協議資料と確認事項12件を作成済み（うち高齢者に係るもの8件）** | O9: **町との協議。協議会の回数が決まらないとP6・P8・P9・P10の日程が引けない**
A10: P2 統計分析 | B10: 2-1 | C10: 人口・世帯の分析 | D10: 総人口、高齢化率、前期・後期高齢者、世帯。令和32年まで推計 | E10: B2 統計分析 | F10: 仕様書4(1)①ア | G10: 【4(1)①ア】統計分析（ア）人口 | H10: 受託者 | I10: 2026-07 | J10: 2026-07 | K10: 完了 | L10: 100 | M10: 3 | N10: 基礎数値整理ブック（A系13ファイル） | O10: ―
A11: P2 統計分析 | B11: 2-2 | C11: 第1号被保険者の分析 | D11: 被保険者数の推移と推計 | E11: B2 統計分析 | F11: 仕様書4(1)①ア | G11: 【4(1)①ア】統計分析（ア）人口 | H11: 受託者 | I11: 2026-07 | J11: 2026-07 | K11: 完了 | L11: 100 | M11: 1 | N11: B系4ファイル | O11: ―
A12: P2 統計分析 | B12: 2-3 | C12: 認定者数・認定率の分析 | D12: 平成19年3月末〜令和8年3月末の20期。要介護度別7区分・年齢階層別・被保険者区分別 | E12: B2 統計分析 | F12: 仕様書4(1)①イ | G12: 【4(1)①イ】統計分析（イ）要支援者数、要介護認定者数、認知症高齢者数 | H12: 受託者 | I12: 2026-08 | J12: 2026-08 | K12: 完了 | L12: 100 | M12: 4 | N12: 要支援要介護認定者数の整理（07_見える化整理・10シート）。第1号＋第2号＝全体を20期で検算済み | O12: ―
A13: P2 統計分析 | B13: 2-4 | C13: 認定者数の異常値の検証 | D13: 令和8年3月末の▲152人（▲16.1％）の要因分析。県内59市町村との比較 | E13: B2 統計分析 | F13: 仕様書4(1)①イ | G13: 【4(1)①イ】統計分析（イ）要支援者数、要介護認定者数、認知症高齢者数 | H13: 受託者・町 | I13: 2026-08 | J13: 2026-10 | K13: 進行中 | L13: 85 | M13: 5 | N13: **792人は介護保険事業状況報告（年報）様式1の5で裏付けられた（第1号783＋第2号9）。**国保連月報28か月で、減少が令和7年9月審査分の1か月に集中していること（961→862人）と、同じ月に給付件数が減っていないこと（1,303→1,365件）を確認。減少は要介護2以上に集中し、要支援1は増えている。死亡171人は平年並み | O13: **「令和7年8〜9月に計上方法の変更がなかったか」に論点が絞られた。町外施設入所者の帰属、住所地特例、国保連の集計定義のいずれか**
... A64: P10 完成・納品 | B64: 10-8 | C64: 納品・検収 | D64: 令和9年3月31日まで | E64: B10 業務管理・計画の基本的な考え方 | F64: 仕様書3（業務期間） | G64: 【3】契約締結の日から令和9年3月31日まで | H64: 受託者・町 | I64: 2027-03 | J64: 2027-03 | K64: 未着手 | L64: 0 | M64: 1 | N64: ― | O64: 全成果品の完成

Sheet 02_段階サマリ
A1: 段階 | B1: 作業数 | C1: 完了 | D1: 進行中 | E1: 要対応 | F1: データ待ち | G1: 未着手 | H1: 加重進捗率 | I1: 予定開始 | J1: 予定完了 | K1: 律速要因
A2: P1 準備・現状把握 | B2: =COUNTIF('01_WBS'!$A$2:$A$64,$A2) | C2: =COUNTIFS('01_WBS'!$A$2:$A$64,$A2,'01_WBS'!$K$2:$K$64,"完了") | D2: =COUNTIFS('01_WBS'!$A$2:$A$64,$A2,'01_WBS'!$K$2:$K$64,"進行中") | E2: =COUNTIFS('01_WBS'!$A$2:$A$64,$A2,'01_WBS'!$K$2:$K$64,"要対応") | F2: =COUNTIFS('01_WBS'!$A$2:$A$64,$A2,'01_WBS'!$K$2:$K$64,"データ待ち") | G2: =COUNTIFS('01_WBS'!$A$2:$A$64,$A2,'01_WBS'!$K$2:$K$64,"未着手") | H2: =IF(SUMPRODUCT(('01_WBS'!$A$2:$A$64=$A2)*'01_WBS'!$M$2:$M$64)=0,0,SUMPRODUCT(('01_WBS'!$A$2:$A$64=$A2)*'01_WBS'!$L$2:$L$64*'01_WBS'!$M$2:$M$64)/SUMPRODUCT(('01_WBS'!$A$2:$A$64=$A2)*'01_WBS'!$M$2:$M$64)/100) | I2: 2026-06 | J2: 2026-09 | K2: 町データの受領（依頼35件・受領0件）
A3: P2 統計分析 | B3: =COUNTIF('01_WBS'!$A$2:$A$64,$A3) | C3: =COUNTIFS('01_WBS'!$A$2:$A$64,$A3,'01_WBS'!$K$2:$K$64,"完了") | D3: =COUNTIFS('01_WBS'!$A$2:$A$64,$A3,'01_WBS'!$K$2:$K$64,"進行中") | E3: =COUNTIFS('01_WBS'!$A$2:$A$64,$A3,'01_WBS'!$K$2:$K$64,"要対応") | F3: =COUNTIFS('01_WBS'!$A$2:$A$64,$A3,'01_WBS'!$K$2:$K$64,"データ待ち") | G3: =COUNTIFS('01_WBS'!$A$2:$A$64,$A3,'01_WBS'!$K$2:$K$64,"未着手") | H3: =IF(SUMPRODUCT(('01_WBS'!$A$2:$A$64=$A3)*'01_WBS'!$M$2:$M$64)=0,0,SUMPRODUCT(('01_WBS'!$A$2:$A$64=$A3)*'01_WBS'!$L$2:$L$64*'01_WBS'!$M$2:$M$64)/SUMPRODUCT(('01_WBS'!$A$2:$A$64=$A3)*'01_WBS'!$M$2:$M$64)/100) | I3: 2026-07 | J3: 2026-10 | K3: **令和8年3月末の認定者数の確認。本業務の最大の律速**
A4: P3 給付費等の分析 | B4: =COUNTIF('01_WBS'!$A$2:$A$64,$A4) | C4: =COUNTIFS('01_WBS'!$A$2:$A$64,$A4,'01_WBS'!$K$2:$K$64,"完了") | D4: =COUNTIFS('01_WBS'!$A$2:$A$64,$A4,'01_WBS'!$K$2:$K$64,"進行中") | E4: =COUNTIFS('01_WBS'!$A$2:$A$64,$A4,'01_WBS'!$K$2:$K$64,"要対応") | F4: =COUNTIFS('01_WBS'!$A$2:$A$64,$A4,'01_WBS'!$K$2:$K$64,"データ待ち") | G4: =COUNTIFS('01_WBS'!$A$2:$A$64,$A4,'01_WBS'!$K$2:$K$64,"未着手") | H4: =IF(SUMPRODUCT(('01_WBS'!$A$2:$A$64=$A4)*'01_WBS'!$M$2:$M$64)=0,0,SUMPRODUCT(('01_WBS'!$A$2:$A$64=$A4)*'01_WBS'!$L$2:$L$64*'01_WBS'!$M$2:$M$64)/SUMPRODUCT(('01_WBS'!$A$2:$A$64=$A4)*'01_WBS'!$M$2:$M$64)/100) | I4: 2026-07 | J4: 2027-03 | K4: 町の給付実績（令和3〜7年度）
A5: P4 調査結果の反映 | B5: =COUNTIF('01_WBS'!$A$2:$A$64,$A5) | C5: =COUNTIFS('01_WBS'!$A$2:$A$64,$A5,'01_WBS'!$K$2:$K$64,"完了") | D5: =COUNTIFS('01_WBS'!$A$2:$A$64,$A5,'01_WBS'!$K$2:$K$64,"進行中") | E5: =COUNTIFS('01_WBS'!$A$2:$A$64,$A5,'01_WBS'!$K$2:$K$64,"要対応") | F5: =COUNTIFS('01_WBS'!$A$2:$A$64,$A5,'01_WBS'!$K$2:$K$64,"データ待ち") | G5: =COUNTIFS('01_WBS'!$A$2:$A$64,$A5,'01_WBS'!$K$2:$K$64,"未着手") | H5: =IF(SUMPRODUCT(('01_WBS'!$A$2:$A$64=$A5)*'01_WBS'!$M$2:$M$64)=0,0,SUMPRODUCT(('01_WBS'!$A$2:$A$64=$A5)*'01_WBS'!$L$2:$L$64*'01_WBS'!$M$2:$M$64)/SUMPRODUCT(('01_WBS'!$A$2:$A$64=$A5)*'01_WBS'!$M$2:$M$64)/100) | I5: 2026-08 | J5: 2026-10 | K5: 令和7年度調査の個票データ（クロス集計17件）
A6: P5 第9期の評価 | B6: =COUNTIF('01_WBS'!$A$2:$A$64,$A6) | C6: =COUNTIFS('01_WBS'!$A$2:$A$64,$A6,'01_WBS'!$K$2:$K$64,"完了") | D6: =COUNTIFS('01_WBS'!$A$2:$A$64,$A6,'01_WBS'!$K$2:$K$64,"進行中") | E6: =COUNTIFS('01_WBS'!$A$2:$A$64,$A6,'01_WBS'!$K$2:$K$64,"要対応") | F6: =COUNTIFS('01_WBS'!$A$2:$A$64,$A6,'01_WBS'!$K$2:$K$64,"データ待ち") | G6: =COUNTIFS('01_WBS'!$A$2:$A$64,$A6,'01_WBS'!$K$2:$K$64,"未着手") | H6: =IF(SUMPRODUCT(('01_WBS'!$A$2:$A$64=$A6)*'01_WBS'!$M$2:$M$64)=0,0,SUMPRODUCT(('01_WBS'!$A$2:$A$64=$A6)*'01_WBS'!$L$2:$L$64*'01_WBS'!$M$2:$M$64)/SUMPRODUCT(('01_WBS'!$A$2:$A$64=$A6)*'01_WBS'!$M$2:$M$64)/100) | I6: 2026-08 | J6: 2026-10 | K6: 町の事業実績。とくに総合事業・通いの場
A7: P6 骨子案 | B7: =COUNTIF('01_WBS'!$A$2:$A$64,$A7) | C7: =COUNTIFS('01_WBS'!$A$2:$A$64,$A7,'01_WBS'!$K$2:$K$64,"完了") | D7: =COUNTIFS('01_WBS'!$A$2:$A$64,$A7,'01_WBS'!$K$2:$K$64,"進行中") | E7: =COUNTIFS('01_WBS'!$A$2:$A$64,$A7,'01_WBS'!$K$2:$K$64,"要対応") | F7: =COUNTIFS('01_WBS'!$A$2:$A$64,$A7,'01_WBS'!$K$2:$K$64,"データ待ち") | G7: =COUNTIFS('01_WBS'!$A$2:$A$64,$A7,'01_WBS'!$K$2:$K$64,"未着手") | H7: =IF(SUMPRODUCT(('01_WBS'!$A$2:$A$64=$A7)*'01_WBS'!$M$2:$M$64)=0,0,SUMPRODUCT(('01_WBS'!$A$2:$A$64=$A7)*'01_WBS'!$L$2:$L$64*'01_WBS'!$M$2:$M$64)/SUMPRODUCT(('01_WBS'!$A$2:$A$64=$A7)*'01_WBS'!$M$2:$M$64)/100) | I7: 2026-07 | J7: 2027-03 | K7: 協議会の開催回数・時期が未定
A8: P7 推計・算定 | B8: =COUNTIF('01_WBS'!$A$2:$A$64,$A8) | C8: =COUNTIFS('01_WBS'!$A$2:$A$64,$A8,'01_WBS'!$K$2:$K$64,"完了") | D8: =COUNTIFS('01_WBS'!$A$2:$A$64,$A8,'01_WBS'!$K$2:$K$64,"進行中") | E8: =COUNTIFS('01_WBS'!$A$2:$A$64,$A8,'01_WBS'!$K$2:$K$64,"要対応") | F8: =COUNTIFS('01_WBS'!$A$2:$A$64,$A8,'01_WBS'!$K$2:$K$64,"データ待ち") | G8: =COUNTIFS('01_WBS'!$A$2:$A$64,$A8,'01_WBS'!$K$2:$K$64,"未着手") | H8: =IF(SUMPRODUCT(('01_WBS'!$A$2:$A$64=$A8)*'01_WBS'!$M$2:$M$64)=0,0,SUMPRODUCT(('01_WBS'!$A$2:$A$64=$A8)*'01_WBS'!$L$2:$L$64*'01_WBS'!$M$2:$M$64)/SUMPRODUCT(('01_WBS'!$A$2:$A$64=$A8)*'01_WBS'!$M$2:$M$64)/100) | I8: 2026-08 | J8: 2027-03 | K8: **認定者数の確定。算式は実装済みで、値が入れば通る**
A9: P8 素案 | B9: =COUNTIF('01_WBS'!$A$2:$A$64,$A9) | C9: =COUNTIFS('01_WBS'!$A$2:$A$64,$A9,'01_WBS'!$K$2:$K$64,"完了") | D9: =COUNTIFS('01_WBS'!$A$2:$A$64,$A9,'01_WBS'!$K$2:$K$64,"進行中") | E9: =COUNTIFS('01_WBS'!$A$2:$A$64,$A9,'01_WBS'!$K$2:$K$64,"要対応") | F9: =COUNTIFS('01_WBS'!$A$2:$A$64,$A9,'01_WBS'!$K$2:$K$64,"データ待ち") | G9: =COUNTIFS('01_WBS'!$A$2:$A$64,$A9,'01_WBS'!$K$2:$K$64,"未着手") | H9: =IF(SUMPRODUCT(('01_WBS'!$A$2:$A$64=$A9)*'01_WBS'!$M$2:$M$64)=0,0,SUMPRODUCT(('01_WBS'!$A$2:$A$64=$A9)*'01_WBS'!$L$2:$L$64*'01_WBS'!$M$2:$M$64)/SUMPRODUCT(('01_WBS'!$A$2:$A$64=$A9)*'01_WBS'!$M$2:$M$64)/100) | I9: 2026-08 | J9: 2027-03 | K9: P7の完了と成果指標の現状値
A10: P9 意見聴取 | B10: =COUNTIF('01_WBS'!$A$2:$A$64,$A10) | C10: =COUNTIFS('01_WBS'!$A$2:$A$64,$A10,'01_WBS'!$K$2:$K$64,"完了") | D10: =COUNTIFS('01_WBS'!$A$2:$A$64,$A10,'01_WBS'!$K$2:$K$64,"進行中") | E10: =COUNTIFS('01_WBS'!$A$2:$A$64,$A10,'01_WBS'!$K$2:$K$64,"要対応") | F10: =COUNTIFS('01_WBS'!$A$2:$A$64,$A10,'01_WBS'!$K$2:$K$64,"データ待ち") | G10: =COUNTIFS('01_WBS'!$A$2:$A$64,$A10,'01_WBS'!$K$2:$K$64,"未着手") | H10: =IF(SUMPRODUCT(('01_WBS'!$A$2:$A$64=$A10)*'01_WBS'!$M$2:$M$64)=0,0,SUMPRODUCT(('01_WBS'!$A$2:$A$64=$A10)*'01_WBS'!$L$2:$L$64*'01_WBS'!$M$2:$M$64)/SUMPRODUCT(('01_WBS'!$A$2:$A$64=$A10)*'01_WBS'!$M$2:$M$64)/100) | I10: 2026-08 | J10: 2027-02 | K10: **協議会の開催回数・時期が未定。工程が引けない**
A11: P10 完成・納品 | B11: =COUNTIF('01_WBS'!$A$2:$A$64,$A11) | C11: =COUNTIFS('01_WBS'!$A$2:$A$64,$A11,'01_WBS'!$K$2:$K$64,"完了") | D11: =COUNTIFS('01_WBS'!$A$2:$A$64,$A11,'01_WBS'!$K$2:$K$64,"進行中") | E11: =COUNTIFS('01_WBS'!$A$2:$A$64,$A11,'01_WBS'!$K$2:$K$64,"要対応") | F11: =COUNTIFS('01_WBS'!$A$2:$A$64,$A11,'01_WBS'!$K$2:$K$64,"データ待ち") | G11: =COUNTIFS('01_WBS'!$A$2:$A$64,$A11,'01_WBS'!$K$2:$K$64,"未着手") | H11: =IF(SUMPRODUCT(('01_WBS'!$A$2:$A$64=$A11)*'01_WBS'!$M$2:$M$64)=0,0,SUMPRODUCT(('01_WBS'!$A$2:$A$64=$A11)*'01_WBS'!$L$2:$L$64*'01_WBS'!$M$2:$M$64)/SUMPRODUCT(('01_WBS'!$A$2:$A$64=$A11)*'01_WBS'!$M$2:$M$64)/100) | I11: 2026-08 | J11: 2027-03 | K11: 令和9年2月下旬の校了が動かせない期限
A12: 合計 | B12: =SUM(B2:B11) | C12: =SUM(C2:C11) | D12: =SUM(D2:D11) | E12: =SUM(E2:E11) | F12: =SUM(F2:F11) | G12: =SUM(G2:G11) | H12: =IF(SUM('01_WBS'!$M$2:$M$64)=0,0,SUMPRODUCT('01_WBS'!$L$2:$L$64,'01_WBS'!$M$2:$M$64)/SUM('01_WBS'!$M$2:$M$64)/100) | I12: 2026-06 | J12: 2027-03
A14: ※ 加重進捗率＝Σ（進捗率×重み）÷Σ重み。重みは工数の目安（1〜5）。
A15: ※ 各作業が仕様書のどの条項にあたるかは 01_WBS のE列・F列、条項の網羅状況は 09_仕様書対応表 を参照。
A16: ※ 01_WBS の「状態」「進捗率」を書き換えると、本表とダッシュボードが再計算されます。

Sheet 03_成果品管理
A1: 成果品 | B1: 名称 | C1: 納品仕様 | D1: 版 | E1: 状態 | F1: 進捗率 | G1: 現状 | H1: 確定に必要なもの
A2: ① | B2: 介護保険給付費等分析結果報告書 | C2: データCD-R1部＋冊子（簡易製本）3部 | D2: 第5版 | E2: 進行中 | F2: 70 | G2: 8章・44表・約29,500字 | H2: 町の給付実績、認定者数の確定
A3: ② | B3: サービス見込量推計結果報告書 | C3: データCD-R1部＋冊子（簡易製本）3部 | D3: ― | E3: 進行中 | F3: 20 | G3: 算定シート（11シート・算式実装済み）を構築。報告書本体は未着手 | H3: 認定者数の確定、見える化への入力
A4: ③ | B4: 第10期計画 骨子案 | C4: データCD-R1部＋冊子（簡易製本）3部 | D4: 第3版 | E4: 進行中 | F4: 80 | G4: 13表・9,241字。第9期の5章構成・3基本目標・14施策を反映 | H4: 協議会での合意
A5: ④ | B5: 第10期計画 素案 | C5: データCD-R1部＋冊子（簡易製本）3部 | D5: 第2版 | E5: 進行中 | F5: 65 | G5: 5章＋資料編・67表・約32,000字。未確定156箇所を5区分で明示 | H5: 見込量・保険料、成果指標の現状値、協議会での合意
A6: ⑤ | B6: 第10期計画 | C6: データCD-R1部、印刷50部（A4・4色刷り・80頁程度） | D6: ― | E6: 未着手 | F6: 0 | G6: ― | H6: 素案の確定、パブコメ、印刷工程
A7: ⑥ | B7: 第10期計画 概要版 | C7: データCD-R1部、印刷50部（A4・4色刷り・8頁） | D7: ― | E7: 未着手 | F7: 5 | G7: 構成案（8頁のページ割り）は作成済み | H7: 計画書の確定
A8: ※ 進捗率は目安。納品仕様（製本・印刷）を満たして初めて完了となる。

Sheet 04_工程表
A1: 時期 | B1: 作業 | C1: 担当 | D1: 状態 | E1: 備考
A2: 2026-08 | B2: 町データの照会（依頼票の送付） | C2: 受託者 | D2: 要対応 | E2: **認定者数の確認を含む。最優先**
A3: 2026-08〜09 | B3: 協議会 第1回（第9期の評価・調査結果） | C3: 受託者・町 | D3: 要対応 | E3: 資料は作成済み。**開催日が未定**
A4: 2026-09 | B4: 見える化 優先度C分野の出力 | C4: 受託者 | D4: 未着手 | E4: ―
A5: 2026-10 | B5: 認定者数の確定、見込量の推計、見える化への入力 | C5: 受託者 | D5: 未着手 | E5: **本業務の最大の節目**
A6: 2026-11 | B6: 保険料のケース別算定、協議会 第2回（骨子案・見込量・保険料・成果指標） | C6: 受託者・町 | D6: 未着手 | E6: ―
A7: 2026-12 | B7: 素案の確定、協議会 第3回（素案） | C7: 受託者・町 | D7: 未着手 | E7: ―
A8: 2027-01 | B8: パブリックコメント（1か月） | C8: 町 | D8: 未着手 | E8: ―
A9: 2027-02 | B9: 意見への対応、協議会 第4回（最終案）、**計画書の校了・下版** | C9: 受託者・町 | D9: 未着手 | E9: **2月下旬の校了が動かせない期限**
A10: 2027-03 | B10: 印刷・製本、概要版の作成、納品 | C10: 受託者 | D10: 未着手 | E10: 計画書50部・概要版50部・簡易製本各3部

Sheet 05_資料・データ受領
A1: No | B1: 資料・データ | C1: 提供元 | D1: 状態 | E1: 受領日 | F1: 使途・備考
A2: 町資料 | B2: **介護保険事業状況報告（年報）令和3〜7年度（各47様式）** | C2: 町 | D2: 完了 | E2: 2026-09-08 | F2: **認定者数（様式1の5）・被保険者数（様式1）・受給者数（様式1の6）・サービス別給付費（様式2）・保険料収納状況（様式3）・所得段階別被保険者数・経理状況（様式4）。依頼票N1・S1〜S5を一括で解決した**
A3: 町資料 | B3: **保険者別 国保連合会業務統計表（月報）令和6年5月〜令和8年8月送付分** | C3: 町 | D3: 完了 | E3: 2026-09-08 | F3: **28か月分の月次認定者数と給付件数。令和7年9月審査分の▲99人の断層を特定した**
A4: 町資料 | B4: **第10期将来推計用推計人口（男女別・5歳階級別・令和2〜32年）** | C4: 町 | D4: 完了 | E4: 2026-09-08 | F4: コーホート変化率法。令和9年8,591人→令和11年8,232人。**障がい福祉計画が用いている人口（令和9年8,287人）と300人以上異なり、統一が必要**
A5: 見える化 | B5: 人口・世帯（A系13）／第1号被保険者（B系4）／地域分析（B・D・δ系53） | C5: 見える化システム | D5: 完了 | E5: 2026-07 | F5: 基礎数値・地域分析ブックに取込
A6: 見える化 | B6: 認定者数 年度末基準（B3a〜B3e／5系列） | C6: 見える化システム | D6: 完了 | E6: 2026-08-05 | F6: **平成19年3月末〜令和8年3月末の20期。第1号＋第2号＝全体を検算済み**
A7: 見える化 | B7: 介護保険特別会計経理状況（D47・D48系25） | C7: 見える化システム | D7: 完了 | E7: 2026-08-04 | F7: 財政整理ブックに取込。H26〜R5
A8: 見える化 | B8: 入所定員（D25〜D30）／介護予防・総合事業（F系27）／認知症施策（J16〜18） | C8: 見える化システム | D8: 完了 | E8: 2026-08-04 | F8: 通いの場はR2まで、総合事業はR1・R2のみ
A9: 見える化 | B9: サービス自給率（δ2・δ3系12）／給付分析（D17・D1〜D6・B1・B4-a／29） | C9: 見える化システム | D9: 完了 | E9: 2026-08-04 | F9: 県内59市町村の比較値つき
A10: 見える化 | B10: 在宅医療・介護連携、医療提供体制、リハビリ提供体制、交付金評価指標 | C10: 見える化システム | D10: 未着手 | E10: ― | F10: 優先度C。システムへのアクセスが必要
A11: 町資料 | B11: 第9期高齢者保健福祉計画・介護保険事業計画 本文 | C11: 町 | D11: 完了 | E11: 2026-08-04 | F11: 5章構成・3基本目標・14施策、標準給付費3,566,486千円、保険料6,600円の算定根拠
A12: 町資料 | B12: 第3期地域福祉計画 本文・概要版 | C12: 町 | D12: 完了 | E12: 2026-08-04 | F12: 重複5施策を特定し役割分担を整理
... A19: 町資料 | B19: 成果指標の現状値 17項目（H1〜H17） | C19: 町 | D19: 未着手 | E19: ― | F19: **うちH3（総合事業・通いの場）とH16（調査の個票）が最優先**
A20: ※ 依頼の詳細（粒度・様式・基準日）は 16_町データ依頼/小野町_データ依頼票 を参照。

Sheet 06_会議体・意見聴取
A1: 区分 | B1: 回 | C1: 時期 | D1: 議題 | E1: 資料の状態 | F1: 備考
A2: 高齢者福祉サービス推進協議会 | B2: 第1回 | C2: 令和8年8〜9月 | D2: 第9期計画の評価、令和7年度調査結果の整理 | E2: 完了 | F2: **資料は作成済み（42表・約23,500字）。開催日が未定**
A3: 高齢者福祉サービス推進協議会 | B3: 第2回 | C3: 令和8年11月 | D3: 骨子案、サービス見込量、保険料の考え方、成果指標の目標値 | E3: 進行中 | F3: 骨子案第3版・成果指標目標値案（40指標）は作成済み
A4: 高齢者福祉サービス推進協議会 | B4: 第3回 | C4: 令和8年12月 | D4: 計画素案 | E4: 進行中 | F4: 素案第2版は作成済み。見込量・保険料の反映が必要
A5: 高齢者福祉サービス推進協議会 | B5: 第4回 | C5: 令和9年2月 | D5: パブリックコメントの結果、計画最終案 | E5: 未着手 | F5: ―
A6: パブリックコメント | B6: ― | C6: 令和9年1月 | D6: 計画素案に対する意見の募集 | E6: 完了 | F6: 実施要領・意見提出様式・対応表の様式は作成済み
A7: 町との打合せ | B7: 随時 | C7: 通年 | D7: 工程、データ、協議事項 | E7: 完了 | F7: **仕様書8①により受託者が記録を作成し相互確認する。様式は作成済み**

Sheet 07_課題・リスク
A1: No | B1: 課題・リスク | C1: 内容 | D1: 影響 | E1: 対応 | F1: 状態
A2: 1 | B2: 認定者数の計上方法の変更（旧「認定者数の異常」） | C2: **令和8年3月末の792人は年報 様式1の5で裏付けられ、値そのものは確定した。**国保連月報28か月で、減少が令和7年9月審査分の1か月に集中していること（961→862人・▲10.3％）と、同じ月に給付件数が減っていないこと（1,303→1,365件）が判明した。減少は要介護2以上に集中し要支援1は増えている。死亡171人は平年並み | D2: **実態の変化ではなく計上の変更である可能性が高い。**認定者数ベースで給付費を推計すると過小になる（令和7年度は認定者▲16.1％に対し給付費▲7.4％） | E2: **令和7年8〜9月の計上方法の変更を町に確認する。見込量は認定者数ベースではなく受給者数・給付費の実績を基礎に組む** | F2: 要対応
A3: 2 | B3: 町の実績データの受領状況 | C3: **9月8日に年報5年分・国保連月報28か月・将来推計人口を受領し、依頼35項目のうち主要項目が解決した。**残るのは地域支援事業費の内訳、令和7年度決算、成果指標の現状値17項目 | D3: 見込量・保険料の算定に着手できる状態になった | E3: 残項目を再依頼する。とくに地域支援事業費は総合事業・通いの場の評価に必須 | F3: 進行中
A4: 3 | B4: 協議会の開催回数・時期が未定 | C4: 仕様書4(5)は開催支援を定めるが回数の指定がない | D4: 工程が引けず、パブコメ・印刷の日程も確定できない | E4: 受託者案（4回）を提示して町と確定する（依頼票C4） | F4: 要対応
A5: 4 | B5: 介護予防のデータ欠落 | C5: 見える化の通いの場はR2まで、総合事業はR1・R2のみで値もほぼ空。F7〜F14は本町の値が未登録 | D5: 第9期の介護予防施策を評価できない | E5: 町の事業実績（令和3〜7年度）で代替する（依頼票H3） | F5: データ待ち
A6: 5 | B6: 通いの場が実質ゼロ | C6: 見える化では週1回以上が平成28年度以降0か所。一方、調査では週1回以上の参加が5.5％（高齢者人口換算で約190人） | D6: 第10期の最重点施策が設計できない。調整済み軽度認定率は10.6％→15.2％に上昇 | E6: 町の実態を確認したうえで、実態把握と登録を令和9年度の目標に置く | F6: 進行中
A7: 6 | B7: 認定と利用のギャップ | C7: 認定率の地域差指数1.24に対し受給率1.07（比0.86）。在宅の認定者の42.1％が未利用 | D7: 利用に移行した場合に給付費が急増するリスク | E7: 未利用理由の92.9％が需要側（供給制約は0.6％）。供給確保ではなく認定運用の確認・利用意向への働きかけ・レスパイトで対応する | F7: 進行中
A8: 7 | B8: 財政余剰の取扱いと基金残高の不整合 | C8: **年報 様式4で、歳入歳出差引残額は令和6年度末144.2百万円ある一方、介護給付費準備基金の保有額は12.0百万円しかない。**しかも令和4年度末は120.0百万円で、令和5年度末に1桁減っている。第9期は基金取崩35.0百万円を見込んでいた | D8: **基金が12百万円しかなければ35百万円の取崩は実行できない。**第10期の保険料水準の判断に直結する | E8: 取崩実績か入力誤りかを町に確認したうえで、余剰の還元（据置・引下げ・繰越金の基金積立）をケースC5・C6として算定する | F8: 要対応
A9: 8 | B9: 施設整備方針との不整合 | C9: 第9期は新規施設整備を原則行わない方針だが、認知症対応型共同生活介護の定員が令和4年度71人から令和6年度98人へ27人（38.0％）増加 | D9: 第9期評価の記述に影響 | E9: 整備の経緯を町に確認する（依頼票H15） | F9: 未着手
A10: 9 | B10: 印刷工程の未確保 | C10: 計画書50部（A4・4色刷り・80頁程度）、概要版50部（8頁）、簡易製本各3部が納品仕様 | D10: 納期に間に合わない | E10: **逆算表を作成済み（令和9年2月下旬の校了が期限）。12月までに印刷業者を押さえる** | F10: 進行中
A11: 10 | B11: 見える化システムへの入力作業 | C11: 仕様書4(2)は入力作業を業務に含むと定める | D11: 出力の分析だけでは仕様を満たさない | E11: アカウント・権限・作業範囲・時期を町と確認する（依頼票C5） | F11: 進行中
A12: 11 | B12: 認知症施策推進基本計画の包含の形式が未決 | C12: 仕様書2(3)は包含を計画の構成要件と定める | D12: 章立てが変わるため、素案の確定前に決める必要がある | E12: **基本的施策12項目との対応表を作成済み。分散＋対応表方式を提案** | F12: 進行中
A13: 12 | B13: 成果品欄の「（７）」への参照 | C13: 成果品は（１）〜（６）だが、納品仕様欄に「※（７）のデータ（ＣＤ－Ｒ）１部、概要版印刷50部」との記載がある | D13: 概要版の納品部数の解釈に関わる | E13: 町に確認する（依頼票C2） | F13: 進行中

Sheet 08_変更管理・打合せ記録
A1: No | B1: 区分 | C1: 内容 | D1: 根拠 | E1: 状態 | F1: 記録の有無
A2: 1 | B2: 工程 | C2: 高齢者計画の仕様書には工程表がない（工程が定められているのは障がい計画のみ）。業務期間は令和9年3月31日まで | D2: 仕様書3 | E2: 要対応 | F2: **業務期間から逆算した工程案を作成済み。町との合意が未**
A3: 2 | B3: 協議会 | C3: 開催回数の指定がない。受託者案は4回 | D3: 仕様書4(5) | E3: 要対応 | F3: 未
A4: 3 | B4: 保険料算定 | C4: ケース設定を引継ぎ時点の3ケース（基金の扱いのみ）からC1〜C6に組み直した。仕様書が例示する施設整備・制度改正に対応させた | D4: 仕様書4(2) | E4: 完了 | F4: 受託者の内部判断。町への説明が必要
A5: 4 | B5: 認知症計画 | C5: 包含の形式（独立章方式／分散＋対応表方式） | D5: 仕様書2(3) | E5: 進行中 | F5: **分散＋対応表方式を提案。町の意思決定が未**
A6: 5 | B6: 打合せ記録 | C6: 契約後の打合せ記録が引継ぎ資料に含まれていない | D6: 仕様書8①（受託者が作成し相互確認） | E6: 要対応 | F6: **様式を作成済み。8月の協議から適用する**
A7: ※ 仕様書8①により、打合せ記録は受託者が作成し町と相互に確認する。
A8: ※ 様式は 02_キックオフ・業務計画/小野町_工程変更協議資料 の第5節。

Sheet 09_仕様書対応表
A1: 区分 | B1: 条項 | C1: 仕様書の記載内容（原文） | D1: 対応する作業（01_WBS） | E1: 作業数 | F1: 網羅
A2: 計画の考え方 | B2: 1 | C2: 本業務は、国や福島県の動向、本町の高齢者の状況を的確に把握し、高齢者へのアンケート調査結果及び小野町高齢者保健福祉計画・第9期介護保険事業計画の評価等を行い、本町が取り組むべき課題や高齢者保健福祉施策の方向性、サービスの目標量を定める（第10期計画）とする。 | D2: ― | E2: 0 | F2: 前提条項
A3: 計画の考え方 | B3: 2(1) | C3: 令和9年度から令和11年度までの3年間に実施する取り組みを定める計画とする。 | D3: ― | E3: 0 | F3: 前提条項
A4: 計画の考え方 | B4: 2(2) | C4: 国が示す第10期計画に関する基本的な考え方を踏まえた上で、本町の特性を活かした計画とする。 | D4: 1-5 第3期地域福祉計画との役割分担の整理 | E4: 1 | F4: ○
A5: 計画の考え方 | B5: 2(3) | C5: 国の「認知症施策推進基本計画」に基づく市町村計画も包含する計画とする。 | D5: 2-7 認知症高齢者の分析 8-3 認知症施策推進基本計画の包含方針 | E5: 2 | F5: ○
A6: 計画の考え方 | B6: 3 | C6: 契約締結の日から令和9年3月31日まで | D6: 10-8 納品・検収 | E6: 1 | F6: ○
A7: 業務の内容 | B7: 4(1) | C7: 基礎的な地域データ及び資料の整理分析（現状分析）。高齢者福祉・介護保険をめぐる施策の動向、小野町の概要及び社会経済的特性、地域福祉資源の整備状況、高齢者の現況動向及びサービスの利用状況等について、小野町が提供するデータをもとに整理分析を行う。（計画策定の検討資料として活用するため、各種事項の将来推計を行う。なお、推計にあたっては、可能な限り細分化する） | D7: 1-4 第9期計画本文の確認 | E7: 1 | F7: ○
A8: 業務の内容 | B8: 4(1)①ア | C8: 統計分析（ア）人口 | D8: 2-1 人口・世帯の分析 2-2 第1号被保険者の分析 | E8: 2 | F8: ○
A9: 業務の内容 | B9: 4(1)①イ | C9: 統計分析（イ）要支援者数、要介護認定者数、認知症高齢者数 | D9: 2-3 認定者数・認定率の分析 2-4 認定者数の異常値の検証 2-7 認知症高齢者の分析 | E9: 3 | F9: ○
A10: 業務の内容 | B10: 4(1)①ウ | C10: 統計分析（ウ）居宅サービス・施設サービス・地域密着型サービスの受給者数 | D10: 2-5 サービス受給者数の分析 | E10: 1 | F10: ○
A11: 業務の内容 | B11: 4(1)①エ | C11: 統計分析（エ）介護予防事業対象者数 | D11: 2-6 介護予防事業対象者数の分析 | E11: 1 | F11: ○
A12: 業務の内容 | B12: 4(1)①オ | C12: 統計分析（オ）その他計画策定に必要な推計 | D12: 2-8 サービス自給率の分析 2-10 見える化 優先度C分野の出力 | E12: 2 | F12: ○
A13: 業務の内容 | B13: 4(1)② | C13: 介護保険給付費等の分析。介護サービス費目ごとの介護給付費や地域支援事業の利用状況等を分析し、現在の状況や傾向の把握、また、制度改正に伴う影響等を分析し、今後の見通しや具体的施策を検討する。 | D13: 3-1 給付費等分析結果報告書の作成 3-2 町の給付実績との突合 5-1 協議会資料（第9期評価・調査結果）の作成 5-2 成果目標の達成状況の確定 5-3 施設整備方針との不整合の確認 | E13: 5 | F13: ○
... A29: その他 | B29: 公告10⑥ | C29: 研究員は「見える化」システムやニーズ調査など各種データから介護給付費の統計分析により将来のサービス量を推計し計画化できる者（公告第1-19号 10⑥） | D29: 1-1 契約・体制の確立、キックオフ | E29: 1 | F29: ○
A31: ※ 「要確認」は、01_WBS に対応する作業が置かれていない条項です。業務の抜けを疑ってください。
A32: ※ 「前提条項」は、目的・計画期間・個人情報の取扱いなど、作業として分解せず業務全体で担保する条項です。

Sheet 10_ブロック別進捗
A1: 仕様書ブロック | B1: 該当条項 | C1: 作業数 | D1: 完了 | E1: 進行中 | F1: 要対応 | G1: データ待ち | H1: 未着手 | I1: 加重進捗率 | J1: 現況・律速
A2: B1 現状分析（基礎データ・資料の整理分析） | B2: 4(1) | C2: =COUNTIF('01_WBS'!$E$2:$E$64,$A2) | D2: =COUNTIFS('01_WBS'!$E$2:$E$64,$A2,'01_WBS'!$K$2:$K$64,"完了") | E2: =COUNTIFS('01_WBS'!$E$2:$E$64,$A2,'01_WBS'!$K$2:$K$64,"進行中") | F2: =COUNTIFS('01_WBS'!$E$2:$E$64,$A2,'01_WBS'!$K$2:$K$64,"要対応") | G2: =COUNTIFS('01_WBS'!$E$2:$E$64,$A2,'01_WBS'!$K$2:$K$64,"データ待ち") | H2: =COUNTIFS('01_WBS'!$E$2:$E$64,$A2,'01_WBS'!$K$2:$K$64,"未着手") | I2: =IF(SUMPRODUCT(('01_WBS'!$E$2:$E$64=$A2)*'01_WBS'!$M$2:$M$64)=0,"―",SUMPRODUCT(('01_WBS'!$E$2:$E$64=$A2)*'01_WBS'!$L$2:$L$64*'01_WBS'!$M$2:$M$64)/SUMPRODUCT(('01_WBS'!$E$2:$E$64=$A2)*'01_WBS'!$M$2:$M$64)/100) | J2: 第9期計画・第3期地域福祉計画の確認は完了。町からの実績データが未受領
A3: B2 統計分析 | B3: 4(1)①ア、4(1)①イ、4(1)①ウ、4(1)①エ、4(1)①オ | C3: =COUNTIF('01_WBS'!$E$2:$E$64,$A3) | D3: =COUNTIFS('01_WBS'!$E$2:$E$64,$A3,'01_WBS'!$K$2:$K$64,"完了") | E3: =COUNTIFS('01_WBS'!$E$2:$E$64,$A3,'01_WBS'!$K$2:$K$64,"進行中") | F3: =COUNTIFS('01_WBS'!$E$2:$E$64,$A3,'01_WBS'!$K$2:$K$64,"要対応") | G3: =COUNTIFS('01_WBS'!$E$2:$E$64,$A3,'01_WBS'!$K$2:$K$64,"データ待ち") | H3: =COUNTIFS('01_WBS'!$E$2:$E$64,$A3,'01_WBS'!$K$2:$K$64,"未着手") | I3: =IF(SUMPRODUCT(('01_WBS'!$E$2:$E$64=$A3)*'01_WBS'!$M$2:$M$64)=0,"―",SUMPRODUCT(('01_WBS'!$E$2:$E$64=$A3)*'01_WBS'!$L$2:$L$64*'01_WBS'!$M$2:$M$64)/SUMPRODUCT(('01_WBS'!$E$2:$E$64=$A3)*'01_WBS'!$M$2:$M$64)/100) | J3: **認定者数792人は年報で裏付けられた。論点は令和7年8〜9月の計上変更に絞られた。介護予防（総合事業・通いの場）のデータ欠落は残る**
A4: B3 介護保険給付費等の分析 | B4: 4(1)② | C4: =COUNTIF('01_WBS'!$E$2:$E$64,$A4) | D4: =COUNTIFS('01_WBS'!$E$2:$E$64,$A4,'01_WBS'!$K$2:$K$64,"完了") | E4: =COUNTIFS('01_WBS'!$E$2:$E$64,$A4,'01_WBS'!$K$2:$K$64,"進行中") | F4: =COUNTIFS('01_WBS'!$E$2:$E$64,$A4,'01_WBS'!$K$2:$K$64,"要対応") | G4: =COUNTIFS('01_WBS'!$E$2:$E$64,$A4,'01_WBS'!$K$2:$K$64,"データ待ち") | H4: =COUNTIFS('01_WBS'!$E$2:$E$64,$A4,'01_WBS'!$K$2:$K$64,"未着手") | I4: =IF(SUMPRODUCT(('01_WBS'!$E$2:$E$64=$A4)*'01_WBS'!$M$2:$M$64)=0,"―",SUMPRODUCT(('01_WBS'!$E$2:$E$64=$A4)*'01_WBS'!$L$2:$L$64*'01_WBS'!$M$2:$M$64)/SUMPRODUCT(('01_WBS'!$E$2:$E$64=$A4)*'01_WBS'!$M$2:$M$64)/100) | J4: 成果品①は第5版。町の給付実績で数値を確定する段階
A5: B4 令和7年度調査結果の反映 | B5: 4(1)③ | C5: =COUNTIF('01_WBS'!$E$2:$E$64,$A5) | D5: =COUNTIFS('01_WBS'!$E$2:$E$64,$A5,'01_WBS'!$K$2:$K$64,"完了") | E5: =COUNTIFS('01_WBS'!$E$2:$E$64,$A5,'01_WBS'!$K$2:$K$64,"進行中") | F5: =COUNTIFS('01_WBS'!$E$2:$E$64,$A5,'01_WBS'!$K$2:$K$64,"要対応") | G5: =COUNTIFS('01_WBS'!$E$2:$E$64,$A5,'01_WBS'!$K$2:$K$64,"データ待ち") | H5: =COUNTIFS('01_WBS'!$E$2:$E$64,$A5,'01_WBS'!$K$2:$K$64,"未着手") | I5: =IF(SUMPRODUCT(('01_WBS'!$E$2:$E$64=$A5)*'01_WBS'!$M$2:$M$64)=0,"―",SUMPRODUCT(('01_WBS'!$E$2:$E$64=$A5)*'01_WBS'!$L$2:$L$64*'01_WBS'!$M$2:$M$64)/SUMPRODUCT(('01_WBS'!$E$2:$E$64=$A5)*'01_WBS'!$M$2:$M$64)/100) | J5: **単純集計は完了。個票がないとクロス集計17件ができない**
A6: B5 事業量推計・保険料算出・介護財政 | B6: 4(2) | C6: =COUNTIF('01_WBS'!$E$2:$E$64,$A6) | D6: =COUNTIFS('01_WBS'!$E$2:$E$64,$A6,'01_WBS'!$K$2:$K$64,"完了") | E6: =COUNTIFS('01_WBS'!$E$2:$E$64,$A6,'01_WBS'!$K$2:$K$64,"進行中") | F6: =COUNTIFS('01_WBS'!$E$2:$E$64,$A6,'01_WBS'!$K$2:$K$64,"要対応") | G6: =COUNTIFS('01_WBS'!$E$2:$E$64,$A6,'01_WBS'!$K$2:$K$64,"データ待ち") | H6: =COUNTIFS('01_WBS'!$E$2:$E$64,$A6,'01_WBS'!$K$2:$K$64,"未着手") | I6: =IF(SUMPRODUCT(('01_WBS'!$E$2:$E$64=$A6)*'01_WBS'!$M$2:$M$64)=0,"―",SUMPRODUCT(('01_WBS'!$E$2:$E$64=$A6)*'01_WBS'!$L$2:$L$64*'01_WBS'!$M$2:$M$64)/SUMPRODUCT(('01_WBS'!$E$2:$E$64=$A6)*'01_WBS'!$M$2:$M$64)/100) | J6: **年報の受領で実績が揃い、算定シートに投入済み。残るのはサービス別見込量の算定と、地域支援事業費・調整交付金・基金取崩の確定**
A7: B6 骨子案・素案の作成 | B7: 4(3) | C7: =COUNTIF('01_WBS'!$E$2:$E$64,$A7) | D7: =COUNTIFS('01_WBS'!$E$2:$E$64,$A7,'01_WBS'!$K$2:$K$64,"完了") | E7: =COUNTIFS('01_WBS'!$E$2:$E$64,$A7,'01_WBS'!$K$2:$K$64,"進行中") | F7: =COUNTIFS('01_WBS'!$E$2:$E$64,$A7,'01_WBS'!$K$2:$K$64,"要対応") | G7: =COUNTIFS('01_WBS'!$E$2:$E$64,$A7,'01_WBS'!$K$2:$K$64,"データ待ち") | H7: =COUNTIFS('01_WBS'!$E$2:$E$64,$A7,'01_WBS'!$K$2:$K$64,"未着手") | I7: =IF(SUMPRODUCT(('01_WBS'!$E$2:$E$64=$A7)*'01_WBS'!$M$2:$M$64)=0,"―",SUMPRODUCT(('01_WBS'!$E$2:$E$64=$A7)*'01_WBS'!$L$2:$L$64*'01_WBS'!$M$2:$M$64)/SUMPRODUCT(('01_WBS'!$E$2:$E$64=$A7)*'01_WBS'!$M$2:$M$64)/100) | J7: 骨子案第3版・素案第2版・成果指標の目標値案まで到達。見込量と保険料の反映が残る
A8: B7 最終調整及び計画書の作成 | B8: 4(4) | C8: =COUNTIF('01_WBS'!$E$2:$E$64,$A8) | D8: =COUNTIFS('01_WBS'!$E$2:$E$64,$A8,'01_WBS'!$K$2:$K$64,"完了") | E8: =COUNTIFS('01_WBS'!$E$2:$E$64,$A8,'01_WBS'!$K$2:$K$64,"進行中") | F8: =COUNTIFS('01_WBS'!$E$2:$E$64,$A8,'01_WBS'!$K$2:$K$64,"要対応") | G8: =COUNTIFS('01_WBS'!$E$2:$E$64,$A8,'01_WBS'!$K$2:$K$64,"データ待ち") | H8: =COUNTIFS('01_WBS'!$E$2:$E$64,$A8,'01_WBS'!$K$2:$K$64,"未着手") | I8: =IF(SUMPRODUCT(('01_WBS'!$E$2:$E$64=$A8)*'01_WBS'!$M$2:$M$64)=0,"―",SUMPRODUCT(('01_WBS'!$E$2:$E$64=$A8)*'01_WBS'!$L$2:$L$64*'01_WBS'!$M$2:$M$64)/SUMPRODUCT(('01_WBS'!$E$2:$E$64=$A8)*'01_WBS'!$M$2:$M$64)/100) | J8: パブリックコメント後に着手する。時期が来ていない
A9: B8 協議会・パブリックコメントの支援 | B9: 4(5) | C9: =COUNTIF('01_WBS'!$E$2:$E$64,$A9) | D9: =COUNTIFS('01_WBS'!$E$2:$E$64,$A9,'01_WBS'!$K$2:$K$64,"完了") | E9: =COUNTIFS('01_WBS'!$E$2:$E$64,$A9,'01_WBS'!$K$2:$K$64,"進行中") | F9: =COUNTIFS('01_WBS'!$E$2:$E$64,$A9,'01_WBS'!$K$2:$K$64,"要対応") | G9: =COUNTIFS('01_WBS'!$E$2:$E$64,$A9,'01_WBS'!$K$2:$K$64,"データ待ち") | H9: =COUNTIFS('01_WBS'!$E$2:$E$64,$A9,'01_WBS'!$K$2:$K$64,"未着手") | I9: =IF(SUMPRODUCT(('01_WBS'!$E$2:$E$64=$A9)*'01_WBS'!$M$2:$M$64)=0,"―",SUMPRODUCT(('01_WBS'!$E$2:$E$64=$A9)*'01_WBS'!$L$2:$L$64*'01_WBS'!$M$2:$M$64)/SUMPRODUCT(('01_WBS'!$E$2:$E$64=$A9)*'01_WBS'!$M$2:$M$64)/100) | J9: **資料と様式は揃っている。協議会の開催回数・時期が未定で工程が引けない**
A10: B9 成果品の納品 | B10: 成果品①、成果品②、成果品③、成果品④、成果品⑤、成果品⑥ ほか | C10: =COUNTIF('01_WBS'!$E$2:$E$64,$A10) | D10: =COUNTIFS('01_WBS'!$E$2:$E$64,$A10,'01_WBS'!$K$2:$K$64,"完了") | E10: =COUNTIFS('01_WBS'!$E$2:$E$64,$A10,'01_WBS'!$K$2:$K$64,"進行中") | F10: =COUNTIFS('01_WBS'!$E$2:$E$64,$A10,'01_WBS'!$K$2:$K$64,"要対応") | G10: =COUNTIFS('01_WBS'!$E$2:$E$64,$A10,'01_WBS'!$K$2:$K$64,"データ待ち") | H10: =COUNTIFS('01_WBS'!$E$2:$E$64,$A10,'01_WBS'!$K$2:$K$64,"未着手") | I10: =IF(SUMPRODUCT(('01_WBS'!$E$2:$E$64=$A10)*'01_WBS'!$M$2:$M$64)=0,"―",SUMPRODUCT(('01_WBS'!$E$2:$E$64=$A10)*'01_WBS'!$L$2:$L$64*'01_WBS'!$M$2:$M$64)/SUMPRODUCT(('01_WBS'!$E$2:$E$64=$A10)*'01_WBS'!$M$2:$M$64)/100) | J10: **製本・印刷が納品仕様に含まれる。令和9年2月下旬の校了が動かせない期限**
A11: B10 業務管理・計画の基本的な考え方 | B11: 1、2(1)、2(2)、2(3)、3、5(1) ほか | C11: =COUNTIF('01_WBS'!$E$2:$E$64,$A11) | D11: =COUNTIFS('01_WBS'!$E$2:$E$64,$A11,'01_WBS'!$K$2:$K$64,"完了") | E11: =COUNTIFS('01_WBS'!$E$2:$E$64,$A11,'01_WBS'!$K$2:$K$64,"進行中") | F11: =COUNTIFS('01_WBS'!$E$2:$E$64,$A11,'01_WBS'!$K$2:$K$64,"要対応") | G11: =COUNTIFS('01_WBS'!$E$2:$E$64,$A11,'01_WBS'!$K$2:$K$64,"データ待ち") | H11: =COUNTIFS('01_WBS'!$E$2:$E$64,$A11,'01_WBS'!$K$2:$K$64,"未着手") | I11: =IF(SUMPRODUCT(('01_WBS'!$E$2:$E$64=$A11)*'01_WBS'!$M$2:$M$64)=0,"―",SUMPRODUCT(('01_WBS'!$E$2:$E$64=$A11)*'01_WBS'!$L$2:$L$64*'01_WBS'!$M$2:$M$64)/SUMPRODUCT(('01_WBS'!$E$2:$E$64=$A11)*'01_WBS'!$M$2:$M$64)/100) | J11: 仕様書の適合性チェック・データ依頼票は完了。工程と協議会日程の合意が残る
A12: B11 仕様書に定めのない作業 | B12: （該当条項なし） | C12: =COUNTIF('01_WBS'!$E$2:$E$64,$A12) | D12: =COUNTIFS('01_WBS'!$E$2:$E$64,$A12,'01_WBS'!$K$2:$K$64,"完了") | E12: =COUNTIFS('01_WBS'!$E$2:$E$64,$A12,'01_WBS'!$K$2:$K$64,"進行中") | F12: =COUNTIFS('01_WBS'!$E$2:$E$64,$A12,'01_WBS'!$K$2:$K$64,"要対応") | G12: =COUNTIFS('01_WBS'!$E$2:$E$64,$A12,'01_WBS'!$K$2:$K$64,"データ待ち") | H12: =COUNTIFS('01_WBS'!$E$2:$E$64,$A12,'01_WBS'!$K$2:$K$64,"未着手") | I12: =IF(SUMPRODUCT(('01_WBS'!$E$2:$E$64=$A12)*'01_WBS'!$M$2:$M$64)=0,"―",SUMPRODUCT(('01_WBS'!$E$2:$E$64=$A12)*'01_WBS'!$L$2:$L$64*'01_WBS'!$M$2:$M$64)/SUMPRODUCT(('01_WBS'!$E$2:$E$64=$A12)*'01_WBS'!$M$2:$M$64)/100) | J12: 該当なし。仕様書のいずれかの条項に紐づかない作業が発生した場合はここに現れる
A13: 合計 | C13: =SUM(C2:C12) | D13: =SUM(D2:D12) | E13: =SUM(E2:E12) | F13: =SUM(F2:F12) | G13: =SUM(G2:G12) | H13: =SUM(H2:H12) | I13: =IF(SUM('01_WBS'!$M$2:$M$64)=0,0,SUMPRODUCT('01_WBS'!$L$2:$L$64,'01_WBS'!$M$2:$M$64)/SUM('01_WBS'!$M$2:$M$64)/100)
A15: ※ 段階（02_段階サマリ）は業務の進み方の切り口、ブロックは委託契約上の業務単位の切り口です。同じ作業を別の軸で見ています。
A16: ※ 作業が複数の条項にまたがる場合は、先頭の条項が属するブロックに数えています。
A17: ※ 未分類の作業があります：[]
