Workbook

Sheet 00_ダッシュボード
A1: 小野町 おのまち障がい者計画・第4期障がい児福祉計画・第8期障がい福祉計画 業務進捗管理表
A2: 基準日：令和8年10月7日
A4: 全体進捗 | B4: ='02_段階サマリ'!H10 | D4: 作業数 | E4: ='02_段階サマリ'!B10 | G4: 完了 | H4: ='02_段階サマリ'!C10
A6: ■ 予定との乖離（11_進捗の乖離）
A7: 予定進捗率 | B7: 0.51752893 | C7: 実績進捗率 | D7: 0.53801653 | E7: 乖離 | F7: 0.020487603
A8: おおむね予定どおり 31件／前倒し 10件／期限超過（1か月） 5件／遅れ 2件／期限超過（2か月） 1件
A10: 段階 | B10: 作業数 | C10: 加重進捗率 | D10: 律速要因
A11: ='02_段階サマリ'!A2 | B11: ='02_段階サマリ'!B2 | C11: ='02_段階サマリ'!H2 | D11: ='02_段階サマリ'!K2
A12: ='02_段階サマリ'!A3 | B12: ='02_段階サマリ'!B3 | C12: ='02_段階サマリ'!H3 | D12: ='02_段階サマリ'!K3
A13: ='02_段階サマリ'!A4 | B13: ='02_段階サマリ'!B4 | C13: ='02_段階サマリ'!H4 | D13: ='02_段階サマリ'!K4
A14: ='02_段階サマリ'!A5 | B14: ='02_段階サマリ'!B5 | C14: ='02_段階サマリ'!H5 | D14: ='02_段階サマリ'!K5
A15: ='02_段階サマリ'!A6 | B15: ='02_段階サマリ'!B6 | C15: ='02_段階サマリ'!H6 | D15: ='02_段階サマリ'!K6
A16: ='02_段階サマリ'!A7 | B16: ='02_段階サマリ'!B7 | C16: ='02_段階サマリ'!H7 | D16: ='02_段階サマリ'!K7
A17: ='02_段階サマリ'!A8 | B17: ='02_段階サマリ'!B8 | C17: ='02_段階サマリ'!H8 | D17: ='02_段階サマリ'!K8
A18: ='02_段階サマリ'!A9 | B18: ='02_段階サマリ'!B9 | C18: ='02_段階サマリ'!H9 | D18: ='02_段階サマリ'!K9
A20: ■ 仕様書の業務ブロック別
A21: 仕様書ブロック | B21: 作業数 | C21: 加重進捗率 | D21: 現況・律速
A22: ='10_ブロック別進捗'!A2 | B22: ='10_ブロック別進捗'!C2 | C22: ='10_ブロック別進捗'!I2 | D22: ='10_ブロック別進捗'!J2
A23: ='10_ブロック別進捗'!A3 | B23: ='10_ブロック別進捗'!C3 | C23: ='10_ブロック別進捗'!I3 | D23: ='10_ブロック別進捗'!J3
A24: ='10_ブロック別進捗'!A4 | B24: ='10_ブロック別進捗'!C4 | C24: ='10_ブロック別進捗'!I4 | D24: ='10_ブロック別進捗'!J4
A25: ='10_ブロック別進捗'!A5 | B25: ='10_ブロック別進捗'!C5 | C25: ='10_ブロック別進捗'!I5 | D25: ='10_ブロック別進捗'!J5
A26: ='10_ブロック別進捗'!A6 | B26: ='10_ブロック別進捗'!C6 | C26: ='10_ブロック別進捗'!I6 | D26: ='10_ブロック別進捗'!J6
A27: ='10_ブロック別進捗'!A7 | B27: ='10_ブロック別進捗'!C7 | C27: ='10_ブロック別進捗'!I7 | D27: ='10_ブロック別進捗'!J7
A28: ='10_ブロック別進捗'!A8 | B28: ='10_ブロック別進捗'!C8 | C28: ='10_ブロック別進捗'!I8 | D28: ='10_ブロック別進捗'!J8
A30: ■ 現況
A31: **障がい計画は仕様書7の工程から3〜4か月遅れている。**仕様書は調査を7月までに実施し、9月に骨子案、10月に骨子案検討としているが、調査票が確定せず調査は未実施である。
A32: 8月13日に、ヒアリングの実施計画書と質問票6種、障がい者ニーズ調査の実施設計書（600件の抽出条件案・回収率67％の逆算工程）、工程変更協議資料を作成した。**設計は整い、あとは調査票の確定を待つ状態にある。**
A33: 9月7日、町提出のワークシートに基づく見込量・成果目標設定シート（9シート）を受領し、レッドチームレビューを実施した。**算式は利用者数22行・利用量7行の全行で再現一致し、人口・手帳の内訳合計とサマリーの突合も全一致した。計算に誤りはない。**一方、重大5件を含む16件の不具合を検出した。成果目標の基準年度が施設入所系（R7年度末）と一般就労系（R6年度）で混在していること、「精神障害にも対応した地域包括ケアシステム」と「人材確保・生産性向上」の2分野が丸ごと欠落していること、「のぞまないセルフプラン0件」の目標に対し相談支援の見込量が構造的に不足していること、地域生活支援事業が21項目中11項目で未設定であること、の4点が中心である。
A34: **見込量の水準に効く前提の置き方の差は、居宅介護で2.2倍（R7の異常値を平均に含めるか）、放課後等デイのR11で＋23％（低下した利用率を固定するか4年平均を使うか）、施設入所者目標で最大3人（基準年度の取り方）である。**
A35: **8月19日の自立支援協議会の結果と、★0727版調査票の入手状況は本セッションでは未確認である。**調査票が確定していない場合、9月中旬発送という逆算工程はすでに崩れており、工程の再設定が要る。
A36: **関係者団体等ヒアリングは、仕様書5(3)及び成果品①が求める業務項目でありながら、これまで実施も計画もされていなかった。**実施計画書と質問票（大問35・小問102）を作成し、9月中旬〜10月下旬にアンケートと並行して実施する設計とした。
A37: **回収率は仕様書が66.7％を想定するのに対し、前回実績は54.3％である。**12.4ポイントの改善が必要で、督促だけでは埋まらない。回収率を9要素に分解し、9月中旬発送の逆算工程を置いた。
A38: **手帳所持者は508人まで減少しており、600件の配布には対象拡大が必要である。**自立支援医療・難病・サービス利用者・障がい児通所・特別支援学級で補う抽出条件案（区分①〜⑩）を作成した。抽出は町の作業であるため、区分ごとの実数の回答を待って確定する。
A39: **素案は引継ぎ時点の拡充版のまま第2版への改訂が未着手である。**これは外部の条件に依存せず着手できる唯一の残作業であり、次に着手する。
A41: ■ 警戒事項
A42: # | B42: 内容 | C42: 影響 | D42: 対応
A43: 1 | B43: 成果目標に2分野（精神包括ケア・人材確保）が欠落 | C43: 計画の法定要件を欠く可能性。活動指標も連動して欠落する | D43: **精神は小野町で唯一増加している手帳（45人→62人・＋37.8％）の分野。**成果目標に追加し、保健所・圏域の精神科医療機関と調整する
A44: 2 | B44: 成果目標の基準年度が混在（施設入所=R7年度末／一般就労=R6年度） | C44: R11年度末の施設入所者目標が15人／17人／18人と最大3人ぶれる。R7基準では R8実績18人ですでに達成済みで、目標として機能しない | D44: 告示本文と県方針で基準年度を確定し、統一する
A45: 3 | B45: セルフプラン0件目標と相談支援の見込量が不整合 | C45: 障害児相談支援R8実績0人に対し児発6人・放デイ19人が利用中。R11見込5人では対象19人をカバーできない | D45: セルフプランの実件数を町に照会し、見込量を積み上げ直す（依頼票D5）
A46: 4 | B46: 地域生活支援事業が21項目中11項目で未設定 | C46: **障害者総合支援法第88条の必須記載事項。この状態では計画が成立しない** | D46: 町の決算・実績報告からR6〜R8実績を補完する
...

Sheet 01_WBS
A1: 段階 | B1: No | C1: 作業 | D1: 内容 | E1: 仕様書ブロック | F1: 仕様書 条項 | G1: 仕様書の記載内容（原文） | H1: 担当 | I1: 予定開始 | J1: 予定完了 | K1: 状態 | L1: 進捗率 | M1: 重み | N1: 実績・根拠 | O1: 前提条件・ブロッカー
A2: P1 準備・現状把握 | B2: 1-1 | C2: 契約・体制の確立、キックオフ | D2: 実施体制、役割分担 | E2: B6 業務管理・打合せ | F2: 公告10⑥ | G2: 【公告10⑥】自治体の当該計画策定や調査研究実績があり、本計画策定の実務を担う者（公告第1-36号 10⑥） | H2: 受託者 | I2: 2026-06 | J2: 2026-07 | K2: 完了 | L2: 100 | M2: 2 | N2: キックオフ資料・業務計画書 | O2: ―
A3: P1 準備・現状把握 | B3: 1-2 | C3: 委託仕様書の確認と適合性チェック | D3: 成果品要件・工程・作業分担の確定 | E3: B6 業務管理・打合せ | F3: 仕様書全般 | G3: 【全般】委託仕様書及び公告の全体（成果品要件・工程・作業分担の確認） | H3: 受託者 | I3: 2026-08 | J3: 2026-08 | K3: 完了 | L3: 100 | M3: 3 | N3: 仕様書適合性チェック 第2版（00_引継ぎ） | O3: ―
A4: P1 準備・現状把握 | B4: 1-3 | C4: 現行計画（第7期・第3期）の確認 | D4: 3部構成、9分野の施策体系 | E4: B2 現状分析と課題の整理 | F4: 仕様書5(3) | G4: 【5(3)】現状分析と課題の整理。現行計画の取組み状況及び課題の検証を行う。また、障がい者ニーズ調査結果や関係者団体等ヒアリング調査結果、当町が実施する関連調査等の結果、国や県の上位計画や各種施策、並びに当町が保有する各種データ等をもとに、障がい者を取り巻く環境の分析や課題の抽出を行う。 | H4: 受託者 | I4: 2026-07 | J4: 2026-08 | K4: 完了 | L4: 100 | M4: 2 | N4: 計画接続マトリクス（02_キックオフ） | O4: ―
A5: P1 準備・現状把握 | B5: 1-4 | C5: 第3期地域福祉計画との役割分担の整理 | D5: 地域共生社会、重層的支援体制、成年後見制度利用促進の切り分け | E5: B2 現状分析と課題の整理 | F5: 仕様書5(3) | G5: 【5(3)】現状分析と課題の整理。現行計画の取組み状況及び課題の検証を行う。また、障がい者ニーズ調査結果や関係者団体等ヒアリング調査結果、当町が実施する関連調査等の結果、国や県の上位計画や各種施策、並びに当町が保有する各種データ等をもとに、障がい者を取り巻く環境の分析や課題の抽出を行う。 | H5: 受託者 | I5: 2026-08 | J5: 2026-08 | K5: 完了 | L5: 100 | M5: 2 | N5: 地域福祉計画との整合確認メモ | O5: ―
A6: P1 準備・現状把握 | B6: 1-5 | C6: 町への資料依頼票の作成 | D6: 障がい分7項目＋確認事項 | E6: B1 障がい者ニーズ調査 | F6: 仕様書5(1) | G6: 【5(1)】障がい者ニーズ調査。アンケート調査により、障がい福祉サービスの実態や障がい者の意向などを把握し分析・課題の抽出等を行う。単純集計の他、性別・年齢別・障がい別・地域別等の必要なクロス集計、自由回答のとりまとめを含めて行い、町の現状や課題などを抽出・把握し、計画策定のための基礎資料となるものと位置づける。アンケート等の作成及び発送については受託者が実施する。受託者はアンケート等回収票の開封、データ入力、集計、分析、課題整理を行う。なお、アンケート等の送付数は600件程度であり、回収数は400件程度を見込んでいる。 | H6: 受託者 | I6: 2026-08 | J6: 2026-08 | K6: 完了 | L6: 100 | M6: 2 | N6: 小野町_データ依頼票 04_障がい計画（16_町データ依頼） | O6: ―
A7: P1 準備・現状把握 | B7: 1-6 | C7: 町データの受領 | D7: サービス実績、セルフプラン、対象者数等 | E7: B1 障がい者ニーズ調査 | F7: 仕様書5(1) | G7: 【5(1)】障がい者ニーズ調査。アンケート調査により、障がい福祉サービスの実態や障がい者の意向などを把握し分析・課題の抽出等を行う。単純集計の他、性別・年齢別・障がい別・地域別等の必要なクロス集計、自由回答のとりまとめを含めて行い、町の現状や課題などを抽出・把握し、計画策定のための基礎資料となるものと位置づける。アンケート等の作成及び発送については受託者が実施する。受託者はアンケート等回収票の開封、データ入力、集計、分析、課題整理を行う。なお、アンケート等の送付数は600件程度であり、回収数は400件程度を見込んでいる。 | H7: 町 | I7: 2026-08 | J7: 2026-09 | K7: 未着手 | L7: 0 | M7: 4 | N7: 受領0件／依頼7件 | O7: **町の回答。P2・P5・P6が依存する**
A8: P1 準備・現状把握 | B8: 1-7 | C8: 工程変更の協議と打合せ記録の作成 | D8: 仕様書7の工程から3〜4か月遅れているため、変更を町と協議し記録化する。**記録の作成は仕様書8①により受託者の義務** | E8: B6 業務管理・打合せ | F8: 仕様書11④・仕様書8① | G8: 【11④】本仕様書について定めのない事項等が生じた場合、または本業務履行上、基本事項の変更の必要が認められた場合には、当町と受託者間で双方協議の上、定めるものとする。 【8①】打合せは必要に応じて随時行い、受託者が打ち合わせ内容の記録を作成し当町と相互に確認する。 | H8: 受託者・町 | I8: 2026-08 | J8: 2026-08 | K8: 要対応 | L8: 40 | M8: 2 | N8: **工程変更協議資料と打合せ記録様式を作成済み（02_キックオフ・業務計画）** | O8: **町との協議。8月19日の協議会またはその前後に行う**
A9: P2 ニーズ調査 | B9: 2-1 | C9: 調査内容の企画 | D9: 設問設計、クロス集計軸、見込量への接続表 | E9: B1 障がい者ニーズ調査 | F9: 仕様書5(1)①ア | G9: 【5(1)①ア】委託事項（ア）調査内容の企画 | H9: 受託者 | I9: 2026-07 | J9: 2026-07 | K9: 完了 | L9: 100 | M9: 3 | N9: アンケート接続表（04_算定・見込量） | O9: ―
A10: P2 ニーズ調査 | B10: 2-2 | C10: 調査実施設計 | D10: 抽出条件案、回収率67％の逆算工程、調査用品の仕様、集計方針 | E10: B1 障がい者ニーズ調査 | F10: 仕様書5(1) | G10: 【5(1)】障がい者ニーズ調査。アンケート調査により、障がい福祉サービスの実態や障がい者の意向などを把握し分析・課題の抽出等を行う。単純集計の他、性別・年齢別・障がい別・地域別等の必要なクロス集計、自由回答のとりまとめを含めて行い、町の現状や課題などを抽出・把握し、計画策定のための基礎資料となるものと位置づける。アンケート等の作成及び発送については受託者が実施する。受託者はアンケート等回収票の開封、データ入力、集計、分析、課題整理を行う。なお、アンケート等の送付数は600件程度であり、回収数は400件程度を見込んでいる。 | H10: 受託者 | I10: 2026-08 | J10: 2026-08 | K10: 完了 | L10: 100 | M10: 3 | N10: **障がい者ニーズ調査実施設計書（15_ヒアリング・調査設計）。**回収率を9要素に分解し、9月中旬発送の逆算工程を作成 | O10: ―
A11: P2 ニーズ調査 | B11: 2-3 | C11: 調査票の作成と補修正 | D11: ★0727版の児童用に28箇所以上の本文欠落。一般用も問番号・条件見出し・ルビ13件 | E11: B1 障がい者ニーズ調査 | F11: 仕様書5(1)①イ | G11: 【5(1)①イ】委託事項（イ）調査票の作成 | H11: 受託者 | I11: 2026-08 | J11: 2026-08 | K11: 完了 | L11: 100 | M11: 4 | N11: **調査は令和8年8月14日から9月25日まで実施済み（他メンバーが担当）。**調査票は確定し、障がい者259件・障がい児25件の有効回答を得ている | O11: ―
A12: P2 ニーズ調査 | B12: 2-4 | C12: 調査票原案の町の確認 | D12: 町による内容確認 | E12: B1 障がい者ニーズ調査 | F12: 作業分担表（発注者） | G12: 【作業分担表】調査票原案の検討＝発注者／調査票原案の作成と補修正＝受託者／対象者抽出＝発注者／宛名ラベル作成・調査票の印刷・封筒の手配・ラベル貼付・発送回収経費負担（回収見込70％）・督促はがきの準備と発送・回収票開封・データ入力・集計・分析＝受託者／報告書の確認＝発注者／報告書の完成＝受託者 | H12: 町 | I12: 2026-08 | J12: 2026-08 | K12: 完了 | L12: 100 | M12: 1 | N12: 調査が実施されているため確認は済んでいる | O12: ―
A13: P2 ニーズ調査 | B13: 2-5 | C13: 対象者の抽出 | D13: 送付600件。手帳所持者508人では届かず対象拡大が必要 | E13: B1 障がい者ニーズ調査 | F13: 作業分担表（発注者） | G13: 【作業分担表】調査票原案の検討＝発注者／調査票原案の作成と補修正＝受託者／対象者抽出＝発注者／宛名ラベル作成・調査票の印刷・封筒の手配・ラベル貼付・発送回収経費負担（回収見込70％）・督促はがきの準備と発送・回収票開封・データ入力・集計・分析＝受託者／報告書の確認＝発注者／報告書の完成＝受託者 | H13: 町 | I13: 2026-08 | J13: 2026-09 | K13: 要対応 | L13: 80 | M13: 3 | N13: 抽出は完了し回答を得ている（障がい者259件・障がい児25件） | O13: **配布数と抽出方法が未記入。**前回は520人の層化無作為抽出であり、**全数配布か標本抽出かで経年比較の可否が決まる（依頼票D5）**
... A50: P8 完成・納品 | B50: 8-4 | C50: 納品・検収 | D50: 電子データ（Microsoft Word 2019以上の形式）。**印刷の指定はなし** | E50: B5 成果品の納品 | F50: 仕様書6 成果品② | G50: 【成果品②】②障がい者計画・第4期障がい児福祉計画・第8期障がい福祉計画 電子データ。※原稿作成、レイアウトデザイン（イラスト起こし数点）、リライト作業を含む。※電子データはMicrosoft Word 2019以上の形式で収録すること。 | H50: 受託者・町 | I50: 2027-03 | J50: 2027-03 | K50: 未着手 | L50: 0 | M50: 1 | N50: ― | O50: **完了日が公告（3月31日）と仕様書（3月25日）で異なる（依頼票C1）**

Sheet 02_段階サマリ
A1: 段階 | B1: 作業数 | C1: 完了 | D1: 進行中 | E1: 要対応 | F1: データ待ち | G1: 未着手 | H1: 加重進捗率 | I1: 予定開始 | J1: 予定完了 | K1: 律速要因
A2: P1 準備・現状把握 | B2: =COUNTIF('01_WBS'!$A$2:$A$50,$A2) | C2: =COUNTIFS('01_WBS'!$A$2:$A$50,$A2,'01_WBS'!$K$2:$K$50,"完了") | D2: =COUNTIFS('01_WBS'!$A$2:$A$50,$A2,'01_WBS'!$K$2:$K$50,"進行中") | E2: =COUNTIFS('01_WBS'!$A$2:$A$50,$A2,'01_WBS'!$K$2:$K$50,"要対応") | F2: =COUNTIFS('01_WBS'!$A$2:$A$50,$A2,'01_WBS'!$K$2:$K$50,"データ待ち") | G2: =COUNTIFS('01_WBS'!$A$2:$A$50,$A2,'01_WBS'!$K$2:$K$50,"未着手") | H2: =IF(SUMPRODUCT(('01_WBS'!$A$2:$A$50=$A2)*'01_WBS'!$M$2:$M$50)=0,0,SUMPRODUCT(('01_WBS'!$A$2:$A$50=$A2)*'01_WBS'!$L$2:$L$50*'01_WBS'!$M$2:$M$50)/SUMPRODUCT(('01_WBS'!$A$2:$A$50=$A2)*'01_WBS'!$M$2:$M$50)/100) | I2: 2026-06 | J2: 2026-09 | K2: 町データの受領（依頼7件・受領0件）
A3: P2 ニーズ調査 | B3: =COUNTIF('01_WBS'!$A$2:$A$50,$A3) | C3: =COUNTIFS('01_WBS'!$A$2:$A$50,$A3,'01_WBS'!$K$2:$K$50,"完了") | D3: =COUNTIFS('01_WBS'!$A$2:$A$50,$A3,'01_WBS'!$K$2:$K$50,"進行中") | E3: =COUNTIFS('01_WBS'!$A$2:$A$50,$A3,'01_WBS'!$K$2:$K$50,"要対応") | F3: =COUNTIFS('01_WBS'!$A$2:$A$50,$A3,'01_WBS'!$K$2:$K$50,"データ待ち") | G3: =COUNTIFS('01_WBS'!$A$2:$A$50,$A3,'01_WBS'!$K$2:$K$50,"未着手") | H3: =IF(SUMPRODUCT(('01_WBS'!$A$2:$A$50=$A3)*'01_WBS'!$M$2:$M$50)=0,0,SUMPRODUCT(('01_WBS'!$A$2:$A$50=$A3)*'01_WBS'!$L$2:$L$50*'01_WBS'!$M$2:$M$50)/SUMPRODUCT(('01_WBS'!$A$2:$A$50=$A3)*'01_WBS'!$M$2:$M$50)/100) | I3: 2026-07 | J3: 2026-11 | K3: **★0727版の入手（児童用の本文欠落）。工程全体の律速**
A4: P3 ヒアリング | B4: =COUNTIF('01_WBS'!$A$2:$A$50,$A4) | C4: =COUNTIFS('01_WBS'!$A$2:$A$50,$A4,'01_WBS'!$K$2:$K$50,"完了") | D4: =COUNTIFS('01_WBS'!$A$2:$A$50,$A4,'01_WBS'!$K$2:$K$50,"進行中") | E4: =COUNTIFS('01_WBS'!$A$2:$A$50,$A4,'01_WBS'!$K$2:$K$50,"要対応") | F4: =COUNTIFS('01_WBS'!$A$2:$A$50,$A4,'01_WBS'!$K$2:$K$50,"データ待ち") | G4: =COUNTIFS('01_WBS'!$A$2:$A$50,$A4,'01_WBS'!$K$2:$K$50,"未着手") | H4: =IF(SUMPRODUCT(('01_WBS'!$A$2:$A$50=$A4)*'01_WBS'!$M$2:$M$50)=0,0,SUMPRODUCT(('01_WBS'!$A$2:$A$50=$A4)*'01_WBS'!$L$2:$L$50*'01_WBS'!$M$2:$M$50)/SUMPRODUCT(('01_WBS'!$A$2:$A$50=$A4)*'01_WBS'!$M$2:$M$50)/100) | I4: 2026-08 | J4: 2026-11 | K4: 対象先の選定に必要な町のサービス実績
A5: P4 成果品① | B5: =COUNTIF('01_WBS'!$A$2:$A$50,$A5) | C5: =COUNTIFS('01_WBS'!$A$2:$A$50,$A5,'01_WBS'!$K$2:$K$50,"完了") | D5: =COUNTIFS('01_WBS'!$A$2:$A$50,$A5,'01_WBS'!$K$2:$K$50,"進行中") | E5: =COUNTIFS('01_WBS'!$A$2:$A$50,$A5,'01_WBS'!$K$2:$K$50,"要対応") | F5: =COUNTIFS('01_WBS'!$A$2:$A$50,$A5,'01_WBS'!$K$2:$K$50,"データ待ち") | G5: =COUNTIFS('01_WBS'!$A$2:$A$50,$A5,'01_WBS'!$K$2:$K$50,"未着手") | H5: =IF(SUMPRODUCT(('01_WBS'!$A$2:$A$50=$A5)*'01_WBS'!$M$2:$M$50)=0,0,SUMPRODUCT(('01_WBS'!$A$2:$A$50=$A5)*'01_WBS'!$L$2:$L$50*'01_WBS'!$M$2:$M$50)/SUMPRODUCT(('01_WBS'!$A$2:$A$50=$A5)*'01_WBS'!$M$2:$M$50)/100) | I5: 2026-10 | J5: 2026-12 | K5: 調査の集計とヒアリング記録
A6: P5 現状分析・課題 | B6: =COUNTIF('01_WBS'!$A$2:$A$50,$A6) | C6: =COUNTIFS('01_WBS'!$A$2:$A$50,$A6,'01_WBS'!$K$2:$K$50,"完了") | D6: =COUNTIFS('01_WBS'!$A$2:$A$50,$A6,'01_WBS'!$K$2:$K$50,"進行中") | E6: =COUNTIFS('01_WBS'!$A$2:$A$50,$A6,'01_WBS'!$K$2:$K$50,"要対応") | F6: =COUNTIFS('01_WBS'!$A$2:$A$50,$A6,'01_WBS'!$K$2:$K$50,"データ待ち") | G6: =COUNTIFS('01_WBS'!$A$2:$A$50,$A6,'01_WBS'!$K$2:$K$50,"未着手") | H6: =IF(SUMPRODUCT(('01_WBS'!$A$2:$A$50=$A6)*'01_WBS'!$M$2:$M$50)=0,0,SUMPRODUCT(('01_WBS'!$A$2:$A$50=$A6)*'01_WBS'!$L$2:$L$50*'01_WBS'!$M$2:$M$50)/SUMPRODUCT(('01_WBS'!$A$2:$A$50=$A6)*'01_WBS'!$M$2:$M$50)/100) | I6: 2026-08 | J6: 2026-11 | K6: 町のサービス実績・支給決定量
A7: P6 計画策定支援 | B7: =COUNTIF('01_WBS'!$A$2:$A$50,$A7) | C7: =COUNTIFS('01_WBS'!$A$2:$A$50,$A7,'01_WBS'!$K$2:$K$50,"完了") | D7: =COUNTIFS('01_WBS'!$A$2:$A$50,$A7,'01_WBS'!$K$2:$K$50,"進行中") | E7: =COUNTIFS('01_WBS'!$A$2:$A$50,$A7,'01_WBS'!$K$2:$K$50,"要対応") | F7: =COUNTIFS('01_WBS'!$A$2:$A$50,$A7,'01_WBS'!$K$2:$K$50,"データ待ち") | G7: =COUNTIFS('01_WBS'!$A$2:$A$50,$A7,'01_WBS'!$K$2:$K$50,"未着手") | H7: =IF(SUMPRODUCT(('01_WBS'!$A$2:$A$50=$A7)*'01_WBS'!$M$2:$M$50)=0,0,SUMPRODUCT(('01_WBS'!$A$2:$A$50=$A7)*'01_WBS'!$L$2:$L$50*'01_WBS'!$M$2:$M$50)/SUMPRODUCT(('01_WBS'!$A$2:$A$50=$A7)*'01_WBS'!$M$2:$M$50)/100) | I7: 2026-07 | J7: 2027-02 | K7: **素案の第2版改訂は条件なしで着手できる**
A8: P7 意見聴取 | B8: =COUNTIF('01_WBS'!$A$2:$A$50,$A8) | C8: =COUNTIFS('01_WBS'!$A$2:$A$50,$A8,'01_WBS'!$K$2:$K$50,"完了") | D8: =COUNTIFS('01_WBS'!$A$2:$A$50,$A8,'01_WBS'!$K$2:$K$50,"進行中") | E8: =COUNTIFS('01_WBS'!$A$2:$A$50,$A8,'01_WBS'!$K$2:$K$50,"要対応") | F8: =COUNTIFS('01_WBS'!$A$2:$A$50,$A8,'01_WBS'!$K$2:$K$50,"データ待ち") | G8: =COUNTIFS('01_WBS'!$A$2:$A$50,$A8,'01_WBS'!$K$2:$K$50,"未着手") | H8: =IF(SUMPRODUCT(('01_WBS'!$A$2:$A$50=$A8)*'01_WBS'!$M$2:$M$50)=0,0,SUMPRODUCT(('01_WBS'!$A$2:$A$50=$A8)*'01_WBS'!$L$2:$L$50*'01_WBS'!$M$2:$M$50)/SUMPRODUCT(('01_WBS'!$A$2:$A$50=$A8)*'01_WBS'!$M$2:$M$50)/100) | I8: 2026-08 | J8: 2027-02 | K8: 素案の確定、実施時期の確定
A9: P8 完成・納品 | B9: =COUNTIF('01_WBS'!$A$2:$A$50,$A9) | C9: =COUNTIFS('01_WBS'!$A$2:$A$50,$A9,'01_WBS'!$K$2:$K$50,"完了") | D9: =COUNTIFS('01_WBS'!$A$2:$A$50,$A9,'01_WBS'!$K$2:$K$50,"進行中") | E9: =COUNTIFS('01_WBS'!$A$2:$A$50,$A9,'01_WBS'!$K$2:$K$50,"要対応") | F9: =COUNTIFS('01_WBS'!$A$2:$A$50,$A9,'01_WBS'!$K$2:$K$50,"データ待ち") | G9: =COUNTIFS('01_WBS'!$A$2:$A$50,$A9,'01_WBS'!$K$2:$K$50,"未着手") | H9: =IF(SUMPRODUCT(('01_WBS'!$A$2:$A$50=$A9)*'01_WBS'!$M$2:$M$50)=0,0,SUMPRODUCT(('01_WBS'!$A$2:$A$50=$A9)*'01_WBS'!$L$2:$L$50*'01_WBS'!$M$2:$M$50)/SUMPRODUCT(('01_WBS'!$A$2:$A$50=$A9)*'01_WBS'!$M$2:$M$50)/100) | I9: 2027-02 | J9: 2027-03 | K9: **レイアウトデザイン・イラスト起こしの工程が未確保**
A10: 合計 | B10: =SUM(B2:B9) | C10: =SUM(C2:C9) | D10: =SUM(D2:D9) | E10: =SUM(E2:E9) | F10: =SUM(F2:F9) | G10: =SUM(G2:G9) | H10: =IF(SUM('01_WBS'!$M$2:$M$50)=0,0,SUMPRODUCT('01_WBS'!$L$2:$L$50,'01_WBS'!$M$2:$M$50)/SUM('01_WBS'!$M$2:$M$50)/100) | I10: 2026-06 | J10: 2027-03
A12: ※ 加重進捗率＝Σ（進捗率×重み）÷Σ重み。重みは工数の目安（1〜5）。
A13: ※ 各作業が仕様書のどの条項にあたるかは 01_WBS のE列・F列、条項の網羅状況は 09_仕様書対応表 を参照。
A14: ※ 01_WBS の「状態」「進捗率」を書き換えると、本表とダッシュボードが再計算されます。

Sheet 03_成果品管理
A1: 成果品 | B1: 名称 | C1: 納品仕様 | D1: 版 | E1: 状態 | F1: 進捗率 | G1: 現状 | H1: 確定に必要なもの
A2: ① | B2: アンケート調査結果及びヒアリング調査結果報告書 | C2: 電子データ | D2: ― | E2: 未着手 | F2: 15 | G2: ヒアリングの実施計画書と質問票6種は作成済み。調査は未実施 | H2: 調査の実施と集計、ヒアリングの実施
A3: ② | B3: 障がい者計画・第4期障がい児福祉計画・第8期障がい福祉計画 | C3: 電子データ（Word 2019以上）。原稿作成、レイアウトデザイン（イラスト起こし数点）、リライトを含む | D3: 初版（拡充版） | E3: 進行中 | F3: 30 | G3: 骨子案は作成済み。素案は引継ぎ時点のまま | H3: 調査結果、実績データ、協議会での合意、**デザイン工程の確保**
A4: ※ 進捗率は目安。納品仕様（製本・印刷）を満たして初めて完了となる。

Sheet 04_工程表
A1: 時期 | B1: 作業 | C1: 担当 | D1: 状態 | E1: 備考
A2: 2026-08 | B2: 調査票の確定、対象者抽出の照会、協議会 第1回（8月19日） | C2: 受託者・町 | D2: 要対応 | E2: **★0727版の入手が前提**
A3: 2026-09 | B3: 調査の発送、ヒアリングの依頼・日程調整 | C3: 受託者 | D3: 未着手 | E3: 9月中旬の発送が回収率確保の条件
A4: 2026-09〜10 | B4: ヒアリングの実施（20〜27件） | C4: 受託者 | D4: 未着手 | E4: アンケートと並行
A5: 2026-10 | B5: 督促はがきの発送、回答期限、開封・入力 | C5: 受託者 | D5: 未着手 | E5: ―
A6: 2026-11 | B6: 集計・分析、ヒアリング記録の作成、骨子案の更新 | C6: 受託者 | D6: 未着手 | E6: ―
A7: 2026-12 | B7: 成果品①の完成、素案の作成、協議会 第2回（調査結果・骨子案・見込量） | C7: 受託者・町 | D7: 未着手 | E7: **骨子案を12月の回で諮り工程に復活させる**
A8: 2027-01 | B8: 素案の確定、パブリックコメント（1か月） | C8: 受託者・町 | D8: 未着手 | E8: ―
A9: 2027-02 | B9: 意見への対応、計画案の作成、協議会 第3回（最終案） | C9: 受託者・町 | D9: 未着手 | E9: **仕様書8②の3回に収まる**
A10: 2027-03 | B10: レイアウトデザイン・イラスト起こし、リライト、納品 | C10: 受託者 | D10: 未着手 | E10: **完了日が公告と仕様書で異なる**

Sheet 05_資料・データ受領
A1: No | B1: 資料・データ | C1: 提供元 | D1: 状態 | E1: 受領日 | F1: 使途・備考
A2: 町資料 | B2: 障がい福祉計画ワークシート（人口・手帳・R5〜R8サービス実績） | C2: 町 | D2: 完了 | E2: 2026-09-07 | F2: **見込量・目標値設定シートの基礎データとして受領。**ただし地域生活支援事業のR6〜R8実績は大半が未入力で、精神障がい者の内数が総数を超える箇所がある
A3: 受託者 | B3: 見込量・目標値設定シート（9シート）＋レッドチームレビュー | C3: 受託者 | D3: 完了 | E3: 2026-09-07 | F3: **算式は全行再現一致。重大5件を含む16件の不具合を検出**（04_算定・見込量）
A4: 町資料 | B4: ★0727版アンケート調査票（一般用・児童用） | C4: 町・他メンバー | D4: 要対応 | E4: ― | F4: **児童用に28箇所以上の本文欠落。復元の照合元。工程全体の律速**
A5: 町資料 | B5: 障がい者ニーズ調査の対象者数（区分①〜⑩） | C5: 町 | D5: 要対応 | E5: ― | F5: **手帳所持者508人では600件に届かない。所管課をまたぐ照会で2〜3週間**
A6: 町資料 | B6: 前回調査（令和5年10月）の実施方法 | C6: 町 | D6: 未着手 | E6: ― | F6: **督促はがきを発送したか。54.3％が督促込みか否かで実施設計が変わる**
A7: 町資料 | B7: 令和6〜8年度 障害福祉サービスの実績（町内外事業所別） | C7: 町 | D7: 要対応 | E7: ― | F7: **サービス別の総量はワークシートで受領済み。町内外事業所別の内訳が未受領で、ヒアリング対象先の選定ができない**
A8: 町資料 | B8: セルフプラン件数、相談支援専門員数 | C8: 町 | D8: 未着手 | E8: ― | F8: 国の新規成果目標「望まないセルフプランゼロ」の起点
A9: 町資料 | B9: 特別支援学校卒業予定者、医療的ケア児の状況 | C9: 町 | D9: 未着手 | E9: ― | F9: 18歳移行の見込量
A10: 町資料 | B10: 障害支援区分の認定状況 | C10: 町 | D10: 未着手 | E10: ― | F10: 見込量算定の基礎
A11: 既受領 | B11: 現行計画（第7期・第3期）本文 | C11: 町 | D11: 完了 | E11: 2026-07以前 | F11: 3部構成・9分野
A12: 既受領 | B12: 前回アンケート結果（障がい者280件・障がい児22件） | C12: 町 | D12: 完了 | E12: 2026-07以前 | F12: 計画接続マトリクスを作成済み
A13: 既受領 | B13: 手帳所持者数（令和5年539人→令和7年508人） | C13: 町 | D13: 完了 | E13: 2026-07以前 | F13: 身体▲9.7％、療育▲9.8％、精神＋37.8％
A14: ※ 依頼の詳細（粒度・様式・基準日）は 16_町データ依頼/小野町_データ依頼票 を参照。

Sheet 06_会議体・意見聴取
A1: 区分 | B1: 回 | C1: 時期 | D1: 議題 | E1: 資料の状態 | F1: 備考
A2: 自立支援協議会 | B2: 第1回 | C2: 令和8年8月19日 | D2: 前回計画の総括、動向、次期計画の方向性 | E2: 完了 | F2: **資料第3版を作成済み**
A3: 自立支援協議会 | B3: 第2回 | C3: 令和8年12月 | D3: 調査結果、ヒアリング結果、**骨子案**、サービス見込量の考え方 | E3: 進行中 | F3: **仕様書7では10月に骨子案検討の回。工程変更により12月に統合する案**
A4: 自立支援協議会 | B4: 第3回 | C4: 令和9年2月 | D4: 計画最終案の確認 | E4: 未着手 | F4: **仕様書8②の3回に収まる**
A5: パブリックコメント | B5: ― | C5: 令和9年1月 | D5: 計画素案に対する意見の募集 | E5: 完了 | F5: 様式は作成済み（高齢者計画と共通）
A6: 関係者団体等ヒアリング | B6: 6区分 | C6: 令和8年9〜10月 | D6: 相談支援・サービス事業所・教育・医療・防災・当事者団体 | E6: 完了 | F6: **実施計画書と質問票6種（大問35・小問102）を作成済み**
A7: 町との打合せ | B7: 随時 | C7: 通年 | D7: 工程、調査票、対象者抽出、協議事項 | E7: 完了 | F7: 仕様書8①により受託者が記録を作成し相互確認する

Sheet 07_課題・リスク
A1: No | B1: 課題・リスク | C1: 内容 | D1: 影響 | E1: 対応 | F1: 状態
A2: 1 | B2: 児童用調査票の本文欠落 | C2: ★0727版に28箇所以上の欠落があり配布不可。当該ファイルが手元にない | D2: 調査の発送ができず、工程全体が遅延する | E2: **一般用を先行発送し児童用を2週間遅らせる分岐案を用意。**★0727版の入手を町に依頼 | F2: 要対応
A3: 2 | B3: 仕様書工程からの遅延 | C3: 調査は7月まで、骨子案9月、骨子案検討10月とされているが、いずれも未実施 | D3: 契約上の工程変更にあたる | E3: **工程変更協議資料を作成済み。**仕様書11④により町と協議し、8①により記録化する | F3: 要対応
A4: 3 | B4: 回収率目標の未達 | C4: 仕様は送付600件・回収400件程度（66.7％）。前回実績は54.3％ | D4: 分析の代表性が下がる | E4: **回収率を9要素に分解し逆算工程を作成済み。**前回が督促込みだった場合は電子回答の併用が必須 | F4: 進行中
A5: 4 | B5: 母集団が600件に満たない可能性 | C5: 手帳所持者508人。重複所持を除くと実人数はさらに少ない | D5: 回収数400件が達成不能になる | E5: **抽出条件案（区分①〜⑩）で対象を拡大。回収率で見るか回収数で見るかを抽出前に町と合意する** | F5: 要対応
A6: 5 | B6: 関係者団体等ヒアリングの未実施 | C6: 仕様書5(3)及び成果品①が求める業務項目 | D6: 成果品①が完成しない | E6: **実施計画書と質問票6種を作成済み。**対象先の選定に町のサービス実績が必要 | F6: 進行中
A7: 6 | B7: 人口推計の出典の不一致 | C7: 高齢者計画は見える化（社人研）、障がい計画は地域福祉計画（コーホート変化率法）。最大310人・3.4％の差 | D7: 同年度に公表する2計画で数値が食い違う | E7: 8月19日の自立支援協議会で協議し統一する | F7: 要対応
A8: 7 | B8: レイアウトデザイン・イラスト起こしの工程未確保 | C8: 仕様書6は成果品②に「原稿作成、レイアウトデザイン（イラスト起こし数点）、リライト作業を含む」と定める | D8: 納期に間に合わない | E8: 令和9年2〜3月にデザイン工程を確保する | F8: 未着手
A9: 8 | B9: 完了日の不一致 | C9: 公告第1-36号は令和9年3月31日、仕様書4は3月25日。**高齢者計画は3月31日であり、両計画で納期が異なる** | D9: 納期の認識齟齬 | E9: 町に確認する（依頼票C1） | F9: 進行中
A10: 9 | B10: クロス集計軸に性別が欠けていた | C10: 仕様書5(1)は性別・年齢別・障がい別・地域別を明示要件とするが、接続表に性別が未記載 | D10: 仕様を満たさない集計になる | E10: **集計軸9種に性別を追加済み。**調査票の確定と併せて接続表を改訂する | F10: 進行中
A11: 10 | B11: 地域別集計の粒度 | C11: 行政区単位では1セルあたりの回答数が1桁になり、個人が特定されうる | D11: 地域別集計が公表できない | E11: 小学校区又はこれに準じる粒度とすることを町に提案する（依頼票C12） | F11: 進行中
A12: 11 | B12: 素案の第2版改訂が未着手 | C12: 引継ぎ時点の拡充版のまま。地域福祉計画との役割分担、国の基本指針の8分野、望まないセルフプランゼロ等が未反映 | D12: 12月の協議会に諮る素案が間に合わない | E12: **外部の条件に依存せず着手できる。次に着手する** | F12: 進行中
A13: 12 | B13: 成果目標に2分野が欠落している | C13: 受領した設定シートに「精神障害にも対応した地域包括ケアシステムの構築」と「人材確保・生産性向上」の成果目標がない。**小野町では精神障害者保健福祉手帳所持者が45人→62人（＋37.8％）と3手帳で唯一増加しており、最も伸びている分野の目標がない** | D13: 計画の法定要件を欠く可能性。活動指標も連動して欠落する | E13: 成果目標に2分野を追加する。精神は保健所・圏域の精神科医療機関との調整が前提（ヒアリング区分D） | F13: 要対応
... A17: 16 | B17: 仕様書5の（２）欠番 | C17: 「５ 委託業務の内容」は（１）→（３）と続き、（２）が存在しない | D17: 削除された業務項目がある可能性 | E17: 町に確認する（依頼票C3） | F17: 進行中

Sheet 08_変更管理・打合せ記録
A1: No | B1: 区分 | C1: 内容 | D1: 根拠 | E1: 状態 | F1: 記録の有無
A2: 1 | B2: 工程 | C2: 仕様書7の工程から3〜4か月の遅延。9月の骨子案作成と10月の骨子案検討が失われている | D2: 仕様書7・11④ | E2: 要対応 | F2: **変更後の工程案を作成済み（12月の第2回に骨子案を統合）。町との合意が未**
A3: 2 | B3: 骨子案 | C3: 工程から骨子案が消えている。仕様書5(4)の明示的な工程 | D3: 仕様書5(4)・7 | E3: 要対応 | F3: **12月の協議会に復活させる案。合意が未**
A4: 3 | B4: ヒアリング | C4: 実施も計画もされていなかった。成果品①を構成する業務項目 | D4: 仕様書5(3)・成果品① | E4: 進行中 | F4: **実施計画書と質問票を作成済み。町への説明が必要**
A5: 4 | B5: 集計軸 | C5: 仕様が明示する性別が接続表に欠けていた | D5: 仕様書5(1) | E5: 進行中 | F5: 受託者の内部修正。調査票の確定と併せて反映する
A6: 5 | B6: 調査の発送時期 | C6: 仕様書は7月まで。実施設計では9月中旬 | D6: 仕様書5(1)・7 | E6: 要対応 | F6: 工程変更協議資料に含めて協議する
A7: 6 | B7: 電子回答の併用 | C7: 仕様書に定めがない。回収率確保の手段として提案 | D7: 仕様書5(1) | E7: 未着手 | F7: 町の可否判断が必要（依頼票C11）
A8: 7 | B8: 打合せ記録 | C8: 契約後の打合せ記録が引継ぎ資料に含まれていない | D8: 仕様書8① | E8: 要対応 | F8: **様式を作成済み。8月19日の協議会から適用する**
A9: ※ 仕様書8①により、打合せ記録は受託者が作成し町と相互に確認する。
A10: ※ 様式は 02_キックオフ・業務計画/小野町_工程変更協議資料 の第5節。

Sheet 09_仕様書対応表
A1: 区分 | B1: 条項 | C1: 仕様書の記載内容（原文） | D1: 対応する作業（01_WBS） | E1: 作業数 | F1: 網羅
A2: 目的・期間 | B2: 2 | C2: 障がいのある人が自立した生活のもと安心して暮らすことができるとともに、障がいのある人もない人も一人の人間として尊重され、互いに思いやりを持って生き生きと暮らせるまちづくりを進めるため、国が定める基本指針や県の計画、当町の現行計画を踏まえ、おのまち障がい者計画・第4期障がい児福祉計画・第8期障がい福祉計画を策定するものとする。 | D2: ― | E2: 0 | F2: 前提条項
A3: 目的・期間 | B3: 4 | C3: 契約締結日から令和9年3月25日まで（※公告第1-36号は令和9年3月31日） | D3: ― | E3: 0 | F3: 前提条項
A4: 目的・期間 | B4: 7 | C4: スケジュール。6月 業者選定・契約締結／〜7月 アンケート調査・統計整理／〜8月 アンケート調査・課題分析（自立支援協議会による検討）／9月 骨子案作成／10月 骨子案検討（自立支援協議会による検討）／〜12月 素案作成／〜1月 素案検討（自立支援協議会による検討・パブリックコメントの実施）／〜2月 計画書承認・校正・計画書完成／3月 契約完了 | D4: 6-2 骨子案の協議（自立支援協議会） 6-6 素案の協議（自立支援協議会） 7-2 パブリックコメントの実施 | E4: 3 | F4: ○
A5: 委託業務の内容 | B5: 5(1) | C5: 障がい者ニーズ調査。アンケート調査により、障がい福祉サービスの実態や障がい者の意向などを把握し分析・課題の抽出等を行う。単純集計の他、性別・年齢別・障がい別・地域別等の必要なクロス集計、自由回答のとりまとめを含めて行い、町の現状や課題などを抽出・把握し、計画策定のための基礎資料となるものと位置づける。アンケート等の作成及び発送については受託者が実施する。受託者はアンケート等回収票の開封、データ入力、集計、分析、課題整理を行う。なお、アンケート等の送付数は600件程度であり、回収数は400件程度を見込んでいる。 | D5: 1-5 町への資料依頼票の作成 1-6 町データの受領 2-2 調査実施設計 | E5: 3 | F5: ○
A6: 委託業務の内容 | B6: 5(1)①ア | C6: 委託事項（ア）調査内容の企画 | D6: 2-1 調査内容の企画 | E6: 1 | F6: ○
A7: 委託業務の内容 | B7: 5(1)①イ | C7: 委託事項（イ）調査票の作成 | D7: 2-3 調査票の作成と補修正 | E7: 1 | F7: ○
A8: 委託業務の内容 | B8: 5(1)①ウ | C8: 委託事項（ウ）調査用品の準備・印刷。※印刷物は墨印刷とする。発送封筒は角2封筒、返送は長3封筒（テープ加工）を用いる。※対象者の抽出は当町にて行い、受託者が宛名ラベルの作成を行う。 | D8: 2-6 調査用品の準備・印刷 | E8: 1 | F8: ○
A9: 委託業務の内容 | B9: 5(1)①エ | C9: 委託事項（エ）調査の実施（郵送での発送返送） | D9: 2-8 調査の発送・回収 | E9: 1 | F9: ○
A10: 委託業務の内容 | B10: 5(1)①オ | C10: 委託事項（オ）御礼を兼ねた督促はがきの発送準備 | D10: 2-9 督促はがきの準備・発送 | E10: 1 | F10: ○
A11: 委託業務の内容 | B11: 5(1)①カ | C11: 委託事項（カ）御礼を兼ねた督促はがきの発送 | D11: 2-9 督促はがきの準備・発送 | E11: 1 | F11: ○
A12: 委託業務の内容 | B12: 5(1)①キ | C12: 委託事項（キ）回収票点検〜データ入力（自由意見の入力整理）〜チェック〜集計 | D12: 2-10 回収票の点検・ナンバリング・データ入力 | E12: 1 | F12: ○
A13: 委託業務の内容 | B13: 5(1)①ク | C13: 委託事項（ク）分析（単純集計・クロス集計からの分析） | D13: 2-11 集計・分析 2-12 分析報告書のレビュー 2-14 アンケートで不足する事項の洗い出しと対応方針 2-15 介護保険の利用の有無による問31の再集計 | E13: 4 | F13: ○
... A23: 打合せ・その他 | B23: 公告10⑥ | C23: 自治体の当該計画策定や調査研究実績があり、本計画策定の実務を担う者（公告第1-36号 10⑥） | D23: 1-1 契約・体制の確立、キックオフ | E23: 1 | F23: ○
A25: ※ 「要確認」は、01_WBS に対応する作業が置かれていない条項です。業務の抜けを疑ってください。
A26: ※ 「前提条項」は、目的・計画期間・個人情報の取扱いなど、作業として分解せず業務全体で担保する条項です。

Sheet 10_ブロック別進捗
A1: 仕様書ブロック | B1: 該当条項 | C1: 作業数 | D1: 完了 | E1: 進行中 | F1: 要対応 | G1: データ待ち | H1: 未着手 | I1: 加重進捗率 | J1: 現況・律速
A2: B1 障がい者ニーズ調査 | B2: 5(1)、5(1)①ア、5(1)①イ、5(1)①ウ、5(1)①エ、5(1)①オ ほか | C2: =COUNTIF('01_WBS'!$E$2:$E$50,$A2) | D2: =COUNTIFS('01_WBS'!$E$2:$E$50,$A2,'01_WBS'!$K$2:$K$50,"完了") | E2: =COUNTIFS('01_WBS'!$E$2:$E$50,$A2,'01_WBS'!$K$2:$K$50,"進行中") | F2: =COUNTIFS('01_WBS'!$E$2:$E$50,$A2,'01_WBS'!$K$2:$K$50,"要対応") | G2: =COUNTIFS('01_WBS'!$E$2:$E$50,$A2,'01_WBS'!$K$2:$K$50,"データ待ち") | H2: =COUNTIFS('01_WBS'!$E$2:$E$50,$A2,'01_WBS'!$K$2:$K$50,"未着手") | I2: =IF(SUMPRODUCT(('01_WBS'!$E$2:$E$50=$A2)*'01_WBS'!$M$2:$M$50)=0,"―",SUMPRODUCT(('01_WBS'!$E$2:$E$50=$A2)*'01_WBS'!$L$2:$L$50*'01_WBS'!$M$2:$M$50)/SUMPRODUCT(('01_WBS'!$E$2:$E$50=$A2)*'01_WBS'!$M$2:$M$50)/100) | J2: **実施設計は完了。★0727版が入手できず調査票が確定しないため発送できない**
A3: B2 現状分析と課題の整理 | B3: 5(3) | C3: =COUNTIF('01_WBS'!$E$2:$E$50,$A3) | D3: =COUNTIFS('01_WBS'!$E$2:$E$50,$A3,'01_WBS'!$K$2:$K$50,"完了") | E3: =COUNTIFS('01_WBS'!$E$2:$E$50,$A3,'01_WBS'!$K$2:$K$50,"進行中") | F3: =COUNTIFS('01_WBS'!$E$2:$E$50,$A3,'01_WBS'!$K$2:$K$50,"要対応") | G3: =COUNTIFS('01_WBS'!$E$2:$E$50,$A3,'01_WBS'!$K$2:$K$50,"データ待ち") | H3: =COUNTIFS('01_WBS'!$E$2:$E$50,$A3,'01_WBS'!$K$2:$K$50,"未着手") | I3: =IF(SUMPRODUCT(('01_WBS'!$E$2:$E$50=$A3)*'01_WBS'!$M$2:$M$50)=0,"―",SUMPRODUCT(('01_WBS'!$E$2:$E$50=$A3)*'01_WBS'!$L$2:$L$50*'01_WBS'!$M$2:$M$50)/SUMPRODUCT(('01_WBS'!$E$2:$E$50=$A3)*'01_WBS'!$M$2:$M$50)/100) | J3: 前回調査による検証は済み。今期調査・ヒアリングの結果待ち
A4: B3 計画策定支援業務 | B4: 5(4) | C4: =COUNTIF('01_WBS'!$E$2:$E$50,$A4) | D4: =COUNTIFS('01_WBS'!$E$2:$E$50,$A4,'01_WBS'!$K$2:$K$50,"完了") | E4: =COUNTIFS('01_WBS'!$E$2:$E$50,$A4,'01_WBS'!$K$2:$K$50,"進行中") | F4: =COUNTIFS('01_WBS'!$E$2:$E$50,$A4,'01_WBS'!$K$2:$K$50,"要対応") | G4: =COUNTIFS('01_WBS'!$E$2:$E$50,$A4,'01_WBS'!$K$2:$K$50,"データ待ち") | H4: =COUNTIFS('01_WBS'!$E$2:$E$50,$A4,'01_WBS'!$K$2:$K$50,"未着手") | I4: =IF(SUMPRODUCT(('01_WBS'!$E$2:$E$50=$A4)*'01_WBS'!$M$2:$M$50)=0,"―",SUMPRODUCT(('01_WBS'!$E$2:$E$50=$A4)*'01_WBS'!$L$2:$L$50*'01_WBS'!$M$2:$M$50)/SUMPRODUCT(('01_WBS'!$E$2:$E$50=$A4)*'01_WBS'!$M$2:$M$50)/100) | J4: **骨子案は作成済み。素案の第2版改訂は外部条件に依存せず着手できるが未着手**
A5: B4 パブリックコメントの実施支援 | B5: 5(5) | C5: =COUNTIF('01_WBS'!$E$2:$E$50,$A5) | D5: =COUNTIFS('01_WBS'!$E$2:$E$50,$A5,'01_WBS'!$K$2:$K$50,"完了") | E5: =COUNTIFS('01_WBS'!$E$2:$E$50,$A5,'01_WBS'!$K$2:$K$50,"進行中") | F5: =COUNTIFS('01_WBS'!$E$2:$E$50,$A5,'01_WBS'!$K$2:$K$50,"要対応") | G5: =COUNTIFS('01_WBS'!$E$2:$E$50,$A5,'01_WBS'!$K$2:$K$50,"データ待ち") | H5: =COUNTIFS('01_WBS'!$E$2:$E$50,$A5,'01_WBS'!$K$2:$K$50,"未着手") | I5: =IF(SUMPRODUCT(('01_WBS'!$E$2:$E$50=$A5)*'01_WBS'!$M$2:$M$50)=0,"―",SUMPRODUCT(('01_WBS'!$E$2:$E$50=$A5)*'01_WBS'!$L$2:$L$50*'01_WBS'!$M$2:$M$50)/SUMPRODUCT(('01_WBS'!$E$2:$E$50=$A5)*'01_WBS'!$M$2:$M$50)/100) | J5: 様式は作成済み。実施時期の確定待ち
A6: B5 成果品の納品 | B6: 成果品①、成果品② | C6: =COUNTIF('01_WBS'!$E$2:$E$50,$A6) | D6: =COUNTIFS('01_WBS'!$E$2:$E$50,$A6,'01_WBS'!$K$2:$K$50,"完了") | E6: =COUNTIFS('01_WBS'!$E$2:$E$50,$A6,'01_WBS'!$K$2:$K$50,"進行中") | F6: =COUNTIFS('01_WBS'!$E$2:$E$50,$A6,'01_WBS'!$K$2:$K$50,"要対応") | G6: =COUNTIFS('01_WBS'!$E$2:$E$50,$A6,'01_WBS'!$K$2:$K$50,"データ待ち") | H6: =COUNTIFS('01_WBS'!$E$2:$E$50,$A6,'01_WBS'!$K$2:$K$50,"未着手") | I6: =IF(SUMPRODUCT(('01_WBS'!$E$2:$E$50=$A6)*'01_WBS'!$M$2:$M$50)=0,"―",SUMPRODUCT(('01_WBS'!$E$2:$E$50=$A6)*'01_WBS'!$L$2:$L$50*'01_WBS'!$M$2:$M$50)/SUMPRODUCT(('01_WBS'!$E$2:$E$50=$A6)*'01_WBS'!$M$2:$M$50)/100) | J6: **成果品①はヒアリングの実施が前提。②はレイアウトデザイン工程が未確保**
A7: B6 業務管理・打合せ | B7: 2、4、7、8①、8②、11④ ほか | C7: =COUNTIF('01_WBS'!$E$2:$E$50,$A7) | D7: =COUNTIFS('01_WBS'!$E$2:$E$50,$A7,'01_WBS'!$K$2:$K$50,"完了") | E7: =COUNTIFS('01_WBS'!$E$2:$E$50,$A7,'01_WBS'!$K$2:$K$50,"進行中") | F7: =COUNTIFS('01_WBS'!$E$2:$E$50,$A7,'01_WBS'!$K$2:$K$50,"要対応") | G7: =COUNTIFS('01_WBS'!$E$2:$E$50,$A7,'01_WBS'!$K$2:$K$50,"データ待ち") | H7: =COUNTIFS('01_WBS'!$E$2:$E$50,$A7,'01_WBS'!$K$2:$K$50,"未着手") | I7: =IF(SUMPRODUCT(('01_WBS'!$E$2:$E$50=$A7)*'01_WBS'!$M$2:$M$50)=0,"―",SUMPRODUCT(('01_WBS'!$E$2:$E$50=$A7)*'01_WBS'!$L$2:$L$50*'01_WBS'!$M$2:$M$50)/SUMPRODUCT(('01_WBS'!$E$2:$E$50=$A7)*'01_WBS'!$M$2:$M$50)/100) | J7: **仕様書工程から3〜4か月遅延。工程変更の協議と記録化が要対応**
A8: B7 仕様書に定めのない作業 | B8: （該当条項なし） | C8: =COUNTIF('01_WBS'!$E$2:$E$50,$A8) | D8: =COUNTIFS('01_WBS'!$E$2:$E$50,$A8,'01_WBS'!$K$2:$K$50,"完了") | E8: =COUNTIFS('01_WBS'!$E$2:$E$50,$A8,'01_WBS'!$K$2:$K$50,"進行中") | F8: =COUNTIFS('01_WBS'!$E$2:$E$50,$A8,'01_WBS'!$K$2:$K$50,"要対応") | G8: =COUNTIFS('01_WBS'!$E$2:$E$50,$A8,'01_WBS'!$K$2:$K$50,"データ待ち") | H8: =COUNTIFS('01_WBS'!$E$2:$E$50,$A8,'01_WBS'!$K$2:$K$50,"未着手") | I8: =IF(SUMPRODUCT(('01_WBS'!$E$2:$E$50=$A8)*'01_WBS'!$M$2:$M$50)=0,"―",SUMPRODUCT(('01_WBS'!$E$2:$E$50=$A8)*'01_WBS'!$L$2:$L$50*'01_WBS'!$M$2:$M$50)/SUMPRODUCT(('01_WBS'!$E$2:$E$50=$A8)*'01_WBS'!$M$2:$M$50)/100) | J8: 該当なし。仕様書のいずれかの条項に紐づかない作業が発生した場合はここに現れる
A9: 合計 | C9: =SUM(C2:C8) | D9: =SUM(D2:D8) | E9: =SUM(E2:E8) | F9: =SUM(F2:F8) | G9: =SUM(G2:G8) | H9: =SUM(H2:H8) | I9: =IF(SUM('01_WBS'!$M$2:$M$50)=0,0,SUMPRODUCT('01_WBS'!$L$2:$L$50,'01_WBS'!$M$2:$M$50)/SUM('01_WBS'!$M$2:$M$50)/100)
A11: ※ 段階（02_段階サマリ）は業務の進み方の切り口、ブロックは委託契約上の業務単位の切り口です。同じ作業を別の軸で見ています。
A12: ※ 作業が複数の条項にまたがる場合は、先頭の条項が属するブロックに数えています。

Sheet 11_進捗の乖離
A1: 段階 | B1: No | C1: 作業 | D1: 担当 | E1: 予定開始 | F1: 予定完了 | G1: 状態 | H1: 実績進捗率 | I1: 予定進捗率 | J1: 乖離 | K1: 重み | L1: 判定 | M1: 前提条件・ブロッカー
A2: P1 準備・現状把握 | B2: 1-6 | C2: 町データの受領 | D2: 町 | E2: 2026-08 | F2: 2026-09 | G2: 未着手 | H2: 0 | I2: 100 | J2: -100 | K2: 4 | L2: 期限超過（1か月） | M2: **町の回答。P2・P5・P6が依存する**
A3: P3 ヒアリング | B3: 3-2 | C3: 対象先の選定 | D3: 受託者・町 | E3: 2026-08 | F3: 2026-09 | G3: 未着手 | H3: 0 | I3: 100 | J3: -100 | K3: 2 | L3: 期限超過（1か月） | M3: **町のサービス実績（町内外事業所別・依頼票D4）**
A4: P3 ヒアリング | B4: 3-3 | C4: 依頼の送付・日程調整 | D4: 受託者 | E4: 2026-09 | F4: 2026-09 | G4: 未着手 | H4: 0 | I4: 100 | J4: -100 | K4: 1 | L4: 期限超過（1か月） | M4: 対象先の選定
A5: P3 ヒアリング | B5: 3-4 | C5: ヒアリングの実施 | D5: 受託者 | E5: 2026-09 | F5: 2026-10 | G5: 未着手 | H5: 0 | I5: 60 | J5: -60 | K5: 4 | L5: 遅れ | M5: 日程調整
A6: P1 準備・現状把握 | B6: 1-7 | C6: 工程変更の協議と打合せ記録の作成 | D6: 受託者・町 | E6: 2026-08 | F6: 2026-08 | G6: 要対応 | H6: 40 | I6: 100 | J6: -60 | K6: 2 | L6: 期限超過（2か月） | M6: **町との協議。8月19日の協議会またはその前後に行う**
A7: P2 ニーズ調査 | B7: 2-9 | C7: 督促はがきの準備・発送 | D7: 受託者 | E7: 2026-08 | F7: 2026-09 | G7: 要対応 | H7: 50 | I7: 100 | J7: -50 | K7: 1 | L7: 期限超過（1か月） | M7: **今回の督促の実施の有無が未確認。**配布数とあわせて確認する（依頼票D5）
A8: P2 ニーズ調査 | B8: 2-5 | C8: 対象者の抽出 | D8: 町 | E8: 2026-08 | F8: 2026-09 | G8: 要対応 | H8: 80 | I8: 100 | J8: -20 | K8: 3 | L8: 期限超過（1か月） | M8: **配布数と抽出方法が未記入。**前回は520人の層化無作為抽出であり、**全数配布か標本抽出かで経年比較の可否が決まる（依頼票D5）**
A9: P2 ニーズ調査 | B9: 2-16 | C9: 確認票の2枚化（町向け・事業所向け） | D9: 受託者 | E9: 2026-10 | F9: 2026-10 | G9: 未着手 | H9: 0 | I9: 20 | J9: -20 | K9: 2 | L9: 遅れ | M9: 2-15の結果（短期入所の照会の主題が変わる）
A10: P6 計画策定支援 | B10: 6-1 | C10: 骨子案の作成 | D10: 受託者 | E10: 2026-07 | F10: 2026-11 | G10: 進行中 | H10: 60 | I10: 64.5 | J10: -4.5 | K10: 3 | L10: おおむね予定どおり | M10: 調査結果の反映
A11: P5 現状分析・課題 | B11: 5-1 | C11: 現行計画の取組み状況の検証 | D11: 受託者 | E11: 2026-08 | F11: 2026-10 | G11: 進行中 | H11: 70 | I11: 73.6 | J11: -3.6 | K11: 3 | L11: おおむね予定どおり | M11: **前回計画31項目の令和8年度末の実績（依頼票D6）。**目標値は受領済みのため、残るのは実績のみ
A12: P5 現状分析・課題 | B12: 5-4 | C12: 人口推計の出典の統一 | D12: 受託者・町 | E12: 2026-08 | F12: 2026-10 | G12: 要対応 | H12: 70 | I12: 73.6 | J12: -3.6 | K12: 1 | L12: おおむね予定どおり | M12: **町の判断（4件）。計画本文の出典、男女別5歳階級の住基人口の提供、障がい児の見込量を再計算するか、保険料算定に第10期推計を使うこと**
A13: P7 意見聴取 | B13: 7-4 | C13: 自立支援協議会への出席（3回） | D13: 受託者 | E13: 2026-08 | F13: 2027-02 | G13: 進行中 | H13: 30 | I13: 31.8 | J13: -1.8 | K13: 2 | L13: おおむね予定どおり | M13: 第2回・第3回の時期は工程変更の協議による
... A50: P2 ニーズ調査 | B50: 2-14 | C50: アンケートで不足する事項の洗い出しと対応方針 | D50: 受託者 | E50: 2026-10 | F50: 2026-10 | G50: 完了 | H50: 100 | I50: 20 | J50: 80 | K50: 3 | L50: 前倒し | M50: ―
A52: 加重の実績進捗率 53.8％ 対 予定進捗率 51.8％ 乖離 +2.0ポイント
A53: 期限超過 6件
A54: 遅れ 2件
A55: おおむね予定どおり 31件
A56: 前倒し 10件
A57: ※ 予定進捗率＝予定開始の月初から予定完了の月末までを直線で見たとき、基準日に何％進んでいるはずかの値です。
A58: ※ 判定は実績と予定の差が±10ポイント以内なら「おおむね予定どおり」としています。月単位の予定を日割りした誤差の幅です。
A59: ※ 予定完了の月を過ぎてなお完了していないものを「期限超過」としています。
A60: ※ 加重は工数の目安（重み1〜5）です。製本1件の遅れと見込量推計1件の遅れを同じ重さにしないためです。
