Workbook
Name 採用・退職: #REF!
Name 所属コード表_新旧対照_: #REF!

Sheet 料金改定率
A1: 女川町水道事業 経営戦略財政シミュレーション結果（法定耐用年数×1.2倍ver）
I2: 【財政シミュレーション結果】
D3: 改定率
C4: 基本料金 | D4: 1.5
C5: 従量料金 | D5: 1
B6: 【料金体系】
B7: 〇基本料金 | C7: 現行 | D7: 他町 | F7: ="現行×"&料金改定率!D4*100&"%" -> 現行×150%
B8: 口径 | C8: 料金 | D8: 料金 | E8: 乖離率 | F8: 料金 | G8: 改定率
B9: 13ミリ | C9: =#REF! -> #REF! | E9: =IFERROR(D9/C9,"") | F9: ='【料金算定－現行×改定率】総括原価'!D9 -> #REF! | G9: =F9/C9 -> #REF!
B10: 20ミリ | C10: =#REF! -> #REF! | E10: =IFERROR(D10/C10,"") | F10: ='【料金算定－現行×改定率】総括原価'!D10 -> #REF! | G10: =F10/C10 -> #REF!
B11: 25ミリ | C11: =#REF! -> #REF! | E11: =IFERROR(D11/C11,"") | F11: ='【料金算定－現行×改定率】総括原価'!D11 -> #REF! | G11: =F11/C11 -> #REF!
B12: 30ミリ | C12: =#REF! -> #REF! | E12: =IFERROR(D12/C12,"") | F12: ='【料金算定－現行×改定率】総括原価'!D12 -> #REF! | G12: =F12/C12 -> #REF!
B13: 40ミリ | C13: =#REF! -> #REF! | E13: =IFERROR(D13/C13,"") | F13: ='【料金算定－現行×改定率】総括原価'!D13 -> #REF! | G13: =F13/C13 -> #REF!
B14: 50ミリ | C14: =#REF! -> #REF! | E14: =IFERROR(D14/C14,"") | F14: ='【料金算定－現行×改定率】総括原価'!D14 -> #REF! | G14: =F14/C14 -> #REF!
B15: 75ミリ | C15: =#REF! -> #REF! | E15: =IFERROR(D15/C15,"") | F15: ='【料金算定－現行×改定率】総括原価'!D15 -> #REF! | G15: =F15/C15 -> #REF!
B16: 100ミリ | C16: =#REF! -> #REF! | E16: =IFERROR(D16/C16,"") | F16: ='【料金算定－現行×改定率】総括原価'!D16 -> #REF! | G16: =F16/C16 -> #REF!
W19: （単位：千円）
B20: 〇水量料金 | C20: 現行 | D20: 他市 | F20: ="現行×"&料金改定率!D5*100&"%" -> 現行×100% | J20: 実績 | L20: 試算
B21: 区分 | C21: 料金 | D21: 料金 | E21: 乖離率 | F21: 料金 | G21: 改定率 | J21: H30 | L21: H31 | N21: R10 | P21: R20 | R21: R30 | T21: R40 | V21: R50
B22: 1～10㎥ | C22: =#REF! -> #REF! | E22: =IFERROR(D22/C22,"") | F22: ='【料金算定－現行×改定率】総括原価'!D18 -> #REF! | G22: =F22/C22 -> #REF! | J22: 収入 | K22: 費用 | L22: 収入 | M22: 費用 | N22: 収入 | O22: 費用 | P22: 収入 | Q22: 費用 | R22: 収入 | S22: 費用 | T22: 収入 | U22: 費用 | V22: 収入 | W22: 費用
B23: 11～20㎥ | C23: =#REF! -> #REF! | E23: =IFERROR(D23/C23,"") | F23: ='【料金算定－現行×改定率】総括原価'!D19 -> #REF! | G23: =F23/C23 -> #REF! | I23: 3条 | J23: =【現行×調整率】財政シミュ!R5 -> #REF! | K23: =【現行×調整率】財政シミュ!R23 -> #REF! | L23: =【現行×調整率】財政シミュ!T5 -> #REF! | M23: =【現行×調整率】財政シミュ!T23 -> #REF! | N23: =【現行×調整率】財政シミュ!AC5 -> #REF! | O23: =【現行×調整率】財政シミュ!AC23 -> #REF! | P23: =【現行×調整率】財政シミュ!AM5 -> #REF! | Q23: =【現行×調整率】財政シミュ!AM23 -> #REF! | R23: =【現行×調整率】財政シミュ!AW5 -> #REF! | S23: =【現行×調整率】財政シミュ!AW23 -> #REF! | T23: =【現行×調整率】財政シミュ!BG5 -> #REF! | U23: =【現行×調整率】財政シミュ!BG23 -> #REF! | V23: =【現行×調整率】財政シミュ!BQ5 -> #REF! | W23: =【現行×調整率】財政シミュ!BQ23 -> #REF!
B24: 21～50㎥ | C24: =#REF! -> #REF! | E24: =IFERROR(D24/C24,"") | F24: ='【料金算定－現行×改定率】総括原価'!D20 -> #REF! | G24: =F24/C24 -> #REF! | I24: 4条 | J24: =【現行×調整率】財政シミュ!R72 -> 9335000 | K24: =【現行×調整率】財政シミュ!R79 -> 280177715 | L24: =【現行×調整率】財政シミュ!T72 -> 150000000000000 | M24: =【現行×調整率】財政シミュ!T79 -> 160000079463153 | N24: =【現行×調整率】財政シミュ!AC72 -> 160000130000000 | O24: =【現行×調整率】財政シミュ!AC79 -> 160000182991959 | P24: =【現行×調整率】財政シミュ!AM72 -> 50000550000000 | Q24: =【現行×調整率】財政シミュ!AM79 -> 50000681474127 | R24: =【現行×調整率】財政シミュ!AW72 -> 50000010000000 | S24: =【現行×調整率】財政シミュ!AW79 -> 50000201631756 | T24: =【現行×調整率】財政シミュ!BG72 -> 50000010000000 | U24: =【現行×調整率】財政シミュ!BG79 -> 50000254808211 | V24: =【現行×調整率】財政シミュ!BQ72 -> 0 | W24: =【現行×調整率】財政シミュ!BQ79 -> 192307993
B25: 51～100㎥ | C25: =#REF! -> #REF! | E25: =IFERROR(D25/C25,"") | F25: ='【料金算定－現行×改定率】総括原価'!D21 -> #REF! | G25: =F25/C25 -> #REF! | I25: 資金残高 | J25: =【現行×調整率】財政シミュ!R113 -> 132458270 | L25: =【現行×調整率】財政シミュ!T113 -> #REF! | N25: =【現行×調整率】財政シミュ!AC113 -> #REF! | P25: =【現行×調整率】財政シミュ!AM113 -> #REF! | R25: =【現行×調整率】財政シミュ!AW113 -> #REF! | T25: =【現行×調整率】財政シミュ!BG113 -> #REF! | V25: =【現行×調整率】財政シミュ!BQ113 -> #REF!
B26: 100㎥超 | C26: =#REF! -> #REF! | E26: =IFERROR(D26/C26,"") | F26: ='【料金算定－現行×改定率】総括原価'!D22 -> #REF! | G26: =F26/C26 -> #REF! | I26: 企業債残高 | J26: =【現行×調整率】財政シミュ!R114 -> 763361128 | L26: =【現行×調整率】財政シミュ!T114 -> 450554111 | N26: =【現行×調整率】財政シミュ!AC114 -> 2822863405 | P26: =【現行×調整率】財政シミュ!AM114 -> 6354190571 | R26: =【現行×調整率】財政シミュ!AW114 -> 5688232449 | T26: =【現行×調整率】財政シミュ!BG114 -> 3988555190 | V26: =【現行×調整率】財政シミュ!BQ114 -> 1904019121

Sheet 【PL】決算数値入力
B1: 収益的収支（税抜き） | F1: この色部分を入れる。
B2: DS:女川町水道事業会計収益費用明細書 | P2: （単位：千円） | R2: 収益的収支（税抜き） | W2: （単位：千円）
B3: 款 | C3: 項 | D3: 目 | E3: 節 | F3: 実績期間 | P3: 平均 | R3: 款 | S3: 項 | T3: 目 | V3: 総括原価の区分 | W3: 実績期間 | AB3: 10年平均値
F4: H26 | G4: H27 | H4: H28 | I4: H29 | J4: H30 | K4: R1 | L4: R2 | M4: R3 | N4: R4 | O4: R5 | W4: R1 | X4: R2 | Y4: R3 | Z4: R4 | AA4: R5
B5: 水道事業収益 | F5: =SUM(F6,F15,F28) -> 140644902 | G5: =SUM(G6,G15,G28) -> 354853084 | H5: =SUM(H6,H15,H28) -> 181202744 | I5: =SUM(I6,I15,I28) -> 225661934 | J5: =SUM(J6,J15,J28) -> 246381566 | K5: =SUM(K6,K15,K28) -> 236084433 | L5: =SUM(L6,L15,L28) -> 471816622 | M5: =SUM(M6,M15,M28) -> 506142175 | ... O5: =SUM(O6,O15,O28) -> 504865980 | P5: =AVERAGE(F5:O5) -> 346115904 | R5: 水道事業収益 | W5: =SUM(W6,W11,W19,W20) -> 236084433 | X5: =SUM(X6,X11,X19,X20) -> 471816622 | Y5: =SUM(Y6,Y11,Y19,Y20) -> 506142175 | Z5: =SUM(Z6,Z11,Z19,Z20) -> 593505600 | AA5: =SUM(AA6,AA11,AA19,AA20) -> 504865980 | AB5: =SUM(AB6,AB11,AB19,AB20) -> 3.4374651e+08
C6: 営業収益 | F6: =SUM(F7,F9,F11) -> 98303392 | G6: =SUM(G7,G9,G11) -> 106482674 | H6: =SUM(H7,H9,H11) -> 108666066 | I6: =SUM(I7,I9,I11) -> 118698260 | J6: =SUM(J7,J9,J11) -> 117662769 | K6: =SUM(K7,K9,K11) -> 115230130 | L6: =SUM(L7,L9,L11) -> 119471832 | M6: =SUM(M7,M9,M11) -> 122357520 | ... O6: =SUM(O7,O9,O11) -> 120750259 | P6: =AVERAGE(F6:O6) -> 1.1474756e+08 | S6: 営業収益 | W6: =SUM(W7:W10) -> 115230130 | X6: =SUM(X7:X10) -> 119471832 | Y6: =SUM(Y7:Y10) -> 122357520 | Z6: =SUM(Z7:Z10) -> 119852700 | AA6: =SUM(AA7:AA10) -> 120750259 | AB6: =SUM(AB7:AB10) -> 112378170
D7: 給水収益 | F7: =F8 -> 90864970 | G7: =G8 -> 96266880 | H7: =H8 -> 101214980 | I7: =I8 -> 117729860 | J7: =J8 -> 117200769 | K7: =K8 -> 114968230 | L7: =L8 -> 119265632 | M7: =M8 -> 122177720 | ... O7: =O8 -> 120553459 | P7: =AVERAGE(F7:O7) -> 111985280 | T7: 給水収益 | W7: =K7 -> 114968230 | X7: =L7 -> 119265632 | Y7: =M7 -> 122177720 | Z7: =N7 -> 119610300 | AA7: =O7 -> 120553459 | AB7: =P7 -> 111985280
E8: 水道使用料 | F8: 90864970 | G8: 96266880 | H8: 101214980 | I8: 117729860 | J8: 117200769 | K8: 114968230 | L8: 119265632 | M8: 122177720 | N8: 119610300 | O8: 120553459 | P8: =AVERAGE(F8:O8) -> 111985280 | T8: 加入金 | AB8: 0
D9: 受託工事収益 | F9: =F10 -> 0 | G9: =G10 -> 0 | H9: =H10 -> 0 | I9: =I10 -> 0 | J9: =J10 -> 0 | K9: =K10 -> 0 | L9: =L10 -> 0 | M9: =M10 -> 0 | ... O9: =O10 -> 0 | P9: =AVERAGE(F9:O9) -> 0 | T9: 受託工事収益 | W9: =K9 -> 0 | X9: =L9 -> 0 | Y9: =M9 -> 0 | Z9: =N9 -> 0 | AA9: =O9 -> 0 | AB9: =P9 -> 0
E10: 受託工事収益 | F10: 0 | G10: 0 | H10: 0 | I10: 0 | J10: 0 | K10: 0 | L10: 0 | M10: 0 | N10: 0 | O10: 0 | P10: =AVERAGE(F10:O10) -> 0 | T10: その他の営業収益 | W10: =K12+K13 -> 261900 | X10: =L12+L13 -> 206200 | Y10: =M12+M13 -> 179800 | Z10: =N12+N13 -> 242400 | AA10: =O12+O13 -> 196800 | AB10: =P12 -> 392890
D11: その他の営業収益 | F11: =SUM(F12:F14) -> 7438422 | G11: =SUM(G12:G14) -> 10215794 | H11: =SUM(H12:H14) -> 7451086 | I11: =SUM(I12:I14) -> 968400 | J11: =SUM(J12:J14) -> 462000 | K11: =SUM(K12:K14) -> 261900 | L11: =SUM(L12:L14) -> 206200 | M11: =SUM(M12:M14) -> 179800 | ... O11: =SUM(O12:O14) -> 196800 | P11: =AVERAGE(F11:O11) -> 2762280.2 | S11: 営業外収益 | W11: =SUM(W12:W16) -> 120854303 | X11: =SUM(X12:X16) -> 352344790 | Y11: =SUM(Y12:Y16) -> 383784655 | Z11: =SUM(Z12:Z16) -> 473652900 | AA11: =SUM(AA12:AA16) -> 384115721 | AB11: =SUM(AB12:AB16) -> 2.3136834e+08
E12: 手数料 | F12: 329800 | G12: 411700 | H12: 669900 | I12: 968400 | J12: 462000 | K12: 261900 | L12: 206200 | M12: 179800 | N12: 242400 | O12: 196800 | P12: =AVERAGE(F12:O12) -> 392890 | T12: 受取利息及び配当金 | W12: =K16 -> 0 | X12: =L16 -> 0 | Y12: =M16 -> 0 | Z12: =N16 -> 0 | AA12: =O16 -> 0 | AB12: =P16 -> 15431.1
E13: 分水収益 | F13: 6961710 | G13: 9706982 | H13: 6730537 | I13: 0 | J13: 0 | K13: 0 | L13: 0 | M13: 0 | N13: 0 | O13: 0 | P13: =AVERAGE(F13:O13) -> 2339922.9 | T13: 他会計補助金 | W13: =K18 -> 23034829 | X13: =L18 -> 61004862 | Y13: =M18 -> 0 | Z13: =N18 -> 25962175 | AA13: =O18 -> 25117004 | AB13: =P18 -> 13834221
E14: 材料売却収益 | F14: 146912 | G14: 97112 | H14: 50649 | I14: 0 | J14: 0 | K14: 0 | L14: 0 | M14: 0 | N14: 0 | O14: 0 | P14: =AVERAGE(F14:O14) -> 29467.3 | T14: 補助金 | W14: =K24 -> 0 | X14: =L24 -> 0 | Y14: =M24 -> 25000000 | Z14: =N24 -> 20000000 | AA14: =O24 -> 20000000 | AB14: =P24 -> 15900000
C15: 営業外収益 | F15: =SUM(F16,F18,F20,F24,F26) -> 42341510 | G15: =SUM(G16,G18,G20,G24,G26) -> 248370410 | H15: =SUM(H16,H18,H20,H24,H26) -> 72536678 | I15: =SUM(I16,I18,I20,I24,I26) -> 106963674 | J15: =SUM(J16,J18,J20,J24,J26) -> 128718797 | K15: =SUM(K16,K18,K20,K24,K26) -> 120854303 | L15: =SUM(L16,L18,L20,L24,L26) -> 352344790 | M15: =SUM(M16,M18,M20,M24,M26) -> 383784655 | ... O15: =SUM(O16,O18,O20,O24,O26) -> 384115721 | P15: =AVERAGE(F15:O15) -> 2.3136834e+08 | T15: 雑収益 | W15: =K20 -> 2684327 | X15: =L20 -> 2450229 | Y15: =M20 -> 22402177 | Z15: =N20 -> 8371047 | AA15: =O20 -> 2589660 | AB15: =P20 -> 4890572.8
D16: 受取利息及び配当金 | F16: =F17 -> 26979 | G16: =G17 -> 19775 | H16: =H17 -> 14752 | I16: =I17 -> 15030 | J16: =J17 -> 77775 | K16: =K17 -> 0 | L16: =L17 -> 0 | M16: =M17 -> 0 | ... O16: =O17 -> 0 | P16: =AVERAGE(F16:O16) -> 15431.1 | T16: 長期前受金戻入益 | W16: =SUM(W17:W18) -> 95135147 | X16: =SUM(X17:X18) -> 288889699 | Y16: =SUM(Y17:Y18) -> 336382478 | Z16: =SUM(Z17:Z18) -> 419319678 | AA16: =SUM(AA17:AA18) -> 336409057 | AB16: =SUM(AB17:AB18) -> 1.9672812e+08
E17: 預金利息 | F17: 26979 | G17: 19775 | H17: 14752 | I17: 15030 | J17: 77775 | K17: 0 | L17: 0 | M17: 0 | N17: 0 | O17: 0 | P17: =AVERAGE(F17:O17) -> 15431.1 | U17: H30末の取得資産 | W17: =K26 -> 95135147 | X17: =L26 -> 288889699 | Y17: =M26 -> 336382478 | Z17: =N26 -> 419319678 | AA17: =O26 -> 336409057 | AB17: =P26 -> 1.9672812e+08
D18: 他会計補助金 | F18: =F19 -> 480000 | G18: =G19 -> 488000 | H18: =H19 -> 1343340 | I18: =I19 -> 576000 | J18: =J19 -> 336000 | K18: =K19 -> 23034829 | L18: =L19 -> 61004862 | M18: =M19 -> 0 | ... O18: =O19 -> 25117004 | P18: =AVERAGE(F18:O18) -> 13834221 | U18: H31以降の取得資産
E19: 他会計補助金 | F19: 480000 | G19: 488000 | H19: 1343340 | I19: 576000 | J19: 336000 | K19: 23034829 | L19: 61004862 | M19: 0 | N19: 25962175 | O19: 25117004 | P19: =AVERAGE(F19:O19) -> 13834221 | S19: 引当金戻入益
D20: 雑収益 | F20: =SUM(F21:F23) -> 1792752 | G20: =SUM(G21:G23) -> 1015811 | H20: =SUM(H21:H23) -> 1702162 | I20: =SUM(I21:I23) -> 1962207 | J20: =SUM(J21:J23) -> 3935356 | K20: =SUM(K21:K23) -> 2684327 | L20: =SUM(L21:L23) -> 2450229 | M20: =SUM(M21:M23) -> 22402177 | ... O20: =SUM(O21:O23) -> 2589660 | P20: =AVERAGE(F20:O20) -> 4890572.8 | S20: 特別利益 | W20: =SUM(W21:W23) -> 0 | X20: =SUM(X21:X23) -> 0 | Y20: =SUM(Y21:Y23) -> 0 | Z20: =SUM(Z21:Z23) -> 0 | AA20: =SUM(AA21:AA23) -> 0 | AB20: =SUM(AB21:AB23) -> 0
E21: その他雑収益 | F21: 1789952 | G21: 1015811 | H21: 1702162 | I21: 1962207 | J21: 2052299 | K21: 2684327 | L21: 2450229 | M21: 22402177 | N21: 8371047 | O21: 2589660 | P21: =AVERAGE(F21:O21) -> 4701987.1 | T21: 固定資産売却益 | W21: =K32 -> 0 | X21: =L32 -> 0 | Y21: =M32 -> 0 | Z21: =N32 -> 0 | AA21: =O32 -> 0 | AB21: =P32 -> 0
E22: 消費税関係雑収益 | F22: 2800 | G22: 0 | H22: 0 | I22: 0 | J22: 1883057 | K22: 0 | L22: 0 | M22: 0 | N22: 0 | O22: 0 | P22: =AVERAGE(F22:O22) -> 188585.7 | T22: 過年度修正益 | W22: =K29 -> 0 | X22: =L29 -> 0 | Y22: =M29 -> 0 | Z22: =N29 -> 0 | AA22: =O29 -> 0 | AB22: =P29 -> 0
E23: 不用品売却収益 | F23: 0 | G23: 0 | H23: 0 | I23: 0 | J23: 0 | K23: 0 | L23: 0 | M23: 0 | N23: 0 | O23: 0 | P23: =AVERAGE(F23:O23) -> 0 | T23: その他特別利益
D24: 補助金 | F24: =F25 -> 14000000 | G24: =G25 -> 15000000 | H24: =H25 -> 11000000 | I24: =I25 -> 27000000 | J24: =J25 -> 27000000 | K24: =K25 -> 0 | L24: =L25 -> 0 | M24: =M25 -> 25000000 | ... O24: =O25 -> 20000000 | P24: =AVERAGE(F24:O24) -> 15900000 | R24: 水道事業費用 | W24: =SUM(W25,W58,W63) -> 390874183 | X24: =SUM(X25,X58,X63) -> 507845824 | Y24: =SUM(Y25,Y58,Y63) -> 543887736 | Z24: =SUM(Z25,Z58,Z63) -> 694576672 | AA24: =SUM(AA25,AA58,AA63) -> 564428515 | AB24: =P35 -> 4.2086899e+08
E25: 国庫補助金 | F25: 14000000 | G25: 15000000 | H25: 11000000 | I25: 27000000 | J25: 27000000 | K25: 0 | L25: 0 | M25: 25000000 | N25: 20000000 | O25: 20000000 | P25: =AVERAGE(F25:O25) -> 15900000 | S25: 営業費用 | W25: =SUM(W26,W34,W43,W52,W55) -> 276187944 | X25: =SUM(X26,X34,X43,X52,X55) -> 493988554 | Y25: =SUM(Y26,Y34,Y43,Y52,Y55) -> 537473069 | Z25: =SUM(Z26,Z34,Z43,Z52,Z55) -> 687804951 | AA25: =SUM(AA26,AA34,AA43,AA52,AA55) -> 548360734 | AB25: =P36 -> 3.5942518e+08
D26: 長期前受金戻入益 | F26: =F27 -> 26041779 | G26: =G27 -> 231846824 | H26: =H27 -> 58476424 | I26: =I27 -> 77410437 | J26: =J27 -> 97369666 | K26: =K27 -> 95135147 | L26: =L27 -> 288889699 | M26: =M27 -> 336382478 | ... O26: =O27 -> 336409057 | P26: =AVERAGE(F26:O26) -> 1.9672812e+08 | T26: 原水及び浄水費 | V26: 原浄水部門費 | W26: =SUM(W27:W33) -> 68125490 | X26: =SUM(X27:X33) -> 86729085 | Y26: =SUM(Y27:Y33) -> 77675517 | Z26: =SUM(Z27:Z33) -> 81124641 | AA26: =SUM(AA27:AA33) -> 85901288 | AB26: =P37 -> 69189921
E27: 長期前受金戻入益 | F27: 26041779 | G27: 231846824 | H27: 58476424 | I27: 77410437 | J27: 97369666 | K27: 95135147 | L27: 288889699 | M27: 336382478 | N27: 419319678 | O27: 336409057 | P27: =AVERAGE(F27:O27) -> 1.9672812e+08 | U27: 人件費 | W27: =K38+K39+K40+K41 -> 6871890 | X27: =L38+L39+L40+L41 -> 6834594 | Y27: =M38+M39+M40+M41 -> 6604994 | Z27: =N38+N39+N40+N41 -> 6808256 | AA27: =O38+O39+O40+O41 -> 6912531 | AB27: =P38+P39+P40+P41 -> 7539318.4
C28: 特別利益 | F28: =SUM(F31,F29) -> 0 | G28: =SUM(G31,G29) -> 0 | H28: =SUM(H31,H29) -> 0 | I28: =SUM(I31,I29) -> 0 | J28: =SUM(J31,J29) -> 0 | K28: =SUM(K31,K29) -> 0 | L28: =SUM(L31,L29) -> 0 | M28: =SUM(M31,M29) -> 0 | ... O28: =SUM(O31,O29) -> 0 | P28: =AVERAGE(F28:O28) -> 0 | U28: 動力費 | W28: =K50 -> 2543653 | X28: =L50 -> 6880183 | Y28: =M50 -> 7599848 | Z28: =N50 -> 9405448 | AA28: =O50 -> 8392602 | AB28: =P50 -> 4481765.6
D29: 過年度損益修正益 | F29: =F30 -> 0 | G29: =G30 -> 0 | H29: =H30 -> 0 | I29: =I30 -> 0 | J29: =J30 -> 0 | K29: =K30 -> 0 | L29: =L30 -> 0 | M29: =M30 -> 0 | ... O29: =O30 -> 0 | P29: =AVERAGE(F29:O29) -> 0 | U29: 薬品費 | W29: =K51 -> 2231130 | X29: =L51 -> 2383550 | Y29: =M51 -> 2505150 | Z29: =N51 -> 2578200 | AA29: =O51 -> 3328640 | AB29: =P51 -> 2232707.9
E30: 過年度損益修正益 | F30: 0 | G30: 0 | H30: 0 | I30: 0 | J30: 0 | K30: 0 | L30: 0 | M30: 0 | N30: 0 | O30: 0 | P30: =AVERAGE(F30:O30) -> 0 | U30: 修繕費 | W30: =K49 -> 4684722 | X30: =L49 -> 8618000 | Y30: =M49 -> 1967420 | Z30: =N49 -> 0 | AA30: =O49 -> 3913900 | AB30: =P49 -> 2660995.2
D31: 固定資産売却益 | F31: =F32 -> 0 | G31: =G32 -> 0 | H31: =H32 -> 0 | I31: =I32 -> 0 | J31: =J32 -> 0 | K31: =K32 -> 0 | L31: =L32 -> 0 | M31: =M32 -> 0 | ... O31: =O32 -> 0 | P31: =AVERAGE(F31:O31) -> 0 | U31: 委託料 | W31: =K46 -> 33900347 | X31: =L46 -> 31437870 | Y31: =M46 -> 37142870 | Z31: =N46 -> 33639873 | AA31: =O46 -> 36092000 | AB31: =P46 -> 30459801
E32: 固定資産売却益 | F32: 0 | G32: 0 | H32: 0 | I32: 0 | J32: 0 | K32: 0 | L32: 0 | M32: 0 | N32: 0 | O32: 0 | P32: =AVERAGE(F32:O32) -> 0 | U32: その他（物価上昇を考慮する） | W32: =K42+K43+K44+K45+K47+K48+K52+K54+K55 -> 7655578 | X32: =L42+L43+L44+L45+L47+L48+L52+L54+L55 -> 9645808 | Y32: =M42+M43+M44+M45+M47+M48+M52+M54+M55 -> 9829369 | Z32: =N42+N43+N44+N45+N47+N48+N52+N54+N55 -> 10153949 | AA32: =O42+O43+O44+O45+O47+O48+O52+O54+O55 -> 9171593 | AB32: =P42+P43+P44+P45+P47+P48+P52+P54+P55 -> 7339389.2
B33: 決算書「水道事業収益」数値 | F33: 140644902 | G33: 354853084 | H33: 181202744 | I33: 225661934 | J33: 246381566 | K33: 236084433 | L33: 471816622 | M33: 506142175 | N33: 593505600 | O33: 504865980 | U33: その他（負担金） | W33: =K53 -> 10238170 | X33: =L53 -> 20929080 | Y33: =M53 -> 12025866 | Z33: =N53 -> 18538915 | AA33: =O53 -> 18090022 | AB33: =P53 -> 14475944
B34: 差異の有無 | F34: =IF(F5=F33,"OK","NG") -> OK | G34: =IF(G5=G33,"OK","NG") -> OK | H34: =IF(H5=H33,"OK","NG") -> OK | I34: =IF(I5=I33,"OK","NG") -> OK | J34: =IF(J5=J33,"OK","NG") -> OK | K34: =IF(K5=K33,"OK","NG") -> OK | L34: =IF(L5=L33,"OK","NG") -> OK | M34: =IF(M5=M33,"OK","NG") -> OK | ... O34: =IF(O5=O33,"OK","NG") -> OK | T34: 配水及び給水費 | V34: 配給水部門費 | W34: =SUM(W35:W41) -> 39566820 | X34: =SUM(X35:X41) -> 36646933 | Y34: =SUM(Y35:Y41) -> 35722581 | Z34: =SUM(Z35:Z41) -> 36936296 | AA34: =SUM(AA35:AA41) -> 32180340 | AB34: =P56 -> 34923211
B35: 水道事業費用 | F35: =SUM(F36,F112,F116) -> 190236030 | G35: =SUM(G36,G112,G116) -> 525072793 | H35: =SUM(H36,H112,H116) -> 228906571 | I35: =SUM(I36,I112,I116) -> 275120413 | J35: =SUM(J36,J112,J116) -> 287741207 | K35: =SUM(K36,K112,K116) -> 390874183 | L35: =SUM(L36,L112,L116) -> 507845824 | M35: =SUM(M36,M112,M116) -> 543887736 | ... O35: =SUM(O36,O112,O116) -> 564428515 | P35: =AVERAGE(F35:O35) -> 4.2086899e+08 | U35: 人件費 | W35: =K57+K58+K59+K60+K61 -> 13528381 | X35: =L57+L58+L59+L60+L61 -> 10517166 | Y35: =M57+M58+M59+M60+M61 -> 10463981 | Z35: =N57+N58+N59+N60+N61 -> 10732216 | AA35: =O57+O58+O59+O60+O61 -> 6777049 | AB35: =P57+P58+P59+P60+P61 -> 12599585
C36: 営業費用 | F36: =SUM(F37,F56,F76,F78,F104,F106,F109) -> 185755422 | G36: =SUM(G37,G56,G76,G78,G104,G106,G109) -> 157078455 | H36: =SUM(H37,H56,H76,H78,H104,H106,H109) -> 157638137 | I36: =SUM(I37,I56,I76,I78,I104,I106,I109) -> 266575866 | J36: =SUM(J37,J56,J76,J78,J104,J106,J109) -> 283388690 | K36: =SUM(K37,K56,K76,K78,K104,K106,K109) -> 276187944 | L36: =SUM(L37,L56,L76,L78,L104,L106,L109) -> 493988554 | M36: =SUM(M37,M56,M76,M78,M104,M106,M109) -> 537473069 | ... O36: =SUM(O37,O56,O76,O78,O104,O106,O109) -> 548360734 | P36: =AVERAGE(F36:O36) -> 3.5942518e+08 | U36: 動力費 | W36: =K72 -> 3189420 | X36: =L72 -> 2083304 | Y36: =M72 -> 2339387 | Z36: =N72 -> 3088131 | AA36: =O72 -> 2470534 | AB36: =P72 -> 2159463.6
D37: 原水及び浄水費 | F37: =SUM(F38:F55) -> 58676576 | G37: =SUM(G38:G55) -> 54090290 | H37: =SUM(H38:H55) -> 45431047 | I37: =SUM(I38:I55) -> 64803015 | J37: =SUM(J38:J55) -> 69342260 | K37: =SUM(K38:K55) -> 68125490 | L37: =SUM(L38:L55) -> 86729085 | M37: =SUM(M38:M55) -> 77675517 | ... O37: =SUM(O38:O55) -> 85901288 | P37: =AVERAGE(F37:O37) -> 69189921 | U37: 薬品費
E38: 給料 | F38: =4689000 -> 4689000 | G38: 4698000 | H38: 4698000 | I38: 3057600 | J38: 3457800 | K38: 3479400 | L38: 3501900 | M38: 3526200 | N38: 3568800 | O38: 3669600 | P38: =AVERAGE(F38:O38) -> 3834630 | U38: 修繕費 | W38: =K70 -> 1577280 | X38: =L70 -> 327448 | Y38: =M70 -> 569069 | Z38: =N70 -> 3745890 | AA38: =O70 -> 3642734 | AB38: =P70 -> 1417521.1
E39: 手当+引当金 | F39: =2534306+603139 -> 3137445 | G39: =1694429+577463 -> 2271892 | H39: =1678889+604723 -> 2283612 | I39: =572069+619295 -> 1191364 | J39: =1263097+460538 -> 1723635 | K39: 1524409 | L39: 1480350 | M39: 1399400 | N39: 1546263 | O39: 1570022 | P39: =AVERAGE(F39:O39) -> 1812839.2 | U39: 委託料 | W39: =K67 -> 17175629 | X39: =L67 -> 18885642 | Y39: =M67 -> 16161047 | Z39: =N67 -> 13583646 | AA39: =O67 -> 13164934 | AB39: =P67 -> 14950335
E40: 法定福利費 | F40: 1580740 | G40: 1545406 | H40: 1419631 | I40: 802571 | J40: 1184413 | K40: 1170458 | L40: 1150209 | M40: 1148697 | N40: 1156088 | O40: 1120349 | P40: =AVERAGE(F40:O40) -> 1227856.2 | U40: その他（物価上昇を考慮する） | W40: =K62+K63+K64+K65+K66+K68+K69+K71+K73+K74+K75 -> 4096110 | X40: =L62+L63+L64+L65+L66+L68+L69+L71+L73+L74+L75 -> 4833373 | Y40: =M62+M63+M64+M65+M66+M68+M69+M71+M73+M74+M75 -> 6189097 | Z40: =N62+N63+N64+N65+N66+N68+N69+N71+N73+N74+N75 -> 5786413 | AA40: =O62+O63+O64+O65+O66+O68+O69+O71+O73+O74+O75 -> 6125089 | AB40: =P62+P63+P64+P65+P66+P68+P69+P71+P73+P74+P75 -> 3796306.5
...

Sheet 【PL】決算数値入力 (仮保存)
B1: 収益的収支（税抜き） | F1: この色部分を入れる。
B2: DS:女川町水道事業会計収益費用明細書 | P2: （単位：千円） | R2: 収益的収支（税抜き） | W2: （単位：千円）
B3: 款 | C3: 項 | D3: 目 | E3: 節 | F3: 実績期間 | P3: 平均 | R3: 款 | S3: 項 | T3: 目 | V3: 総括原価の区分 | W3: 実績期間 | AB3: 平均値
F4: H26 | G4: H27 | H4: H28 | I4: H29 | J4: H30 | K4: R1 | L4: R2 | M4: R3 | N4: R4 | O4: R5 | W4: R1 | X4: R2 | Y4: R3 | Z4: R4 | AA4: R5
B5: 水道事業収益 | F5: =SUM(F6,F15,F28) -> 0 | G5: =SUM(G6,G15,G28) -> 0 | H5: =SUM(H6,H15,H28) -> 0 | I5: =SUM(I6,I15,I28) -> 0 | J5: =SUM(J6,J15,J28) -> 0 | K5: =SUM(K6,K15,K28) -> 0 | L5: =SUM(L6,L15,L28) -> 0 | M5: =SUM(M6,M15,M28) -> 0 | ... O5: =SUM(O6,O15,O28) -> 504865980 | P5: =AVERAGE(F5:O5) -> 50486598 | R5: 水道事業収益 | W5: =SUM(W6,W11,W18,W19) -> 0 | X5: =SUM(X6,X11,X18,X19) -> 0 | Y5: =SUM(Y6,Y11,Y18,Y19) -> 0 | Z5: =SUM(Z6,Z11,Z18,Z19) -> 0 | AA5: =SUM(AA6,AA11,AA18,AA19) -> 484865980 | AB5: =SUM(AB6,AB11,AB18,AB19) -> 48663718
C6: 営業収益 | F6: =SUM(F7,F9,F11) -> 0 | G6: =SUM(G7,G9,G11) -> 0 | H6: =SUM(H7,H9,H11) -> 0 | I6: =SUM(I7,I9,I11) -> 0 | J6: =SUM(J7,J9,J11) -> 0 | K6: =SUM(K7,K9,K11) -> 0 | L6: =SUM(L7,L9,L11) -> 0 | M6: =SUM(M7,M9,M11) -> 0 | ... O6: =SUM(O7,O9,O11) -> 120750259 | P6: =AVERAGE(F6:O6) -> 12075026 | S6: 営業収益 | W6: =SUM(W7:W10) -> 0 | X6: =SUM(X7:X10) -> 0 | Y6: =SUM(Y7:Y10) -> 0 | Z6: =SUM(Z7:Z10) -> 0 | AA6: =SUM(AA7:AA10) -> 120750259 | AB6: =SUM(AB7:AB10) -> 12252146
D7: 給水収益 | F7: =F8 -> 0 | G7: =G8 -> 0 | H7: =H8 -> 0 | I7: =I8 -> 0 | J7: =J8 -> 0 | K7: =K8 -> 0 | L7: =L8 -> 0 | M7: =M8 -> 0 | ... O7: =O8 -> 120553459 | P7: =AVERAGE(F7:O7) -> 12055346 | T7: 給水収益 | W7: =K7 -> 0 | X7: =L7 -> 0 | Y7: =M7 -> 0 | Z7: =N7 -> 0 | AA7: =O7 -> 120553459 | AB7: =P7 -> 12055346
E8: 水道使用料 | O8: 120553459 | P8: =AVERAGE(F8:O8) -> 120553459 | T8: 加入金 | W8: =K13 -> 0 | X8: =L13 -> 0 | Y8: =M13 -> 0 | Z8: =N13 -> 0 | AA8: =O13 -> 0 | AB8: =P13 -> 0
D9: 受託工事収益 | F9: =F10 -> 0 | G9: =G10 -> 0 | H9: =H10 -> 0 | I9: =I10 -> 0 | J9: =J10 -> 0 | K9: =K10 -> 0 | L9: =L10 -> 0 | M9: =M10 -> 0 | ... O9: =O10 -> 0 | P9: =AVERAGE(F9:O9) -> 0 | T9: 受託工事収益 | W9: =K9 -> 0 | X9: =L9 -> 0 | Y9: =M9 -> 0 | Z9: =N9 -> 0 | AA9: =O9 -> 0 | AB9: =P9 -> 0
E10: 受託工事収益 | O10: 0 | P10: =AVERAGE(F10:O10) -> 0 | T10: その他の営業収益 | W10: =K12 -> 0 | X10: =L12 -> 0 | Y10: =M12 -> 0 | Z10: =N12 -> 0 | AA10: =O12 -> 196800 | AB10: =P12 -> 196800
D11: その他の営業収益 | F11: =SUM(F12:F14) -> 0 | G11: =SUM(G12:G14) -> 0 | H11: =SUM(H12:H14) -> 0 | I11: =SUM(I12:I14) -> 0 | J11: =SUM(J12:J14) -> 0 | K11: =SUM(K12:K14) -> 0 | L11: =SUM(L12:L14) -> 0 | M11: =SUM(M12:M14) -> 0 | ... O11: =SUM(O12:O14) -> 196800 | P11: =AVERAGE(F11:O11) -> 19680 | S11: 営業外収益 | W11: =SUM(W12:W15) -> 0 | X11: =SUM(X12:X15) -> 0 | Y11: =SUM(Y12:Y15) -> 0 | Z11: =SUM(Z12:Z15) -> 0 | AA11: =SUM(AA12:AA15) -> 364115721 | AB11: =SUM(AB12:AB15) -> 36411572
E12: 手数料 | O12: 196800 | P12: =AVERAGE(F12:O12) -> 196800 | T12: 受取利息及び配当金 | W12: =K16 -> 0 | X12: =L16 -> 0 | Y12: =M16 -> 0 | Z12: =N16 -> 0 | AA12: =O16 -> 0 | AB12: =P16 -> 0
E13: 加入金 | O13: 0 | P13: =AVERAGE(F13:O13) -> 0 | T13: 他会計補助金 | W13: =K18 -> 0 | X13: =L18 -> 0 | Y13: =M18 -> 0 | Z13: =N18 -> 0 | AA13: =O18 -> 25117004 | AB13: =P18 -> 2511700.4
E14: 他会計負担金 | O14: 0 | P14: =AVERAGE(F14:O14) -> 0 | T14: 雑収益 | W14: =K20 -> 0 | X14: =L20 -> 0 | Y14: =M20 -> 0 | Z14: =N20 -> 0 | AA14: =O20 -> 2589660 | AB14: =P20 -> 258966
C15: 営業外収益 | F15: =SUM(F16,F18,F20,F24,F26) -> 0 | G15: =SUM(G16,G18,G20,G24,G26) -> 0 | H15: =SUM(H16,H18,H20,H24,H26) -> 0 | I15: =SUM(I16,I18,I20,I24,I26) -> 0 | J15: =SUM(J16,J18,J20,J24,J26) -> 0 | K15: =SUM(K16,K18,K20,K24,K26) -> 0 | L15: =SUM(L16,L18,L20,L24,L26) -> 0 | M15: =SUM(M16,M18,M20,M24,M26) -> 0 | ... O15: =SUM(O16,O18,O20,O24,O26) -> 384115721 | P15: =AVERAGE(F15:O15) -> 38411572 | T15: 長期前受金戻入益 | W15: =SUM(W16:W17) -> 0 | X15: =SUM(X16:X17) -> 0 | Y15: =SUM(Y16:Y17) -> 0 | Z15: =SUM(Z16:Z17) -> 0 | AA15: =SUM(AA16:AA17) -> 336409057 | AB15: =SUM(AB16:AB17) -> 33640906
D16: 受取利息及び配当金 | F16: =F17 -> 0 | G16: =G17 -> 0 | H16: =H17 -> 0 | I16: =I17 -> 0 | J16: =J17 -> 0 | K16: =K17 -> 0 | L16: =L17 -> 0 | M16: =M17 -> 0 | ... O16: =O17 -> 0 | P16: =AVERAGE(F16:O16) -> 0 | U16: H30末の取得資産 | W16: =K26 -> 0 | X16: =L26 -> 0 | Y16: =M26 -> 0 | Z16: =N26 -> 0 | AA16: =O26 -> 336409057 | AB16: =P26 -> 33640906
E17: 預金利息 | O17: 0 | P17: =AVERAGE(F17:O17) -> 0 | U17: H31以降の取得資産
D18: 他会計補助金 | F18: =F19 -> 0 | G18: =G19 -> 0 | H18: =H19 -> 0 | I18: =I19 -> 0 | J18: =J19 -> 0 | K18: =K19 -> 0 | L18: =L19 -> 0 | M18: =M19 -> 0 | ... O18: =O19 -> 25117004 | P18: =AVERAGE(F18:O18) -> 2511700.4 | S18: 引当金戻入益
E19: 他会計補助金 | O19: 25117004 | P19: =AVERAGE(F19:O19) -> 25117004 | S19: 特別利益 | W19: =SUM(W20:W22) -> 0 | X19: =SUM(X20:X22) -> 0 | Y19: =SUM(Y20:Y22) -> 0 | Z19: =SUM(Z20:Z22) -> 0 | AA19: =SUM(AA20:AA22) -> 0 | AB19: =SUM(AB20:AB22) -> 0
D20: 雑収益 | F20: =SUM(F21:F23) -> 0 | G20: =SUM(G21:G23) -> 0 | H20: =SUM(H21:H23) -> 0 | I20: =SUM(I21:I23) -> 0 | J20: =SUM(J21:J23) -> 0 | K20: =SUM(K21:K23) -> 0 | L20: =SUM(L21:L23) -> 0 | M20: =SUM(M21:M23) -> 0 | ... O20: =SUM(O21:O23) -> 2589660 | P20: =AVERAGE(F20:O20) -> 258966 | T20: 固定資産売却益 | W20: =K32 -> 0 | X20: =L32 -> 0 | Y20: =M32 -> 0 | Z20: =N32 -> 0 | AA20: =O32 -> 0 | AB20: =P32 -> 0
E21: その他雑収益 | O21: 2589660 | P21: =AVERAGE(F21:O21) -> 2589660 | T21: 過年度修正益 | W21: =K29 -> 0 | X21: =L29 -> 0 | Y21: =M29 -> 0 | Z21: =N29 -> 0 | AA21: =O29 -> 0 | AB21: =P29 -> 0
E22: 発生品受入益 | O22: 0 | P22: =AVERAGE(F22:O22) -> 0 | T22: その他特別利益
E23: 不用品売却収益 | O23: 0 | P23: =AVERAGE(F23:O23) -> 0 | R23: 水道事業費用 | W23: =SUM(W24,W57,W62) -> 0 | X23: =SUM(X24,X57,X62) -> 0 | Y23: =SUM(Y24,Y57,Y62) -> 0 | Z23: =SUM(Z24,Z57,Z62) -> 0 | AA23: =SUM(AA24,AA57,AA62) -> 0 | AB23: =SUM(AB24,AB57,AB62) -> #DIV/0!
D24: 補助金 | F24: =F25 -> 0 | G24: =G25 -> 0 | H24: =H25 -> 0 | I24: =I25 -> 0 | J24: =J25 -> 0 | K24: =K25 -> 0 | L24: =L25 -> 0 | M24: =M25 -> 0 | ... O24: =O25 -> 20000000 | P24: =AVERAGE(F24:O24) -> 2000000 | S24: 営業費用 | W24: =SUM(W25,W33,W42,W51,W54) -> 0 | X24: =SUM(X25,X33,X42,X51,X54) -> 0 | Y24: =SUM(Y25,Y33,Y42,Y51,Y54) -> 0 | Z24: =SUM(Z25,Z33,Z42,Z51,Z54) -> 0 | AA24: =SUM(AA25,AA33,AA42,AA51,AA54) -> 0 | AB24: =SUM(AB25,AB33,AB42,AB51,AB54) -> #DIV/0!
E25: 国庫補助金 | O25: 20000000 | P25: =AVERAGE(F25:O25) -> 20000000 | T25: 原水及び浄水費 | V25: 原浄水部門費 | W25: =SUM(W26:W32) -> 0 | X25: =SUM(X26:X32) -> 0 | Y25: =SUM(Y26:Y32) -> 0 | Z25: =SUM(Z26:Z32) -> 0 | AA25: =SUM(AA26:AA32) -> 0 | AB25: =SUM(AB26:AB32) -> #DIV/0!
D26: 長期前受金戻入益 | F26: =F27 -> 0 | G26: =G27 -> 0 | H26: =H27 -> 0 | I26: =I27 -> 0 | J26: =J27 -> 0 | K26: =K27 -> 0 | L26: =L27 -> 0 | M26: =M27 -> 0 | ... O26: =O27 -> 336409057 | P26: =AVERAGE(F26:O26) -> 33640906 | U26: 人件費
E27: 長期前受金戻入益 | O27: 336409057 | P27: =AVERAGE(F27:O27) -> 336409057 | U27: 動力費 | W27: =K48 -> 0 | X27: =L48 -> 0 | Y27: =M48 -> 0 | Z27: =N48 -> 0 | AA27: =O48 -> 0 | AB27: =P48 -> #DIV/0!
C28: 特別利益 | F28: =SUM(F31,F29) -> 0 | G28: =SUM(G31,G29) -> 0 | H28: =SUM(H31,H29) -> 0 | I28: =SUM(I31,I29) -> 0 | J28: =SUM(J31,J29) -> 0 | K28: =SUM(K31,K29) -> 0 | L28: =SUM(L31,L29) -> 0 | M28: =SUM(M31,M29) -> 0 | ... O28: =SUM(O31,O29) -> 0 | P28: =AVERAGE(F28:O28) -> 0 | U28: 薬品費 | W28: =K49 -> 0 | X28: =L49 -> 0 | Y28: =M49 -> 0 | Z28: =N49 -> 0 | AA28: =O49 -> 0 | AB28: =P49 -> #DIV/0!
D29: 過年度損益修正益 | F29: =F30 -> 0 | G29: =G30 -> 0 | H29: =H30 -> 0 | I29: =I30 -> 0 | J29: =J30 -> 0 | K29: =K30 -> 0 | L29: =L30 -> 0 | M29: =M30 -> 0 | ... O29: =O30 -> 0 | P29: =AVERAGE(F29:O29) -> 0 | U29: 修繕費 | W29: =K47 -> 0 | X29: =L47 -> 0 | Y29: =M47 -> 0 | Z29: =N47 -> 0 | AA29: =O47 -> 0 | AB29: =P47 -> #DIV/0!
E30: 過年度損益修正益 | O30: 0 | P30: =AVERAGE(F30:O30) -> 0 | U30: 委託料 | W30: =K44 -> 0 | X30: =L44 -> 0 | Y30: =M44 -> 0 | Z30: =N44 -> 0 | AA30: =O44 -> 0 | AB30: =P44 -> #DIV/0!
D31: 固定資産売却益 | F31: =F32 -> 0 | G31: =G32 -> 0 | H31: =H32 -> 0 | I31: =I32 -> 0 | J31: =J32 -> 0 | K31: =K32 -> 0 | L31: =L32 -> 0 | M31: =M32 -> 0 | ... O31: =O32 -> 0 | P31: =AVERAGE(F31:O31) -> 0 | U31: その他（物価上昇を考慮する） | W31: =SUM(K39:K43,K45,K50:K52) -> 0 | X31: =SUM(L39:L43,L45,L50:L52) -> 0 | Y31: =SUM(M39:M43,M45,M50:M52) -> 0 | Z31: =SUM(N39:N43,N45,N50:N52) -> 0 | AA31: =SUM(O39:O43,O45,O50:O52) -> 0 | AB31: =SUM(P39:P43,P45,P50:P52) -> #DIV/0!
E32: 固定資産売却益 | O32: 0 | P32: =AVERAGE(F32:O32) -> 0 | U32: その他（物価上昇を考慮しない） | W32: =K46+K53 -> 0 | X32: =L46+L53 -> 0 | Y32: =M46+M53 -> 0 | Z32: =N46+N53 -> 0 | AA32: =O46+O53 -> 0 | AB32: =P46+P53 -> #DIV/0!
B33: 決算書「水道事業収益」数値 | O33: 504865980 | T33: 配水及び給水費 | V33: 配給水部門費 | W33: =SUM(W34:W40) -> 0 | X33: =SUM(X34:X40) -> 0 | Y33: =SUM(Y34:Y40) -> 0 | Z33: =SUM(Z34:Z40) -> 0 | AA33: =SUM(AA34:AA40) -> 0 | AB33: =SUM(AB34:AB40) -> #DIV/0!
B34: 差異の有無 | F34: =IF(F5=F33,"OK","NG") -> OK | G34: =IF(G5=G33,"OK","NG") -> OK | H34: =IF(H5=H33,"OK","NG") -> OK | I34: =IF(I5=I33,"OK","NG") -> OK | J34: =IF(J5=J33,"OK","NG") -> OK | K34: =IF(K5=K33,"OK","NG") -> OK | L34: =IF(L5=L33,"OK","NG") -> OK | M34: =IF(M5=M33,"OK","NG") -> OK | ... O34: =IF(O5=O33,"OK","NG") -> OK | U34: 人件費
B35: 水道事業費用 | F35: =SUM(F36,F104,F107) -> 0 | G35: =SUM(G36,G104,G107) -> 0 | H35: =SUM(H36,H104,H107) -> 0 | I35: =SUM(I36,I104,I107) -> 0 | J35: =SUM(J36,J104,J107) -> 0 | K35: =SUM(K36,K104,K107) -> 0 | L35: =SUM(L36,L104,L107) -> 0 | M35: =SUM(M36,M104,M107) -> 0 | ... O35: =SUM(O36,O104,O107) -> 0 | P35: =AVERAGE(F35:O35) -> 0 | U35: 動力費 | W35: =K64 -> 0 | X35: =L64 -> 0 | Y35: =M64 -> 0 | Z35: =N64 -> 0 | AA35: =O64 -> 0 | AB35: =P64 -> #DIV/0!
C36: 営業費用 | F36: =SUM(F37,F54,F69,F75,F96,F98,F101) -> 0 | G36: =SUM(G37,G54,G69,G75,G96,G98,G101) -> 0 | H36: =SUM(H37,H54,H69,H75,H96,H98,H101) -> 0 | I36: =SUM(I37,I54,I69,I75,I96,I98,I101) -> 0 | J36: =SUM(J37,J54,J69,J75,J96,J98,J101) -> 0 | K36: =SUM(K37,K54,K69,K75,K96,K98,K101) -> 0 | L36: =SUM(L37,L54,L69,L75,L96,L98,L101) -> 0 | M36: =SUM(M37,M54,M69,M75,M96,M98,M101) -> 0 | ... O36: =SUM(O37,O54,O69,O75,O96,O98,O101) -> 0 | P36: =AVERAGE(F36:O36) -> 0 | U36: 薬品費 | W36: =K65 -> 0 | X36: =L65 -> 0 | Y36: =M65 -> 0 | Z36: =N65 -> 0 | AA36: =O65 -> 0 | AB36: =P65 -> #DIV/0!
D37: 原水及び浄水費 | F37: =SUM(F38:F53) -> 0 | G37: =SUM(G38:G53) -> 0 | H37: =SUM(H38:H53) -> 0 | I37: =SUM(I38:I53) -> 0 | J37: =SUM(J38:J53) -> 0 | K37: =SUM(K38:K53) -> 0 | L37: =SUM(L38:L53) -> 0 | M37: =SUM(M38:M53) -> 0 | ... O37: =SUM(O38:O53) -> 0 | P37: =AVERAGE(F37:O37) -> 0 | U37: 修繕費 | W37: =K63 -> 0 | X37: =L63 -> 0 | Y37: =M63 -> 0 | Z37: =N63 -> 0 | AA37: =O63 -> 0 | AB37: =P63 -> #DIV/0!
E38: 賃金 | P38: =AVERAGE(F38:O38) -> #DIV/0! | U38: 委託料 | W38: =K60 -> 0 | X38: =L60 -> 0 | Y38: =M60 -> 0 | Z38: =N60 -> 0 | AA38: =O60 -> 0 | AB38: =P60 -> #DIV/0!
E39: 備消品費 | P39: =AVERAGE(F39:O39) -> #DIV/0! | U39: その他（物価上昇を考慮する） | W39: =SUM(K55:K59,K61,K66:K67) -> 0 | X39: =SUM(L55:L59,L61,L66:L67) -> 0 | Y39: =SUM(M55:M59,M61,M66:M67) -> 0 | Z39: =SUM(N55:N59,N61,N66:N67) -> 0 | AA39: =SUM(O55:O59,O61,O66:O67) -> 0 | AB39: =SUM(P55:P59,P61,P66:P67) -> #DIV/0!
E40: 燃料費 | P40: =AVERAGE(F40:O40) -> #DIV/0! | U40: その他（物価上昇を考慮しない） | W40: =K62+K68 -> 0 | X40: =L62+L68 -> 0 | Y40: =M62+M68 -> 0 | Z40: =N62+N68 -> 0 | AA40: =O62+O68 -> 0 | AB40: =P62+P68 -> #DIV/0!
...

Sheet 【BS】決算数値入力
B1: 収益的収支（税抜き）
B2: BS:女川町水道事業会計貸借対照表 | O2: （単位：千円）
B3: 款 | C3: 項 | D3: 目 | E3: 節 | F3: 実績期間
F4: H26 | G4: H27 | H4: H28 | I4: H29 | J4: H30 | K4: R1 | L4: R2 | M4: R3 | N4: R4 | O4: R5
B5: 資産の部 | F5: =F6+F26 -> 2380097996 | G5: =G6+G26 -> 2537722473 | H5: =H6+H26 -> 4801386046 | I5: =I6+I26 -> 12233768878 | J5: =J6+J26 -> 13712547499 | K5: =K6+K26 -> 15321720545 | L5: =L6+L26 -> 13316385816 | M5: =M6+M26 -> 13018106023 | ... O5: =O6+O26 -> 12170791768
C6: 固定資産 | F6: =F7+F22 -> 2147056679 | G6: =G7+G22 -> 1935770531 | H6: =H7+H22 -> 3185400831 | I6: =I7+I22 -> 7267487467 | J6: =J7+J22 -> 10241837798 | K6: =K7+K22 -> 12577603623 | L6: =L7+L22 -> 12376362332 | M6: =M7+M22 -> 12293301793 | ... O6: =O7+O22 -> 11730394419
D7: 有形固定資産 | F7: =SUM(F8,(F9-F10),(F11-F12),(F13-F14),(F15-F16),(F17-F18),(F19-F20),F21) -> 2147007479 | G7: =SUM(G8,(G9-G10),(G11-G12),(G13-G14),(G15-G16),(G17-G18),(G19-G20),G21) -> 1935721331 | H7: =SUM(H8,(H9-H10),(H11-H12),(H13-H14),(H15-H16),(H17-H18),(H19-H20),H21) -> 3185351631 | I7: =SUM(I8,(I9-I10),(I11-I12),(I13-I14),(I15-I16),(I17-I18),(I19-I20),I21) -> 7267438267 | J7: =SUM(J8,(J9-J10),(J11-J12),(J13-J14),(J15-J16),(J17-J18),(J19-J20),J21) -> 10241788598 | K7: =SUM(K8,(K9-K10),(K11-K12),(K13-K14),(K15-K16),(K17-K18),(K19-K20),K21) -> 12577554423 | L7: =SUM(L8,(L9-L10),(L11-L12),(L13-L14),(L15-L16),(L17-L18),(L19-L20),L21) -> 12376313132 | M7: =SUM(M8,(M9-M10),(M11-M12),(M13-M14),(M15-M16),(M17-M18),(M19-M20),M21) -> 12291412593 | ... O7: =SUM(O8,(O9-O10),(O11-O12),(O13-O14),(O15-O16),(O17-O18),(O19-O20),O21) -> 11728505219
E8: 土地 | F8: 45233178 | G8: 45233178 | H8: 45233178 | I8: 46918915 | J8: 46918915 | K8: 46918915 | L8: 46918915 | M8: 46918915 | N8: 46918915 | O8: 46918915
E9: 建物 | F9: 59370402 | G9: 59370402 | H9: 91470402 | I9: 89113320 | J9: 89113320 | K9: 1343128687 | L9: 1343128687 | M9: 826599519 | N9: 826599519 | O9: 826599519
E10: (建)減価償却累計額 | F10: 33818728 | G10: 34777993 | H10: 35737258 | I10: 35628402 | J10: 37580772 | K10: 39396251 | L10: 63693534 | M10: 78177861 | N10: 92652413 | O10: 107126965
E11: 構築物 | F11: 2572383314 | G11: 2268080298 | H11: 2526407046 | I11: 4706136663 | J11: 4706136663 | K11: 5789073943 | L11: 5789073943 | M11: 9380476976 | N11: 9462973196 | O11: 9462973196
E12: (構)減価償却累計額 | F12: 965347881 | G12: 790807786 | H12: 792283372 | I12: 279247134 | J12: 406187489 | K12: 521442915 | L12: 680861584 | M12: 868310357 | N12: 1182092860 | O12: 1375313348
E13: 機械及び装置 | F13: 366676929 | G13: 384212699 | H13: 384597135 | I13: 318156805 | J13: 318156805 | K13: 2592286405 | L13: 2592286405 | M13: 3510077728 | N13: 3510077728 | O13: 3510077728
E14: (機)減価償却累計額 | F14: 221813804 | G14: 235985278 | H14: 246364814 | I14: 166404822 | J14: 182253600 | K14: 196783961 | L14: 343850683 | M14: 530301159 | N14: 714317516 | O14: 896423637
E15: 車両運搬具 | F15: 0 | G15: 0 | H15: 0 | I15: 0 | J15: 0 | K15: 0 | L15: 0 | M15: 0 | N15: 0 | O15: 0
E16: (車)減価償却累計額 | F16: 0 | G16: 0 | H16: 0 | I16: 0 | J16: 0 | K16: 0 | L16: 0 | M16: 0 | N16: 0 | O16: 0
E17: 工具器具及び備品 | F17: 3134000 | G17: 3134000 | H17: 924000 | I17: 924000 | J17: 924000 | K17: 924000 | L17: 924000 | M17: 924000 | N17: 924000 | O17: 924000
E18: (工)減価償却累計額 | F18: 2915700 | G18: 2966100 | H18: 877800 | I18: 877800 | J18: 877800 | K18: 877800 | L18: 877800 | M18: 877800 | N18: 877800 | O18: 877800
E19: 量水器 | F19: 6316071 | G19: 7058898 | H19: 9191977 | I19: 9064993 | J19: 10018309 | K19: 10249740 | L19: 10249740 | M19: 11710950 | N19: 11710950 | O19: 11710950
... E21: 建設仮勘定 | F21: 321704780 | G21: 237428032 | H21: 1207370563 | I21: 2584266044 | J21: 5702756936 | K21: 3559117411 | L21: 3689585765 | M21: 0 | N21: 18025897 | O21: 259008337
D22: 無形固定資産 | F22: =SUM(F23:F25) -> 49200 | G22: =SUM(G23:G25) -> 49200 | H22: =SUM(H23:H25) -> 49200 | I22: =SUM(I23:I25) -> 49200 | J22: =SUM(J23:J25) -> 49200 | K22: =SUM(K23:K25) -> 49200 | L22: =SUM(L23:L25) -> 49200 | M22: =SUM(M23:M25) -> 1889200 | ... O22: =SUM(O23:O25) -> 1889200
E23: 水利権 | F23: 0 | G23: 0 | H23: 0 | I23: 0 | J23: 0 | K23: 0 | L23: 0 | M23: 0 | N23: 0 | O23: 0
E24: 電話加入権 | F24: 49200 | G24: 49200 | H24: 49200 | I24: 49200 | J24: 49200 | K24: 49200 | L24: 49200 | M24: 49200 | N24: 49200 | O24: 49200
E25: その他無形固定資産 | F25: 0 | G25: 0 | H25: 0 | I25: 0 | J25: 0 | K25: 0 | L25: 0 | M25: 1840000 | N25: 1840000 | O25: 1840000
C26: 流動資産 | F26: =SUM(F27:F31) -> 233041317 | G26: =SUM(G27:G31) -> 601951942 | H26: =SUM(H27:H31) -> 1615985215 | I26: =SUM(I27:I31) -> 4966281411 | J26: =SUM(J27:J31) -> 3470709701 | K26: =SUM(K27:K31) -> 2744116922 | L26: =SUM(L27:L31) -> 940023484 | M26: =SUM(M27:M31) -> 724804230 | ... O26: =SUM(O27:O31) -> 440397349
D27: 現金預金 | F27: 111278743 | G27: 387970804 | H27: 541703435 | I27: 2381558496 | J27: 1404969361 | K27: 362817447 | L27: 565026725 | M27: 334744715 | N27: 143864193 | O27: 132458270
D28: 未収金 | F28: 119304242 | G28: 211927898 | H28: 1072286402 | I28: 2430272734 | J28: 1904004223 | K28: 2104310806 | L28: 202810510 | M28: 216699042 | N28: 78306576 | O28: 133778738 | P28: =AVERAGE(F28:O28) -> 8.4737012e+08 | Q28: =ROUND(【BS】決算数値入力!P28/【PL】決算数値入力!P7,3) -> 7.567
D29: 貯蔵品 | F29: 2458332 | G29: 2053240 | H29: 1995378 | I29: 1487206 | J29: 1693453 | K29: 2463653 | L29: 2253062 | M29: 3427286 | N29: 3315927 | O29: 4227154
D30: その他流動資産 | F30: 0 | G30: 0 | H30: 0 | I30: 152962975 | J30: 160042664 | K30: 274525016 | L30: 169933187 | M30: 169933187 | N30: 169933187 | O30: 169933187
D31: 前払金 | F31: 0 | G31: 0 | H31: 0 | I31: 0 | J31: 0 | K31: 0 | L31: 0 | M31: 0 | N31: 0 | O31: 0
B32: 決算書記載の「資産合計」数値 | F32: 2380097996 | G32: 2537722473 | H32: 4801386046 | I32: 12233768878 | J32: 13712547499 | K32: 15321720545 | L32: 13316385816 | M32: 13018106023 | N32: 12275738271
B33: 差異の有無 | F33: =IF(F32=F5,"OK","NG") -> OK | G33: =IF(G32=G5,"OK","NG") -> OK | H33: =IF(H32=H5,"OK","NG") -> OK | I33: =IF(I32=I5,"OK","NG") -> OK | J33: =IF(J32=J5,"OK","NG") -> OK | K33: =IF(K32=K5,"OK","NG") -> OK | L33: =IF(L32=L5,"OK","NG") -> OK | M33: =IF(M32=M5,"OK","NG") -> OK | ... O33: =IF(O32=O5,"OK","NG") -> NG
B35: 負債の部 | F35: =F36+F40+F46 -> 1035293321 | G35: =G36+G40+G46 -> 1176501757 | H35: =H36+H40+H46 -> 2159362638 | I35: =I36+I40+I46 -> 6917884484 | J35: =J36+J40+J46 -> 5272906202 | K35: =K36+K40+K46 -> 7081250998 | L35: =L36+L40+L46 -> 5259514723 | M35: =M36+M40+M46 -> 4998980491 | ... O35: =O36+O40+O46 -> 4312299843
C36: 固定負債 | F36: =SUM(F37:F39) -> 145506374 | G36: =SUM(G37:G39) -> 143734775 | H36: =SUM(H37:H39) -> 157383556 | I36: =SUM(I37:I39) -> 270451036 | J36: =SUM(J37:J39) -> 332135617 | K36: =SUM(K37:K39) -> 353124203 | L36: =SUM(L37:L39) -> 455771228 | M36: =SUM(M37:M39) -> 591530416 | ... O36: =SUM(O37:O39) -> 763361128
D37: 引当金 | F37: 0 | G37: 0 | H37: 0 | I37: 0 | J37: 0 | K37: 0 | L37: 0 | M37: 0 | N37: 0 | O37: 0
D38: 企業債 | F38: 145506374 | G38: 143734775 | H38: 157383556 | I38: 270451036 | J38: 332135617 | K38: 353124203 | L38: 455771228 | M38: 591530416 | N38: 639346881 | O38: 763361128 | P38: 210154111 | Q38: 145371217 | R38: 93398792 | S38: 51146958 | T38: 28589700 | U38: 20827028 | V38: 15575425 | W38: 11249315 | X38: 7472491 | Y38: 3619451 | Z38: 0
D39: 退職給付引当金 | F39: 0 | G39: 0 | H39: 0 | I39: 0 | J39: 0 | K39: 0 | L39: 0 | M39: 0 | N39: 0 | O39: 0
C40: 流動負債 | F40: =SUM(F41:F45) -> 44339482 | G40: =SUM(G41:G45) -> 419166341 | H40: =SUM(H41:H45) -> 1446854865 | I40: =SUM(I41:I45) -> 4707571986 | J40: =SUM(J41:J45) -> 3098278789 | K40: =SUM(K41:K45) -> 2331458110 | L40: =SUM(L41:L45) -> 671046620 | M40: =SUM(M41:M45) -> 442806688 | ... O40: =SUM(O41:O45) -> 217640899
D41: 一時借入金 | F41: 0 | G41: 198000000 | H41: 852000000 | I41: 2830000000 | J41: 3000000000 | K41: 1800000000 | L41: 600000000 | M41: 260000000 | N41: 100000000 | O41: 200000000
D42: 未払金 | F42: 40802389 | G42: 216756487 | H42: 588784896 | I42: 1874217518 | J42: 92927555 | K42: 526300084 | L42: 58138057 | M42: 172474380 | N42: 12616598 | O42: 8058954 | P42: =AVERAGE(F42:O42) -> 3.5910769e+08 | Q42: =ROUND(P42/【PL】決算数値入力!P35,3) -> 0.853
...

Sheet 【統計】水道統計指標
B1: 水道統計（女川町） | I1: ↓女川町の状況を確認して入力
B2: DS：水道用水供給事業調査表 | I2: ※H23資料なし。（H24資料内、前年度数値より入力）
B3: 項目 | C3: 該当箇所 | D3: コード | E3: 該当ページ | F3: 単位 | G3: H26 | H3: H27 | I3: H28 | J3: H29 | K3: H30 | L3: R1 | M3: R2 | N3: R3 | O3: R4 | P3: R5 | Q3: 平均
B4: 人口 行政区域内人口 | C4: （１－６）事業計画と水道普及 水道の普及状況 | D4: 0201 | E4: 2 | F4: 人 | G4: 7012 | H4: 6818 | I4: 6668 | J4: 6575 | K4: 6466 | L4: 6337 | M4: 6211 | N4: 6033 | O4: 5928 | P4: 6263 | Q4: =AVERAGE(G4:P4) -> 6431.1
B5: 人口 給水区域内人口 | C5: （１－６）事業計画と水道普及 水道の普及状況 | D5: 0202 | E5: 2 | F5: 人 | G5: 5621 | H5: 5526 | I5: 5500 | J5: 6575 | K5: 6466 | L5: 6337 | M5: 6209 | N5: 6031 | O5: 5926 | P5: 6263 | Q5: =AVERAGE(G5:P5) -> 6045.4
B6: 人口 計画給水人口 | C6: （１－６）事業計画と水道普及 水道の普及状況 | D6: 0204 | E6: 2 | F6: 人 | G6: 12000 | H6: 12000 | I6: 12000 | J6: 8055 | K6: 8055 | L6: 8055 | M6: 8055 | N6: 8055 | O6: 8055 | P6: 7600 | Q6: =AVERAGE(G6:P6) -> 9193
B7: 人口 現在給水人口 | C7: （１－６）事業計画と水道普及 水道の普及状況 | D7: 0206 | E7: 2 | F7: 人 | G7: 5620 | H7: 5525 | I7: 5499 | J7: 6572 | K7: 6463 | L7: 6335 | M7: 6209 | N7: 6031 | O7: 5926 | P7: 5317 | Q7: =AVERAGE(G7:P7) -> 5949.7
B8: 人口 給水普及率 | C8: （１－６）事業計画と水道普及 水道の普及状況 | D8: 0208 | E8: 2 | F8: ％ | G8: 100 | H8: 100 | I8: 100 | J8: 100 | K8: 100 | L8: 100 | M8: 100 | N8: 100 | O8: 100 | P8: 84.9 | Q8: =AVERAGE(G8:P8) -> 98.49
B9: 世帯数 行政区域内世帯数 | C9: （１－６）事業計画と水道普及 水道の普及状況 | D9: 0209 | E9: 2 | F9: 戸 | G9: 3179 | H9: 3153 | I9: 3137 | K9: 3125 | L9: 3105 | M9: 3074 | N9: 2975 | O9: 3014 | P9: 3045 | Q9: =AVERAGE(G9:P9) -> 3089.6667
B10: 世帯数 給水区域内世帯数 | C10: （１－６）事業計画と水道普及 水道の普及状況 | D10: 0210 | E10: 2 | F10: 戸 | G10: 2578 | H10: 2563 | I10: 2587 | K10: 3125 | L10: 3105 | M10: 3074 | N10: 2975 | O10: 3014 | P10: 3045 | Q10: =AVERAGE(G10:P10) -> 2896.2222
B11: 世帯数 現在給水世帯数 | C11: （１－６）事業計画と水道普及 水道の普及状況 | D11: 0212 | E11: 2 | F11: 戸 | G11: 2577 | H11: 2562 | I11: 2586 | K11: 3122 | L11: 3103 | M11: 3072 | N11: 2973 | O11: 3012 | P11: 3045 | Q11: =AVERAGE(G11:P11) -> 2894.6667
B12: 年間給水量 年間給水量 | C12: （３－２）給水状況 取水量・浄水量・給水量 | D12: 5020 | E12: 11 | F12: 千㎥ | G12: =G13+G16 -> 1035 | H12: =H13+H16 -> 1014 | I12: =I13+I16 -> 0 | J12: =J13+J16 -> 1168 | K12: =K13+K16 -> 1159 | L12: =L13+L16 -> 1112 | M12: =M13+M16 -> 1144 | N12: =N13+N16 -> 1207 | ... P12: =P13+P16 -> 1152 | Q12: =AVERAGE(G12:P12) -> 1018.1
B13: 年間給水量 有効水量 | C13: （３－２）給水状況 取水量・浄水量・給水量 | D13: 5021 | E13: 11 | F13: 千㎥ | G13: =G14+G15 -> 835 | H13: =H14+H15 -> 885 | I13: =I14+I15 -> 0 | J13: =J14+J15 -> 1054 | K13: =K14+K15 -> 1089 | L13: =L14+L15 -> 1077 | M13: =M14+M15 -> 1116 | N13: =N14+N15 -> 1155 | ... P13: =P14+P15 -> 937 | Q13: =AVERAGE(G13:P13) -> 928.5
B14: 年間給水量 内訳 有収水量 | C14: （３－２）給水状況 取水量・浄水量・給水量 | D14: 5022 | E14: 11 | F14: 千㎥ | G14: 791 | H14: 841 | J14: 1004 | K14: 1009 | L14: 986 | M14: 1024 | N14: 1053 | O14: 1028 | P14: 913 | Q14: =AVERAGE(G14:P14) -> 961
B15: 年間給水量 内訳 無収水量 | C15: （３－２）給水状況 取水量・浄水量・給水量 | D15: 5023 | E15: 11 | F15: 千㎥ | G15: 44 | H15: 44 | J15: 50 | K15: 80 | L15: 91 | M15: 92 | N15: 102 | O15: 109 | P15: 24 | Q15: =AVERAGE(G15:P15) -> 70.666667
B16: 年間給水量 無効水量 | C16: （３－２）給水状況 取水量・浄水量・給水量 | D16: 5024 | E16: 11 | F16: 千㎥ | G16: 200 | H16: 129 | J16: 114 | K16: 70 | L16: 35 | M16: 28 | N16: 52 | O16: 53 | P16: 215 | Q16: =AVERAGE(G16:P16) -> 99.555556
B17: 口径別給水契約数 13㎜ | C17: （３－４）給水状況 口径別給水契約数及び年間有収水量 | D17: 5329 | E17: 12 | F17: 件 | G17: 1602 | H17: 1432 | I17: 1027 | J17: 789 | K17: 789 | L17: 745 | M17: 728 | N17: 705 | O17: 698 | P17: 1870 | Q17: =AVERAGE(G17:P17) -> 1038.5
B18: 口径別給水契約数 20㎜ | C18: （３－４）給水状況 口径別給水契約数及び年間有収水量 | D18: 5331 | E18: 12 | F18: 件 | G18: 1124 | H18: 1379 | I18: 1889 | J18: 2062 | K18: 2062 | L18: 2132 | M18: 2133 | N18: 2141 | O18: 2142 | P18: 175 | Q18: =AVERAGE(G18:P18) -> 1723.9
B19: 口径別給水契約数 25㎜ | C19: （３－４）給水状況 口径別給水契約数及び年間有収水量 | D19: 5332 | E19: 12 | F19: 件 | G19: 56 | H19: 71 | I19: 71 | J19: 73 | K19: 73 | L19: 70 | M19: 69 | N19: 69 | O19: 69 | P19: 30 | Q19: =AVERAGE(G19:P19) -> 65.1
B20: 口径別給水契約数 30㎜ | C20: （３－４）給水状況 口径別給水契約数及び年間有収水量 | D20: 5333 | E20: 12 | F20: 件 | G20: 0 | H20: 0 | I20: 0 | J20: 0 | K20: 0 | L20: 0 | M20: 0 | N20: 0 | O20: 0 | P20: 12 | Q20: =AVERAGE(G20:P20) -> 1.2
B21: 口径別給水契約数 40㎜ | C21: （３－４）給水状況 口径別給水契約数及び年間有収水量 | D21: 5334 | E21: 12 | F21: 件 | G21: 45 | H21: 55 | I21: 61 | J21: 57 | K21: 57 | L21: 64 | M21: 72 | N21: 72 | O21: 72 | P21: 9 | Q21: =AVERAGE(G21:P21) -> 56.4
B22: 口径別給水契約数 50㎜ | C22: （３－４）給水状況 口径別給水契約数及び年間有収水量 | D22: 5335 | E22: 12 | F22: 件 | G22: 18 | H22: 23 | I22: 20 | J22: 20 | K22: 20 | L22: 21 | M22: 19 | N22: 21 | O22: 22 | P22: 12 | Q22: =AVERAGE(G22:P22) -> 19.6
B23: 口径別給水契約数 75㎜ | C23: （３－４）給水状況 口径別給水契約数及び年間有収水量 | D23: 5336 | E23: 12 | F23: 件 | G23: 6 | H23: 7 | I23: 5 | J23: 6 | K23: 6 | L23: 6 | M23: 8 | N23: 8 | O23: 8 | P23: 6 | Q23: =AVERAGE(G23:P23) -> 6.6
B24: 口径別給水契約数 100㎜ | C24: （３－４）給水状況 口径別給水契約数及び年間有収水量 | D24: 5337 | E24: 12 | F24: 件 | G24: 5 | H24: 5 | I24: 3 | J24: 4 | K24: 4 | L24: 4 | M24: 3 | N24: 3 | O24: 3 | P24: 1 | Q24: =AVERAGE(G24:P24) -> 3.5
B25: 口径別給水契約数 合計 | C25: （３－４）給水状況 口径別給水契約数及び年間有収水量 | D25: 5342 | E25: 12 | F25: 件 | G25: =SUM(G17:G24) -> 2856 | H25: =SUM(H17:H24) -> 2972 | I25: =SUM(I17:I24) -> 3076 | J25: =SUM(J17:J24) -> 3011 | K25: =SUM(K17:K24) -> 3011 | L25: =SUM(L17:L24) -> 3042 | M25: =SUM(M17:M24) -> 3032 | N25: =SUM(N17:N24) -> 3019 | ... P25: =SUM(P17:P24) -> 2115 | Q25: =AVERAGE(G25:P25) -> 2914.8
B26: 口径別給水有収水量 13㎜ | C26: （３－４）給水状況 口径別給水契約数及び年間有収水量 | D26: 5344 | E26: 12 | F26: 千㎥ | G26: 502 | H26: 463 | I26: 391 | J26: 295 | K26: 125 | L26: 116 | M26: 114 | N26: 108 | O26: 103 | P26: 419 | Q26: =AVERAGE(G26:P26) -> 263.6
B27: 口径別給水有収水量 20㎜ | C27: （３－４）給水状況 口径別給水契約数及び年間有収水量 | D27: 5346 | E27: 12 | F27: 千㎥ | G27: 451 | H27: 504 | I27: 601 | J27: 714 | K27: 382 | L27: 397 | M27: 410 | N27: 396 | O27: 378 | P27: 48 | Q27: =AVERAGE(G27:P27) -> 428.1
B28: 口径別給水有収水量 25㎜ | C28: （３－４）給水状況 口径別給水契約数及び年間有収水量 | D28: 5347 | E28: 12 | F28: 千㎥ | G28: 125 | H28: 150 | I28: 158 | J28: 148 | K28: 67 | L28: 62 | M28: 62 | N28: 65 | O28: 67 | P28: 24 | Q28: =AVERAGE(G28:P28) -> 92.8
B29: 口径別給水有収水量 30㎜ | C29: （３－４）給水状況 口径別給水契約数及び年間有収水量 | D29: 5348 | E29: 12 | F29: 千㎥ | G29: 0 | H29: 0 | I29: 0 | J29: 0 | K29: 0 | L29: 0 | M29: 0 | N29: 0 | O29: 0 | P29: 50 | Q29: =AVERAGE(G29:P29) -> 5
B30: 口径別給水有収水量 40㎜ | C30: （３－４）給水状況 口径別給水契約数及び年間有収水量 | D30: 5349 | E30: 12 | F30: 千㎥ | G30: 307 | H30: 319 | I30: 336 | J30: 342 | K30: 171 | L30: 158 | M30: 165 | N30: 172 | O30: 178 | P30: 58 | Q30: =AVERAGE(G30:P30) -> 220.6
B31: 口径別給水有収水量 50㎜ | C31: （３－４）給水状況 口径別給水契約数及び年間有収水量 | D31: 5350 | E31: 12 | F31: 千㎥ | G31: 263 | H31: 282 | I31: 282 | J31: 278 | K31: 141 | L31: 142 | M31: 145 | N31: 149 | O31: 146 | P31: 85 | Q31: =AVERAGE(G31:P31) -> 191.3
B32: 口径別給水有収水量 75㎜ | C32: （３－４）給水状況 口径別給水契約数及び年間有収水量 | D32: 5351 | E32: 12 | F32: 千㎥ | G32: 138 | H32: 166 | I32: 182 | J32: 197 | K32: 102 | L32: 97 | M32: 122 | N32: 153 | O32: 148 | P32: 222 | Q32: =AVERAGE(G32:P32) -> 152.7
B33: 口径別給水有収水量 100㎜ | C33: （３－４）給水状況 口径別給水契約数及び年間有収水量 | D33: 5352 | E33: 12 | F33: 千㎥ | G33: 41 | H33: 38 | I33: 36 | J33: 33 | K33: 22 | L33: 17 | M33: 15 | N33: 12 | O33: 10 | P33: 7 | Q33: =AVERAGE(G33:P33) -> 23.1
B34: 口径別給水有収水量 合計 | C34: （３－４）給水状況 口径別給水契約数及び年間有収水量 | D34: 5357 | E34: 12 | F34: 千㎥ | G34: =SUM(G26:G33) -> 1827 | H34: =SUM(H26:H33) -> 1922 | I34: =SUM(I26:I33) -> 1986 | J34: =SUM(J26:J33) -> 2007 | K34: =SUM(K26:K33) -> 1010 | L34: =SUM(L26:L33) -> 989 | M34: =SUM(M26:M33) -> 1033 | N34: =SUM(N26:N33) -> 1055 | ... P34: =SUM(P26:P33) -> 913 | Q34: =AVERAGE(G34:P34) -> 1377.2
B36: ※以下、削除予定。（確認の後、削除）
B37: 差異の確認（コード：5342) | G37: =IF(G25=G38,"OK","NG") -> NG | H37: =IF(H25=H38,"OK","NG") -> NG | I37: =IF(I25=I38,"OK","NG") -> NG | J37: =IF(J25=J38,"OK","NG") -> NG | K37: =IF(K25=K38,"OK","NG") -> NG | L37: =IF(L25=L38,"OK","NG") -> NG | M37: =IF(M25=M38,"OK","NG") -> NG | N37: =IF(N25=N38,"OK","NG") -> NG | ... P37: =IF(P25=P38,"OK","NG") -> OK
G38: 1961 | H38: 1978 | I38: 1997 | J38: 2000 | K38: 2016 | L38: 2050 | M38: 2063 | N38: 2080 | O38: 2086 | P38: 2115
B39: 差異の確認（コード：5357) | G39: =IF(G34=G40,"OK","NG") -> NG | H39: =IF(H34=H40,"OK","NG") -> NG | I39: =IF(I34=I40,"OK","NG") -> NG | J39: =IF(J34=J40,"OK","NG") -> NG | K39: =IF(K34=K40,"OK","NG") -> NG | L39: =IF(L34=L40,"OK","NG") -> NG | M39: =IF(M34=M40,"OK","NG") -> NG | N39: =IF(N34=N40,"OK","NG") -> NG | ... P39: =IF(P34=P40,"OK","NG") -> OK
G40: 883 | H40: 928 | I40: 843 | J40: 922 | K40: 909 | L40: 864 | M40: 862 | N40: 859 | O40: 894 | P40: 913

Sheet 【成行】財政シミュ
B2: 収益的収支（税抜き） | N2: （単位：千円） | T2: 1 | U2: 2 | V2: 3 | W2: 4 | X2: 5 | Y2: 6 | Z2: 7 | AA2: 8 | AB2: 9 | AC2: 10 | AD2: 11 | AE2: 12 | AF2: 13 | AG2: 14 | AH2: 15 | AI2: 16 | AJ2: 17 | AK2: 18 | AL2: 19 | AM2: 20 | AN2: 21 | AO2: 22 | AP2: 23 | AQ2: 24 | AR2: 25 | AS2: 26 | AT2: 27 | AU2: 28 | AV2: 29 | AW2: 30 | AX2: 31 | AY2: 32 | AZ2: 33 | BA2: 34 | BB2: 35 | BC2: 36 | BD2: 37 | BE2: 38 | BF2: 39 | BG2: 40 | BH2: 41 | BI2: 42 | BJ2: 43 | BK2: 44 | BL2: 45 | BM2: 46 | BN2: 47 | BO2: 48 | BP2: 49 | BQ2: 50
B3: 款 | C3: 項 | D3: 目 | F3: 総括原価の区分 | J3: 控除 項目 | K3: 将来設定条件 | L3: 物価 | M3: 算出根拠 | N3: 実績期間 | S3: 平均値 | T3: 料金算定期間 | X3: 参考期間
G4: 需要家費 | H4: 固定費 | I4: 変動費 | N4: R1 | O4: R2 | P4: R3 | Q4: R4 | R4: R5 | T4: R6 | U4: R7 | V4: R8 | W4: R9 | X4: R10 | Y4: R11 | Z4: R12 | AA4: R13 | AB4: R14 | AC4: R15 | AD4: R16 | AE4: R17 | AF4: R18 | AG4: R19 | AH4: R20 | AI4: R21 | AJ4: R22 | AK4: R23 | AL4: R24 | AM4: R25 | AN4: R26 | AO4: R27 | AP4: R28 | AQ4: R29 | AR4: R30 | AS4: R31 | AT4: R32 | AU4: R33 | AV4: R34 | AW4: R35 | AX4: R36 | AY4: R37 | AZ4: R38 | BA4: R39 | BB4: R40 | BC4: R41 | BD4: R42 | BE4: R43 | BF4: R44 | BG4: R45 | BH4: R46 | BI4: R47 | BJ4: R48 | BK4: R49 | BL4: R50 | BM4: R51 | BN4: R52 | BO4: R53 | BP4: R54 | BQ4: R55
B5: 水道事業収益 | N5: =【PL】決算数値入力!W5 -> 236084433 | O5: =【PL】決算数値入力!X5 -> 471816622 | P5: =【PL】決算数値入力!Y5 -> 506142175 | Q5: =【PL】決算数値入力!Z5 -> 593505600 | R5: =【PL】決算数値入力!AA5 -> 504865980 | S5: =【PL】決算数値入力!AB5 -> 3.4374651e+08 | T5: =SUM(T6,T11,T19,T20) -> 4.897277e+08 | U5: =SUM(U6,U11,U19,U20) -> 4.9683515e+08 | V5: =SUM(V6,V11,V19,V20) -> 5.5440086e+08 | W5: =SUM(W6,W11,W19,W20) -> 5.8790332e+08 | X5: =SUM(X6,X11,X19,X20) -> 5.8128791e+08 | Y5: =SUM(Y6,Y11,Y19,Y20) -> 5.7556906e+08 | Z5: =SUM(Z6,Z11,Z19,Z20) -> 5.669954e+08 | AA5: =SUM(AA6,AA11,AA19,AA20) -> 5.6319106e+08 | ... BQ5: =SUM(BQ6,BQ11,BQ19,BQ20) -> 1.7133013e+08
C6: 営業収益 | N6: =【PL】決算数値入力!W6 -> 115230130 | O6: =【PL】決算数値入力!X6 -> 119471832 | P6: =【PL】決算数値入力!Y6 -> 122357520 | Q6: =【PL】決算数値入力!Z6 -> 119852700 | R6: =【PL】決算数値入力!AA6 -> 120750259 | S6: =【PL】決算数値入力!AB6 -> 112378170 | T6: =SUM(T7:T10) -> 125118797 | U6: =SUM(U7:U10) -> 123815212 | V6: =SUM(V7:V10) -> 121932198 | W6: =SUM(W7:W10) -> 120296885 | X6: =SUM(X7:X10) -> 118705087 | Y6: =SUM(Y7:Y10) -> 117347425 | Z6: =SUM(Z7:Z10) -> 114527804 | AA6: =SUM(AA7:AA10) -> 113135742 | ... BQ6: =SUM(BQ7:BQ10) -> 72995032
D7: 給水収益 | K7: 【収益】給水収益シート参照 | N7: =【PL】決算数値入力!W7 -> 114968230 | O7: =【PL】決算数値入力!X7 -> 119265632 | P7: =【PL】決算数値入力!Y7 -> 122177720 | Q7: =【PL】決算数値入力!Z7 -> 119610300 | R7: =【PL】決算数値入力!AA7 -> 120553459 | S7: =【PL】決算数値入力!AB7 -> 111985280 | T7: ='【収益－現行】給水収益'!S32 -> 124725907 | U7: ='【収益－現行】給水収益'!T32 -> 123422322 | V7: ='【収益－現行】給水収益'!U32 -> 121539308 | W7: ='【収益－現行】給水収益'!V32 -> 119903995 | X7: ='【収益－現行】給水収益'!W32 -> 118312197 | Y7: ='【収益－現行】給水収益'!X32 -> 116954535 | Z7: ='【収益－現行】給水収益'!Y32 -> 114134914 | AA7: ='【収益－現行】給水収益'!Z32 -> 112742852 | ... BQ7: ='【収益－現行】給水収益'!BP32 -> 72602142
D8: 加入金 | N8: =【PL】決算数値入力!W8 -> 0 | O8: =【PL】決算数値入力!X8 -> 0 | P8: =【PL】決算数値入力!Y8 -> 0 | Q8: =【PL】決算数値入力!Z8 -> 0 | R8: =【PL】決算数値入力!AA8 -> 0 | S8: =【PL】決算数値入力!AB8 -> 0 | T8: =S8 -> 0 | U8: =T8 -> 0 | V8: =U8 -> 0 | W8: =V8 -> 0 | X8: =W8 -> 0 | Y8: =X8 -> 0 | Z8: =Y8 -> 0 | AA8: =Z8 -> 0 | ... BQ8: =BP8 -> 0
D9: 受託工事収益 | K9: 計上しない | N9: =【PL】決算数値入力!W9 -> 0 | O9: =【PL】決算数値入力!X9 -> 0 | P9: =【PL】決算数値入力!Y9 -> 0 | Q9: =【PL】決算数値入力!Z9 -> 0 | R9: =【PL】決算数値入力!AA9 -> 0 | S9: =【PL】決算数値入力!AB9 -> 0 | T9: 0 | U9: 0 | V9: 0 | W9: 0 | X9: 0 | Y9: 0 | Z9: 0 | AA9: 0 | AB9: 0 | AC9: 0 | AD9: 0 | AE9: 0 | AF9: 0 | AG9: 0 | AH9: 0 | AI9: 0 | AJ9: 0 | AK9: 0 | AL9: 0 | AM9: 0 | AN9: 0 | AO9: 0 | AP9: 0 | AQ9: 0 | AR9: 0 | AS9: 0 | AT9: 0 | AU9: 0 | AV9: 0 | AW9: 0 | AX9: 0 | AY9: 0 | AZ9: 0 | BA9: 0 | BB9: 0 | BC9: 0 | BD9: 0 | BE9: 0 | BF9: 0 | BG9: 0 | BH9: 0 | BI9: 0 | BJ9: 0 | BK9: 0 | BL9: 0 | BM9: 0 | BN9: 0 | BO9: 0 | BP9: 0 | BQ9: 0
D10: その他の営業収益 | J10: ● | K10: R1~R5決算の平均値で一定 | N10: =【PL】決算数値入力!W10 -> 261900 | O10: =【PL】決算数値入力!X10 -> 206200 | P10: =【PL】決算数値入力!Y10 -> 179800 | Q10: =【PL】決算数値入力!Z10 -> 242400 | R10: =【PL】決算数値入力!AA10 -> 196800 | S10: =【PL】決算数値入力!AB10 -> 392890 | T10: =S10 -> 392890 | U10: =T10 -> 392890 | V10: =U10 -> 392890 | W10: =V10 -> 392890 | X10: =W10 -> 392890 | Y10: =X10 -> 392890 | Z10: =Y10 -> 392890 | AA10: =Z10 -> 392890 | ... BQ10: =BP10 -> 392890
C11: 営業外収益 | N11: =【PL】決算数値入力!W11 -> 120854303 | O11: =【PL】決算数値入力!X11 -> 352344790 | P11: =【PL】決算数値入力!Y11 -> 383784655 | Q11: =【PL】決算数値入力!Z11 -> 473652900 | R11: =【PL】決算数値入力!AA11 -> 384115721 | S11: =【PL】決算数値入力!AB12 -> 15431.1 | T11: =SUM(T12:T16) -> 3.646089e+08 | U11: =SUM(U12:U16) -> 3.7301994e+08 | V11: =SUM(V12:V16) -> 4.3246866e+08 | W11: =SUM(W12:W16) -> 4.6760643e+08 | X11: =SUM(X12:X16) -> 4.6258282e+08 | Y11: =SUM(Y12:Y16) -> 4.5822163e+08 | Z11: =SUM(Z12:Z16) -> 4.524676e+08 | AA11: =SUM(AA12:AA16) -> 4.5005532e+08 | ... BQ11: =SUM(BQ12:BQ16) -> 98335098
D12: 受取利息及び配当金 | J12: ● | K12: R1~R5決算の平均値で一定 | N12: =【PL】決算数値入力!W12 -> 0 | O12: =【PL】決算数値入力!X12 -> 0 | P12: =【PL】決算数値入力!Y12 -> 0 | Q12: =【PL】決算数値入力!Z12 -> 0 | R12: =【PL】決算数値入力!AA12 -> 0 | S12: =【PL】決算数値入力!AB12 -> 15431.1 | T12: =S12 -> 15431.1 | U12: =T12 -> 15431.1 | V12: =U12 -> 15431.1 | W12: =V12 -> 15431.1 | X12: =W12 -> 15431.1 | Y12: =X12 -> 15431.1 | Z12: =Y12 -> 15431.1 | AA12: =Z12 -> 15431.1 | ... BQ12: =BP12 -> 15431.1
D13: 他会計補助金 | J13: ● | K13: 現状の算定式（＝減価償却費＋人件費＋支払利息）で算定 | N13: =【PL】決算数値入力!W13 -> 23034829 | O13: =【PL】決算数値入力!X13 -> 61004862 | P13: =【PL】決算数値入力!Y13 -> 0 | Q13: =【PL】決算数値入力!Z13 -> 25962175 | R13: =【PL】決算数値入力!AA13 -> 25117004 | S13: =【PL】決算数値入力!AB13 -> 13834221 | T13: =T44+T59 -> 25500721 | U13: =U44+U59 -> 33861477 | V13: =V44+V59 -> 38616631 | W13: =W44+W59 -> 47830328 | X13: =X44+X59 -> 55812079 | Y13: =Y44+Y59 -> 63330098 | Z13: =Z44+Z59 -> 67407860 | AA13: =AA44+AA59 -> 71335475 | ... BQ13: =BQ44+BQ59 -> 75107743
D14: 補助金 | V14: 59000000 | W14: 90000000 | X14: 90000000 | Y14: 90000000 | Z14: 90000000 | AA14: 90000000 | AB14: 90000000 | AC14: 90000000 | AD14: 90000000 | AE14: 90000000
D15: 雑収益 | J15: ● | K15: R1~R5決算の平均値で一定 | N15: =【PL】決算数値入力!W15 -> 2684327 | O15: =【PL】決算数値入力!X15 -> 2450229 | P15: =【PL】決算数値入力!Y15 -> 22402177 | Q15: =【PL】決算数値入力!Z15 -> 8371047 | R15: =【PL】決算数値入力!AA15 -> 2589660 | S15: =【PL】決算数値入力!AB15 -> 4890572.8 | T15: =S15 -> 4890572.8 | U15: =T15 -> 4890572.8 | V15: =U15 -> 4890572.8 | W15: =V15 -> 4890572.8 | X15: =W15 -> 4890572.8 | Y15: =X15 -> 4890572.8 | Z15: =Y15 -> 4890572.8 | AA15: =Z15 -> 4890572.8 | ... BQ15: =BP15 -> 4890572.8
D16: 長期前受金戻入益 | N16: =【PL】決算数値入力!W16 -> 95135147 | O16: =【PL】決算数値入力!X16 -> 288889699 | P16: =【PL】決算数値入力!Y16 -> 336382478 | Q16: =【PL】決算数値入力!Z16 -> 419319678 | R16: =【PL】決算数値入力!AA16 -> 336409057 | S16: =【PL】決算数値入力!AB16 -> 1.9672812e+08 | T16: =SUM(T17:T18) -> 334202174 | U16: =SUM(U17:U18) -> 334252462 | V16: =SUM(V17:V18) -> 329946028 | W16: =SUM(W17:W18) -> 3.248701e+08 | X16: =SUM(X17:X18) -> 3.1186474e+08 | Y16: =SUM(Y17:Y18) -> 2.9998553e+08 | Z16: =SUM(Z17:Z18) -> 2.9015374e+08 | AA16: =SUM(AA17:AA18) -> 2.8381384e+08 | ... BQ16: =SUM(BQ17:BQ18) -> 18321351
E17: R6末の取得資産 | K17: 固定資産台帳データに基づく算定額 | N17: =【PL】決算数値入力!W17 -> 95135147 | O17: =【PL】決算数値入力!X17 -> 288889699 | P17: =【PL】決算数値入力!Y17 -> 336382478 | Q17: =【PL】決算数値入力!Z17 -> 419319678 | R17: =【PL】決算数値入力!AA17 -> 336409057 | S17: =【PL】決算数値入力!AB17 -> 1.9672812e+08 | T17: 334202174 | U17: 334252462 | V17: 329946028 | W17: 323203522 | X17: 308882372 | Y17: 295687375 | Z17: 284539789 | AA17: 276884100 | AB17: 273884174 | AC17: 267903518 | AD17: 261262088 | AE17: 205550308 | AF17: 191542873 | AG17: 184974519 | AH17: 179375298 | AI17: 177581276 | AJ17: 160752472 | AK17: 158769256 | AL17: 156848393 | AM17: 155469435 | AN17: 153891335 | AO17: 152287794 | AP17: 149732486 | AQ17: 148229911 | AR17: 147808454 | AS17: 146754939 | AT17: 145900166 | AU17: 144227410 | AV17: 143083103 | AW17: 141709968 | AX17: 140410450 | AY17: 125972764 | AZ17: 121872042 | BA17: 120244124 | BB17: 115023758 | BC17: 101260785 | BD17: 91443893 | BE17: 57528148 | BF17: 39528004 | BG17: 36969798 | BH17: 36224421 | BI17: 35120010 | BJ17: 34484753 | BK17: 34171874 | BL17: 33895777 | BM17: 32945758 | BN17: 29650024 | BO17: 26441622 | BP17: 21615106 | BQ17: 18321351
E18: R7以降の取得資産 | K18: 償却計算額 | N18: =【PL】決算数値入力!W18 -> 0 | O18: =【PL】決算数値入力!X18 -> 0 | P18: =【PL】決算数値入力!Y18 -> 0 | Q18: =【PL】決算数値入力!Z18 -> 0 | R18: =【PL】決算数値入力!AA18 -> 0 | S18: =【PL】決算数値入力!AB18 -> 0 | T18: =新規取得!I5 -> 0 | U18: =新規取得!J5 -> 0 | V18: =新規取得!P5 -> 0 | W18: =新規取得!Q5 -> 1666578.9 | X18: =新規取得!R5 -> 2982368.4 | Y18: =新規取得!S5 -> 4298157.9 | Z18: =新規取得!T5 -> 5613947.4 | AA18: =新規取得!U5 -> 6929736.8 | AB18: =新規取得!V5 -> 6929736.8 | AC18: =新規取得!W5 -> 6929736.8 | ... BQ18: =新規取得!BK5 -> 0
C19: 引当金戻入益 | J19: ● | K19: 計上しない | N19: =【PL】決算数値入力!W19 -> 0 | O19: =【PL】決算数値入力!X19 -> 0 | P19: =【PL】決算数値入力!Y19 -> 0 | Q19: =【PL】決算数値入力!Z19 -> 0 | R19: =【PL】決算数値入力!AA19 -> 0 | S19: =【PL】決算数値入力!AB19 -> 0 | T19: 0 | U19: 0 | V19: 0 | W19: 0 | X19: 0 | Y19: 0 | Z19: 0 | AA19: 0 | AB19: 0 | AC19: 0 | AD19: 0 | AE19: 0 | AF19: 0 | AG19: 0 | AH19: 0 | AI19: 0 | AJ19: 0 | AK19: 0 | AL19: 0 | AM19: 0 | AN19: 0 | AO19: 0 | AP19: 0 | AQ19: 0 | AR19: 0 | AS19: 0 | AT19: 0 | AU19: 0 | AV19: 0 | AW19: 0 | AX19: 0 | AY19: 0 | AZ19: 0 | BA19: 0 | BB19: 0 | BC19: 0 | BD19: 0 | BE19: 0 | BF19: 0 | BG19: 0 | BH19: 0 | BI19: 0 | BJ19: 0 | BK19: 0 | BL19: 0 | BM19: 0 | BN19: 0 | BO19: 0 | BP19: 0 | BQ19: 0
C20: 特別利益 | N20: =【PL】決算数値入力!W20 -> 0 | O20: =【PL】決算数値入力!X20 -> 0 | P20: =【PL】決算数値入力!Y20 -> 0 | Q20: =【PL】決算数値入力!Z20 -> 0 | R20: =【PL】決算数値入力!AA20 -> 0 | S20: =【PL】決算数値入力!AB20 -> 0 | T20: =SUM(T21:T23) -> 0 | U20: =SUM(U21:U23) -> 0 | V20: =SUM(V21:V23) -> 0 | W20: =SUM(W21:W23) -> 0 | X20: =SUM(X21:X23) -> 0 | Y20: =SUM(Y21:Y23) -> 0 | Z20: =SUM(Z21:Z23) -> 0 | AA20: =SUM(AA21:AA23) -> 0 | ... BQ20: =SUM(BQ21:BQ23) -> 0
D21: 固定資産売却益 | J21: ● | K21: 計上しない | N21: =【PL】決算数値入力!W21 -> 0 | O21: =【PL】決算数値入力!X21 -> 0 | P21: =【PL】決算数値入力!Y21 -> 0 | Q21: =【PL】決算数値入力!Z21 -> 0 | R21: =【PL】決算数値入力!AA21 -> 0 | S21: =【PL】決算数値入力!AB21 -> 0 | T21: 0 | U21: 0 | V21: 0 | W21: 0 | X21: 0 | Y21: 0 | Z21: 0 | AA21: 0 | AB21: 0 | AC21: 0 | AD21: 0 | AE21: 0 | AF21: 0 | AG21: 0 | AH21: 0 | AI21: 0 | AJ21: 0 | AK21: 0 | AL21: 0 | AM21: 0 | AN21: 0 | AO21: 0 | AP21: 0 | AQ21: 0 | AR21: 0 | AS21: 0 | AT21: 0 | AU21: 0 | AV21: 0 | AW21: 0 | AX21: 0 | AY21: 0 | AZ21: 0 | BA21: 0 | BB21: 0 | BC21: 0 | BD21: 0 | BE21: 0 | BF21: 0 | BG21: 0 | BH21: 0 | BI21: 0 | BJ21: 0 | BK21: 0 | BL21: 0 | BM21: 0 | BN21: 0 | BO21: 0 | BP21: 0 | BQ21: 0
D22: 過年度修正益 | J22: ● | K22: 計上しない | N22: =【PL】決算数値入力!W22 -> 0 | O22: =【PL】決算数値入力!X22 -> 0 | P22: =【PL】決算数値入力!Y22 -> 0 | Q22: =【PL】決算数値入力!Z22 -> 0 | R22: =【PL】決算数値入力!AA22 -> 0 | S22: =【PL】決算数値入力!AB22 -> 0 | V22: 0 | W22: 0 | X22: 0 | Y22: 0 | Z22: 0 | AA22: 0 | AB22: 0 | AC22: 0 | AD22: 0 | AE22: 0 | AF22: 0 | AG22: 0 | AH22: 0 | AI22: 0 | AJ22: 0 | AK22: 0 | AL22: 0 | AM22: 0 | AN22: 0 | AO22: 0 | AP22: 0 | AQ22: 0 | AR22: 0 | AS22: 0 | AT22: 0 | AU22: 0 | AV22: 0 | AW22: 0 | AX22: 0 | AY22: 0 | AZ22: 0 | BA22: 0 | BB22: 0 | BC22: 0 | BD22: 0 | BE22: 0 | BF22: 0 | BG22: 0 | BH22: 0 | BI22: 0 | BJ22: 0 | BK22: 0 | BL22: 0 | BM22: 0 | BN22: 0 | BO22: 0 | BP22: 0 | BQ22: 0
D23: その他特別利益 | J23: ● | K23: 計上しない | N23: =【PL】決算数値入力!W23 -> 0 | O23: =【PL】決算数値入力!X23 -> 0 | P23: =【PL】決算数値入力!Y23 -> 0 | Q23: =【PL】決算数値入力!Z23 -> 0 | R23: =【PL】決算数値入力!AA23 -> 0 | S23: =【PL】決算数値入力!AB23 -> 0 | T23: 0 | U23: 0 | V23: 0 | W23: 0 | X23: 0 | Y23: 0 | Z23: 0 | AA23: 0 | AB23: 0 | AC23: 0 | AD23: 0 | AE23: 0 | AF23: 0 | AG23: 0 | AH23: 0 | AI23: 0 | AJ23: 0 | AK23: 0 | AL23: 0 | AM23: 0 | AN23: 0 | AO23: 0 | AP23: 0 | AQ23: 0 | AR23: 0 | AS23: 0 | AT23: 0 | AU23: 0 | AV23: 0 | AW23: 0 | AX23: 0 | AY23: 0 | AZ23: 0 | BA23: 0 | BB23: 0 | BC23: 0 | BD23: 0 | BE23: 0 | BF23: 0 | BG23: 0 | BH23: 0 | BI23: 0 | BJ23: 0 | BK23: 0 | BL23: 0 | BM23: 0 | BN23: 0 | BO23: 0 | BP23: 0 | BQ23: 0
B24: 水道事業費用 | N24: =【PL】決算数値入力!W24 -> 390874183 | O24: =【PL】決算数値入力!X24 -> 507845824 | P24: =【PL】決算数値入力!Y24 -> 543887736 | Q24: =【PL】決算数値入力!Z24 -> 694576672 | R24: =【PL】決算数値入力!AA24 -> 564428515 | S24: =【PL】決算数値入力!AB24 -> 4.2086899e+08 | T24: =SUM(T25,T58,T63) -> 532105330 | U24: =SUM(U25,U58,U63) -> 546680663 | V24: =SUM(V25,V58,V63) -> 554561152 | W24: =SUM(W25,W58,W63) -> 584482252 | X24: =SUM(X25,X58,X63) -> 591468537 | Y24: =SUM(Y25,Y58,Y63) -> 594356181 | Z24: =SUM(Z25,Z58,Z63) -> 594585505 | AA24: =SUM(AA25,AA58,AA63) -> 597174026 | ... BQ24: =SUM(BQ25,BQ58,BQ63) -> 280012115
