Workbook

Sheet WBS・進捗管理
A1: 第10期北塩原村高齢者福祉計画・第10期北塩原村介護保険事業計画 策定業務 WBS／進捗管理表
A2: 委託第27号／業務期間：契約締結の日〜令和9年3月31日／計画期間：令和9〜11年度 ｜ 出典：仕様書（8北保福第483号 別紙）を作業レベルに分解（対応は「仕様書対照」シート） ｜ 進捗基準日：令和8年10月13日
A4: No. | B4: 大分類 | C4: 中分類 | D4: 作業項目 | E4: 仕様書該当 | F4: 担当 | G4: 成果物・アウトプット | H4: 前提・依存 | I4: 想定時期 | J4: 予定開始 | K4: 予定完了 | L4: 実績開始 | M4: 実績完了 | N4: 進捗率 | O4: ステータス | P4: 備考
A5: ０-01 | B5: ０ 契約・立上げ | C5: 契約手続 | D5: 見積書の提出 | E5: 通知2 | F5: 受託者 | G5: 見積書 | I5: R8.8 | L5: 46235 | M5: 46254 | N5: 1 | O5: 完了 | P5: 受注決定の連絡を受領。
A6: ０-02 | B6: ０ 契約・立上げ | C6: 契約手続 | D6: 契約締結 | E6: 仕様書3 | F6: 双方 | G6: 委託契約書 | H6: 北塩原村委託契約約款に準拠 | I6: R8.9 | N6: 0.5 | O6: 確認中 | P6: 受注決定は連絡済。契約締結日・契約書の取り交わし状況を要確認。
A7: ０-03 | B7: ０ 契約・立上げ | C7: 立上げ | D7: キックオフ会議の開催 | E7: 仕様書4Ⅲ | F7: 双方 | G7: キックオフ会議資料・議事録 | I7: R8.9上 | L7: 46259 | M7: 46266 | N7: 1 | O7: 完了 | P7: 令和8年9月1日（火）北塩原村役場にて開催。議事録を受領し確認・論点整理を完了（doc22）。優先度S 16件のうち9件が決着。基準日R8.9.1・在宅調査の抽出基準・管理番号の紐付け・発送9/18・ラベル封筒は村が用意・回収は100件ごとの小分け送付。
A8: ０-04 | B8: ０ 契約・立上げ | C8: 立上げ | D8: 連絡体制・資料授受方法の確定 | E8: 仕様書4Ⅲ | F8: 双方 | G8: 連絡体制表 | H8: 所管課（保健福祉課福祉係）の確認 | I8: R8.9上 | L8: 46259 | N8: 0.5 | O8: 着手 | P8: 資料授受は継続中。所管課（住民課→保健福祉課）の確認が未了（doc01確認事項1）。★10/5：村への照会を6通の照会票にまとめた。従来の資料提供確認依頼書（9月8日・調査票の工程）とは別に、計画策定の工程の照会を束ごとに1通とする形にした。
A9: ０-05 | B9: ０ 契約・立上げ | C9: 立上げ | D9: 現行計画・関連計画・実績資料の受領 | E9: 仕様書4Ⅱ(2) | F9: 北塩原村 | G9: 第9期計画書／第5次総合振興計画／第3次健康21ほか | I9: R8.9上 | L9: 46259 | N9: 0.7 | O9: 着手 | P9: 第9期計画書・第9期概要版（表裏）に加え、第四次生涯学習推進計画（全112頁）を受領（doc21）。第五次総合振興計画・第3次健康21・障がい福祉計画が未受領。
A10: ０-06 | B10: ０ 契約・立上げ | C10: 立上げ | D10: 見える化システムのID・パスワードの受領 | E10: 確認 | F10: 北塩原村 | G10: アカウント情報 | I10: R8.9上 | L10: 46259 | N10: 0.9 | O10: 着手 | P10: 見える化の出力を分割して受領（ZIP20本・738冊）。本村の値26,480行を取り出し data/mieruka_batch.csv に収めた（doc52）。ID自体の授受は要確認。
A11: Ⅰ-07 | B11: Ⅰ ニーズ調査 | C11: Ⅰ-1 調査設計 | D11: 調査手法の決定（在宅：手法Ⅰ〜Ⅳ） | E11: 手引き／確認 | F11: 双方 | G11: 調査手法決定メモ | H11: 手法Ⅲは自動集計ソフトなし。仕様書Ⅰ(5)との整合を要確認 | I11: R8.9上 | L11: 46259 | M11: 46274 | N11: 1 | O11: 完了 | P11: ★議事録に記載なし。手法Ⅲか手法Ⅳ（新版 在宅生活改善調査）を加えるかが未決着。9/3の第1稿提出時に併せて提起する（doc22 A-1）。★10/10 村より「高齢者のアンケート発送は全て完了」とのご連絡をいただいた。発送が完了したということは、調査票・依頼状・封筒・宛名ラベル・管理番号がすべて確定して物として出ていったということであり、その前提の工程はいずれも完了している。実績完了日は校了日（令和8年9月9日・doc34）または議事録の発送日（令和8年9月18日）としており、実際の発送日は村にご教示いただいて置き直す。
A12: Ⅰ-08 | B12: Ⅰ ニーズ調査 | C12: Ⅰ-1 調査設計 | D12: 調査対象者の抽出条件の確定 | E12: 仕様書4Ⅰ(1) | F12: 双方 | G12: 抽出条件メモ | H12: ①要支援を含むか②更新・区分変更に限るか③サ高住等を含むか | I12: R8.9上 | L12: 46259 | M12: 46274 | N12: 1 | O12: 完了 | P12: ★在宅介護実態調査は「要支援1・2および要介護1〜5の在宅生活者等」150件で決着（議事録）。基準日は令和8年9月1日。ニーズ調査約850件の抽出基準（要支援を含むか）は未決着。★10/10 村より「高齢者のアンケート発送は全て完了」とのご連絡をいただいた。発送が完了したということは、調査票・依頼状・封筒・宛名ラベル・管理番号がすべて確定して物として出ていったということであり、その前提の工程はいずれも完了している。実績完了日は校了日（令和8年9月9日・doc34）または議事録の発送日（令和8年9月18日）としており、実際の発送日は村にご教示いただいて置き直す。
A13: Ⅰ-09 | B13: Ⅰ ニーズ調査 | C13: Ⅰ-1 調査設計 | D13: 調査票の設計（ニーズ調査） | E13: 仕様書4Ⅰ(2) | F13: 受託者 | G13: 調査票案 | H13: 厚労省令和7年8月版様式を基礎 | I13: R8.9上 | L13: 46269 | M13: 46274 | N13: 1 | O13: 完了 | P13: ★第1稿（0828版）を受領し令和7年8月版との全面突合を完了（doc23）。要修正：選択肢の順序が標準と逆になっている7か所（うち2か所は文字列の誤植）、標準様式の残骸3か所、問7の番号繰り上がり。村独自14問の採否を判定し、削除提案は問3(10)の1問のみ。★9/4：第2稿（0904版）を確認。指摘13件のうち11件が反映。ルビを57→105か所に拡充、通いの場の名称を現行事業名に修正、自由記述欄を新設。未対応は問1(2)①の選択肢順序と問7(7)の採用可否の2件。新たに保険外サービスの選択肢の不統一と個人情報の説明文の後退を検出（doc27）。★9/14：0909校正版（doc34）を確認。問1(2)①の選択肢順序は解消。一方、問1(4)住まいの種類と問4(16)若い人に話しかけるが削除済み、問4(15)病人を見舞うに削除の指示。いずれも見える化の登録対象で、問4(15)(16)が落ちるとR09社会的役割の低下が算出できずR99が10領域→9領域に減る。印刷前の判断を要する。★10/10 村より「高齢者のアンケート発送は全て完了」とのご連絡をいただいた。発送が完了したということは、調査票・依頼状・封筒・宛名ラベル・管理番号がすべて確定して物として出ていったということであり、その前提の工程はいずれも完了している。実績完了日は校了日（令和8年9月9日・doc34）または議事録の発送日（令和8年9月18日）としており、実際の発送日は村にご教示いただいて置き直す。
A14: Ⅰ-10 | B14: Ⅰ ニーズ調査 | C14: Ⅰ-1 調査設計 | D14: 調査票の設計（在宅介護実態調査） | E14: 仕様書4Ⅰ(2) | F14: 受託者 | G14: 調査票案 | H14: 調査手法の決定が前提 | I14: R8.9上 | L14: 46269 | M14: 46274 | N14: 1 | O14: 完了 | P14: ★第1稿を受領し手法Ⅲ標準様式との突合を完了（doc23）。要修正：標準の問13「訪問診療」が削除され問13が欠番、前回指摘2件（介護療養型医療施設の削除・傷病の選択肢13/14の入替）が未反映、基準月が空欄。村独自の問0・問6-1は番号体系を壊さない適切な設計。★9/4：第2稿で介護療養型医療施設の削除・傷病の選択肢13/14・基準月（問8）・訪問診療の復活がすべて反映。ただし訪問診療の番号が問12となり問12が重複・問13が欠番、問9の基準月が未修正、B票の案内文1行が削除された（doc27§3・§5-3）。★9/14：0909校正版（doc34）を確認。問12の重複・問13の欠番と問9の基準月は解消。傷病に「なし」「わからない」が追加され疾病数が算出可能に。サービスは12→9に整理（夜間対応型・定期巡回・看多機を削除。実績0で妥当）。残る印刷前の修正は問7-1の参照先「問6」→「問7」、問10の記号K→H・L→I、A票問15の分岐の食い違い。★10/10 村より「高齢者のアンケート発送は全て完了」とのご連絡をいただいた。発送が完了したということは、調査票・依頼状・封筒・宛名ラベル・管理番号がすべて確定して物として出ていったということであり、その前提の工程はいずれも完了している。実績完了日は校了日（令和8年9月9日・doc34）または議事録の発送日（令和8年9月18日）としており、実際の発送日は村にご教示いただいて置き直す。
A15: Ⅰ-11 | B15: Ⅰ ニーズ調査 | C15: Ⅰ-1 調査設計 | D15: 令和7年8月版 標準様式との逐条突合 | E15: 手引き | F15: 受託者 | G15: 突合ワークシート | H15: 必須項目・オプション項目の充足確認 | I15: R8.9上 | L15: 46261 | M15: 46261 | N15: 1 | O15: 完了 | P15: 122行・全行記入・要確認0件で完了（doc05／突合ワークシートCSV）。
A16: Ⅰ-12 | B16: Ⅰ ニーズ調査 | C16: Ⅰ-1 調査設計 | D16: オプション項目の採否決定 | E16: 仕様書4Ⅰ(2) | F16: 双方 | G16: 採否一覧 | H16: 「問6 就労について」の採否を含む | I16: R8.9上 | L16: 46261 | M16: 46274 | N16: 1 | O16: 完了 | P16: ★第1稿はオプション項目をほぼ全採用。不採用は問7(7)「この1か月間に会った友人・知人の人数」の1問のみだが、番号を繰り上げているため見える化への入力時に対応が崩れる。ICF分析の参加軸に使えるため採用を推奨（doc23§1-2）。★10/10 村より「高齢者のアンケート発送は全て完了」とのご連絡をいただいた。発送が完了したということは、調査票・依頼状・封筒・宛名ラベル・管理番号がすべて確定して物として出ていったということであり、その前提の工程はいずれも完了している。実績完了日は校了日（令和8年9月9日・doc34）または議事録の発送日（令和8年9月18日）としており、実際の発送日は村にご教示いただいて置き直す。
A17: Ⅰ-13 | B17: Ⅰ ニーズ調査 | C17: Ⅰ-1 調査設計 | D17: 村独自設問の設定 | E17: 仕様書4Ⅰ(2) | F17: 双方 | G17: 設問一覧 | H17: 除雪・在宅医療・成年後見・歯科受診・服薬ほか | I17: R8.9上 | L17: 46267 | M17: 46274 | N17: 1 | O17: 完了 | P17: ★第1稿に村独自14問（ニーズ調査）を確認し、1問ずつ採否を判定（doc23§4）。削除提案は問3(10)「1日に何回食事をとりますか」の1問のみで、他13問は施策・交付金の指標と結びつくため残置を推奨。問7(9)の自由記入3欄は入力コストのため簡素化を提案。在宅調査の問0・問6-1は適切。★10/10 村より「高齢者のアンケート発送は全て完了」とのご連絡をいただいた。発送が完了したということは、調査票・依頼状・封筒・宛名ラベル・管理番号がすべて確定して物として出ていったということであり、その前提の工程はいずれも完了している。実績完了日は校了日（令和8年9月9日・doc34）または議事録の発送日（令和8年9月18日）としており、実際の発送日は村にご教示いただいて置き直す。
A18: Ⅰ-14 | B18: Ⅰ ニーズ調査 | C18: Ⅰ-1 調査設計 | D18: 依頼状（表紙）の作成 | E18: 仕様書4Ⅰ(2) | F18: 受託者 | G18: 依頼状 | H18: 村長名・担当課・問合せ先・基準日・回答期限 | I18: R8.9上 | L18: 46274 | M18: 46274 | N18: 1 | O18: 完了 | P18: ★10/10 村より「高齢者のアンケート発送は全て完了」とのご連絡をいただいた。発送が完了したということは、調査票・依頼状・封筒・宛名ラベル・管理番号がすべて確定して物として出ていったということであり、その前提の工程はいずれも完了している。実績完了日は校了日（令和8年9月9日・doc34）または議事録の発送日（令和8年9月18日）としており、実際の発送日は村にご教示いただいて置き直す。実績開始日の記録がないため完了日と同じ日を置いた。実際の開始日は置き直す。
A19: Ⅰ-15 | B19: Ⅰ ニーズ調査 | C19: Ⅰ-1 調査設計 | D19: 調査票の村協議・確定 | E19: 仕様書4Ⅰ(2) | F19: 双方 | G19: 確定版調査票 | H19: 以降の全工程の起点 | I19: R8.9上 | L19: 46269 | M19: 46274 | N19: 1 | O19: 完了 | P19: ★議事録により9/3に第1稿提出、9/9頃に最終校了と確定。未決事項（手法・オプション項目・独自設問・依頼状名義・部数）は選択肢併記で提出する。★9/4：第2稿を受領しレビュー完了（doc27）。校了までの修正リスト11件を優先度付きで整理。必須3件（在宅の問13の番号・問9の基準月・ニーズ問1(2)①の選択肢順序）。★9/14：校了版の校正紙と対象者リスト・返信用封筒の版下を受領（doc34）。印刷前に決着が必要な事項6件を整理し依頼書に追加。返信用封筒の差出有効期間が回収期限と同日（2026年10月16日）で、期限翌日以降の投函が届かないため延長を要請。回収期限は手書きで10月16日（金）に確定。対象者はニーズ882人・在宅118人（在宅は想定150人を32人下回る）。★9/16：発送予定日（9/18）まで2日。印刷前に決着が必要な6件はいずれも未回答であり、本業務で現時点の最大のリスクである。とくに問4(15)(16)の削除は、見える化システムのR09（社会的役割の低下）が算出できなくなり、R99が10領域→9領域となって第9期との比較が成立しなくなる。印刷後は取り返しがつかない。返信用封筒の差出有効期間（2026年10月16日）も回収期限と同日で、期限翌日以降の投函が届かない。村へ至急の判断を要請している（確認事項 優先度S）。★10/10 村より「高齢者のアンケート発送は全て完了」とのご連絡をいただいた。発送が完了したということは、調査票・依頼状・封筒・宛名ラベル・管理番号がすべて確定して物として出ていったということであり、その前提の工程はいずれも完了している。実績完了日は校了日（令和8年9月9日・doc34）または議事録の発送日（令和8年9月18日）としており、実際の発送日は村にご教示いただいて置き直す。
A20: Ⅰ-16 | B20: Ⅰ ニーズ調査 | C20: Ⅰ-1 調査設計 | D20: ウェブ回答フォームの作成 | E20: 仕様書4Ⅰ(2) | F20: 受託者 | G20: ウェブフォーム | H20: 通信の暗号化・公開期間の設定 | I20: R8.9上 | L20: 46267 | M20: 46283 | N20: 1 | O20: 完了 | P20: ★QRコード併用は議事録で決着。実装方法（Googleフォームの可否）が未決着で、不可の場合は代替の構築期間が必要となり9/9校了に影響する（doc22 A-2）。★10/10 村より「高齢者のアンケート発送は全て完了」とのご連絡をいただいた。発送が完了したということは、調査票・依頼状・封筒・宛名ラベル・管理番号がすべて確定して物として出ていったということであり、その前提の工程はいずれも完了している。実績完了日は校了日（令和8年9月9日・doc34）または議事録の発送日（令和8年9月18日）としており、実際の発送日は村にご教示いただいて置き直す。ウェブ回答フォームは、二次元コードを印字した調査票が発送された以上、公開されていなければ回答できないため完了とした。稼働確認の記録の有無を確かめる。
A21: Ⅰ-17 | B21: Ⅰ ニーズ調査 | C21: Ⅰ-1 調査設計 | D21: 二次元コードの作成・調査票／依頼状への印字 | E21: 仕様書4Ⅰ(2) | F21: 受託者 | G21: 二次元コード | H21: URLの確定が前提 | I21: R8.9上 | L21: 46274 | M21: 46274 | N21: 1 | O21: 完了 | P21: ★10/10 村より「高齢者のアンケート発送は全て完了」とのご連絡をいただいた。発送が完了したということは、調査票・依頼状・封筒・宛名ラベル・管理番号がすべて確定して物として出ていったということであり、その前提の工程はいずれも完了している。実績完了日は校了日（令和8年9月9日・doc34）または議事録の発送日（令和8年9月18日）としており、実際の発送日は村にご教示いただいて置き直す。実績開始日の記録がないため完了日と同じ日を置いた。実際の開始日は置き直す。
A22: Ⅰ-18 | B22: Ⅰ ニーズ調査 | C22: Ⅰ-1 調査設計 | D22: 重複回答の管理方法の設計（管理番号） | E22: 仕様書4Ⅰ(2) | F22: 受託者 | G22: 管理番号設計書 | H22: 紙・ウェブの重複を排除 | I22: R8.9上 | L22: 46261 | M22: 46274 | N22: 1 | O22: 完了 | P22: ★議事録で方針決着。氏名は記載せず管理番号を付与し被保険者番号と紐付ける。具体的な番号形式は村のラベル作成仕様と一体で要調整。★10/10 村より「高齢者のアンケート発送は全て完了」とのご連絡をいただいた。発送が完了したということは、調査票・依頼状・封筒・宛名ラベル・管理番号がすべて確定して物として出ていったということであり、その前提の工程はいずれも完了している。実績完了日は校了日（令和8年9月9日・doc34）または議事録の発送日（令和8年9月18日）としており、実際の発送日は村にご教示いただいて置き直す。
A23: Ⅰ-101 | B23: Ⅰ ニーズ調査 | C23: Ⅰ-1 調査設計 | D23: ウェブ回答フォームの公開・稼働確認・受付停止 | E23: 仕様書4Ⅰ(2) | F23: 受託者 | G23: 稼働確認記録 | H23: 二次元コードの印字前に実機で回答→保存まで通す。回収期限の到来で受付を停止し、以後の紙回答との重複を断つ | I23: R8.9中〜10下 | L23: 46283 | N23: 0.7 | O23: 着手 | P23: ★仕様書Ⅰ(2)は「作成し」としか書いていないが、紙とウェブの併用を成り立たせるには公開・稼働確認・受付停止が要る。二次元コードの印字前に実機で回答→保存まで通す必要があり、印刷の校了（Ⅰ-102）と同時期の律速。Webフォームの実装方法が未決のため着手できていない。★10/10 村より「高齢者のアンケート発送は全て完了」とのご連絡をいただいた。発送が完了したということは、調査票・依頼状・封筒・宛名ラベル・管理番号がすべて確定して物として出ていったということであり、その前提の工程はいずれも完了している。実績完了日は校了日（令和8年9月9日・doc34）または議事録の発送日（令和8年9月18日）としており、実際の発送日は村にご教示いただいて置き直す。公開と稼働は発送により確認できる。受付停止は回収期限（令和8年10月16日）の後に行う。
A24: Ⅰ-19 | B24: Ⅰ ニーズ調査 | C24: Ⅰ-1 調査設計 | D24: 被保険者番号と照合可能な管理番号の設計 | E24: 手引き | F24: 双方 | G24: 管理番号設計書 | H24: 第10期の新規要件。村のラベル作成仕様と一体 | I24: R8.9上 | L24: 46261 | M24: 46274 | N24: 1 | O24: 完了 | P24: ★議事録で方針決着（同上）。見える化システムへの登録を見据えた設計とする。★10/10 村より「高齢者のアンケート発送は全て完了」とのご連絡をいただいた。発送が完了したということは、調査票・依頼状・封筒・宛名ラベル・管理番号がすべて確定して物として出ていったということであり、その前提の工程はいずれも完了している。実績完了日は校了日（令和8年9月9日・doc34）または議事録の発送日（令和8年9月18日）としており、実際の発送日は村にご教示いただいて置き直す。
A25: Ⅰ-20 | B25: Ⅰ ニーズ調査 | C25: Ⅰ-2 印刷・発送準備 | D25: 入稿データの作成 | E25: 仕様書4Ⅰ(3) | F25: 受託者 | G25: 入稿データ | H25: 調査票の確定が前提 | I25: R8.9中 | L25: 46279 | M25: 46283 | N25: 1 | O25: 完了 | P25: ★9/9頃の校了・印刷依頼が目標（議事録）。9/3の第1稿提出→修正・確認を経て確定する。★10/10 村より「高齢者のアンケート発送は全て完了」とのご連絡をいただいた。発送が完了したということは、調査票・依頼状・封筒・宛名ラベル・管理番号がすべて確定して物として出ていったということであり、その前提の工程はいずれも完了している。実績完了日は校了日（令和8年9月9日・doc34）または議事録の発送日（令和8年9月18日）としており、実際の発送日は村にご教示いただいて置き直す。
A26: Ⅰ-102 | B26: Ⅰ ニーズ調査 | C26: Ⅰ-2 印刷・発送準備 | D26: 印刷の校正・校了 | E26: 仕様書4Ⅰ(3) | F26: 双方 | G26: 校正紙・校了の記録 | H26: 仕様書(3)の「印刷」には校了の判断が含まれる。印刷後は取り返しがつかない | I26: R8.9中 | L26: 46274 | M26: 46274 | N26: 1 | O26: 完了 | P26: ★0909校正版の校正紙を受領し、印刷前に決着が必要な6件を整理した（doc34）。9/16時点で6件とも未回答で、本業務で現時点の最大のリスク。とくに問4(15)(16)の削除はR09（社会的役割の低下）が算出できなくなり、R99が10領域→9領域となって第9期との比較が成立しない。返信用封筒の差出有効期間が回収期限と同日である点も未決。★10/10 村より「高齢者のアンケート発送は全て完了」とのご連絡をいただいた。発送が完了したということは、調査票・依頼状・封筒・宛名ラベル・管理番号がすべて確定して物として出ていったということであり、その前提の工程はいずれも完了している。実績完了日は校了日（令和8年9月9日・doc34）または議事録の発送日（令和8年9月18日）としており、実際の発送日は村にご教示いただいて置き直す。
A27: Ⅰ-103 | B27: Ⅰ ニーズ調査 | C27: Ⅰ-2 印刷・発送準備 | D27: 印刷部数の確定（予備を含む） | E27: 仕様書4Ⅰ(3) | F27: 双方 | G27: 部数内訳 | H27: 対象者はニーズ882人・在宅118人。仕様書の「約850人／約150人」との差を部数に反映 | I27: R8.9中 | L27: 46279 | M27: 46283 | N27: 1 | O27: 完了 | P27: ★対象者リストによりニーズ882人・在宅118人と判明。★9/24：村の回答により在宅118人で決着（仕様書の「約150人」との差異は解消）。残るのは予備を含めた部数の確定と、回収70〜80件を前提とした集計設計（要介護度3区分を2区分に束ねるか）の判断。★10/10 村より「高齢者のアンケート発送は全て完了」とのご連絡をいただいた。発送が完了したということは、調査票・依頼状・封筒・宛名ラベル・管理番号がすべて確定して物として出ていったということであり、その前提の工程はいずれも完了している。実績完了日は校了日（令和8年9月9日・doc34）または議事録の発送日（令和8年9月18日）としており、実際の発送日は村にご教示いただいて置き直す。
A28: Ⅰ-21 | B28: Ⅰ ニーズ調査 | C28: Ⅰ-2 印刷・発送準備 | D28: 調査票の印刷（ニーズ調査 A4約12頁・黒1色） | E28: 仕様書4Ⅰ(3) | F28: 受託者 | G28: 印刷物 約850部 | H28: 頁数は村と要協議 | I28: R8.9中 | L28: 46283 | M28: 46283 | N28: 1 | O28: 完了 | P28: ★10/10 村より「高齢者のアンケート発送は全て完了」とのご連絡をいただいた。発送が完了したということは、調査票・依頼状・封筒・宛名ラベル・管理番号がすべて確定して物として出ていったということであり、その前提の工程はいずれも完了している。実績完了日は校了日（令和8年9月9日・doc34）または議事録の発送日（令和8年9月18日）としており、実際の発送日は村にご教示いただいて置き直す。実績開始日の記録がないため完了日と同じ日を置いた。実際の開始日は置き直す。
A29: Ⅰ-22 | B29: Ⅰ ニーズ調査 | C29: Ⅰ-2 印刷・発送準備 | D29: 調査票の印刷（在宅調査 A4約8頁・黒1色） | E29: 仕様書4Ⅰ(3) | F29: 受託者 | G29: 印刷物 約150部 | I29: R8.9中 | L29: 46283 | M29: 46283 | N29: 1 | O29: 完了 | P29: ★10/10 村より「高齢者のアンケート発送は全て完了」とのご連絡をいただいた。発送が完了したということは、調査票・依頼状・封筒・宛名ラベル・管理番号がすべて確定して物として出ていったということであり、その前提の工程はいずれも完了している。実績完了日は校了日（令和8年9月9日・doc34）または議事録の発送日（令和8年9月18日）としており、実際の発送日は村にご教示いただいて置き直す。実績開始日の記録がないため完了日と同じ日を置いた。実際の開始日は置き直す。
A30: Ⅰ-23 | B30: Ⅰ ニーズ調査 | C30: Ⅰ-2 印刷・発送準備 | D30: 返信用封筒の印刷 | E30: 仕様書4Ⅰ(3) | F30: 受託者 | G30: 返信用封筒 | I30: R8.9中 | L30: 46274 | M30: 46283 | N30: 1 | O30: 完了 | P30: ★版下を受領済（doc34）。★9/24：配布用封筒は村が用意し費用は村側で請求処理することが決着したため、受託者が印刷するのは返信用（回収用）のみで確定（仕様書4Ⅰ(3)の「封筒（配布用・回収用）」との差異は解消）。差出有効期間が回収期限と同日（2026年10月16日）である点は未決で、期限翌日以降に投函された回答が届かない。★10/10 村より「高齢者のアンケート発送は全て完了」とのご連絡をいただいた。発送が完了したということは、調査票・依頼状・封筒・宛名ラベル・管理番号がすべて確定して物として出ていったということであり、その前提の工程はいずれも完了している。実績完了日は校了日（令和8年9月9日・doc34）または議事録の発送日（令和8年9月18日）としており、実際の発送日は村にご教示いただいて置き直す。
A31: Ⅰ-24 | B31: Ⅰ ニーズ調査 | C31: Ⅰ-2 印刷・発送準備 | D31: 調査対象者の抽出 | E31: 仕様書4Ⅰ(1) | F31: 北塩原村 | G31: 対象者リスト | H31: ニーズ約850人／在宅約150人 | I31: R8.9中 | L31: 46266 | M31: 46293 | N31: 1 | O31: 完了 | P31: ★村が抽出。2026/09/28に対象者名簿2件を受領した。ニーズ調査882人（リスト805＋引き抜き77）、在宅介護実態調査118人（リスト66＋引き抜き52）。個人情報を含むため原本はリポジトリに複製せず、属性の集計値のみを保存（doc16§5-2・§6に従い、年齢・性別・行政区・要介護度のみを読み、該当数10未満は伏せた）。
A32: Ⅰ-25 | B32: Ⅰ ニーズ調査 | C32: Ⅰ-2 印刷・発送準備 | D32: 宛名ラベルシールの作成・提供 | E32: 仕様書4Ⅰ(1) | F32: 北塩原村 | G32: 宛名ラベルシール | H32: 被保険者番号との照合可能な形式 | I32: R8.9中 | L32: 46279 | M32: 46283 | N32: 1 | O32: 完了 | P32: ★名簿の管理番号はニーズ調査が数字のみ、在宅介護実態調査が英字＋数字であることを確認した。調査票の印字見本がどちらも「1」であったことから形式の食い違いを疑い優先度Sで起票したが、印字見本は見本であり実物には名簿の形式のまま管理番号が入ることを村にご確認いただき解決した（doc43§2-4）。管理番号が欠損した場合は氏名でも突合できる。集計プログラムでは管理番号を数値ではなく文字列として扱う（在宅の英字＋数字が壊れるため）。★10/10 村より「高齢者のアンケート発送は全て完了」とのご連絡をいただいた。発送が完了したということは、調査票・依頼状・封筒・宛名ラベル・管理番号がすべて確定して物として出ていったということであり、その前提の工程はいずれも完了している。実績完了日は校了日（令和8年9月9日・doc34）または議事録の発送日（令和8年9月18日）としており、実際の発送日は村にご教示いただいて置き直す。
A33: Ⅰ-26 | B33: Ⅰ ニーズ調査 | C33: Ⅰ-2 印刷・発送準備 | D33: 配布用封筒の提供 | E33: 仕様書4Ⅰ(4) | F33: 北塩原村 | G33: 配布用封筒 | I33: R8.9中 | L33: 46266 | M33: 46283 | N33: 1 | O33: 完了 | P33: ★キックオフ会議で村が用意すると決着。★9/24：費用は村側で請求処理することを確認。提供期限は9/14（9/11への前倒しを要請中）。★10/10 村より「高齢者のアンケート発送は全て完了」とのご連絡をいただいた。発送が完了したということは、調査票・依頼状・封筒・宛名ラベル・管理番号がすべて確定して物として出ていったということであり、その前提の工程はいずれも完了している。実績完了日は校了日（令和8年9月9日・doc34）または議事録の発送日（令和8年9月18日）としており、実際の発送日は村にご教示いただいて置き直す。
A34: Ⅰ-27 | B34: Ⅰ ニーズ調査 | C34: Ⅰ-2 印刷・発送準備 | D34: 宛名ラベルの貼付 | E34: 仕様書4Ⅰ(4) | F34: 受託者 | G34: ― | H34: 村からの提供が前提 | I34: R8.9中 | L34: 46283 | M34: 46283 | N34: 1 | O34: 完了 | P34: ★10/10 村より「高齢者のアンケート発送は全て完了」とのご連絡をいただいた。発送が完了したということは、調査票・依頼状・封筒・宛名ラベル・管理番号がすべて確定して物として出ていったということであり、その前提の工程はいずれも完了している。実績完了日は校了日（令和8年9月9日・doc34）または議事録の発送日（令和8年9月18日）としており、実際の発送日は村にご教示いただいて置き直す。実績開始日の記録がないため完了日と同じ日を置いた。実際の開始日は置き直す。
A35: Ⅰ-28 | B35: Ⅰ ニーズ調査 | C35: Ⅰ-2 印刷・発送準備 | D35: 封入・封緘 | E35: 仕様書4Ⅰ(4) | F35: 受託者 | G35: 発送物 | I35: R8.9中 | L35: 46283 | M35: 46283 | N35: 1 | O35: 完了 | P35: ★10/10 村より「高齢者のアンケート発送は全て完了」とのご連絡をいただいた。発送が完了したということは、調査票・依頼状・封筒・宛名ラベル・管理番号がすべて確定して物として出ていったということであり、その前提の工程はいずれも完了している。実績完了日は校了日（令和8年9月9日・doc34）または議事録の発送日（令和8年9月18日）としており、実際の発送日は村にご教示いただいて置き直す。実績開始日の記録がないため完了日と同じ日を置いた。実際の開始日は置き直す。
A36: Ⅰ-29 | B36: Ⅰ ニーズ調査 | C36: Ⅰ-3 発送・回収 | D36: 発送（郵送費は受託者負担） | E36: 仕様書4Ⅰ(4) | F36: 受託者 | G36: 発送完了報告 | H36: 5連休（9/19〜9/23）の影響を考慮 | I36: R8.9下 | L36: 46283 | M36: 46283 | N36: 1 | O36: 完了 | P36: ★10/10 村より「高齢者のアンケート発送は全て完了」とのご連絡をいただいた。発送が完了したということは、調査票・依頼状・封筒・宛名ラベル・管理番号がすべて確定して物として出ていったということであり、その前提の工程はいずれも完了している。実績完了日は校了日（令和8年9月9日・doc34）または議事録の発送日（令和8年9月18日）としており、実際の発送日は村にご教示いただいて置き直す。対象はニーズ調査882人・在宅介護実態調査118人である。9月18日は金曜で翌日から5連休（敬老の日・国民の休日・秋分の日）であったため、配達が連休明けにずれ込んだ可能性がある（doc22）。実績開始日の記録がないため完了日と同じ日を置いた。実際の開始日は置き直す。
A37: Ⅰ-30 | B37: Ⅰ ニーズ調査 | C37: Ⅰ-3 発送・回収 | D37: 回収状況の管理 | E37: 仕様書4Ⅰ(4) | F37: 双方 | G37: 回収状況表 | H37: ★議事録により、村で100件程度集まるごとに随時受託者へ小分け送付する運用と確定 | I37: R8.9下〜10 | L37: 46283 | N37: 0.4 | O37: 着手 | P37: ★小分け送付の運用に合わせ、村側の送付単位と受託者側の入力進捗を突き合わせる管理表が必要。★10/10 村より「今集計分析を行なっています」とのご連絡をいただき着手を確認した。実績開始日はご連絡をいただいた日としており、実際の着手日は置き直す。回収件数と回収率は村からのご連絡を待って記録する。
A38: Ⅰ-31 | B38: Ⅰ ニーズ調査 | C38: Ⅰ-3 発送・回収 | D38: 督促（リマインド）の実施 | E38: 確認 | F38: 受託者 | G38: 督促文書 | H38: 第9期の在宅調査回収率45.8%を踏まえ実施要否を判断 | I38: R8.10上 | N38: 0 | O38: 未着手
A39: Ⅰ-32 | B39: Ⅰ ニーズ調査 | C39: Ⅰ-3 発送・回収 | D39: 回収期限の管理・締切 | E39: 仕様書4Ⅰ(4) | F39: 受託者 | G39: ― | I39: R8.10 | L39: 46283 | N39: 0.5 | O39: 着手 | P39: ★10/10 村より「今集計分析を行なっています」とのご連絡をいただき着手を確認した。実績開始日はご連絡をいただいた日としており、実際の着手日は置き直す。回収期限は令和8年10月16日（金）である。
A40: Ⅰ-33 | B40: Ⅰ ニーズ調査 | C40: Ⅰ-3 発送・回収 | D40: 開封確認 | E40: 仕様書4Ⅰ(4) | F40: 受託者 | G40: ― | I40: R8.10 | L40: 46305 | N40: 0.4 | O40: 着手 | P40: ★10/10 村より「今集計分析を行なっています」とのご連絡をいただき着手を確認した。実績開始日はご連絡をいただいた日としており、実際の着手日は置き直す。
A41: Ⅰ-94 | B41: Ⅰ ニーズ調査 | C41: Ⅰ-3 発送・回収 | D41: 調査票の受渡し記録の作成・運用 | E41: 確認 | F41: 双方 | G41: 受渡し記録 | H41: ★小分け送付の運用に対応。日付・数量・受渡者・受領者を記録。doc16に追記 | I41: R8.9下〜11 | L41: 46305 | N41: 0.3 | O41: 着手 | P41: ★議事録により村が100件程度ごとに随時送付する運用と確定。個人情報の授受が複数回に分かれるため受渡し記録の様式を用意し doc16 に追記する。★10/10 村より「今集計分析を行なっています」とのご連絡をいただき着手を確認した。実績開始日はご連絡をいただいた日としており、実際の着手日は置き直す。★村で100件程度集まるごとに随時受託者へ小分け送付する運用であり（doc22）、受渡しはすでに起きている。doc74で作ったのは従事者名簿・誓約書・持出簿・廃棄記録簿の4様式で、受渡し記録簿は作っていない。受領日・件数・媒体・引渡者・受領者を記録する様式を作る必要がある。
...

Sheet 村への確認事項
A1: 北塩原村への確認事項 一覧（基準日：令和8年10月13日）
A2: 優先度S＝9月3日の調査票第1稿提出・9月9日の校了・9月18日の発送を守るために決着が必要（キックオフ議事録で未決着のもの）／A＝令和8年9月中に確定が必要／B＝第1回策定委員会（11月）まで／C＝第2回以降 ｜ 出所の doc番号は docs/北塩原村_第10期/ 配下の分析資料に対応します
A4: 優先度 | B4: 区分 | C4: 確認事項 | D4: なぜ必要か／影響 | E4: 関連WBS No. | F4: 出所 | G4: 状況 | H4: 回答内容・回答日
A5: S | B5: スケジュール | C5: 対象者抽出・宛名ラベル・配布用封筒の提供時期 | D5: 村作業が遅れると発送が連鎖的に遅れる。9/19〜23が5連休。 | E5: Ⅰ-24,Ⅰ-25,Ⅰ-26 | F5: doc01-4 | G5: 未依頼
A6: S | B6: スケジュール | C6: 宛名ラベル・配布用封筒の提供期限の前倒し可否（9/14→9/11） | D6: ★提供が1日遅れると発送が5連休に食い込む。村作業の遅延に対する余裕がない。 | E6: Ⅰ-25,Ⅰ-26 | F6: doc19 指-2 | G6: 未依頼
A7: S | B7: スケジュール | C7: ★策定委員会 現委員の任期満了（令和8年9月30日）と改選手続きの所要期間 | D7: ★議事録で触れられていない。第2回を11月に開催するには10月中の改選・委嘱が必要。 | E7: Ⅱ-80 | F7: doc22 K-76 | G7: 未依頼
A8: S | B8: スケジュール | C8: ★実際の発送日と回収状況（件数・回収率）、ウェブ回答フォームの稼働確認 | D8: ★10/10 起票：村より「高齢者のアンケート発送は全て完了。今集計分析を行なっています」とのご連絡をいただいた。WBSの実績日は、議事録の発送日（令和8年9月18日）と校了日（令和8年9月9日）で置いている。次の4点をご教示いただきたい。①実際の発送日（9月18日は金曜で翌日から5連休であったため、配達が連休明けにずれ込んだ可能性がある）。②本日時点の回収件数（ニーズ調査・在宅介護実態調査それぞれ。対象は882人・118人）。回収率は督促（Ⅰ-31）の判断に用いる。③ウェブ回答フォームの稼働確認の記録の有無と、ウェブ回答の件数。二次元コードを印字して発送した以上フォームは公開されているはずだが、稼働確認の記録が当方にない（Ⅰ-101）。④これまでの受渡しの回数・日・件数。回収は村で100件程度集まるごとに随時小分け送付する運用であり（doc22）、受渡し記録簿（doc74 §4-2）にさかのぼって記録する必要がある。★回収期限は令和8年10月16日（金）である。 | E8: Ⅰ-29,Ⅰ-30,Ⅰ-101,Ⅰ-94 | F8: doc75 | G8: 未依頼
A9: S | B9: データ | C9: ★返信用封筒の差出有効期間の延長 | D9: ★★印刷前に要対応。版下は「差出有効期間 2026年10月16日まで」で回収期限（10月16日）と同日。期限翌日以降に投函された回答は料金受取人払が効かず届かない。通常は回収期限＋2週間程度。回収率に直結する。 | E9: Ⅰ-23,Ⅰ-102 | F9: doc34§1-2 | G9: 未依頼
A10: S | B10: データ | C10: ★ニーズ調査の対象者882人に対応する要介護認定データ（認定の有無・要介護度） | D10: ★2026/09/28に受領した名簿のうち、要介護度の列があるのは在宅介護実態調査の対象者118人分のみで、ニーズ調査の対象者882人分にはない。資料3の3-3（元気な軽度者）・3-4（生活機能からみた4つの層）・3-6（担い手の可能性）は、ニーズ調査の回答者一人ひとりの認定状況を必要とするため、このままでは作成できない。資料3の3-6は第10期に共助・互助の仕組みをどの規模で構想できるかを示す表であり、合意1・2の根拠でもある。★10/10 優先度をAからSに上げた：村より「高齢者のアンケート発送は全て完了。今集計分析を行なっています」とのご連絡をいただいた。集計が動き出した以上、これが入らないと資料3の3-3・3-4・3-6が作れないまま第2回策定委員会（11月）の資料作成に入ることになる。回答データに後から認定状況を付けることはできるため、集計そのものは止まらないが、クロス集計をやり直す手戻りが生じる。できるだけ早くご提供いただきたい。 | E10: Ⅰ-37,Ⅰ-38 | F10: doc43§1 | G10: 未依頼
A11: S | B11: データ | C11: ★要介護認定データの提供時期と項目（要介護度・認定日・サービス利用状況）および総合事業対象者（基本チェックリスト該当者）の情報 | D11: ★仕様書4Ⅰ(5)。ICF分析の「認定状況×生活機能リスク」表と在宅調査のクロスに必須。目的外利用の手続きの確認を含む。議事録の「元気な軽度者が総合事業を利用している」の検証はこの紐付けでしかできない。★9/28：集計軸の認定状況を「認定なし／事業対象者／要支援1・2／要介護1以上」の4区分に統一したため、要介護認定データだけでは事業対象者を判別できない。総合事業の対象者（基本チェックリスト該当者）の情報もあわせてご提供いただきたい。議事録の「元気な軽度者」は事業対象者と要支援認定者の両方を指すため、これがないと検証の対象が半分になる。★10/10 優先度をAからSに上げた（上記と同じ理由。集計が動き出した）。 | E11: Ⅰ-37 | F11: doc24§12 K-87 | G11: 未依頼
A12: S | B12: 分析 | C12: ★ICFを用いたクロス分析の具体的な期待像（軸・アウトプットのイメージ） | D12: ★議事録の新規要件。「元気な高齢者」×「地域のニーズ」で共助・互助の必要性を示す分析。調査票の設計段階でクロス軸を確保しないと後から分析できない。9/3の第1稿に影響。 | E12: Ⅰ-95 | F12: doc22 K-77 | G12: 未依頼
A13: S | B13: 方針 | C13: ★準備基金の取崩額を40,000,000円（残高の94.9%）とすることの可否（第11期が＋32.4%になる関係） | D13: ★国の推計ワークシートは準備基金の残高42,128,183円のうち40,000,000円を取り崩す前提で、第10期の保険料基準額を5,513.72円（第9期6,760.76円比▲18.45%）としている。一方、第11期は取崩の余地が残らないため7,301.29円（＋1,787.57円・＋32.4%）に跳ね上がる見込みである。第10期を下げるほど第11期の上がり幅が大きくなる関係であり、取崩額の水準は世代間の負担の公平に関わる村の判断事項である。厚生労働省の事務連絡3(3)も、保険料が第9期と比べて大きく増減している場合には推計データ全体の確認を求めている。第2回策定委員会の資料6に、取崩額を変えた場合の第10期・第11期の保険料の対比を示す案で進めてよいかをご確認いただきたい。★10/9 あわせてお願いしたいこと：取崩額を0円・24,000,000円とした場合の第10期・第11期の基準額を、推計ワークシートをご操作のうえ出力いただきたい。当方でも試算できるが、第10期の値が確かめられるのに対し、第11期は中長期シートが令和12年度の単年で立っているため、残高を単年に充てるか3か年に均すかで効きが3倍違う（残高42,128,183円の場合、単年基準では月額3,504円、3か年に均すと1,168円）。ワークシートで再計算いただければこの不確かさがなくなる。なお当方の算定（取崩なし6,756円）と国の算定（同6,610.55円）の差は145円であるが、第9期の条例基準額6,700円との向きが逆になる。当方の算定では取崩なしで条例6,800円（＋100円）、国の算定では条例6,600円（▲100円）であり、取崩しをしなくても第9期を下回る。このため資料6の3案のうちC案「保険料の据置きを優先し、基金を最大限取り崩す」は前提が崩れており、3案を国の算定の上に組み直す。 | E13: Ⅱ-63,Ⅱ-64,Ⅱ-107 | F13: doc66§2-3,doc72 | G13: 未依頼
A14: S | B14: 方針 | C14: ★ニーズ調査 問4(15)(16)（社会的役割）を削除するかどうか | D14: ★★印刷前に要決定。国の手引きは問4(13)〜(16)の4項目すべてが「いいえ」で「社会的役割の低下」と判定する。(16)は削除済み、(15)は0909校正で削除の指示。2項目が欠けるとR09が算出できず、見える化への登録も全国・県との比較も不可。R99が10領域→9領域に減るため第9期調査との比較も成立しない。左余白の「見える化関係」の書き込みは(10)〜(14)を指すとみられるが(15)(16)も登録対象である。 | E14: Ⅰ-15,Ⅰ-102 | F14: doc34§1-1 | G14: 未依頼
A15: S | B15: 方針 | C15: ★第9期計画の第1号被保険者数の推計に用いたデータ（国配布の住基ベース推計か別の推計か） | D15: ★国の事務連絡により、福島県では社人研の市町村別推計が公表されておらず第9期でも住基ベース推計が配布されていたことが判明。当方が示してきた「社人研推計をそのまま用いたため6.6%ずれた」という説明の前提が崩れた。第10期の説明の組み立てに影響する。 | E15: Ⅱ-59 | F15: doc28§1-1 K-105 | G15: 未依頼
A16: S | B16: 疑義 | C16: ★【期限 令和8年10月13日18時】令和9年度以降も0で入っている6サービスを0のままとしてよいか | D16: ★★国の推計ワークシートで、令和6・7年度に実績があるのに令和8年度が0になっているサービスが10件あり、うち6件は令和9年度以降も0のままである（介護予防短期入所生活介護／訪問入浴介護／短期入所療養介護（老健）／特定福祉用具購入費／住宅改修費／地域密着型通所介護）。村の申し送りは「福祉用具購入費や住宅改修費は金額が反映されずゼロ」としており、入力漏れの可能性がある。住宅改修費は令和6年度213.1千円・令和7年度314.5千円、特定福祉用具購入費は令和6年度381.2千円・令和7年度128.3千円の実績がある。厚生労働省の事務連絡は国の集計の提出期間を令和8年9月30日9時から10月13日（火）18時（厳守）としており、都道府県が異常値の確認を保険者に依頼して推計を支援する仕組みがあるため、10月13日18時までは修正の余地がある。0のままとするか修正するかを村にご確認いただき、修正する場合は県にご相談いただきたい。 | E16: Ⅱ-56,Ⅱ-62,Ⅱ-107 | F16: doc66§3-1,§5 | G16: 未依頼
... A211: C | B211: 成果品 | C211: 計画書の判型・レイアウト・表紙デザインの踏襲可否 | D211: 第9期はA4・本文104頁・全6章＋資料編。 | E211: Ⅱ-113,Ⅳ-89 | F211: doc01-10 | G211: 未依頼
A213: ■ 解決済み（記録）
A214: ― | B214: 疑義 | C214: 第1号被保険者数・認定者数の推計に2系列が併存していた（社内・解消済） | D214: ★素案5-2・5-3が社人研推計（国勢調査ベース）、5-4以降が厚生労働省配布の推計用人口（住民基本台帳ベース）を用いており、令和11年の認定者数が230人と220人で食い違っていた。厚生労働省配布の系列（B案）に統一し、5-1・5-2・5-3を全面的に書き改めた。介護保険の第1号被保険者数が住民基本台帳を基礎とすること、国の推計ワークシートが同じ配布データを用いることによる。 | E214: Ⅱ-56,Ⅱ-64 | F214: doc35§7-3(1) | G214: 解決済
A215: ― | B215: データ | C215: 成年後見制度（市民後見人養成含む）の利用実態・実績 | D215: 令和7・8年度の成年後見制度利用促進施策に係る取組状況調査（市町村票）と会津権利擁護・成年後見センターの相談件数の受領により解決。利用者4人、市町村長申立て0件、市民後見人の登録0人・受任0件、中核機関・協議会・申立費用助成・報酬助成はいずれも整備済。 | E215: Ⅱ-68,Ⅱ-69 | F215: doc28§3 | G215: 解決済
A216: ― | B216: 体制 | C216: 所管課・窓口の確認（住民課→保健福祉課の変更の有無、担当者体制） | D216: 成年後見の調査票により解決。報告担当課・主管課とも保健福祉課であることを確認した。担当者名・連絡先は個人情報のため本表には記載しない。調査票の問合せ先表記も裏づけられた。 | E216: ０-04 | F216: doc28§4 | G216: 解決済
A217: ― | B217: データ | C217: 所得段階別の第1号被保険者数 | D217: 令和8年度合計所得金額分布調査の入力済み調査票により解決。13段階・合計1,015人。非課税層60.3%、第1〜3段階だけで346人・34.1%。10万円刻みの分布も入手。 | E217: Ⅱ-64 | F217: doc28§2 | G217: 解決済
A218: ― | B218: データ | C218: 第10期の将来推計人口・第1号被保険者数の推計データ | D218: 厚労省配布の第10期将来推計用人口推計（住基ベース）と補正係数の受領により解決。補正後の第1号被保険者数は令和9年946人／令和10年939人／令和11年931人。ただし直近実績を約6%下回る論点あり（K-106）。 | E218: Ⅱ-59 | F218: doc28§1 | G218: 解決済
A219: ― | B219: 調査設計 | C219: ニーズ調査 選択肢の順序が標準と逆になっている7か所の修正 | D219: 第2稿（0904版）で問7の6か所を修正済。誤植2件（「そのような人はいないその他」「いないその他」）も解消。★問1(2)①の1か所が未修正のため別項目として再掲。 | E219: Ⅰ-09 | F219: doc27§1-1 | G219: 解決済（一部再掲）
A220: ― | B220: 調査設計 | C220: 在宅介護実態調査 前回指摘2件の反映（介護療養型医療施設の削除／傷病の選択肢13・14の入替） | D220: 第2稿（0904版）で両方とも修正済。 | E220: Ⅰ-10 | F220: doc27§1-2 | G220: 解決済
A221: ― | B221: 調査設計 | C221: 在宅介護実態調査 標準の問13「訪問診療」の復活 | D221: 第2稿（0904版）で復活。★ただし番号が問12として付されており問13が欠番。番号の修正を別項目として再掲。 | E221: Ⅰ-10 | F221: doc27§1-2 | G221: 解決済（番号は再掲）
A222: ― | B222: 調査設計 | C222: 調査の基準日（ニーズ調査・在宅介護実態調査） | D222: キックオフ会議（令和8年9月1日）で決着：令和8年9月1日を基準日とする。 | E222: Ⅰ-08,Ⅰ-24 | F222: doc22 §1 | G222: 解決済
A223: ― | B223: 調査設計 | C223: 在宅介護実態調査 約150人の抽出基準 | D223: キックオフ会議で決着：要支援1・2および要介護1〜5の在宅生活者等、150件。 | E223: Ⅰ-08,Ⅰ-24 | F223: doc22 §1 | G223: 解決済
A224: ― | B224: 成果品 | C224: 施策体系図（基本理念→基本目標5→施策28の階層図）の計画書への掲載 | D224: ★2026/09/25 作成して素案3-4と委員会資料4-4に掲載した。第9期が第3章に掲げていた施策体系とSDGsの対応を、体系図（3-4）と対応表（3-5）の2本立てに再構成したもの。3-4にあった同じ内容の平坦な表は図に置き換えて重複を解いた。計画書の推定は97頁で仕様書の約100頁に3頁の余裕がある。 | E224: Ⅱ-113,Ⅱ-71 | F224: doc41§6 | G224: 解決済
A225: ― | B225: データ | C225: 在宅調査票の管理番号の印字形式（N付きか数字のみか） | D225: ★2026/09/28 決着：調査票の印字見本の「1」はあくまで見本であり、実物には対象者ごとの管理番号が入る。名簿の形式（ニーズは数字のみ、在宅は英字＋数字）がそのまま印字される。当方が印字見本を実物と取り違えて優先度Sとしていたもので、問題は生じない。なお回収後の突合は管理番号によるが、万一欠損した場合は氏名で突合できることを村にご確認いただいた。 | E225: Ⅰ-18,Ⅰ-20,Ⅰ-38 | F225: doc34§5-3,doc43§2-4 | G225: 解決済
... A247: ― | B247: データ | C247: 社会保障審議会介護保険部会（令和8年9月18日）の資料の入手 | D247: ★10/8 解決：第136回社会保障審議会介護保険部会（令和8年9月18日）の資料1〜6および参考資料の提供を受けた。入手できていなかったために保留していた3件は、いずれも原典により確定した。①補足給付の区分の細分化の施行の時期は「令和9年度から」（第3段階②の負担限度額の上乗せは令和8年度から）で、年度の当初からの施行である（資料2）。素案1-8の2・5-12を書き改めた。②調整交付金の一定の取組による減額は、年齢区分の精緻化により交付額が増加する保険者について、①主要3事業（要介護認定の適正化／ケアプラン等の点検／医療情報との突合・縦覧点検）のいずれかを実施していない場合、または②令和9年2月から令和10年1月までの1人あたり給付費が外れ値（平均値＋2×標準偏差）に該当した保険者が、国保連の介護給付適正化システムの帳票を活用した点検（ケアプラン等の点検の実施件数・医療情報との突合の実施率・縦覧点検の実施率）について令和10年度下半期の実施率等を令和9年度下半期以上に保てなかった場合に、増加額の5%を減額するものである（資料5）。素案1-8の3・5-8(3)・6-4⑦を新設・改訂した。③特定地域サービス・特定地域居宅サービス等事業の制度の内容は、本部会の資料には含まれていなかった。引き続き省令・通知および介護給付費分科会の検討の結果を待つ（素案5-12(2)に残置）。あわせて、介護給付適正化計画の期数（第6期＝令和6〜8年度／第7期＝令和9〜11年度）、第1号保険料の標準段階・標準乗率の見直しの論点、介護情報基盤の適合基準日と本格運用開始日、ケアプランデータ連携の導入率と統合の時期、都道府県との協定の仕組み、介護経営DBの報告の再開時期、引き続き検討することとされた9事項が原典により確定した。 | E247: Ⅱ-50,Ⅱ-62,Ⅱ-64 | F247: doc70§2,doc71 | G247: 解決済

Sheet 仕様書対照
A1: 仕様書（委託第27号／8北保福第483号 別紙）とWBSの対照
A2: 仕様書の側から「求められていること」を列挙し、WBSのどの作業がそれを担うかを示したもの。状況の「○」は対応する作業がWBSにあること、「村」は村が実施し受託者の作業を伴わないことを表す ｜ 突合は scripts/verify_wbs.py で機械的に行い、漏れがあれば終了コード1を返す
A4: 区分 | B4: 条項 | C4: 仕様書が求めていること | D4: 担当 | E4: 対応WBS No. | F4: 対応する作業項目 | G4: 状況 | H4: 備考
A5: 見積徴取通知 | B5: 通知2-a | C5: 見積書を令和8年8月21日までに保健福祉課へ提出する | D5: 受託者 | E5: ０-01 | F5: 見積書の提出 | G5: ○
A6: 見積徴取通知 | B6: 通知2-b | C6: 契約保証金は免除 | D6: ― | E6: ０-02 | F6: 契約締結 | G6: ○ | H6: 契約手続の条件。作業を伴わない
A7: 1 委託業務名 | B7: 仕様書1-a | C7: 業務名「第10期北塩原村高齢者福祉計画・第10期北塩原村介護保険事業計画策定業務委託」 | D7: 双方 | E7: Ⅱ-111 | F7: 計画の名称・計画期間の表記の統一 | G7: ○ | H7: 計画書の表紙・奥付・本文の名称はこれに合わせる
A8: 2 業務の目的 | B8: 仕様書2-a | C8: 介護保険制度の改正など社会環境の変化を把握する | D8: 受託者 | E8: Ⅱ-50 Ⅱ-51 | F8: 制度改正動向の資料収集・整理 第10期国の基本指針の確認・反映 | G8: ○
A9: 2 業務の目的 | B9: 仕様書2-b | C9: 第9期計画期間（R6〜R8年度）における介護給付実績を評価する | D9: 受託者 | E9: Ⅱ-55 Ⅱ-56 | F9: 介護保険給付統計の取りまとめ 計画数値の評価（計画値と実績の乖離分析） | G9: ○
A10: 2 業務の目的 | B10: 仕様書2-c | C10: 高齢者福祉施策の実施状況を評価する | D10: 受託者 | E10: Ⅱ-53 Ⅱ-54 | F10: 高齢者福祉事業等の実績資料の受領 高齢者福祉事業等の実施状況の把握と課題整理 | G10: ○
A11: 2 業務の目的 | B11: 仕様書2-d | C11: ニーズ調査・在宅介護実態調査の結果を踏まえる | D11: 受託者 | E11: Ⅰ-48 Ⅱ-52 | F11: 調査結果報告書の執筆・レイアウト 前提条件と基本的課題の明確化 | G11: ○
A12: 2 業務の目的 | B12: 仕様書2-e | C12: 第10期計画期間の課題を明らかにした上で計画案を策定する | D12: 受託者 | E12: Ⅱ-70 Ⅱ-75 | F12: 第10期の課題の整理 素案の作成 | G12: ○
A13: 3 業務期間 | B13: 仕様書3-a | C13: 業務期間は契約締結の日から令和9年3月31日まで | D13: 双方 | E13: ０-02 Ⅳ-96 | F13: 契約締結 納品・検収 | G13: ○ | H13: 履行期限。全工程の外枠
A14: 3 業務期間 | B14: 仕様書3-b | C14: 計画期間は令和9年度から令和11年度までの3か年 | D14: 受託者 | E14: Ⅱ-111 | F14: 計画の名称・計画期間の表記の統一 | G14: ○
A15: 4Ⅰ ニーズ調査 | B15: 仕様書4Ⅰ(1)-a | C15: 調査対象区域は全村域 | D15: 双方 | E15: Ⅰ-08 | F15: 調査対象者の抽出条件の確定 | G15: ○
A16: 4Ⅰ ニーズ調査 | B16: 仕様書4Ⅰ(1)-b | C16: 介護予防・日常生活圏域ニーズ調査は約850人（一般高齢者・総合事業対象者・要支援認定者） | D16: 双方 | E16: Ⅰ-08 Ⅰ-24 | F16: 調査対象者の抽出条件の確定 調査対象者の抽出 | G16: ○ | H16: 実際の抽出は882人
A17: 4Ⅰ ニーズ調査 | B17: 仕様書4Ⅰ(1)-c | C17: 在宅介護実態調査は約150人（在宅の要介護認定者） | D17: 双方 | E17: Ⅰ-08 Ⅰ-24 | F17: 調査対象者の抽出条件の確定 調査対象者の抽出 | G17: ○ | H17: 実際の抽出は118人。2026/09/24 村の了解により決着（集計設計上の扱いは当方の判断事項）
A18: 4Ⅰ ニーズ調査 | B18: 仕様書4Ⅰ(1)-d | C18: 対象者の抽出は村が実施し、受託者へ宛名ラベルシールとして提供する | D18: 北塩原村 | E18: Ⅰ-24 Ⅰ-25 | F18: 調査対象者の抽出 宛名ラベルシールの作成・提供 | G18: ○
A19: 4Ⅰ ニーズ調査 | B19: 仕様書4Ⅰ(2)-a | C19: 厚生労働省が示す調査項目を踏まえて調査票を設計する | D19: 受託者 | E19: Ⅰ-09 Ⅰ-10 Ⅰ-11 | F19: 調査票の設計（ニーズ調査） 調査票の設計（在宅介護実態調査） 令和7年8月版 標準様式との逐条突合 | G19: ○ | H19: 令和7年8月版の標準様式
A20: 4Ⅰ ニーズ調査 | B20: 仕様書4Ⅰ(2)-b | C20: 村の過去の調査を踏まえて設計する（時系列比較の確保） | D20: 双方 | E20: Ⅰ-13 Ⅰ-41 | F20: 村独自設問の設定 時系列比較（第8期・第9期との対比） | G20: ○
A21: 4Ⅰ ニーズ調査 | B21: 仕様書4Ⅰ(2)-c | C21: 村と協議の上で調査票を決定する | D21: 双方 | E21: Ⅰ-12 Ⅰ-15 | F21: オプション項目の採否決定 調査票の村協議・確定 | G21: ○
A22: 4Ⅰ ニーズ調査 | B22: 仕様書4Ⅰ(2)-d | C22: 紙とウェブ回答を併用する | D22: 受託者 | E22: Ⅰ-16 Ⅰ-34 Ⅰ-35 | F22: ウェブ回答フォームの作成 用紙回答のデータ入力 ウェブ回答データの取込 | G22: ○
A23: 4Ⅰ ニーズ調査 | B23: 仕様書4Ⅰ(2)-e | C23: 専用のウェブ回答フォームを作成する | D23: 受託者 | E23: Ⅰ-16 Ⅰ-101 | F23: ウェブ回答フォームの作成 ウェブ回答フォームの公開・稼働確認・受付停止 | G23: ○ | H23: 作成のみならず公開・稼働確認・受付停止までが必要
A24: 4Ⅰ ニーズ調査 | B24: 仕様書4Ⅰ(2)-f | C24: 二次元コードを調査票または依頼状に印字する | D24: 受託者 | E24: Ⅰ-14 Ⅰ-17 | F24: 依頼状（表紙）の作成 二次元コードの作成・調査票／依頼状への印字 | G24: ○
A25: 4Ⅰ ニーズ調査 | B25: 仕様書4Ⅰ(2)-g | C25: 紙・ウェブ双方で回答された場合に重複集計されないよう管理番号等で管理する | D25: 受託者 | E25: Ⅰ-18 Ⅰ-36 | F25: 重複回答の管理方法の設計（管理番号） 重複回答の排除 | G25: ○
A26: 4Ⅰ ニーズ調査 | B26: 仕様書4Ⅰ(3)-a | C26: ニーズ調査票を A4判・約12ページ・黒1色で印刷する | D26: 受託者 | E26: Ⅰ-20 Ⅰ-21 | F26: 入稿データの作成 調査票の印刷（ニーズ調査 A4約12頁・黒1色） | G26: ○
A27: 4Ⅰ ニーズ調査 | B27: 仕様書4Ⅰ(3)-b | C27: 在宅介護実態調査票を A4判・約8ページ・黒1色で印刷する | D27: 受託者 | E27: Ⅰ-20 Ⅰ-22 | F27: 入稿データの作成 調査票の印刷（在宅調査 A4約8頁・黒1色） | G27: ○
A28: 4Ⅰ ニーズ調査 | B28: 仕様書4Ⅰ(3)-c | C28: 封筒（配布用・回収用）を各必要部数用意する | D28: 双方 | E28: Ⅰ-23 Ⅰ-26 Ⅰ-103 | F28: 返信用封筒の印刷 配布用封筒の提供 印刷部数の確定（予備を含む） | G28: ○ | H28: 2026/09/24 決着：配布用封筒は村が用意し費用は村側で請求処理。受託者の印刷は返信用（回収用）のみ
A29: 4Ⅰ ニーズ調査 | B29: 仕様書4Ⅰ(3)-d | C29: 印刷にあたり個人情報の取扱いに十分配慮する | D29: 受託者 | E29: Ⅴ-97 | F29: 個人情報の適正管理（アクセス制限・保管ルール） | G29: ○
A30: 4Ⅰ ニーズ調査 | B30: 仕様書4Ⅰ(3)-e | C30: 印刷物の校了を判断する（条項名「印刷」に含まれる） | D30: 双方 | E30: Ⅰ-102 | F30: 印刷の校正・校了 | G30: ○ | H30: 印刷後は修正できないため、本業務で最もリスクが高い判断
A31: 4Ⅰ ニーズ調査 | B31: 仕様書4Ⅰ(4)-a | C31: 村提供の宛名ラベルシールを配布用封筒に貼付する | D31: 受託者 | E31: Ⅰ-26 Ⅰ-27 | F31: 配布用封筒の提供 宛名ラベルの貼付 | G31: ○
A32: 4Ⅰ ニーズ調査 | B32: 仕様書4Ⅰ(4)-b | C32: 調査票と返信用封筒を封入・封緘する | D32: 受託者 | E32: Ⅰ-28 | F32: 封入・封緘 | G32: ○
A33: 4Ⅰ ニーズ調査 | B33: 仕様書4Ⅰ(4)-c | C33: 発送する | D33: 受託者 | E33: Ⅰ-29 | F33: 発送（郵送費は受託者負担） | G33: ○
A34: 4Ⅰ ニーズ調査 | B34: 仕様書4Ⅰ(4)-d | C34: 回収票は受託者が開封確認のうえデータ入力する | D34: 受託者 | E34: Ⅰ-30 Ⅰ-32 Ⅰ-33 Ⅰ-34 | F34: 回収状況の管理 回収期限の管理・締切 開封確認 用紙回答のデータ入力 | G34: ○
A35: 4Ⅰ ニーズ調査 | B35: 仕様書4Ⅰ(4)-e | C35: 発送費用は受託者の負担とする | D35: 受託者 | E35: Ⅰ-29 | F35: 発送（郵送費は受託者負担） | G35: ○ | H35: 往復約1,000通分
A36: 4Ⅰ ニーズ調査 | B36: 仕様書4Ⅰ(5)-a | C36: 厚生労働省が提示する集計ファイル様式を基本として入力する | D36: 受託者 | E36: Ⅰ-34 Ⅰ-35 Ⅰ-46 | F36: 用紙回答のデータ入力 ウェブ回答データの取込 見える化システム登録用データの作成 | G36: ○
A37: 4Ⅰ ニーズ調査 | B37: 仕様書4Ⅰ(5)-b | C37: 在宅介護実態調査は厚生労働省提供の認定データ自動関連付けプログラムを活用できる入力とする | D37: 双方 | E37: Ⅰ-07 Ⅰ-37 Ⅰ-38 | F37: 調査手法の決定（在宅：手法Ⅰ〜Ⅳ） 要介護認定データの受領 認定データとの関連付け（自動プログラム） | G37: ○
A38: 4Ⅰ ニーズ調査 | B38: 仕様書4Ⅰ(5)-c | C38: 入力を管理する（条項名「入力管理」＝入力後の精度の確認） | D38: 受託者 | E38: Ⅰ-104 | F38: 入力データの精度管理（論理チェック・ベリファイ） | G38: ○
A39: 4Ⅰ ニーズ調査 | B39: 仕様書4Ⅰ(6)-a | C39: 単純集計を行う | D39: 受託者 | E39: Ⅰ-39 | F39: 単純集計 | G39: ○
A40: 4Ⅰ ニーズ調査 | B40: 仕様書4Ⅰ(6)-b | C40: 基本属性別のクロス集計を行う | D40: 受託者 | E40: Ⅰ-40 | F40: 基本属性別クロス集計（地区・性別・年齢） | G40: ○
A41: 4Ⅰ ニーズ調査 | B41: 仕様書4Ⅰ(6)-c | C41: 時系列比較・設問間クロス等の詳細は村と協議の上で決定する | D41: 双方 | E41: Ⅰ-41 Ⅰ-42 | F41: 時系列比較（第8期・第9期との対比） 設問間クロス集計 | G41: ○
...

Sheet 受領資料・データ管理
A1: 受領資料・データ管理（基準日：令和8年10月13日）
A2: 仕様書4Ⅲ「資料授受の管理」に対応。★＝未受領で業務進行に影響するもの
A4: 区分 | B4: 資料・データ名 | C4: 内容・数量 | D4: 受領日 | E4: 整理先 | F4: 状況
A5: 仕様書 | B5: 委託第27号 仕様書（8北保福第483号 別紙） | C5: 業務内容・成果品・その他条件 | D5: 46259 | E5: docs/…/01_業務内容整理.md | F5: 受領済
A6: 現行計画 | B6: 第9期北塩原村高齢者福祉計画・介護保険事業計画 | C6: 本文104頁・全6章＋資料編 | D6: 46259 | E6: docs/…/01_業務内容整理.md | F6: 受領済
A7: 現行計画 | B7: 第9期計画 概要版（表・裏の2ページ） | C7: 基本理念・基本目標・数値①〜⑦・施策体系図 | D7: 46265 | E7: docs/…/08_第9期計画概要_計画実績突合.md | F7: 受領済
A8: 現行計画 | B8: ★北塩原村第五次総合振興計画（2017〜2026） | C8: 上位計画。第六次の策定状況も要確認 | D8: ― | E8: ― | F8: 未受領
A9: 現行計画 | B9: ★第3次健康きたしおばら21 | C9: 関連計画 | D9: ― | E9: ― | F9: 未受領
A10: 調査票 | B10: キックオフ資料（0828版・082802版） | C10: 2版をレビュー済 | D10: 46259 | E10: docs/…/03,06 | F10: 受領済
A11: 調査票 | B11: ニーズ調査・在宅介護実態調査 調査票案（資料B・C・C'） | C11: 修正案まで受領 | D11: 46259 | E11: docs/…/03,04 | F11: 受領済
A12: 国様式 | B12: 令和7年8月版 標準調査票（ニーズ調査・在宅介護実態調査） | C12: 逐条突合の基礎。要確認0件で完了 | D12: 46261 | E12: docs/…/05_令和7年8月版との逐条突合.md | F12: 受領済
A13: 見える化 | B13: A系 人口・世帯／B系 認定者 | C13: 第1号被保険者数・認定者数・認定率ほか | D13: 46259 | E13: data/mieruka_tidy.csv | F13: 受領済
A14: 見える化 | B14: C1 保険料／D系 給付費・受給者・利用回数 | C14: 第1号被保険者1人あたり給付月額ほか | D14: 46265 | E14: data/mieruka_tidy.csv | F14: 受領済
A15: 見える化 | B15: K系 施設数／D13系 給付費 | C15: 村内施設ゼロを確認 | D15: 46265 | E15: data/mieruka_tidy.csv | F15: 受領済
A16: 見える化 | B16: D25〜D30 定員／F15〜F25 地域包括支援センター | C16: 定員は平成30年度以降据置 | D16: 46265 | E16: docs/…/02 追記3 | F16: 受領済
A17: 見える化 | B17: F1〜F14・F28〜F40 日常生活支援総合事業 | C17: 17系列が実データなし（＝未実施） | D17: 46265 | E17: docs/…/02 追記3 | F17: 受領済
A18: 見える化 | B18: D47・D48 介護保険特別会計 歳入・歳出 | C18: 平成26〜令和5年度決算 | D18: 46265 | E18: docs/…/02 追記3 | F18: 受領済
A19: 見える化 | B19: W系 保険者機能強化推進交付金 評価指標（77ファイル） | C19: 令和3〜5年度。0点項目21件を抽出 | D19: 46265 | E19: docs/…/07 | F19: 受領済
A20: 見える化 | B20: W138〜W155 アウトプット・アウトカム指標（18ファイル） | C20: 令和5年度 | D20: 46265 | E20: docs/…/07 | F20: 受領済
A21: 見える化 | B21: 地域分析 P1〜P4 | C21: 県平均・全国平均・県内順位・全国順位 | D21: 46265 | E21: docs/…/09 | F21: 受領済
A22: 村データ | B22: ★介護給付費準備基金の現在高 | C22: 令和6年度末実績・令和7年度末見込 | D22: ― | E22: ― | F22: 未受領
A23: 村データ | B23: ★令和6年度決算・令和7年度給付費見込 | C23: 第9期の乖離確定に必要 | D23: ― | E23: ― | F23: 未受領
A24: 村データ | B24: ★通いの場の実数（令和3〜7年度） | C24: 見える化は令和2年度で更新停止。令和6年度分のみ受領 | D24: ― | E24: ― | F24: 一部受領
A25: 村データ | B25: ★高齢者福祉事業（村単独事業）の実績 | C25: 現行計画の評価に必要 | D25: ― | E25: ― | F25: 未受領
A26: 成果物 | B26: 第10期 要介護度別認定者数の推計（doc29／data/…推計.csv） | C26: 前期・後期別の認定率に分解。基準年が実績と完全一致 | D26: 46272 | E26: docs/…/29_要介護認定者数の推計.md | F26: 作成済
A27: 国資料 | B27: 第10期将来推計用人口推計（北塩原村のみ）＋推計の考え方（別紙1・2） | C27: 住基ベース推計と補正係数。令和22年まで。厚労省R8.8.24事務連絡／県R8.8.25通知 | D27: 46272 | E27: docs/…/28_受領資料分析…md §1 | F27: 受領済
A28: 村データ | B28: 令和8年度 合計所得金額分布調査 調査票（入力済） | C28: 所得段階別の第1号被保険者数13段階・合計1,015人。10万円刻みの分布を含む | D28: 46272 | E28: docs/…/28_受領資料分析…md §2 | F28: 受領済
A29: 村データ | B29: 成年後見制度利用促進施策に係る取組状況調査（令和7・8年度 市町村票） | C29: 利用者4人、中核機関整備済、市民後見人0人ほか | D29: 46272 | E29: docs/…/28_受領資料分析…md §3 | F29: 受領済
A30: 村データ | B30: 会津権利擁護・成年後見センター 相談件数（令和6・7年度） | C30: 本村 令和6年度134件／令和7年度76件。圏域13市町村の比較表 | D30: 46272 | E30: docs/…/28_受領資料分析…md §3-3 | F30: 受領済
A31: 調査票 | B31: 調査票 第2稿（0904版） | C31: 指摘13件のうち11件が反映。必須修正3件を新たに検出 | D31: 46269 | E31: docs/…/27_調査票第2稿レビュー.md | F31: 受領済
A32: 成果物 | B32: 第2回策定委員会 資料2・5・6・7（output/08_第2回策定委員会資料.docx） | C32: 26表・A4約30頁。資料2と7は本体完成、資料5と6は骨格 | D32: 46268 | E32: docs/…/26_第2回策定委員会_資料構成.md §11 | F32: 作成済
A33: 成果物 | B33: 集計仕様書（output/07_集計仕様書.xlsx） | C33: 6シート。ニーズ80設問・在宅26設問・派生変数20・クロス表20 | D33: 46268 | E33: docs/…/25_集計仕様書.md | F33: 作成済
A34: 成果物 | B34: 第2回策定委員会 資料構成（doc26） | C34: 資料1〜8・約53頁＋素案別冊。合意事項5点 | D34: 46268 | E34: docs/…/26_第2回策定委員会_資料構成.md | F34: 作成済
A35: 調査票 | B35: 調査票 第1稿（ニーズ調査・在宅介護実態調査） | C35: 0828版。令和7年8月版・手法Ⅲ標準様式と全面突合 | D35: 46267 | E35: docs/…/23_調査票第1稿レビュー_ICF分析設計.md | F35: 受領済
A36: 国資料 | B36: 令和8年度 交付金評価指標（市町村分）配点表 | C36: 全17頁。推進400点・支援400点、目標Ⅰ〜Ⅳ各100点 | D36: 46267 | E36: docs/…/20_交付金評価結果分析.md | F36: 受領済
A37: 国資料 | B37: 令和6年度 該当状況調査票集計表（全国一覧表） | C37: 全国1,741市町村。村は第398行。合計295点 | D37: 46267 | E37: docs/…/20_交付金評価結果分析.md | F37: 受領済
... A46: 村データ | B46: 調査対象者名簿（在宅介護実態調査118人・要介護度を含む） | C46: ★個人情報を含む。要介護1が49人・2が30人・3が18人・4が14人・5が7人 | D46: 46293 | E46: docs/…/43_調査対象者データの確認.md | F46: 受領済
A47: 村データ | B47: ★要介護認定データ（調査票との関連付け用） | C47: 仕様書4Ⅰ(5)。調査回収後に必要 | D47: ― | E47: ― | F47: 未受領
A48: 村データ | B48: 第10期介護保険事業計画 推計ワークシート（将来推計総括表。令和8年10月5日出力） | C48: 県へ10月5日に提出した暫定値。保険料基準額5,513.72円・準備基金残高42,128,183円・取崩額40,000,000円・確定した係数一式。福祉用具購入費・住宅改修費と新サービスは0で入っている | D48: 46302 | E48: docs/…/66_国の推計ワークシートの受領と内容確認.md | F48: 受領済
A49: 村データ | B49: 施設・居住系サービスの整備量見込みシート（令和8年10月6日提出） | C49: 認知症高齢者グループホームの定員27人・整備数0。令和6〜8年度は月平均の実績人数 | D49: 46302 | E49: docs/…/69_施設居住系の見込量を県シートに揃えた.md | F49: 受領済
...

Sheet 凡例・集計
B2: 凡例・入力ルール／進捗集計
B4: ■ 入力する列（ここだけ編集してください）
B5: 予定開始・予定完了 | C5: 日付 | D5: yyyy/mm/dd 形式で入力します。村との協議で工程が固まり次第、入力してください。
B6: 実績開始・実績完了 | C6: 日付 | D6: 着手日・完了日を実績として入力します。
B7: 進捗率 | C7: ％ | D7: 0〜100% を入力します。完了時は 100%。
B8: ステータス | C8: 選択 | D8: 未着手／着手／確認中／完了／保留／対象外 から選択します。
B9: 備考 | C9: 自由 | D9: 課題・懸案・村への確認事項などを記入します。
B11: ■ 行の塗り分け
B12: 薄い緑 | C12: 完了した作業です。
B13: 薄い黄 | C13: 着手中・確認中の作業、または北塩原村が担当する作業です。
B14: 薄い赤 | C14: 「村への確認事項」シートの優先度S・A、および未受領の資料です。
B16: ■ 進捗集計（WBSシートから自動集計されます）
B17: 大分類 | C17: 件数 | D17: 未着手 | E17: 着手 | F17: 確認中 | G17: 完了 | H17: 保留 | I17: 対象外
B18: ０ 契約・立上げ | C18: =COUNTIF('WBS・進捗管理'!$B$5:$B$121,$B18) | D18: =COUNTIFS('WBS・進捗管理'!$B$5:$B$121,$B18,'WBS・進捗管理'!$O$5:$O$121,D$17) | E18: =COUNTIFS('WBS・進捗管理'!$B$5:$B$121,$B18,'WBS・進捗管理'!$O$5:$O$121,E$17) | F18: =COUNTIFS('WBS・進捗管理'!$B$5:$B$121,$B18,'WBS・進捗管理'!$O$5:$O$121,F$17) | G18: =COUNTIFS('WBS・進捗管理'!$B$5:$B$121,$B18,'WBS・進捗管理'!$O$5:$O$121,G$17) | H18: =COUNTIFS('WBS・進捗管理'!$B$5:$B$121,$B18,'WBS・進捗管理'!$O$5:$O$121,H$17) | I18: =COUNTIFS('WBS・進捗管理'!$B$5:$B$121,$B18,'WBS・進捗管理'!$O$5:$O$121,I$17)
B19: Ⅰ ニーズ調査 | C19: =COUNTIF('WBS・進捗管理'!$B$5:$B$121,$B19) | D19: =COUNTIFS('WBS・進捗管理'!$B$5:$B$121,$B19,'WBS・進捗管理'!$O$5:$O$121,D$17) | E19: =COUNTIFS('WBS・進捗管理'!$B$5:$B$121,$B19,'WBS・進捗管理'!$O$5:$O$121,E$17) | F19: =COUNTIFS('WBS・進捗管理'!$B$5:$B$121,$B19,'WBS・進捗管理'!$O$5:$O$121,F$17) | G19: =COUNTIFS('WBS・進捗管理'!$B$5:$B$121,$B19,'WBS・進捗管理'!$O$5:$O$121,G$17) | H19: =COUNTIFS('WBS・進捗管理'!$B$5:$B$121,$B19,'WBS・進捗管理'!$O$5:$O$121,H$17) | I19: =COUNTIFS('WBS・進捗管理'!$B$5:$B$121,$B19,'WBS・進捗管理'!$O$5:$O$121,I$17)
B20: Ⅱ 計画策定 | C20: =COUNTIF('WBS・進捗管理'!$B$5:$B$121,$B20) | D20: =COUNTIFS('WBS・進捗管理'!$B$5:$B$121,$B20,'WBS・進捗管理'!$O$5:$O$121,D$17) | E20: =COUNTIFS('WBS・進捗管理'!$B$5:$B$121,$B20,'WBS・進捗管理'!$O$5:$O$121,E$17) | F20: =COUNTIFS('WBS・進捗管理'!$B$5:$B$121,$B20,'WBS・進捗管理'!$O$5:$O$121,F$17) | G20: =COUNTIFS('WBS・進捗管理'!$B$5:$B$121,$B20,'WBS・進捗管理'!$O$5:$O$121,G$17) | H20: =COUNTIFS('WBS・進捗管理'!$B$5:$B$121,$B20,'WBS・進捗管理'!$O$5:$O$121,H$17) | I20: =COUNTIFS('WBS・進捗管理'!$B$5:$B$121,$B20,'WBS・進捗管理'!$O$5:$O$121,I$17)
B21: Ⅲ 打合せ等 | C21: =COUNTIF('WBS・進捗管理'!$B$5:$B$121,$B21) | D21: =COUNTIFS('WBS・進捗管理'!$B$5:$B$121,$B21,'WBS・進捗管理'!$O$5:$O$121,D$17) | E21: =COUNTIFS('WBS・進捗管理'!$B$5:$B$121,$B21,'WBS・進捗管理'!$O$5:$O$121,E$17) | F21: =COUNTIFS('WBS・進捗管理'!$B$5:$B$121,$B21,'WBS・進捗管理'!$O$5:$O$121,F$17) | G21: =COUNTIFS('WBS・進捗管理'!$B$5:$B$121,$B21,'WBS・進捗管理'!$O$5:$O$121,G$17) | H21: =COUNTIFS('WBS・進捗管理'!$B$5:$B$121,$B21,'WBS・進捗管理'!$O$5:$O$121,H$17) | I21: =COUNTIFS('WBS・進捗管理'!$B$5:$B$121,$B21,'WBS・進捗管理'!$O$5:$O$121,I$17)
B22: Ⅳ 成果品・納品 | C22: =COUNTIF('WBS・進捗管理'!$B$5:$B$121,$B22) | D22: =COUNTIFS('WBS・進捗管理'!$B$5:$B$121,$B22,'WBS・進捗管理'!$O$5:$O$121,D$17) | E22: =COUNTIFS('WBS・進捗管理'!$B$5:$B$121,$B22,'WBS・進捗管理'!$O$5:$O$121,E$17) | F22: =COUNTIFS('WBS・進捗管理'!$B$5:$B$121,$B22,'WBS・進捗管理'!$O$5:$O$121,F$17) | G22: =COUNTIFS('WBS・進捗管理'!$B$5:$B$121,$B22,'WBS・進捗管理'!$O$5:$O$121,G$17) | H22: =COUNTIFS('WBS・進捗管理'!$B$5:$B$121,$B22,'WBS・進捗管理'!$O$5:$O$121,H$17) | I22: =COUNTIFS('WBS・進捗管理'!$B$5:$B$121,$B22,'WBS・進捗管理'!$O$5:$O$121,I$17)
B23: Ⅴ 管理 | C23: =COUNTIF('WBS・進捗管理'!$B$5:$B$121,$B23) | D23: =COUNTIFS('WBS・進捗管理'!$B$5:$B$121,$B23,'WBS・進捗管理'!$O$5:$O$121,D$17) | E23: =COUNTIFS('WBS・進捗管理'!$B$5:$B$121,$B23,'WBS・進捗管理'!$O$5:$O$121,E$17) | F23: =COUNTIFS('WBS・進捗管理'!$B$5:$B$121,$B23,'WBS・進捗管理'!$O$5:$O$121,F$17) | G23: =COUNTIFS('WBS・進捗管理'!$B$5:$B$121,$B23,'WBS・進捗管理'!$O$5:$O$121,G$17) | H23: =COUNTIFS('WBS・進捗管理'!$B$5:$B$121,$B23,'WBS・進捗管理'!$O$5:$O$121,H$17) | I23: =COUNTIFS('WBS・進捗管理'!$B$5:$B$121,$B23,'WBS・進捗管理'!$O$5:$O$121,I$17)
B24: 合計 | C24: =SUM(C18:C23) | D24: =SUM(D18:D23) | E24: =SUM(E18:E23) | F24: =SUM(F18:F23) | G24: =SUM(G18:G23) | H24: =SUM(H18:H23) | I24: =SUM(I18:I23)
B26: ■ 主要指標
B27: 全体進捗率（対象外を除く） | C27: =AVERAGEIF('WBS・進捗管理'!$O$5:$O$121,"<>対象外",'WBS・進捗管理'!$N$5:$N$121)
B28: 作業総数 | C28: =COUNTA('WBS・進捗管理'!$A$5:$A$121)
B29: 完了した作業 | C29: =COUNTIF('WBS・進捗管理'!$O$5:$O$121,"完了")
B30: 着手・確認中の作業 | C30: =COUNTIF('WBS・進捗管理'!$O$5:$O$121,"着手")+COUNTIF('WBS・進捗管理'!$O$5:$O$121,"確認中")
B31: 未着手の作業 | C31: =COUNTIF('WBS・進捗管理'!$O$5:$O$121,"未着手")
B32: 対象外の作業 | C32: =COUNTIF('WBS・進捗管理'!$O$5:$O$121,"対象外")
B33: 村への確認事項（優先度S） | C33: =COUNTIF('村への確認事項'!$A:$A,"S")
B34: 村への確認事項（優先度A） | C34: =COUNTIF('村への確認事項'!$A:$A,"A")
B35: 村への確認事項（未依頼） | C35: =COUNTIF('村への確認事項'!$G:$G,"未依頼")
B36: 未受領の資料・データ | C36: =COUNTIF('受領資料・データ管理'!$F:$F,"未受領")
B38: ■ マイルストーン（令和8年9月1日 キックオフ議事録により確定）
C39: 期日 | D39: 内容 | E39: 留意点
C40: 令和8年9月1日（火） | D40: キックオフ会議 | E40: 完了。議事録を受領（doc22）。S項目16件のうち9件が決着
B41: ★ | C41: 令和8年9月3日（木） | D41: 調査票 第1稿の提出 | E41: ★議事録で確定。未決事項は選択肢併記で提出
B42: ★ | C42: 令和8年9月9日（水）頃 | D42: 調査票の最終校了・印刷依頼 | E42: ★Webフォームの実装方法が未決だと間に合わない恐れ
C43: 令和8年9月14日（月） | D43: 宛名ラベル・配布用封筒の提供 | E43: 村。9/11への前倒しを要請
C44: 令和8年9月16〜17日 | D44: 宛名貼付・封入・封緘 | E44: 受託者
B45: ★ | C45: 令和8年9月18日（金）頃 | D45: アンケート発送 | E45: ★5連休（9/19〜9/23）の直前。9/17前倒しを協議
B46: ★ | C46: 令和8年9月30日（水） | D46: 策定委員会 現委員の任期満了 | E46: ★議事録で触れられず。第2回（11月）には改選が前提
...

Sheet ペンディング・作業順位
A2: ペンディングの影響度と作業順位（基準日 令和8年10月13日／対象の翌営業日 令和8年10月13日）
A4: ■ 影響度の定義（当方の作業に対する影響）
A5: 影響度 | B5: 呼び方 | C5: 意味
A6: 0 | B6: 社内 | C6: 村の回答を待つものではない。当方で確かめれば解消する。ペンディングとして数えない。
A7: 1 | B7: 停止 | C7: 回答がないと当方の作業が前に進まない。据え置きでは代替できず、回答後の差替えが章節の広い範囲に及ぶ。
A8: 2 | B8: 仮置き | C8: 仮定を置いて進められている。確定時に数値が動くため再算定と差替えが生じる。差替えの範囲は節の単位にとどまる。
A9: 3 | B9: 記載待ち | C9: 記載そのものは済んでいる。回答により文言・施策の内容が変わる。数値は動かない。
A10: 4 | B10: 工程外 | C10: 当方の作業は止まらない。村の内部手続または日程の決定を待つもの。
A11: 5 | B11: 対象外 | C11: 調査工程の項目。調査票は他メンバーが作成しているため当方では作業を進めない。
A13: ■ 未解決の確認事項 187件の内訳（影響度 × 優先度）
A14: 影響度 | B14: 呼び方 | C14: 優先度S | D14: 優先度A | E14: 優先度B | F14: 優先度C | G14: 小計 | H14: 備考
A15: 0 | B15: 社内 | C15: 0 | D15: 2 | E15: 0 | F15: 0 | G15: 2 | H15: 当方で確かめれば解消する。ペンディングとして数えない。
A16: 1 | B16: 停止 | C16: 4 | D16: 2 | E16: 0 | F16: 0 | G16: 6 | H16: 回答がないと成果品の数値が確定しない。最優先で照会する。
A17: 2 | B17: 仮置き | C17: 3 | D17: 28 | E17: 0 | F17: 0 | G17: 31 | H17: 仮定を置いて進めている。確定時に再算定と差替えが生じる。
A18: 3 | B18: 記載待ち | C18: 1 | D18: 35 | E18: 0 | F18: 0 | G18: 36 | H18: 記載は済んでいる。回答により文言・施策の内容が変わる。
A19: 4 | B19: 工程外 | C19: 2 | D19: 8 | E19: 0 | F19: 0 | G19: 10 | H19: 当方の作業は止まらない。村の内部手続または日程の決定を待つ。
A20: 5 | B20: 対象外 | C20: 22 | D20: 5 | E20: 4 | F20: 0 | G20: 31 | H20: 調査票は他メンバーが作成しているため当方では作業しない。
A21: ― | B21: 判定未了 | C21: 0 | D21: 0 | E21: 89 | F21: 2 | G21: 91 | H21: 優先度B・Cのうち計画策定側のもの。第2回策定委員会以降の照会を予定しており影響度は判定していない。ただしこのうち進捗0.90以上のWBSを止めているものは下段の見直し候補に掲げた。
B22: 合計 | C22: 32 | D22: 80 | E22: 93 | F22: 2 | G22: 207
A24: ■ 影響度1（停止）・2（仮置き）の明細 — 村への照会はこの順で起案する
A25: 影響度 | B25: No. | C25: 優先度 | D25: 確認事項 | E25: 止まる対象 | F25: 当方の手当（現時点の扱い） | G25: 回答が必要な時期 | H25: 束
A26: 1 | B26: K-010 | C26: S | D26: ★【期限 令和8年10月13日18時】令和9年度以降も0で入っている6サービスを0のままとしてよいか | E26: 素案 5-4・5-6／Ⅱ-56・Ⅱ-62・Ⅱ-107 | F26: 国の推計ワークシートを正として5-4・5-6を組み替える準備を進めている。6サービス（介護予防短期入所生活介護・訪問入浴介護・短期入所療養介護（老健）・特定福祉用具購入費・住宅改修費・地域密着型通所介護）が0のままでは、実績のあるサービスの見込量を0と掲げることになり、計画として成り立たない。村が修正する場合は当方の算定（素案5-4の現行値）を代替案として示せる。 | G26: 令和8年10月13日（火）18時（国の集計の提出期限。厳守） | H26: 束1
A27: 1 | B27: K-129 | C27: S | D27: ★ニーズ調査の対象者882人に対応する要介護認定データ（認定の有無・要介護度） | E27: 資料3の3-3・3-4・3-6／Ⅰ-37・Ⅰ-38 | F27: 回答データの集計そのものは進むが、認定状況を軸にしたクロス集計は作れない。資料3の3-3（元気な軽度者）・3-4（生活機能からみた4つの層）・3-6（担い手の可能性）がこれに当たる。3-6は第10期に共助・互助の仕組みをどの規模で構想できるかを示す表であり、基本理念・基本目標のご判断の材料になる（資料8-4）。後から認定状況を付けてクロスをやり直すことはできるが手戻りになる。 | G27: 10月中旬（第2回策定委員会の資料作成に入る前） | H27: 束8
A28: 1 | B28: K-133 | C28: S | D28: ★要介護認定データの提供時期と項目（要介護度・認定日・サービス利用状況）および総合事業対象者（基本チェックリスト該当者）の情報 | E28: 資料3の3-3・3-4・3-6／Ⅰ-37 | F28: 上記と一体のもの。集計軸の認定状況は「認定なし／事業対象者／要支援1・2／要介護1以上」の4区分であり、要介護認定データだけでは事業対象者を判別できない。総合事業の対象者（基本チェックリスト該当者）の情報もあわせて要る。 | G28: 10月中旬（同上） | H28: 束8
A29: 1 | B29: K-159 | C29: A | D29: 養護老人ホーム措置・軽費老人ホーム・老人クラブの実績は見える化に系列が一切ない | E29: 素案 4-30・5-4(8)／Ⅱ-53・Ⅱ-54 | F29: 養護老人ホーム措置・軽費老人ホーム・老人クラブは見える化に系列が一切なく、老人福祉事業の量の目標（Ⅱ-110）が立てられない。村提供のみが情報源。★10/12 影響度を2から1に上げた。老人福祉法第20条の8第2項が定めることを求めている量であり、実績がないまま目標の量を置くことはできない。仮定で代替できない。 | G29: 10月下旬 | H29: 束2
A30: 1 | B30: K-202 | C30: A | D30: ★法が定めることを求めている2つの量が空欄である（老人福祉事業の量19事業・地域支援事業の量10事業） | E30: 素案 4-6・5-5・5-12／Ⅱ-53・Ⅱ-110 | F30: 老人福祉法第20条の8第2項の老人福祉事業の量（20事業のうち19事業）と、介護保険法第117条第2項第2号の地域支援事業の量（19事業のうち10事業）が令和9〜11年度とも空欄である。いずれも法が計画に定めることを求めている事項であり、仮定を置いて進めることができない。令和5〜7年度の実績の受領を待つ。 | G30: 10月下旬 | H30: 束2
A31: 1 | B31: K-205 | C31: S | D31: ★令和8年法律第51号により介護保険法第117条に加わった記載事項の第10期計画への適用 | E31: 素案 5-11・5-5・施策4-3・施策4-6・1-6／Ⅱ-72・Ⅱ-110・Ⅱ-113 | F31: 10/15 起票。条文単位の対照（scripts/hotei_kisai.py・点検78）により、令和9年4月1日施行の記載事項7つが本計画に書かれていないことが分かった。うち中長期的な推計と中長期的な観点からの施策の2つは義務であり、書かなければ計画が法の求めを満たさない。要綱により書ける範囲は当方で加えるが、号の番号は新旧対照条文を待つ。加えると紙面が許容110頁を超えるため、削減案を1つ増やすか許容頁数のご判断をいただく必要がある。 | G31: 10月下旬（第2回策定委員会の資料作成前） | H31: 束2
A32: 2 | B32: K-011 | C32: S | D32: ★準備基金の取崩額を40,000,000円（残高の94.9%）とすることの可否（第11期が＋32.4%になる関係） | E32: 素案 5-7・5-11／資料6／Ⅱ-63・Ⅱ-64・Ⅱ-107 | F32: 国の推計ワークシートの前提（取崩40,000千円・保険料5,513.72円）を正として置き、取崩24,000千円・取崩なしを併記する案で資料6を組む。確定すれば併記を1案に絞る。 | G32: 11月上旬（第2回策定委員会資料の確定前） | H32: 束1
A33: 2 | B33: K-012 | C33: A | D33: ★条例上の保険料基準額の百円未満の処理（第9期は切捨てと見られる） | E33: 素案 5-7・図5-2／資料6 6-3b／Ⅱ-64・Ⅱ-107 | F33: 第9期の実例（算定上6,760.76円に対し条例6,700円）に合わせて切捨てで示した。四捨五入とした場合、基金の3案のうちB案（24,000千円取崩）は第10期6,000円・第11期6,800円となり、切捨て（5,900円・6,700円）と100円動く。条例の文言を確かめるまでは切捨てで置き、確認後に確定する。 | G33: 11月上旬（第2回策定委員会まで） | H33: 束1
A34: 2 | B34: K-013 | C34: A | D34: ★第1号被保険者数の前期・後期の内訳が国の様式（3区分）と素案5-2（2区分）で食い違う | E34: 素案 2-2・5-2・5-3／Ⅱ-59・Ⅱ-56 | F34: 10/7 に素案5-2を国の様式（3区分。前期444／425／405、後期560／575／589）に書き換え、2-2の「後期高齢者は令和12年の551人まで増加」を602人に直した。当方のB案の内訳は検算として注記に残した。併記の形でよいかのご確認を待つ。 | G34: 11月上旬（第2回策定委員会まで） | H34: 束1
A35: 2 | B35: K-014 | C35: A | D35: ★認定者数が国の推計（3か年計629人）と当方の算定（651人）で3.4%食い違う | E35: 素案 5-3・5-4／Ⅱ-56・Ⅱ-59 | F35: 10/7 に素案5-3を国の値（208／211／210）に書き換え、当方の算定（214／217／220）を検算として併記した。差の原因は認定率の置き方であることを本文に書いた。併記の形でよいかのご確認を待つ。 | G35: 11月上旬（第2回策定委員会まで） | H35: 束1
A36: 2 | B36: K-015 | C36: A | D36: ★後期高齢者加入割合補正係数（F）の算出方法（当方の復元が国の値と一致しない） | E36: 素案 5-7・5-11／Ⅱ-62・Ⅱ-64・Ⅱ-107 | F36: 国の値を用いて5-7・5-11を記載し、当方の復元が一致しないことを5-11の注記と5-12に明記した。Fは0.1の違いで月額約250円動くため、算出方法が確かめられないと中長期の保険料の形（第12期8,281円・第14期7,736円と上下する）を説明できない。 | G36: 11月上旬（第2回策定委員会まで） | H36: 束1
A37: 2 | B37: K-016 | C37: A | D37: ★調整交付金見込交付割合5.36／5.03／4.67%の出所（県の指示値か村の入力値か） | E37: 素案 5-7(3)・5-9／Ⅱ-62・Ⅱ-64 | F37: 国の値（5.36／5.03／4.67%）を正として5-7を書き換える。当方が復元した4.10〜4.32%との差（1.0ポイント超＝月額約260円）は、出所が分かれば説明できる。 | G37: 10月下旬 | H37: 束1
... A64: 0 | B64: K-199 | C64: A | D64: ★【社内】校了版（令和8年9月9日）の調査票Wordの提供（コードブックの作り直しに必要） | E64: 集計 Ⅰ-104・Ⅰ-35・Ⅰ-36 | F64: 論理チェック（doc25 §7・shukei_check.py）は組み終えており、ダミーデータで結果が出ることと自己試験が通ることを確かめている。ただしコードブックが令和8年9月4日版の調査票から作られているため、版が合うまで結果は暫定である（shukei_check.py は版を確かめて止まる。--暫定 で続行可）。校了版のWordを受領すればコードブックを作り直し、9月4日版の読み取りの不備7件（C01 1件・C02 5件・C03 1件）も同時に解消する。所要は半日。調査票は他メンバーの担当であり、当方では作成しない。お願いするのはWordの提供のみである。受領できないまま入力が進むと、鳴らなかった件が「誤りがない」のか「版違いで鳴らなかった」のか区別できなくなる。 | G64: 入力の開始前（回収期限 令和8年10月16日の前） | H64: 束8
A66: ■ 照会の束 — 1通にまとめて起案する単位（未解決の確認事項を関連WBSで束ねたもの）
A67: 束 | B67: 名称 | C67: 未解決 | D67: うちS | E67: うちA | F67: 止まるWBS | G67: 照会の方法
A68: 束1 | B68: 保険料と推計の確定 | C68: 27 | D68: 3 | E68: 13 | F68: Ⅱ-107、Ⅱ-59、Ⅱ-62、Ⅱ-63、Ⅱ-64 | G68: 国の推計ワークシートの受領（令和8年10月7日）により生じた確認事項を1通にまとめる。令和9年度以降も0で入っている6サービスの扱い（国の集計の提出期限が令和8年10月13日18時）、準備基金の取崩額の水準（第11期が＋32.4%になる関係）、被保険者数と認定者数の内訳の食い違い、調整交付金見込交付割合の出所、条例上の基準額の扱いである。
A69: 束2 | B69: 給付実績・決算と第9期の計画値 | C69: 70 | D69: 1 | E69: 22 | F69: Ⅱ-105、Ⅱ-106、Ⅱ-110、Ⅱ-115、Ⅱ-53、Ⅱ-54、Ⅱ-55、Ⅱ-56、Ⅱ-57、Ⅱ-58、Ⅱ-60、Ⅱ-61 | G69: 令和6・7年度の決算と給付実績、将来推計総括表、第9期計画の本文、見える化に系列のない事業（養護老人ホーム措置・軽費老人ホーム・老人クラブ）を1通にまとめる。
A70: 束3 | B70: 交付金の得点と給付適正化 | C70: 21 | D70: 0 | E70: 13 | F70: Ⅱ-109、Ⅱ-65、Ⅱ-67 | G70: 得点が低下した指標の理由と、未得点項目の取組可否を1通にまとめる。交付金の該当状況調査票の写しにより当方で確かめられるものは照会から除く。
A71: 束4 | B71: 認知症施策と権利擁護 | C71: 12 | D71: 0 | E71: 6 | F71: Ⅱ-68、Ⅱ-69 | G71: 認知症関連事業の実績、意見を聴く方法、権利擁護センターの相談減の要因を1通にまとめる。
...

Sheet 納品物の構成
A2: 納品物に収録する範囲（仕様書5③-b／WBS Ⅳ-114）
A4: ■ 考え方 — 仕様書は「成果品及び関連データ」とするのみで範囲を定めていない。個人情報は収録しない（doc16 §5-1・§5-2・§6）
A6: ■ 村へ申し送る事項
A7: ・調査票の個人データ（氏名・住所・被保険者番号を含む一切）は電子媒体に収録しません。doc16§5-2により、関連付けの完了後に氏名・被保険者番号を分離し、認定データの原本は村と協議のうえ消去または返還します。
A8: ・管理番号と被保険者番号の対応表は収録しません（doc16§5-1）。業務完了後に消去し、消去の記録を村へ提出します（WBS Ⅴ-98）。
A9: ・集計結果は、該当数10未満のクロス集計の区分を統合または非表示としたうえで収録します（doc16§6）。本村は総人口2,315人・高齢者1,015人と小規模であり、地区×性別×年齢のような多重クロスは特定の恐れがあります。
A10: ・自由記述は、氏名・地区名・事業所名など個人が特定され得る記述を伏字または要約としたうえで収録します（doc16§6）。原文は収録しません。
A11: ・他の県内自治体の数値を含むファイルは収録しません。比較のために参照したものであり、成果品には団体名も数値も掲げていません。
A12: ・業務完了後の個人情報の返還・消去は、別に定める手順により行います。対象の一覧（宛名ラベル・対応表・調査票の原本・ウェブ回答・認定データ・個票・策定委員の連絡先・複写・バックアップ・受領資料の10件）、返還と消去の別、確かめ方、完了報告書の様式を定めています。消去は納品物の検収が済んでから行います。返還と消去の別は村にご確認いただきます。
A13: ・地域包括ケア「見える化」システムの出力そのものは収録しません。村が同じシステムから出力できるためです。計画書に用いた値は図表データ管理台帳に収めており、そこから検算できます。
A15: ■ 成果品 4件
A16: 区分 | B16: ファイル | C16: 媒体での置き場所 | D16: 理由
A17: 成果品 | B17: output/06_北塩原村第10期_計画素案.docx | C17: 01_計画書 | D17: 仕様書5①。確定後に『計画書』として差し替える
A18: 成果品 | B18: output/07_北塩原村第10期_集計仕様書.xlsx | C18: 02_調査報告書 | D18: 仕様書4Ⅰ(5)。集計の定義。報告書の付属
A19: 成果品 | B19: output/08_北塩原村第10期_第2回策定委員会資料.docx | C19: 03_委員会資料 | D19: 策定の経過。仕様書4Ⅱ(8)の会議資料
A20: 成果品 | B20: output/12_北塩原村第10期_第3回策定委員会資料.docx | C20: 03_委員会資料 | D20: 策定の経過。仕様書4Ⅱ(8)の会議資料。現在は骨子であり、第3回の開催前に中身を入れる
A22: ■ 関連 34件
A23: 区分 | B23: ファイル | C23: 媒体での置き場所 | D23: 理由
A24: 関連 | B24: data/集計_コードブック.json | C24: 02_調査報告書 | D24: 集計の変数定義
A25: 関連 | B25: output/11_北塩原村第10期_図表データ管理台帳.xlsx | C25: 04_図表データ | D25: 計画書の図の数値。村が数値を直せば図が変わる。更新の手順を00シートに記す
A26: 関連 | B26: output/figures | C26: 04_図表データ | D26: 計画書に差し込んだ図のPNG。台帳から作り直せる
A27: 関連 | B27: output/05_北塩原村第10期_WBS進捗管理表.xlsx | C27: 05_策定の記録 | D27: 策定の工程と村への確認事項。【氏名・連絡先は記載していない】
A28: 関連 | B28: output/09_北塩原村第10期_資料提供確認依頼書.docx | C28: 05_策定の記録 | D28: 村への照会の記録
A29: 関連 | B29: output/13-1_北塩原村第10期_照会票_束1_保険料と推計の確定.docx | C29: 05_策定の記録 | D29: 村への照会（保険料と推計の確定）。村にご記入いただいて返していただく様式。24件
A30: 関連 | B30: output/13-2_北塩原村第10期_照会票_束2_給付実績・決算と第9期の計画値.docx | C30: 05_策定の記録 | D30: 村への照会（給付実績・決算と第9期の計画値）。村にご記入いただいて返していただく様式。57件
A31: 関連 | B31: output/13-3_北塩原村第10期_照会票_束3_交付金の得点と給付適正化.docx | C31: 05_策定の記録 | D31: 村への照会（交付金の得点と給付適正化）。村にご記入いただいて返していただく様式。20件
A32: 関連 | B32: output/13-4_北塩原村第10期_照会票_束4_認知症施策と権利擁護.docx | C32: 05_策定の記録 | D32: 村への照会（認知症施策と権利擁護）。村にご記入いただいて返していただく様式。10件
A33: 関連 | B33: output/13-5_北塩原村第10期_照会票_束5_計画構成と施策体系.docx | C33: 05_策定の記録 | D33: 村への照会（計画構成と施策体系）。村にご記入いただいて返していただく様式。18件
A34: 関連 | B34: output/13-6_北塩原村第10期_照会票_束6_日程・体制・成果品.docx | C34: 05_策定の記録 | D34: 村への照会（日程・体制・成果品）。村にご記入いただいて返していただく様式。14件
... A57: 関連 | B57: data/第10期_需要に対する供給.csv | C57: 06_算定の根拠 | D57: 5-4(12)
A59: ■ 収録しない 32件
A60: 区分 | B60: ファイル | C60: 媒体での置き場所 | D60: 理由
A61: 収録しない | B61: data/05_令和7年8月版_突合ワークシート.csv | C61: ― | D61: 調査票の突合の作業用。調査は他メンバーの担当
A62: 収録しない | B62: data/dummy_ニーズ.csv | C62: ― | D62: 集計プログラムの検証に用いた架空のデータ。成果品ではない
A63: 収録しない | B63: data/dummy_在宅.csv | C63: ― | D63: 同上
A64: 収録しない | B64: data/mieruka_batch.csv | C64: ― | D64: 見える化の出力から取り出した中間データ。村は同じシステムから出力できる
A65: 収録しない | B65: data/mieruka_inventory.csv | C65: ― | D65: 受領の記録。作業の途中のもの
A66: 収録しない | B66: data/mieruka_inventory_追加分.csv | C66: ― | D66: 同上
A67: 収録しない | B67: data/mieruka_inventory_追加分2.csv | C67: ― | D67: 同上
A68: 収録しない | B68: data/mieruka_inventory_追加分3.csv | C68: ― | D68: 同上
...
