Workbook

Sheet 00_ダッシュボード
A1: 北塩原村 第8期障がい福祉計画・第4期障がい児福祉計画 業務進捗管理表
A2: 基準日：令和8年10月9日
A4: ■ 目次（シートの構成）
A5: シート | B5: 内容 | C5: 件数 | D5: このシートで分かること
A6: 00_ダッシュボード | B6: 全体進捗・現況・警戒事項・直近のマイルストーン | C6: ― | D6: いま何が止まっていて、次に何が来るか
A7: 01_WBS | B7: 作業の一覧（段階・状態・進捗率・重み・必要な村資料） | C7: 73件 | D7: 作業ごとの状態と、その作業が待っている村資料
A8: 02_段階サマリ | B8: P1〜P10の段階別集計（01_WBS から数式で再計算） | C8: 10段階 | D8: どの段階が遅れているか、段階ごとの律速要因
A9: 03_成果品管理 | B9: 仕様書5の成果品①〜③と参考成果物の版・状態 | C9: 4件 | D9: 納品物それぞれの到達点と、確定に必要なもの
A10: 04_工程表 | B10: 月別の予定（仕様書の工程案と実際の見込み） | C10: 11件 | D10: いつ何をするか、工程案とのずれ
A11: 05_村資料・依頼の詳細 | B11: 村への依頼の全文（優先度・依頼の詳細・反映先・関係WBS・状態） | C11: 69件 | D11: 何を誰にいつまでに依頼し、届かないとどの作業が止まるか
A12: 06_会議体・意見聴取 | B12: 協議会・庁議・パブリックコメントの予定と資料の状態 | C12: 7件 | D12: 意見聴取の場ごとに、資料が間に合うか
A13: 07_課題・リスク | B13: 課題とリスク（区分・影響度・対応・状態） | C13: 36件 | D13: 放置すると工程や品質に出る問題と、その手当て
A14: 08_変更管理・打合せ記録 | B14: 仕様書と実際の運用の差（変更管理） | C14: 27件 | D14: 書面で詰め直す必要がある条項
A15: 09_翌日の着手順 | B15: 令和8年10月15日（木）の打合せまでの着手順と、その順番にした理由 | C15: 14件 | D15: 朝いちばんに何から手を付けるか
A17: ■ 全体進捗
A18: 全体進捗 | B18: ='02_段階サマリ'!H12 | C18: 作業数 | D18: ='02_段階サマリ'!B12
A19: 完了 | B19: ='02_段階サマリ'!C12 | C19: データ待ち | D19: ='02_段階サマリ'!F12
A21: 段階 | B21: 作業数 | C21: 加重進捗率 | D21: 律速要因
A22: ='02_段階サマリ'!A2 | B22: ='02_段階サマリ'!B2 | C22: ='02_段階サマリ'!H2 | D22: ='02_段階サマリ'!K2
A23: ='02_段階サマリ'!A3 | B23: ='02_段階サマリ'!B3 | C23: ='02_段階サマリ'!H3 | D23: ='02_段階サマリ'!K3
A24: ='02_段階サマリ'!A4 | B24: ='02_段階サマリ'!B4 | C24: ='02_段階サマリ'!H4 | D24: ='02_段階サマリ'!K4
A25: ='02_段階サマリ'!A5 | B25: ='02_段階サマリ'!B5 | C25: ='02_段階サマリ'!H5 | D25: ='02_段階サマリ'!K5
A26: ='02_段階サマリ'!A6 | B26: ='02_段階サマリ'!B6 | C26: ='02_段階サマリ'!H6 | D26: ='02_段階サマリ'!K6
A27: ='02_段階サマリ'!A7 | B27: ='02_段階サマリ'!B7 | C27: ='02_段階サマリ'!H7 | D27: ='02_段階サマリ'!K7
A28: ='02_段階サマリ'!A8 | B28: ='02_段階サマリ'!B8 | C28: ='02_段階サマリ'!H8 | D28: ='02_段階サマリ'!K8
A29: ='02_段階サマリ'!A9 | B29: ='02_段階サマリ'!B9 | C29: ='02_段階サマリ'!H9 | D29: ='02_段階サマリ'!K9
A30: ='02_段階サマリ'!A10 | B30: ='02_段階サマリ'!B10 | C30: ='02_段階サマリ'!H10 | D30: ='02_段階サマリ'!K10
A31: ='02_段階サマリ'!A11 | B31: ='02_段階サマリ'!B11 | C31: ='02_段階サマリ'!H11 | D31: ='02_段階サマリ'!K11
A33: ■ 現況
A34: 推計・分析の枠組みは概ね組み上がった。国の基本指針（令和8年3月31日告示）の成果目標8区分と別表第一〜第五を条項単位で照合し、本村が全域過疎であることから別表第五の算定方法は適用対象外と判定して、個別積上げ方式を原則どおり採用できることを確定させた。
A35: 推計ブックは将来推計・サービス見込量・地域生活支援事業・活動指標・財源構成の5冊が算式まで実装済みで、実績データが入れば給付費と財源構成まで通る状態にしてある。計画書は計画素案として全8章に到達し、目次とページ番号を付与した（到達点は 03_成果品管理）。
A36: 一方、村からの資料は69件のうち受領済7件・一部受領6件・県照会中1件・未受領55件で、現行計画の評価・見込量・成果目標のいずれも確定できない。どの依頼がどの作業を止めているかは 05_村資料・依頼の詳細 の「関係WBS」列（及び 01_WBS の「必要な村資料」列）で追える。
A37: 令和8年10月の外部レビューを受けて、見込量の推計を4層（支給決定と実利用の分離・移行者・本人の必要量・確保可能量）に組み替え、介護保険事業計画との切り分けを支給決定の内容で整理した。いずれも村の個票（Ｍ-19・Ｍ-18）がないと数値まで到達しない。
A38: 最大の律速はアンケートの発送である。工程案の令和8年8月上旬発送に対し、印刷仕様・宛名ラベル・対象者数の3点がいずれも未了で、既に期限を超過している。回収に約1か月を要するため、遅延はそのまま集計・報告書・計画書の工程を圧迫する。
A39: 令和8年8月に村から調査票の朱書き修正指示40か所を受領した。設問の修正は他メンバーの担当だが、削除理由として書き添えられた数値9件は計画本体に直結するため、成果目標と見込量に反映した。障害支援区分別人数15人・医療的ケア児1人（経管栄養が毎日必要）・セルフプラン率0％・基幹相談支援センター未設置がその内容である。
A40: 同月、国が「障害福祉計画策定に係る実態調査及びPDCAサイクルに関するマニュアル」を改定し、福島県から市町村へ通知された（8生福第2646号・8こ第2041号）。全81頁を読み、成果物と突合した。別表第五を適用しないという当方の判定は国の文書で裏付けられた。
A41: 調査票は8月25日版で確定した。マニュアルの発出（8月19日事務連絡）と確定の時期が重なったため、標準項目のうち外出の目的・介護保険の利用状況・強度行動障害の該当有無・障害支援区分の4件が確定版にない。クロス集計25件と行政データとの突合6件を設計し、うち3件は代替の目処が立った。残る1件（外出の目的）は第4次障がい者計画の指標に関わるため村との再協議を要する。
A43: ■ 警戒事項
A44: # | B44: 内容 | C44: 影響 | D44: 対応
A45: 1 | B45: アンケートの発送が工程案の令和8年8月上旬に間に合わない | C45: 回収期間または集計期間が圧縮され、報告書・計画書の工程に波及する | D45: 印刷仕様を確定し、宛名ラベルの提供日を村と合意する。遅延が確定した場合は回収期間を維持して集計以降を短縮する
...

Sheet 01_WBS
A1: 段階 | B1: No | C1: 作業 | D1: 内容 | E1: 仕様書根拠 | F1: 担当 | G1: 予定開始 | H1: 予定完了 | I1: 状態 | J1: 進捗率 | K1: 重み | L1: 実績・根拠 | M1: 前提条件・ブロッカー | N1: 必要な村資料（確定に必要／精度を上げる）
A2: P1 準備・現状把握 | B2: 1-1 | C2: 契約・受注範囲の確定 | D2: 仕様書の条項を分解し、契約上の受注範囲と打合せで合意した運用の差を突合 | E2: 仕様書全般 | F2: 受託者 | G2: 2026-06 | H2: 2026-08 | I2: 完了 | J2: 100 | K2: 3 | L2: 受注内容整理（docs/北塩原村_第8期障がい福祉計画_受注内容整理.md）。仕様書の要求を条項単位で33項目に分解 | M2: ― | N2: ―
A3: P1 準備・現状把握 | B3: 1-2 | C3: 現行計画本編の確認 | D3: 第4次障がい者計画・第7期障がい福祉計画・第3期障がい児福祉計画（63頁）の構成・成果目標7区分・見込量・施策目標値の把握 | E3: 仕様書4-Ⅱ(2) | F3: 受託者 | G3: 2026-08 | H3: 2026-08 | I3: 完了 | J3: 100 | K3: 3 | L3: 受領による確認と訂正（docs/北塩原村_現行計画本編_受領による確認と訂正.md）。推定していた9件を実測値に置換し、誤りを4件訂正 | M3: ― | N3: 現行計画本編（第4次障がい者計画・第7期・第3期）
A4: P1 準備・現状把握 | B4: 1-3 | C4: 改定対象の切り分け | D4: 第4次障がい者計画（令和6〜11年度）は継続中で改定対象外。基本理念・基本目標を継承する整合記述にとどめる範囲を確定 | E4: 仕様書1・2 | F4: 受託者 | G4: 2026-08 | H4: 2026-08 | I4: 完了 | J4: 100 | K4: 2 | L4: 骨子案修正版 第3章を「参考」から本計画の内容へ再構成。仕様書4-Ⅱ(5)①②の記載事項を措置 | M4: ― | N4: ―
A5: P1 準備・現状把握 | B5: 1-4 | C5: 村への資料依頼の一本化 | D5: 各推計ブックに分散していた村確認事項を横断で一本化し、優先度・希望期限を付す | E5: ― | F5: 受託者 | G5: 2026-08 | H5: 2026-08 | I5: 完了 | J5: 100 | K5: 2 | L5: 05_村資料・依頼の詳細（69件）に一本化し、WBS番号と結び付けた。最優先16件・高32件 | M5: ― | N5: ―
A6: P1 準備・現状把握 | B6: 1-5 | C6: 村資料の受領 | D6: 依頼69件の受領。実績データ・匿名利用者一覧・年齢階級別人口ほか | E6: ― | F6: 北塩原村 | G6: 2026-08 | H6: 2026-10 | I6: データ待ち | J6: 25 | K6: 5 | L6: 受領済7件・一部受領6件・県照会中1件・未受領55件。令和8年8月の調査票朱書きで実データ9件が判明。令和8年10月に外部レビューを踏まえて6件を追加（Ｍ-19・Ｍ-18・Ｍ-13・Ｍ-14・Ｍ-20・Ｍ-21） | M6: 村の回答。P3・P6・P7のほぼ全てがこれに依存する | N6: ―
A7: P1 準備・現状把握 | B7: 1-6 | C7: 打合せ等業務 | D7: 電話・面談（オンライン・対面）による協議。議事録の作成 | E7: 仕様書4-Ⅲ | F7: 受託者 | G7: 2026-06 | H7: 2027-03 | I7: 進行中 | J7: 40 | K7: 2 | L7: 令和8年7月7日打合せの議事録。以降の協議事項を進捗管理に反映。令和8年10月9日の打合せ（網羅性点検への加筆）を北塩原村_打合せ記録_20261009.xlsx に記録（論点10件。提案4・合意3・指摘1・了承1・考察1）。加筆の原文と当方の読み取りを並べ、読み取りに迷った5件は勝手に直さず確認事項に残した。同日受領の論点メモを北塩原村_論点整理_20261009.xlsx に整理（論点30件・用語の是正15件）。あわせて並行する3つの版を突き合わせ、論点メモが読んだ版は正本（他メンバー版）ではなく当方の素案の注記削除版であることを特定した | M7: 次回打合せの設定。発送前の確認事項を議題とする | N7: ―
A8: P1 準備・現状把握 | B8: 1-7 | C8: 成果物の再現性確保 | D8: 成果物を作り直せる状態（生成器・原本・必要なライブラリ）がすべてリポジトリに残っていることを機械で点検する仕組みの整備 | E8: 仕様書4-Ⅳ（成果品の納入） | F8: 受託者 | G8: 2026-10 | H8: 2027-03 | I8: 進行中 | J8: 90 | K8: 2 | L8: check_reproducibility.py を整備し7項目を点検。生成器23本・成果物35点の対応表を依存順に明記。全22本の再実行で34/34点が内容一致。別の場所に複製した状態でも全項目合格を確認（docs/北塩原村_成果物の再現性点検と再発防止.md） | M8: ―（納品まで節目ごとに再実行する） | N8: ―
A9: P1 準備・現状把握 | B9: 1-8 | C9: 福島県の障がい計画との整合の確認 | D9: 県の障がい者計画・障がい福祉計画・障がい児福祉計画を確認し、計画期間・区域の設定・成果目標・圏域計画との整合を計画素案に反映する | E9: 基本指針 第三の一の5・7 | F9: 受託者 | G9: 2026-10 | H9: 2027-01 | I9: 進行中 | J9: 90 | K9: 2 | L9: 北塩原村_福島県計画との整合.xlsx（7シート）。第7期県計画（令和6年3月・206頁）が source/精神保健 にあり、令和8年10月8日に県の概要2点と本文テキストを受領（source/県計画）。県が定める区域は会津障がい保健福祉圏域（2市8町3村）で、本計画がいう会津北部圏域（4町村）とは範囲が異なることを特定。一方で県計画の会津圏域計画が地域生活支援拠点として「会津北部」を挙げており、本計画の前提は県計画と整合することも確認。基幹相談支援センターは県全体59市町村（令和4年度実績44市町村）・会津圏域13市町村が目標だが圏域の設置は2か所にとどまる。計画素案 第1章2に3節、第4章（4）（6）・第5章8に圏域の現況を反映 | M9: 県障がい者計画（第5次）の計画期間（Q-7）と第8期県計画の策定時期・基盤整備量の算定値（Q-5）の確認 | N9: ―（精度：福島県の長期入院患者に係る基盤整備量（利用者数））
A10: P1 準備・現状把握 | B10: 1-9 | C10: 他メンバーの計画素案の網羅性点検 | D10: 他メンバーが作成した計画素案と策定ワークシートを、別表第二の記載事項・成果目標8区分・県計画・介護保険事業計画・村の公表実績と突き合わせる | E10: ― | F10: 受託者 | G10: 2026-10 | H10: 2026-11 | I10: 進行中 | J10: 80 | K10: 2 | L10: 北塩原村_他メンバー素案_網羅性点検.xlsx（9シート）。漏れている論点18件（最優先4・高5・中7・低2）。最も重いのは、素案の実績値・現状値が他メンバー自身が仮置きと記した着色セル（16シート549個）に由来するのに、本文では実数として出所表示つきで書かれていること。村の公表実績とは11サービスで食い違い、うち3件は実績の有無が逆転。定めなければならない事項の未記載は別表第二 三㈠⑤（基盤整備量）の1件 | M10: 確認Ｓ-1（仮置きの前提の共有）とＳ-2〜Ｓ-4（村の実数）。どちらの素案を正本にするかの村・社内の判断 | N10: ―
A11: P2 基礎調査 | B11: 2-1 | C11: 国の基本指針の確認と原典照合 | D11: 令和8年3月31日告示（こども家庭庁・厚生労働省告示第4号）の本文・新旧対照表により、成果目標8区分の国基準数値と別表第一〜第五を条項単位で照合 | E11: 仕様書4-Ⅱ(1) | F11: 受託者 | G11: 2026-08 | H11: 2026-08 | I11: 完了 | J11: 100 | K11: 5 | L11: 国基準数値 原典照合結果（docs/北塩原村_国基準数値_原典照合結果.md）。骨子案の≪国の基本指針≫欄8か所を告示本文で全面差替 | M11: ― | N11: ―
A12: P2 基礎調査 | B12: 2-2 | C12: 法制度の改正動向の整理 | D12: 障害者総合支援法・児童福祉法の改正動向、就労選択支援の創設、令和8年度報酬改定（処遇改善加算拡充・B型基本報酬区分見直し） | E12: 仕様書4-Ⅱ(1) | F12: 受託者 | G12: 2026-08 | H12: 2026-08 | I12: 完了 | J12: 100 | K12: 3 | L12: 骨子案修正版 第1章4（基本指針の見直し16項目）。報酬改定資料3点を source/報酬改定 に保存 | M12: ― | N12: ―
A13: P2 基礎調査 | B13: 2-3 | C13: 福島県計画等の関連資料の収集 | D13: 福島県障がい福祉計画（第7期）本編、県の精神医療指標、県内の過疎・中山間地域の指定状況 | E13: 仕様書4-Ⅱ(1) | F13: 受託者 | G13: 2026-08 | H13: 2026-08 | I13: 完了 | J13: 100 | K13: 3 | L13: 福島県_精神医療指標抽出.xlsx（7シート）。本村は過疎法第2条により全域が過疎地域と確定し、別表第五の適用対象外を判定 | M13: ― | N13: ―
... A74: P10 完成・納品 | B74: 10-6 | C74: 納品・検収 | D74: 令和9年3月31日まで | E74: 仕様書3（業務期間） | F74: 受託者・北塩原村 | G74: 2027-03 | H74: 2027-03 | I74: 未着手 | J74: 0 | K74: 1 | L74: ― | M74: 全成果品の完成 | N74: ―

Sheet 02_段階サマリ
A1: 段階 | B1: 作業数 | C1: 完了 | D1: 進行中 | E1: 要対応 | F1: データ待ち | G1: 未着手 | H1: 加重進捗率 | I1: 予定開始 | J1: 予定完了 | K1: 律速要因
A2: P1 準備・現状把握 | B2: =COUNTIF('01_WBS'!$A$2:$A$74,$A2) | C2: =COUNTIFS('01_WBS'!$A$2:$A$74,$A2,'01_WBS'!$I$2:$I$74,"完了") | D2: =COUNTIFS('01_WBS'!$A$2:$A$74,$A2,'01_WBS'!$I$2:$I$74,"進行中") | E2: =COUNTIFS('01_WBS'!$A$2:$A$74,$A2,'01_WBS'!$I$2:$I$74,"要対応") | F2: =COUNTIFS('01_WBS'!$A$2:$A$74,$A2,'01_WBS'!$I$2:$I$74,"データ待ち") | G2: =COUNTIFS('01_WBS'!$A$2:$A$74,$A2,'01_WBS'!$I$2:$I$74,"未着手") | H2: =IF(SUMPRODUCT(('01_WBS'!$A$2:$A$74=$A2)*'01_WBS'!$K$2:$K$74)=0,0,SUMPRODUCT(('01_WBS'!$A$2:$A$74=$A2)*'01_WBS'!$J$2:$J$74*'01_WBS'!$K$2:$K$74)/SUMPRODUCT(('01_WBS'!$A$2:$A$74=$A2)*'01_WBS'!$K$2:$K$74)/100) | I2: 2026-06 | J2: 2026-09 | K2: 村資料の受領（依頼69件・受領済7件・一部受領6件・県照会中1件・未受領55件）
A3: P2 基礎調査 | B3: =COUNTIF('01_WBS'!$A$2:$A$74,$A3) | C3: =COUNTIFS('01_WBS'!$A$2:$A$74,$A3,'01_WBS'!$I$2:$I$74,"完了") | D3: =COUNTIFS('01_WBS'!$A$2:$A$74,$A3,'01_WBS'!$I$2:$I$74,"進行中") | E3: =COUNTIFS('01_WBS'!$A$2:$A$74,$A3,'01_WBS'!$I$2:$I$74,"要対応") | F3: =COUNTIFS('01_WBS'!$A$2:$A$74,$A3,'01_WBS'!$I$2:$I$74,"データ待ち") | G3: =COUNTIFS('01_WBS'!$A$2:$A$74,$A3,'01_WBS'!$I$2:$I$74,"未着手") | H3: =IF(SUMPRODUCT(('01_WBS'!$A$2:$A$74=$A3)*'01_WBS'!$K$2:$K$74)=0,0,SUMPRODUCT(('01_WBS'!$A$2:$A$74=$A3)*'01_WBS'!$J$2:$J$74*'01_WBS'!$K$2:$K$74)/SUMPRODUCT(('01_WBS'!$A$2:$A$74=$A3)*'01_WBS'!$K$2:$K$74)/100) | I3: 2026-07 | J3: 2026-09 | K3: ―（基本指針は令和8年3月31日告示、実態調査PDCAマニュアルは同年8月改定。いずれも確認済み）
A4: P3 統計分析 | B4: =COUNTIF('01_WBS'!$A$2:$A$74,$A4) | C4: =COUNTIFS('01_WBS'!$A$2:$A$74,$A4,'01_WBS'!$I$2:$I$74,"完了") | D4: =COUNTIFS('01_WBS'!$A$2:$A$74,$A4,'01_WBS'!$I$2:$I$74,"進行中") | E4: =COUNTIFS('01_WBS'!$A$2:$A$74,$A4,'01_WBS'!$I$2:$I$74,"要対応") | F4: =COUNTIFS('01_WBS'!$A$2:$A$74,$A4,'01_WBS'!$I$2:$I$74,"データ待ち") | G4: =COUNTIFS('01_WBS'!$A$2:$A$74,$A4,'01_WBS'!$I$2:$I$74,"未着手") | H4: =IF(SUMPRODUCT(('01_WBS'!$A$2:$A$74=$A4)*'01_WBS'!$K$2:$K$74)=0,0,SUMPRODUCT(('01_WBS'!$A$2:$A$74=$A4)*'01_WBS'!$J$2:$J$74*'01_WBS'!$K$2:$K$74)/SUMPRODUCT(('01_WBS'!$A$2:$A$74=$A4)*'01_WBS'!$K$2:$K$74)/100) | I4: 2026-07 | J4: 2026-10 | K4: 年齢階級別の手帳所持者数・人口（未受領）
A5: P4 ニーズ調査 | B5: =COUNTIF('01_WBS'!$A$2:$A$74,$A5) | C5: =COUNTIFS('01_WBS'!$A$2:$A$74,$A5,'01_WBS'!$I$2:$I$74,"完了") | D5: =COUNTIFS('01_WBS'!$A$2:$A$74,$A5,'01_WBS'!$I$2:$I$74,"進行中") | E5: =COUNTIFS('01_WBS'!$A$2:$A$74,$A5,'01_WBS'!$I$2:$I$74,"要対応") | F5: =COUNTIFS('01_WBS'!$A$2:$A$74,$A5,'01_WBS'!$I$2:$I$74,"データ待ち") | G5: =COUNTIFS('01_WBS'!$A$2:$A$74,$A5,'01_WBS'!$I$2:$I$74,"未着手") | H5: =IF(SUMPRODUCT(('01_WBS'!$A$2:$A$74=$A5)*'01_WBS'!$K$2:$K$74)=0,0,SUMPRODUCT(('01_WBS'!$A$2:$A$74=$A5)*'01_WBS'!$J$2:$J$74*'01_WBS'!$K$2:$K$74)/SUMPRODUCT(('01_WBS'!$A$2:$A$74=$A5)*'01_WBS'!$K$2:$K$74)/100) | I5: 2026-07 | J5: 2026-09 | K5: 印刷仕様・宛名ラベル・対象者数の3点。本業務の最大の律速
A6: P5 集計・分析 | B6: =COUNTIF('01_WBS'!$A$2:$A$74,$A6) | C6: =COUNTIFS('01_WBS'!$A$2:$A$74,$A6,'01_WBS'!$I$2:$I$74,"完了") | D6: =COUNTIFS('01_WBS'!$A$2:$A$74,$A6,'01_WBS'!$I$2:$I$74,"進行中") | E6: =COUNTIFS('01_WBS'!$A$2:$A$74,$A6,'01_WBS'!$I$2:$I$74,"要対応") | F6: =COUNTIFS('01_WBS'!$A$2:$A$74,$A6,'01_WBS'!$I$2:$I$74,"データ待ち") | G6: =COUNTIFS('01_WBS'!$A$2:$A$74,$A6,'01_WBS'!$I$2:$I$74,"未着手") | H6: =IF(SUMPRODUCT(('01_WBS'!$A$2:$A$74=$A6)*'01_WBS'!$K$2:$K$74)=0,0,SUMPRODUCT(('01_WBS'!$A$2:$A$74=$A6)*'01_WBS'!$J$2:$J$74*'01_WBS'!$K$2:$K$74)/SUMPRODUCT(('01_WBS'!$A$2:$A$74=$A6)*'01_WBS'!$K$2:$K$74)/100) | I6: 2026-09 | J6: 2026-12 | K6: アンケートの回収
A7: P6 現行計画の評価 | B7: =COUNTIF('01_WBS'!$A$2:$A$74,$A7) | C7: =COUNTIFS('01_WBS'!$A$2:$A$74,$A7,'01_WBS'!$I$2:$I$74,"完了") | D7: =COUNTIFS('01_WBS'!$A$2:$A$74,$A7,'01_WBS'!$I$2:$I$74,"進行中") | E7: =COUNTIFS('01_WBS'!$A$2:$A$74,$A7,'01_WBS'!$I$2:$I$74,"要対応") | F7: =COUNTIFS('01_WBS'!$A$2:$A$74,$A7,'01_WBS'!$I$2:$I$74,"データ待ち") | G7: =COUNTIFS('01_WBS'!$A$2:$A$74,$A7,'01_WBS'!$I$2:$I$74,"未着手") | H7: =IF(SUMPRODUCT(('01_WBS'!$A$2:$A$74=$A7)*'01_WBS'!$K$2:$K$74)=0,0,SUMPRODUCT(('01_WBS'!$A$2:$A$74=$A7)*'01_WBS'!$J$2:$J$74*'01_WBS'!$K$2:$K$74)/SUMPRODUCT(('01_WBS'!$A$2:$A$74=$A7)*'01_WBS'!$K$2:$K$74)/100) | I7: 2026-08 | J7: 2026-11 | K7: 令和6・7年度の実績と令和8年度見込
A8: P7 推計・見込量 | B8: =COUNTIF('01_WBS'!$A$2:$A$74,$A8) | C8: =COUNTIFS('01_WBS'!$A$2:$A$74,$A8,'01_WBS'!$I$2:$I$74,"完了") | D8: =COUNTIFS('01_WBS'!$A$2:$A$74,$A8,'01_WBS'!$I$2:$I$74,"進行中") | E8: =COUNTIFS('01_WBS'!$A$2:$A$74,$A8,'01_WBS'!$I$2:$I$74,"要対応") | F8: =COUNTIFS('01_WBS'!$A$2:$A$74,$A8,'01_WBS'!$I$2:$I$74,"データ待ち") | G8: =COUNTIFS('01_WBS'!$A$2:$A$74,$A8,'01_WBS'!$I$2:$I$74,"未着手") | H8: =IF(SUMPRODUCT(('01_WBS'!$A$2:$A$74=$A8)*'01_WBS'!$K$2:$K$74)=0,0,SUMPRODUCT(('01_WBS'!$A$2:$A$74=$A8)*'01_WBS'!$J$2:$J$74*'01_WBS'!$K$2:$K$74)/SUMPRODUCT(('01_WBS'!$A$2:$A$74=$A8)*'01_WBS'!$K$2:$K$74)/100) | I8: 2026-08 | J8: 2026-12 | K8: 村の実績データ。算式は実装済みで、値が入れば給付費・財源まで通る
A9: P8 施策検討・計画案 | B9: =COUNTIF('01_WBS'!$A$2:$A$74,$A9) | C9: =COUNTIFS('01_WBS'!$A$2:$A$74,$A9,'01_WBS'!$I$2:$I$74,"完了") | D9: =COUNTIFS('01_WBS'!$A$2:$A$74,$A9,'01_WBS'!$I$2:$I$74,"進行中") | E9: =COUNTIFS('01_WBS'!$A$2:$A$74,$A9,'01_WBS'!$I$2:$I$74,"要対応") | F9: =COUNTIFS('01_WBS'!$A$2:$A$74,$A9,'01_WBS'!$I$2:$I$74,"データ待ち") | G9: =COUNTIFS('01_WBS'!$A$2:$A$74,$A9,'01_WBS'!$I$2:$I$74,"未着手") | H9: =IF(SUMPRODUCT(('01_WBS'!$A$2:$A$74=$A9)*'01_WBS'!$K$2:$K$74)=0,0,SUMPRODUCT(('01_WBS'!$A$2:$A$74=$A9)*'01_WBS'!$J$2:$J$74*'01_WBS'!$K$2:$K$74)/SUMPRODUCT(('01_WBS'!$A$2:$A$74=$A9)*'01_WBS'!$K$2:$K$74)/100) | I9: 2026-07 | J9: 2027-01 | K9: P5・P7の完了
A10: P9 意見聴取 | B10: =COUNTIF('01_WBS'!$A$2:$A$74,$A10) | C10: =COUNTIFS('01_WBS'!$A$2:$A$74,$A10,'01_WBS'!$I$2:$I$74,"完了") | D10: =COUNTIFS('01_WBS'!$A$2:$A$74,$A10,'01_WBS'!$I$2:$I$74,"進行中") | E10: =COUNTIFS('01_WBS'!$A$2:$A$74,$A10,'01_WBS'!$I$2:$I$74,"要対応") | F10: =COUNTIFS('01_WBS'!$A$2:$A$74,$A10,'01_WBS'!$I$2:$I$74,"データ待ち") | G10: =COUNTIFS('01_WBS'!$A$2:$A$74,$A10,'01_WBS'!$I$2:$I$74,"未着手") | H10: =IF(SUMPRODUCT(('01_WBS'!$A$2:$A$74=$A10)*'01_WBS'!$K$2:$K$74)=0,0,SUMPRODUCT(('01_WBS'!$A$2:$A$74=$A10)*'01_WBS'!$J$2:$J$74*'01_WBS'!$K$2:$K$74)/SUMPRODUCT(('01_WBS'!$A$2:$A$74=$A10)*'01_WBS'!$K$2:$K$74)/100) | I10: 2026-10 | J10: 2027-02 | K10: 村の方針では第2回協議会10月・パブコメ11月・第3回協議会12月・庁議令和9年1月・議会2月
A11: P10 完成・納品 | B11: =COUNTIF('01_WBS'!$A$2:$A$74,$A11) | C11: =COUNTIFS('01_WBS'!$A$2:$A$74,$A11,'01_WBS'!$I$2:$I$74,"完了") | D11: =COUNTIFS('01_WBS'!$A$2:$A$74,$A11,'01_WBS'!$I$2:$I$74,"進行中") | E11: =COUNTIFS('01_WBS'!$A$2:$A$74,$A11,'01_WBS'!$I$2:$I$74,"要対応") | F11: =COUNTIFS('01_WBS'!$A$2:$A$74,$A11,'01_WBS'!$I$2:$I$74,"データ待ち") | G11: =COUNTIFS('01_WBS'!$A$2:$A$74,$A11,'01_WBS'!$I$2:$I$74,"未着手") | H11: =IF(SUMPRODUCT(('01_WBS'!$A$2:$A$74=$A11)*'01_WBS'!$K$2:$K$74)=0,0,SUMPRODUCT(('01_WBS'!$A$2:$A$74=$A11)*'01_WBS'!$J$2:$J$74*'01_WBS'!$K$2:$K$74)/SUMPRODUCT(('01_WBS'!$A$2:$A$74=$A11)*'01_WBS'!$K$2:$K$74)/100) | I11: 2027-01 | J11: 2027-03 | K11: 令和9年3月31日が業務期間の末日
A12: 合計 | B12: =SUM(B2:B11) | C12: =SUM(C2:C11) | D12: =SUM(D2:D11) | E12: =SUM(E2:E11) | F12: =SUM(F2:F11) | G12: =SUM(G2:G11) | H12: =IF(SUMPRODUCT('01_WBS'!$K$2:$K$74)=0,0,SUMPRODUCT('01_WBS'!$J$2:$J$74*'01_WBS'!$K$2:$K$74)/SUMPRODUCT('01_WBS'!$K$2:$K$74)/100) | I12: 2026-06 | J12: 2027-03
A14: ※ 加重進捗率＝Σ（進捗率×重み）÷Σ重み。重みは工数の目安（1〜5）。
A15: ※ 01_WBS の「状態」「進捗率」を書き換えると、本表とダッシュボードが再計算されます。

Sheet 03_成果品管理
A1: 成果品 | B1: 名称 | C1: 納品仕様 | D1: 版 | E1: 状態 | F1: 進捗率 | G1: 現状 | H1: 確定に必要なもの
A2: ① | B2: 第8期北塩原村障がい福祉計画・第4期北塩原村障がい児福祉計画 | C2: A4判・両面 約60頁・モノクロ・コピー・くるみ製本 30部 | D2: 素案 | E2: 進行中 | F2: 78 | G2: 令和8年10月9日に正本を他メンバー版（全8章・約45頁）に変更した。当方の素案（全8章・59節・152表）は、移植の元と点検の基準として残す。北塩原村_申し送り_他メンバー版への移植_20261009.docx（第2版）に基づき、令和8年10月10日に正本へ移植した（北塩原村_計画素案_正本_移植後.docx。段落526→1012・表55→135・図19→28）。移植20件・論点メモからの修正5件・用語解説3語・村資料点検5件（V-1〜V-5）・12重点施策の再レビュー12件（W-1〜W-13）・村ホームページの棚卸し5件（X-1〜X-6）・村ホームページ3分野の棚卸し8件（Y-1〜Y-8。第7章4としてこども・子育て計画との連携の節を新設）・救急・防災・冬季のRed Teamレビュー5件（RT-1〜RT-5。第5章2（15）として医療へのアクセスの項を新設）・当方で作成した図8点（Z-1〜Z-8）を入れた。あわせて当方が書いた記述2件の書きぶりを弱めた（冬季の振替え、地域生活支援拠点による代替受入れの調整）。さらに図25点・表88点に章ごとの番号と表題を付け、目次の後に図表目次を置いた（注記ボックス46点には振らない）。網羅性点検で挙げた漏れのうち、村・県の回答を待たずに書けるものはすべて入れた。残るのは2件（Ｉ推計方法はＭ-19の回答が前提、Ｌ圏域の基盤整備は県の圏域計画の必要事業所数が前提）と、村の回答を待つ論点メモ19件 | H2: アンケート結果、令和6〜8年度の実績、見込量・成果目標の確定、協議会・パブコメ
A3: ② | B3: アンケート調査結果報告書 | C3: A4判・両面 約60頁・モノクロ・コピー・ホチキス製本 10部 | D3: ― | E3: 未着手 | F3: 10 | G3: 集計分析方法（少数母数対応）とクロス集計の設計は作成済み。報告書本体は未着手 | H3: アンケートの発送・回収・集計
A4: ③ | B4: 電子媒体 | C4: ①②の電子データ一式 | D4: ― | E4: 未着手 | F4: 0 | G4: ― | H4: ①②の確定。編集可能形式とPDFの別を村に確認する
A5: 参考 | B5: 計画の概要版 | C5: A4判・6頁（部数・仕様は未確定） | D5: 素案 概要版 | E5: 進行中 | F5: 85 | G5: 令和8年9月17日に村の指示により作成し、令和8年10月10日に正本へ合わせて6頁に改めた。方策・年齢到達（図）・他計画との連携の3節とパブリックコメントの案内を追加 | H5: ①と同じ現状値・目標値の確定。頁数が増えたため部数・仕様を村と再確認する
A7: ※ 進捗率は目安。納品仕様（部数・製本）を満たして初めて完了となる。

Sheet 04_工程表
A1: 時期 | B1: 作業 | C1: 担当 | D1: 状態 | E1: 備考
A2: 2026-08 | B2: 印刷仕様の確定、宛名ラベルの受領、対象者数の確定 | C2: 受託者・北塩原村 | D2: 要対応 | E2: アンケート発送のクリティカルパス。いずれも未了。調査票は8月25日版で確定済み
A3: 2026-08〜09 | B3: アンケートの印刷・封入・発送 | C3: 受託者 | D3: 要対応 | E3: 工程案は8月上旬発送。既に超過している
A4: 2026-09 | B4: アンケートの回収（約1か月）、村実績データの受領 | C4: 北塩原村・受託者 | D4: 未着手 | E4: 返送先は村役場。窓口での現地回収
A5: 2026-10 | B5: 第2回自立支援協議会（村の策定方針による） | C5: 北塩原村・受託者 | D5: 要対応 | E5: 村の計画策定方針（令和8年5月25日 資料4）の工程。議題は現行計画の現状・評価分析、アンケート調査の結果報告、計画素案の検討（概要版を含む）。評価・素案・概要版は作成済みでアンケート結果だけが欠ける。開催日と議題の組み替えを村に確認する（Ｍ-40）
A6: 2026-10 | B6: データ入力・集計、現行計画の評価の確定 | C6: 受託者 | D6: 未着手 | E6: 厚生労働省の集計様式による入力。少数母数の公表基準を事前に合意する
A7: 2026-11 | B7: パブリックコメントの実施（村の策定方針による） | C7: 北塩原村 | D7: 要対応 | E7: 村の方針は11月実施。正本 第1章5(4)は令和9年2月8日〜22日と書いており直す必要がある（修正案V-24）。前回（令和6年2月）は意見0件であったため周知の方法も見直す
A8: 2026-11 | B8: 見込量・成果目標・活動指標・給付費の確定 | C8: 受託者 | D8: 未着手 | E8: 算式は実装済み。実績データが入れば財源構成まで通る
A9: 2026-12 | B9: 第3回自立支援協議会（4町村広域）、計画案の修正 | C9: 受託者・北塩原村 | D9: 未着手 | E9: 村の方針では猪苗代町・磐梯町・湯川村・本村の4町村広域で開催し、パブリックコメントの結果報告と計画案の修正を行う。仕様書4-Ⅱ(7)の「協議会の開催は1回程度」との関係を村と整理する
A10: 2027-01 | B10: 概要版による庁議への説明、計画案の最終調整、調査結果報告書の作成 | C10: 北塩原村・受託者 | D10: 未着手 | E10: 村の方針の工程。概要版は作成済み
A11: 2027-02 | B11: 議会全員協議会への説明（令和9年度主要事業）、計画決定、計画書の原稿確定・組版 | C11: 北塩原村・受託者 | D11: 未着手 | E11: 村の方針では2月に計画決定。正本 第1章5に村議会への説明がないため加える（修正案V-4）
A12: 2027-03 | B12: 校正・印刷・製本、公表、納品 | C12: 受託者 | D12: 未着手 | E12: 計画書30部・調査報告書10部・電子媒体。村の方針は関係機関への送付とホームページへの掲載を公表としている。令和9年3月31日が業務期間の末日

Sheet 05_村資料・依頼の詳細
A1: 優先度 | B1: 資料・データ（依頼番号） | C1: 依頼の詳細 | D1: 反映先（成果物） | E1: 関係WBS（確定に必要／精度を上げる） | F1: 提供元 | G1: 状態 | H1: 希望期限 | I1: 受領日 | J1: WBS状態
A2: 最優先 | B2: 計画値の基礎とする系列（Ｍ-19） | C2: 村が自立支援協議会に報告している実利用者数（人／月）・サービス量を計画値の基礎としてよいか。当方の第1次概算は年間請求件数を基礎にしたため12サービスで村の公表実績と食い違う（計画相談支援 村25人・当方22人、障がい児相談支援 村4人・当方2人ほか）。あわせて令和8年度の実績見込 | D2: 計画素案 第5章3〜7／レビュー対応 02シート | E2: 5-10・7-2・7-3・7-7・8-7 | F2: 北塩原村 | G2: 未受領 | H2: 2026-10-09 | J2: 未着手
A3: 最優先 | B3: 移行管理台帳（Ｍ-18） | C3: 匿名ID・生年月・学年・学校種別・障害支援区分・行動関連項目・医療的ケア・重症心身・現在のサービス・支給決定量・実利用量・利用先と所在地・送迎の可否・冬季の利用可否・卒業予定・65歳到達年度・家族介護の状況。この1枚でＭ-10（継続入所者）・Ｍ-11（保育所等の受入体制）・Ｍ-15（65歳到達者）・Ｍ-21（卒業予定者）が同時に片付く | D3: 計画素案 第5章1・第5章2（第2次算定の入力） | E3: 5-10・7-2・7-3・8-10 | F3: 北塩原村 | G3: 未受領 | H3: 2026-10-09 | J3: 未着手
A4: 最優先 | B4: 施設入所支援4人の支給決定の内容（Ｍ-13） | C4: 年齢、生活介護との同時支給決定の有無、入所先の施設類型（指定障害者支援施設か）。介護保険法施行法第11条第1項の適用除外に当たると、介護保険の第1号被保険者・認定者から除く | D4: 介護保険事業計画との整合 K-1 | E4: 7-9（精度：7-5） | F4: 北塩原村 | G4: 未受領 | H4: 2026-10-09 | J4: 未着手
A5: 最優先 | B5: 介護保険の第2号被保険者との重なり（Ｍ-14） | C5: 介護保険側が見込む第2号被保険者の認定者（各年度2〜3人）のうち、障がい福祉サービスの受給者証をお持ちの方の人数と利用サービス。重なる場合は介護保険が優先し障がい計画の見込量から減算する | D5: 介護保険事業計画との整合 K-2 | E5: 7-9（精度：2-4） | F5: 北塩原村 | G5: 未受領 | H5: 2026-10-09 | J5: 未着手
A6: 高 | B6: 相談支援の体制（Ｍ-20） | C6: 相談支援専門員の人数、1人当たりの担当件数、新規に受け入れられる件数、主任相談支援専門員の配置。専門員が不足すると受入先があっても移行が進まない | D6: 計画素案 第5章8（確保可能量を決める要素） | E6: 7-2（精度：8-3） | F6: 北塩原村 | G6: 未受領 | H6: 2026-10-09 | J6: 未着手
A7: 最優先 | B7: グループホーム・福祉ホームの設置の予定（Ｍ-37） | C7: 精神・知的障がいの方のグループホーム又は福祉ホームの設置の予定。設置する場合の主体・時期・定員と、条例改正の要否。令和8年10月9日の論点メモに「精神・知的のGHの設置（正式名・福祉ホームだが、条例の改正が必要）」とある。共同生活援助（訓練等給付）と福祉ホーム（地域生活支援事業の任意事業）では根拠も財源も変わる | D7: 計画素案 第5章の居住系の見込量・確保方策・地域生活支援事業 | E7: 7-2・7-4（精度：8-3） | F7: 北塩原村 | G7: 未受領 | H7: 2026-10-16 | J7: 未着手
A8: 高 | B8: 物品調達の実績（Ｍ-34） | C8: 障がい者就労施設等からの物品調達の実績（目標3件に対する令和6〜8年度の件数）と、障害者優先調達推進法第9条に基づく調達方針の策定・公表の有無 | D8: 計画素案 第3章5（第4次障がい者計画の目標値の進捗） | E8: 8-1（精度：6-4） | F8: 北塩原村 | G8: 未受領 | H8: 2026-10-31 | J8: 未着手
A9: 高 | B9: 社会福祉法改正への対応（Ｍ-35） | C9: 身寄りのない高齢者への日常生活支援・入院手続・死後事務への対応と、権利擁護の窓口の配置の検討状況。障がい者の親亡き後の支援と同じ課題であり、第6章に書くかを判断する | D9: 計画素案 第6章・第7章 | E9: 8-1（精度：2-4） | F9: 北塩原村 | G9: 未受領 | H9: 2026-10-31 | J9: 未着手
A10: 中 | B10: 防災の取組の状況（Ｍ-36） | C10: 防災無線の設置状況、災害図上訓練（ＤＩＧ）・避難所運営ゲーム（ＨＵＧ）の実施状況、避難訓練の頻度。個別避難計画10件の目標を達成する手順として書く | D10: 計画素案 第3章3（⑥生活環境） | E10: 8-1 | F10: 北塩原村 | G10: 未受領 | H10: 2026-10-31 | J10: 未着手
A11: 高 | B11: 排泄管理支援用具の増減の理由（Ｍ-38） | C11: 日常生活用具（排泄管理支援用具）の給付件数の直近の増減とその理由。当方は40→68→69→72件と増加傾向と整理したが、論点メモは「死亡により減少」としている。地域生活支援事業の給付件数の大半を占め、事業費にも響く | D11: 計画素案 第5章9／地域生活支援事業 01 | E11: 7-4（精度：7-7） | F11: 北塩原村 | G11: 未受領 | H11: 2026-10-31 | J11: 未着手
A12: 高 | B12: 成年後見の類型別内訳（Ｍ-39） | C12: 成年後見制度の利用者数の類型別内訳（後見・保佐・補助）と、会津権利擁護・成年後見センターにおける本村の位置（相談時間が3番目か、利用者数が3番目か）。民法等改正により後見・保佐が補助に一元化されるため、類型別の把握が要る | D12: 計画素案 第6章 | E12: 8-1（精度：7-4） | F12: 北塩原村 | G12: 未受領 | H12: 2026-10-31 | J12: 未着手
A13: 高 | B13: 指定難病による対象者（Ｍ-32） | C13: 手帳を所持していないが障害者総合支援法の対象疾病に該当してサービスを利用している方、又は利用しうる方の人数。対象疾病は令和7年4月1日から376疾病（厚生労働省の資料で原典確認済み。平成25年4月の施行時は130疾病で、7次にわたり拡大された）。手帳所持者数だけで対象者を数えると、手帳を所持しない方が漏れる | D13: 計画素案 第2章2・第5章1（推計方法） | E13: 7-2（精度：3-2） | F13: 北塩原村 | G13: 未受領 | H13: 2026-10-31 | J13: 未着手
... A70: 中 | B70: 自立支援協議会の委員名簿 | C70: 任期・氏名・所属・役職 | D70: 計画書 資料編 | E70: 10-1（精度：9-1） | F70: 北塩原村 | G70: 未受領 | H70: 2026-12-31 | J70: 未着手
A72: ※ 本シートは 北塩原村_業務進捗管理.xlsx 04_村資料受領状況 と同じデータから作成しており、「関係WBS」列を足して 01_WBS と結び付けたものです。依頼の詳細を見るために2冊を行き来する必要はありません。
A73: ※ 「関係WBS」は、その資料が届かないと確定できない作業の番号です。括弧内（精度：…）は、公表データ等で作業自体は済んでおり、資料が届くと具体性が増すものです。01_WBS の「必要な村資料」列が同じ対応の逆引きで、確定に必要な資料が届いていない作業は赤字にしています。
A74: ※ 「状態」は村資料の原語（未受領・一部受領・県照会中・受領済）、「WBS状態」は 01_WBS と同じ語彙（未着手・進行中・データ待ち・完了）です。受領したら「状態」を受領済に、「受領日」に日付を入れてください。
A75: ※ 現況：69件のうち受領済7件・一部受領6件・県照会中1件・未受領55件。見込量の基礎となる系列（Ｍ-19）は1件の回答で 7-2・7-3・7-7・8-7・5-10 の5作業が動くため、単独で先に照会します。

Sheet 06_会議体・意見聴取
A1: 区分 | B1: 回 | C1: 時期 | D1: 議題 | E1: 資料の状態 | F1: 備考
A2: 北塩原村障がい者自立支援協議会 | B2: 第1回（既済） | C2: 令和8年5月25日 | D2: 第7期計画の進捗管理・評価、計画策定方針、アンケート調査、意見・提案（21件） | E2: 完了 | F2: 資料13点を令和8年10月8日に受領。令和8年10月10日に未読の4点を読み、正本と突合（北塩原村_村資料点検_20261010.xlsx）
A3: 北塩原村障がい者自立支援協議会 | B3: 第2回 | C3: 令和8年10月 | D3: 現行計画の現状・評価分析、アンケート調査の結果報告、計画素案の検討（概要版を含む） | E3: 要対応 | F3: 村の計画策定方針による。評価・素案・概要版は作成済みでアンケート結果だけが欠ける。開催日を村に確認する（Ｍ-40）
A4: 北塩原村障がい者自立支援協議会（4町村広域） | B4: 第3回 | C4: 令和8年12月 | D4: パブリックコメントの結果報告、計画案の修正 | E4: 未着手 | F4: 村の方針では猪苗代町・磐梯町・湯川村・本村の4町村広域。正本 第1章5に4町村広域の協議会を加える（修正案V-4）
A5: 庁議 | B5: 第1回 | C5: 令和9年1月 | D5: 計画の概要についての説明、計画案の最終調整 | E5: 進行中 | F5: 村の方針による。庁議資料2・4の2点を作成済み
A6: 議会全員協議会 | B6: 第1回 | C6: 令和9年2月 | D6: 計画案の説明（令和9年度主要事業）、計画決定 | E6: 未着手 | F6: 村の方針による。正本 第1章5に村議会への説明がない
A7: パブリックコメント | B7: ― | C7: 令和8年11月 | D7: 計画案に対する意見の募集 | E7: 要対応 | F7: 村の方針は11月実施。正本 第1章5(4)は令和9年2月8日〜22日と書いており直す必要がある（修正案V-24）。前回（令和6年2月）は意見0件
A8: 村との打合せ | B8: 随時 | C8: 通年 | D8: 工程、資料、協議事項 | E8: 進行中 | F8: 仕様書4-Ⅲ。令和8年7月7日の打合せで実施設計を合意

Sheet 07_課題・リスク
A1: No | B1: 課題・リスク | C1: 内容 | D1: 影響 | E1: 対応 | F1: 状態
A2: R-39 | B2: 高齢者施策への接続について、村が答えられない形で照会していた | C2: 本計画は、65歳に達した後の生活を支える仕組みが介護保険の給付だけではないことを書き、村の高齢者福祉施策・村単独事業・介護保険の地域支援事業への接続を扱っている。当方はこれまで「障がいのある方が対象に含まれるかは事業ごとに異なります」と書き、村に「対象となるか」を照会していた（Ｍ-50・Ｍ-71・Ｍ-81）。国の地域支援事業実施要綱を読んだところ、任意事業の対象者は「被保険者、要介護被保険者を現に介護する者その他個々の事業の対象者として市町村が認める者」とされており、障がいのある方を対象に含めるかどうかは村の要綱の定め方による事項であった。村にとっては、国に決められていることを聞かれているのか自らの定めを聞かれているのかが分からない問いになっていた。あわせて、成年後見制度利用支援事業の条項を第115条の45第2項第2号と取り違えており（正しくは第3項第3号の任意事業。第2項第2号は権利擁護事業）、この誤りが村へ出す照会文Ｍ-97の本文にも入っていた | D2: 照会の立て方／影響度中 | E2: 令和8年10月11日に、要綱の原典を照合して直した。Ｍ-108（本村が実施している地域支援事業と、その要綱における対象者の定め）を起票し、「対象となるか」から「村の要綱が対象者をどう定めているか」へ聞き方を改めた。第5章5（2）に理由と表5-40（地域支援事業の区分と対象者の定め）を入れた（ＣＳ-1）。Ｍ-97とＫ-9の条項は第3項第3号に直した。照会文は村に渡るものであるため、送る前に直した。以後、照会を立てるときは「国が決めていること」と「村が決めていること」を分けてから書く | F2: 対応済み
A3: R-38 | B3: 高次脳機能障害者支援法が令和8年4月1日に施行され、村にも窓口の明確化と実施状況の公表が求められる | C3: 高次脳機能障害者支援法（令和7年法律第96号）は令和7年12月24日に公布され、令和8年4月1日から施行された。施行通知（障精発0415第1号 令和8年4月15日）は「各自治体」として、①相談できる窓口の明確化と周知（法第17条）、②普及啓発（法第18条・第26条・第27条・第28条）、③関係部局間の連携と人材の確保（法第29条）、④実態把握の調査（法第5条）、⑤支援の状況及び施策の実施状況の公表（法第10条第2項）を求めている。通知の宛先は都道府県及び指定都市であるが、都道府県に管内市町村への周知徹底を求めているため、本村も含まれる。とくに⑤は、都道府県が管内市区町村の状況を取りまとめて国へ報告することとされており、本村の実施状況が国へ上がる。さらに施行令（令和8年政令第60号）第1条は、高次脳機能障害から認知症及び発達障害を除いている。窓口が一つしかない本村では、記憶や注意の障がいという見え方が同じでもつなぎ先が分かれるため、この切り分けが相談の入口を決める | D3: 制度動向／影響度高 | E3: 令和8年10月11日に、施行通知と施行令の原典を照合して反映した。第1章4（3）に公布と施行の日を書き（ＫＮ-1）、第5章2（2）に村が行うこと、定義の切り分けの表（表5-17）、及び県が行うことを書いた（ＫＮ-2）。県の支援センターの指定は令和8年度内に行われる見込みであり、指定の状況、地域協議会への参画、及び公表の様式と時期を照会する（Ｍ-107）。手元にないのは法律の条文そのもの、支援事業の実施要綱（障発0407第31号 別紙1）、及び公表等についての通知の別紙様式である。とくに公表の様式は本村が公表する事項に直に関わる | F3: 進行中
A4: R-37 | B4: 国の予算資料は当初予算と前年度補正予算が同じ資料に載るため、年度を取り違えやすい | C4: 令和8年度障害保健福祉部予算案の概要には、令和8年度当初予算と令和7年度補正予算が同じ資料に載っている。レビューは令和7年度補正の7事業（賃上げ439億円ほか）を令和8年度当初として扱っており、当方はこれを指摘した。ところが当方自身も、令和7年度の資料に【令和6年度補正予算】として載っている中核的人材養成研修事業21百万円を「令和7年度予算にもある」と書いていた。同じ種類の誤りである。あわせて広域的支援人材の配置の開始年度を1年遅く書き（正しくは令和6年度当初予算）、令和8年度の原典にある【新規】の表示を「政策の新設ではない」と言い換えて消していた | D4: 資料の読み方／影響度高 | E4: 令和8年10月11日に、令和6年度の原典を得て訂正した。build_kitashiobara_yosan_mece.py の自己点検に、①令和7年度の資料についても補正予算の見出しの後ろに並んでいるかを確かめる、②広域的支援人材が令和6年度の原典に「新たに配置」とあることを確かめる、③令和8年度の原典の【新規】表示を確かめる、④訂正前の主張が残っていないこと及び訂正後の記述が入っていることを確かめる、の4点を加えた。いずれも生成のたびに走る。正本の本文（ＹＳ-1・ＹＳ-3）は年度を言わずに書いていたため、本文の訂正は要らなかった。以後、国の施策を本文に書くときは年度を言わず、「進められている」「令和９年度から始められるよう準備が進められている」のように書く | F4: 対応済み
A5: R-36 | B5: 確保の方策の記述が当方の中で食い違っていた（共生型サービス） | C5: 第5章2（4）のＷ-11は、同じ段落の中で「本村には障がい福祉サービスの事業所が３カ所しかありません」と書きながら、末尾で「村内で居宅介護又は生活介護を受けられるようになれば」と書いていた。前者は村内に事業所があると言い、後者はまだ受けられないと言っている。当方の調べ（ReMHRAD障害福祉資源）では令和7年時点で居宅介護１カ所・重度訪問介護１カ所・生活介護１カ所があり、後者が誤りである。外部の資料を見るまでもなく、当方が書いた文の中で矛盾していた。あわせて「共生型サービス又は基準該当サービスの指定を受けることを働きかけます」という書き方も制度用語として誤っていた。基準該当障害福祉サービスは指定を受ける制度ではない | D5: 記述の整合／影響度高 | E5: 令和8年10月11日に、国の資料7件を照合したうえでＷ-11を書き直した（build_kitashiobara_juten12.py の側）。村内の３カ所の内訳を明示し、共生型が指定の手続の特例であって事業者の申請が要ることと、一方の指定がもう一方の基準を満たすことを意味しないことを書き足した。第5章5（2）にＫＹ-1（事業所の指定の形と65歳到達後の続け方）を追記した。村内の事業所の指定の形は当方では確かめられないため村に照会する（Ｍ-106）。同種の食い違いを防ぐため、build_kitashiobara_kyoseigata.py の自己点検で直す前の文が正本に残っていないことを生成のたびに確かめる | F5: 進行中
A6: R-35 | B6: 令和8年度の報酬改定（＋1.84％）を見込量の基準年度に織り込んでいない | C6: 本計画の見込量は令和7年度の給付実績を基礎としている。しかし令和8年度の障害福祉サービス等報酬改定は既に決まっており、改定率は＋1.84％である（令和8年度障害保健福祉部予算案の概要）。正本の第1章4（3）は令和9年度の改定（検討中）にしか触れておらず、令和8年度の改定を書いていなかった。利用する方の人数が横ばいでも給付費は増えるため、改定前の単価による見込みのままでは給付費を低く見積もる。国の予算でも障害福祉サービス関係費は令和7年度から令和8年度にかけて9.5％の増である | D6: 財政／影響度高 | E6: 令和8年10月10日に、第1章4（3）と第5章7（1）へ書き足した（ＹＳ-1・ＹＳ-7）。令和8年度の給付実績が出そろった段階で、改定後の単価による額を基準に置き直し、第2次算定に用いる。それまでの間、第5章7の給付費は改定前の単価によるものとして読む | F6: 進行中
A7: R-34 | B7: 意思決定支援ガイドラインが第2版に改訂され、考え方が変わった | C7: 厚生労働省が令和8年9月に第2版を公表した。「本人の最善の利益」から「本人の意思と選好に基づく最善の解釈」への転換、どのような障害があっても意思決定能力があることを前提とする原則、本人参加の意思決定支援会議、意思決定支援責任者などが第1版から変わっている。周囲が本人にとってよいことを決めるのではなく、本人であれば何を望むのかを読み取るという向きの変更であり、用語の差し替えでは済まない。正本は案の段階から3段階を取り込んでいたが、価値観・最善の解釈・意思決定能力の前提は入っていなかった | D7: 制度動向／影響度中 | E7: 令和8年10月10日に、原典を1件ずつ照合したうえで反映した。移植8（第4章2（7））、移植18（第5章5（1））、Ｙ-5（第6章3）を生成器の側で直し、ＩＫ-1・ＩＫ-2を追記した。新しい数値の指標は作らず、県研修への参加の内数として扱う。残るのは県研修で第2版がいつから扱われるかの確認（Ｓ-12） | F7: 進行中
A8: R-33 | B8: 情報公表制度の公表率・更新率100％は、村に達成の手段がほとんどない | C8: 国の基本指針は管内事業所の公表率・更新率100％を成果目標としており、正本も表4-16に置いている。しかし事業者の指定もこの制度の報告先も県であり、村は指定を行う立場にない。国のＱ＆Ａ（問3-1-1）によれば、システムには自治体から事業所へ報告を促す機能も備わっていない。村にできるのは公表・更新の状況を確かめて県と連携した周知を行うことだけであり、100％に届かなかった場合に村の取組み不足とは言えない。さらに、表4-16には公表率・更新率の現状の欄が無く、いまの値を把握できていない | D8: 成果目標／影響度中 | E8: 令和8年10月10日に、目標が何のためのものかと、村にできることの範囲を正本に書いた（ＫＪ-1）。照会Ｍ-104（令和7年度の公表・更新の実績、未報告減算の対象の有無、県から村への情報提供の有無）を第1便に入れた。県から村へ状況の提供がない場合、村は100％かどうかを確かめる手段を持たないため、目標の書き方そのものを見直す | F8: 進行中
A9: R-32 | B9: 広域で確保するとした機能が、相手方の計画と同じ単位・同じ数え方になっているか確かめられていない | C9: 本計画は、地域生活支援拠点、基幹相談支援センター、医療的ケア児等支援、インクルージョン推進、強度行動障害支援を猪苗代町・磐梯町・湯川村との広域で確保するとしている。しかし相手方の計画では、医療的ケア児等支援の協議の場を「圏域1カ所」としており、この「圏域」が会津北部4町村か会津障がい保健福祉圏域かが分からない。単位が違えば設置すべき会議体そのものが変わる。医療的ケア児等コーディネーターも、県の養成研修の修了者、本村が数える1人、磐梯町が令和8年4月から制度化した独自配置が混在し、同じ方を双方が数えると4町村の合計が実際より多く見える。本村の計画の中では整っていても、相手方の計画と施設数・コーディネーター数・目標年度・会議体・KPIが食い違えば、広域で確保したことにならない | D9: 広域連携／影響度高 | E9: 令和8年10月10日に会津北部4町村共同確認票（16項目）を作成し、照会Ｍ-98として第6便に入れた（期限 令和8年12月12日）。県への照会8項目はＭ-99。正本には、協議の場の単位とコーディネーターの数え方を書き分ける記述を加えた（ＫＯ-1）。回答が揃うまで、成果目標の「4町村共同」は確定表記にしない | F9: 進行中
A10: R-31 | B10: 手帳所持者数の将来推計が、令和8年4月の実績と逆の方向を向いている | C10: 当方の将来推計ブックは平成31年〜令和5年の5か年（156人まで減少）を延ばし、令和11年度の中位推計を145人（減少）としている。他メンバー版の正本 第2章2 には令和8年4月の実績が入っており、身体127人・療育16人・精神38人の計181人で、令和5年から25人の増加である。減少という前提そのものが成り立たない。あわせて、これまで確認事項としていた「仕様書の約190人と現行計画156人の差」は、約190人が令和8年時点の実数であったと考えられるため解消した。手帳所持者数は所持率法による見込量の検証に用いるため、第2次算定の検証の土台が狂う | D10: 推計／影響度高 | E10: 令和8年10月10日に概要版から令和11年度の推計値を外し、やり直す旨を注記した（計画素案・将来推計ブックにも【要更新】を付した）。令和6年度・令和7年度の手帳所持者数を村から受領したうえで、第2次算定で推計をやり直す。それまでの間、令和11年度の推計値を計画本文・概要版・委員会資料に載せない | F10: 進行中
A11: R-26 | B11: 第4次障がい者計画のアンケート指標3件が前回と比較できない | C11: ①満足度は前回n=25（利用者のみ・2択）に対し今回n=33（「利用していない」を含む）。分母により39.4％（未達）と61.9％（目標60％超）に分かれ達成判定が逆転する。②差別・偏見は前回3択（25.3％）に対し今回は頻度尺度（29.0％）で、前回にない「わからない」が32.3％を占める。③外出の目的は今回の調査票に設問がなく測定できない | D11: 指標／影響度高 | E11: 令和8年10月4日に全数を洗い出し済み（北塩原村_目標KPI_前回比較可能性.xlsx）。報告書の確定前に、3指標の扱いを村と決める。①は前回と同じ基準（利用者のみ）に揃える。②は基準値を置き直すか定義を見直す。③は行政データによる代替指標へ振り替える（クロス集計設計 Ｓ-1）。計画素案 第3章5の目標値表に直結する | F11: 未着手
A12: R-23 | B12: 告示後に基本指針が2度改正されており、追跡から漏れる | C12: 令和8年3月31日の告示の後、同年7月10日（社会福祉法等改正）と8月19日（医療的ケア児支援法改正）に改正案が示されている。いずれも審議会資料として出たもので、告示本文だけを見ていると取りこぼす。前者は別表第二に六の項（人材確保・生産性向上・経営基盤）を新設し、市町村計画の定めるよう努めなければならない事項を1項目増やした。後者は医療的ケア者（成人）を新設し、成果目標 四の4を拡充した。計画確定の令和9年3月までにさらに改正が示される可能性がある | D12: 制度動向／影響度高 | E12: 社会保障審議会障害者部会・こども家庭審議会障害児支援部会の資料と、県からの市町村あて通知を定期的に確認する。村にも県通知の共有を依頼する。確認結果は骨子案レビューブックに追記する | F12: 進行中
... A37: R-19 | B37: 障がい児版の設問番号に誤りがある | C37: 問11の選択肢番号「13」が2つある（「自傷、他害、強いこだわり、パニックなどへの対応」と「特にない」）。問10の選択肢番号は「3」が欠番。いずれも村の朱書きとは別に、通読して気づいたもの | D37: 調査設計／影響度低 | E37: 調査票担当へ申し送り済み。印刷前に番号を振り直す。問10は問8との統合指示があるため、統合時に整理する | F37: 進行中

Sheet 08_変更管理・打合せ記録
A1: No | B1: 区分 | C1: 内容 | D1: 根拠 | E1: 状態 | F1: 記録の有無
A2: 11 | B2: 計画素案の正本 | C2: 当方が原本（他メンバー作成の骨子案）から起こした素案で進めてきたが、令和8年10月9日に他メンバー版（令和8年10月8日受領）を正本とする方針に変更した | D2: ― | E2: 完了 | F2: 北塩原村_申し送り_他メンバー版への移植_20261009.docx（第2版・移植20件）。令和8年10月10日に正本へ移植した（北塩原村_計画素案_正本_移植後.docx。段落526→626・表55→97）。当方の素案は移植の元と点検の基準として残す。村・県の回答を待つ2件（Ｉ推計方法・Ｌ圏域の基盤整備）は申し送りに残した
A3: 10 | B3: 人口・手帳所持者数の基準日 | C3: 現行計画は「各年4月1日現在」だが、令和8年10月9日の打合せで9月30日に揃える提案があった（打合せ記録 U-1）。基準日を変えると前回計画との経年比較が接続しない | D3: ― | E3: 要対応 | F3: 北塩原村_打合せ記録_20261009.xlsx 01シート U-1。9月30日とする典拠は未確認（熊谷氏へＳ-15）。村に9月30日時点のデータが取れるかを照会（Ｍ-28）
A4: 1 | B4: 印刷仕様 | C4: 仕様書はアンケート調査をA4判・約24ページ・黒1色の1種類とするが、実際は障がい者版・障がい児版の2種類で、頁数も異なる | D4: 仕様書4-Ⅰ(3) | E4: 要対応 | F4: 未。頁数・種類数・部数・単価の取扱いを協議する
A5: 2 | B5: 郵送費の負担 | C5: 仕様書は発送及び回収に係る費用を受託者の負担とするが、打合せでは村が立替え後日実費精算とされた | D5: 仕様書4-Ⅰ(4) | E5: 要対応 | F5: 令和8年7月7日議事録に記載。精算方法・範囲・上限の書面確認が未
A6: 3 | B6: 調査対象者数 | C6: 仕様書は約190人（身体約130・精神約40・療育約20）とするが、現行計画の手帳所持者数は156人（令和5年）で22％の差がある | D6: 仕様書4-Ⅰ(1) | E6: 要対応 | F6: 未。回収率の分母・管理番号の設計に直結する
A7: 4 | B7: 協議会の開催回数 | C7: 仕様書は開催1回程度を見込むとするが、現行計画の評価・素案・計画案の3段階を1回で審議することになる | D7: 仕様書4-Ⅱ(7) | E7: 進行中 | F7: 資料は段階別に3点作成済み。1回に集約する場合の構成を村と協議する
A8: 5 | B8: 編集所管課の表記 | C8: 仕様書の事務担当は保健福祉課福祉係、骨子案の奥付は住民課となっていた | D8: 仕様書・骨子案奥付 | E8: 完了 | F8: 令和8年8月の調査票修正指示で問合せ先が「医療福祉班」から「保健福祉課 福祉係」に修正されたことにより確定。骨子案の奥付に反映済み
A9: 6 | B9: 追加業務の位置づけ | C9: 補足ヒアリング調査、財政負担の可視化は仕様書に明示がない | D9: ― | E9: 要対応 | F9: 令和8年7月7日議事録に記載。範囲・工数・対象機関を整理して協議する
A10: 9 | B10: 調査票の確定と国の標準項目の欠落 | C10: 調査票は令和8年8月25日版で確定し設問の追加ができない。国のマニュアルの標準項目のうち、外出の目的・介護保険の利用状況・強度行動障害の該当有無・障害支援区分の4件が確定版にない | D10: 仕様書4-Ⅰ(2)（委託者との協議の上決定） | E10: 進行中 | F10: クロス集計設計.xlsx で代替方針を整理済み。3件は行政データで代替可。外出の目的のみ村との再協議が必要
A11: 8 | B11: 国のマニュアルの改定 | C11: 令和8年8月に「障害福祉計画策定に係る実態調査及びPDCAサイクルに関するマニュアル」が改定され、福島県から市町村へ通知された。調査票の標準項目と、見込量推計・PDCAサイクルの要求水準が示された | D11: 厚労省・こども家庭庁 令和8年8月19日事務連絡／福島県 8生福第2646号・8こ第2041号 令和8年8月24日 | E11: 進行中 | F11: 確認結果を文書化済み。別表第五の適用外判定は裏付けられた。調査票の欠落3件について発送前に村と協議する必要がある
A12: 12 | B12: 評価の様式 | C12: 令和8年10月10日の再レビューにより、12重点施策のうちNo.5（65歳移行）・No.6（移動・冬季支援）・No.10（住まい・親亡き後）・No.12（防災・緊急時）を、村に既にある高齢者施策・権利擁護・緊急連絡の仕組みと接続して評価する形に改めた。評価を実施／未実施の2択から6区分（障害福祉で実施・他制度で対応・圏域で対応・ニーズなし・ニーズあり供給不足・把握不足）に広げ、年次の点検評価の様式を7列（実績・ニーズ・障害福祉での供給・他制度による代替補完・圏域利用・未充足・令和9〜11年度の対応）とした | D12: 再レビュー（令和8年10月10日） | E12: 進行中 | F12: 北塩原村_12重点施策_評価設計.xlsx（12シート）。再レビューが引く3資料（高齢者サービスの手引き・緊急連絡カード・令和8年度住民向け成年後見講座）は同日中に受領し、source/村資料_高齢者施策_20261010 に格納して原典で照合した。正本には12件（W-1〜W-13）を反映済み。原典から、村内の介護保険事業所7カ所のうち訪問介護1・通所介護2が共生型サービスの指定を受けられることが分かり、確保のための方策に具体の働きかけ先を書けた（W-11）。高齢者福祉施策の対象が「高齢者世帯等」であり障がいのある方が含まれるかは手引きから読み取れないため照会Ｍ-49・Ｍ-50に残した
A13: 13 | B13: 既存施策の棚卸し | C13: 令和8年10月10日に村ホームページの掲載施策の整理を受領。手話言語条例（令和7年4月制定）、公式動画による手話の紹介、指文字の紹介、手話出前講座、ヘルプマーク・ヘルプカード・耳マーク、電話お願い手帳、つなぐ窓口、障がい者活躍推進計画、パラスポーツ指導員養成講習会など、正本に書いていなかった既存施策が分かった | D13: 村ホームページ（当方は組織のネットワーク方針により取得できず、レビューの記述を出所とする） | E13: 進行中 | F13: 北塩原村_村HP掲載施策の棚卸し.xlsx（11シート）。正本に5件（X-1〜X-6）を反映し、照会10件（Ｍ-59〜Ｍ-68）を立てた。あわせて当方の誤り（本村に独自の条例がない）を2か所直した
... A28: 7 | B28: 調査票の修正指示 | C28: 令和8年8月に村から朱書き40か所の修正指示を受領。うち9件は削除理由として村の実データが書き添えられていた | D28: 仕様書4-Ⅰ(2)（委託者との協議の上決定） | E28: 進行中 | F28: 確認結果を文書化済み（docs/北塩原村_アンケート調査票_村修正指示_確認結果.md）。問36の削除について再考を依頼中
A30: ※ 仕様書6(3)により北塩原村委託契約約款に準拠する。仕様書と異なる運用は書面で記録を残す。

Sheet 09_翌日の着手順
A1: 順 | B1: 時間帯 | C1: 作業 | D1: なぜこの順番か | E1: 所要 | F1: 成果物 | G1: 外部依存 | H1: 関係番号
A2: 1 | B2: 手持ち・済 | C2: 村への照会文6通を作る（Ｍ-41〜Ｍ-105 の65件） | D2: 照会は55件に増えていたが、村に出す文書そのものを1通も作っていなかった。照会を出さない限り、見込量も成果目標も委員会資料も確定しない。これが工程上の最大の詰まりであった。回答がいつ要るかで5通に分けた。①委員会に直に要るもの9件（10月24日）②見込量の確定8件（10月31日）③高齢者施策との接続20件（11月14日）④児童福祉との接続4件（11月14日）⑤既存施策の実績16件（11月28日）。Ｍ-40（工程の確認）は文書にせず電話で確かめる。工程が分からないと5通の期限そのものを決められないため | E2: 3時間 | F2: 北塩原村_村への照会_6通.docx | G2: なし（当方で完結） | H2: 照会文 5通／各点検・レビューの照会シート
A3: 2 | B3: 打合せ当日 | C3: 村へ工程の確認（Ｍ-40。電話で確かめる） | D3: 村の計画策定方針（令和8年5月25日 資料4）は、第2回協議会を令和8年10月、パブリックコメントを11月、第3回協議会（4町村広域）を12月、庁議を令和9年1月、議会説明と計画決定を2月としている。委員会が11月との連絡を受けたため、方針の工程からさらにずれている可能性がある。パブリックコメントの時期が決まらないと、概要版とパブコメ資料の作成期限が決まらない | E3: 0.3時間 | F3: 工程の確認（工程表・会議体の更新） | G3: なし（当方で完結） | H3: 村資料点検 02シート／照会Ｍ-40
A4: 3 | B4: 打合せ当日 | C4: 照会5通を手渡し、第1便の期限を合意する | D4: 第1便（10月24日）は11月の委員会資料に直に載る数値である。ここが遅れると委員会に未確定の表を出すことになる。人数が少なく個人が特定されるおそれがあるものは「該当あり・なし」のみでよいことも、その場で伝える | E4: 0.5時間 | F4: 照会5通の発出 | G4: 村の回答（第1便 10月24日） | H4: 照会文 5通
A5: 4 | B5: 手持ち | C5: 委員会資料を作る（前回計画の評価。3枚＋別立て1枚） | D5: 北塩原村_前回計画の評価整理.xlsx の01〜03シートは村の回答を待たずに資料にできる。①KPIの達成状況（達成9・一部達成1・未達成4）②見込量と実績（6区分。実績0をニーズ0としない）③施策評価と第8期への接続（継続・強化・新設・見直し）。④第4次障がい者計画の中間評価は8指標のうち5件が未確認のため、現在値の欄を「確認中」として別立てで出す | E5: 4時間 | F5: 委員会資料（前回計画の評価） | G5: なし（当方で完結） | H5: 前回計画の評価整理 00〜04・06シート
A6: 5 | B6: 手持ち・済 | C6: 概要版を今の正本に合わせて作り直す（令和8年10月10日） | D6: 概要版は古い正本に基づいており、医療へのアクセス（第5章2（15））、ライフコースの図、こども・子育て計画との連携（第7章4）が入っていなかった。4頁から6頁に改め、11 必要な見込量を確保するための方策（9項目）、12 年齢到達に伴うサービスの移行（図を新設）、13 他計画との連携（4計画）を足した。巻末にパブリックコメントの案内と問合せ先を置いた。あわせて、人口と手帳所持者数が古いままであったため、正本の令和8年4月の値（2,316人・181人）に置き換えた | E6: 4時間 | F6: 北塩原村_計画素案_概要版.docx（A4・6頁） | G6: なし（当方で完結） | H6: 成果品①／概要版の生成器
A7: 6 | B7: 手持ち | C7: パブリックコメント一式を用意する | D7: 村の方針では11月にパブリックコメントを実施する。実施要領、意見提出様式、公表する資料の一覧、意見への対応表の様式を先に作っておく。村の回答を要しない。工程がずれても様式は使えるため、先に作って損がない | E7: 3時間 | F7: パブリックコメント一式 | G7: なし（当方で完結） | H7: WBS 9-4・9-5
A8: 7 | B8: 手持ち | C8: 第2次算定のワークシートの枠を作る | D8: 見込量算定の再レビューで、算定根拠を残すべきものが6件挙がった（居宅介護の1人増、保育所等訪問支援の1人、短期入所の5人日、就労系の個人の経路、共同生活援助の内訳、計画相談支援のネット計算）。村の回答が来てから枠を作ると間に合わないため、入力すれば数字が出る形を先に用意する | E8: 3時間 | F8: 第2次算定のワークシート | G8: なし（当方で完結） | H8: 見込量算定のRedTeam再レビュー 05シート／MECE 06シート
A9: 8 | B9: 手持ち | C9: 表記の統一の一括置換を用意する（Ｓ-25の合意後に通す） | D9: 障害児通所支援は法令表記4件・村表記11件、障害児相談支援は法令3件・村表記12件と混在している。第5章1（5）では⑤障害児入所支援と⑥障がい児相談支援が同じ並びで食い違う。どちらに寄せるかは他メンバーとの合意事項であるため、合意後に1回で通せる置換の一覧を先に作っておく | E9: 1時間 | F9: 表記の統一の置換一覧 | G9: 他メンバーの合意（Ｓ-25） | H9: MECE 07シート／Ｓ-25
A10: 9 | B10: 手持ち | C10: 他メンバーへの確認8件（Ｓ-19〜Ｓ-26）を1通にまとめる | D10: 図の元データ（Ｓ-19）、緑と青の組合せ（Ｓ-20）、図表番号（Ｓ-21）、図2-8の表題（Ｓ-22）、計画の位置づけ図の重複（Ｓ-23）、画像内の表題（Ｓ-24）、制度名称の表記（Ｓ-25）、クロス集計の優先順位（Ｓ-26）。いずれも当方だけでは決められない | E10: 1時間 | F10: 他メンバーへの確認（1通。8件） | G10: なし（当方で完結） | H10: 図表一覧 07シート／図表番号一覧 04シート
A11: 10 | B11: 他メンバー・村 | C11: 正本の目次と頁数の確定（Word で目次を更新する） | D11: 当方の環境では LibreOffice が動かず、Word の目次フィールドを更新できない。第5章2に（15）、第7章に4が増え、図表目次も入れたため、頁数は約60頁から増えている。図表目次の頁番号もここで入る。Word のある環境での作業が要る | E11: 2時間 | F11: 正本の目次と頁数 | G11: Word のある環境（他メンバー又は村） | H11: 図表番号一覧 00シート／WBS 10-2
A12: 11 | B12: 回答後 | C12: 見込量を第2次算定で組み直す（1人単位の積上げ） | D12: 第2便（10月31日）とＭ-15・Ｍ-20・Ｍ-21の回答が前提。現在の見込量は第1次の概算であり、協議会・最終計画に載せる確定値としては未完成である（見込量算定の再レビューの総合判定「条件付き妥当」） | E12: 8時間 | F12: 正本 第5章1・3の見込量 | G12: 村の回答（第2便・Ｍ-15・Ｍ-20・Ｍ-21） | H12: 見込量算定のRedTeam再レビュー 01・07シート
A13: 12 | B13: 回答後 | C13: 前回計画の評価の中間評価を確定する | D13: 第1便（10月24日）の回答が前提。第4次障がい者計画の8指標のうち5件の現在値を埋め、基準値→現在値→目標→進捗率の形で委員会に出す | E13: 2時間 | F13: 委員会資料（第4次の中間評価） | G13: 村の回答（第1便 Ｍ-95・Ｍ-41） | H13: 前回計画の評価整理 04シート
... A15: 14 | B15: 節目ごと | C15: 成果物の再現性点検を回す（素案を直したあと必ず） | D15: 計画素案を直したあとに点検を回し、生成器から同じものが作り直せる状態を保つ。素案だけを単独で作り直すと目次が落ちるため、BUILDERS の依存順で全体を作り直してから確定させる。python3 check_reproducibility.py --regenerate で約3分。令和8年10月10日に実際にこれを踏んだ（C-6b が検出）。C-3 に「順序が効く成果物」を毎回表示するようにした | E15: 0.2時間 | F15: 点検結果（終了コード0） | G15: なし（当方で完結） | H15: WBS 1-7／docs/北塩原村_成果物の再現性点検と再発防止.md
A17: ※ 令和8年10月15日（木）の打合せまでの着手順（令和8年10月12日はスポーツの日のため、次の平日から）。律速は村のデータの受領であるため、①相手の時間がかかるもの（1〜6。村・県・介護保険側へ投げる）、②手元で完結するもの（7〜10。回答待ちの間にできる）、③回答が届いてからのもの（11〜13）の順に組んでいる。1を先頭に置いたのは、村の計画策定方針では第2回協議会が令和8年10月・パブリックコメントが11月であり、当方の工程表と2か月ずれているためである。いつ何を出すかが決まらないと、ほかの作業の順番も決まらない。2は見込量の基礎が1点の確認で決まるため単独で出す。正本への移植（20件）は令和8年10月10日に終え、未読だった村資料4点も同日に読み終えた（北塩原村_村資料点検_20261010.xlsx）。14は相手の予定に依存するため今週中に投げる。15は素案を直すたびに回す点検であり、作業の順番には入らない。
