Workbook

Sheet サマリー
B2: 北海道・東北 案件サマリー（今期案件残／来期計画）
B3: 出所：営業会議ブック シート「20260904㉜」（第32回・2026/9/4 時点） 単位：件数＝件、金額＝千円
B5: ① 今年度（今期）の案件残 | E5: 金額＝件数×単価×掛率（原本の算定式と同一）
B6: エリア | C6: 案件残 件数 | D6: 案件残 金額 | E6: 補正対象 件数 | F6: 補正対象 金額 | G6: 合計 件数 | H6: 合計 金額 | I6: 全社比 (金額)
B7: 北海道 | C7: =今期_案件残明細!$E$15 -> 4 | D7: =今期_案件残明細!$F$15 -> 4000 | E7: =今期_案件残明細!$E$28 -> 1 | F7: =今期_案件残明細!$F$28 -> 1000 | G7: =C7+E7 -> 5 | H7: =D7+F7 -> 5000 | I7: =IFERROR(H7/$H$10,0) -> 0.081566069
B8: 東北 | C8: =今期_案件残明細!$G$15 -> 9 | D8: =今期_案件残明細!$H$15 -> 7800 | E8: =今期_案件残明細!$G$28 -> 5 | F8: =今期_案件残明細!$H$28 -> 4100 | G8: =C8+E8 -> 14 | H8: =D8+F8 -> 11900 | I8: =IFERROR(H8/$H$10,0) -> 0.19412724
B9: 2エリア計 | C9: =SUM(C7:C8) -> 13 | D9: =SUM(D7:D8) -> 11800 | E9: =SUM(E7:E8) -> 6 | F9: =SUM(F7:F8) -> 5100 | G9: =SUM(G7:G8) -> 19 | H9: =SUM(H7:H8) -> 16900 | I9: =IFERROR(H9/$H$10,0) -> 0.27569331
B10: （参考）全社 | C10: =今期_案件残明細!$O$15 -> 31 | D10: =今期_案件残明細!$P$15 -> 32800 | E10: =今期_案件残明細!$O$28 -> 18 | F10: =今期_案件残明細!$P$28 -> 28500 | G10: =C10+E10 -> 49 | H10: =D10+F10 -> 61300 | I10: 1
B13: ② 来期の案件計画 | E13: 原本の来期テーマ別計画（件数・金額とも原本の入力値）
B14: エリア | C14: 件数 | D14: 金額 | E14: 平均単価 (千円/件) | F14: 全社比 (件数) | G14: 全社比 (金額) | H14: 要員数 (名) | I14: 1名あたり 売上
B15: 北海道 | C15: =来期_案件明細!$C$15 -> 280 | D15: =来期_案件明細!$D$15 -> 270000 | E15: =IFERROR(D15/C15,0) -> 964.28571 | F15: =IFERROR(C15/$C$18,0) -> 0.39325843 | G15: =IFERROR(D15/$D$18,0) -> 0.31764706 | H15: 12 | I15: =IFERROR(D15/H15,0) -> 22500
B16: 東北 | C16: =来期_案件明細!$E$15 -> 172 | D16: =来期_案件明細!$F$15 -> 190000 | E16: =IFERROR(D16/C16,0) -> 1104.6512 | F16: =IFERROR(C16/$C$18,0) -> 0.24157303 | G16: =IFERROR(D16/$D$18,0) -> 0.22352941 | H16: 6 | I16: =IFERROR(D16/H16,0) -> 31666.667
B17: 2エリア計 | C17: =SUM(C15:C16) -> 452 | D17: =SUM(D15:D16) -> 460000 | E17: =IFERROR(D17/C17,0) -> 1017.6991 | F17: =IFERROR(C17/$C$18,0) -> 0.63483146 | G17: =IFERROR(D17/$D$18,0) -> 0.54117647 | H17: =SUM(H15:H16) -> 18 | I17: =IFERROR(D17/H17,0) -> 25555.556
B18: （参考）全社 | C18: =来期_案件明細!$I$15 -> 712 | D18: =来期_案件明細!$J$15 -> 850000 | E18: =IFERROR(D18/C18,0) -> 1193.8202 | F18: 1 | G18: 1
B21: ③（参考）今期の確保済実績とエリア別見積状況
B22: エリア | C22: 随契 金額 | D22: 落札 金額 | E22: 確保済 計 | F22: 見積提示 今期分 | G22: 見積提示 来期分 | H22: 指名停止 影響件数 | I22: 指名停止 影響額
B23: 北海道 | C23: 168748 | D23: 37614 | E23: =C23+D23 -> 206362 | F23: 1 | G23: 44 | H23: =今期_案件残明細!$E$41 -> 0 | I23: =今期_案件残明細!$F$41 -> 0
B24: 東北 | C24: 110969 | D24: 42890 | E24: =C24+D24 -> 153859 | F24: 2 | G24: 57 | H24: =今期_案件残明細!$G$41 -> 14 | I24: =今期_案件残明細!$H$41 -> 14100
B25: 関東 | C25: 97200 | D25: 99921 | E25: =C25+D25 -> 197121 | F25: 2 | G25: 29 | H25: =今期_案件残明細!$K$41 -> 33 | I25: =今期_案件残明細!$L$41 -> 53500
B26: 西日本 | C26: 0 | D26: 52072 | E26: =C26+D26 -> 52072 | F26: 0 | G26: 4 | H26: =今期_案件残明細!$M$41 -> 34 | I26: =今期_案件残明細!$N$41 -> 50600
B27: 全社計 | C27: =SUM(C23:C26) -> 376917 | D27: =SUM(D23:D26) -> 232497 | E27: =SUM(E23:E26) -> 609414 | F27: =SUM(F23:F26) -> 5 | G27: =SUM(G23:G26) -> 134 | H27: =SUM(H23:H26) -> 81 | I27: =SUM(I23:I26) -> 118200
B29: ※ 随契・落札はエリア別の金額のみ原本に記載（件数のエリア別内訳は原本に無し）。全社は随契353件、落札161件。
B30: ※ 指名停止の影響は【指名停止の影響】表の件数に各テーマの単価×掛率を乗じた参考値。北海道は影響無し。
B31: ※ 東北の当期実損は原本コメントで「5件：△8,000千円（うち3件公会計・須賀川市/関連組合）」と記載。上表はテーマ別集計値。
B32: ※ 全社の見積提示済は今期分5件・来期分134件、指名停止の影響額は118,200千円で、いずれも原本の集計と一致。

Sheet 今期_案件残明細
B2: ① 今年度（今期）案件 テーマ別明細
B3: 出所：営業会議ブック「20260904㉜」【現在の案件残】D32:K38 ／【補正対象】D42:K48 ／【指名停止の影響】C20:K26
B4: 単位：金額＝千円 ／ 青字＝原本からの転記値、黒字＝本表の計算式
B6: 【現在の案件残】 | E6: 今期中に決着する未確定案件
B7: テーマ | C7: 単価 (千円) | D7: 掛率 | E7: 北海道 件数 | F7: 北海道 金額 | G7: 東北 件数 | H7: 東北 金額 | I7: 2エリア 件数 | J7: 2エリア 金額 | K7: (参考) 関東件数 | L7: (参考) 関東金額 | M7: (参考) 西日本件数 | N7: (参考) 西日本金額 | O7: 全社 件数 | P7: 全社 金額
B8: 公会計 | C8: 1000 | D8: 0.7 | E8: 0 | F8: =ROUND(E8*$C8*$D8,0) -> 0 | G8: 4 | H8: =ROUND(G8*$C8*$D8,0) -> 2800 | I8: =E8+G8 -> 4 | J8: =F8+H8 -> 2800 | K8: 5 | L8: =ROUND(K8*$C8*$D8,0) -> 3500 | M8: 3 | N8: =ROUND(M8*$C8*$D8,0) -> 2100 | O8: =E8+G8+K8+M8 -> 12 | P8: =F8+H8+L8+N8 -> 8400
B9: 会計支援 | E9: 0 | F9: =ROUND(E9*$C9*$D9,0) -> 0 | G9: 0 | H9: =ROUND(G9*$C9*$D9,0) -> 0 | I9: =E9+G9 -> 0 | J9: =F9+H9 -> 0 | K9: 0 | L9: =ROUND(K9*$C9*$D9,0) -> 0 | M9: 0 | N9: =ROUND(M9*$C9*$D9,0) -> 0 | O9: =E9+G9+K9+M9 -> 0 | P9: =F9+H9+L9+N9 -> 0
B10: 経営戦略 | C10: 3000 | D10: 0.8 | E10: 0 | F10: =ROUND(E10*$C10*$D10,0) -> 0 | G10: 0 | H10: =ROUND(G10*$C10*$D10,0) -> 0 | I10: =E10+G10 -> 0 | J10: =F10+H10 -> 0 | K10: 0 | L10: =ROUND(K10*$C10*$D10,0) -> 0 | M10: 0 | N10: =ROUND(M10*$C10*$D10,0) -> 0 | O10: =E10+G10+K10+M10 -> 0 | P10: =F10+H10+L10+N10 -> 0
B11: 経営改善 | C11: 4000 | D11: 0.7 | E11: 0 | F11: =ROUND(E11*$C11*$D11,0) -> 0 | G11: 0 | H11: =ROUND(G11*$C11*$D11,0) -> 0 | I11: =E11+G11 -> 0 | J11: =F11+H11 -> 0 | K11: 2 | L11: =ROUND(K11*$C11*$D11,0) -> 5600 | M11: 1 | N11: =ROUND(M11*$C11*$D11,0) -> 2800 | O11: =E11+G11+K11+M11 -> 3 | P11: =F11+H11+L11+N11 -> 8400
B12: 公共施設M | C12: 2000 | D12: 0.5 | E12: 3 | F12: =ROUND(E12*$C12*$D12,0) -> 3000 | G12: 3 | H12: =ROUND(G12*$C12*$D12,0) -> 3000 | I12: =E12+G12 -> 6 | J12: =F12+H12 -> 6000 | K12: 1 | L12: =ROUND(K12*$C12*$D12,0) -> 1000 | M12: 2 | N12: =ROUND(M12*$C12*$D12,0) -> 2000 | O12: =E12+G12+K12+M12 -> 9 | P12: =F12+H12+L12+N12 -> 9000
B13: 福祉計画 | C13: 2000 | D13: 0.5 | E13: 1 | F13: =ROUND(E13*$C13*$D13,0) -> 1000 | G13: 2 | H13: =ROUND(G13*$C13*$D13,0) -> 2000 | I13: =E13+G13 -> 3 | J13: =F13+H13 -> 3000 | K13: 1 | L13: =ROUND(K13*$C13*$D13,0) -> 1000 | M13: 3 | N13: =ROUND(M13*$C13*$D13,0) -> 3000 | O13: =E13+G13+K13+M13 -> 7 | P13: =F13+H13+L13+N13 -> 7000
B14: その他 | E14: 0 | F14: =ROUND(E14*$C14*$D14,0) -> 0 | G14: 0 | H14: =ROUND(G14*$C14*$D14,0) -> 0 | I14: =E14+G14 -> 0 | J14: =F14+H14 -> 0 | K14: 0 | L14: =ROUND(K14*$C14*$D14,0) -> 0 | M14: 0 | N14: =ROUND(M14*$C14*$D14,0) -> 0 | O14: =E14+G14+K14+M14 -> 0 | P14: =F14+H14+L14+N14 -> 0
B15: 計 | E15: =SUM(E8:E14) -> 4 | F15: =SUM(F8:F14) -> 4000 | G15: =SUM(G8:G14) -> 9 | H15: =SUM(H8:H14) -> 7800 | I15: =SUM(I8:I14) -> 13 | J15: =SUM(J8:J14) -> 11800 | K15: =SUM(K8:K14) -> 9 | L15: =SUM(L8:L14) -> 11100 | ... P15: =SUM(P8:P14) -> 32800
B16: 原本の全社計 | O16: 31 | P16: 32800
B17: 差異（0であること） | O17: =O15-O16 -> 0 | P17: =P15-P16 -> 0
B19: 【補正対象】 | E19: 補正予算での発注が見込まれる案件（原本上は別枠管理）
B20: テーマ | C20: 単価 (千円) | D20: 掛率 | E20: 北海道 件数 | F20: 北海道 金額 | G20: 東北 件数 | H20: 東北 金額 | I20: 2エリア 件数 | J20: 2エリア 金額 | K20: (参考) 関東件数 | L20: (参考) 関東金額 | M20: (参考) 西日本件数 | N20: (参考) 西日本金額 | O20: 全社 件数 | P20: 全社 金額
B21: 公会計 | C21: 1000 | D21: 0.7 | E21: 0 | F21: =ROUND(E21*$C21*$D21,0) -> 0 | G21: 3 | H21: =ROUND(G21*$C21*$D21,0) -> 2100 | I21: =E21+G21 -> 3 | J21: =F21+H21 -> 2100 | K21: 0 | L21: =ROUND(K21*$C21*$D21,0) -> 0 | M21: 0 | N21: =ROUND(M21*$C21*$D21,0) -> 0 | O21: =E21+G21+K21+M21 -> 3 | P21: =F21+H21+L21+N21 -> 2100
B22: 会計支援 | E22: 0 | F22: =ROUND(E22*$C22*$D22,0) -> 0 | G22: 0 | H22: =ROUND(G22*$C22*$D22,0) -> 0 | I22: =E22+G22 -> 0 | J22: =F22+H22 -> 0 | K22: 0 | L22: =ROUND(K22*$C22*$D22,0) -> 0 | M22: 0 | N22: =ROUND(M22*$C22*$D22,0) -> 0 | O22: =E22+G22+K22+M22 -> 0 | P22: =F22+H22+L22+N22 -> 0
B23: 経営戦略 | C23: 3000 | D23: 0.8 | E23: 0 | F23: =ROUND(E23*$C23*$D23,0) -> 0 | G23: 0 | H23: =ROUND(G23*$C23*$D23,0) -> 0 | I23: =E23+G23 -> 0 | J23: =F23+H23 -> 0 | K23: 4 | L23: =ROUND(K23*$C23*$D23,0) -> 9600 | M23: 1 | N23: =ROUND(M23*$C23*$D23,0) -> 2400 | O23: =E23+G23+K23+M23 -> 5 | P23: =F23+H23+L23+N23 -> 12000
B24: 経営改善 | C24: 4000 | D24: 0.7 | E24: 0 | F24: =ROUND(E24*$C24*$D24,0) -> 0 | G24: 0 | H24: =ROUND(G24*$C24*$D24,0) -> 0 | I24: =E24+G24 -> 0 | J24: =F24+H24 -> 0 | K24: 3 | L24: =ROUND(K24*$C24*$D24,0) -> 8400 | M24: 0 | N24: =ROUND(M24*$C24*$D24,0) -> 0 | O24: =E24+G24+K24+M24 -> 3 | P24: =F24+H24+L24+N24 -> 8400
B25: 公共施設M | C25: 2000 | D25: 0.5 | E25: 0 | F25: =ROUND(E25*$C25*$D25,0) -> 0 | G25: 2 | H25: =ROUND(G25*$C25*$D25,0) -> 2000 | I25: =E25+G25 -> 2 | J25: =F25+H25 -> 2000 | K25: 2 | L25: =ROUND(K25*$C25*$D25,0) -> 2000 | M25: 0 | N25: =ROUND(M25*$C25*$D25,0) -> 0 | O25: =E25+G25+K25+M25 -> 4 | P25: =F25+H25+L25+N25 -> 4000
B26: 福祉計画 | C26: 2000 | D26: 0.5 | E26: 1 | F26: =ROUND(E26*$C26*$D26,0) -> 1000 | G26: 0 | H26: =ROUND(G26*$C26*$D26,0) -> 0 | I26: =E26+G26 -> 1 | J26: =F26+H26 -> 1000 | K26: 0 | L26: =ROUND(K26*$C26*$D26,0) -> 0 | M26: 1 | N26: =ROUND(M26*$C26*$D26,0) -> 1000 | O26: =E26+G26+K26+M26 -> 2 | P26: =F26+H26+L26+N26 -> 2000
B27: その他 | E27: 0 | F27: =ROUND(E27*$C27*$D27,0) -> 0 | G27: 0 | H27: =ROUND(G27*$C27*$D27,0) -> 0 | I27: =E27+G27 -> 0 | J27: =F27+H27 -> 0 | K27: 1 | L27: =ROUND(K27*$C27*$D27,0) -> 0 | M27: 0 | N27: =ROUND(M27*$C27*$D27,0) -> 0 | O27: =E27+G27+K27+M27 -> 1 | P27: =F27+H27+L27+N27 -> 0
B28: 計 | E28: =SUM(E21:E27) -> 1 | F28: =SUM(F21:F27) -> 1000 | G28: =SUM(G21:G27) -> 5 | H28: =SUM(H21:H27) -> 4100 | I28: =SUM(I21:I27) -> 6 | J28: =SUM(J21:J27) -> 5100 | K28: =SUM(K21:K27) -> 10 | L28: =SUM(L21:L27) -> 20000 | ... P28: =SUM(P21:P27) -> 28500
B29: 原本の全社計 | O29: 18 | P29: 28500
B30: 差異（0であること） | O30: =O28-O29 -> 0 | P30: =P28-P29 -> 0
B32: 【指名停止の影響】 | E32: 指名停止により影響が及びうる案件（参考・案件残とは別集計）
B33: テーマ | C33: 単価 (千円) | D33: 掛率 | E33: 北海道 件数 | F33: 北海道 金額 | G33: 東北 件数 | H33: 東北 金額 | I33: 2エリア 件数 | J33: 2エリア 金額 | K33: (参考) 関東件数 | L33: (参考) 関東金額 | M33: (参考) 西日本件数 | N33: (参考) 西日本金額 | O33: 全社 件数 | P33: 全社 金額
B34: 公会計 | C34: 1000 | D34: 0.7 | E34: 0 | F34: =ROUND(E34*$C34*$D34,0) -> 0 | G34: 3 | H34: =ROUND(G34*$C34*$D34,0) -> 2100 | I34: =E34+G34 -> 3 | J34: =F34+H34 -> 2100 | K34: 5 | L34: =ROUND(K34*$C34*$D34,0) -> 3500 | M34: 6 | N34: =ROUND(M34*$C34*$D34,0) -> 4200 | O34: =E34+G34+K34+M34 -> 14 | P34: =F34+H34+L34+N34 -> 9800
B35: 会計支援 | E35: 0 | F35: =ROUND(E35*$C35*$D35,0) -> 0 | G35: 0 | H35: =ROUND(G35*$C35*$D35,0) -> 0 | I35: =E35+G35 -> 0 | J35: =F35+H35 -> 0 | K35: 0 | L35: =ROUND(K35*$C35*$D35,0) -> 0 | M35: 0 | N35: =ROUND(M35*$C35*$D35,0) -> 0 | O35: =E35+G35+K35+M35 -> 0 | P35: =F35+H35+L35+N35 -> 0
B36: 経営戦略 | C36: 3000 | D36: 0.8 | E36: 0 | F36: =ROUND(E36*$C36*$D36,0) -> 0 | G36: 0 | H36: =ROUND(G36*$C36*$D36,0) -> 0 | I36: =E36+G36 -> 0 | J36: =F36+H36 -> 0 | K36: 8 | L36: =ROUND(K36*$C36*$D36,0) -> 19200 | M36: 8 | N36: =ROUND(M36*$C36*$D36,0) -> 19200 | O36: =E36+G36+K36+M36 -> 16 | P36: =F36+H36+L36+N36 -> 38400
B37: 経営改善 | C37: 4000 | D37: 0.7 | E37: 0 | F37: =ROUND(E37*$C37*$D37,0) -> 0 | G37: 0 | H37: =ROUND(G37*$C37*$D37,0) -> 0 | I37: =E37+G37 -> 0 | J37: =F37+H37 -> 0 | K37: 6 | L37: =ROUND(K37*$C37*$D37,0) -> 16800 | M37: 4 | N37: =ROUND(M37*$C37*$D37,0) -> 11200 | O37: =E37+G37+K37+M37 -> 10 | P37: =F37+H37+L37+N37 -> 28000
B38: 公共施設M | C38: 2000 | D38: 0.5 | E38: 0 | F38: =ROUND(E38*$C38*$D38,0) -> 0 | G38: 2 | H38: =ROUND(G38*$C38*$D38,0) -> 2000 | I38: =E38+G38 -> 2 | J38: =F38+H38 -> 2000 | K38: 5 | L38: =ROUND(K38*$C38*$D38,0) -> 5000 | M38: 4 | N38: =ROUND(M38*$C38*$D38,0) -> 4000 | O38: =E38+G38+K38+M38 -> 11 | P38: =F38+H38+L38+N38 -> 11000
B39: 福祉計画 | C39: 2000 | D39: 0.5 | E39: 0 | F39: =ROUND(E39*$C39*$D39,0) -> 0 | G39: 7 | H39: =ROUND(G39*$C39*$D39,0) -> 7000 | I39: =E39+G39 -> 7 | J39: =F39+H39 -> 7000 | K39: 9 | L39: =ROUND(K39*$C39*$D39,0) -> 9000 | M39: 12 | N39: =ROUND(M39*$C39*$D39,0) -> 12000 | O39: =E39+G39+K39+M39 -> 28 | P39: =F39+H39+L39+N39 -> 28000
B40: その他 | C40: 3000 | D40: 0.5 | E40: 0 | F40: =ROUND(E40*$C40*$D40,0) -> 0 | G40: 2 | H40: =ROUND(G40*$C40*$D40,0) -> 3000 | I40: =E40+G40 -> 2 | J40: =F40+H40 -> 3000 | K40: 0 | L40: =ROUND(K40*$C40*$D40,0) -> 0 | M40: 0 | N40: =ROUND(M40*$C40*$D40,0) -> 0 | O40: =E40+G40+K40+M40 -> 2 | P40: =F40+H40+L40+N40 -> 3000
B41: 計 | E41: =SUM(E34:E40) -> 0 | F41: =SUM(F34:F40) -> 0 | G41: =SUM(G34:G40) -> 14 | H41: =SUM(H34:H40) -> 14100 | I41: =SUM(I34:I40) -> 14 | J41: =SUM(J34:J40) -> 14100 | K41: =SUM(K34:K40) -> 33 | L41: =SUM(L34:L40) -> 53500 | ... P41: =SUM(P34:P40) -> 118200
B42: 原本の全社計 | O42: 81 | P42: 118200
B43: 差異（0であること） | O43: =O41-O42 -> 0 | P43: =P41-P42 -> 0
B45: ※ 単価／掛率が空欄の行は原本に設定が無いもの（会計支援は全ブロック、その他は案件残・補正対象ブロック）。件数のみ計上し金額は0。
...

Sheet 来期_案件明細
B2: ② 来期案件計画 テーマ別明細
B3: 出所：営業会議ブック「20260904㉜」F123:P132（来期テーマ別 件数・金額）
B4: 単位：金額＝千円 ／ 青字＝原本からの転記値、黒字＝本表の計算式
B5: テーマ | C5: 北海道 件数 | D5: 北海道 金額 | E5: 東北 件数 | F5: 東北 金額 | G5: 2エリア 件数 | H5: 2エリア 金額 | I5: 全社 件数 | J5: 全社 金額 | K5: 全社比 (金額)
B6: 公会計 | C6: 182 | D6: 121100 | E6: 102 | F6: 70000 | G6: =C6+E6 -> 284 | H6: =D6+F6 -> 191100 | I6: 416 | J6: 269600 | K6: =IFERROR(H6/J6,0) -> 0.70882789
B7: 会計支援 | C7: 35 | D7: 25400 | E7: 18 | F7: 11000 | G7: =C7+E7 -> 53 | H7: =D7+F7 -> 36400 | I7: 70 | J7: 56000 | K7: =IFERROR(H7/J7,0) -> 0.65
B8: 公営企業 | C8: 14 | D8: 33500 | E8: 16 | F8: 37500 | G8: =C8+E8 -> 30 | H8: =D8+F8 -> 71000 | I8: 66 | J8: 188200 | K8: =IFERROR(H8/J8,0) -> 0.37725824
B9: 公共施設マネジメント | C9: 14 | D9: 26400 | E9: 12 | F9: 21000 | G9: =C9+E9 -> 26 | H9: =D9+F9 -> 47400 | I9: 54 | J9: 110100 | K9: =IFERROR(H9/J9,0) -> 0.43051771
B10: 総合計画 | C10: 5 | D10: 10500 | E10: 0 | F10: 0 | G10: =C10+E10 -> 5 | H10: =D10+F10 -> 10500 | I10: 11 | J10: 19500 | K10: =IFERROR(H10/J10,0) -> 0.53846154
B11: 福祉計画 | C11: 6 | D11: 12000 | E11: 8 | F11: 18500 | G11: =C11+E11 -> 14 | H11: =D11+F11 -> 30500 | I11: 34 | J11: 79900 | K11: =IFERROR(H11/J11,0) -> 0.38172716
B12: 社会生活計画 | C12: 7 | D12: 15000 | E12: 6 | F12: 13000 | G12: =C12+E12 -> 13 | H12: =D12+F12 -> 28000 | I12: 26 | J12: 61600 | K12: =IFERROR(H12/J12,0) -> 0.45454545
B13: その他計画 | C13: 15 | D13: 25500 | E13: 10 | F13: 19000 | G13: =C13+E13 -> 25 | H13: =D13+F13 -> 44500 | I13: 33 | J13: 64500 | K13: =IFERROR(H13/J13,0) -> 0.68992248
B14: その他 | C14: 2 | D14: 600 | E14: 0 | F14: 0 | G14: =C14+E14 -> 2 | H14: =D14+F14 -> 600 | I14: 2 | J14: 600 | K14: =IFERROR(H14/J14,0) -> 1
B15: 合計 | C15: =SUM(C6:C14) -> 280 | D15: =SUM(D6:D14) -> 270000 | E15: =SUM(E6:E14) -> 172 | F15: =SUM(F6:F14) -> 190000 | G15: =SUM(G6:G14) -> 452 | H15: =SUM(H6:H14) -> 460000 | I15: =SUM(I6:I14) -> 712 | J15: =SUM(J6:J14) -> 850000 | K15: =IFERROR(H15/J15,0) -> 0.54117647
B16: 平均単価(千円/件) | D16: =IFERROR(D15/C15,0) -> 964.28571 | F16: =IFERROR(F15/E15,0) -> 1104.6512 | H16: =IFERROR(H15/G15,0) -> 1017.6991 | J16: =IFERROR(J15/I15,0) -> 1193.8202
B18: ※ 件数・金額とも原本の入力値をそのまま採用（原本合計：北海道 280件/270,000千円、東北 172件/190,000千円）。
B19: ※ 全社の来期計画は 712件／850,000千円。今期見込売上 700,000千円に対し +150,000千円（+21.4%）の計画。
B20: ※ 来期要員計画は北海道12名・東北6名（原本 G133／I133）。1名あたり売上は北海道22,500千円・東北31,667千円。

Sheet 前提・注記
B2: 前提・出所・注記
B4: 元データ | C4: 営業会議ブック（週次営業会議シート）
B5: 基準シート | C5: 「20260904㉜」＝第32回・2026年9月4日時点（ブック内で最新の回）
B6: 比較シート | C6: 「20260828㉛」＝第31回・2026年8月28日時点（先週比の算定に使用）
B7: 単位 | C7: 件数＝件、金額＝千円
B8: 今期案件残の定義 | C8: 【現在の案件残】＝入札・提案の結果が未確定で今期中に決着する案件。【補正対象】＝補正予算での発注が見込まれる案件で、原本上は別枠管理。
B9: 金額の算定 | C9: 原本はエリア別の金額を持たず全社計のみを ROUND(件数×単価×掛率,0) で算定している。本サマリーは同じ単価・掛率をエリア別件数に適用して展開した。4エリア合計は原本の全社計（案件残32,800千円／補正対象28,500千円）と一致することを確認済み。
B10: 掛率の意味 | C10: 原本で設定された受注確度。公会計0.7／経営戦略0.8／経営改善0.7／公共施設M0.5／福祉計画0.5。したがって案件残金額は「確度加味後の見込売上」であり、満額ベースではない。
B11: 来期計画 | C11: 原本 F123:P132 のテーマ別 件数・金額をそのまま採用。原本上は「※イメージ」と付記された計画値。
B12: 今期確保済実績 | C12: 随契は原本 G7:J7、落札は G9:J9（いずれもエリア別金額）。件数のエリア別内訳は原本に無し。
B13: 見積提示済件数 | C13: エリア別明細ブロック（北海道 H172:I172／東北 H186:I186）の合計行。今期分・来期分の区分は原本どおり。
B14: 指名停止の影響 | C14: 【指名停止の影響】C20:K26 のエリア別件数に各テーマの単価×掛率を適用した参考値。北海道は原本コメントで「無し」。東北の当期実損は原本コメントで「5件：△8,000千円」と記載されており、本表の14件／14,100千円は影響が及びうる案件の総量を指す。
B15: 留意点 | C15: 原本は週次で上書き更新されるため、本サマリーは2026/9/4時点のスナップショット。
