Workbook

Sheet サマリー
B2: 営業活動ログ 分析サマリー
B3: 対象：訪問活動ログ 450件（2026/03/19〜2026/09/16） 基準日 2026/09/17
B5: ① 今週の活動量
B6: 区分 | C6: 活動件数 | D6: 団体数 | E6: 稼働者数 | F6: 再アプローチ | G6: 見積提示 | H6: 再訪不要
B7: 今週（9/14〜、3日分） | C7: =COUNTIFS(データ!$C$2:$C$451,"2026-09-14") -> 17 | D7: 12 | E7: 3 | F7: =COUNTIFS(データ!$C$2:$C$451,"2026-09-14",データ!$H$2:$H$451,"再アプローチ") -> 11 | G7: =COUNTIFS(データ!$C$2:$C$451,"2026-09-14",データ!$H$2:$H$451,"見積提示") -> 6 | H7: =COUNTIFS(データ!$C$2:$C$451,"2026-09-14",データ!$H$2:$H$451,"再訪不要") -> 0
B8: 先週（9/07〜） | C8: =COUNTIFS(データ!$C$2:$C$451,"2026-09-07") -> 35 | D8: 26 | E8: 5 | F8: =COUNTIFS(データ!$C$2:$C$451,"2026-09-07",データ!$H$2:$H$451,"再アプローチ") -> 26 | G8: =COUNTIFS(データ!$C$2:$C$451,"2026-09-07",データ!$H$2:$H$451,"見積提示") -> 6 | H8: =COUNTIFS(データ!$C$2:$C$451,"2026-09-07",データ!$H$2:$H$451,"再訪不要") -> 3
B9: 前々週（8/31〜） | C9: =COUNTIFS(データ!$C$2:$C$451,"2026-08-31") -> 85 | D9: 58 | E9: 7 | F9: =COUNTIFS(データ!$C$2:$C$451,"2026-08-31",データ!$H$2:$H$451,"再アプローチ") -> 36 | G9: =COUNTIFS(データ!$C$2:$C$451,"2026-08-31",データ!$H$2:$H$451,"見積提示") -> 4 | H9: =COUNTIFS(データ!$C$2:$C$451,"2026-08-31",データ!$H$2:$H$451,"再訪不要") -> 33
B10: → 8/24週109件をピークに 85→35→17件と減少。稼働者数も9→7→5→3名と連動しており、1人1日あたりの件数（約2件）はほぼ横ばい。活動量の減少は「人が動いていない」ことが主因。
B12: ② 個人ごとの案件数（上位）
B13: 入力者 | C13: 活動件数 | D13: 1日あたり | E13: 再訪不要率 | F13: 直近2週
B14: 林 | C14: =②個人別案件数!C6 -> 108 | D14: =②個人別案件数!F6 -> 3.6 | E14: =②個人別案件数!K6 -> 34.951456 | F14: =COUNTIFS(データ!$A$2:$A$451,"林",データ!$C$2:$C$451,"2026-09-14")+COUNTIFS(データ!$A$2:$A$451,"林",データ!$C$2:$C$451,"2026-09-07") -> 0
B15: 相澤 | C15: =②個人別案件数!C7 -> 92 | D15: =②個人別案件数!F7 -> 7.0769231 | E15: =②個人別案件数!K7 -> 7.6923077 | F15: =COUNTIFS(データ!$A$2:$A$451,"相澤",データ!$C$2:$C$451,"2026-09-14")+COUNTIFS(データ!$A$2:$A$451,"相澤",データ!$C$2:$C$451,"2026-09-07") -> 18
B16: 村田 | C16: =②個人別案件数!C8 -> 72 | D16: =②個人別案件数!F8 -> 4.5 | E16: =②個人別案件数!K8 -> 52.542373 | F16: =COUNTIFS(データ!$A$2:$A$451,"村田",データ!$C$2:$C$451,"2026-09-14")+COUNTIFS(データ!$A$2:$A$451,"村田",データ!$C$2:$C$451,"2026-09-07") -> 10
B17: 角張 | C17: =②個人別案件数!C9 -> 37 | D17: =②個人別案件数!F9 -> 6.1666667 | E17: =②個人別案件数!K9 -> 11.428571 | F17: =COUNTIFS(データ!$A$2:$A$451,"角張",データ!$C$2:$C$451,"2026-09-14")+COUNTIFS(データ!$A$2:$A$451,"角張",データ!$C$2:$C$451,"2026-09-07") -> 9
B18: 長戸 | C18: =②個人別案件数!C10 -> 30 | D18: =②個人別案件数!F10 -> 5 | E18: =②個人別案件数!K10 -> 20 | F18: =COUNTIFS(データ!$A$2:$A$451,"長戸",データ!$C$2:$C$451,"2026-09-14")+COUNTIFS(データ!$A$2:$A$451,"長戸",データ!$C$2:$C$451,"2026-09-07") -> 0
B19: 松田 | C19: =②個人別案件数!C11 -> 26 | D19: =②個人別案件数!F11 -> 4.3333333 | E19: =②個人別案件数!K11 -> 40 | F19: =COUNTIFS(データ!$A$2:$A$451,"松田",データ!$C$2:$C$451,"2026-09-14")+COUNTIFS(データ!$A$2:$A$451,"松田",データ!$C$2:$C$451,"2026-09-07") -> 0
B20: 高橋 | C20: =②個人別案件数!C12 -> 23 | D20: =②個人別案件数!F12 -> 2.0909091 | E20: =②個人別案件数!K12 -> 0 | F20: =COUNTIFS(データ!$A$2:$A$451,"高橋",データ!$C$2:$C$451,"2026-09-14")+COUNTIFS(データ!$A$2:$A$451,"高橋",データ!$C$2:$C$451,"2026-09-07") -> 10
B21: 岡本 | C21: =②個人別案件数!C13 -> 23 | D21: =②個人別案件数!F13 -> 3.8333333 | E21: =②個人別案件数!K13 -> 36.363636 | F21: =COUNTIFS(データ!$A$2:$A$451,"岡本",データ!$C$2:$C$451,"2026-09-14")+COUNTIFS(データ!$A$2:$A$451,"岡本",データ!$C$2:$C$451,"2026-09-07") -> 0
B22: 吉野 | C22: =②個人別案件数!C14 -> 19 | D22: =②個人別案件数!F14 -> 2.375 | E22: =②個人別案件数!K14 -> 0 | F22: =COUNTIFS(データ!$A$2:$A$451,"吉野",データ!$C$2:$C$451,"2026-09-14")+COUNTIFS(データ!$A$2:$A$451,"吉野",データ!$C$2:$C$451,"2026-09-07") -> 5
B23: 若山 | C23: =②個人別案件数!C15 -> 17 | D23: =②個人別案件数!F15 -> 17 | E23: =②個人別案件数!K15 -> 0 | F23: =COUNTIFS(データ!$A$2:$A$451,"若山",データ!$C$2:$C$451,"2026-09-14")+COUNTIFS(データ!$A$2:$A$451,"若山",データ!$C$2:$C$451,"2026-09-07") -> 0
B24: 計 | C24: =SUM(C14:C23) -> 447 | F24: =SUM(F14:F23) -> 52
B25: → 活動量は林・相澤・村田の3名で272件（全体の6割）。ただし林は直近2週ゼロ。相澤は1日7.1件・再訪不要率7.7%で量と質が両立。村田は再訪不要率52.5%で突出。
B27: ③ 再訪不要の要因（大分類）
B28: 大分類 | C28: 件数 | D28: 構成比 | E28: 主な内容
B29: 他社受託 | C29: =③再訪不要_要因分析!C18+③再訪不要_要因分析!C19+③再訪不要_要因分析!C25 -> 37 | D29: =IFERROR(C29/$C$37*100,0) -> 36.27451 | E29: システム保守に抱き合わせ22件／随契・委託継続14件／入札実績要件1件
B30: 自前作成方針（庁内対応） | C30: =③再訪不要_要因分析!C17 -> 37 | D30: =IFERROR(C30/$C$37*100,0) -> 36.27451 | E30: 長年自前・担当者が内製、前回数値の置き換えで足りる
B31: 策定済み・改定時期が先 | C31: =③再訪不要_要因分析!C20 -> 10 | D31: =IFERROR(C31/$C$37*100,0) -> 9.8039216 | E31: R8改定直後、計画期間がR10〜R11まで。時期を待てば再浮上
B32: 必要性・意欲が低い | C32: =③再訪不要_要因分析!C21 -> 8 | D32: =IFERROR(C32/$C$37*100,0) -> 7.8431373 | E32: 罰則なし・メリット感じない・長の方針で実施しない
B33: 予算がつかない・否決 | C33: =③再訪不要_要因分析!C22 -> 5 | D33: =IFERROR(C33/$C$37*100,0) -> 4.9019608 | E33: 例年予算つかず、予算否決により自前化
B34: 他計画へ一体化・包含され単独案件消滅 | C34: =③再訪不要_要因分析!C23 -> 3 | D34: =IFERROR(C34/$C$37*100,0) -> 2.9411765 | E34: こども計画・健康増進計画・総合計画に内包
B35: 要因不明（備考・結果とも未記入） | C35: =③再訪不要_要因分析!C24 -> 1 | D35: =IFERROR(C35/$C$37*100,0) -> 0.98039216 | E35: 備考・結果とも空欄で判定不能
B36: 庁内事情・外部要因による遅延 | C36: =③再訪不要_要因分析!C26 -> 1 | D36: =IFERROR(C36/$C$37*100,0) -> 0.98039216 | E36: 庁内調整負担、地番整理待ち
B37: 計 | C37: =SUM(C29:C36) -> 102 | D37: =IFERROR(C37/C37*100,0) -> 100
B39: → 「他社受託」と「自前作成方針」で各36%、合計7割超。うちシステム保守への抱き合わせ22件は公会計・会計支援・福祉計画に集中しており、単発の訪問では崩せない構造要因。
B40: → 一方「策定済み・改定時期が先」10件は案件が消えたのではなく時期待ち。改定時期を管理して再アプローチすれば戻せる母数。

Sheet ①週次活動量
B2: ① 週次の活動量
B3: 基準日：2026/09/17（木） 週は月曜起算 今週＝9/14週は 9/17 時点で未了（最終入力 9/16）
B5: 週開始 (月曜) | C5: 活動件数 | D5: 団体数 | E5: 稼働者数 | F5: 訪問日数 | G5: 1人1日 件数 | H5: 再アプローチ | I5: 見積提示 | J5: 再訪不要 | K5: 再訪不要率 | L5: 前週比 件数
B6: 2026-07-06 | C6: =COUNTIFS(データ!$C$2:$C$451,"2026-07-06") -> 12 | D6: 11 | E6: 1 | F6: 4 | G6: =IFERROR(C6/F6/E6,0) -> 3 | H6: =COUNTIFS(データ!$C$2:$C$451,"2026-07-06",データ!$H$2:$H$451,"再アプローチ") -> 5 | I6: =COUNTIFS(データ!$C$2:$C$451,"2026-07-06",データ!$H$2:$H$451,"見積提示") -> 0 | J6: =COUNTIFS(データ!$C$2:$C$451,"2026-07-06",データ!$H$2:$H$451,"再訪不要") -> 2 | K6: =IFERROR(J6/C6*100,0) -> 16.666667 | L6: -
B7: 2026-07-20 | C7: =COUNTIFS(データ!$C$2:$C$451,"2026-07-20") -> 10 | D7: 7 | E7: 1 | F7: 3 | G7: =IFERROR(C7/F7/E7,0) -> 3.3333333 | H7: =COUNTIFS(データ!$C$2:$C$451,"2026-07-20",データ!$H$2:$H$451,"再アプローチ") -> 3 | I7: =COUNTIFS(データ!$C$2:$C$451,"2026-07-20",データ!$H$2:$H$451,"見積提示") -> 0 | J7: =COUNTIFS(データ!$C$2:$C$451,"2026-07-20",データ!$H$2:$H$451,"再訪不要") -> 3 | K7: =IFERROR(J7/C7*100,0) -> 30 | L7: =C7-C6 -> -2
B8: 2026-07-27 | C8: =COUNTIFS(データ!$C$2:$C$451,"2026-07-27") -> 1 | D8: 1 | E8: 1 | F8: 1 | G8: =IFERROR(C8/F8/E8,0) -> 1 | H8: =COUNTIFS(データ!$C$2:$C$451,"2026-07-27",データ!$H$2:$H$451,"再アプローチ") -> 1 | I8: =COUNTIFS(データ!$C$2:$C$451,"2026-07-27",データ!$H$2:$H$451,"見積提示") -> 0 | J8: =COUNTIFS(データ!$C$2:$C$451,"2026-07-27",データ!$H$2:$H$451,"再訪不要") -> 0 | K8: =IFERROR(J8/C8*100,0) -> 0 | L8: =C8-C7 -> -9
B9: 2026-08-03 | C9: =COUNTIFS(データ!$C$2:$C$451,"2026-08-03") -> 3 | D9: 3 | E9: 1 | F9: 1 | G9: =IFERROR(C9/F9/E9,0) -> 3 | H9: =COUNTIFS(データ!$C$2:$C$451,"2026-08-03",データ!$H$2:$H$451,"再アプローチ") -> 1 | I9: =COUNTIFS(データ!$C$2:$C$451,"2026-08-03",データ!$H$2:$H$451,"見積提示") -> 0 | J9: =COUNTIFS(データ!$C$2:$C$451,"2026-08-03",データ!$H$2:$H$451,"再訪不要") -> 0 | K9: =IFERROR(J9/C9*100,0) -> 0 | L9: =C9-C8 -> 2
B10: 2026-08-10 | C10: =COUNTIFS(データ!$C$2:$C$451,"2026-08-10") -> 14 | D10: 11 | E10: 2 | F10: 3 | G10: =IFERROR(C10/F10/E10,0) -> 2.3333333 | H10: =COUNTIFS(データ!$C$2:$C$451,"2026-08-10",データ!$H$2:$H$451,"再アプローチ") -> 6 | I10: =COUNTIFS(データ!$C$2:$C$451,"2026-08-10",データ!$H$2:$H$451,"見積提示") -> 6 | J10: =COUNTIFS(データ!$C$2:$C$451,"2026-08-10",データ!$H$2:$H$451,"再訪不要") -> 0 | K10: =IFERROR(J10/C10*100,0) -> 0 | L10: =C10-C9 -> 11
B11: 2026-08-17 | C11: =COUNTIFS(データ!$C$2:$C$451,"2026-08-17") -> 101 | D11: 59 | E11: 7 | F11: 5 | G11: =IFERROR(C11/F11/E11,0) -> 2.8857143 | H11: =COUNTIFS(データ!$C$2:$C$451,"2026-08-17",データ!$H$2:$H$451,"再アプローチ") -> 50 | I11: =COUNTIFS(データ!$C$2:$C$451,"2026-08-17",データ!$H$2:$H$451,"見積提示") -> 17 | J11: =COUNTIFS(データ!$C$2:$C$451,"2026-08-17",データ!$H$2:$H$451,"再訪不要") -> 22 | K11: =IFERROR(J11/C11*100,0) -> 21.782178 | L11: =C11-C10 -> 87
B12: 2026-08-24 | C12: =COUNTIFS(データ!$C$2:$C$451,"2026-08-24") -> 109 | D12: 74 | E12: 9 | F12: 6 | G12: =IFERROR(C12/F12/E12,0) -> 2.0185185 | H12: =COUNTIFS(データ!$C$2:$C$451,"2026-08-24",データ!$H$2:$H$451,"再アプローチ") -> 58 | I12: =COUNTIFS(データ!$C$2:$C$451,"2026-08-24",データ!$H$2:$H$451,"見積提示") -> 17 | J12: =COUNTIFS(データ!$C$2:$C$451,"2026-08-24",データ!$H$2:$H$451,"再訪不要") -> 16 | K12: =IFERROR(J12/C12*100,0) -> 14.678899 | L12: =C12-C11 -> 8
B13: 2026-08-31 | C13: =COUNTIFS(データ!$C$2:$C$451,"2026-08-31") -> 85 | D13: 58 | E13: 7 | F13: 5 | G13: =IFERROR(C13/F13/E13,0) -> 2.4285714 | H13: =COUNTIFS(データ!$C$2:$C$451,"2026-08-31",データ!$H$2:$H$451,"再アプローチ") -> 36 | I13: =COUNTIFS(データ!$C$2:$C$451,"2026-08-31",データ!$H$2:$H$451,"見積提示") -> 4 | J13: =COUNTIFS(データ!$C$2:$C$451,"2026-08-31",データ!$H$2:$H$451,"再訪不要") -> 33 | K13: =IFERROR(J13/C13*100,0) -> 38.823529 | L13: =C13-C12 -> -24
B14: 2026-09-07 | C14: =COUNTIFS(データ!$C$2:$C$451,"2026-09-07") -> 35 | D14: 26 | E14: 5 | F14: 4 | G14: =IFERROR(C14/F14/E14,0) -> 1.75 | H14: =COUNTIFS(データ!$C$2:$C$451,"2026-09-07",データ!$H$2:$H$451,"再アプローチ") -> 26 | I14: =COUNTIFS(データ!$C$2:$C$451,"2026-09-07",データ!$H$2:$H$451,"見積提示") -> 6 | J14: =COUNTIFS(データ!$C$2:$C$451,"2026-09-07",データ!$H$2:$H$451,"再訪不要") -> 3 | K14: =IFERROR(J14/C14*100,0) -> 8.5714286 | L14: =C14-C13 -> -50
B15: 2026-09-14 ←今週 | C15: =COUNTIFS(データ!$C$2:$C$451,"2026-09-14") -> 17 | D15: 12 | E15: 3 | F15: 3 | G15: =IFERROR(C15/F15/E15,0) -> 1.8888889 | H15: =COUNTIFS(データ!$C$2:$C$451,"2026-09-14",データ!$H$2:$H$451,"再アプローチ") -> 11 | I15: =COUNTIFS(データ!$C$2:$C$451,"2026-09-14",データ!$H$2:$H$451,"見積提示") -> 6 | J15: =COUNTIFS(データ!$C$2:$C$451,"2026-09-14",データ!$H$2:$H$451,"再訪不要") -> 0 | K15: =IFERROR(J15/C15*100,0) -> 0 | L15: =C15-C14 -> -18
B16: 掲載週 計 | C16: =SUM(C6:C15) -> 387 | H16: =SUM(H6:H15) -> 197 | I16: =SUM(I6:I15) -> 56 | J16: =SUM(J6:J15) -> 79 | K16: =IFERROR(J16/C16*100,0) -> 20.413437
B19: 今週（9/14〜）の内訳
B20: 入力者別 | C20: 件数
B21: 相澤 | C21: =COUNTIFS(データ!$C$2:$C$451,"2026-09-14",データ!$A$2:$A$451,"相澤") -> 9
B22: 高橋 | C22: =COUNTIFS(データ!$C$2:$C$451,"2026-09-14",データ!$A$2:$A$451,"高橋") -> 7
B23: 角張 | C23: =COUNTIFS(データ!$C$2:$C$451,"2026-09-14",データ!$A$2:$A$451,"角張") -> 1
B24: 計 | C24: =SUM(C21:C23) -> 17
B26: エリア別 | C26: 件数
B27: 岩手県 | C27: =COUNTIFS(データ!$C$2:$C$451,"2026-09-14",データ!$D$2:$D$451,"岩手県") -> 14
B28: 福島県 | C28: =COUNTIFS(データ!$C$2:$C$451,"2026-09-14",データ!$D$2:$D$451,"福島県") -> 3
B29: 計 | C29: =SUM(C27:C28) -> 17
B31: テーマ別 | C31: 件数
B32: 公会計 | C32: =COUNTIFS(データ!$C$2:$C$451,"2026-09-14",データ!$F$2:$F$451,"公会計") -> 8
B33: その他計画 | C33: =COUNTIFS(データ!$C$2:$C$451,"2026-09-14",データ!$F$2:$F$451,"その他計画") -> 4
B34: 福祉計画 | C34: =COUNTIFS(データ!$C$2:$C$451,"2026-09-14",データ!$F$2:$F$451,"福祉計画") -> 3
B35: 公共施設マネジメント | C35: =COUNTIFS(データ!$C$2:$C$451,"2026-09-14",データ!$F$2:$F$451,"公共施設マネジメント") -> 1
B36: 経営戦略 | C36: =COUNTIFS(データ!$C$2:$C$451,"2026-09-14",データ!$F$2:$F$451,"経営戦略") -> 1
B37: 計 | C37: =SUM(C32:C36) -> 17
B39: 状態別 | C39: 件数
B40: セカンドアプローチ | C40: =COUNTIFS(データ!$C$2:$C$451,"2026-09-14",データ!$L$2:$L$451,"セカンドアプローチ") -> 7
B41: 初回訪問 | C41: =COUNTIFS(データ!$C$2:$C$451,"2026-09-14",データ!$L$2:$L$451,"初回訪問") -> 5
B42: 見積提示 | C42: =COUNTIFS(データ!$C$2:$C$451,"2026-09-14",データ!$L$2:$L$451,"見積提示") -> 4
B43: 見積＋仕様書 | C43: =COUNTIFS(データ!$C$2:$C$451,"2026-09-14",データ!$L$2:$L$451,"見積＋仕様書") -> 1
B44: 計 | C44: =SUM(C40:C43) -> 17
B46: ※ 活動件数・各アクション件数は「データ」シートへの COUNTIFS。団体数／稼働者数／訪問日数は一意カウントのため生成時点の実数（青字）。
B47: ※ 1人1日件数＝活動件数÷訪問日数÷稼働者数。稼働者数の増減を除いた1人あたりの活動密度を見るための指標。
B48: ※ 今週（9/14週）は 9/14・9/15・9/16 の3日分のみ。週の途中であり、他週との単純比較はできない。

Sheet ②個人別案件数
B2: ② 個人ごとの案件数
B3: 活動件数＝ログ1行を1件として計上（同一団体でもテーマが異なれば別件）
B5: 入力者 | C5: 活動件数 | D5: 団体数 | E5: 訪問日数 | F5: 1日あたり 件数 | G5: 再アプローチ | H5: 見積提示 | I5: 同行依頼、 再訪 | J5: 再訪不要 | K5: 再訪不要率 | L5: 08/24週 | M5: 08/31週 | N5: 09/07週 | O5: 09/14週
B6: 林 | C6: =COUNTIFS(データ!$A$2:$A$451,"林") -> 108 | D6: 40 | E6: 30 | F6: =IFERROR(C6/E6,0) -> 3.6 | G6: =COUNTIFS(データ!$A$2:$A$451,"林",データ!$H$2:$H$451,"再アプローチ") -> 49 | H6: =COUNTIFS(データ!$A$2:$A$451,"林",データ!$H$2:$H$451,"見積提示") -> 1 | I6: =COUNTIFS(データ!$A$2:$A$451,"林",データ!$H$2:$H$451,"同行依頼、再訪") -> 17 | J6: =COUNTIFS(データ!$A$2:$A$451,"林",データ!$H$2:$H$451,"再訪不要") -> 36 | K6: =IFERROR(J6/SUM(G6:J6)*100,0) -> 34.951456 | L6: =COUNTIFS(データ!$A$2:$A$451,"林",データ!$C$2:$C$451,"2026-08-24") -> 1 | M6: =COUNTIFS(データ!$A$2:$A$451,"林",データ!$C$2:$C$451,"2026-08-31") -> 2 | N6: =COUNTIFS(データ!$A$2:$A$451,"林",データ!$C$2:$C$451,"2026-09-07") -> 0 | O6: =COUNTIFS(データ!$A$2:$A$451,"林",データ!$C$2:$C$451,"2026-09-14") -> 0
B7: 相澤 | C7: =COUNTIFS(データ!$A$2:$A$451,"相澤") -> 92 | D7: 42 | E7: 13 | F7: =IFERROR(C7/E7,0) -> 7.0769231 | G7: =COUNTIFS(データ!$A$2:$A$451,"相澤",データ!$H$2:$H$451,"再アプローチ") -> 74 | H7: =COUNTIFS(データ!$A$2:$A$451,"相澤",データ!$H$2:$H$451,"見積提示") -> 5 | I7: =COUNTIFS(データ!$A$2:$A$451,"相澤",データ!$H$2:$H$451,"同行依頼、再訪") -> 5 | J7: =COUNTIFS(データ!$A$2:$A$451,"相澤",データ!$H$2:$H$451,"再訪不要") -> 7 | K7: =IFERROR(J7/SUM(G7:J7)*100,0) -> 7.6923077 | L7: =COUNTIFS(データ!$A$2:$A$451,"相澤",データ!$C$2:$C$451,"2026-08-24") -> 33 | M7: =COUNTIFS(データ!$A$2:$A$451,"相澤",データ!$C$2:$C$451,"2026-08-31") -> 20 | N7: =COUNTIFS(データ!$A$2:$A$451,"相澤",データ!$C$2:$C$451,"2026-09-07") -> 9 | O7: =COUNTIFS(データ!$A$2:$A$451,"相澤",データ!$C$2:$C$451,"2026-09-14") -> 9
B8: 村田 | C8: =COUNTIFS(データ!$A$2:$A$451,"村田") -> 72 | D8: 40 | E8: 16 | F8: =IFERROR(C8/E8,0) -> 4.5 | G8: =COUNTIFS(データ!$A$2:$A$451,"村田",データ!$H$2:$H$451,"再アプローチ") -> 16 | H8: =COUNTIFS(データ!$A$2:$A$451,"村田",データ!$H$2:$H$451,"見積提示") -> 12 | I8: =COUNTIFS(データ!$A$2:$A$451,"村田",データ!$H$2:$H$451,"同行依頼、再訪") -> 0 | J8: =COUNTIFS(データ!$A$2:$A$451,"村田",データ!$H$2:$H$451,"再訪不要") -> 31 | K8: =IFERROR(J8/SUM(G8:J8)*100,0) -> 52.542373 | L8: =COUNTIFS(データ!$A$2:$A$451,"村田",データ!$C$2:$C$451,"2026-08-24") -> 8 | M8: =COUNTIFS(データ!$A$2:$A$451,"村田",データ!$C$2:$C$451,"2026-08-31") -> 34 | N8: =COUNTIFS(データ!$A$2:$A$451,"村田",データ!$C$2:$C$451,"2026-09-07") -> 10 | O8: =COUNTIFS(データ!$A$2:$A$451,"村田",データ!$C$2:$C$451,"2026-09-14") -> 0
B9: 角張 | C9: =COUNTIFS(データ!$A$2:$A$451,"角張") -> 37 | D9: 21 | E9: 6 | F9: =IFERROR(C9/E9,0) -> 6.1666667 | G9: =COUNTIFS(データ!$A$2:$A$451,"角張",データ!$H$2:$H$451,"再アプローチ") -> 27 | H9: =COUNTIFS(データ!$A$2:$A$451,"角張",データ!$H$2:$H$451,"見積提示") -> 3 | I9: =COUNTIFS(データ!$A$2:$A$451,"角張",データ!$H$2:$H$451,"同行依頼、再訪") -> 1 | J9: =COUNTIFS(データ!$A$2:$A$451,"角張",データ!$H$2:$H$451,"再訪不要") -> 4 | K9: =IFERROR(J9/SUM(G9:J9)*100,0) -> 11.428571 | L9: =COUNTIFS(データ!$A$2:$A$451,"角張",データ!$C$2:$C$451,"2026-08-24") -> 15 | M9: =COUNTIFS(データ!$A$2:$A$451,"角張",データ!$C$2:$C$451,"2026-08-31") -> 13 | N9: =COUNTIFS(データ!$A$2:$A$451,"角張",データ!$C$2:$C$451,"2026-09-07") -> 8 | O9: =COUNTIFS(データ!$A$2:$A$451,"角張",データ!$C$2:$C$451,"2026-09-14") -> 1
B10: 長戸 | C10: =COUNTIFS(データ!$A$2:$A$451,"長戸") -> 30 | D10: 14 | E10: 6 | F10: =IFERROR(C10/E10,0) -> 5 | G10: =COUNTIFS(データ!$A$2:$A$451,"長戸",データ!$H$2:$H$451,"再アプローチ") -> 17 | H10: =COUNTIFS(データ!$A$2:$A$451,"長戸",データ!$H$2:$H$451,"見積提示") -> 7 | I10: =COUNTIFS(データ!$A$2:$A$451,"長戸",データ!$H$2:$H$451,"同行依頼、再訪") -> 0 | J10: =COUNTIFS(データ!$A$2:$A$451,"長戸",データ!$H$2:$H$451,"再訪不要") -> 6 | K10: =IFERROR(J10/SUM(G10:J10)*100,0) -> 20 | L10: =COUNTIFS(データ!$A$2:$A$451,"長戸",データ!$C$2:$C$451,"2026-08-24") -> 4 | M10: =COUNTIFS(データ!$A$2:$A$451,"長戸",データ!$C$2:$C$451,"2026-08-31") -> 2 | N10: =COUNTIFS(データ!$A$2:$A$451,"長戸",データ!$C$2:$C$451,"2026-09-07") -> 0 | O10: =COUNTIFS(データ!$A$2:$A$451,"長戸",データ!$C$2:$C$451,"2026-09-14") -> 0
B11: 松田 | C11: =COUNTIFS(データ!$A$2:$A$451,"松田") -> 26 | D11: 19 | E11: 6 | F11: =IFERROR(C11/E11,0) -> 4.3333333 | G11: =COUNTIFS(データ!$A$2:$A$451,"松田",データ!$H$2:$H$451,"再アプローチ") -> 12 | H11: =COUNTIFS(データ!$A$2:$A$451,"松田",データ!$H$2:$H$451,"見積提示") -> 3 | I11: =COUNTIFS(データ!$A$2:$A$451,"松田",データ!$H$2:$H$451,"同行依頼、再訪") -> 0 | J11: =COUNTIFS(データ!$A$2:$A$451,"松田",データ!$H$2:$H$451,"再訪不要") -> 10 | K11: =IFERROR(J11/SUM(G11:J11)*100,0) -> 40 | L11: =COUNTIFS(データ!$A$2:$A$451,"松田",データ!$C$2:$C$451,"2026-08-24") -> 0 | M11: =COUNTIFS(データ!$A$2:$A$451,"松田",データ!$C$2:$C$451,"2026-08-31") -> 11 | N11: =COUNTIFS(データ!$A$2:$A$451,"松田",データ!$C$2:$C$451,"2026-09-07") -> 0 | O11: =COUNTIFS(データ!$A$2:$A$451,"松田",データ!$C$2:$C$451,"2026-09-14") -> 0
B12: 高橋 | C12: =COUNTIFS(データ!$A$2:$A$451,"高橋") -> 23 | D12: 18 | E12: 11 | F12: =IFERROR(C12/E12,0) -> 2.0909091 | G12: =COUNTIFS(データ!$A$2:$A$451,"高橋",データ!$H$2:$H$451,"再アプローチ") -> 14 | H12: =COUNTIFS(データ!$A$2:$A$451,"高橋",データ!$H$2:$H$451,"見積提示") -> 9 | I12: =COUNTIFS(データ!$A$2:$A$451,"高橋",データ!$H$2:$H$451,"同行依頼、再訪") -> 0 | J12: =COUNTIFS(データ!$A$2:$A$451,"高橋",データ!$H$2:$H$451,"再訪不要") -> 0 | K12: =IFERROR(J12/SUM(G12:J12)*100,0) -> 0 | L12: =COUNTIFS(データ!$A$2:$A$451,"高橋",データ!$C$2:$C$451,"2026-08-24") -> 5 | M12: =COUNTIFS(データ!$A$2:$A$451,"高橋",データ!$C$2:$C$451,"2026-08-31") -> 0 | N12: =COUNTIFS(データ!$A$2:$A$451,"高橋",データ!$C$2:$C$451,"2026-09-07") -> 3 | O12: =COUNTIFS(データ!$A$2:$A$451,"高橋",データ!$C$2:$C$451,"2026-09-14") -> 7
B13: 岡本 | C13: =COUNTIFS(データ!$A$2:$A$451,"岡本") -> 23 | D13: 15 | E13: 6 | F13: =IFERROR(C13/E13,0) -> 3.8333333 | G13: =COUNTIFS(データ!$A$2:$A$451,"岡本",データ!$H$2:$H$451,"再アプローチ") -> 6 | H13: =COUNTIFS(データ!$A$2:$A$451,"岡本",データ!$H$2:$H$451,"見積提示") -> 8 | I13: =COUNTIFS(データ!$A$2:$A$451,"岡本",データ!$H$2:$H$451,"同行依頼、再訪") -> 0 | J13: =COUNTIFS(データ!$A$2:$A$451,"岡本",データ!$H$2:$H$451,"再訪不要") -> 8 | K13: =IFERROR(J13/SUM(G13:J13)*100,0) -> 36.363636 | L13: =COUNTIFS(データ!$A$2:$A$451,"岡本",データ!$C$2:$C$451,"2026-08-24") -> 20 | M13: =COUNTIFS(データ!$A$2:$A$451,"岡本",データ!$C$2:$C$451,"2026-08-31") -> 3 | N13: =COUNTIFS(データ!$A$2:$A$451,"岡本",データ!$C$2:$C$451,"2026-09-07") -> 0 | O13: =COUNTIFS(データ!$A$2:$A$451,"岡本",データ!$C$2:$C$451,"2026-09-14") -> 0
B14: 吉野 | C14: =COUNTIFS(データ!$A$2:$A$451,"吉野") -> 19 | D14: 13 | E14: 8 | F14: =IFERROR(C14/E14,0) -> 2.375 | G14: =COUNTIFS(データ!$A$2:$A$451,"吉野",データ!$H$2:$H$451,"再アプローチ") -> 9 | H14: =COUNTIFS(データ!$A$2:$A$451,"吉野",データ!$H$2:$H$451,"見積提示") -> 8 | I14: =COUNTIFS(データ!$A$2:$A$451,"吉野",データ!$H$2:$H$451,"同行依頼、再訪") -> 1 | J14: =COUNTIFS(データ!$A$2:$A$451,"吉野",データ!$H$2:$H$451,"再訪不要") -> 0 | K14: =IFERROR(J14/SUM(G14:J14)*100,0) -> 0 | L14: =COUNTIFS(データ!$A$2:$A$451,"吉野",データ!$C$2:$C$451,"2026-08-24") -> 8 | M14: =COUNTIFS(データ!$A$2:$A$451,"吉野",データ!$C$2:$C$451,"2026-08-31") -> 0 | N14: =COUNTIFS(データ!$A$2:$A$451,"吉野",データ!$C$2:$C$451,"2026-09-07") -> 5 | O14: =COUNTIFS(データ!$A$2:$A$451,"吉野",データ!$C$2:$C$451,"2026-09-14") -> 0
B15: 若山 | C15: =COUNTIFS(データ!$A$2:$A$451,"若山") -> 17 | D15: 16 | E15: 1 | F15: =IFERROR(C15/E15,0) -> 17 | G15: =COUNTIFS(データ!$A$2:$A$451,"若山",データ!$H$2:$H$451,"再アプローチ") -> 2 | H15: =COUNTIFS(データ!$A$2:$A$451,"若山",データ!$H$2:$H$451,"見積提示") -> 0 | I15: =COUNTIFS(データ!$A$2:$A$451,"若山",データ!$H$2:$H$451,"同行依頼、再訪") -> 0 | J15: =COUNTIFS(データ!$A$2:$A$451,"若山",データ!$H$2:$H$451,"再訪不要") -> 0 | K15: =IFERROR(J15/SUM(G15:J15)*100,0) -> 0 | L15: =COUNTIFS(データ!$A$2:$A$451,"若山",データ!$C$2:$C$451,"2026-08-24") -> 15 | M15: =COUNTIFS(データ!$A$2:$A$451,"若山",データ!$C$2:$C$451,"2026-08-31") -> 0 | N15: =COUNTIFS(データ!$A$2:$A$451,"若山",データ!$C$2:$C$451,"2026-09-07") -> 0 | O15: =COUNTIFS(データ!$A$2:$A$451,"若山",データ!$C$2:$C$451,"2026-09-14") -> 0
B16: 計 | C16: =SUM(C6:C15) -> 447 | G16: =SUM(G6:G15) -> 226 | H16: =SUM(H6:H15) -> 56 | I16: =SUM(I6:I15) -> 24 | J16: =SUM(J6:J15) -> 102 | K16: =IFERROR(J16/SUM(G16:J16)*100,0) -> 25 | L16: =SUM(L6:L15) -> 109 | M16: =SUM(M6:M15) -> 85 | N16: =SUM(N6:N15) -> 35 | O16: =SUM(O6:O15) -> 17
B18: ※ 再訪不要率＝再訪不要÷（次回アクション記入分の合計）。アクション未記入の行は母数から除外。
B19: ※ 団体数・訪問日数は一意カウントのため生成時点の実数（青字）。活動件数・アクション別件数は COUNTIFS。
B20: ※ 入力者が未記入の行3件は本表の対象外。

Sheet ③再訪不要_要因分析
B2: ③ 再訪不要の件数と要因分析
B3: 要因は備考テキストのキーワード判定＋結果区分で自動分類（ロジックは activity_factor_rules.py）
B5: 全体像
B6: 指標 | C6: 件数 | D6: 構成比
B7: 活動ログ総件数 | C7: =COUNTA(データ!$A$2:$A$451) -> 450
B8: うち次回アクション記入 | C8: =COUNTA(データ!$H$2:$H$451)-COUNTIFS(データ!$H$2:$H$451,"(未記入)") -> 408
B9: 再訪不要 | C9: =COUNTIFS(データ!$H$2:$H$451,"再訪不要") -> 102 | D9: =IFERROR(C9/$C$8*100,0) -> 25 | E9: ← アクション記入分に対する比率
B10: 再アプローチ | C10: =COUNTIFS(データ!$H$2:$H$451,"再アプローチ") -> 226 | D10: =IFERROR(C10/$C$8*100,0) -> 55.392157
B11: 見積提示 | C11: =COUNTIFS(データ!$H$2:$H$451,"見積提示") -> 56 | D11: =IFERROR(C11/$C$8*100,0) -> 13.72549
B12: 同行依頼、再訪 | C12: =COUNTIFS(データ!$H$2:$H$451,"同行依頼、再訪") -> 24 | D12: =IFERROR(C12/$C$8*100,0) -> 5.8823529
B15: 要因別の内訳
B16: 要因 | C16: 件数 | D16: 構成比 | E16: 大分類
B17: 自前作成方針（庁内対応） | C17: =COUNTIFS(データ!$H$2:$H$451,"再訪不要",データ!$N$2:$N$451,"自前作成方針（庁内対応）") -> 37 | D17: =IFERROR(C17/$C$27*100,0) -> 36.27451 | E17: 自前作成方針（庁内対応）
B18: 他社受託：システム抱き合わせ | C18: =COUNTIFS(データ!$H$2:$H$451,"再訪不要",データ!$N$2:$N$451,"他社受託：システム抱き合わせ") -> 22 | D18: =IFERROR(C18/$C$27*100,0) -> 21.568627 | E18: 他社受託
B19: 他社受託：随契・委託継続 | C19: =COUNTIFS(データ!$H$2:$H$451,"再訪不要",データ!$N$2:$N$451,"他社受託：随契・委託継続") -> 14 | D19: =IFERROR(C19/$C$27*100,0) -> 13.72549 | E19: 他社受託
B20: 策定済み・改定時期が先 | C20: =COUNTIFS(データ!$H$2:$H$451,"再訪不要",データ!$N$2:$N$451,"策定済み・改定時期が先") -> 10 | D20: =IFERROR(C20/$C$27*100,0) -> 9.8039216 | E20: 策定済み・改定時期が先
B21: 必要性・意欲が低い | C21: =COUNTIFS(データ!$H$2:$H$451,"再訪不要",データ!$N$2:$N$451,"必要性・意欲が低い") -> 8 | D21: =IFERROR(C21/$C$27*100,0) -> 7.8431373 | E21: 必要性・意欲が低い
B22: 予算がつかない・否決 | C22: =COUNTIFS(データ!$H$2:$H$451,"再訪不要",データ!$N$2:$N$451,"予算がつかない・否決") -> 5 | D22: =IFERROR(C22/$C$27*100,0) -> 4.9019608 | E22: 予算がつかない・否決
B23: 他計画へ一体化・包含され単独案件消滅 | C23: =COUNTIFS(データ!$H$2:$H$451,"再訪不要",データ!$N$2:$N$451,"他計画へ一体化・包含され単独案件消滅") -> 3 | D23: =IFERROR(C23/$C$27*100,0) -> 2.9411765 | E23: 他計画へ一体化・包含され単独案件消滅
B24: 要因不明（備考・結果とも未記入） | C24: =COUNTIFS(データ!$H$2:$H$451,"再訪不要",データ!$N$2:$N$451,"要因不明（備考・結果とも未記入）") -> 1 | D24: =IFERROR(C24/$C$27*100,0) -> 0.98039216 | E24: 要因不明（備考・結果とも未記入）
B25: 他社受託：入札実績要件で参入不可 | C25: =COUNTIFS(データ!$H$2:$H$451,"再訪不要",データ!$N$2:$N$451,"他社受託：入札実績要件で参入不可") -> 1 | D25: =IFERROR(C25/$C$27*100,0) -> 0.98039216 | E25: 他社受託
B26: 庁内事情・外部要因による遅延 | C26: =COUNTIFS(データ!$H$2:$H$451,"再訪不要",データ!$N$2:$N$451,"庁内事情・外部要因による遅延") -> 1 | D26: =IFERROR(C26/$C$27*100,0) -> 0.98039216 | E26: 庁内事情・外部要因による遅延
B27: 計 | C27: =SUM(C17:C26) -> 102 | D27: =IFERROR(C27/C27*100,0) -> 100
B30: 属性別の再訪不要率（どこで案件が落ちているか）
B31: 結果 | C31: 再訪不要 | D31: 全件数 | E31: 再訪不要率
B32: 自力 | C32: =COUNTIFS(データ!$H$2:$H$451,"再訪不要",データ!$G$2:$G$451,"自力") -> 46 | D32: =COUNTIFS(データ!$G$2:$G$451,"自力") -> 99 | E32: =IFERROR(C32/D32*100,0) -> 46.464646
B33: 他社随契 | C33: =COUNTIFS(データ!$H$2:$H$451,"再訪不要",データ!$G$2:$G$451,"他社随契") -> 15 | D33: =COUNTIFS(データ!$G$2:$G$451,"他社随契") -> 50 | E33: =IFERROR(C33/D33*100,0) -> 30
B34: その他 | C34: =COUNTIFS(データ!$H$2:$H$451,"再訪不要",データ!$G$2:$G$451,"その他") -> 9 | D34: =COUNTIFS(データ!$G$2:$G$451,"その他") -> 97 | E34: =IFERROR(C34/D34*100,0) -> 9.2783505
B35: 見積提示 | C35: =COUNTIFS(データ!$H$2:$H$451,"再訪不要",データ!$G$2:$G$451,"見積提示") -> 1 | D35: =COUNTIFS(データ!$G$2:$G$451,"見積提示") -> 29 | E35: =IFERROR(C35/D35*100,0) -> 3.4482759
B36: 不在 | C36: =COUNTIFS(データ!$H$2:$H$451,"再訪不要",データ!$G$2:$G$451,"不在") -> 0 | D36: =COUNTIFS(データ!$G$2:$G$451,"不在") -> 33 | E36: =IFERROR(C36/D36*100,0) -> 0
B37: (未記入) | C37: =COUNTIFS(データ!$H$2:$H$451,"再訪不要",データ!$G$2:$G$451,"(未記入)") -> 31 | D37: =COUNTIFS(データ!$G$2:$G$451,"(未記入)") -> 142 | E37: =IFERROR(C37/D37*100,0) -> 21.830986
B38: 計 | C38: =SUM(C32:C37) -> 102 | D38: =SUM(D32:D37) -> 450 | E38: =IFERROR(C38/D38*100,0) -> 22.666667
B40: 状態 | C40: 再訪不要 | D40: 全件数 | E40: 再訪不要率
B41: 初回訪問 | C41: =COUNTIFS(データ!$H$2:$H$451,"再訪不要",データ!$L$2:$L$451,"初回訪問") -> 35 | D41: =COUNTIFS(データ!$L$2:$L$451,"初回訪問") -> 111 | E41: =IFERROR(C41/D41*100,0) -> 31.531532
B42: セカンドアプローチ | C42: =COUNTIFS(データ!$H$2:$H$451,"再訪不要",データ!$L$2:$L$451,"セカンドアプローチ") -> 17 | D42: =COUNTIFS(データ!$L$2:$L$451,"セカンドアプローチ") -> 162 | E42: =IFERROR(C42/D42*100,0) -> 10.493827
B43: 見積提示 | C43: =COUNTIFS(データ!$H$2:$H$451,"再訪不要",データ!$L$2:$L$451,"見積提示") -> 1 | D43: =COUNTIFS(データ!$L$2:$L$451,"見積提示") -> 32 | E43: =IFERROR(C43/D43*100,0) -> 3.125
B44: 見積＋仕様書 | C44: =COUNTIFS(データ!$H$2:$H$451,"再訪不要",データ!$L$2:$L$451,"見積＋仕様書") -> 0 | D44: =COUNTIFS(データ!$L$2:$L$451,"見積＋仕様書") -> 12 | E44: =IFERROR(C44/D44*100,0) -> 0
B45: (未記入) | C45: =COUNTIFS(データ!$H$2:$H$451,"再訪不要",データ!$L$2:$L$451,"(未記入)") -> 49 | D45: =COUNTIFS(データ!$L$2:$L$451,"(未記入)") -> 133 | E45: =IFERROR(C45/D45*100,0) -> 36.842105
B46: 計 | C46: =SUM(C41:C45) -> 102 | D46: =SUM(D41:D45) -> 450 | E46: =IFERROR(C46/D46*100,0) -> 22.666667
B48: テーマ | C48: 再訪不要 | D48: 全件数 | E48: 再訪不要率
...

Sheet ④再訪不要_明細
B2: ④ 再訪不要 明細（要因判定の検証用）
B3: 要因の自動判定が実態と合わない行は、この明細で確認して activity_factor_rules.py のルールを調整する。
B5: 入力者 | C5: 訪問日 | D5: エリア | E5: 団体名 | F5: テーマ | G5: 結果 | H5: 要因 | I5: 備考
B6: 松田 | C6: 46253 | D6: 秋田県 | E6: 小坂町 | F6: 公会計 | G6: 他社随契 | H6: 他社受託：随契・委託継続 | I6: ・以前訪問時に再度プロポ実施し、変更するかもと言っていた。・来年度も随契とのこと。来年度担当者変更があれば、入札に持っていく。
B7: 松田 | C7: 46253 | D7: 秋田県 | E7: 小坂町 | F7: 福祉計画 | G7: その他 | H7: 策定済み・改定時期が先 | I7: ・こども計画策定済み・R11までのため、R9～10にアプローチを行う。
B8: 相澤 | C8: 46252 | D8: 岩手県 | E8: 二戸市 | F8: その他計画 | G8: 自力 | H8: 自前作成方針（庁内対応） | I8: 今年度自前作成
B9: 相澤 | C9: 46252 | D9: 岩手県 | E9: 二戸地区広域行政事務組合 | F9: その他計画 | G9: 他社随契 | H9: 他社受託：システム抱き合わせ | I9: ぎょうせい随契
B10: 相澤 | C10: 46252 | D10: 岩手県 | E10: 葛巻町 | F10: 公共施設マネジメント | G10: 他社随契 | H10: 他社受託：随契・委託継続 | I10: 今年度改訂
B11: 相澤 | C11: 46252 | D11: 岩手県 | E11: 岩泉町 | F11: その他計画 | G11: 他社随契 | H11: 策定済み・改定時期が先 | I11: R6こども計画策定済み。
B12: 相澤 | C12: 46252 | D12: 岩手県 | E12: 九戸村 | F12: 公共施設マネジメント | G12: 他社随契 | H12: 他社受託：随契・委託継続 | I12: 昨年、委託にて個別施設計画改訂。セミナー案内
B13: 松田 | C13: 46254 | D13: 秋田県 | E13: 秋田県後期高齢者医療広域連合 | F13: 公会計 | G13: 見積提示 | H13: 要因不明（備考・結果とも未記入） | I13: 今年度当社契約
B14: 松田 | C14: 46253 | D14: 秋田県 | E14: 大館市 | F14: 公共施設マネジメント | G14: 自力 | H14: 自前作成方針（庁内対応） | I14: セミナー参加自治体。自前作成を継続している自治体。基本的に自前での作成を実施している。
B15: 松田 | C15: 46255 | D15: 秋田県 | E15: 三種町 | F15: 経営戦略 | G15: 他社随契 | H15: 他社受託：随契・委託継続 | I15: 委託済みのため、改定時期に提案。HPに掲載後、戦略の確認を実施する。
B16: 相澤 | C16: 46259 | D16: 岩手県 | E16: 山田町 | F16: その他計画 | G16: 他社随契 | H16: 他計画へ一体化・包含され単独案件消滅 | I16: R7こども計画に統合済み。
B17: 長戸 | C17: 46253 | D17: 北海道 | E17: 小樽市 | F17: 公会計 | G17: 自力 | H17: 自前作成方針（庁内対応） | I17: セミナーパンフ配布
B18: 長戸 | C18: 46253 | D18: 北海道 | E18: 小樽市 | F18: 公共施設マネジメント | G18: 自力 | H18: 自前作成方針（庁内対応）
B19: 長戸 | C19: 46253 | D19: 北海道 | E19: 余市町 | F19: 公共施設マネジメント | G19: 自力 | H19: 自前作成方針（庁内対応） | I19: 公表されているものはガイドラインを満たしていないが 手引きを別に作っており、合算して計画として有効性を持たせている。 道に確認をして了承を得ている。 まだ時期は未定だが、庁舎の建て替え案も出ており、その際に 計画見直しを検討している。セミナーパンフ配布。
B20: 長戸 | C20: 46254 | D20: 北海道 | E20: 厚沢部町 | F20: 社会生活計画 | G20: その他 | H20: 策定済み・改定時期が先 | I20: 策定済。起債利用し、エアコン購入やＬＥＤ照明入れ替えを実施中とのこと。
B21: 岡本 | C21: 46259 | D21: 青森県 | E21: 外ヶ浜町 | F21: その他計画 | G21: (未記入) | H21: 必要性・意欲が低い | I21: 改定時期の国要領に留意し、基本は前回数値の置き換えで行っているため、委託等の必要性を感じていないとのことでした。
B22: 岡本 | C22: 46259 | D22: 青森県 | E22: 蓬田村 | F22: 経営改善 | G22: (未記入) | H22: 必要性・意欲が低い | I22: 料金・使用料改定の検討状況について聴き取り。当面は考えていないが、必要性は感じている。次期経営戦略改定に合わせて検討したいとのこと。合間を見て訪問し、状況を確認します。
B23: 岡本 | C23: 46260 | D23: 青森県 | E23: 中泊町 | F23: その他計画 | G23: (未記入) | H23: 他社受託：随契・委託継続 | I23: こども計画については時期子ども子育て支援計画改定時期まで近隣の様子を見るとのこと。大規模な子供施設の更新等もなく、早期の策定は考えていない。なお、子ども子育て支援計画は入札で冨士商事に300万円程度で委託したとのことです。
B24: 岡本 | C24: 46260 | D24: 青森県 | E24: 中泊町 | F24: その他計画 | G24: (未記入) | H24: 自前作成方針（庁内対応） | I24: 文化財活用計画 国指定の文化財について、今年度採択され、第1期の計画を自前（有識者の協力有）策定中とのこと。改定時に参画できるよう関係性を構築していきます。
B25: 岡本 | C25: 46260 | D25: 青森県 | E25: 五所川原市 | F25: その他計画 | G25: (未記入) | H25: 必要性・意欲が低い | I25: 環境基本計画 現状温暖化対策計画があり、地方債などの財政措置も受けており、改めて上位計画を立てる予定はない。ただし、努力義務から義務規定に代わる場合は策定する。
B26: 岡本 | C26: 46260 | D26: 青森県 | E26: 板柳町 | F26: 公会計 | G26: 他社随契 | H26: 他社受託：随契・委託継続 | I26: 辻本郷と随契。業者切替も考えていないとの個ですので、次回訪問は無し。ただし、助教変化もあり得るので、毎年確認します。
B27: 林 | C27: 46254 | D27: 北海道 | E27: 美幌町 | F27: 福祉計画 | G27: 自力 | H27: 他計画へ一体化・包含され単独案件消滅 | I27: こども計画として一体策定。中間見直し予定。課内協議実施のうえ委託の意思なし。
B28: 林 | C28: 46184 | D28: 北海道 | E28: 津別町 | F28: 公会計 | G28: 自力 | H28: 必要性・意欲が低い | I28: 熱心でない
B29: 林 | C29: 46184 | D29: 北海道 | E29: 津別町 | F29: 公会計 | G29: 自力 | H29: 必要性・意欲が低い | I29: 認知はしているものの、罰則ないため未実施
B30: 林 | C30: 46184 | D30: 北海道 | E30: 小清水町 | F30: 福祉計画 | G30: (未記入) | H30: 他社受託：随契・委託継続 | I30: 直近3期とも随意契約にて他社へ委託。社名は教えてもらえず
... B54: 林 | C54: 46190 | D54: 北海道 | E54: 弟子屈町 | F54: 会計支援 | G54: (未記入) | H54: 自前作成方針（庁内対応） | I54: 担当者経歴長く、自前作成
B55: 村田 | C55: 46261 | D55: 北海道 | E55: 平取町 | F55: 社会生活計画 | G55: 自力 | H55: 自前作成方針（庁内対応）
B56: 村田 | C56: 46261 | D56: 北海道 | E56: 新ひだか町 | F56: 社会生活計画 | G56: 自力 | H56: 自前作成方針（庁内対応）
B57: 村田 | C57: 46261 | D57: 北海道 | E57: 浦河町 | F57: 社会生活計画 | G57: 自力 | H57: 策定済み・改定時期が先 | I57: R4期限切れ。今まで自前。
B58: 林 | C58: 46134 | D58: 北海道 | E58: 弟子屈町 | F58: 福祉計画 | G58: (未記入) | H58: 他社受託：システム抱き合わせ | I58: MJSに随契で委託。
B59: 林 | C59: 46100 | D59: 北海道 | E59: 別海町 | F59: 福祉計画 | G59: (未記入) | H59: 他社受託：システム抱き合わせ | I59: ぎょうせい委託
B60: 林 | C60: 46252 | D60: 北海道 | E60: 別海町 | F60: 福祉計画 | G60: (未記入) | H60: 他社受託：システム抱き合わせ | I60: こども計画策定済。ぎょうせいとサーベイの入札のため実績要件が入っていた可能性有
B61: 林 | C61: 46139 | D61: 北海道 | E61: 中標津町 | F61: 公共施設マネジメント | G61: (未記入) | H61: 予算がつかない・否決 | I61: 予算否決につき今年度自前改定。
B62: 林 | C62: 46190 | D62: 北海道 | E62: 中標津町 | F62: 福祉計画 | G62: 他社随契 | H62: 他社受託：システム抱き合わせ | I62: ぎょうせいへ委託済
B63: 林 | C63: 46190 | D63: 北海道 | E63: 標津町 | F63: 公会計 | G63: 他社随契 | H63: 他社受託：システム抱き合わせ | I63: 行政研負担金
B64: 林 | C64: 46225 | D64: 北海道 | E64: 標津町 | F64: 会計支援 | G64: 他社随契 | H64: 他社受託：システム抱き合わせ | I64: 役場内全体で行政研システムを使用しており、保守料の中で会計支援、消費税監査を実施。
B65: 林 | C65: 46190 | D65: 北海道 | E65: 根室北部消防事務組合 | F65: 公会計 | G65: 他社随契 | H65: 他社受託：システム抱き合わせ | I65: オーレンス会計事務所にてシステム保守とともに委託。
...

Sheet ⑤北海道_活動停止要因
B2: ⑤ 北海道の活動が止まっている要因
B3: 活動ログで特定できるのは「いつ・何が」まで。「なぜ」は営業会議ブックの構造要因と突き合わせた推論を含む。支持度欄を参照。
B5: 1. 止まったのは北海道だけではない（移動圏単位で揃っている）
B6: 移動圏 | C6: 08/17週 | D6: 08/24週 | E6: 08/31週 | F6: 09/07週 | G6: 09/14週 | H6: 最終活動日
B7: 北海道 | C7: =COUNTIFS(データ!$O$2:$O$451,"北海道",データ!$C$2:$C$451,"2026-08-17") -> 62 | D7: =COUNTIFS(データ!$O$2:$O$451,"北海道",データ!$C$2:$C$451,"2026-08-24") -> 23 | E7: =COUNTIFS(データ!$O$2:$O$451,"北海道",データ!$C$2:$C$451,"2026-08-31") -> 38 | F7: =COUNTIFS(データ!$O$2:$O$451,"北海道",データ!$C$2:$C$451,"2026-09-07") -> 15 | G7: =COUNTIFS(データ!$O$2:$O$451,"北海道",データ!$C$2:$C$451,"2026-09-14") -> 0 | H7: 46275
B8: 北東北 | C8: =COUNTIFS(データ!$O$2:$O$451,"北東北",データ!$C$2:$C$451,"2026-08-17") -> 15 | D8: =COUNTIFS(データ!$O$2:$O$451,"北東北",データ!$C$2:$C$451,"2026-08-24") -> 28 | E8: =COUNTIFS(データ!$O$2:$O$451,"北東北",データ!$C$2:$C$451,"2026-08-31") -> 14 | F8: =COUNTIFS(データ!$O$2:$O$451,"北東北",データ!$C$2:$C$451,"2026-09-07") -> 0 | G8: =COUNTIFS(データ!$O$2:$O$451,"北東北",データ!$C$2:$C$451,"2026-09-14") -> 0 | H8: 46269
B9: 南東北・岩手 | C9: =COUNTIFS(データ!$O$2:$O$451,"南東北・岩手",データ!$C$2:$C$451,"2026-08-17") -> 24 | D9: =COUNTIFS(データ!$O$2:$O$451,"南東北・岩手",データ!$C$2:$C$451,"2026-08-24") -> 58 | E9: =COUNTIFS(データ!$O$2:$O$451,"南東北・岩手",データ!$C$2:$C$451,"2026-08-31") -> 33 | F9: =COUNTIFS(データ!$O$2:$O$451,"南東北・岩手",データ!$C$2:$C$451,"2026-09-07") -> 20 | G9: =COUNTIFS(データ!$O$2:$O$451,"南東北・岩手",データ!$C$2:$C$451,"2026-09-14") -> 17 | H9: 46281
B11: → 北東北（青森・秋田）は9/07週から、北海道は9/14週からゼロ。南東北・岩手の3名（相澤・角張・高橋）のみ継続。個人の問題ではなく圏単位で止まっている。
B13: 2. 北海道担当4名の最終活動（営業会議ブック J162「※基本は長戸・村田・林・吉野」）
B14: 担当者 | C14: 活動件数 | D14: 最終活動日 | E14: 経過日数 | F14: 最終日の件数 | G14: 最終日のアクション
B15: 長戸 | C15: =COUNTIFS(データ!$A$2:$A$451,"長戸",データ!$O$2:$O$451,"北海道") -> 30 | D15: 46266 | E15: 16 | F15: 2 | G15: 見積提示2件
B16: 村田 | C16: =COUNTIFS(データ!$A$2:$A$451,"村田",データ!$O$2:$O$451,"北海道") -> 72 | D16: 46275 | E16: 7 | F16: 2 | G16: 見積提示1件／再訪不要1件
B17: 林 | C17: =COUNTIFS(データ!$A$2:$A$451,"林",データ!$O$2:$O$451,"北海道") -> 108 | D17: 46268 | E17: 14 | F17: 2 | G17: 再アプローチ2件
B18: 吉野 | C18: =COUNTIFS(データ!$A$2:$A$451,"吉野",データ!$O$2:$O$451,"北海道") -> 19 | D18: 46275 | E18: 7 | F18: 3 | G18: 見積提示2件／再アプローチ1件
B20: → 4名とも最終記録は「見積提示」または「再アプローチ」。投げ出しではなく、訪問から見積・提案フェーズへ移った形で記録が途絶えている。
B22: 3. 北海道と東北の違い（なぜ北海道から先に枯れたか）
B23: 指標 | C23: 北海道 | D23: 東北 | E23: 単位 | F23: 出所 | H23: 読み方
B24: 活動件数 | C24: =COUNTIFS(データ!$O$2:$O$451,"北海道") -> 231 | D24: =COUNTIFS(データ!$O$2:$O$451,"北東北")+COUNTIFS(データ!$O$2:$O$451,"南東北・岩手") -> 216 | E24: 件 | F24: 活動ログ | H24: 母数はほぼ同等。活動量そのものの差ではない
B25: 訪問済み団体数 | C25: 108 | D25: 120 | E25: 団体 | F25: 活動ログ | H25: 北海道108／道内179自治体（60%）。未訪問は約71団体残っている
B26: 再訪不要 | C26: =COUNTIFS(データ!$O$2:$O$451,"北海道",データ!$H$2:$H$451,"再訪不要") -> 73 | D26: =COUNTIFS(データ!$O$2:$O$451,"北東北",データ!$H$2:$H$451,"再訪不要")+COUNTIFS(データ!$O$2:$O$451,"南東北・岩手",データ!$H$2:$H$451,"再訪不要") -> 29 | E26: 件 | F26: 活動ログ
B27: 再訪不要率（対 活動件数） | C27: =IFERROR(C26/C24*100,0) -> 31.601732 | D27: =IFERROR(D26/D24*100,0) -> 13.425926 | E27: % | F27: 活動ログ | H27: 北海道は3件に1件が案件化せず終了。東北の2.4倍
B28: 残パイプライン（再アプローチ＋同行依頼） | C28: =COUNTIFS(データ!$O$2:$O$451,"北海道",データ!$H$2:$H$451,"再アプローチ")+COUNTIFS(データ!$O$2:$O$451,"北海道",データ!$H$2:$H$451,"同行依頼、再訪") -> 109 | D28: =COUNTIFS(データ!$O$2:$O$451,"北東北",データ!$H$2:$H$451,"再アプローチ")+COUNTIFS(データ!$O$2:$O$451,"北東北",データ!$H$2:$H$451,"同行依頼、再訪")+COUNTIFS(データ!$O$2:$O$451,"南東北・岩手",データ!$H$2:$H$451,"再アプローチ")+COUNTIFS(データ!$O$2:$O$451,"南東北・岩手",データ!$H$2:$H$451,"同行依頼、再訪") -> 141 | E28: 件 | F28: 活動ログ | H28: 次がある前提の案件。件数では東北のほうが多い
B29: うちアプローチ時期＝今年度 | C29: =COUNTIFS(データ!$O$2:$O$451,"北海道",データ!$H$2:$H$451,"再アプローチ",データ!$K$2:$K$451,"今年度")+COUNTIFS(データ!$O$2:$O$451,"北海道",データ!$H$2:$H$451,"同行依頼、再訪",データ!$K$2:$K$451,"今年度") -> 44 | D29: =COUNTIFS(データ!$O$2:$O$451,"北東北",データ!$H$2:$H$451,"再アプローチ",データ!$K$2:$K$451,"今年度")+COUNTIFS(データ!$O$2:$O$451,"北東北",データ!$H$2:$H$451,"同行依頼、再訪",データ!$K$2:$K$451,"今年度")+COUNTIFS(データ!$O$2:$O$451,"南東北・岩手",データ!$H$2:$H$451,"再アプローチ",データ!$K$2:$K$451,"今年度")+COUNTIFS(データ!$O$2:$O$451,"南東北・岩手",データ!$H$2:$H$451,"同行依頼、再訪",データ!$K$2:$K$451,"今年度") -> 93 | E29: 件 | F29: 活動ログ | H29: 今すぐ訪ねる理由のある案件。北海道は残パイプの40%、東北は66%
B30: アプローチ時期＝再来年度 | C30: =COUNTIFS(データ!$O$2:$O$451,"北海道",データ!$K$2:$K$451,"再来年度") -> 31 | D30: =COUNTIFS(データ!$O$2:$O$451,"北東北",データ!$K$2:$K$451,"再来年度")+COUNTIFS(データ!$O$2:$O$451,"南東北・岩手",データ!$K$2:$K$451,"再来年度") -> 13 | E30: 件 | F30: 活動ログ | H30: 先送り案件。北海道に偏って積み上がっている
B31: 見積提示済（今期分） | C31: 1 | D31: 2 | E31: 件 | F31: 会議ブック | G31: H172 | H31: 成果が今期に落ちていない
B32: 見積提示済（来期分） | C32: 44 | D32: 57 | E32: 件 | F32: 会議ブック | G32: I172 | H32: 北海道の成果は44件すべて来期。今期に刈る玉がない
B33: 9月入札見込 | C33: 3 | D33: 3 | E33: 件 | F33: 会議ブック | G33: E63
B34: 9月入札確定 | C34: 0 | D34: 1 | E34: 件 | F34: 会議ブック | G34: E64 | H34: 北海道は9月の確定ゼロ。5〜8月は毎月2〜4件確定していた
B35: 公会計 現状件数（納品） | C35: 138 | D35: 75 | E35: 件 | F35: 会議ブック | G35: E240 | H35: 全国最多。納品側の母数が大きい
B36: 固定資産台帳 精緻化 | C36: 39 | D36: 11 | E36: 件 | F36: 会議ブック | G36: E259 | H36: 全国55件中39件が北海道。9月決算期の作業負荷が集中
B37: 会計支援 対象 | C37: 29 | D37: 24 | E37: 件 | F37: 会議ブック | G37: D270
B38: うち決算報告書 | C38: 10 | D38: 6 | E38: 件 | F38: 会議ブック | G38: I270 | H38: 9月は自治体の決算期。納品と営業が同じ人員なら営業は後回しになる
B40: ※ 「会議ブック」出所の値は営業会議ブック 20260904㉜ からの転記（青字）。G列に参照セルを記載。
B42: 4. 要因の候補と根拠
B43: 要因 | C43: データでの支持度 | E43: 根拠
B44: ① 今期に動かせる案件の枯渇 | C44: 強い（ログ・会議ブック双方が一致） | E44: 残パイプ109件中 今年度分は44件（40%）。東北は141件中93件（66%）。再来年度案件19件が北海道に偏在。8/31週は38件訪問して22件（57.9%）が再訪不要。会議ブックでも見積提示済は今期1件・来期44件、9月入札は見込3件→確定0件。
B45: ② 納品業務のピークと人員の重複 | C45: 中（構造は事実／投入の直接記録はなし） | E45: 9月は自治体の決算期。北海道は公会計138件・精緻化39件（全国55件の7割）・決算報告書10件を抱え全国最多。札幌14名で最大拠点だが採用は一旦中止。営業と納品を同じ人員が担う場合、9月は納品が優先される。
B46: ③ 広域ゆえの移動コスト | C46: 中（効率差はログで確認できる） | E46: 1実訪問日あたり 北海道2.4団体 vs 南東北・岩手3.9団体。未訪問の約71団体は道内に散在。今期案件が薄い先へ長距離移動する費用対効果は低く、①と重なって足が止まる。
B47: ④ テーマ構成の偏り | C47: 中（ログで確認できる） | E47: 北海道は福祉計画が71件（31%）で東北11件（5%）と大きく異なる。福祉計画は全体でも再訪不要率28%と高く、自前作成・他計画への一体化が起きやすい領域。
B48: ⑤ セミナー準備 | C48: 弱い（時期は一致するが担当が合わない） | E48: 全国セミナーは9/25〜10/23開催、テキスト期限9/18〜9/22で今週が締切直前。ただし講師は川崎・北城・南澤・若山・山田・さいとう/おの・大窪で、北海道担当4名（長戸・村田・林・吉野）は含まれない。若山の停止（最終8/24）は説明できる。
...

Sheet 前提・注記
B2: 前提・出所・注記
B4: 元データ | C4: 訪問活動ログ（Book1.xlsx／シート「query」）450行。SharePointリストの書き出しと見られ、1行＝1団体1テーマの接触記録。
B5: 期間 | C5: 訪問日 2026/03/19〜2026/09/16（欠損8件）。8/17週より入力者が7〜9名に増え、それ以前は実質1〜2名のみの記録。したがって8月以前との時系列比較はできない。
B6: 「今週」の定義 | C6: 月曜起算で 2026/09/14〜。基準日 2026/09/17（木）時点の最終入力は 9/16 で、9/14・9/15・9/16 の3日分のみ。週の途中の数値である。
B7: 案件数の数え方 | C7: ログ1行を1件として計上。同一団体でもテーマが異なれば別件。団体数は重複を除いた実数を併記している。
B8: 要因分類の方法 | C8: 備考テキストのキーワード判定を優先し、該当しない場合は結果区分（自力→自前作成方針、他社随契→他社受託、不在→接触不可）で補完。判定ロジックは activity_factor_rules.py に切り出しており、「④再訪不要 明細」で1件ずつ検証・調整できる。102件中101件を分類、1件は備考・結果とも未記入。
B9: システム抱き合わせの判定 | C9: 備考に 行政研／ぎょうせい／TKC／MJS／アチカ／オーレンス、または「システム保守」「保守範囲」等が現れる行。会計システムの保守料の中で会計支援・消費税監査まで提供されており、「切替の意思なし」と記録されているケース。
B10: データ品質（未記入） | C10: 結果 142件 契約予定 386件 状態 133件 アプローチ時期 152件 前回策定 177件。結果・契約予定の未記入が多く、受注確度の定量評価には使えない。再訪不要率の母数は「次回アクション」記入分に限定している。
B11: 集計方式 | C11: すべての件数は「データ」シートへの COUNTIFS。元データを差し替えれば全シートが再計算される。ただし団体数・稼働者数・訪問日数は一意カウントのため生成時点の実数を青字で埋め込んでいる。
B12: 色の意味 | C12: 青字＝元データからの転記値および一意カウントの実数／黒字＝本ブックの計算式。

Sheet データ
A1: 入力者 | B1: 訪問日 | C1: 週ラベル | D1: エリア | E1: 団体名 | F1: テーマ | G1: 結果 | H1: 次回アクション | I1: 前回策定 | J1: 改定時期 | K1: アプローチ時期 | L1: 状態 | M1: 契約予定 | N1: 要因 | O1: 圏 | P1: 備考
A2: 松田 | B2: 46253 | C2: 2026-08-17 | D2: 秋田県 | E2: 小坂町 | F2: 経営改善 | G2: 不在 | H2: 再アプローチ | I2: (未記入) | J2: (未記入) | K2: (未記入) | L2: (未記入) | M2: (未記入) | O2: 北東北 | P2: ・セミナー案内を配布
A3: 松田 | B3: 46253 | C3: 2026-08-17 | D3: 秋田県 | E3: 小坂町 | F3: 公会計 | G3: 他社随契 | H3: 再訪不要 | I3: (未記入) | J3: (未記入) | K3: (未記入) | L3: (未記入) | M3: (未記入) | N3: 他社受託：随契・委託継続 | O3: 北東北 | P3: ・以前訪問時に再度プロポ実施し、変更するかもと言っていた。・来年度も随契とのこと。来年度担当者変更があれば、入札に持っていく。
A4: 松田 | B4: 46253 | C4: 2026-08-17 | D4: 秋田県 | E4: 小坂町 | F4: 福祉計画 | G4: その他 | H4: 再訪不要 | I4: (未記入) | J4: (未記入) | K4: (未記入) | L4: (未記入) | M4: (未記入) | N4: 策定済み・改定時期が先 | O4: 北東北 | P4: ・こども計画策定済み・R11までのため、R9～10にアプローチを行う。
A5: 若山 | B5: 46258 | C5: 2026-08-24 | D5: 福島県 | E5: 二本松市 | F5: 会計支援 | G5: (未記入) | H5: (未記入) | I5: (未記入) | J5: (未記入) | K5: (未記入) | L5: (未記入) | M5: 見積合わせ | O5: 南東北・岩手
A6: 若山 | C6: (未記入) | D6: 福島県 | E6: 猪苗代町 | F6: 会計支援 | G6: (未記入) | H6: (未記入) | I6: (未記入) | J6: (未記入) | K6: (未記入) | L6: (未記入) | M6: 見積合わせ | O6: 南東北・岩手
A7: 若山 | B7: 46258 | C7: 2026-08-24 | D7: 福島県 | E7: 下郷町 | F7: 会計支援 | G7: (未記入) | H7: (未記入) | I7: (未記入) | J7: (未記入) | K7: (未記入) | L7: (未記入) | M7: 随契 | O7: 南東北・岩手
A8: 若山 | B8: 46258 | C8: 2026-08-24 | D8: 宮城県 | E8: 女川町 | F8: 会計支援 | G8: (未記入) | H8: 再アプローチ | I8: (未記入) | J8: (未記入) | K8: (未記入) | L8: (未記入) | M8: 見積合わせ | O8: 南東北・岩手
A9: 若山 | B9: 46258 | C9: 2026-08-24 | D9: 青森県 | E9: 階上町 | F9: 会計支援 | G9: 見積提示 | H9: 再アプローチ | I9: 委託 | J9: R9 | K9: 今年度 | L9: 見積＋仕様書 | M9: 入札 | O9: 北東北
A10: 角張 | B10: 46258 | C10: 2026-08-24 | D10: 山形県 | E10: 山形市 | F10: 公会計 | G10: 他社随契 | H10: 再アプローチ | I10: 委託 | J10: R9 | K10: 今年度 | L10: セカンドアプローチ | M10: (未記入) | O10: 南東北・岩手 | P10: 今年度EY新日本随契。R9改定時期ですのでアプローチかけます。
A11: 角張 | B11: 46258 | C11: 2026-08-24 | D11: 山形県 | E11: 天童市 | F11: 福祉計画 | G11: 自力 | H11: 再アプローチ | I11: 自前 | J11: R9 | K11: 今年度 | L11: セカンドアプローチ | M11: (未記入) | O11: 南東北・岩手 | P11: 自前作成。（予算取れれば委託検討）
A12: 若山 | B12: 46258 | C12: 2026-08-24 | D12: 青森県 | E12: 板柳町 | F12: 会計支援 | G12: (未記入) | H12: (未記入) | I12: (未記入) | J12: (未記入) | K12: (未記入) | L12: (未記入) | M12: 入札 | O12: 北東北
A13: 若山 | B13: 46258 | C13: 2026-08-24 | D13: 青森県 | E13: 六戸町 | F13: 会計支援 | G13: (未記入) | H13: (未記入) | I13: (未記入) | J13: (未記入) | K13: (未記入) | L13: (未記入) | M13: 随契 | O13: 北東北
A14: 若山 | B14: 46258 | C14: 2026-08-24 | D14: 青森県 | E14: 東北町 | F14: 会計支援 | G14: (未記入) | H14: (未記入) | I14: (未記入) | J14: (未記入) | K14: (未記入) | L14: (未記入) | M14: 随契 | O14: 北東北
A15: 若山 | B15: 46258 | C15: 2026-08-24 | D15: 青森県 | E15: 三戸町 | F15: 会計支援 | G15: (未記入) | H15: (未記入) | I15: (未記入) | J15: (未記入) | K15: (未記入) | L15: (未記入) | M15: 随契 | O15: 北東北
A16: 若山 | B16: 46258 | C16: 2026-08-24 | D16: 青森県 | E16: むつ市 | F16: 経営改善 | G16: (未記入) | H16: (未記入) | I16: (未記入) | J16: R9 | K16: 今年度 | L16: (未記入) | M16: (未記入) | O16: 北東北 | P16: 水道 R8～関与
A17: 若山 | B17: 46258 | C17: 2026-08-24 | D17: 秋田県 | E17: にかほ市 | F17: 会計支援 | G17: (未記入) | H17: (未記入) | I17: (未記入) | J17: (未記入) | K17: (未記入) | L17: (未記入) | M17: 見積合わせ | O17: 北東北
A18: 若山 | B18: 46258 | C18: 2026-08-24 | D18: 秋田県 | E18: 東成瀬村 | F18: 会計支援 | G18: (未記入) | H18: (未記入) | I18: (未記入) | J18: (未記入) | K18: (未記入) | L18: (未記入) | M18: 見積合わせ | O18: 北東北
A19: 若山 | B19: 46258 | C19: 2026-08-24 | D19: 福島県 | E19: 川内村 | F19: 会計支援 | G19: (未記入) | H19: (未記入) | I19: (未記入) | J19: (未記入) | K19: (未記入) | L19: (未記入) | M19: 随契 | O19: 南東北・岩手
A20: 若山 | B20: 46258 | C20: 2026-08-24 | D20: 福島県 | E20: 葛尾村 | F20: 会計支援 | G20: (未記入) | H20: (未記入) | I20: (未記入) | J20: (未記入) | K20: (未記入) | L20: (未記入) | M20: 随契 | O20: 南東北・岩手
A21: 若山 | C21: (未記入) | D21: 福島県 | E21: 只見町 | F21: 会計支援 | G21: (未記入) | H21: (未記入) | I21: (未記入) | J21: (未記入) | K21: (未記入) | L21: (未記入) | M21: 随契 | O21: 南東北・岩手
A22: 若山 | B22: 46258 | C22: 2026-08-24 | D22: 北海道 | E22: 長万部町 | F22: 経営改善 | G22: (未記入) | H22: (未記入) | I22: 委託 | J22: R9 | K22: 今年度 | L22: (未記入) | M22: 随契 | O22: 北海道 | P22: 水道
A23: 若山 | B23: 46258 | C23: 2026-08-24 | D23: 北海道 | E23: 長万部町 | F23: 経営改善 | G23: (未記入) | H23: (未記入) | I23: 委託 | J23: R9 | K23: 今年度 | L23: (未記入) | M23: 随契 | O23: 北海道 | P23: 下水道
A24: 高橋 | B24: 46247 | C24: 2026-08-10 | D24: 宮城県 | E24: 松島町 | F24: 公共施設マネジメント | G24: 見積提示 | H24: 再アプローチ | I24: 委託 | J24: R9 | K24: 今年度 | L24: 見積＋仕様書 | M24: 見積合わせ | O24: 南東北・岩手 | P24: 昨年度から話あり
A25: 高橋 | B25: 46248 | C25: 2026-08-10 | D25: 宮城県 | E25: 涌谷町 | F25: 公共施設マネジメント | G25: 見積提示 | H25: 再アプローチ | I25: 委託 | J25: R9 | K25: 今年度 | L25: 見積＋仕様書 | M25: 見積合わせ | O25: 南東北・岩手 | P25: 施設カルテも追加営業中
A26: 高橋 | B26: 46251 | C26: 2026-08-17 | D26: 福島県 | E26: 国見町 | F26: 公共施設マネジメント | G26: 見積提示 | H26: 再アプローチ | I26: 委託 | J26: R9 | K26: 今年度 | L26: 見積提示 | M26: 見積合わせ | O26: 南東北・岩手 | P26: 個別施設も追加提案中
A27: 高橋 | B27: 46253 | C27: 2026-08-17 | D27: 福島県 | E27: 天栄村 | F27: 公共施設マネジメント | G27: 見積提示 | H27: 再アプローチ | I27: 自前 | J27: R9 | K27: 今年度 | L27: 見積提示 | M27: 見積合わせ | O27: 南東北・岩手 | P27: 個別施設、施設カルテ、セミナー参加
A28: 高橋 | B28: 46247 | C28: 2026-08-10 | D28: 宮城県 | E28: 登米市 | F28: 公会計 | G28: その他 | H28: 再アプローチ | I28: 自前 | J28: R9 | K28: 今年度 | L28: 見積提示 | M28: 入札 | O28: 南東北・岩手 | P28: 所有外も併せて提案
A29: 高橋 | B29: 46233 | C29: 2026-07-27 | D29: 福島県 | E29: 白河市 | F29: 福祉計画 | G29: 見積提示 | H29: 再アプローチ | I29: 委託 | J29: R9 | K29: 今年度 | L29: 見積提示 | M29: プロポ | O29: 南東北・岩手 | P29: 地域福祉計画策定
A30: 高橋 | B30: 46254 | C30: 2026-08-17 | D30: 福島県 | E30: 須賀川地方消防組合 | F30: 公会計 | G30: 他社随契 | H30: 再アプローチ | I30: 委託 | J30: R9 | K30: 今年度 | L30: 見積提示 | M30: (未記入) | O30: 南東北・岩手
A31: 松田 | B31: 46253 | C31: 2026-08-17 | D31: 秋田県 | E31: 鹿角市 | F31: 経営戦略 | G31: 自力 | H31: 再アプローチ | I31: 自前 | J31: R8 | K31: 今年度 | L31: セカンドアプローチ | M31: (未記入) | O31: 北東北
A32: 松田 | B32: 46253 | C32: 2026-08-17 | D32: 秋田県 | E32: 鹿角市 | F32: 公会計 | G32: (未記入) | H32: 見積提示 | I32: 委託 | J32: (未記入) | K32: 今年度 | L32: (未記入) | M32: 入札 | O32: 北東北 | P32: 今年度、一般入札と言っていたがｎサーチに出てこず。入札時期や方法を念入りに確認する必要有。
A33: 松田 | B33: 46253 | C33: 2026-08-17 | D33: 秋田県 | E33: 藤里町 | F33: 公会計 | G33: (未記入) | H33: 見積提示 | I33: 委託 | J33: (未記入) | K33: 今年度 | L33: セカンドアプローチ | M33: 入札 | O33: 北東北 | P33: 今年度指名入札、来年度は入れるように見積提示できるよう再アプローチ予定。問題点は以前顛末書提出した経歴があること。
A34: 松田 | B34: 46253 | C34: 2026-08-17 | D34: 秋田県 | E34: 藤里町 | F34: 経営改善 | G34: 不在 | H34: 再アプローチ | I34: (未記入) | J34: (未記入) | K34: (未記入) | L34: セカンドアプローチ | M34: (未記入) | O34: 北東北 | P34: 料金・使用料改定のセミナー参加のため、継続してアプローチを行う。今回は担当者不在のため、次回詳細確認。
A35: (未記入) | C35: (未記入) | D35: (未記入) | E35: (未記入) | F35: (未記入) | G35: (未記入) | H35: (未記入) | I35: (未記入) | J35: (未記入) | K35: (未記入) | L35: (未記入) | M35: (未記入) | O35: (未記入)
A36: 相澤 | B36: 46252 | C36: 2026-08-17 | D36: 岩手県 | E36: 二戸市 | F36: 公会計 | G36: 自力 | H36: 再アプローチ | I36: 自前 | J36: R8 | K36: 来年度 | L36: セカンドアプローチ | M36: (未記入) | O36: 南東北・岩手 | P36: 所有外セミナー案内
A37: 相澤 | B37: 46252 | C37: 2026-08-17 | D37: 岩手県 | E37: 二戸市 | F37: その他計画 | G37: 自力 | H37: 再訪不要 | I37: 自前 | J37: R8 | K37: 今年度 | L37: 初回訪問 | M37: (未記入) | N37: 自前作成方針（庁内対応） | O37: 南東北・岩手 | P37: 今年度自前作成
A38: 相澤 | B38: 46252 | C38: 2026-08-17 | D38: 岩手県 | E38: 二戸市 | F38: その他計画 | G38: 他社随契 | H38: (未記入) | I38: 委託 | J38: ～R7 | K38: (未記入) | L38: 初回訪問 | M38: (未記入) | O38: 南東北・岩手 | P38: R7改訂、セミナー案内実施
A39: 相澤 | B39: 46252 | C39: 2026-08-17 | D39: 岩手県 | E39: 二戸地区広域行政事務組合 | F39: 公会計 | G39: 他社随契 | H39: 見積提示 | I39: 委託 | J39: R8 | K39: 来年度 | L39: セカンドアプローチ | M39: (未記入) | O39: 南東北・岩手 | P39: 佐藤会計随契。来年度予算申請の見積依頼あり。
A40: 相澤 | B40: 46252 | C40: 2026-08-17 | D40: 岩手県 | E40: 二戸地区広域行政事務組合 | F40: その他計画 | G40: 他社随契 | H40: 再訪不要 | I40: 委託 | J40: R11 | K40: 再来年度 | L40: セカンドアプローチ | M40: (未記入) | N40: 他社受託：システム抱き合わせ | O40: 南東北・岩手 | P40: ぎょうせい随契
...
