Workbook

Sheet 01_設定
A1: 女川町水道事業 総括原価 前提条件の切替表
A2: 黄色のセルが選択箇所です。経営戦略の前提と、今回の再試算の前提を項目ごとに切り替えられます。選択を変えると「02_総括原価」の計算結果が更新されます。
B3: 初期値は現在の成果品（01_rate_reform_simulation_MAIN.xlsx）の前提を再現しています。この状態で総括原価は2,552,199千円、給水原価591.3円/㎥、必要改定率4.32倍になります。
A4: 【A】建設改良費と資本費の前提
B5: 項目 | C5: 選択（黄色セル） | D5: 経営戦略の設定 | E5: 再試算の候補 | G5: 説明
A6: A1 | B6: 建設改良費 | C6: 経営戦略の計画 | D6: 経営戦略の計画 | E6: 調査票 ／ 調査票＋量水器費 | G6: R8〜R17の整備費。経営戦略4,526,000千円、調査票3,515,000千円。
A7: A2 | B7: 新規取得資産の耐用年数（管路・構築物） | C7: 38 | D7: 38年 | E7: 35年 ／ 40年（調査票の入力値） | G7: 経営戦略は機械・電気を区分せず一律38年。調査票は4事業とも40年。
A8: A3 | B8: 新規取得資産の耐用年数（機械・電気） | C8: 38 | D8: 38年（区分なし） | E8: 15年 ／ 20年 ／ 25年 ／ 30年 ／ 40年 | G8: 鷲神高度処理設備が該当。経営戦略は38年、法定耐用年数はこれより短い。
A9: A4 | B9: 企業債の借入利率（％） | C9: 2.1 | D9: 2.1％ | E9: 2.0〜3.0％から選択 | G9: 調査票の利率欄は4事業とも未入力。経営戦略の加重平均借入利率は2.1％。
A10: A5 | B10: 企業債の償還条件 | C10: 経営戦略方式（40年・据置なし） | D10: 40年・元利均等・借入翌年度から | E10: 調査票方式（25/40年・据置3年） | G10: 調査票はNo.1が25年、他は40年、据置3年。
A12: 【B】資産維持費の前提
B13: 項目 | C13: 選択（黄色セル） | D13: 経営戦略の設定 | E13: 再試算の候補 | G13: 説明
A14: B1 | B14: 資産維持率（％） | C14: 3 | D14: 1.0％ | E14: 3.0％（業務仕様書の正式ケース） | G14: 経営戦略は「従前それほど大きな修繕がないため1.0％と仮定」。仕様書は3％の算入を求めている。
A15: B2 | B15: 対象資産の取り方 | C15: 期首期末平均 | D15: 期首の帳簿価額 1,042,625千円 | E15: 期首期末平均 896,312千円 | G15: 経営戦略は期首のみ。日本水道協会の算定要領は期首期末平均。
A16: B3 | B16: 資産維持費の年数 | C16: 5 | D16: 4年 | E16: 5年（R8〜R12） | G16: 経営戦略の料金算定期間は4年。本件の算定期間はR8〜R12の5年。
A18: 【C】減価償却費と控除項目の前提 ★総括原価への影響が最も大きい区分
B19: 項目 | C19: 選択（黄色セル） | D19: 経営戦略の設定 | E19: 再試算の候補 | G19: 説明
A20: C1 | B20: 減価償却費の算入方法 | C20: 損益計算書ベース | D20: 固定資産台帳ベース | E20: 損益計算書ベース | G20: 経営戦略は補助財源で取得した資産の償却費を原価に入れず、長期前受金戻入も控除しない。成果品は償却費を全額入れ、長期前受金戻入を控除する。両者は本来同じ結果になるべきもの。
A21: C2 | B21: 長期前受金戻入益の控除額 | C21: 成果品の推計値 | D21: 実額（1,542,259千円・既往資産分） | E21: 実額 ／ 推計値 ／ 控除しない | G21: ★経営戦略の実額は成果品の推計値の3.4倍。震災復興交付金で取得した資産が多いため。「減価償却費の算入方法」で固定資産台帳ベースを選ぶとこの項目は自動的に無効になる。
A22: C3 | B22: 他会計補助金等の控除額 | C22: 成果品の推計値 | D22: 控除していない | E22: 他会計補助金＋補助金 691,997千円 ／ 推計値 ／ 控除しない | G22: ★経営戦略の原価計算表（分解原価集計）は他会計補助金を控除していない。期間原価集計J列の控除項目の●印は要領上の分類として付されているだけで、最終集計には反映されていない。これに合わせて控除しないのが確定した前提。繰出基準の整理が変わる場合はここを切り替える。
A23: C4 | B23: その他営業収益・受取利息・雑収益の控除 | C23: 控除しない | D23: 控除していない | E23: 控除する（26,494千円） | G23: 期間原価集計では控除項目の●が付いているが、分解原価集計では控除されていない。経営戦略に合わせて控除しない。
A24: C5 | B24: 雑支出の算入 | C24: 算入しない | D24: 算入していない | E24: 算入する（36,696千円） | G24: 期間原価集計では固定費の●が付いているが、分解原価集計では算入されていない。経営戦略に合わせて算入しない。
A25: C6 | B25: 動力費・薬品費の単価 | C25: 経営戦略の値のまま | D25: 経営戦略の値のまま | E25: 実績単価に補正（＋47,167千円） | G25: ★経営戦略の単価算定は、1年分の費用を10年分の有収水量で割っており、実績の1/9〜1/14の水準。
B27: ▼ 一括設定の目安
B28: 「経営戦略に合わせる」…A1=経営戦略の計画／A2=38／A3=38／A4=2.1／A5=経営戦略方式／B1=1.0／B2=期首の帳簿価額／B3=4／C1=固定資産台帳ベース／C3=他会計補助金 272,997千円／C4=控除する／C5=算入しない／C6=経営戦略の値のまま
B29: 「今回の再試算」…A1=建設改良費調査票／A2=38／A3=38／A4=2.1／A5=経営戦略方式／B1=3.0／B2=期首期末平均／B3=5／C1=損益計算書ベース／C2=実額／C3=他会計補助金 272,997千円／C4=控除する／C5=算入する／C6=実績単価に補正

Sheet 02_総括原価
A1: 女川町水道事業 総括原価の算定 R8〜R12（5年間）
A2: 「01_設定」の選択に基づいて計算しています。金額はすべて千円。
A4: 【1】適用中の前提条件
B5: 建設改良費 | C5: ='01_設定'!$C$6
B6: 耐用年数（管路・構築物） | C6: ='01_設定'!$C$7
B7: 耐用年数（機械・電気） | C7: ='01_設定'!$C$8
B8: 借入利率（％） | C8: ='01_設定'!$C$9
B9: 償還条件 | C9: ='01_設定'!$C$10
B10: 資産維持率（％） | C10: ='01_設定'!$C$14
B11: 対象資産の取り方 | C11: ='01_設定'!$C$15
B12: 資産維持費の年数 | C12: ='01_設定'!$C$16
B13: 減価償却費の算入方法 | C13: ='01_設定'!$C$20
B14: 長期前受金戻入益の控除 | C14: ='01_設定'!$C$21
B15: 他会計補助金等の控除 | C15: ='01_設定'!$C$22
B16: その他収益の控除 | C16: ='01_設定'!$C$23
B17: 雑支出 | C17: ='01_設定'!$C$24
B18: 動力費・薬品費 | C18: ='01_設定'!$C$25
A20: 【2】総括原価の算定
B21: 費目 | C21: 金額（千円） | G21: 算定の内容
A22: Ⅰ | B22: 維持管理費 | C22: =672327+IF('01_設定'!$C$25="実績単価に補正",47167,0) | G22: 財政シミュの営業費用−減価償却費。動力費・薬品費の単価をR1〜R5実績で置き換えると＋47,167千円。
A23: Ⅱ | B23: 減価償却費 | C23: =IF('01_設定'!$C$20="固定資産台帳ベース",32188*5+INDEX('05_計算用データ'!$E$6:$E$113,MATCH('01_設定'!$C$6&"|"&'01_設定'!$C$20&"|"&'01_設定'!$C$7&"|"&'01_設定'!$C$8,'05_計算用データ'!$G$6:$G$113,0)),2032440-218421+INDEX('05_計算用データ'!$E$6:$E$113,MATCH('01_設定'!$C$6&"|"&'01_設定'!$C$20&"|"&'01_設定'!$C$7&"|"&'01_設定'!$C$8,'05_計算用データ'!$G$6:$G$113,0))) | G23: 損益計算書ベースは財政シミュ計上額から旧計画の新規取得分を除き、選択した計画の償却費を加算。固定資産台帳ベースは既往資産の年32,188千円×5年に、補助財源を除いた新規取得分を加算。
A24: Ⅲ | B24: 支払利息（既往債） | C24: =50585 | G24: 財政シミュの既往債利息。
A25: Ⅳ | B25: 支払利息（新規債） | C25: =44630+INDEX('05_計算用データ'!$D$118:$D$183,MATCH('01_設定'!$C$6&"|"&TEXT('01_設定'!$C$9,"0.0")&"|"&'01_設定'!$C$10,'05_計算用データ'!$G$118:$G$183,0)) | G25: R7以前の借入分44,630千円は固定。R8以降の借入分を選択した計画・借入利率・償還条件で算定。
A26: Ⅴ | B26: 雑支出 | C26: =IF('01_設定'!$C$24="算入する",36696,0) | G26: 営業外費用。
A27: Ⅵ | B27: 資産維持費 | C27: =ROUND(IF('01_設定'!$C$15="期首の帳簿価額",1042625,896312)*'01_設定'!$C$14/100,0)*'01_設定'!$C$16 | G27: 対象資産×資産維持率×年数。
A28: Ⅶ | B28: 控除：長期前受金戻入益 | C28: =-IF('01_設定'!$C$20="固定資産台帳ベース",0,IF('01_設定'!$C$21="経営戦略の実額",1542259+INDEX('05_計算用データ'!$F$6:$F$113,MATCH('01_設定'!$C$6&"|"&'01_設定'!$C$20&"|"&'01_設定'!$C$7&"|"&'01_設定'!$C$8,'05_計算用データ'!$G$6:$G$113,0)),IF('01_設定'!$C$21="成果品の推計値",450000,0))) | G28: 固定資産台帳ベースを選んだ場合は二重控除になるため自動的にゼロ。
A29: Ⅷ | B29: 控除：他会計補助金等 | C29: =-IF('01_設定'!$C$22="他会計補助金のみ",272997,IF('01_設定'!$C$22="他会計補助金＋補助金",691997,IF('01_設定'!$C$22="成果品の推計値",15000,0))) | G29: 基準内繰入金は控除、基準外繰入金（赤字補填）は控除しないのが原則。
A30: Ⅸ | B30: 控除：その他営業収益・受取利息・雑収益 | C30: =-IF('01_設定'!$C$23="控除する",26494,0) | G30: 算定要領上の控除項目。
B31: 総括原価 合計 | C31: =SUM(C22:C30)
A33: 【3】給水原価・料金回収率・必要改定幅
B34: 指標 | C34: 算定値 | G34: 算定式
B35: 有収水量 R8〜R12（㎥） | C35: =4316000 | G35: 財政シミュの水需要予測。
B36: 給水収益 R8〜R12（千円・現行料金） | C36: =590845 | G36: 財政シミュの給水収益。
B37: 給水原価（円/㎥） | C37: =C31*1000/4316000 | G37: 総括原価×1,000÷有収水量。
B38: 現行供給単価（円/㎥） | C38: =128.2 | G38: R7実績 131,429千円÷1,025千㎥。
B39: 料金回収率 | C39: =128.2/C37 | G39: 現行供給単価÷給水原価。
B40: 年間不足額（千円/年） | C40: =(C31-590845)/5 | G40: （総括原価−給水収益）÷5年。
B41: 必要改定率（総括原価÷現行収入） | C41: =C31/590845 | G41: 1.00倍なら現行料金で原価を回収できる水準。
B42: 標準世帯（20㎥/月）月額への換算（円） | C42: =ROUND(2395*C31/590845,0) | G42: 現行2,395円×必要改定率。参考値。
B44: ※ この表は開いたときに再計算されます。数値が空欄に見える場合は、Excelで開き直してください。

Sheet 03_差異一覧
A1: 経営戦略と再試算の差異一覧
A2: 双方の設定が異なる箇所と、確認が必要な箇所をまとめたものです。金額は千円。
A4: 【A】前提条件の差異（「01_設定」で切り替えられる項目）
B5: 項目 | C5: 経営戦略 | D5: 再試算（成果品） | E5: 影響の大きさ | G5: 内容
A6: 1 | B6: 料金算定期間 | C6: R6〜R9の4年間 | D6: R8〜R12の5年間 | E6: 大 | G6: 経営戦略の期間原価集計は年度ラベルがH31・R2・R3・R4のままだが、参照先の数値はR6〜R9。ラベルの更新漏れ。
A7: 2 | B7: 減価償却費の算入方法 | C7: 固定資産台帳ベース 128,750（4年） | D7: 損益計算書ベース 2,032,440（5年） | E7: 特大 | G7: 経営戦略は補助財源で取得した資産の償却費を原価に算入していない。成果品は全額算入し長期前受金戻入を控除する方式。
A8: 3 | B8: 長期前受金戻入益の控除 | C8: 実額 1,542,259（R8〜R12・既往資産分） | D8: 推計 450,000 | E8: 特大 | G8: 成果品の推計値は実額の約29％。震災復興交付金で取得した資産が多く、償却費の8割超が戻入で相殺される構造。
A9: 4 | B9: 他会計補助金等の控除 | C9: 他会計補助金 272,997（R8〜R12） | D9: 推計 15,000 | E9: 大 | G9: 経営戦略の算定式は「減価償却費＋人件費＋支払利息」。基準内・基準外の区分が未確定。
A10: 5 | B10: 補助金の控除 | C10: 419,000（R8〜R12・営業外収益） | D10: 算入なし | E10: 大 | G10: 性格の確認が必要。
A11: 6 | B11: その他営業収益・受取利息・雑収益 | C11: 控除する 26,494 | D11: 控除していない | E11: 小 | G11: 算定要領上の控除項目。
A12: 7 | B12: 雑支出 | C12: 算入していない 36,696 | D12: 算入していない | E12: 小 | G12: 営業外費用。双方とも未算入。
A13: 8 | B13: 資産維持率 | C13: 1.0％ | D13: 3.0％ | E13: 中 | G13: 経営戦略は「従前それほど大きな修繕がない」ことを理由に1.0％と仮定。仕様書は3％を求めている。
A14: 9 | B14: 資産維持費の対象資産 | C14: 期首 1,042,625 | D14: 期首期末平均 896,312 | E14: 中 | G14: 算定要領は期首期末平均。
A15: 10 | B15: 資産維持費の年数 | C15: 4年 | D15: 5年 | E15: 中 | G15: 料金算定期間の設定に連動。
A16: 11 | B16: 新規取得資産の耐用年数 | C16: 一律38年（機械・電気の区分なし） | D16: 調査票40年 | E16: 中 | G16: 鷲神高度処理設備は機械・電気設備。法定耐用年数はこれより短い。
A17: 12 | B17: 企業債の借入利率 | C17: 2.1％ | D17: 調査票は未入力 | E17: 小 | G17: 経営戦略の根拠欄には「1.79％」と別の数値が残っている。
A18: 13 | B18: 企業債の償還条件 | C18: 40年・元利均等・借入翌年度から | D18: 調査票は25／40年・据置3年 | E18: 小
A19: 14 | B19: 建設改良費 | C19: 4,526,000（R8〜R17） | D19: 3,515,000（調査票） | E19: 中 | G19: 差 1,011,000。施設区分別では構造物及び設備▲475,000、送水管▲230,000、配水本管▲200,000、量水器費▲106,000。
A20: 15 | B20: 動力費・薬品費の単価 | C20: 1年分の費用を10年分の有収水量で除している | D20: 経営戦略の値をそのまま使用 | E20: 中 | G20: 実績の1/9〜1/14の水準。年約7,200の過小計上。
A21: 16 | B21: 有収水量 R8〜R12 | C21: 4,315,366㎥ | D21: 4,316,000㎥ | E21: なし | G21: 丸めの差のみ。
A22: 17 | B22: 給水収益 R8〜R12 | C22: 590,845 | D22: 590,845 | E22: なし | G22: 一致。
A23: 18 | B23: 維持管理費 R8〜R12 | C23: 672,328 | D23: 672,327 | E23: なし | G23: 一致。
A24: 19 | B24: 支払利息（既往債）R8〜R12 | C24: 50,585 | D24: 50,585 | E24: なし | G24: 一致。
A26: 【B】経営戦略試算シートで確認が必要な箇所
B27: 箇所 | C27: 内容 | G27: 対応
A28: 1 | B28: 料金算定－要領 総括原価シート | C28: 固定費の配賦から料金表の算定まで、参照切れにより計算結果が出ない状態。 | G28: 有収水量合計と口径別調定件数の参照先を復旧する。
A29: 2 | B29: 料金算定－現行×改定率 総括原価シート | C29: 口径別基本料金・水量料金の算定結果がすべて参照切れ。 | G29: 同上。
A30: 3 | B30: 原水及び浄水費の動力費 | C30: 1年分の平均費用を10年分の有収水量合計で除して単価を算定しており、さらに単価を整数に丸めているため1円/㎥になっている。計上額は有収水量と同額。 | G30: 単価を1年あたりの有収水量で算定し直す。実績ベースでは約4.7円/㎥。
A31: 4 | B31: 原水及び浄水費の薬品費 | C31: 同じ理由で0.258円/㎥。実績ベースでは約2.3円/㎥。 | G31: 同上。
A32: 5 | B32: 配水及び給水費の動力費 | C32: 同じ理由で単価が0.25円/㎥となり、整数への丸めで0円になっている。実績では年2,159千円が発生している。 | G32: 同上。丸めの位置も見直す。
A33: 6 | B33: 期間原価集計の年度ラベル | C33: K4〜N4が「H31・R2・R3・R4」のままだが、参照先の数値はR6〜R9。 | G33: ラベルを実態に合わせる。
A34: 7 | B34: 支払利息の算定根拠欄 | C34: 「利率の平均値（1.79％）」と記載されているが、実際の計算は2.1％。 | G34: 根拠欄を2.1％に更新する。
A35: 8 | B35: 新規取得資産の耐用年数 | C35: 機械・電気設備を区分せず一律38年。貸借対照表では「機械及び装置」を独立科目として持っている。 | G35: 将来取得分についても資産区分ごとの耐用年数を設定するか、一律とする理由を明記する。
A37: 【C】建設改良費調査票で確認が必要な箇所
B38: 箇所 | C38: 内容 | G38: 対応
A39: 1 | B39: No.3 鷲神高度処理設備の財源構成割合 | C39: 「財源構成割合(%)」欄に金額（企業債444,000・繰入金444,000）が入力されている。単純な割合で出せない事業があるため、入力された金額を正として扱う。ただし様式の財源行の数式が割合前提（整備費×入力値÷100）のままのため、集計表の「財源：繰入金」が約3.9兆円、「財源：その他」が同額のマイナスになる。 | G39: 当方で入力金額から直接集計する。様式の数式は今後の混乱を避けるため修正しておく。女川町への再提出依頼は不要。
A40: 2 | B40: 企業債の利率 | C40: 4事業とも未入力。 | G40: 借入予定利率を記入する。
A41: 3 | B41: No.4 江島海底送水管 | C41: 資産種別・更新新規の別・補助単独の別がいずれも未入力。 | G41: 記入する。
A42: 4 | B42: 量水器費 | C42: 経営戦略はR8〜R17で106,000を計上しているが、調査票は委託・工事のみを対象としているため計上されていない。 | G42: 量水器の更新費を別途見込む必要があるか確認する。
A43: 5 | B43: 出資金と繰入金 | C43: 経営戦略は出資金1,230,000、調査票は繰入金444,000。差786,000。 | G43: 一般会計負担の方針を確認する。
...

Sheet 04_建設改良費
A1: 建設改良費の新旧比較（R8〜R17）
A2: 金額は千円。
A4: 【経営戦略の計画】
A5: 事業名 | B5: R8 | C5: R9 | D5: R10 | E5: R11 | F5: R12 | G5: R13 | H5: R14 | I5: R15 | J5: R16 | K5: R17 | L5: 合計
A6: 経営戦略の建設改良費 | B6: 1030000 | C6: 950000 | D6: 500000 | E6: 330000 | F6: 310000 | G6: 311000 | H6: 371000 | I6: 294000 | J6: 230000 | K6: 200000 | L6: 4526000
A7: 計 | B7: 1030000 | C7: 950000 | D7: 500000 | E7: 330000 | F7: 310000 | G7: 311000 | H7: 371000 | I7: 294000 | J7: 230000 | K7: 200000 | L7: 4526000
A10: 【建設改良費調査票】
A11: 事業名 | B11: R8 | C11: R9 | D11: R10 | E11: R11 | F11: R12 | G11: R13 | H11: R14 | I11: R15 | J11: R16 | K11: R17 | L11: 合計
A12: No.1 老朽管布設替工事 | B12: 180000 | C12: 150000 | D12: 150000 | E12: 100000 | F12: 100000 | G12: 100000 | H12: 100000 | I12: 100000 | J12: 100000 | K12: 100000 | L12: 1180000
A13: No.2 水道施設耐震化工事 | B13: 12000 | C13: 35000 | D13: 60000 | E13: 220000 | F13: 220000 | G13: 220000 | H13: 60000 | I13: 150000 | J13: 150000 | K13: 150000 | L13: 1277000
A14: No.3 鷲神高度処理設備整備工事 | B14: 353400 | C14: 534600 | D14: 0 | E14: 0 | F14: 0 | G14: 0 | H14: 0 | I14: 0 | J14: 0 | K14: 0 | L14: 888000
A15: No.4 江島海底送水管本復旧工事 | B15: 20000 | C15: 150000 | D15: 0 | E15: 0 | F15: 0 | G15: 0 | H15: 0 | I15: 0 | J15: 0 | K15: 0 | L15: 170000
A16: 計 | B16: 565400 | C16: 869600 | D16: 210000 | E16: 320000 | F16: 320000 | G16: 320000 | H16: 160000 | I16: 250000 | J16: 250000 | K16: 250000 | L16: 3515000
A19: 【調査票＋量水器費】
A20: 事業名 | B20: R8 | C20: R9 | D20: R10 | E20: R11 | F20: R12 | G20: R13 | H20: R14 | I20: R15 | J20: R16 | K20: R17 | L20: 合計
A21: No.1 老朽管布設替工事 | B21: 180000 | C21: 150000 | D21: 150000 | E21: 100000 | F21: 100000 | G21: 100000 | H21: 100000 | I21: 100000 | J21: 100000 | K21: 100000 | L21: 1180000
A22: No.2 水道施設耐震化工事 | B22: 12000 | C22: 35000 | D22: 60000 | E22: 220000 | F22: 220000 | G22: 220000 | H22: 60000 | I22: 150000 | J22: 150000 | K22: 150000 | L22: 1277000
A23: No.3 鷲神高度処理設備整備工事 | B23: 353400 | C23: 534600 | D23: 0 | E23: 0 | F23: 0 | G23: 0 | H23: 0 | I23: 0 | J23: 0 | K23: 0 | L23: 888000
A24: No.4 江島海底送水管本復旧工事 | B24: 20000 | C24: 150000 | D24: 0 | E24: 0 | F24: 0 | G24: 0 | H24: 0 | I24: 0 | J24: 0 | K24: 0 | L24: 170000
A25: 量水器費（調査票の対象外・経営戦略から復元） | B25: 20000 | C25: 20000 | D25: 20000 | E25: 0 | F25: 0 | G25: 1000 | H25: 1000 | I25: 4000 | J25: 20000 | K25: 20000 | L25: 106000
A26: 計 | B26: 585400 | C26: 889600 | D26: 230000 | E26: 320000 | F26: 320000 | G26: 321000 | H26: 161000 | I26: 254000 | J26: 270000 | K26: 270000 | L26: 3621000

Sheet 05_計算用データ
A1: 計算用データ（参照専用）
A2: 「01_設定」の選択に応じて「02_総括原価」が参照します。直接編集しないでください。
A4: 【減価償却費・長期前受金（新規取得分）R8〜R12 5年計・千円】
A5: 計画 | B5: 減価償却費の算入方法 | C5: 管路年数 | D5: 機電年数 | E5: 減価償却費 | F5: 長期前受金(新規) | G5: 照合キー
A6: 経営戦略の計画 | B6: 損益計算書ベース | C6: 35 | D6: 15 | E6: 237143 | F6: 16666 | G6: 経営戦略の計画|損益計算書ベース|35|15
A7: 経営戦略の計画 | B7: 損益計算書ベース | C7: 35 | D7: 20 | E7: 237143 | F7: 16666 | G7: 経営戦略の計画|損益計算書ベース|35|20
A8: 経営戦略の計画 | B8: 損益計算書ベース | C8: 35 | D8: 25 | E8: 237143 | F8: 16666 | G8: 経営戦略の計画|損益計算書ベース|35|25
A9: 経営戦略の計画 | B9: 損益計算書ベース | C9: 35 | D9: 30 | E9: 237143 | F9: 16666 | G9: 経営戦略の計画|損益計算書ベース|35|30
A10: 経営戦略の計画 | B10: 損益計算書ベース | C10: 35 | D10: 38 | E10: 237143 | F10: 16666 | G10: 経営戦略の計画|損益計算書ベース|35|38
A11: 経営戦略の計画 | B11: 損益計算書ベース | C11: 35 | D11: 40 | E11: 237143 | F11: 16666 | G11: 経営戦略の計画|損益計算書ベース|35|40
A12: 経営戦略の計画 | B12: 損益計算書ベース | C12: 38 | D12: 15 | E12: 218421 | F12: 15351 | G12: 経営戦略の計画|損益計算書ベース|38|15
A13: 経営戦略の計画 | B13: 損益計算書ベース | C13: 38 | D13: 20 | E13: 218421 | F13: 15351 | G13: 経営戦略の計画|損益計算書ベース|38|20
A14: 経営戦略の計画 | B14: 損益計算書ベース | C14: 38 | D14: 25 | E14: 218421 | F14: 15351 | G14: 経営戦略の計画|損益計算書ベース|38|25
A15: 経営戦略の計画 | B15: 損益計算書ベース | C15: 38 | D15: 30 | E15: 218421 | F15: 15351 | G15: 経営戦略の計画|損益計算書ベース|38|30
A16: 経営戦略の計画 | B16: 損益計算書ベース | C16: 38 | D16: 38 | E16: 218421 | F16: 15351 | G16: 経営戦略の計画|損益計算書ベース|38|38
A17: 経営戦略の計画 | B17: 損益計算書ベース | C17: 38 | D17: 40 | E17: 218421 | F17: 15351 | G17: 経営戦略の計画|損益計算書ベース|38|40
... A113: 調査票＋量水器費 | B113: 固定資産台帳ベース | C113: 40 | D113: 40 | E113: 122722 | F113: 0 | G113: 調査票＋量水器費|固定資産台帳ベース|40|40
A116: 【支払利息・元金償還（新規債）R8〜R12 5年計・千円】
A117: 計画 | B117: 借入利率(％) | C117: 償還条件 | D117: 支払利息 | E117: 元金償還 | G117: 照合キー
A118: 経営戦略の計画 | B118: 2 | C118: 経営戦略方式（40年・据置なし） | D118: 78800 | E118: 67850 | G118: 経営戦略の計画|2.0|経営戦略方式（40年・据置なし）
A119: 経営戦略の計画 | B119: 2 | C119: 調査票方式（25/40年・据置3年） | D119: 80234 | E119: 7428 | G119: 経営戦略の計画|2.0|調査票方式（25/40年・据置3年）
A120: 経営戦略の計画 | B120: 2.1 | C120: 経営戦略方式（40年・据置なし） | D120: 82772 | E120: 66462 | G120: 経営戦略の計画|2.1|経営戦略方式（40年・据置なし）
A121: 経営戦略の計画 | B121: 2.1 | C121: 調査票方式（25/40年・据置3年） | D121: 84245 | E121: 7268 | G121: 経営戦略の計画|2.1|調査票方式（25/40年・据置3年）
A122: 経営戦略の計画 | B122: 2.2 | C122: 経営戦略方式（40年・据置なし） | D122: 86746 | E122: 65096 | G122: 経営戦略の計画|2.2|経営戦略方式（40年・据置なし）
A123: 経営戦略の計画 | B123: 2.2 | C123: 調査票方式（25/40年・据置3年） | D123: 88257 | E123: 7111 | G123: 経営戦略の計画|2.2|調査票方式（25/40年・据置3年）
A124: 経営戦略の計画 | B124: 2.3 | C124: 経営戦略方式（40年・据置なし） | D124: 90722 | E124: 63752 | G124: 経営戦略の計画|2.3|経営戦略方式（40年・据置なし）
A125: 経営戦略の計画 | B125: 2.3 | C125: 調査票方式（25/40年・据置3年） | D125: 92269 | E125: 6957 | G125: 経営戦略の計画|2.3|調査票方式（25/40年・据置3年）
A126: 経営戦略の計画 | B126: 2.4 | C126: 経営戦略方式（40年・据置なし） | D126: 94701 | E126: 62429 | G126: 経営戦略の計画|2.4|経営戦略方式（40年・据置なし）
A127: 経営戦略の計画 | B127: 2.4 | C127: 調査票方式（25/40年・据置3年） | D127: 96280 | E127: 6806 | G127: 経営戦略の計画|2.4|調査票方式（25/40年・据置3年）
A128: 経営戦略の計画 | B128: 2.5 | C128: 経営戦略方式（40年・据置なし） | D128: 98682 | E128: 61128 | G128: 経営戦略の計画|2.5|経営戦略方式（40年・据置なし）
A129: 経営戦略の計画 | B129: 2.5 | C129: 調査票方式（25/40年・据置3年） | D129: 100292 | E129: 6657 | G129: 経営戦略の計画|2.5|調査票方式（25/40年・据置3年）
... A183: 調査票＋量水器費 | B183: 3 | C183: 調査票方式（25/40年・据置3年） | D183: 95736 | E183: 5550 | G183: 調査票＋量水器費|3.0|調査票方式（25/40年・据置3年）

Sheet 06_主要ケース
A1: 主要ケースの計算結果一覧
A2: 「01_設定」で選択できる組み合わせのうち、代表的なものを並べたものです。金額は千円。
B4: ケース | C4: 総括原価5年計 | D4: 給水原価(円/㎥) | E4: 料金回収率 | F4: 年間不足額 | G4: 必要改定率 | H4: 維持管理費 | I4: 減価償却費 | J4: 控除計
B5: ① 経営戦略の前提をそのまま使う | C5: 956537.3 | D5: 221.6 | E5: 0.6 | F5: 73138.5 | G5: 1.6 | H5: 672327 | I5: 364010.5 | J5: -299491
B6: ② 成果品（現行）の前提 | C6: 2552198.8 | D6: 591.3 | E6: 0.2 | F6: 392270.8 | G6: 4.3 | H6: 672327 | I6: 2032440 | J6: -465000
B7: ③ ②に建設改良費調査票だけ反映 | C7: 2460778.1 | D7: 570.2 | E7: 0.2 | F7: 373986.6 | G7: 4.2 | H7: 672327 | I7: 1961661.1 | J7: -465000
B8: ④ ③＋長期前受金戻入を実額に | C8: 1345321.7 | D8: 311.7 | E8: 0.4 | F8: 150895.3 | G8: 2.3 | H8: 672327 | I8: 1961661.1 | J8: -1580456.4
B9: ⑤ ④＋動力費・薬品費を補正【確定した前提】 | C9: 1407488.7 | D9: 326.1 | E9: 0.4 | F9: 163328.7 | G9: 2.4 | H9: 719494 | I9: 1961661.1 | J9: -1565456.4
B10: ⑥ ⑤＋他会計補助金272,997を控除（繰出基準が変わる場合） | C10: 1134491.7 | D10: 262.9 | E10: 0.5 | F10: 108729.3 | G10: 1.9 | H10: 719494 | I10: 1961661.1 | J10: -1838453.4
B11: ⑦ ⑤＋他会計補助金＋補助金691,997を控除 | C11: 715491.7 | D11: 165.8 | E11: 0.8 | F11: 24929.3 | G11: 1.2 | H11: 719494 | I11: 1961661.1 | J11: -2257453.4
B12: ⑧ ⑤＋機械・電気を20年償却 | C12: 1478953.4 | D12: 342.7 | E12: 0.4 | F12: 177621.7 | G12: 2.5 | H12: 719494 | I12: 2033125.8 | J12: -1565456.4
B13: ⑨ ⑤＋量水器費を戻す | C13: 1415936.8 | D13: 328.1 | E13: 0.4 | F13: 165018.4 | G13: 2.4 | H13: 719494 | I13: 1966397.9 | J13: -1565456.4
B14: ⑩ ⑤＋借入利率3.0％ | C14: 1434396.3 | D14: 332.3 | E14: 0.4 | F14: 168710.3 | G14: 2.4 | H14: 719494 | I14: 1961661.1 | J14: -1565456.4
B15: ⑪ ⑤で減価償却を固定資産台帳ベースに | C15: 1296668.7 | D15: 300.4 | E15: 0.4 | F15: 141164.7 | G15: 2.2 | H15: 719494 | I15: 285384.7 | J15: 0
B16: ⑫ ⑤＋その他営業収益等を控除し雑支出を算入 | C16: 1417690.7 | D16: 328.5 | E16: 0.4 | F16: 165369.1 | G16: 2.4 | H16: 719494 | I16: 1961661.1 | J16: -1591950.4
B18: ▼ 読み取り方
B19: ・①と②の差が、経営戦略と成果品の前提の違いによるものです。建設改良費の改定より、控除項目の扱いの方が影響が大きくなっています。
B20: ・②→④で給水原価が大きく下がるのは、長期前受金戻入益を推計値450,000千円から実額1,542,259千円に置き換えたためです。
B21: ・⑤は繰入金を控除しない前提です。経営戦略報告書案が「繰出基準以外の繰出金で補填している」と述べているためで、基準内と認められる分があれば⑥⑦の水準まで下がります。
B22: ・⑪は減価償却費を経営戦略と同じ固定資産台帳ベースに揃えたもので、①に近づきます。
B23: ・⑧⑨⑩は、確定していない前提（機械電気の耐用年数・量水器費・借入利率）が振れた場合の幅を示しています。

Sheet 07_参照元
A1: 主要な数値の参照元
A2: 各数値がどのファイル・シート・行から来ているかの対応表です。
A4: 【A】控除項目
B5: 項目 | C5: 参照元 | D5: 値 | G5: 確認結果
A6: 1 | B6: 長期前受金戻入益（既往資産分） | C6: 経営戦略試算シート【成行】財政シミュ r17 | D6: R8 329,946／R9 324,870／R10 311,865／R11 299,986／R12 290,154（5年計1,542,259） | G6: 全年度が直接入力の固定値。根拠欄は「固定資産台帳データに基づく算定額」。固定資産台帳そのものは同ブックに含まれていない。実績（【PL】決算数値入力 r26）はR3 336,382／R4 419,320／R5 336,409で、見込額はこの水準と整合している。
A7: 2 | B7: 長期前受金戻入益（新規取得分） | C7: 【成行】財政シミュ r18 ＝ 新規取得!P5 | D7: R8 0／R9 1,667／R10 2,982／R11 4,298／R12 5,614 | G7: 国庫補助金を38年で収益化。新規取得シートH3の式は 財政シミュ!$V$77/38。
A8: 3 | B8: 成果品の推計値 | C8: 01_rate_reform_simulation_MAIN.xlsx 02_総括原価 C13:G13 | D8: R8 ▲94,000／R9 ▲92,000／R10 ▲90,000／R11 ▲88,000／R12 ▲86,000（5年計450,000） | G8: 注記は「（推計）非キャッシュ控除。減価償却費の約22%を相殺」。経営戦略の見込額はR8で減価償却費の83%、5年平均で77%にあたり、推計値は約3.4分の1。
A9: 4 | B9: 他会計補助金（収益的収入） | C9: 【成行】財政シミュ r13 ＝ r44＋r59 | D9: R8 38,617／R9 47,830／R10 55,812／R11 63,330／R12 67,408（5年計272,997） | G9: 総係費の人件費（r44）と支払利息（r59）の合計。根拠欄は「現状の算定式（＝減価償却費＋人件費＋支払利息）」と書かれているが、式に減価償却費は入っていない。
A10: 5 | B10: 補助金（収益的収入） | C10: 【成行】財政シミュ r14 | D10: R8 59,000／R9〜R12 各90,000（5年計419,000） | G10: 直接入力の固定値で根拠欄なし。料金改定後シートでは同じ行が「既往債の支払利息（r60）」に置き換わっており、2つのシートで中身が食い違っている。
A11: 6 | B11: 他会計補助金（資本的収入） | C11: 【成行】財政シミュ r76 | D11: R8〜R17 各3,000 | G11: 直接入力の固定値。根拠欄は「R6以降はゼロ」とあり、値と矛盾している。
A12: 7 | B12: 他会計補助（元金償還） | C12: 【成行】財政シミュ (料金改定後) r79 ＝ r97 | D12: R8 30,882／R9 44,652／R10 38,509／R11 47,923／R12 53,577 | G12: ★資本的収入の最下段。R6末の既往債の元金償還額と同額で、企業債元金償還に対する繰出。繰出基準に該当する典型例だが、資本的収支のため収益的収支の総括原価には入らない。成行シートには計上されていない（同じ行は「固定資産売却代金・計上しない」）。
A13: 8 | B13: 出資金（資本的収入） | C13: 【成行】財政シミュ r75 | D13: R8 515,000（＝65,000＋450,000）／R9 495,000／R10 60,000／R11 40,000／R12以降 20,000 | G13: 直接入力の固定値。根拠欄は「予定額」。
A15: 【B】経営戦略報告書案の記載
B16: 箇所 | C16: 記載内容 | G16: 読み取れること
A17: 1 | B17: 3-8 ⑹料金回収率 | C17: 数値が低く、国が定める繰出基準以外の繰出金によって収入不足を補填している状況で、今後も施設更新の予定がありますが、料金改定を行うのか施設更新（投資規模）を先送り又は縮小するのか判断が求められます。 | G17: 現在の繰入金の相当部分が基準外（赤字補填）であると本文が明言している。
A18: 2 | B18: 4-1 ⑷一般会計繰入金 | C18: 過去の一般会計からの繰入手法（現金部分の赤字補填）により算定しました。 | G18: 財政シミュの繰入金は赤字補填額として算定されており、繰出基準に基づく積上げではない。
A19: 3 | B19: 4-1 ⑹支払利息 | C19: 企業債残高に地方債の加重平均借入利率（2.1％）を乗じて試算しました。 | G19: 借入利率は2.1％。ただし財政シミュr61の根拠欄には「1.79％」と別の数値が残っている。
A20: 4 | B20: 4-1 ⑺企業債償還金 | C20: 建設改良費から補助金収入を控除した残額を企業債で充当し、借入年度の翌年度から40年にわたり元利均等で返済すると仮定して試算しました。 | G20: 据置期間は設定されていない。調査票は据置3年。
A21: 5 | B21: 4-5 ⑵②企業債 | C21: 新たに高度処理施設の整備のほか、老朽管布設替えや水道施設耐震化など将来の更新投資に伴い、企業債の元利償還金の額が増加する見込みです。 | G21: 調査票のNo.1〜No.3と対応している。北上川導水管への言及はない。
A22: 6 | B22: 4-5 ⑵③繰入金 | C22: 企業債償還及び施設改良費等を水道料金等収入だけで賄うことが困難な状況にあることから、一般会計から一定額を繰入を行う計画となっています。国の定める繰出基準内の繰入金はもとより、不採算地域となる出島地区・江島地区に対する費用負担について、一般会計側との協議を継続していきます。 | G22: 基準内繰入は既にあり、それに加えて離島分の基準外繰入を求めていく方針。
A23: 7 | B23: 5 ⑶一般会計繰入金 | C23: 離半島地区での施設整備には、国の定める基準内繰入金のほかに、地域的事情によるものとして基準外繰入金により整備することが必要となるので、一般会計での負担ができないか検討・協議を行っていきます。 | G23: 基準内と基準外を明確に区別して記述している。現時点では基準外の負担は未確定。
A24: 8 | B24: 2-2 現状 | C24: 今後は、本町から24km離れた一級河川・北上川（石巻市）からの導水管や東日本大震災後に未更新の管路、施設の更新による災害危機対策が求められています。 | G24: ★北上川導水管は「求められている課題」として書かれているだけで、投資計画には計上されていない。更新投資額の内訳（r119）の「取・導水管」は全年度ゼロ。
A26: 【C】経営戦略の原価計算表の作り（【料金算定】分解原価集計）
B27: 費目 | C27: 算定式 | D27: 4年計（円） | G27: 内容
A28: 1 | B28: 維持管理費（原浄水） | C28: 期間原価集計!O24−O26−O27 | D28: 255,240,131 | G28: 原水及び浄水費から動力費・薬品費を除いた額。動力費・薬品費は変動費として別掲。
A29: 2 | B29: 維持管理費（配給水） | C29: 期間原価集計!O32−O34−O35 | D29: 134,698,869 | G29: 配水及び給水費から同様に控除。
A30: 3 | B30: 維持管理費（その他管理） | C30: 期間原価集計!O40 | D30: 130,727,396 | G30: 総係費。
A31: 4 | B31: 減価償却費等 | C31: 固定資産台帳集計結果 T6＋T7＋T8 | D31: 128,750,077 | G31: ★取水12,729,056＋浄水16,442,189＋配水99,578,832。損益計算書の減価償却費1,591,381,741ではなく、固定資産台帳の自己財源相当分のみ。補助財源で取得した資産の償却費は原価に入れない設計。
A32: 5 | B32: 支払利息 | C32: 固定資産台帳集計結果 T19＋T20＋T21 | D32: 39,061,345 | G32: ★H30末の既往債分のみ。期間原価集計O58の新規債利息32,793,807は算入されていない。
A33: 6 | B33: 資産維持費 | C33: 【料金算定】資産維持費!C12＋C13 | D33: 41,705,008 | G33: 対象資産1,042,625,176×1.0%×4年。
A34: 7 | B34: 合計 | D34: 734,751,816 | G34: 料金算定期間はR6〜R9の4年（期間原価集計K4〜N4のラベルはH31・R2・R3・R4のまま）。
B36: ★ 控除項目は一切参照されていない。期間原価集計のJ列「控除項目」に●が付いている
B37: その他の営業収益・受取利息・他会計補助金・雑収益・長期前受金戻入益は、分解原価集計の算定式に現れない。
B38: 補助財源分は「減価償却費と支払利息を固定資産台帳ベースに絞る」ことで原価から除く設計になっている。
B39: ★ 雑支出（期間原価集計O59・固定費の●あり）も分解原価集計では算入されていない。
B40: ★ 期間原価集計の営業外収益の内訳（受取利息＋他会計補助金＋雑収益＋長期前受金戻入益）は、
B41: R8で373,468,663円となり、同シートの営業外収益合計432,468,663円と59,000,000円合わない。
B42: 差額は成行シートの「補助金」で、期間原価集計には行そのものがない。
A44: 【D】建設改良費の施設区分別対比（R8〜R17・千円）
B45: 施設区分 | C45: 経営戦略の計画 | D45: 建設改良費調査票 | E45: 差引 | G45: 対応する事業
...
