Workbook

Sheet 入力方法
B2: 建設改良費調査票 入力ガイド
B4: ■ 基本ルール
C5: 黄色のセルが「入力箇所」です。担当者様はこちらに数値を入力してください。
C6: グレーのセルは「自動計算」されますが、金額がわかっているものについては直接入力してください。
C7: 金額の単位はすべて【税込み・千円単位】で入力をお願いいたします。
B10: ■対象選別ルール
B11: ① | C11: Ｒ９～Ｒ１７で行う予定の委託（設計等）・工事について、全て抜き出してください。
B12: ② | C12: 下水道は、「管渠」「ポンプ場」「処理場（流域下水道負担金）」を計上してください。
C13: 上水道は、「浄水場」「配水池」「その他」で計上してください。
C14: 老朽配水管、送水管は、その他に分類してください。
C15: 浄化槽は、全て「その他」に分類してください。
B19: ③ | C19: 更新／新規の別、補助／単独の別を入力してください。
B20: ④ | C20: 委託・工事金額は、概算でも構いませんが、金額があまりにも大きくズレると料金改定に大きく影響を与えます。
B21: ⑤ | C21: 20事業まで記載できますが、不足する場合は、コピーして作成してください。
B24: 入力返答期限は、８月28日（金）までです。８月31日には、データをビズアップ公共コンサルティングに提出します。

Sheet 建設改良費調査票
A1: 建設改良費調査票（女川町上下水道事業）
A2: ※将来の建設事業計画に基づき、事業ごと（施設別・金額規模別）に必要事項を入力してください。黄色のセルが入力箇所です。
A3: ※金額はすべて【税込み・千円単位】で入力してください。
A5: 【No.1】 事業名称： | C5: 老朽管布設替工事（詳細設計業務を含む） | N5: memo
A6: 資産種別 | B6: その他 | C6: 更新/新規 | D6: 更新 | E6: 補助/単独 | F6: 補助 | N6: 老朽管布設替工事については、基準内繰入可能であるが、更新率により金額上限が定まるため、全て企業債という厳しい状況で見込むものとする。
A7: 財源構成割合 (%) ※合計100% | E7: 償却条件 | G7: 企業債償還条件 | N7: また、送水管についても基準内で１／４を見込むことは可能だが、こちらも想定として除く。
A8: 国費 | B8: 企業債 | C8: 負担金 | D8: 繰入金 | E8: 償却年数 | F8: 残存価額 | G8: 利率(%) | H8: 据置期間 | I8: 償還年数 | J8: 方式
A9: =L14 -> 240000 | B9: =L15 -> 940000 | E9: 40 | H9: 3 | I9: 25 | J9: 元利均等
A11: 西暦 | B11: 2026 | C11: 2027 | D11: 2028 | E11: 2029 | F11: 2030 | G11: 2031 | H11: 2032 | I11: 2033 | J11: 2034 | K11: 2035 | L11: 合計
A12: 和暦 | B12: R8 | C12: R9 | D12: R10 | E12: R11 | F12: R12 | G12: R13 | H12: R14 | I12: R15 | J12: R16 | K12: R17
A13: 整備費（千円） | B13: 180000 | C13: 150000 | D13: 150000 | E13: 100000 | F13: 100000 | G13: 100000 | H13: 100000 | I13: 100000 | J13: 100000 | K13: 100000 | L13: =SUM(B13:K13) -> 1180000
A14: 財源：国費 | B14: 80000 | C14: 80000 | D14: 80000 | E14: 0 | F14: 0 | G14: 0 | H14: 0 | I14: 0 | J14: 0 | K14: 0 | L14: =SUM(B14:K14) -> 240000 | M14: 電源立地地域対策交付金
A15: 財源：企業債 | B15: 100000 | C15: 70000 | D15: 70000 | E15: 100000 | F15: 100000 | G15: 100000 | H15: 100000 | I15: 100000 | J15: 100000 | K15: 100000 | L15: =SUM(B15:K15) -> 940000
A16: 財源：負担金 | B16: =IFERROR(ROUNDDOWN(B13*($C$9/100), 0), 0) -> 0 | C16: =IFERROR(ROUNDDOWN(C13*($C$9/100), 0), 0) -> 0 | D16: =IFERROR(ROUNDDOWN(D13*($C$9/100), 0), 0) -> 0 | E16: =IFERROR(ROUNDDOWN(E13*($C$9/100), 0), 0) -> 0 | F16: =IFERROR(ROUNDDOWN(F13*($C$9/100), 0), 0) -> 0 | G16: =IFERROR(ROUNDDOWN(G13*($C$9/100), 0), 0) -> 0 | H16: =IFERROR(ROUNDDOWN(H13*($C$9/100), 0), 0) -> 0 | I16: =IFERROR(ROUNDDOWN(I13*($C$9/100), 0), 0) -> 0 | ... K16: =IFERROR(ROUNDDOWN(K13*($C$9/100), 0), 0) -> 0 | L16: =SUM(B16:K16) -> 0
A17: 財源：繰入金 | B17: =IFERROR(ROUNDDOWN(B13*($D$9/100), 0), 0) -> 0 | C17: =IFERROR(ROUNDDOWN(C13*($D$9/100), 0), 0) -> 0 | D17: =IFERROR(ROUNDDOWN(D13*($D$9/100), 0), 0) -> 0 | E17: =IFERROR(ROUNDDOWN(E13*($D$9/100), 0), 0) -> 0 | F17: =IFERROR(ROUNDDOWN(F13*($D$9/100), 0), 0) -> 0 | G17: =IFERROR(ROUNDDOWN(G13*($D$9/100), 0), 0) -> 0 | H17: =IFERROR(ROUNDDOWN(H13*($D$9/100), 0), 0) -> 0 | I17: =IFERROR(ROUNDDOWN(I13*($D$9/100), 0), 0) -> 0 | ... K17: =IFERROR(ROUNDDOWN(K13*($D$9/100), 0), 0) -> 0 | L17: =SUM(B17:K17) -> 0
A18: 財源：その他 | B18: =IFERROR(B13-SUM(B14:B17), 0) -> 0 | C18: =IFERROR(C13-SUM(C14:C17), 0) -> 0 | D18: =IFERROR(D13-SUM(D14:D17), 0) -> 0 | E18: =IFERROR(E13-SUM(E14:E17), 0) -> 0 | F18: =IFERROR(F13-SUM(F14:F17), 0) -> 0 | G18: =IFERROR(G13-SUM(G14:G17), 0) -> 0 | H18: =IFERROR(H13-SUM(H14:H17), 0) -> 0 | I18: =IFERROR(I13-SUM(I14:I17), 0) -> 0 | ... K18: =IFERROR(K13-SUM(K14:K17), 0) -> 0 | L18: =SUM(B18:K18) -> 0
A21: 【No.2】 事業名称： | C21: 水道施設耐震化工事（調査、設計を含む）
A22: 資産種別 | B22: 配水池 | C22: 更新/新規 | D22: 更新 | E22: 補助/単独 | F22: 補助 | N22: memo
A23: 財源構成割合 (%) ※合計100% | E23: 償却条件 | G23: 企業債償還条件 | N23: 岸田元首相主導の耐震化関連事業である。
A24: 国費 | B24: 企業債 | C24: 負担金 | D24: 繰入金 | E24: 償却年数 | F24: 残存価額 | G24: 利率(%) | H24: 据置期間 | I24: 償還年数 | J24: 方式 | N24: 国の求めに応じて令和7年度から配水池の耐震診断を実施している。
A25: =L30 -> 331000 | B25: =L31 -> 922500 | D25: =L34 -> 23500 | E25: 40 | H25: 3 | I25: 40 | J25: 元利均等 | N25: 耐震診断は令和９年度まで実施予定である。
N26: その後、町中心部で対応が必要となる工事を想定している。
A27: 西暦 | B27: 2026 | C27: 2027 | D27: 2028 | E27: 2029 | F27: 2030 | G27: 2031 | H27: 2032 | I27: 2033 | J27: 2034 | K27: 2035 | L27: 合計
A28: 和暦 | B28: R8 | C28: R9 | D28: R10 | E28: R11 | F28: R12 | G28: R13 | H28: R14 | I28: R15 | J28: R16 | K28: R17
A29: 整備費（千円） | B29: 12000 | C29: 35000 | D29: 60000 | E29: 220000 | F29: 220000 | G29: 220000 | H29: 60000 | I29: 150000 | J29: 150000 | K29: 150000 | L29: =SUM(B29:K29) -> 1277000
A30: 財源：国費 | B30: 6000 | C30: 17500 | D30: 15000 | E30: 55000 | F30: 55000 | G30: 55000 | H30: 15000 | I30: 37500 | J30: 37500 | K30: 37500 | L30: =SUM(B30:K30) -> 331000
A31: 財源：企業債 | B31: 0 | C31: 0 | D31: 45000 | E31: 165000 | F31: 165000 | G31: 165000 | H31: 45000 | I31: 112500 | J31: 112500 | K31: 112500 | L31: =SUM(B31:K31) -> 922500
A32: 財源：負担金 | B32: =IFERROR(ROUNDDOWN(B29*($C$25/100), 0), 0) -> 0 | C32: =IFERROR(ROUNDDOWN(C29*($C$25/100), 0), 0) -> 0 | D32: =IFERROR(ROUNDDOWN(D29*($C$25/100), 0), 0) -> 0 | E32: =IFERROR(ROUNDDOWN(E29*($C$25/100), 0), 0) -> 0 | F32: =IFERROR(ROUNDDOWN(F29*($C$25/100), 0), 0) -> 0 | G32: =IFERROR(ROUNDDOWN(G29*($C$25/100), 0), 0) -> 0 | H32: =IFERROR(ROUNDDOWN(H29*($C$25/100), 0), 0) -> 0 | I32: =IFERROR(ROUNDDOWN(I29*($C$25/100), 0), 0) -> 0 | ... K32: =IFERROR(ROUNDDOWN(K29*($C$25/100), 0), 0) -> 0 | L32: =SUM(B32:K32) -> 0
A33: 財源：繰入金 | B33: 0 | C33: 0 | D33: 0 | E33: 0 | F33: 0 | G33: 0 | H33: 0 | I33: 0 | J33: 0 | K33: 0 | L33: =SUM(B33:K33) -> 0
A34: 財源：その他 | B34: 6000 | C34: 17500 | D34: 0 | E34: 0 | F34: 0 | G34: 0 | H34: 0 | I34: 0 | J34: 0 | K34: 0 | L34: =SUM(B34:K34) -> 23500
A37: 【No.3】 事業名称： | C37: 鷲神高度処理設備整備工事
A38: 資産種別 | B38: 浄水場 | C38: 更新/新規 | D38: 新規 | E38: 補助/単独 | F38: 単独 | N38: memo
A39: 財源構成割合 (%) ※合計100% | E39: 償却条件 | G39: 企業債償還条件 | N39: 既に発注済みで令和９年度までの工事である。
A40: 国費 | B40: 企業債 | C40: 負担金 | D40: 繰入金 | E40: 償却年数 | F40: 残存価額 | G40: 利率(%) | H40: 据置期間 | I40: 償還年数 | J40: 方式 | N40: 新設である。
B41: 444000 | D41: 444000 | E41: 40 | H41: 3 | I41: 40 | J41: 元利均等 | N41: この施設新設により捨水量が減り、有収水量が増える見込みである。
N42: また、捨水減により動力費、薬品費等も減少見通しである。
A43: 西暦 | B43: 2026 | C43: 2027 | D43: 2028 | E43: 2029 | F43: 2030 | G43: 2031 | H43: 2032 | I43: 2033 | J43: 2034 | K43: 2035 | L43: 合計
A44: 和暦 | B44: R8 | C44: R9 | D44: R10 | E44: R11 | F44: R12 | G44: R13 | H44: R14 | I44: R15 | J44: R16 | K44: R17
A45: 整備費（千円） | B45: 353400 | C45: 534600 | L45: =SUM(B45:K45) -> 888000
A46: 財源：国費 | B46: =IFERROR(ROUNDDOWN(B45*($A$41/100), 0), 0) -> 0 | C46: =IFERROR(ROUNDDOWN(C45*($A$41/100), 0), 0) -> 0 | D46: =IFERROR(ROUNDDOWN(D45*($A$41/100), 0), 0) -> 0 | E46: =IFERROR(ROUNDDOWN(E45*($A$41/100), 0), 0) -> 0 | F46: =IFERROR(ROUNDDOWN(F45*($A$41/100), 0), 0) -> 0 | G46: =IFERROR(ROUNDDOWN(G45*($A$41/100), 0), 0) -> 0 | H46: =IFERROR(ROUNDDOWN(H45*($A$41/100), 0), 0) -> 0 | I46: =IFERROR(ROUNDDOWN(I45*($A$41/100), 0), 0) -> 0 | ... K46: =IFERROR(ROUNDDOWN(K45*($A$41/100), 0), 0) -> 0 | L46: =SUM(B46:K46) -> 0
...

Sheet 集計表
A1: 建設改良費 集計表（全事業合計）
A2: ※「建設改良費調査票」シート（No.1〜20）に入力された値が自動集計されます。
A4: 項目 \ 年度 | B4: 2026 (R8) | C4: 2027 (R9) | D4: 2028 (R10) | E4: 2029 (R11) | F4: 2030 (R12) | G4: 2031 (R13) | H4: 2032 (R14) | I4: 2033 (R15) | J4: 2034 (R16) | K4: 2035 (R17) | L4: 合計
A5: 総整備費 | B5: =SUM(建設改良費調査票!B13,建設改良費調査票!B29,建設改良費調査票!B45,建設改良費調査票!B61,建設改良費調査票!B77,建設改良費調査票!B93,建設改良費調査票!B109,建設改良費調査票!B125,建設改良費調査票!B141,建設改良費調査票!B157,建設改良費調査票!B173,建設改良費調査票!B189,建設改良費調査票!B205,建設改良費調査票!B221,建設改良費調査票!B237,建設改良費調査票!B253,建設改良費調査票!B269,建設改良費調査票!B285,建設改良費調査票!B301,建設改良費調査票!B317) -> 565400 | C5: =SUM(建設改良費調査票!C13,建設改良費調査票!C29,建設改良費調査票!C45,建設改良費調査票!C61,建設改良費調査票!C77,建設改良費調査票!C93,建設改良費調査票!C109,建設改良費調査票!C125,建設改良費調査票!C141,建設改良費調査票!C157,建設改良費調査票!C173,建設改良費調査票!C189,建設改良費調査票!C205,建設改良費調査票!C221,建設改良費調査票!C237,建設改良費調査票!C253,建設改良費調査票!C269,建設改良費調査票!C285,建設改良費調査票!C301,建設改良費調査票!C317) -> 869600 | D5: =SUM(建設改良費調査票!D13,建設改良費調査票!D29,建設改良費調査票!D45,建設改良費調査票!D61,建設改良費調査票!D77,建設改良費調査票!D93,建設改良費調査票!D109,建設改良費調査票!D125,建設改良費調査票!D141,建設改良費調査票!D157,建設改良費調査票!D173,建設改良費調査票!D189,建設改良費調査票!D205,建設改良費調査票!D221,建設改良費調査票!D237,建設改良費調査票!D253,建設改良費調査票!D269,建設改良費調査票!D285,建設改良費調査票!D301,建設改良費調査票!D317) -> 210000 | E5: =SUM(建設改良費調査票!E13,建設改良費調査票!E29,建設改良費調査票!E45,建設改良費調査票!E61,建設改良費調査票!E77,建設改良費調査票!E93,建設改良費調査票!E109,建設改良費調査票!E125,建設改良費調査票!E141,建設改良費調査票!E157,建設改良費調査票!E173,建設改良費調査票!E189,建設改良費調査票!E205,建設改良費調査票!E221,建設改良費調査票!E237,建設改良費調査票!E253,建設改良費調査票!E269,建設改良費調査票!E285,建設改良費調査票!E301,建設改良費調査票!E317) -> 320000 | F5: =SUM(建設改良費調査票!F13,建設改良費調査票!F29,建設改良費調査票!F45,建設改良費調査票!F61,建設改良費調査票!F77,建設改良費調査票!F93,建設改良費調査票!F109,建設改良費調査票!F125,建設改良費調査票!F141,建設改良費調査票!F157,建設改良費調査票!F173,建設改良費調査票!F189,建設改良費調査票!F205,建設改良費調査票!F221,建設改良費調査票!F237,建設改良費調査票!F253,建設改良費調査票!F269,建設改良費調査票!F285,建設改良費調査票!F301,建設改良費調査票!F317) -> 320000 | G5: =SUM(建設改良費調査票!G13,建設改良費調査票!G29,建設改良費調査票!G45,建設改良費調査票!G61,建設改良費調査票!G77,建設改良費調査票!G93,建設改良費調査票!G109,建設改良費調査票!G125,建設改良費調査票!G141,建設改良費調査票!G157,建設改良費調査票!G173,建設改良費調査票!G189,建設改良費調査票!G205,建設改良費調査票!G221,建設改良費調査票!G237,建設改良費調査票!G253,建設改良費調査票!G269,建設改良費調査票!G285,建設改良費調査票!G301,建設改良費調査票!G317) -> 320000 | H5: =SUM(建設改良費調査票!H13,建設改良費調査票!H29,建設改良費調査票!H45,建設改良費調査票!H61,建設改良費調査票!H77,建設改良費調査票!H93,建設改良費調査票!H109,建設改良費調査票!H125,建設改良費調査票!H141,建設改良費調査票!H157,建設改良費調査票!H173,建設改良費調査票!H189,建設改良費調査票!H205,建設改良費調査票!H221,建設改良費調査票!H237,建設改良費調査票!H253,建設改良費調査票!H269,建設改良費調査票!H285,建設改良費調査票!H301,建設改良費調査票!H317) -> 160000 | I5: =SUM(建設改良費調査票!I13,建設改良費調査票!I29,建設改良費調査票!I45,建設改良費調査票!I61,建設改良費調査票!I77,建設改良費調査票!I93,建設改良費調査票!I109,建設改良費調査票!I125,建設改良費調査票!I141,建設改良費調査票!I157,建設改良費調査票!I173,建設改良費調査票!I189,建設改良費調査票!I205,建設改良費調査票!I221,建設改良費調査票!I237,建設改良費調査票!I253,建設改良費調査票!I269,建設改良費調査票!I285,建設改良費調査票!I301,建設改良費調査票!I317) -> 250000 | ... K5: =SUM(建設改良費調査票!K13,建設改良費調査票!K29,建設改良費調査票!K45,建設改良費調査票!K61,建設改良費調査票!K77,建設改良費調査票!K93,建設改良費調査票!K109,建設改良費調査票!K125,建設改良費調査票!K141,建設改良費調査票!K157,建設改良費調査票!K173,建設改良費調査票!K189,建設改良費調査票!K205,建設改良費調査票!K221,建設改良費調査票!K237,建設改良費調査票!K253,建設改良費調査票!K269,建設改良費調査票!K285,建設改良費調査票!K301,建設改良費調査票!K317) -> 250000 | L5: =SUM(B5:K5) -> 3515000
A6: 財源：国費 | B6: =SUM(建設改良費調査票!B14,建設改良費調査票!B30,建設改良費調査票!B46,建設改良費調査票!B62,建設改良費調査票!B78,建設改良費調査票!B94,建設改良費調査票!B110,建設改良費調査票!B126,建設改良費調査票!B142,建設改良費調査票!B158,建設改良費調査票!B174,建設改良費調査票!B190,建設改良費調査票!B206,建設改良費調査票!B222,建設改良費調査票!B238,建設改良費調査票!B254,建設改良費調査票!B270,建設改良費調査票!B286,建設改良費調査票!B302,建設改良費調査票!B318) -> 86000 | C6: =SUM(建設改良費調査票!C14,建設改良費調査票!C30,建設改良費調査票!C46,建設改良費調査票!C62,建設改良費調査票!C78,建設改良費調査票!C94,建設改良費調査票!C110,建設改良費調査票!C126,建設改良費調査票!C142,建設改良費調査票!C158,建設改良費調査票!C174,建設改良費調査票!C190,建設改良費調査票!C206,建設改良費調査票!C222,建設改良費調査票!C238,建設改良費調査票!C254,建設改良費調査票!C270,建設改良費調査票!C286,建設改良費調査票!C302,建設改良費調査票!C318) -> 97500 | D6: =SUM(建設改良費調査票!D14,建設改良費調査票!D30,建設改良費調査票!D46,建設改良費調査票!D62,建設改良費調査票!D78,建設改良費調査票!D94,建設改良費調査票!D110,建設改良費調査票!D126,建設改良費調査票!D142,建設改良費調査票!D158,建設改良費調査票!D174,建設改良費調査票!D190,建設改良費調査票!D206,建設改良費調査票!D222,建設改良費調査票!D238,建設改良費調査票!D254,建設改良費調査票!D270,建設改良費調査票!D286,建設改良費調査票!D302,建設改良費調査票!D318) -> 95000 | E6: =SUM(建設改良費調査票!E14,建設改良費調査票!E30,建設改良費調査票!E46,建設改良費調査票!E62,建設改良費調査票!E78,建設改良費調査票!E94,建設改良費調査票!E110,建設改良費調査票!E126,建設改良費調査票!E142,建設改良費調査票!E158,建設改良費調査票!E174,建設改良費調査票!E190,建設改良費調査票!E206,建設改良費調査票!E222,建設改良費調査票!E238,建設改良費調査票!E254,建設改良費調査票!E270,建設改良費調査票!E286,建設改良費調査票!E302,建設改良費調査票!E318) -> 55000 | F6: =SUM(建設改良費調査票!F14,建設改良費調査票!F30,建設改良費調査票!F46,建設改良費調査票!F62,建設改良費調査票!F78,建設改良費調査票!F94,建設改良費調査票!F110,建設改良費調査票!F126,建設改良費調査票!F142,建設改良費調査票!F158,建設改良費調査票!F174,建設改良費調査票!F190,建設改良費調査票!F206,建設改良費調査票!F222,建設改良費調査票!F238,建設改良費調査票!F254,建設改良費調査票!F270,建設改良費調査票!F286,建設改良費調査票!F302,建設改良費調査票!F318) -> 55000 | G6: =SUM(建設改良費調査票!G14,建設改良費調査票!G30,建設改良費調査票!G46,建設改良費調査票!G62,建設改良費調査票!G78,建設改良費調査票!G94,建設改良費調査票!G110,建設改良費調査票!G126,建設改良費調査票!G142,建設改良費調査票!G158,建設改良費調査票!G174,建設改良費調査票!G190,建設改良費調査票!G206,建設改良費調査票!G222,建設改良費調査票!G238,建設改良費調査票!G254,建設改良費調査票!G270,建設改良費調査票!G286,建設改良費調査票!G302,建設改良費調査票!G318) -> 55000 | H6: =SUM(建設改良費調査票!H14,建設改良費調査票!H30,建設改良費調査票!H46,建設改良費調査票!H62,建設改良費調査票!H78,建設改良費調査票!H94,建設改良費調査票!H110,建設改良費調査票!H126,建設改良費調査票!H142,建設改良費調査票!H158,建設改良費調査票!H174,建設改良費調査票!H190,建設改良費調査票!H206,建設改良費調査票!H222,建設改良費調査票!H238,建設改良費調査票!H254,建設改良費調査票!H270,建設改良費調査票!H286,建設改良費調査票!H302,建設改良費調査票!H318) -> 15000 | I6: =SUM(建設改良費調査票!I14,建設改良費調査票!I30,建設改良費調査票!I46,建設改良費調査票!I62,建設改良費調査票!I78,建設改良費調査票!I94,建設改良費調査票!I110,建設改良費調査票!I126,建設改良費調査票!I142,建設改良費調査票!I158,建設改良費調査票!I174,建設改良費調査票!I190,建設改良費調査票!I206,建設改良費調査票!I222,建設改良費調査票!I238,建設改良費調査票!I254,建設改良費調査票!I270,建設改良費調査票!I286,建設改良費調査票!I302,建設改良費調査票!I318) -> 37500 | ... K6: =SUM(建設改良費調査票!K14,建設改良費調査票!K30,建設改良費調査票!K46,建設改良費調査票!K62,建設改良費調査票!K78,建設改良費調査票!K94,建設改良費調査票!K110,建設改良費調査票!K126,建設改良費調査票!K142,建設改良費調査票!K158,建設改良費調査票!K174,建設改良費調査票!K190,建設改良費調査票!K206,建設改良費調査票!K222,建設改良費調査票!K238,建設改良費調査票!K254,建設改良費調査票!K270,建設改良費調査票!K286,建設改良費調査票!K302,建設改良費調査票!K318) -> 37500 | L6: =SUM(B6:K6) -> 571000
A7: 財源：企業債 | B7: =SUM(建設改良費調査票!B15,建設改良費調査票!B31,建設改良費調査票!B47,建設改良費調査票!B63,建設改良費調査票!B79,建設改良費調査票!B95,建設改良費調査票!B111,建設改良費調査票!B127,建設改良費調査票!B143,建設改良費調査票!B159,建設改良費調査票!B175,建設改良費調査票!B191,建設改良費調査票!B207,建設改良費調査票!B223,建設改良費調査票!B239,建設改良費調査票!B255,建設改良費調査票!B271,建設改良費調査票!B287,建設改良費調査票!B303,建設改良費調査票!B319) -> 291700 | C7: =SUM(建設改良費調査票!C15,建設改良費調査票!C31,建設改良費調査票!C47,建設改良費調査票!C63,建設改良費調査票!C79,建設改良費調査票!C95,建設改良費調査票!C111,建設改良費調査票!C127,建設改良費調査票!C143,建設改良費調査票!C159,建設改良費調査票!C175,建設改良費調査票!C191,建設改良費調査票!C207,建設改良費調査票!C223,建設改良費調査票!C239,建設改良費調査票!C255,建設改良費調査票!C271,建設改良費調査票!C287,建設改良費調査票!C303,建設改良費調査票!C319) -> 449800 | D7: =SUM(建設改良費調査票!D15,建設改良費調査票!D31,建設改良費調査票!D47,建設改良費調査票!D63,建設改良費調査票!D79,建設改良費調査票!D95,建設改良費調査票!D111,建設改良費調査票!D127,建設改良費調査票!D143,建設改良費調査票!D159,建設改良費調査票!D175,建設改良費調査票!D191,建設改良費調査票!D207,建設改良費調査票!D223,建設改良費調査票!D239,建設改良費調査票!D255,建設改良費調査票!D271,建設改良費調査票!D287,建設改良費調査票!D303,建設改良費調査票!D319) -> 115000 | E7: =SUM(建設改良費調査票!E15,建設改良費調査票!E31,建設改良費調査票!E47,建設改良費調査票!E63,建設改良費調査票!E79,建設改良費調査票!E95,建設改良費調査票!E111,建設改良費調査票!E127,建設改良費調査票!E143,建設改良費調査票!E159,建設改良費調査票!E175,建設改良費調査票!E191,建設改良費調査票!E207,建設改良費調査票!E223,建設改良費調査票!E239,建設改良費調査票!E255,建設改良費調査票!E271,建設改良費調査票!E287,建設改良費調査票!E303,建設改良費調査票!E319) -> 265000 | F7: =SUM(建設改良費調査票!F15,建設改良費調査票!F31,建設改良費調査票!F47,建設改良費調査票!F63,建設改良費調査票!F79,建設改良費調査票!F95,建設改良費調査票!F111,建設改良費調査票!F127,建設改良費調査票!F143,建設改良費調査票!F159,建設改良費調査票!F175,建設改良費調査票!F191,建設改良費調査票!F207,建設改良費調査票!F223,建設改良費調査票!F239,建設改良費調査票!F255,建設改良費調査票!F271,建設改良費調査票!F287,建設改良費調査票!F303,建設改良費調査票!F319) -> 265000 | G7: =SUM(建設改良費調査票!G15,建設改良費調査票!G31,建設改良費調査票!G47,建設改良費調査票!G63,建設改良費調査票!G79,建設改良費調査票!G95,建設改良費調査票!G111,建設改良費調査票!G127,建設改良費調査票!G143,建設改良費調査票!G159,建設改良費調査票!G175,建設改良費調査票!G191,建設改良費調査票!G207,建設改良費調査票!G223,建設改良費調査票!G239,建設改良費調査票!G255,建設改良費調査票!G271,建設改良費調査票!G287,建設改良費調査票!G303,建設改良費調査票!G319) -> 265000 | H7: =SUM(建設改良費調査票!H15,建設改良費調査票!H31,建設改良費調査票!H47,建設改良費調査票!H63,建設改良費調査票!H79,建設改良費調査票!H95,建設改良費調査票!H111,建設改良費調査票!H127,建設改良費調査票!H143,建設改良費調査票!H159,建設改良費調査票!H175,建設改良費調査票!H191,建設改良費調査票!H207,建設改良費調査票!H223,建設改良費調査票!H239,建設改良費調査票!H255,建設改良費調査票!H271,建設改良費調査票!H287,建設改良費調査票!H303,建設改良費調査票!H319) -> 145000 | I7: =SUM(建設改良費調査票!I15,建設改良費調査票!I31,建設改良費調査票!I47,建設改良費調査票!I63,建設改良費調査票!I79,建設改良費調査票!I95,建設改良費調査票!I111,建設改良費調査票!I127,建設改良費調査票!I143,建設改良費調査票!I159,建設改良費調査票!I175,建設改良費調査票!I191,建設改良費調査票!I207,建設改良費調査票!I223,建設改良費調査票!I239,建設改良費調査票!I255,建設改良費調査票!I271,建設改良費調査票!I287,建設改良費調査票!I303,建設改良費調査票!I319) -> 212500 | ... K7: =SUM(建設改良費調査票!K15,建設改良費調査票!K31,建設改良費調査票!K47,建設改良費調査票!K63,建設改良費調査票!K79,建設改良費調査票!K95,建設改良費調査票!K111,建設改良費調査票!K127,建設改良費調査票!K143,建設改良費調査票!K159,建設改良費調査票!K175,建設改良費調査票!K191,建設改良費調査票!K207,建設改良費調査票!K223,建設改良費調査票!K239,建設改良費調査票!K255,建設改良費調査票!K271,建設改良費調査票!K287,建設改良費調査票!K303,建設改良費調査票!K319) -> 212500 | L7: =SUM(B7:K7) -> 2434000
A8: 財源：負担金 | B8: =SUM(建設改良費調査票!B16,建設改良費調査票!B32,建設改良費調査票!B48,建設改良費調査票!B64,建設改良費調査票!B80,建設改良費調査票!B96,建設改良費調査票!B112,建設改良費調査票!B128,建設改良費調査票!B144,建設改良費調査票!B160,建設改良費調査票!B176,建設改良費調査票!B192,建設改良費調査票!B208,建設改良費調査票!B224,建設改良費調査票!B240,建設改良費調査票!B256,建設改良費調査票!B272,建設改良費調査票!B288,建設改良費調査票!B304,建設改良費調査票!B320) -> 0 | C8: =SUM(建設改良費調査票!C16,建設改良費調査票!C32,建設改良費調査票!C48,建設改良費調査票!C64,建設改良費調査票!C80,建設改良費調査票!C96,建設改良費調査票!C112,建設改良費調査票!C128,建設改良費調査票!C144,建設改良費調査票!C160,建設改良費調査票!C176,建設改良費調査票!C192,建設改良費調査票!C208,建設改良費調査票!C224,建設改良費調査票!C240,建設改良費調査票!C256,建設改良費調査票!C272,建設改良費調査票!C288,建設改良費調査票!C304,建設改良費調査票!C320) -> 0 | D8: =SUM(建設改良費調査票!D16,建設改良費調査票!D32,建設改良費調査票!D48,建設改良費調査票!D64,建設改良費調査票!D80,建設改良費調査票!D96,建設改良費調査票!D112,建設改良費調査票!D128,建設改良費調査票!D144,建設改良費調査票!D160,建設改良費調査票!D176,建設改良費調査票!D192,建設改良費調査票!D208,建設改良費調査票!D224,建設改良費調査票!D240,建設改良費調査票!D256,建設改良費調査票!D272,建設改良費調査票!D288,建設改良費調査票!D304,建設改良費調査票!D320) -> 0 | E8: =SUM(建設改良費調査票!E16,建設改良費調査票!E32,建設改良費調査票!E48,建設改良費調査票!E64,建設改良費調査票!E80,建設改良費調査票!E96,建設改良費調査票!E112,建設改良費調査票!E128,建設改良費調査票!E144,建設改良費調査票!E160,建設改良費調査票!E176,建設改良費調査票!E192,建設改良費調査票!E208,建設改良費調査票!E224,建設改良費調査票!E240,建設改良費調査票!E256,建設改良費調査票!E272,建設改良費調査票!E288,建設改良費調査票!E304,建設改良費調査票!E320) -> 0 | F8: =SUM(建設改良費調査票!F16,建設改良費調査票!F32,建設改良費調査票!F48,建設改良費調査票!F64,建設改良費調査票!F80,建設改良費調査票!F96,建設改良費調査票!F112,建設改良費調査票!F128,建設改良費調査票!F144,建設改良費調査票!F160,建設改良費調査票!F176,建設改良費調査票!F192,建設改良費調査票!F208,建設改良費調査票!F224,建設改良費調査票!F240,建設改良費調査票!F256,建設改良費調査票!F272,建設改良費調査票!F288,建設改良費調査票!F304,建設改良費調査票!F320) -> 0 | G8: =SUM(建設改良費調査票!G16,建設改良費調査票!G32,建設改良費調査票!G48,建設改良費調査票!G64,建設改良費調査票!G80,建設改良費調査票!G96,建設改良費調査票!G112,建設改良費調査票!G128,建設改良費調査票!G144,建設改良費調査票!G160,建設改良費調査票!G176,建設改良費調査票!G192,建設改良費調査票!G208,建設改良費調査票!G224,建設改良費調査票!G240,建設改良費調査票!G256,建設改良費調査票!G272,建設改良費調査票!G288,建設改良費調査票!G304,建設改良費調査票!G320) -> 0 | H8: =SUM(建設改良費調査票!H16,建設改良費調査票!H32,建設改良費調査票!H48,建設改良費調査票!H64,建設改良費調査票!H80,建設改良費調査票!H96,建設改良費調査票!H112,建設改良費調査票!H128,建設改良費調査票!H144,建設改良費調査票!H160,建設改良費調査票!H176,建設改良費調査票!H192,建設改良費調査票!H208,建設改良費調査票!H224,建設改良費調査票!H240,建設改良費調査票!H256,建設改良費調査票!H272,建設改良費調査票!H288,建設改良費調査票!H304,建設改良費調査票!H320) -> 0 | I8: =SUM(建設改良費調査票!I16,建設改良費調査票!I32,建設改良費調査票!I48,建設改良費調査票!I64,建設改良費調査票!I80,建設改良費調査票!I96,建設改良費調査票!I112,建設改良費調査票!I128,建設改良費調査票!I144,建設改良費調査票!I160,建設改良費調査票!I176,建設改良費調査票!I192,建設改良費調査票!I208,建設改良費調査票!I224,建設改良費調査票!I240,建設改良費調査票!I256,建設改良費調査票!I272,建設改良費調査票!I288,建設改良費調査票!I304,建設改良費調査票!I320) -> 0 | ... K8: =SUM(建設改良費調査票!K16,建設改良費調査票!K32,建設改良費調査票!K48,建設改良費調査票!K64,建設改良費調査票!K80,建設改良費調査票!K96,建設改良費調査票!K112,建設改良費調査票!K128,建設改良費調査票!K144,建設改良費調査票!K160,建設改良費調査票!K176,建設改良費調査票!K192,建設改良費調査票!K208,建設改良費調査票!K224,建設改良費調査票!K240,建設改良費調査票!K256,建設改良費調査票!K272,建設改良費調査票!K288,建設改良費調査票!K304,建設改良費調査票!K320) -> 0 | L8: =SUM(B8:K8) -> 0
A9: 財源：繰入金 | B9: =SUM(建設改良費調査票!B17,建設改良費調査票!B33,建設改良費調査票!B49,建設改良費調査票!B65,建設改良費調査票!B81,建設改良費調査票!B97,建設改良費調査票!B113,建設改良費調査票!B129,建設改良費調査票!B145,建設改良費調査票!B161,建設改良費調査票!B177,建設改良費調査票!B193,建設改良費調査票!B209,建設改良費調査票!B225,建設改良費調査票!B241,建設改良費調査票!B257,建設改良費調査票!B273,建設改良費調査票!B289,建設改良費調査票!B305,建設改良費調査票!B321) -> 1569096000 | C9: =SUM(建設改良費調査票!C17,建設改良費調査票!C33,建設改良費調査票!C49,建設改良費調査票!C65,建設改良費調査票!C81,建設改良費調査票!C97,建設改良費調査票!C113,建設改良費調査票!C129,建設改良費調査票!C145,建設改良費調査票!C161,建設改良費調査票!C177,建設改良費調査票!C193,建設改良費調査票!C209,建設改良費調査票!C225,建設改良費調査票!C241,建設改良費調査票!C257,建設改良費調査票!C273,建設改良費調査票!C289,建設改良費調査票!C305,建設改良費調査票!C321) -> 2373624000 | D9: =SUM(建設改良費調査票!D17,建設改良費調査票!D33,建設改良費調査票!D49,建設改良費調査票!D65,建設改良費調査票!D81,建設改良費調査票!D97,建設改良費調査票!D113,建設改良費調査票!D129,建設改良費調査票!D145,建設改良費調査票!D161,建設改良費調査票!D177,建設改良費調査票!D193,建設改良費調査票!D209,建設改良費調査票!D225,建設改良費調査票!D241,建設改良費調査票!D257,建設改良費調査票!D273,建設改良費調査票!D289,建設改良費調査票!D305,建設改良費調査票!D321) -> 0 | E9: =SUM(建設改良費調査票!E17,建設改良費調査票!E33,建設改良費調査票!E49,建設改良費調査票!E65,建設改良費調査票!E81,建設改良費調査票!E97,建設改良費調査票!E113,建設改良費調査票!E129,建設改良費調査票!E145,建設改良費調査票!E161,建設改良費調査票!E177,建設改良費調査票!E193,建設改良費調査票!E209,建設改良費調査票!E225,建設改良費調査票!E241,建設改良費調査票!E257,建設改良費調査票!E273,建設改良費調査票!E289,建設改良費調査票!E305,建設改良費調査票!E321) -> 0 | F9: =SUM(建設改良費調査票!F17,建設改良費調査票!F33,建設改良費調査票!F49,建設改良費調査票!F65,建設改良費調査票!F81,建設改良費調査票!F97,建設改良費調査票!F113,建設改良費調査票!F129,建設改良費調査票!F145,建設改良費調査票!F161,建設改良費調査票!F177,建設改良費調査票!F193,建設改良費調査票!F209,建設改良費調査票!F225,建設改良費調査票!F241,建設改良費調査票!F257,建設改良費調査票!F273,建設改良費調査票!F289,建設改良費調査票!F305,建設改良費調査票!F321) -> 0 | G9: =SUM(建設改良費調査票!G17,建設改良費調査票!G33,建設改良費調査票!G49,建設改良費調査票!G65,建設改良費調査票!G81,建設改良費調査票!G97,建設改良費調査票!G113,建設改良費調査票!G129,建設改良費調査票!G145,建設改良費調査票!G161,建設改良費調査票!G177,建設改良費調査票!G193,建設改良費調査票!G209,建設改良費調査票!G225,建設改良費調査票!G241,建設改良費調査票!G257,建設改良費調査票!G273,建設改良費調査票!G289,建設改良費調査票!G305,建設改良費調査票!G321) -> 0 | H9: =SUM(建設改良費調査票!H17,建設改良費調査票!H33,建設改良費調査票!H49,建設改良費調査票!H65,建設改良費調査票!H81,建設改良費調査票!H97,建設改良費調査票!H113,建設改良費調査票!H129,建設改良費調査票!H145,建設改良費調査票!H161,建設改良費調査票!H177,建設改良費調査票!H193,建設改良費調査票!H209,建設改良費調査票!H225,建設改良費調査票!H241,建設改良費調査票!H257,建設改良費調査票!H273,建設改良費調査票!H289,建設改良費調査票!H305,建設改良費調査票!H321) -> 0 | I9: =SUM(建設改良費調査票!I17,建設改良費調査票!I33,建設改良費調査票!I49,建設改良費調査票!I65,建設改良費調査票!I81,建設改良費調査票!I97,建設改良費調査票!I113,建設改良費調査票!I129,建設改良費調査票!I145,建設改良費調査票!I161,建設改良費調査票!I177,建設改良費調査票!I193,建設改良費調査票!I209,建設改良費調査票!I225,建設改良費調査票!I241,建設改良費調査票!I257,建設改良費調査票!I273,建設改良費調査票!I289,建設改良費調査票!I305,建設改良費調査票!I321) -> 0 | ... K9: =SUM(建設改良費調査票!K17,建設改良費調査票!K33,建設改良費調査票!K49,建設改良費調査票!K65,建設改良費調査票!K81,建設改良費調査票!K97,建設改良費調査票!K113,建設改良費調査票!K129,建設改良費調査票!K145,建設改良費調査票!K161,建設改良費調査票!K177,建設改良費調査票!K193,建設改良費調査票!K209,建設改良費調査票!K225,建設改良費調査票!K241,建設改良費調査票!K257,建設改良費調査票!K273,建設改良費調査票!K289,建設改良費調査票!K305,建設改良費調査票!K321) -> 0 | L9: =SUM(B9:K9) -> 3942720000
A10: 財源：その他 | B10: =SUM(建設改良費調査票!B18,建設改良費調査票!B34,建設改良費調査票!B50,建設改良費調査票!B66,建設改良費調査票!B82,建設改良費調査票!B98,建設改良費調査票!B114,建設改良費調査票!B130,建設改良費調査票!B146,建設改良費調査票!B162,建設改良費調査票!B178,建設改良費調査票!B194,建設改良費調査票!B210,建設改良費調査票!B226,建設改良費調査票!B242,建設改良費調査票!B258,建設改良費調査票!B274,建設改良費調査票!B290,建設改良費調査票!B306,建設改良費調査票!B322) -> -1568908300 | C10: =SUM(建設改良費調査票!C18,建設改良費調査票!C34,建設改良費調査票!C50,建設改良費調査票!C66,建設改良費調査票!C82,建設改良費調査票!C98,建設改良費調査票!C114,建設改良費調査票!C130,建設改良費調査票!C146,建設改良費調査票!C162,建設改良費調査票!C178,建設改良費調査票!C194,建設改良費調査票!C210,建設改良費調査票!C226,建設改良費調査票!C242,建設改良費調査票!C258,建設改良費調査票!C274,建設改良費調査票!C290,建設改良費調査票!C306,建設改良費調査票!C322) -> -2373301700 | D10: =SUM(建設改良費調査票!D18,建設改良費調査票!D34,建設改良費調査票!D50,建設改良費調査票!D66,建設改良費調査票!D82,建設改良費調査票!D98,建設改良費調査票!D114,建設改良費調査票!D130,建設改良費調査票!D146,建設改良費調査票!D162,建設改良費調査票!D178,建設改良費調査票!D194,建設改良費調査票!D210,建設改良費調査票!D226,建設改良費調査票!D242,建設改良費調査票!D258,建設改良費調査票!D274,建設改良費調査票!D290,建設改良費調査票!D306,建設改良費調査票!D322) -> 0 | E10: =SUM(建設改良費調査票!E18,建設改良費調査票!E34,建設改良費調査票!E50,建設改良費調査票!E66,建設改良費調査票!E82,建設改良費調査票!E98,建設改良費調査票!E114,建設改良費調査票!E130,建設改良費調査票!E146,建設改良費調査票!E162,建設改良費調査票!E178,建設改良費調査票!E194,建設改良費調査票!E210,建設改良費調査票!E226,建設改良費調査票!E242,建設改良費調査票!E258,建設改良費調査票!E274,建設改良費調査票!E290,建設改良費調査票!E306,建設改良費調査票!E322) -> 0 | F10: =SUM(建設改良費調査票!F18,建設改良費調査票!F34,建設改良費調査票!F50,建設改良費調査票!F66,建設改良費調査票!F82,建設改良費調査票!F98,建設改良費調査票!F114,建設改良費調査票!F130,建設改良費調査票!F146,建設改良費調査票!F162,建設改良費調査票!F178,建設改良費調査票!F194,建設改良費調査票!F210,建設改良費調査票!F226,建設改良費調査票!F242,建設改良費調査票!F258,建設改良費調査票!F274,建設改良費調査票!F290,建設改良費調査票!F306,建設改良費調査票!F322) -> 0 | G10: =SUM(建設改良費調査票!G18,建設改良費調査票!G34,建設改良費調査票!G50,建設改良費調査票!G66,建設改良費調査票!G82,建設改良費調査票!G98,建設改良費調査票!G114,建設改良費調査票!G130,建設改良費調査票!G146,建設改良費調査票!G162,建設改良費調査票!G178,建設改良費調査票!G194,建設改良費調査票!G210,建設改良費調査票!G226,建設改良費調査票!G242,建設改良費調査票!G258,建設改良費調査票!G274,建設改良費調査票!G290,建設改良費調査票!G306,建設改良費調査票!G322) -> 0 | H10: =SUM(建設改良費調査票!H18,建設改良費調査票!H34,建設改良費調査票!H50,建設改良費調査票!H66,建設改良費調査票!H82,建設改良費調査票!H98,建設改良費調査票!H114,建設改良費調査票!H130,建設改良費調査票!H146,建設改良費調査票!H162,建設改良費調査票!H178,建設改良費調査票!H194,建設改良費調査票!H210,建設改良費調査票!H226,建設改良費調査票!H242,建設改良費調査票!H258,建設改良費調査票!H274,建設改良費調査票!H290,建設改良費調査票!H306,建設改良費調査票!H322) -> 0 | I10: =SUM(建設改良費調査票!I18,建設改良費調査票!I34,建設改良費調査票!I50,建設改良費調査票!I66,建設改良費調査票!I82,建設改良費調査票!I98,建設改良費調査票!I114,建設改良費調査票!I130,建設改良費調査票!I146,建設改良費調査票!I162,建設改良費調査票!I178,建設改良費調査票!I194,建設改良費調査票!I210,建設改良費調査票!I226,建設改良費調査票!I242,建設改良費調査票!I258,建設改良費調査票!I274,建設改良費調査票!I290,建設改良費調査票!I306,建設改良費調査票!I322) -> 0 | ... K10: =SUM(建設改良費調査票!K18,建設改良費調査票!K34,建設改良費調査票!K50,建設改良費調査票!K66,建設改良費調査票!K82,建設改良費調査票!K98,建設改良費調査票!K114,建設改良費調査票!K130,建設改良費調査票!K146,建設改良費調査票!K162,建設改良費調査票!K178,建設改良費調査票!K194,建設改良費調査票!K210,建設改良費調査票!K226,建設改良費調査票!K242,建設改良費調査票!K258,建設改良費調査票!K274,建設改良費調査票!K290,建設改良費調査票!K306,建設改良費調査票!K322) -> 0 | L10: =SUM(B10:K10) -> -3942210000
