Workbook

Sheet 表題
C6: むつ市 | F6: 御中
C17: 適正水道料金検討業務委託
C20: お見積書

Sheet お見積（PPP保守）
B2: 御 見 積 書
G4: =TODAY() -> 46121
B6: 羽幌町 | D6: 御中
G9: 〒060-0006 札幌市中央区北6条西24丁目YMﾋﾞﾙ
G10: TEL.(011)644-8988／FAX.(011)612-3717
B12: 下記のとおりお見積りいたします。
B13: ご精査の上何卒ご用命賜りますようお願い申し上げます。
B15: 件 名 | C15: 公会計管理システム利用
B17: 合計金額 | C17: =G42 -> 440000
F20: 納入期日 | G20: 別途お打合せ
F21: 納入場所 | G21: 貴自治体ご指定場所
F22: お支払条件 | G22: 納入月末締め翌月末現金
F23: 御見積有効期限 | G23: 御見積書発行日より１ケ月
B25: 品 名 | D25: 数 量 | E25: 単 位 | F25: 単 価 | G25: 金 額
B26: 1.ＰＰＰ保守 | D26: 1 | E26: 式 | G26: 400000
B40: 小 計 | G40: =+G26+G31+G36+G37 -> 400000
B41: 消 費 税 | G41: =INT(G40*0.1) -> 40000
B42: 合 計 | G42: =G40+G41 -> 440000
B43: 備考 | C43: 対象：令和５年度決算
C44: ※R6より、㈱吉岡経営センターからビズアップ公共コンサルティング㈱に社名変更となります。
B47: 見積内訳のご説明
B50: １．制度設計コンサルテーション
B51: ①仕訳パターン定義、②仕訳変換定義
B52: ・・・PPPで複式仕訳を発生させるための予算科目の組み合わせを定め（仕訳変換定義）、そ
B53: れに対して設定する複式仕訳を定める（仕訳パターン定義）。
B54: ③財務諸表科目・帳票定義
B55: ・・・PPPで財務諸表に表示するための科目と、出力する財務諸表のレイアウトを定める。
B57: ２．設計・カストマイズ・開発
B58: ①仕訳パターン、②仕訳変換定義、③財務諸表科目・帳票 設計、カスタマイズ
B59: ・・・仕訳パターン、仕訳変換定義、財務諸表科目・帳票レイアウトをPPPに設定するための
B60: CSVファイルを、個々の自治体様向けに作成する（使用している予算科目が各自治体
B61: 様で異なることがあるため）。
... B94: ・資産管理のための台帳機能を持っています。

Sheet お見積り（適正水道料金検討業務）全体
B2: 御 見 積 書
G4: =TODAY() -> 46121
B6: =+表題!C6 -> むつ市 | D6: 御中
B12: 下記のとおりお見積りいたします。
B13: ご精査の上何卒ご用命賜りますようお願い申し上げます。
B15: 件 名 | C15: 適正水道料金検討業務委託(３年総括）
B17: 合計金額 | C17: =G45 -> 9350000
F20: 納入期日 | G20: 別途お打合せ
F21: 納入場所 | G21: 貴自治体ご指定場所
F22: お支払条件 | G22: 納入月末締め翌月末現金
F23: 御見積有効期限 | G23: 御見積書発行日より１ケ月
B25: 品 名 | D25: 数 量 | E25: 単 位 | F25: 単 価 | G25: 金 額 | I25: 原価
B26: 適正水道料金検討業務委託 | G26: =SUM(G27:G31) -> 8500000
B27: １ 令和８年度（水道事業経営分析及び 予測シミュレーション策定業務委託） | D27: 1 | E27: 式 | G27: ='お見積り（水道事業経営分析及び予測シミュレーション策定業務委)'!G43 -> 800000 | I27: ？
I28: ？
B29: 2 令和９年度（水道ビジョン改定業務委託） | D29: 1 | E29: 式 | G29: ='お見積（水道ビジョン改定業務委託）'!G40 -> 5000000 | I29: ？
I30: ？
B31: ３ 令和10年度（料金改定検討支援業務） | D31: 1 | E31: 式 | G31: ='お見積り（料金改定支援）'!G43 -> 2700000 | I31: ？
I32: ？
I33: ？
I34: ？
B43: 小 計 | G43: =+G26 -> 8500000
B44: 消 費 税 | G44: =INT(G43*0.1) -> 850000
B45: 合 計 | G45: =G43+G44 -> 9350000
B46: 備考 | C46: 対象事業：水道事業
B50: 見積内訳のご説明
B53: １．制度設計コンサルテーション
B54: ①仕訳パターン定義、②仕訳変換定義
B55: ・・・PPPで複式仕訳を発生させるための予算科目の組み合わせを定め（仕訳変換定義）、そ
B56: れに対して設定する複式仕訳を定める（仕訳パターン定義）。
B57: ③財務諸表科目・帳票定義
B58: ・・・PPPで財務諸表に表示するための科目と、出力する財務諸表のレイアウトを定める。
B60: ２．設計・カストマイズ・開発
B61: ①仕訳パターン、②仕訳変換定義、③財務諸表科目・帳票 設計、カスタマイズ
B62: ・・・仕訳パターン、仕訳変換定義、財務諸表科目・帳票レイアウトをPPPに設定するための
B63: CSVファイルを、個々の自治体様向けに作成する（使用している予算科目が各自治体
B64: 様で異なることがあるため）。
... B97: ・資産管理のための台帳機能を持っています。

Sheet お見積り（水道事業経営分析及び予測シミュレーション策定業務委)
B2: 御 見 積 書
G4: =TODAY() -> 46121
B6: =+表題!C6 -> むつ市 | D6: 御中
B12: 下記のとおりお見積りいたします。
B13: ご精査の上何卒ご用命賜りますようお願い申し上げます。
B15: 件 名 | C15: 適正水道料金検討業務委託(令和８年度分）
B17: 合計金額 | C17: =G45 -> 880000
F20: 納入期日 | G20: 別途お打合せ
F21: 納入場所 | G21: 貴自治体ご指定場所
F22: お支払条件 | G22: 納入月末締め翌月末現金
F23: 御見積有効期限 | G23: 御見積書発行日より１ケ月
B25: 品 名 | D25: 数 量 | E25: 単 位 | F25: 単 価 | G25: 金 額 | I25: 原価
B26: 水道事業経営分析及び予測シミュレーション策定業務委託 | G26: =SUM(G27:G31) -> 800000
B27: １ 経営状況分析 | D27: 1 | E27: 式 | F27: 350000 | G27: =F27 -> 350000 | I27: ？
B28: ２ 現状シミュレーション | D28: 1 | E28: 式 | F28: 350000 | G28: =F28 -> 350000 | I28: ？
B29: ３ 審議会運営設計 | D29: 1 | E29: 式 | F29: 100000 | G29: =F29 -> 100000 | I29: ？
I30: ？
I31: ？
I32: ？
I33: ？
I34: ？
B43: 小 計 | G43: =+G26 -> 800000
B44: 消 費 税 | G44: =INT(G43*0.1) -> 80000
B45: 合 計 | G45: =G43+G44 -> 880000
B46: 備考 | C46: １ 経営状況分析 ・令和6年度決算分析 2 現状シミュレーション ・現状の投資計画等シミュレーション ・現状の給水人口推計 ・現状料金でシミュレーション 3 審議会運営設計 ・審議会構成員・条例改正などに関する助言等
B50: 見積内訳のご説明
B53: １．制度設計コンサルテーション
B54: ①仕訳パターン定義、②仕訳変換定義
B55: ・・・PPPで複式仕訳を発生させるための予算科目の組み合わせを定め（仕訳変換定義）、そ
B56: れに対して設定する複式仕訳を定める（仕訳パターン定義）。
B57: ③財務諸表科目・帳票定義
B58: ・・・PPPで財務諸表に表示するための科目と、出力する財務諸表のレイアウトを定める。
B60: ２．設計・カストマイズ・開発
B61: ①仕訳パターン、②仕訳変換定義、③財務諸表科目・帳票 設計、カスタマイズ
B62: ・・・仕訳パターン、仕訳変換定義、財務諸表科目・帳票レイアウトをPPPに設定するための
B63: CSVファイルを、個々の自治体様向けに作成する（使用している予算科目が各自治体
B64: 様で異なることがあるため）。
... B97: ・資産管理のための台帳機能を持っています。

Sheet お見積（水道ビジョン改定業務委託）
B2: 御 見 積 書
G4: =TODAY() -> 46121
B8: むつ市 | D8: 御中
B14: 下記のとおりお見積りいたします。
B15: ご精査の上何卒ご用命賜りますようお願い申し上げます。
B17: 件 名 | C17: 適正水道料金検討業務委託（R9年度分）
B19: 合計金額 | C19: =G42 -> 5500000
F22: 納入期日 | G22: 別途お打合せ
F23: 納入場所 | G23: 貴自治体ご指定場所
F24: お支払条件 | G24: 納入月末締め翌月末現金
F25: 御見積有効期限 | G25: 御見積書発行日より１ケ月
B27: 品 名 | D27: 数 量 | E27: 単 位 | F27: 単 価 | G27: 金 額
B28: 水道ビジョン改定業務委託
B29: １．水道事業の現状評価・課題 | D29: 1 | E29: 式 | G29: 800000
B30: ２．将来の事業予測 | D30: 1 | E30: 式 | G30: 1200000
B31: ３．理想像と目標設定 | D31: 1 | E31: 式 | G31: 400000
B32: ４．推進する実現方策 | D32: 1 | E32: 式 | G32: 400000
B33: ５．水道ビジョン（案）策定 | D33: 1 | E33: 式 | G33: 2000000
B34: ６．審議会発足及び運営支援 | D34: 1 | E34: 式 | G34: 200000
B40: 小 計 | G40: =SUM(G29:G39) -> 5000000
B41: 消 費 税 | G41: =INT(G40*0.1) -> 500000
B42: 合 計 | G42: =G40+G41 -> 5500000
B43: 備考 | C43: 対象事業：水道事業
B47: 見積内訳のご説明
B50: １．制度設計コンサルテーション
B51: ①仕訳パターン定義、②仕訳変換定義
B52: ・・・PPPで複式仕訳を発生させるための予算科目の組み合わせを定め（仕訳変換定義）、そ
B53: れに対して設定する複式仕訳を定める（仕訳パターン定義）。
B54: ③財務諸表科目・帳票定義
B55: ・・・PPPで財務諸表に表示するための科目と、出力する財務諸表のレイアウトを定める。
B57: ２．設計・カストマイズ・開発
B58: ①仕訳パターン、②仕訳変換定義、③財務諸表科目・帳票 設計、カスタマイズ
B59: ・・・仕訳パターン、仕訳変換定義、財務諸表科目・帳票レイアウトをPPPに設定するための
B60: CSVファイルを、個々の自治体様向けに作成する（使用している予算科目が各自治体
B61: 様で異なることがあるため）。
... B94: ・資産管理のための台帳機能を持っています。

Sheet お見積り（料金改定支援）
B2: 御 見 積 書
G4: =TODAY() -> 46121
B6: =+表題!C6 -> むつ市 | D6: 御中
B12: 下記のとおりお見積りいたします。
B13: ご精査の上何卒ご用命賜りますようお願い申し上げます。
B15: 件 名 | C15: 適正水道料金検討業務委託（令和10年度分）
B17: 合計金額 | C17: =G45 -> 2970000
F20: 納入期日 | G20: 別途お打合せ
F21: 納入場所 | G21: 貴自治体ご指定場所
F22: お支払条件 | G22: 納入月末締め翌月末現金
F23: 御見積有効期限 | G23: 御見積書発行日より１ケ月
B25: 品 名 | D25: 数 量 | E25: 単 位 | F25: 単 価 | G25: 金 額 | I25: 原価
B26: 料金改定検討支援業務 | G26: =SUM(G27:G31) -> 2700000
B27: 1 総括原価の算定 | D27: 1 | E27: 式 | F27: 700000 | G27: =F27 -> 700000 | I27: ？
B28: 2 料金体系の検討 | D28: 1 | E28: 式 | F28: 700000 | G28: =F28 -> 700000 | I28: ？
B29: 3 水道料金体系見直し案の策定 | D29: 1 | E29: 式 | F29: 800000 | G29: =F29 -> 800000 | I29: ？
B30: 4 審議会対応 | D30: 4 | E30: 回 | F30: 100000 | G30: =D30*F30 -> 400000 | I30: ？
B31: 5 パブリックコメント対応等 | D31: 1 | E31: 式 | F31: 100000 | G31: =D31*F31 -> 100000 | I31: ？
I32: ？
I33: ？
I34: ？
B43: 小 計 | G43: =+G26 -> 2700000
B44: 消 費 税 | G44: =INT(G43*0.1) -> 270000
B45: 合 計 | G45: =G43+G44 -> 2970000
B46: 備考 | C46: １ 総括原価の算定 ・料金対象経費の算定 ・料金対象経費の分解 ・使用者群の区分 ・料金対象経費の配賦 ２ 料金体系の検討 ・料金の設定 ・水量区分ごとの使用水量と料金収入の算定 ・料金改定率表の作成とシミュレーション ３ 水道料金体系見直し案の策定 ・1～２をもとに水道料金体系見直し案の策定を行います。 ４ 審議会対応 ・4 審議会については、令和10年度4回前後を想定しています。
B50: 見積内訳のご説明
B53: １．制度設計コンサルテーション
B54: ①仕訳パターン定義、②仕訳変換定義
B55: ・・・PPPで複式仕訳を発生させるための予算科目の組み合わせを定め（仕訳変換定義）、そ
B56: れに対して設定する複式仕訳を定める（仕訳パターン定義）。
B57: ③財務諸表科目・帳票定義
B58: ・・・PPPで財務諸表に表示するための科目と、出力する財務諸表のレイアウトを定める。
B60: ２．設計・カストマイズ・開発
B61: ①仕訳パターン、②仕訳変換定義、③財務諸表科目・帳票 設計、カスタマイズ
B62: ・・・仕訳パターン、仕訳変換定義、財務諸表科目・帳票レイアウトをPPPに設定するための
B63: CSVファイルを、個々の自治体様向けに作成する（使用している予算科目が各自治体
B64: 様で異なることがあるため）。
... B97: ・資産管理のための台帳機能を持っています。

Sheet ご支援先一覧
A1: ビズアップ公共コンサルティング株式会社
A3: ご支援先一覧（北海道分）
B5: 完全委託先 | D5: =COUNTIF(E9:E170,E9) -> 126 | E5: 件
B6: 一部支援先 | D6: =COUNTIF(E9:E170,E10) -> 7 | E6: 件 | G6: ※下記順不同
A8: 管区 | E8: 形態 | F8: 作業方法
A9: 石狩 | B9: 千歳市 | E9: 完全委託 | F9: PPP
B10: 恵庭市 | E10: 一部支援 | F10: 点検
B11: 当別町 | E11: 完全委託 | F11: PPP
B12: 新篠津村 | E12: 完全委託 | F12: 簡便法
B13: 道央廃棄物処理組合 | E13: 完全委託 | F13: 簡便法
A15: 管区 | E15: 形態 | F15: 作業方法
A16: 空知 | B16: 美唄市 | E16: 完全委託 | F16: PPP
B17: 芦別市 | E17: 完全委託 | F17: PPP
B18: 歌志内市 | E18: 完全委託 | F18: PPP
B19: 南幌町 | E19: 完全委託 | F19: PPP
B20: 長沼町 | E20: 完全委託 | F20: PPP
B21: 北竜町 | E21: 完全委託 | F21: PPP
B22: 妹背牛町 | E22: 完全委託 | F22: 簡便法
B23: 南空知葬斎組合 | E23: 完全委託 | F23: 簡便法
B24: 南空知公衆衛生組合 | E24: 完全委託 | F24: 簡便法
A26: 管区 | E26: 形態 | F26: 作業方法
A27: 後志 | B27: 黒松内町 | E27: 完全委託 | F27: PPP
B28: 蘭越町 | E28: 完全委託 | F28: PPP
B29: ニセコ町 | E29: 完全委託 | F29: PPP
B30: 真狩村 | E30: 完全委託 | F30: PPP
B31: 岩内町 | E31: 完全委託 | F31: PPP
B32: 積丹町 | E32: 完全委託 | F32: PPP
B33: 神恵内村 | E33: 完全委託 | F33: PPP
B34: 余市町 | E34: 完全委託 | F34: PPP
B35: 岩内・寿都地方消防組合 | E35: 完全委託 | F35: 簡便法
B36: 岩内地方衛生組合 | E36: 完全委託 | F36: 簡便法
B37: 羊蹄山ろく消防組合 | E37: 完全委託 | F37: PPP
B38: 羊蹄山麓環境衛生組合 | E38: 完全委託 | F38: 簡便法
B39: 北後志衛生組合 | E39: 完全委託 | F39: 簡便法
... B42: 南部後志環境衛生組合 | E42: 完全委託 | F42: 簡便法
A44: 管区 | E44: 形態 | F44: 作業方法
A45: 胆振 | B45: 伊達市 | E45: 完全委託 | F45: PPP
B46: 室蘭市 | E46: 完全委託 | F46: PPP
B47: 登別市 | E47: 完全委託 | F47: PPP
B48: 豊浦町 | E48: 完全委託 | F48: PPP
...
