Workbook
Name _A: #REF!
Name _L: #REF!
Name _P: #REF!
Name _R: #REF!
Name _X: #REF!
Name a: #REF!
Name ＣＯＤＥ: #REF!
Name Cood路: #REF!
Name inputarea: #REF!,#REF!,#REF!,#REF!,#REF!,#REF!,#REF!,#REF!,#REF!,#REF!,#REF!,#REF!,#REF!
Name inputarea2: #REF!,#REF!,#REF!,#REF!,#REF!,#REF!,#REF!,#REF!,#REF!,#REF!,#REF!,#REF!,#REF!
Name NO: #REF!
Name page: #REF!
Name page路: #REF!
Name ryoukin: #REF!
Name ryoukin2: #REF!
Name s10_0.10D: #REF!
Name s10_0.10L: #REF!
Name s10_0.35D: #REF!
Name s10_0.35L: #REF!
Name s10_0.60D: #REF!
Name s10_0.60L: #REF!
Name s2_0.10D: #REF!
Name s2_0.10L: #REF!
Name s4_0.20D: #REF!
Name s4_0.20L: #REF!
Name ten_T: #REF!
Name ten_T1: #REF!
Name おＰ: #REF!
Name ﾀﾌﾟ: #REF!
Name 安全費金入: #REF!
Name 安全費金抜: #REF!
Name 按分表: #REF!
Name 一号: #REF!
Name 運搬費単独金入: #REF!
Name 運搬費単独金抜: #REF!
Name 規模: #REF!
Name 給水土: #REF!
Name 金額: #REF!
Name 金入給水: #REF!
Name 金入消火栓: #REF!
Name 金抜給水: #REF!,#REF!
Name 金抜消火栓: #REF!,#REF!
Name 金抜配管1: #REF!,#REF!
Name 金抜配管2: #REF!,#REF!
Name 金抜配管3: #REF!,#REF!
Name 厚: #REF!
Name 工事総括単独金入: #REF!
Name 工事総括単独金抜: #REF!
Name 砂: #REF!
Name 消火栓土: #REF!
Name 人ﾌｨ: #REF!
Name 単位: #REF!
Name 当初_諸経費: #REF!
Name 配管土1: #REF!
Name 配管土2: #REF!
Name 配管土3: #REF!
Name 飛: #REF!
Name 歩掛入力表: [1]歩掛表新!$B$4:$Q$324
Name 歩車: #REF!
Name 名称: #REF!

Sheet 表紙
M10: 委託番号 | P10: 局財～第５号
B13: 令和8年度
B18: 水道事業経営分析及び予測シミュレーション策定業務委託
L22: (建設リサイクル法対象建設工事)
M25: 工事場所 | P25: むつ市大畑町大畑道地内
H29: む つ 市 上 下 水 道 局

Sheet 総括表
C1: 業 務 委 託 費 内 訳
B2: 工 種 | C2: 種 別 | D2: 細 別 | E2: 規 格 | F2: 単 位 | G2: 数 量 | H2: 単 価 | I2: 金 額 | J2: 摘 要
B5: 業務委託
C8: 業務委託費
D9: シミュレーション策定業務
F11: 式 | G11: 1 | I11: ='1.内訳書（設計）'!H41 -> 803000
C26: 合 計 | I26: =SUM(I11,I14,I17) -> 803000
C32: 消費税相当額 | F32: ％ | G32: 10 | I32: =(G32/100)*I26 -> 80300
C35: 業務委託費設計額 | I35: =ROUNDDOWN(I26+I32,0) -> 883300

Sheet 1.内訳書（設計）
B1: 委 託 費 内 訳 書 | I1: 内は変更後を示す
A2: 工 種 | B2: 種 別 | C2: 細 別 | D2: 規 格 | E2: 単 位 | F2: 数 量 | G2: 単 価 | H2: 金 額 | I2: 摘 要
A8: 直接人件費（A）
B11: 経営状況分析 | E11: 業務 | F11: 1 | H11: 90000
B14: 現状シミュレーション | E14: 業務 | F14: 1 | H14: 90000
B17: 審議会運営設計 | E17: 業務 | F17: 1 | H17: 25000
B23: 業務委託費計 | H23: =SUM(H11:H20) -> 205000
A26: 直接経費（B） | H26: =SUM(H29:H32) -> 207000
B29: 機器損料 | E29: 台日 | F29: 90 | G29: 500 | H29: =F29*G29 -> 45000 | I29: パソコン、プリンタ損料
B32: 交通費 | E32: 往復 | F32: 3 | G32: 54000 | H32: =F32*G32 -> 162000
A35: その他原価（C） | H35: =ROUNDDOWN(H23*0.35/(1-0.35),-3) -> 110000 | I35: 直接人件費（A）×0.35/（1-0.35）
A38: 一般管理費等（D） | H38: =ROUNDDOWN((H23+H26+H35)*0.35/(1-0.35),-3) -> 281000 | I38: （（A）+（B）+（C）)×0.35/（1-0.35）
A41: 小計 | H41: =H23+H26+H35+H38 -> 803000 | I41: （A）+（B）+（C）+（D）
A44: 消費税 | H44: =H41/10 -> 80300
A47: 合計 | H47: =SUM(H39:H44) -> 883300
L109: =ROUND(L110,2) -> 53.85
L110: =0.35/(1-0.35)*100 -> 53.846154
L116: =ROUNDDOWN(H113*F116/100,0) -> 0
L117: =SUM(H113+L116) -> 0
L118: =ROUNDDOWN(L117,-4) -> 0 | M118: =L118-L117 -> 0

Sheet 1号　設計協議等
B2: 1 | D2: 設計協議 | G2: 明 細 表 | K2: １業務当たり
C3: 工 種 ： | L3: 内は変更後を示す
B5: 名 称 | D5: 規 格 | F5: 単位 | G5: 数 量 | H5: 単 価 | I5: 金 額 | J5: 摘 要
B7: 第１回打合せ
B9: 主 任 技 師 | F9: 人
G10: 1 | H10: ='R７ 人件費単価'!$C$8 -> 66900 | I10: =INT(G10*H10) -> 66900
B11: 技 師 （A） | F11: 人
G12: 1 | H12: ='R７ 人件費単価'!$C$9 -> 59600 | I12: =ROUNDDOWN(G12*H12,0) -> 59600
B19: 計
I20: =SUM(I8,I12,I14,I10,I16) -> 126500
J31: 6
M32: 225
B35: 2 | D35: 設計協議 | G35: 明 細 表 | K35: １業務当たり
C36: 工 種 ： | L36: 内は変更後を示す
B38: 名 称 | D38: 規 格 | F38: 単位 | G38: 数 量 | H38: 単 価 | I38: 金 額 | J38: 摘 要
B40: 中間打合せ
D41: 1.0回
B42: 技 師 （A） | F42: 人
G43: 1 | H43: ='R７ 人件費単価'!$C$9 -> 59600 | I43: =ROUNDDOWN(G43*H43,0) -> 59600
B44: 技 師 （B） | F44: 人
G45: 1 | H45: ='R７ 人件費単価'!$C$10 -> 48500 | I45: =ROUNDDOWN(G45*H45,0) -> 48500
B52: 計
I53: =SUM(I41,I43,I45,I47,I49) -> 108100
J64: 6
M65: 225
B68: 3 | D68: 設計協議 | G68: 明 細 表 | K68: １業務当たり
C69: 工 種 ： | L69: 内は変更後を示す
B71: 名 称 | D71: 規 格 | F71: 単位 | G71: 数 量 | H71: 単 価 | I71: 金 額 | J71: 摘 要
B73: 最終打合せ
B75: 主 任 技 師 | F75: 人
G76: 1 | H76: ='R７ 人件費単価'!$C$8 -> 66900 | I76: =INT(G76*H76) -> 66900
B77: 技 師 （A） | F77: 人
G78: 1 | H78: ='R７ 人件費単価'!$C$9 -> 59600 | I78: =ROUNDDOWN(G78*H78,0) -> 59600
B85: 計
I86: =SUM(I74,I76,I78,I80,I82) -> 126500
J97: 6
M98: 225
H1277: ='R７ 人件費単価'!$C$12 -> 36100

Sheet ４号　現地調査
B2: 4 | D2: 現地調査 | G2: 明 細 表 | K2: １業務当たり
C3: 工 種 ： | L3: 内は変更後を示す
B5: 名 称 | D5: 規 格 | F5: 単位 | G5: 数 量 | H5: 単 価 | I5: 金 額 | J5: 摘 要
B7: 現地調査
B9: 主 任 技 師 | F9: 人
G10: 1.4 | H10: ='R７ 人件費単価'!$C$8 -> 66900 | I10: =INT(G10*H10) -> 93660
B11: 技 師 （A） | F11: 人
G12: 1.4 | H12: ='R７ 人件費単価'!$C$9 -> 59600 | I12: =INT(G12*H12) -> 83440
B13: 技 師 （B） | F13: 人
G14: 1.4 | H14: ='R７ 人件費単価'!$C$10 -> 48500 | I14: =INT(G14*H14) -> 67900
B19: 計
I20: =SUM(I8,I12,I14,I10,I16) -> 245000
J31: 6
M32: 225
H1204: ='R７ 人件費単価'!$C$12 -> 36100

Sheet ５号　水管橋添架詳細設計
B2: 5 | D2: 水管橋詳細設計 | G2: 明 細 表 | K2: １業務当たり | M2: １業務当たり
C3: 工 種 ： | D3: 添架形式 | F3: 33 | L3: 内は変更後を示す
B5: 名 称 | D5: 規 格 | F5: 単位 | G5: 数 量 | H5: 単 価 | I5: 金 額 | J5: 摘 要
B7: 設計計画
B9: 技 師 長 | F9: 人
G10: =ROUND(J10*L10*N10,3) -> 0 | H10: ='R７ 人件費単価'!$C$7 -> 77500 | I10: =INT(G10*H10) -> 0
B11: 主 任 技 師 | F11: 人 | J11: 標準歩掛 | L11: (1)補正 | N11: (２)補正
G12: =ROUND(J12*L12*N12,3) -> 0.566 | H12: ='R７ 人件費単価'!$C$8 -> 66900 | I12: =INT(G12*H12) -> 37865 | J12: 0.5 | K12: × | L12: =G$28 -> 0.9 | M12: × | N12: =G$30 -> 1.258
B13: 技 師 （A） | F13: 人 | J13: 標準歩掛 | L13: (1)補正 | N13: (２)補正
G14: =ROUND(J14*L14*N14,3) -> 0.906 | H14: ='R７ 人件費単価'!$C$9 -> 59600 | I14: =INT(G14*H14) -> 53997 | J14: 0.8 | K14: × | L14: =G$28 -> 0.9 | M14: × | N14: =G$30 -> 1.258
B15: 技 師 （B） | F15: 人
G16: =ROUND(J16*L16*N16,3) -> 0 | H16: ='R７ 人件費単価'!$C$10 -> 48500 | I16: =INT(G16*H16) -> 0
B17: 技 師 （C） | F17: 人
G18: =ROUND(J18*L18*N18,3) -> 0 | H18: ='R７ 人件費単価'!$C$11 -> 40300 | I18: =INT(G18*H18) -> 0
B19: 技 術 員 | F19: 人
G20: =ROUND(J20*L20*N20,3) -> 0 | H20: ='R７ 人件費単価'!$C$12 -> 36100 | I20: =INT(G20*H20) -> 0
B23: 計
I24: =SUM(I10,I12,I14,I16,I18,I20) -> 91862
B27: （１）添架形式補正
C28: 添架形式のため各歩掛－１０％ | G28: 0.9
B29: （２）橋長補正 | C29: （基本設計なしのため0.05を加算）
C30: Y=（１．５９９×橋長33.0m＋68.02）／１００ | G30: =ROUND((1.599*F3+68.02)/100,3)+0.05 -> 1.258
J31: 6
N32: 226
B35: =B2+1 -> 6 | D35: 水管橋詳細設計 | G35: 明 細 表 | K35: １業務当たり | M35: １業務当たり
C36: 工 種 ： | D36: 添架形式 | F36: 33 | L36: 内は変更後を示す
B38: 名 称 | D38: 規 格 | F38: 単位 | G38: 数 量 | H38: 単 価 | I38: 金 額 | J38: 摘 要
B40: 設計計算
B42: 技 師 長 | F42: 人
G43: =ROUND(J43*L43*N43,3) -> 0 | H43: ='R７ 人件費単価'!$C$7 -> 77500 | I43: =INT(G43*H43) -> 0
B44: 主 任 技 師 | F44: 人 | J44: 標準歩掛 | L44: (1)補正 | N44: (２)補正
G45: =ROUND(J45*L45*N45,3) -> 0.679 | H45: ='R７ 人件費単価'!$C$8 -> 66900 | I45: =INT(G45*H45) -> 45425 | J45: 0.6 | K45: × | L45: =G$28 -> 0.9 | M45: × | N45: =G$30 -> 1.258
B46: 技 師 （A） | F46: 人 | J46: 標準歩掛 | L46: (1)補正 | N46: (２)補正
G47: =ROUND(J47*L47*N47,3) -> 0.566 | H47: ='R７ 人件費単価'!$C$9 -> 59600 | I47: =INT(G47*H47) -> 33733 | J47: 0.5 | K47: × | L47: =G$28 -> 0.9 | M47: × | N47: =G$30 -> 1.258
B48: 技 師 （B） | F48: 人 | J48: 標準歩掛 | L48: (1)補正 | N48: (２)補正
G49: =ROUND(J49*L49*N49,3) -> 2.264 | H49: ='R７ 人件費単価'!$C$10 -> 48500 | I49: =INT(G49*H49) -> 109804 | J49: 2 | K49: × | L49: =G$28 -> 0.9 | M49: × | N49: =G$30 -> 1.258
B50: 技 師 （C） | F50: 人 | J50: 標準歩掛 | L50: (1)補正 | N50: (２)補正
G51: =ROUND(J51*L51*N51,3) -> 2.604 | H51: ='R７ 人件費単価'!$C$11 -> 40300 | I51: =INT(G51*H51) -> 104941 | J51: 2.3 | K51: × | L51: =G$28 -> 0.9 | M51: × | N51: =G$30 -> 1.258
B52: 技 術 員 | F52: 人
G53: =ROUND(J53*L53*N53,3) -> 0 | H53: ='R７ 人件費単価'!$C$12 -> 36100 | I53: =INT(G53*H53) -> 0
...

Sheet R７　人件費単価
B3: 2025年度
B4: 令和7年度 人件費単価
B5: 職種 | C5: 単価
B6: 主任技術者 | C6: 88600
B7: 技 師 長 | C7: 77500
B8: 主 任 技 師 | C8: 66900
B9: 技 師 (Ａ) | C9: 59600
B10: 技 師 (Ｂ) | C10: 48500
B11: 技 師 (Ｃ) | C11: 40300
B12: 技 術 員 | C12: 36100
B14: 測量上級主任技師
B15: 測量主任技師 | C15: 60600
B16: 測量技師 | C16: 52300
B17: 測量技師補 | C17: 41100
B18: 測量助手 | C18: 34900
B19: 測量補助員 | C19: 28700
B21: 地質調査技師 | C21: 56000
B22: 主任地質調査員 | C22: 43800
B23: 地質調査員 | C23: 34100
B25: 普通作業員 | C25: 21700
B26: 軽作業員 | C26: 18100
