Workbook

Sheet ＣＦ (提出用・千円)
B2: 令和７年度小野町水道事業 予定キャッシュ・フロー計算書
B3: (令和７年４月１日～令和８年３月３１日)
X4: (単位：千円)
C6: １ 業務活動によるキャッシュ・フロー | P6: ２ 投資活動によるキャッシュ・フロー | AC6: ◎「減価償却費、長期前受金戻入額、受取利息及び受取配当金、支払利息、建設改良企業債の償還による支出」は、予算書の数値（千円単位）と一致するようにすること ◎「当年度純利益、資金期末残高」は損益計算書、貸借対照表の数値を四捨五入したものと一致させること ◎純利益と純損失の計算に注意すること。
D7: 当年度純利益 | K7: =ROUND(入力シート!W19/1000,1) -> 9823.4 | Q7: 固定資産取得による支出 | X7: =ROUND(入力シート!W36/1000,1) -> -53820.3
D8: 減価償却費 | K8: =ROUND(入力シート!W20/1000,1)+1 -> 77957.6 | Q8: 国庫補助金による収入 | X8: =ROUND(入力シート!W37/1000,1) -> 0
D9: 長期前受金戻入額 | K9: =ROUND(入力シート!W22/1000,1) -> -27053 | Q9: 一般会計からの繰入金等による収入 | X9: =ROUNDDOWN(入力シート!W38/1000,0) -> 30355
D10: 受取利息及び受取配当金 | K10: =ROUND(入力シート!W23/1000,1) -> -1 | P10: ② | Q10: 投資活動によるキャッシュ・フロー | X10: =X7+X8+X9 -> -23465.3
D11: 支払利息 | K11: =ROUND(入力シート!W24/1000,1)+1 -> 4721.7
A12: 1 | D12: 未収金の増加額 | K12: =ROUNDDOWN(入力シート!W26/1000,1) -> -14476 | P12: ３ 財務活動によるキャッシュ・フロー
A13: 2 | D13: 未払金・その他流動負債の増加額 | K13: =ROUND(入力シート!W27/1000,1)+1 -> 6849.9 | Q13: 建設改良企業債による収入 | X13: =ROUND(入力シート!W42/1000,1) -> 9000
A14: 1 | D14: たな卸資産の増加額 | K14: =ROUND(入力シート!W28/1000,1) -> -275.5 | Q14: 建設改良企業債の償還による支出 | X14: =ROUNDUP(入力シート!W43/1000,0) -> -38276
D15: 前払金・その他流動資産の減少額 | K15: =ROUND(入力シート!W29/1000,1) -> 1240 | P15: ③ | Q15: 財務活動によるキャッシュ・フロー | X15: =SUM(X12:Z14) -> -29276
D16: 小計 | K16: =ROUNDDOWN(SUM(K7:M15),0) -> 58787
D17: 利息及び配当金の受取額 | K17: =ROUND(入力シート!W31/1000,1) -> 1 | P17: 資金増減額（①+②+③） | X17: =ROUND(K19+X10+X15,0) -> 1325
D18: 利息の支払額 | K18: =ROUND(入力シート!W32/1000,0)-1 -> -4722 | P18: 資金期首残高 | X18: =ROUND(入力シート!W48/1000,0) -> 85414
C19: ① | D19: 業務活動によるキャッシュ・フロー | K19: =SUM(K16:M18) -> 54066 | P19: 資金期末残高 | X19: =SUM(X17:Z18) -> 86739

Sheet ＣＦ（資料・円）
D3: 予定キャッシュ・フロー計算書
D4: (令和６年４月１日～令和７年３月３１日)
R6: (単位：円)
C8: １ 業務活動によるキャッシュ・フロー
D9: 当年度純利益 | R9: =入力シート!W19 -> 9823378 | W9: 減価償却 予算 | X9: 有形 | Y9: 無形 | Z9: 計
D10: 減価償却費 | R10: =入力シート!W20 -> 77956621 | W10: 小計 | X10: 78358225 | Y10: 4726365 | Z10: =SUM(X10:Y10) -> 83084590
D11: 退職給付引当金の減少額 | R11: =入力シート!W21 -> 0
D12: 長期前受金戻入額 | R12: =入力シート!W22 -> -27053042 | W12: 長期前受金 予算 | X12: 23178218
D13: 受取利息及び受取配当金 | R13: =入力シート!W23 -> -1000 | W13: 利息 予算 | X13: 1000
D14: 支払利息 | R14: =入力シート!W24 -> 4720739 | W14: 償還利息 予算 | X14: 企業債 | Y14: 一般会計 | Z14: 計
D15: 固定資産除却損 | R15: =入力シート!W25 -> 0
D16: 未収金の増加額 | R16: =入力シート!W26 -> -14476028 | W16: 小計 | X16: 7936172 | Y16: 138221 | Z16: =SUM(X16:Y16) -> 8074393
D17: 未払金・その他流動負債の減少額 | R17: =入力シート!W27 -> 6848883
D18: たな卸資産の増加額 | R18: =入力シート!W28 -> -275455
D19: 前払金・その他流動資産の減少額 | R19: =入力シート!W29 -> 1240000 | W19: 貸倒引当金 予算 | X19: 1298000
D20: 小計 | R20: =入力シート!W30 -> 58784096
D21: 利息及び配当金の受取額 | R21: =入力シート!W31 -> 1000 | W21: 利息 予算 | X21: =X13 -> 1000
D22: 利息の支払額 | R22: =入力シート!W32 -> -4720739 | W22: 償還利息 予算 | X22: 企業債 | Y22: 一般会計 | Z22: 計
C23: ① | D23: 業務活動によるキャッシュ・フロー | R23: =入力シート!W33 -> 54064357 | W23: 小計 | X23: 7936172 | Y23: 138221 | Z23: =SUM(X23:Y23) -> 8074393
C28: ２ 投資活動によるキャッシュ・フロー
D29: 固定資産取得による支出 | R29: =入力シート!W36 -> -53820344
D30: 国庫補助金等による収入 | R30: =入力シート!W37 -> 0
D31: 一般会計又は他の特別会計からの繰入金による収入 | R31: =入力シート!W38 -> 30355454
C32: ② | D32: 投資活動によるキャッシュ・フロー | R32: =入力シート!W39 -> -23464890
C34: ３ 財務活動によるキャッシュ・フロー
D35: 建設改良企業債による収入 | R35: =入力シート!W42 -> 9000000 | W35: 企業債 予算 | X35: 11900000
D36: 建設改良企業債の償還による支出 | R36: =入力シート!W43 -> -38275211 | W36: 償還金 予算 | X36: 企業債 | Y36: 一般会計 | Z36: 計
D37: 他会計からの出資による収入 | R37: =入力シート!W45 -> -29275211 | W37: 小計 | X37: 74382 | Y37: 4727 | Z37: =SUM(X37:Y37) -> 79109
C38: ③ | D38: 財務活動によるキャッシュ・フロー | R38: =入力シート!W45 -> -29275211 | W38: 小計 | X38: 26371383 | Y38: 1360667 | Z38: =SUM(X38:Y38) -> 27732050
C40: 資金増減額（①+②+③） | R40: =入力シート!W47 -> 1324256
C41: 資金期首残高 | R41: =入力シート!W48 -> 85414342 | W41: 98450472 | X41: 平成30年度決算金額
C42: 資金期末残高 | R42: =入力シート!W49 -> 86738598

Sheet 入力シート
A1: キャッシュフロー計算書ワークシート(間接法) | D1: （単位：千円）
B2: 貸借対照表 | D2: 45747 | E2: 46112 | F2: 増減 | H2: 減価償却費 | I2: 退職給付 引当金 | J2: 長期前受金 戻入 | K2: 受取利息 | L2: 支払利息 | M2: 固定資産除却 | N2: 資産・負債 増減 | O2: 固定資産取得 | P2: 国庫補助金 | Q2: 他会計負担金 | R2: 他会計出資金 | S2: 企業債発行 | T2: 企業債償還 | U2: 利益剰余金 | V2: 現金及び預金振替 | W2: 合計
B3: 資産の部 | C3: 固定資産・取得価格 | D3: 4132066682 | E3: =4132066682+53820344 -> 4185887026 | F3: =E3-D3 -> 53820344 | O3: =-F3 -> -53820344 | W3: =F3+SUM(H3:V3) -> 0
C4: 固定資産・減価償却累計額 | D4: -2511104850 | E4: =-2511104850+-77956621 -> -2589061471 | F4: =E4-D4 -> -77956621 | H4: =-F4 -> 77956621 | W4: =F4+SUM(H4:V4) -> 0
C5: 現金及び預金 | D5: 85414342 | E5: 86738598 | F5: =E5-D5 -> 1324256 | V5: =-F5 -> -1324256 | W5: =F5+SUM(H5:V5) -> 0
C6: 未収金 | D6: 103144075 | E6: 117620103 | F6: =E6-D6 -> 14476028 | N6: =-F6 -> -14476028 | W6: =F6+SUM(H6:V6) -> 0
C7: 貯蔵品 | D7: 2165552 | E7: =2165552+275455 -> 2441007 | F7: =E7-D7 -> 275455 | N7: =-F7 -> -275455 | W7: =F7+SUM(H7:V7) -> 0
C8: 前払金・その他流動資産 | D8: -15242370 | E8: =-15242370+-1240000 -> -16482370 | F8: =E8-D8 -> -1240000 | N8: =-F8 -> 1240000 | W8: =F8+SUM(H8:V8) -> 0
B9: 負債の部 | C9: 建設改良による企業債 | D9: -380242597 | E9: -350967386 | F9: =E9-D9 -> 29275211 | S9: 9000000 | T9: -38275211 | W9: =F9+SUM(H9:V9) -> 0
C10: 退職給付引当金 | D10: 0 | E10: 0 | F10: =E10-D10 -> 0 | W10: =F10+SUM(H10:V10) -> 0
C11: 未払金・前受金・その他流動負債 | D11: -71674328 | E11: =-79796211+1273000 -> -78523211 | F11: =E11-D11 -> -6848883 | N11: =-F11 -> 6848883 | W11: =F11+SUM(H11:V11) -> 0
C12: 長期前受金 | D12: -515343971 | E12: -518646383 | F12: =E12-D12 -> -3302412 | J12: -27053042 | Q12: 30355454 | W12: =F12+SUM(H12:V12) -> 0
B13: 資本の部 | C13: 資本金 | D13: -652165550 | E13: -652165550 | F13: =E13-D13 -> 0 | W13: =F13+SUM(H13:V13) -> 0
C14: 受贈財産評価額等 | D14: -61231146 | E14: -61231146 | F14: =E14-D14 -> 0 | O14: 0 | W14: =F14+SUM(H14:V14) -> 0
C15: 利益剰余金 | D15: -116332357 | E15: -126155735 | F15: =E15-D15 -> -9823378 | U15: =-F15 -> 9823378 | W15: =F15+SUM(H15:V15) -> 0
D16: =SUM(D3:D15) -> -546518 | E16: =SUM(E3:E15) -> -546518 | F16: =SUM(F3:F15) -> 0 | H16: =SUM(H3:H15) -> 77956621 | I16: =SUM(I3:I15) -> 0 | J16: =SUM(J3:J15) -> -27053042 | K16: =SUM(K3:K15) -> 0 | L16: =SUM(L3:L15) -> 0 | M16: =SUM(M3:M15) -> 0 | N16: =SUM(N3:N15) -> -6662600 | O16: =SUM(O3:O15) -> -53820344 | ... V16: =SUM(V3:V15) -> -1324256 | W16: =F16+SUM(H16:V16) -> 0
C17: キャッシュフロー計算書
C18: Ⅰ営業活動によるキャッシュ・フロー：
C19: 当年度純利益 | U19: 9823378 | W19: =SUM(H19:V19) -> 9823378
C20: 減価償却費 | H20: =H16 -> 77956621 | W20: =SUM(H20:V20) -> 77956621
C21: 退職給付引当金の減少額 | W21: =SUM(H21:V21) -> 0
C22: 長期前受金戻入額 | J22: =J16 -> -27053042 | W22: =SUM(H22:V22) -> -27053042
C23: 受取利息及び受取配当金 | K23: -1000 | W23: =SUM(H23:V23) -> -1000
C24: 支払利息 | L24: 4720739 | W24: =SUM(H24:V24) -> 4720739
C25: 固定資産除却損 | W25: =SUM(H25:V25) -> 0
C26: 未収金の増加額 | N26: =N6 -> -14476028 | W26: =SUM(H26:V26) -> -14476028
C27: 未払金の増加額 | N27: =N11 -> 6848883 | W27: =SUM(H27:V27) -> 6848883
C28: たな卸資産の増加額 | N28: =N7 -> -275455 | W28: =SUM(H28:V28) -> -275455
C29: 前払金・その他流動資産の減少額 | N29: =N8 -> 1240000 | W29: =SUM(H29:V29) -> 1240000
C30: 小計 | H30: =SUM(H19:H29) -> 77956621 | I30: =SUM(I19:I29) -> 0 | J30: =SUM(J19:J29) -> -27053042 | K30: =SUM(K19:K29) -> -1000 | L30: =SUM(L19:L29) -> 4720739 | M30: =SUM(M19:M29) -> 0 | N30: =SUM(N19:N29) -> -6662600 | O30: =SUM(O19:O29) -> 0 | ... V30: =SUM(V19:V29) -> 0 | W30: =SUM(H30:V30) -> 58784096
C31: 利息及び配当金の受取額 | K31: =-K23 -> 1000 | W31: =SUM(H31:V31) -> 1000
C32: 利息の支払額 | L32: =-L24 -> -4720739 | W32: =SUM(H32:V32) -> -4720739
C33: 営業活動によるキャッシュ・フロー | H33: =H30 -> 77956621 | I33: =I30 -> 0 | J33: =J30 -> -27053042 | K33: =K30+K31 -> 0 | L33: =L30+L32 -> 0 | M33: =M30 -> 0 | N33: =N30 -> -6662600 | O33: =O30 -> 0 | P33: =P30 -> 0 | Q33: =Q30 -> 0 | R33: =R30 -> 0 | S33: =S30 -> 0 | T33: =T30 -> 0 | ... V33: =V30 -> 0 | W33: =SUM(H33:V33) -> 54064357
W34: =SUM(H34:V34) -> 0
C35: Ⅱ投資活動によるキャッシュ・フロー | W35: =SUM(H35:V35) -> 0
C36: 固定資産取得による支出 | O36: =O16 -> -53820344 | W36: =SUM(H36:V36) -> -53820344
C37: 国庫補助金等による収入 | P37: =P16 -> 0 | W37: =SUM(H37:V37) -> 0
C38: 一般会計又は他の特別会計からの繰入金による収入 | Q38: =Q16 -> 30355454 | W38: =SUM(H38:V38) -> 30355454
C39: 投資活動によるキャッシュ・フロー | N39: =SUM(N36:N38) -> 0 | O39: =SUM(O36:O38) -> -53820344 | P39: =SUM(P36:P38) -> 0 | Q39: =SUM(Q36:Q38) -> 30355454 | W39: =SUM(H39:V39) -> -23464890
W40: =SUM(H40:V40) -> 0
...

Sheet ＣＦ（参考・円）
D3: 予定キャッシュ・フロー計算書
D4: (平成３１年４月１日～平成３２年３月３１日)
R6: (単位：千円)
C8: １ 業務活動によるキャッシュ・フロー
D9: 当年度純損失 | R9: =入力シート!W19 -> 9823378
D10: 減価償却費 | R10: =入力シート!W20 -> 77956621
D11: 退職給付引当金の減少額 | R11: =入力シート!W21 -> 0
D12: 長期前受金戻入額 | R12: =入力シート!W22 -> -27053042
D13: 受取利息及び受取配当金 | R13: =入力シート!W23 -> -1000
D14: 支払利息 | R14: =入力シート!W24 -> 4720739
D15: 固定資産除却損 | R15: =入力シート!W25 -> 0
D16: 未収金の減少額 | R16: =入力シート!W26 -> -14476028 | W16: 未収金の減→現金が収入になった→ＣＦではプラス
D17: 未払金・その他流動負債の減少額 | R17: =入力シート!W27 -> 6848883 | W17: 未払金の減→現金を支出した→ＣＦではマイナス
D18: たな卸資産の増加額 | R18: =入力シート!W28 -> -275455 | W18: 貯蔵品の増→現金を支出した→ＣＦではマイナス
D19: 前払金・その他流動資産の減少額 | R19: =入力シート!W29 -> 1240000 | W19: 貸倒引当金→現金支出なし→ＣＦではプラス
D20: 小計 | R20: =入力シート!W30 -> 58784096
D21: 利息及び配当金の受取額 | R21: =入力シート!W31 -> 1000
D22: 利息の支払額 | R22: =入力シート!W32 -> -4720739
C23: ① | D23: 業務活動によるキャッシュ・フロー | R23: =入力シート!W33 -> 54064357
C27: ２ 投資活動によるキャッシュ・フロー
D28: 固定資産取得による支出 | R28: =入力シート!W36 -> -53820344
D29: 国庫補助金等による収入 | R29: =入力シート!W37 -> 0
D30: 一般会計又は他の特別会計からの繰入金による収入 | R30: =入力シート!W38 -> 30355454
C31: ② | D31: 投資活動によるキャッシュ・フロー | R31: =入力シート!W39 -> -23464890
C33: ３ 財務活動によるキャッシュ・フロー
D34: 建設改良企業債による収入 | R34: =入力シート!W42 -> 9000000
D35: 建設改良企業債の償還による支出 | R35: =入力シート!W43 -> -38275211
D36: 他会計からの出資による収入 | R36: =入力シート!W44 -> 0
C37: ③ | D37: 財務活動によるキャッシュ・フロー | R37: =入力シート!W45 -> -29275211
C39: 資金増減額（①+②+③） | R39: =入力シート!W47 -> 1324256
C40: 資金期首残高 | R40: =入力シート!W48 -> 85414342
C41: 資金期末残高 | R41: =入力シート!W49 -> 86738598

Sheet 様式
B2: 間接法
C3: キャッシュフロー計算書
C4: 平成２６年４月１日～平成２７年３月３１日
B6: １ 業務活動によるキャッシュ・フロー
B7: 当年度純利益
B8: 減価償却費
B9: 退職給付引当金の減少額
B10: 長期前受金戻入額
B11: 受取利息及び受取配当金
B12: 支払利息
B13: 固定資産除却損
B14: 未収金の減少額
B15: 未払金の増加額
B16: たな卸資産の減少額
B17: 前払金の増加額
... B37: Ⅵ資金期末残高

Sheet Sheet3
B2: -969.6 | D2: -969.6 | F2: -969.6 | I2: 36430000
B3: 92488.9 | D3: 92488.9 | F3: 92488.9 | I3: -17300000
B4: -25935.1 | D4: -25935.1 | F4: -25935.1 | I4: 1000000
B5: -1 | D5: -1 | F5: -1 | I5: 160000
B6: 5793.5 | D6: 5793.5 | F6: 5793.5 | I6: 11000
B7: -4217.5 | D7: -4217.5 | F7: -4217.5 | I7: 1000
B8: -2075.3 | D8: -2075.3 | F8: -2075.3 | I8: -6550000
B9: -275.5 | D9: -275.5 | F9: -275.5 | I9: -720000
B10: -2192.7 | D10: -2192.7 | F10: -2192.7 | I10: -239000
D11: =SUM(D2:D10) -> 62615.7 | I11: -4586000
I12: -6760000
I13: -1207000
I14: -240000
I16: 0

Sheet Sheet1
B1: 73957218 | D1: 9371
B2: 318421865 | D2: 59575.9
B3: 2592782828 | D3: -26463.2
B4: 912617682 | D4: -1
B5: 6546238 | D5: 5793.5
B6: 14284605 | D6: -13399.9
B7: 30331088 | D7: 4588.4
D8: -275.5
B9: =SUM(B1:B8) -> 3948941524 | D9: -132.3
D10: =SUM(D1:D9) -> 39056.9
B11: 3948941524
