Workbook
Name グラフ選択: #REF!
Name グラフ選択: #REF!
Name サービス: #REF!
Name サービス: #REF!
Name サービス選択: #REF!
Name サービス選択: #REF!
Name サービス名: #REF!
Name サービス名: #REF!
Name 在宅サービス: #REF!
Name 在宅サービス: #REF!
Name 施設・居住系サービス: #REF!
Name 施設・居住系サービス: #REF!
Name 推計パターン名: '1_推計値サマリ'!$S$5
Name 選択肢: #REF!
Name 選択肢: #REF!
Name 年度選択: #REF!
Name 年度選択: #REF!
Name 年度選択: #REF!
Name 保険者番号: '1_推計値サマリ'!$S$4
Name 保険者名: '1_推計値サマリ'!$S$3

Sheet 1_推計値サマリ
A1: 第9期介護保険事業（支援）計画策定に向けたワークシート 【総括表】
S2: 出力日： | T2: 2023/10/05
Q3: 保険者名 | S3: 川崎町
Q4: 保険者番号 | S4: 04324
Q5: 推計パターン名 | S5: 第9期川崎町介護保険（R5.8.12）
A6: （１）推計値サマリ
A8: １．被保険者数（年度別）
T9: 単位：人
D10: 令和3年度 | E10: 令和4年度 | F10: 令和5年度 | G10: 令和6年度 | H10: 令和7年度 | I10: 令和8年度 | J10: 伸び率① ※１ | K10: 令和12年度 | L10: 伸び率① ※２ | M10: 令和17年度 | N10: 伸び率① ※２ | O10: 令和22年度 | P10: 伸び率① ※２ | Q10: 令和27年度 | R10: 伸び率① ※２ | S10: 令和32年度 | T10: 伸び率① ※２
A11: 総数 | D11: =SUM(D12:D13) -> 5946 | E11: =SUM(E12:E13) -> 5902 | F11: =SUM(F12:F13) -> 5856 | G11: =SUM(G12:G13) -> 5811 | H11: =SUM(H12:H13) -> 5766 | I11: =SUM(I12:I13) -> 5707 | J11: =IFERROR((SUM(G11:I11)/3)/F11,"－") -> 0.98383424 | K11: =SUM(K12:K13) -> 5460 | L11: =IFERROR(K11/F11,"－") -> 0.93237705 | M11: =SUM(M12:M13) -> 5073 | N11: =IFERROR(M11/F11,"－") -> 0.86629098 | O11: =SUM(O12:O13) -> 4635 | P11: =IFERROR(O11/F11,"－") -> 0.7914959 | Q11: =SUM(Q12:Q13) -> 4090 | R11: =IFERROR(Q11/F11,"－") -> 0.69842896 | S11: =SUM(S12:S13) -> 3686 | T11: =IFERROR(S11/F11,"－") -> 0.62943989
B12: 第1号被保険者数 | D12: 3261 | E12: 3273 | F12: 3281 | G12: 3292 | H12: 3302 | I12: 3281 | J12: =IFERROR((SUM(G12:I12)/3)/F12,"－") -> 1.003251 | K12: 3186 | L12: =IFERROR(K12/F12,"－") -> 0.97104541 | M12: 3032 | N12: =IFERROR(M12/F12,"－") -> 0.9241085 | O12: 2904 | P12: =IFERROR(O12/F12,"－") -> 0.88509601 | Q12: 2658 | R12: =IFERROR(Q12/F12,"－") -> 0.81011887 | S12: 2501 | T12: =IFERROR(S12/F12,"－") -> 0.7622676
B13: 第2号被保険者数 | D13: 2685 | E13: 2629 | F13: 2575 | G13: 2519 | H13: 2464 | I13: 2426 | J13: =IFERROR((SUM(G13:I13)/3)/F13,"－") -> 0.95909385 | K13: 2274 | L13: =IFERROR(K13/F13,"－") -> 0.8831068 | M13: 2041 | N13: =IFERROR(M13/F13,"－") -> 0.79262136 | O13: 1731 | P13: =IFERROR(O13/F13,"－") -> 0.67223301 | Q13: 1432 | R13: =IFERROR(Q13/F13,"－") -> 0.5561165 | S13: 1185 | T13: =IFERROR(S13/F13,"－") -> 0.46019417
G14: ※１：第9期平均値/令和5年度の値*100 | K14: ※２：令和12（17,22,27,30）年度の値/令和5年度の値*100
A16: ２．要介護（支援）認定者数
T17: 単位：人
D18: 令和3年度 | E18: 令和4年度 | F18: 令和5年度 | G18: 令和6年度 | H18: 令和7年度 | I18: 令和8年度 | J18: 伸び率① ※１ | K18: 令和12年度 | L18: 伸び率① ※２ | M18: 令和17年度 | N18: 伸び率① ※２ | O18: 令和22年度 | P18: 伸び率① ※２ | Q18: 令和27年度 | R18: 伸び率① ※２ | S18: 令和32年度 | T18: 伸び率① ※２
A19: 総数 | D19: =SUM(D20:D26) -> 568 | E19: =SUM(E20:E26) -> 575 | F19: =SUM(F20:F26) -> 578 | G19: =SUM(G20:G26) -> 578 | H19: =SUM(H20:H26) -> 579 | I19: =SUM(I20:I26) -> 582 | J19: =IFERROR((SUM(G19:I19)/3)/F19,"－") -> 1.0028835 | K19: =SUM(K20:K26) -> 618 | L19: =IFERROR(K19/F19,"－") -> 1.0692042 | M19: =SUM(M20:M26) -> 675 | N19: =IFERROR(M19/F19,"－") -> 1.1678201 | O19: =SUM(O20:O26) -> 710 | P19: =IFERROR(O19/F19,"－") -> 1.2283737 | Q19: =SUM(Q20:Q26) -> 663 | R19: =IFERROR(Q19/F19,"－") -> 1.1470588 | S19: =SUM(S20:S26) -> 643 | T19: =IFERROR(S19/F19,"－") -> 1.1124567
C20: 要支援1 | D20: 19 | E20: 26 | F20: 31 | G20: 31 | H20: 32 | I20: 33 | J20: =IFERROR((SUM(G20:I20)/3)/F20,"－") -> 1.0322581 | K20: 36 | L20: =IFERROR(K20/F20,"－") -> 1.1612903 | M20: 38 | N20: =IFERROR(M20/F20,"－") -> 1.2258065 | O20: 37 | P20: =IFERROR(O20/F20,"－") -> 1.1935484 | Q20: 35 | R20: =IFERROR(Q20/F20,"－") -> 1.1290323 | S20: 31 | T20: =IFERROR(S20/F20,"－") -> 1
C21: 要支援2 | D21: 93 | E21: 90 | F21: 92 | G21: 91 | H21: 91 | I21: 91 | J21: =IFERROR((SUM(G21:I21)/3)/F21,"－") -> 0.98913043 | K21: 101 | L21: =IFERROR(K21/F21,"－") -> 1.0978261 | M21: 108 | N21: =IFERROR(M21/F21,"－") -> 1.173913 | O21: 108 | P21: =IFERROR(O21/F21,"－") -> 1.173913 | Q21: 94 | R21: =IFERROR(Q21/F21,"－") -> 1.0217391 | S21: 91 | T21: =IFERROR(S21/F21,"－") -> 0.98913043
C22: 要介護1 | D22: 43 | E22: 61 | F22: 59 | G22: 63 | H22: 61 | I22: 60 | J22: =IFERROR((SUM(G22:I22)/3)/F22,"－") -> 1.039548 | K22: 65 | L22: =IFERROR(K22/F22,"－") -> 1.1016949 | M22: 77 | N22: =IFERROR(M22/F22,"－") -> 1.3050847 | O22: 82 | P22: =IFERROR(O22/F22,"－") -> 1.3898305 | Q22: 74 | R22: =IFERROR(Q22/F22,"－") -> 1.2542373 | S22: 70 | T22: =IFERROR(S22/F22,"－") -> 1.1864407
C23: 要介護2 | D23: 145 | E23: 142 | F23: 140 | G23: 140 | H23: 141 | I23: 143 | J23: =IFERROR((SUM(G23:I23)/3)/F23,"－") -> 1.0095238 | K23: 146 | L23: =IFERROR(K23/F23,"－") -> 1.0428571 | M23: 166 | N23: =IFERROR(M23/F23,"－") -> 1.1857143 | O23: 171 | P23: =IFERROR(O23/F23,"－") -> 1.2214286 | Q23: 158 | R23: =IFERROR(Q23/F23,"－") -> 1.1285714 | S23: 150 | T23: =IFERROR(S23/F23,"－") -> 1.0714286
C24: 要介護3 | D24: 128 | E24: 98 | F24: 96 | G24: 90 | H24: 91 | I24: 91 | J24: =IFERROR((SUM(G24:I24)/3)/F24,"－") -> 0.94444444 | K24: 95 | L24: =IFERROR(K24/F24,"－") -> 0.98958333 | M24: 101 | N24: =IFERROR(M24/F24,"－") -> 1.0520833 | O24: 109 | P24: =IFERROR(O24/F24,"－") -> 1.1354167 | Q24: 105 | R24: =IFERROR(Q24/F24,"－") -> 1.09375 | S24: 103 | T24: =IFERROR(S24/F24,"－") -> 1.0729167
C25: 要介護4 | D25: 82 | E25: 95 | F25: 96 | G25: 99 | H25: 99 | I25: 100 | J25: =IFERROR((SUM(G25:I25)/3)/F25,"－") -> 1.0347222 | K25: 109 | L25: =IFERROR(K25/F25,"－") -> 1.1354167 | M25: 112 | N25: =IFERROR(M25/F25,"－") -> 1.1666667 | O25: 123 | P25: =IFERROR(O25/F25,"－") -> 1.28125 | Q25: 122 | R25: =IFERROR(Q25/F25,"－") -> 1.2708333 | S25: 123 | T25: =IFERROR(S25/F25,"－") -> 1.28125
C26: 要介護5 | D26: 58 | E26: 63 | F26: 64 | G26: 64 | H26: 64 | I26: 64 | J26: =IFERROR((SUM(G26:I26)/3)/F26,"－") -> 1 | K26: 66 | L26: =IFERROR(K26/F26,"－") -> 1.03125 | M26: 73 | N26: =IFERROR(M26/F26,"－") -> 1.140625 | O26: 80 | P26: =IFERROR(O26/F26,"－") -> 1.25 | Q26: 75 | R26: =IFERROR(Q26/F26,"－") -> 1.171875 | S26: 75 | T26: =IFERROR(S26/F26,"－") -> 1.171875
B27: うち第1号被保険者数 | D27: =SUM(D28:D34) -> 561 | E27: =SUM(E28:E34) -> 568 | F27: =SUM(F28:F34) -> 570 | G27: =SUM(G28:G34) -> 570 | H27: =SUM(H28:H34) -> 571 | I27: =SUM(I28:I34) -> 574 | J27: =IFERROR((SUM(G27:I27)/3)/F27,"－") -> 1.002924 | K27: =SUM(K28:K34) -> 610 | L27: =IFERROR(K27/F27,"－") -> 1.0701754 | M27: =SUM(M28:M34) -> 668 | N27: =IFERROR(M27/F27,"－") -> 1.1719298 | O27: =SUM(O28:O34) -> 704 | P27: =IFERROR(O27/F27,"－") -> 1.2350877 | Q27: =SUM(Q28:Q34) -> 658 | R27: =IFERROR(Q27/F27,"－") -> 1.154386 | S27: =SUM(S28:S34) -> 639 | T27: =IFERROR(S27/F27,"－") -> 1.1210526
C28: 要支援1 | D28: 19 | E28: 25 | F28: 30 | G28: 30 | H28: 31 | I28: 32 | J28: =IFERROR((SUM(G28:I28)/3)/F28,"－") -> 1.0333333 | K28: 35 | L28: =IFERROR(K28/F28,"－") -> 1.1666667 | M28: 37 | N28: =IFERROR(M28/F28,"－") -> 1.2333333 | O28: 36 | P28: =IFERROR(O28/F28,"－") -> 1.2 | Q28: 34 | R28: =IFERROR(Q28/F28,"－") -> 1.1333333 | S28: 30 | T28: =IFERROR(S28/F28,"－") -> 1
C29: 要支援2 | D29: 91 | E29: 87 | F29: 90 | G29: 89 | H29: 89 | I29: 89 | J29: =IFERROR((SUM(G29:I29)/3)/F29,"－") -> 0.98888889 | K29: 99 | L29: =IFERROR(K29/F29,"－") -> 1.1 | M29: 106 | N29: =IFERROR(M29/F29,"－") -> 1.1777778 | O29: 107 | P29: =IFERROR(O29/F29,"－") -> 1.1888889 | Q29: 93 | R29: =IFERROR(Q29/F29,"－") -> 1.0333333 | S29: 90 | T29: =IFERROR(S29/F29,"－") -> 1
C30: 要介護1 | D30: 43 | E30: 61 | F30: 59 | G30: 63 | H30: 61 | I30: 60 | J30: =IFERROR((SUM(G30:I30)/3)/F30,"－") -> 1.039548 | K30: 65 | L30: =IFERROR(K30/F30,"－") -> 1.1016949 | M30: 77 | N30: =IFERROR(M30/F30,"－") -> 1.3050847 | O30: 82 | P30: =IFERROR(O30/F30,"－") -> 1.3898305 | Q30: 74 | R30: =IFERROR(Q30/F30,"－") -> 1.2542373 | S30: 70 | T30: =IFERROR(S30/F30,"－") -> 1.1864407
C31: 要介護2 | D31: 143 | E31: 141 | F31: 137 | G31: 137 | H31: 138 | I31: 140 | J31: =IFERROR((SUM(G31:I31)/3)/F31,"－") -> 1.0097324 | K31: 143 | L31: =IFERROR(K31/F31,"－") -> 1.0437956 | M31: 164 | N31: =IFERROR(M31/F31,"－") -> 1.1970803 | O31: 169 | P31: =IFERROR(O31/F31,"－") -> 1.2335766 | Q31: 156 | R31: =IFERROR(Q31/F31,"－") -> 1.1386861 | S31: 149 | T31: =IFERROR(S31/F31,"－") -> 1.0875912
C32: 要介護3 | D32: 127 | E32: 98 | F32: 96 | G32: 90 | H32: 91 | I32: 91 | J32: =IFERROR((SUM(G32:I32)/3)/F32,"－") -> 0.94444444 | K32: 95 | L32: =IFERROR(K32/F32,"－") -> 0.98958333 | M32: 101 | N32: =IFERROR(M32/F32,"－") -> 1.0520833 | O32: 109 | P32: =IFERROR(O32/F32,"－") -> 1.1354167 | Q32: 105 | R32: =IFERROR(Q32/F32,"－") -> 1.09375 | S32: 103 | T32: =IFERROR(S32/F32,"－") -> 1.0729167
C33: 要介護4 | D33: 81 | E33: 95 | F33: 96 | G33: 99 | H33: 99 | I33: 100 | J33: =IFERROR((SUM(G33:I33)/3)/F33,"－") -> 1.0347222 | K33: 109 | L33: =IFERROR(K33/F33,"－") -> 1.1354167 | M33: 112 | N33: =IFERROR(M33/F33,"－") -> 1.1666667 | O33: 123 | P33: =IFERROR(O33/F33,"－") -> 1.28125 | Q33: 122 | R33: =IFERROR(Q33/F33,"－") -> 1.2708333 | S33: 123 | T33: =IFERROR(S33/F33,"－") -> 1.28125
C34: 要介護5 | D34: 57 | E34: 61 | F34: 62 | G34: 62 | H34: 62 | I34: 62 | J34: =IFERROR((SUM(G34:I34)/3)/F34,"－") -> 1 | K34: 64 | L34: =IFERROR(K34/F34,"－") -> 1.0322581 | M34: 71 | N34: =IFERROR(M34/F34,"－") -> 1.1451613 | O34: 78 | P34: =IFERROR(O34/F34,"－") -> 1.2580645 | Q34: 74 | R34: =IFERROR(Q34/F34,"－") -> 1.1935484 | S34: 74 | T34: =IFERROR(S34/F34,"－") -> 1.1935484
G35: ※１：第9期平均値/令和5年度の値*100 | K35: ※２：令和12（17,22,27,30）年度の値/令和5年度の値*100
A37: ３．介護予防サービス見込量
T38: 単位：千円
D39: 令和3年度 | E39: 令和4年度 | F39: 令和5年度 | G39: 令和6年度 | H39: 令和7年度 | I39: 令和8年度 | J39: 伸び率① ※１ | K39: 令和12年度 | L39: 伸び率① ※２ | M39: 令和17年度 | N39: 伸び率① ※２ | O39: 令和22年度 | P39: 伸び率① ※２ | Q39: 令和27年度 | R39: 伸び率① ※２ | S39: 令和32年度 | T39: 伸び率① ※２
A40: （１）在宅サービス | D40: =('2_サービス別給付費'!D12+'2_サービス別給付費'!D14+'2_サービス別給付費'!D17+'2_サービス別給付費'!D20+'2_サービス別給付費'!D23+'2_サービス別給付費'!D25+'2_サービス別給付費'!D27+'2_サービス別給付費'!D29+'2_サービス別給付費'!D32+'2_サービス別給付費'!D35+'2_サービス別給付費'!D38+'2_サービス別給付費'!D41+'2_サービス別給付費'!D43+'2_サービス別給付費'!D45+'2_サービス別給付費'!D50+'2_サービス別給付費'!D53+'2_サービス別給付費'!D57) -> 26821.834 | E40: =('2_サービス別給付費'!E12+'2_サービス別給付費'!E14+'2_サービス別給付費'!E17+'2_サービス別給付費'!E20+'2_サービス別給付費'!E23+'2_サービス別給付費'!E25+'2_サービス別給付費'!E27+'2_サービス別給付費'!E29+'2_サービス別給付費'!E32+'2_サービス別給付費'!E35+'2_サービス別給付費'!E38+'2_サービス別給付費'!E41+'2_サービス別給付費'!E43+'2_サービス別給付費'!E45+'2_サービス別給付費'!E50+'2_サービス別給付費'!E53+'2_サービス別給付費'!E57) -> 28327.08 | F40: =('2_サービス別給付費'!F12+'2_サービス別給付費'!F14+'2_サービス別給付費'!F17+'2_サービス別給付費'!F20+'2_サービス別給付費'!F23+'2_サービス別給付費'!F25+'2_サービス別給付費'!F27+'2_サービス別給付費'!F29+'2_サービス別給付費'!F32+'2_サービス別給付費'!F35+'2_サービス別給付費'!F38+'2_サービス別給付費'!F41+'2_サービス別給付費'!F43+'2_サービス別給付費'!F45+'2_サービス別給付費'!F50+'2_サービス別給付費'!F53+'2_サービス別給付費'!F57) -> 28263.688 | G40: =('2_サービス別給付費'!G12+'2_サービス別給付費'!G14+'2_サービス別給付費'!G17+'2_サービス別給付費'!G20+'2_サービス別給付費'!G23+'2_サービス別給付費'!G25+'2_サービス別給付費'!G27+'2_サービス別給付費'!G29+'2_サービス別給付費'!G32+'2_サービス別給付費'!G35+'2_サービス別給付費'!G38+'2_サービス別給付費'!G41+'2_サービス別給付費'!G43+'2_サービス別給付費'!G45+'2_サービス別給付費'!G50+'2_サービス別給付費'!G53+'2_サービス別給付費'!G57) -> 28209 | H40: =('2_サービス別給付費'!H12+'2_サービス別給付費'!H14+'2_サービス別給付費'!H17+'2_サービス別給付費'!H20+'2_サービス別給付費'!H23+'2_サービス別給付費'!H25+'2_サービス別給付費'!H27+'2_サービス別給付費'!H29+'2_サービス別給付費'!H32+'2_サービス別給付費'!H35+'2_サービス別給付費'!H38+'2_サービス別給付費'!H41+'2_サービス別給付費'!H43+'2_サービス別給付費'!H45+'2_サービス別給付費'!H50+'2_サービス別給付費'!H53+'2_サービス別給付費'!H57) -> 28209 | I40: =('2_サービス別給付費'!I12+'2_サービス別給付費'!I14+'2_サービス別給付費'!I17+'2_サービス別給付費'!I20+'2_サービス別給付費'!I23+'2_サービス別給付費'!I25+'2_サービス別給付費'!I27+'2_サービス別給付費'!I29+'2_サービス別給付費'!I32+'2_サービス別給付費'!I35+'2_サービス別給付費'!I38+'2_サービス別給付費'!I41+'2_サービス別給付費'!I43+'2_サービス別給付費'!I45+'2_サービス別給付費'!I50+'2_サービス別給付費'!I53+'2_サービス別給付費'!I57) -> 29004 | J40: =IFERROR((SUM(G40:I40)/3)/F40,"－") -> 1.0074411 | K40: =('2_サービス別給付費'!K12+'2_サービス別給付費'!K14+'2_サービス別給付費'!K17+'2_サービス別給付費'!K20+'2_サービス別給付費'!K23+'2_サービス別給付費'!K25+'2_サービス別給付費'!K27+'2_サービス別給付費'!K29+'2_サービス別給付費'!K32+'2_サービス別給付費'!K35+'2_サービス別給付費'!K38+'2_サービス別給付費'!K41+'2_サービス別給付費'!K43+'2_サービス別給付費'!K45+'2_サービス別給付費'!K50+'2_サービス別給付費'!K53+'2_サービス別給付費'!K57) -> 30614 | L40: =IFERROR(K40/F40,"－") -> 1.0831566 | M40: =('2_サービス別給付費'!M12+'2_サービス別給付費'!M14+'2_サービス別給付費'!M17+'2_サービス別給付費'!M20+'2_サービス別給付費'!M23+'2_サービス別給付費'!M25+'2_サービス別給付費'!M27+'2_サービス別給付費'!M29+'2_サービス別給付費'!M32+'2_サービス別給付費'!M35+'2_サービス別給付費'!M38+'2_サービス別給付費'!M41+'2_サービス別給付費'!M43+'2_サービス別給付費'!M45+'2_サービス別給付費'!M50+'2_サービス別給付費'!M53+'2_サービス別給付費'!M57) -> 33850 | N40: =IFERROR(M40/F40,"－") -> 1.1976498 | O40: =('2_サービス別給付費'!O12+'2_サービス別給付費'!O14+'2_サービス別給付費'!O17+'2_サービス別給付費'!O20+'2_サービス別給付費'!O23+'2_サービス別給付費'!O25+'2_サービス別給付費'!O27+'2_サービス別給付費'!O29+'2_サービス別給付費'!O32+'2_サービス別給付費'!O35+'2_サービス別給付費'!O38+'2_サービス別給付費'!O41+'2_サービス別給付費'!O43+'2_サービス別給付費'!O45+'2_サービス別給付費'!O50+'2_サービス別給付費'!O53+'2_サービス別給付費'!O57) -> 33850 | P40: =IFERROR(O40/F40,"－") -> 1.1976498 | Q40: =('2_サービス別給付費'!Q12+'2_サービス別給付費'!Q14+'2_サービス別給付費'!Q17+'2_サービス別給付費'!Q20+'2_サービス別給付費'!Q23+'2_サービス別給付費'!Q25+'2_サービス別給付費'!Q27+'2_サービス別給付費'!Q29+'2_サービス別給付費'!Q32+'2_サービス別給付費'!Q35+'2_サービス別給付費'!Q38+'2_サービス別給付費'!Q41+'2_サービス別給付費'!Q43+'2_サービス別給付費'!Q45+'2_サービス別給付費'!Q50+'2_サービス別給付費'!Q53+'2_サービス別給付費'!Q57) -> 29162 | R40: =IFERROR(Q40/F40,"－") -> 1.0317833 | S40: =('2_サービス別給付費'!S12+'2_サービス別給付費'!S14+'2_サービス別給付費'!S17+'2_サービス別給付費'!S20+'2_サービス別給付費'!S23+'2_サービス別給付費'!S25+'2_サービス別給付費'!S27+'2_サービス別給付費'!S29+'2_サービス別給付費'!S32+'2_サービス別給付費'!S35+'2_サービス別給付費'!S38+'2_サービス別給付費'!S41+'2_サービス別給付費'!S43+'2_サービス別給付費'!S45+'2_サービス別給付費'!S50+'2_サービス別給付費'!S53+'2_サービス別給付費'!S57) -> 28209 | T40: =IFERROR(S40/F40,"－") -> 0.99806509
A41: （２）居住系サービス | D41: =('2_サービス別給付費'!D47+'2_サービス別給付費'!D55) -> 0 | E41: =('2_サービス別給付費'!E47+'2_サービス別給付費'!E55) -> 0 | F41: =('2_サービス別給付費'!F47+'2_サービス別給付費'!F55) -> 0 | G41: =('2_サービス別給付費'!G47+'2_サービス別給付費'!G55) -> 0 | H41: =('2_サービス別給付費'!H47+'2_サービス別給付費'!H55) -> 0 | I41: =('2_サービス別給付費'!I47+'2_サービス別給付費'!I55) -> 0 | J41: =IFERROR((SUM(G41:I41)/3)/F41,"－") -> － | K41: =('2_サービス別給付費'!K47+'2_サービス別給付費'!K55) -> 0 | L41: =IFERROR(K41/F41,"－") -> － | M41: =('2_サービス別給付費'!M47+'2_サービス別給付費'!M55) -> 0 | N41: =IFERROR(M41/F41,"－") -> － | O41: =('2_サービス別給付費'!O47+'2_サービス別給付費'!O55) -> 0 | P41: =IFERROR(O41/F41,"－") -> － | Q41: =('2_サービス別給付費'!Q47+'2_サービス別給付費'!Q55) -> 0 | R41: =IFERROR(Q41/F41,"－") -> － | S41: =('2_サービス別給付費'!S47+'2_サービス別給付費'!S55) -> 0 | T41: =IFERROR(S41/F41,"－") -> －
A42: 合計 | D42: =SUM(D40:D41) -> 26821.834 | E42: =SUM(E40:E41) -> 28327.08 | F42: =SUM(F40:F41) -> 28263.688 | G42: =SUM(G40:G41) -> 28209 | H42: =SUM(H40:H41) -> 28209 | I42: =SUM(I40:I41) -> 29004 | J42: =IFERROR((SUM(G42:I42)/3)/F42,"－") -> 1.0074411 | K42: =SUM(K40:K41) -> 30614 | L42: =IFERROR(K42/F42,"－") -> 1.0831566 | M42: =SUM(M40:M41) -> 33850 | N42: =IFERROR(M42/F42,"－") -> 1.1976498 | O42: =SUM(O40:O41) -> 33850 | P42: =IFERROR(O42/F42,"－") -> 1.1976498 | Q42: =SUM(Q40:Q41) -> 29162 | R42: =IFERROR(Q42/F42,"－") -> 1.0317833 | S42: =SUM(S40:S41) -> 28209 | T42: =IFERROR(S42/F42,"－") -> 0.99806509
G43: ※１：第9期平均値/令和5年度の値*100 | K43: ※２：令和12（17,22,27,30）年度の値/令和5年度の値*100
...

Sheet 2_サービス別給付費
A1: （２）サービス別給付費
S2: 出力日： | T2: ='1_推計値サマリ'!T2 -> 2023/10/05
Q3: 保険者名 | S3: =保険者名 -> 川崎町
Q4: 保険者番号 | S4: =保険者番号 -> 04324
Q5: 推計パターン名 | S5: =推計パターン名 -> 第9期川崎町介護保険（R5.8.12）
A8: １．介護予防サービス見込量
T9: 単位：各項目の（）内
D10: 令和3年度 | E10: 令和4年度 | F10: 令和5年度 | G10: 令和6年度 | H10: 令和7年度 | I10: 令和8年度 | J10: 伸び率① ※１ | K10: 令和12年度 | L10: 伸び率① ※２ | M10: 令和17年度 | N10: 伸び率① ※２ | O10: 令和22年度 | P10: 伸び率① ※２ | Q10: 令和27年度 | R10: 伸び率① ※２ | S10: 令和32年度 | T10: 伸び率① ※２
A11: （１）介護予防サービス
B12: 未使用 | C12: 給付費（千円）
C13: 人数（人）
B14: 介護予防訪問入浴介護 | C14: 給付費（千円） | D14: 0 | E14: 0 | F14: 0 | G14: 0 | H14: 0 | I14: 0 | J14: =IFERROR(SUM(G14:I14)/3/F14,"－") -> － | K14: 0 | L14: =IFERROR(K14/F14,"－") -> － | M14: 0 | N14: =IFERROR(M14/F14,"－") -> － | O14: 0 | P14: =IFERROR(O14/F14,"－") -> － | Q14: 0 | R14: =IFERROR(Q14/F14,"－") -> － | S14: 0 | T14: =IFERROR(S14/F14,"－") -> －
C15: 回数（回） | D15: 0 | E15: 0 | F15: 0 | G15: 0 | H15: 0 | I15: 0 | J15: =IFERROR(SUM(G15:I15)/3/F15,"－") -> － | K15: 0 | L15: =IFERROR(K15/F15,"－") -> － | M15: 0 | N15: =IFERROR(M15/F15,"－") -> － | O15: 0 | P15: =IFERROR(O15/F15,"－") -> － | Q15: 0 | R15: =IFERROR(Q15/F15,"－") -> － | S15: 0 | T15: =IFERROR(S15/F15,"－") -> －
C16: 人数（人） | D16: 0 | E16: 0 | F16: 0 | G16: 0 | H16: 0 | I16: 0 | J16: =IFERROR(SUM(G16:I16)/3/F16,"－") -> － | K16: 0 | L16: =IFERROR(K16/F16,"－") -> － | M16: 0 | N16: =IFERROR(M16/F16,"－") -> － | O16: 0 | P16: =IFERROR(O16/F16,"－") -> － | Q16: 0 | R16: =IFERROR(Q16/F16,"－") -> － | S16: 0 | T16: =IFERROR(S16/F16,"－") -> －
B17: 介護予防訪問看護 | C17: 給付費（千円） | D17: 0 | E17: 102.87 | F17: 0 | G17: 0 | H17: 0 | I17: 0 | J17: =IFERROR(SUM(G17:I17)/3/F17,"－") -> － | K17: 0 | L17: =IFERROR(K17/F17,"－") -> － | M17: 0 | N17: =IFERROR(M17/F17,"－") -> － | O17: 0 | P17: =IFERROR(O17/F17,"－") -> － | Q17: 0 | R17: =IFERROR(Q17/F17,"－") -> － | S17: 0 | T17: =IFERROR(S17/F17,"－") -> －
C18: 回数（回） | D18: 0 | E18: 2.5 | F18: 0 | G18: 0 | H18: 0 | I18: 0 | J18: =IFERROR(SUM(G18:I18)/3/F18,"－") -> － | K18: 0 | L18: =IFERROR(K18/F18,"－") -> － | M18: 0 | N18: =IFERROR(M18/F18,"－") -> － | O18: 0 | P18: =IFERROR(O18/F18,"－") -> － | Q18: 0 | R18: =IFERROR(Q18/F18,"－") -> － | S18: 0 | T18: =IFERROR(S18/F18,"－") -> －
C19: 人数（人） | D19: 0 | E19: 0.83333333 | F19: 0 | G19: 0 | H19: 0 | I19: 0 | J19: =IFERROR(SUM(G19:I19)/3/F19,"－") -> － | K19: 0 | L19: =IFERROR(K19/F19,"－") -> － | M19: 0 | N19: =IFERROR(M19/F19,"－") -> － | O19: 0 | P19: =IFERROR(O19/F19,"－") -> － | Q19: 0 | R19: =IFERROR(Q19/F19,"－") -> － | S19: 0 | T19: =IFERROR(S19/F19,"－") -> －
B20: 介護予防訪問リハビリテーション | C20: 給付費（千円） | D20: 2490.88 | E20: 2495.085 | F20: 2768.3796 | G20: 2768 | H20: 2768 | I20: 2768 | J20: =IFERROR(SUM(G20:I20)/3/F20,"－") -> 0.99986288 | K20: 2768 | L20: =IFERROR(K20/F20,"－") -> 0.99986288 | M20: 3562 | N20: =IFERROR(M20/F20,"－") -> 1.2866733 | O20: 3562 | P20: =IFERROR(O20/F20,"－") -> 1.2866733 | Q20: 2768 | R20: =IFERROR(Q20/F20,"－") -> 0.99986288 | S20: 2768 | T20: =IFERROR(S20/F20,"－") -> 0.99986288
C21: 回数（回） | D21: 67.083333 | E21: 75.416667 | F21: 84.1 | G21: 84.1 | H21: 84.1 | I21: 84.1 | J21: =IFERROR(SUM(G21:I21)/3/F21,"－") -> 1 | K21: 84.1 | L21: =IFERROR(K21/F21,"－") -> 1 | M21: 108.2 | N21: =IFERROR(M21/F21,"－") -> 1.2865636 | O21: 108.2 | P21: =IFERROR(O21/F21,"－") -> 1.2865636 | Q21: 84.1 | R21: =IFERROR(Q21/F21,"－") -> 1 | S21: 84.1 | T21: =IFERROR(S21/F21,"－") -> 1
C22: 人数（人） | D22: 5.1666667 | E22: 6 | F22: 7 | G22: 7 | H22: 7 | I22: 7 | J22: =IFERROR(SUM(G22:I22)/3/F22,"－") -> 1 | K22: 7 | L22: =IFERROR(K22/F22,"－") -> 1 | M22: 9 | N22: =IFERROR(M22/F22,"－") -> 1.2857143 | O22: 9 | P22: =IFERROR(O22/F22,"－") -> 1.2857143 | Q22: 7 | R22: =IFERROR(Q22/F22,"－") -> 1 | S22: 7 | T22: =IFERROR(S22/F22,"－") -> 1
B23: 介護予防居宅療養管理指導 | C23: 給付費（千円） | D23: 0 | E23: 0 | F23: 0 | G23: 0 | H23: 0 | I23: 0 | J23: =IFERROR(SUM(G23:I23)/3/F23,"－") -> － | K23: 0 | L23: =IFERROR(K23/F23,"－") -> － | M23: 0 | N23: =IFERROR(M23/F23,"－") -> － | O23: 0 | P23: =IFERROR(O23/F23,"－") -> － | Q23: 0 | R23: =IFERROR(Q23/F23,"－") -> － | S23: 0 | T23: =IFERROR(S23/F23,"－") -> －
C24: 人数（人） | D24: 0 | E24: 0 | F24: 0 | G24: 0 | H24: 0 | I24: 0 | J24: =IFERROR(SUM(G24:I24)/3/F24,"－") -> － | K24: 0 | L24: =IFERROR(K24/F24,"－") -> － | M24: 0 | N24: =IFERROR(M24/F24,"－") -> － | O24: 0 | P24: =IFERROR(O24/F24,"－") -> － | Q24: 0 | R24: =IFERROR(Q24/F24,"－") -> － | S24: 0 | T24: =IFERROR(S24/F24,"－") -> －
B25: 未使用 | C25: 給付費（千円） | N25: =IFERROR(M25/F25,"－") -> － | P25: =IFERROR(O25/F25,"－") -> － | R25: =IFERROR(Q25/F25,"－") -> － | T25: =IFERROR(S25/F25,"－") -> －
C26: 人数（人） | N26: =IFERROR(M26/F26,"－") -> － | P26: =IFERROR(O26/F26,"－") -> － | R26: =IFERROR(Q26/F26,"－") -> － | T26: =IFERROR(S26/F26,"－") -> －
B27: 介護予防通所リハビリテーション | C27: 給付費（千円） | D27: 16765.704 | E27: 18497.483 | F27: 18474.588 | G27: 18475 | H27: 18475 | I27: 19007 | J27: =IFERROR(SUM(G27:I27)/3/F27,"－") -> 1.0096211 | K27: 20073 | L27: =IFERROR(K27/F27,"－") -> 1.0865195 | M27: 21969 | N27: =IFERROR(M27/F27,"－") -> 1.189147 | O27: 21969 | P27: =IFERROR(O27/F27,"－") -> 1.189147 | Q27: 19007 | R27: =IFERROR(Q27/F27,"－") -> 1.0288186 | S27: 18475 | T27: =IFERROR(S27/F27,"－") -> 1.0000223
C28: 人数（人） | D28: 33.416667 | E28: 38.083333 | F28: 36 | G28: 36 | H28: 36 | I28: 37 | J28: =IFERROR(SUM(G28:I28)/3/F28,"－") -> 1.0092593 | K28: 39 | L28: =IFERROR(K28/F28,"－") -> 1.0833333 | M28: 43 | N28: =IFERROR(M28/F28,"－") -> 1.1944444 | O28: 43 | P28: =IFERROR(O28/F28,"－") -> 1.1944444 | Q28: 37 | R28: =IFERROR(Q28/F28,"－") -> 1.0277778 | S28: 36 | T28: =IFERROR(S28/F28,"－") -> 1
B29: 介護予防短期入所生活介護 | C29: 給付費（千円） | D29: 336.656 | E29: 34.93 | F29: 0 | G29: 0 | H29: 0 | I29: 0 | J29: =IFERROR(SUM(G29:I29)/3/F29,"－") -> － | K29: 0 | L29: =IFERROR(K29/F29,"－") -> － | M29: 0 | N29: =IFERROR(M29/F29,"－") -> － | O29: 0 | P29: =IFERROR(O29/F29,"－") -> － | Q29: 0 | R29: =IFERROR(Q29/F29,"－") -> － | S29: 0 | T29: =IFERROR(S29/F29,"－") -> －
C30: 日数（日） | D30: 4.4166667 | E30: 0.41666667 | F30: 0 | G30: 0 | H30: 0 | I30: 0 | J30: =IFERROR(SUM(G30:I30)/3/F30,"－") -> － | K30: 0 | L30: =IFERROR(K30/F30,"－") -> － | M30: 0 | N30: =IFERROR(M30/F30,"－") -> － | O30: 0 | P30: =IFERROR(O30/F30,"－") -> － | Q30: 0 | R30: =IFERROR(Q30/F30,"－") -> － | S30: 0 | T30: =IFERROR(S30/F30,"－") -> －
C31: 人数（人） | D31: 0.75 | E31: 0.16666667 | F31: 0 | G31: 0 | H31: 0 | I31: 0 | J31: =IFERROR(SUM(G31:I31)/3/F31,"－") -> － | K31: 0 | L31: =IFERROR(K31/F31,"－") -> － | M31: 0 | N31: =IFERROR(M31/F31,"－") -> － | O31: 0 | P31: =IFERROR(O31/F31,"－") -> － | Q31: 0 | R31: =IFERROR(Q31/F31,"－") -> － | S31: 0 | T31: =IFERROR(S31/F31,"－") -> －
B32: 介護予防短期入所療養介護（老健） | C32: 給付費（千円） | D32: 57.132 | E32: 0 | F32: 0 | G32: 0 | H32: 0 | I32: 0 | J32: =IFERROR(SUM(G32:I32)/3/F32,"－") -> － | K32: 0 | L32: =IFERROR(K32/F32,"－") -> － | M32: 0 | N32: =IFERROR(M32/F32,"－") -> － | O32: 0 | P32: =IFERROR(O32/F32,"－") -> － | Q32: 0 | R32: =IFERROR(Q32/F32,"－") -> － | S32: 0 | T32: =IFERROR(S32/F32,"－") -> －
C33: 日数（日） | D33: 0.66666667 | E33: 0 | F33: 0 | G33: 0 | H33: 0 | I33: 0 | J33: =IFERROR(SUM(G33:I33)/3/F33,"－") -> － | K33: 0 | L33: =IFERROR(K33/F33,"－") -> － | M33: 0 | N33: =IFERROR(M33/F33,"－") -> － | O33: 0 | P33: =IFERROR(O33/F33,"－") -> － | Q33: 0 | R33: =IFERROR(Q33/F33,"－") -> － | S33: 0 | T33: =IFERROR(S33/F33,"－") -> －
C34: 人数（人） | D34: 0.25 | E34: 0 | F34: 0 | G34: 0 | H34: 0 | I34: 0 | J34: =IFERROR(SUM(G34:I34)/3/F34,"－") -> － | K34: 0 | L34: =IFERROR(K34/F34,"－") -> － | M34: 0 | N34: =IFERROR(M34/F34,"－") -> － | O34: 0 | P34: =IFERROR(O34/F34,"－") -> － | Q34: 0 | R34: =IFERROR(Q34/F34,"－") -> － | S34: 0 | T34: =IFERROR(S34/F34,"－") -> －
B35: 介護予防短期入所療養介護（病院等） | C35: 給付費（千円） | D35: 0 | E35: 0 | F35: 0 | G35: 0 | H35: 0 | I35: 0 | J35: =IFERROR(SUM(G35:I35)/3/F35,"－") -> － | K35: 0 | L35: =IFERROR(K35/F35,"－") -> － | M35: 0 | N35: =IFERROR(M35/F35,"－") -> － | O35: 0 | P35: =IFERROR(O35/F35,"－") -> － | Q35: 0 | R35: =IFERROR(Q35/F35,"－") -> － | S35: 0 | T35: =IFERROR(S35/F35,"－") -> －
C36: 日数（日） | D36: 0 | E36: 0 | F36: 0 | G36: 0 | H36: 0 | I36: 0 | J36: =IFERROR(SUM(G36:I36)/3/F36,"－") -> － | K36: 0 | L36: =IFERROR(K36/F36,"－") -> － | M36: 0 | N36: =IFERROR(M36/F36,"－") -> － | O36: 0 | P36: =IFERROR(O36/F36,"－") -> － | Q36: 0 | R36: =IFERROR(Q36/F36,"－") -> － | S36: 0 | T36: =IFERROR(S36/F36,"－") -> －
C37: 人数（人） | D37: 0 | E37: 0 | F37: 0 | G37: 0 | H37: 0 | I37: 0 | J37: =IFERROR(SUM(G37:I37)/3/F37,"－") -> － | K37: 0 | L37: =IFERROR(K37/F37,"－") -> － | M37: 0 | N37: =IFERROR(M37/F37,"－") -> － | O37: 0 | P37: =IFERROR(O37/F37,"－") -> － | Q37: 0 | R37: =IFERROR(Q37/F37,"－") -> － | S37: 0 | T37: =IFERROR(S37/F37,"－") -> －
B38: 介護予防短期入所療養介護(介護医療院) | C38: 給付費（千円） | D38: 0 | E38: 0 | F38: 0 | G38: 0 | H38: 0 | I38: 0 | J38: =IFERROR(SUM(G38:I38)/3/F38,"－") -> － | K38: 0 | L38: =IFERROR(K38/F38,"－") -> － | M38: 0 | N38: =IFERROR(M38/F38,"－") -> － | O38: 0 | P38: =IFERROR(O38/F38,"－") -> － | Q38: 0 | R38: =IFERROR(Q38/F38,"－") -> － | S38: 0 | T38: =IFERROR(S38/F38,"－") -> －
C39: 日数（日） | D39: 0 | E39: 0 | F39: 0 | G39: 0 | H39: 0 | I39: 0 | J39: =IFERROR(SUM(G39:I39)/3/F39,"－") -> － | K39: 0 | L39: =IFERROR(K39/F39,"－") -> － | M39: 0 | N39: =IFERROR(M39/F39,"－") -> － | O39: 0 | P39: =IFERROR(O39/F39,"－") -> － | Q39: 0 | R39: =IFERROR(Q39/F39,"－") -> － | S39: 0 | T39: =IFERROR(S39/F39,"－") -> －
C40: 人数（人） | D40: 0 | E40: 0 | F40: 0 | G40: 0 | H40: 0 | I40: 0 | J40: =IFERROR(SUM(G40:I40)/3/F40,"－") -> － | K40: 0 | L40: =IFERROR(K40/F40,"－") -> － | M40: 0 | N40: =IFERROR(M40/F40,"－") -> － | O40: 0 | P40: =IFERROR(O40/F40,"－") -> － | Q40: 0 | R40: =IFERROR(Q40/F40,"－") -> － | S40: 0 | T40: =IFERROR(S40/F40,"－") -> －
B41: 介護予防福祉用具貸与 | C41: 給付費（千円） | D41: 2939.475 | E41: 3180.388 | F41: 3122.856 | G41: 3123 | H41: 3123 | I41: 3200 | J41: =IFERROR(SUM(G41:I41)/3/F41,"－") -> 1.0082651 | K41: 3449 | L41: =IFERROR(K41/F41,"－") -> 1.1044377 | M41: 3699 | N41: =IFERROR(M41/F41,"－") -> 1.1844927 | O41: 3699 | P41: =IFERROR(O41/F41,"－") -> 1.1844927 | Q41: 3283 | R41: =IFERROR(Q41/F41,"－") -> 1.0512813 | S41: 3123 | T41: =IFERROR(S41/F41,"－") -> 1.0000461
C42: 人数（人） | D42: 37.166667 | E42: 36.916667 | F42: 38 | G42: 38 | H42: 38 | I42: 39 | J42: =IFERROR(SUM(G42:I42)/3/F42,"－") -> 1.0087719 | K42: 42 | L42: =IFERROR(K42/F42,"－") -> 1.1052632 | M42: 45 | N42: =IFERROR(M42/F42,"－") -> 1.1842105 | O42: 45 | P42: =IFERROR(O42/F42,"－") -> 1.1842105 | Q42: 40 | R42: =IFERROR(Q42/F42,"－") -> 1.0526316 | S42: 38 | T42: =IFERROR(S42/F42,"－") -> 1
...

Sheet 3_地域支援事業費
A1: （３）地域支援事業費
K3: 保険者名 | L3: =保険者名 -> 川崎町
K4: 保険者番号 | L4: =保険者番号 -> 04324
K5: 推計パターン名 | L5: =推計パターン名 -> 第9期川崎町介護保険（R5.8.12）
A7: １．介護予防・日常生活支援総合事業 | L7: 単位：円(括弧書きの数値を除く)
A8: サービス種別・項目 | B8: R3 | C8: R4 | D8: R5 | E8: R6 | F8: R7 | G8: R8 | H8: R12 | I8: R17 | J8: R22 | K8: R27 | L8: R32
A9: 訪問介護相当サービス | B9: 2104145 | C9: 1788840 | D9: 1800000 | E9: 1800000 | F9: 1800000 | G9: 1800000 | H9: 1678279 | I9: 1559324 | J9: 1424693 | K9: 1257172 | L9: 1132992
A10: (利用者数：人) | B10: 2 | C10: 2 | D10: 2 | E10: 2 | F10: 2 | G10: 2 | H10: 2 | I10: 2 | J10: 2 | K10: 1 | L10: 1
A11: 訪問型サービスA | B11: 0 | C11: 0 | D11: 0 | E11: 0 | F11: 0 | G11: 0 | H11: 0 | I11: 0 | J11: 0 | K11: 0 | L11: 0
A12: (利用者数：人) | B12: 4 | C12: 7 | D12: 8 | E12: 8 | F12: 8 | G12: 8 | H12: 7 | I12: 7 | J12: 6 | K12: 6 | L12: 5
A13: 訪問型サービスB | B13: 308345 | C13: 336900 | D13: 340000 | E13: 350000 | F13: 350000 | G13: 350000 | H13: 407568 | I13: 430235 | J13: 403467 | K13: 356406 | L13: 324025
A14: 訪問型サービスC | B14: 0 | C14: 0 | D14: 0 | E14: 0 | F14: 0 | G14: 0 | H14: 0 | I14: 0 | J14: 0 | K14: 0 | L14: 0
A15: 訪問型サービスD | B15: 0 | C15: 0 | D15: 0 | E15: 0 | F15: 0 | G15: 0 | H15: 0 | I15: 0 | J15: 0 | K15: 0 | L15: 0
A16: 訪問型サービス(その他) | B16: 0 | C16: 0 | D16: 0 | E16: 0 | F16: 0 | G16: 0 | H16: 0 | I16: 0 | J16: 0 | K16: 0 | L16: 0
A17: 通所介護相当サービス | B17: 2665843 | C17: 3494201 | D17: 3500000 | E17: 3500000 | F17: 3500000 | G17: 3500000 | H17: 3263320 | I17: 3032018 | J17: 2770236 | K17: 2444501 | L17: 2203040
A18: (利用者数：人) | B18: 43 | C18: 43 | D18: 43 | E18: 43 | F18: 43 | G18: 43 | H18: 40 | I18: 37 | J18: 34 | K18: 30 | L18: 27
A19: 通所型サービスA | B19: 0 | C19: 0 | D19: 0 | E19: 0 | F19: 0 | G19: 0 | H19: 0 | I19: 0 | J19: 0 | K19: 0 | L19: 0
A20: (利用者数：人) | B20: 26 | C20: 18 | D20: 30 | E20: 30 | F20: 30 | G20: 30 | H20: 28 | I20: 26 | J20: 24 | K20: 21 | L20: 19
... A33: 上記以外の介護予防・日常生活総合事業 | B33: 0 | C33: 0 | D33: 0 | E33: 0 | F33: 0 | G33: 0 | H33: 0 | I33: 0 | J33: 0 | K33: 0 | L33: 0
A35: ２．包括的支援事業（地域包括支援センターの運営）及び任意事業 | L35: 単位：円
A36: サービス種別・項目 | B36: R3 | C36: R4 | D36: R5 | E36: R6 | F36: R7 | G36: R8 | H36: R12 | I36: R17 | J36: R22 | K36: R27 | L36: R32
A37: 包括的支援事業(地域包括支援センターの運営) | B37: 8123899 | C37: 8770489 | D37: 9000000 | E37: 9000000 | F37: 9000000 | G37: 9000000 | H37: 8739409 | I37: 8316977 | J37: 7965864 | K37: 7291070 | L37: 6860408
A38: 任意事業 | B38: 3947457 | C38: 3999998 | D38: 4000000 | E38: 4000000 | F38: 4000000 | G38: 4000000 | H38: 3884182 | I38: 3696434 | J38: 3540384 | K38: 3240475 | L38: 3049070
A40: ３．包括的支援事業（社会保障充実分） | L40: 単位：円
A41: サービス種別・項目 | B41: R3 | C41: R4 | D41: R5 | E41: R6 | F41: R7 | G41: R8 | H41: R12 | I41: R17 | J41: R22 | K41: R27 | L41: R32
A42: 在宅医療・介護連携推進事業 | B42: 2057834 | C42: 2242541 | D42: 2300000 | E42: 2300000 | F42: 2300000 | G42: 2300000 | H42: 2300000 | I42: 2300000 | J42: 2300000 | K42: 2300000 | L42: 2300000
A43: 生活支援体制整備事業 | B43: 2035101 | C43: 2293128 | D43: 2300000 | E43: 2300000 | F43: 2300000 | G43: 2300000 | H43: 2300000 | I43: 2300000 | J43: 2300000 | K43: 2300000 | L43: 2300000
A44: 認知症初期集中支援推進事業 | B44: 1330775 | C44: 1386948 | D44: 1500000 | E44: 1500000 | F44: 1500000 | G44: 1500000 | H44: 1500000 | I44: 1500000 | J44: 1500000 | K44: 1500000 | L44: 1500000
A45: 認知症地域支援・ケア向上事業 | B45: 1549450 | C45: 1704000 | D45: 1800000 | E45: 1800000 | F45: 1800000 | G45: 1800000 | H45: 1800000 | I45: 1800000 | J45: 1800000 | K45: 1800000 | L45: 1800000
A46: 認知症サポーター活動促進・地域づくり推進事業 | B46: 0 | C46: 0 | D46: 0 | E46: 0 | F46: 0 | G46: 0 | H46: 0 | I46: 0 | J46: 0 | K46: 0 | L46: 0
A47: 地域ケア会議推進事業 | B47: 1005933 | C47: 1062621 | D47: 1100000 | E47: 1100000 | F47: 1100000 | G47: 1100000 | H47: 1100000 | I47: 1100000 | J47: 1100000 | K47: 1100000 | L47: 1100000
A49: ４．地域支援事業費計 | L49: 単位：円
B50: R3 | C50: R4 | D50: R5 | E50: R6 | F50: R7 | G50: R8 | H50: R12 | I50: R17 | J50: R22 | K50: R27 | L50: R32
A51: 介護予防・日常生活支援総合事業費 | B51: =SUM(B9,B11,B13:B17,B19,B21:B33) -> 7314288 | C51: =SUM(C9,C11,C13:C17,C19,C21:C33) -> 8373793 | D51: =SUM(D9,D11,D13:D17,D19,D21:D33) -> 8504240 | E51: =SUM(E9,E11,E13:E17,E19,E21:E33) -> 8520000 | F51: =SUM(F9,F11,F13:F17,F19,F21:F33) -> 8520000 | G51: =SUM(G9,G11,G13:G17,G19,G21:G33) -> 8520000 | H51: =SUM(H9,H11,H13:H17,H19,H21:H33) -> 8782618 | I51: =SUM(I9,I11,I13:I17,I19,I21:I33) -> 8645978 | ... L51: =SUM(L9,L11,L13:L17,L19,L21:L33) -> 6389722
A52: 包括的支援事業（地域包括支援センターの運営）及び任意事業費 | B52: =SUM(B37:B38) -> 12071356 | C52: =SUM(C37:C38) -> 12770487 | D52: =SUM(D37:D38) -> 13000000 | E52: =SUM(E37:E38) -> 13000000 | F52: =SUM(F37:F38) -> 13000000 | G52: =SUM(G37:G38) -> 13000000 | H52: =SUM(H37:H38) -> 12623591 | I52: =SUM(I37:I38) -> 12013411 | ... L52: =SUM(L37:L38) -> 9909478
A53: 包括的支援事業（社会保障充実分） | B53: =SUM(B42:B47) -> 7979093 | C53: =SUM(C42:C47) -> 8689238 | D53: =SUM(D42:D47) -> 9000000 | E53: =SUM(E42:E47) -> 9000000 | F53: =SUM(F42:F47) -> 9000000 | G53: =SUM(G42:G47) -> 9000000 | H53: =SUM(H42:H47) -> 9000000 | I53: =SUM(I42:I47) -> 9000000 | ... L53: =SUM(L42:L47) -> 9000000
A54: 地域支援事業費 | B54: =SUM(B51:B53) -> 27364737 | C54: =SUM(C51:C53) -> 29833518 | D54: =SUM(D51:D53) -> 30504240 | E54: =SUM(E51:E53) -> 30520000 | F54: =SUM(F51:F53) -> 30520000 | G54: =SUM(G51:G53) -> 30520000 | H54: =SUM(H51:H53) -> 30406209 | I54: =SUM(I51:I53) -> 29659389 | ... L54: =SUM(L51:L53) -> 25299200
A56: ※事業費は年間累計の金額。人数は１月当たりの利用者数。

Sheet 4_施策反映の解説
A1: （４）施策反映の内容
K2: 出力日： | L2: ='1_推計値サマリ'!T2 -> 2023/10/05
I3: 保険者名 | K3: =保険者名 -> 川崎町
I4: 保険者番号 | K4: =保険者番号 -> 04324
I5: 推計パターン名 | K5: =推計パターン名 -> 第9期川崎町介護保険（R5.8.12）
A7: 施策反映の全体方針
A8: 出力後に入力
A9: １．自然体推計手法
A10: 認定者数の自然体推計手法 | B10: 性別／年齢５歳階級別／要介護度別に推計する ※初期値
A11: 介護サービス利用者数の自然体推計手法 | B11: サービス別／要介護度別に推計する ※初期値
A12: ２．要介護(支援)認定者数
A13: 推計に用いた認定率の伸び | B13: 令和3年度→令和4年度 ※初期値
B14: 認定者数の設定内容
A15: 認定者数
B17: 施策反映内容
A18: 認定者数
A19: ３．施設・居住系サービス利用者数
A20: 推計に用いた利用率の伸び | B20: ０（ゼロ）※初期値
A21: 推計に用いた1人1月あたりの給付費の実績値 | B21: 令和5年度
B22: 給付費の設定内容
A23: 1人1月あたり給付費
B24: 利用者数の設定内容
A25: 施設・居住系サービス利用者数
B26: 施策反映内容
A27: （１）居宅サービス | B27: 実績値を反映
A28: （２）地域密着型サービス | B28: 実績値を反映
A29: （３）施設サービス | B29: 実績値を反映
A30: ４．在宅サービス利用者数
A31: 推計に用いた利用率の伸び | B31: ０（ゼロ）※初期値
A32: 推計に用いた1人1月あたり利用回（日）数の伸び | B32: ０（ゼロ）※初期値
A33: 推計に用いた1人1月あたりの給付費の実績値 | B33: 令和5年度
B34: 利用者数の設定内容
A35: 在宅サービス利用者数
B36: 利用回(日)数の設定内容
A37: 在宅サービス利用回(日)数
B38: 給付費の設定内容
A39: 1人1月あたり給付費
B40: 施策反映内容
A41: 在宅サービス利用者数(利用率) | B41: 実績値を反映
A42: 在宅サービス利用回(日)数
...

Sheet 5_保険料推計
A1: （５）第１号被保険者の保険料推計
P3: 保険者名 | Q3: =保険者名 -> 川崎町
P4: 保険者番号 | Q4: =保険者番号 -> 04324
P5: 推計パターン名 | Q5: =推計パターン名 -> 第9期川崎町介護保険（R5.8.12）
A7: １．８期保険料基準額
A8: 第８期保険料の基準額（月額） | F8: 6382.5283
A10: ２．保険料基準額の指標
F11: 第9期 | G11: 令和12年度 | H11: 令和17年度 | I11: 令和22年度 | J11: 令和27年度 | K11: 令和32年度
A12: 保険料基準額（月額） | F12: =F101/F102/F200/12 -> 7644.2121 | G12: =J101/J102/J200/12 -> 8737.5221 | H12: =K101/K102/K200/12 -> 9342.0415 | I12: =L101/L102/L200/12 -> 9651.9332 | J12: =M101/M102/M200/12 -> 9870.8316 | K12: =N101/N102/N200/12 -> 10722.786
A13: 準備基金取崩額の影響額 | F13: =(F101+F15)/F102/F200/12-F12 -> 0 | G13: =(J101+G15)/J102/J200/12-G12 -> 0 | H13: =(K101+H15)/K102/K200/12-H12 -> 0 | I13: =(L101+I15)/L102/L200/12-I12 -> 0 | J13: =(M101+J15)/M102/M200/12-J12 -> 0 | K13: =(N101+K15)/N102/N200/12-K12 -> 0
B14: 準備基金の残高（前年度末の見込額） | F14: 0 | G14: 0 | H14: 0 | I14: 0 | J14: 0 | K14: 0
B15: 準備基金取崩額 | F15: 0 | G15: 0 | H15: 0 | I15: 0 | J15: 0 | K15: 0
B16: 準備基金取崩割合 | F16: =IF(F14=0,0, F15/F14) -> 0 | G16: =IF(G14=0,0,G15/G14) -> 0 | H16: =IF(H14=0,0,H15/H14) -> 0 | I16: =IF(I14=0,0,I15/I14) -> 0 | J16: =IF(J14=0,0,J15/J14) -> 0 | K16: =IF(K14=0,0,K15/K14) -> 0
A17: 財政安定化基金拠出金見込額の影響額 | F17: =F12-(F101-F18)/F102/F200/12 -> 0 | G17: =G12-(J101-G18)/J102/J200/12 -> 0 | H17: =H12-(K101-H18)/K102/K200/12 -> 0 | I17: =I12-(L101-I18)/L102/L200/12 -> 0 | J17: =J12-(M101-J18)/M102/M200/12 -> 0 | K17: =K12-(N101-K18)/N102/N200/12 -> 0
B18: 財政安定化基金拠出金見込額 | F18: =(F68+F84)*F19 -> 0 | G18: =(J68+J84)*G19 -> 0 | H18: =(K68+K84)*H19 -> 0 | I18: =(L68+L84)*I19 -> 0 | J18: =(M68+M84)*J19 -> 0 | K18: =(N68+N84)*K19 -> 0
B19: 財政安定化基金拠出率 | F19: 0 | G19: 0 | H19: 0 | I19: 0 | J19: 0 | K19: 0
A20: 財政安定化基金償還金の影響額 | F20: =F12-(F101-F21)/F102/F200/12 -> 0 | G20: =G12-(J101-G21)/J102/J200/12 -> 0 | H20: =H12-(K101-H21)/K102/K200/12 -> 0 | I20: =I12-(L101-I21)/L102/L200/12 -> 0 | J20: =J12-(M101-J21)/M102/M200/12 -> 0 | K20: =K12-(N101-K21)/N102/N200/12 -> 0
B21: 財政安定化基金償還金 | F21: 0 | G21: 0 | H21: 0 | I21: 0 | J21: 0 | K21: 0
A22: 保険料基準額の伸び率（％） （対８期保険料） | F22: =F12/$F$8-1 -> 0.19767774 | G22: =G12/$F$8-1 -> 0.36897505 | H22: =H12/$F$8-1 -> 0.46368978 | I22: =I12/$F$8-1 -> 0.51224291 | J22: =J12/$F$8-1 -> 0.54653941 | K22: =K12/$F$8-1 -> 0.6800217
A24: ３．保険料設定を弾力化した場合の保険料額の指標
F25: 第9期 | G25: 令和12年度 | H25: 令和17年度 | I25: 令和22年度 | J25: 令和27年度 | K25: 令和32年度
A26: 保険料基準額（月額） | F26: =IFERROR(F101/F102/F201/12,"－") -> － | G26: =IFERROR(J101/J102/J201/12,"－") -> － | H26: =IFERROR(K101/K102/K201/12,"－") -> － | I26: =IFERROR(L101/L102/L201/12,"－") -> － | J26: =IFERROR(M101/M102/M201/12,"－") -> － | K26: =IFERROR(N101/N102/N201/12,"－") -> －
A27: 準備基金取崩額の影響額 | F27: =IFERROR((F101+F29)/F102/F201/12-F26,"－") -> － | G27: =IFERROR((J101+G29)/J102/J201/12-G26,"－") -> － | H27: =IFERROR((K101+H29)/K102/K201/12-H26,"－") -> － | I27: =IFERROR((L101+I29)/L102/L201/12-I26,"－") -> － | J27: =IFERROR((M101+J29)/M102/M201/12-J26,"－") -> － | K27: =IFERROR((N101+K29)/N102/N201/12-K26,"－") -> －
B28: 準備基金の残高（前年度末の見込額） | F28: =IF(F26="－","－",F14) -> － | G28: =IF(G26="－","－",G14) -> － | H28: =IF(H26="－","－",H14) -> － | I28: =IF(I26="－","－",I14) -> － | J28: =IF(J26="－","－",J14) -> － | K28: =IF(K26="－","－",K14) -> －
B29: 準備基金取崩額 | F29: =IF(F26="－","－",F15) -> － | G29: =IF(G26="－","－",G15) -> － | H29: =IF(H26="－","－",H15) -> － | I29: =IF(I26="－","－",I15) -> － | J29: =IF(J26="－","－",J15) -> － | K29: =IF(K26="－","－",K15) -> －
B30: 準備基金取崩割合 | F30: =IFERROR(F29/F28,"－") -> － | G30: =IFERROR(G29/G28,"－") -> － | H30: =IFERROR(H29/H28,"－") -> － | I30: =IFERROR(I29/I28,"－") -> － | J30: =IFERROR(J29/J28,"－") -> － | K30: =IFERROR(K29/K28,"－") -> －
A31: 財政安定化基金拠出金見込額の影響額 | F31: =IFERROR(F26-(F101-F32)/F102/F201/12,"－") -> － | G31: =IFERROR(G26-(J101-G32)/J102/J201/12,"－") -> － | H31: =IFERROR(H26-(K101-H32)/K102/K201/12,"－") -> － | I31: =IFERROR(I26-(L101-I32)/L102/L201/12,"－") -> － | J31: =IFERROR(J26-(M101-J32)/M102/M201/12,"－") -> － | K31: =IFERROR(K26-(N101-K32)/N102/N201/12,"－") -> －
B32: 財政安定化基金拠出金見込額 | F32: =IF(F26="－","－",(F68+F84)*F33) -> － | G32: =IF(G26="－","－",(J68+J84)*G33) -> － | H32: =IF(H26="－","－",(K68+K84)*H33) -> － | I32: =IF(I26="－","－",(L68+L84)*I33) -> － | J32: =IF(J26="－","－",(M68+M84)*J33) -> － | K32: =IF(K26="－","－",(N68+N84)*K33) -> －
B33: 財政安定化基金拠出率 | F33: =IF(F26="－","－",F19) -> － | G33: =IF(G26="－","－",G19) -> － | H33: =IF(H26="－","－",H19) -> － | I33: =IF(I26="－","－",I19) -> － | J33: =IF(J26="－","－",J19) -> － | K33: =IF(K26="－","－",K19) -> －
A34: 財政安定化基金償還金の影響額 | F34: =IFERROR(F26-(F101-F35)/F102/F201/12,"－") -> － | G34: =IFERROR(G26-(J101-G35)/J102/J201/12,"－") -> － | H34: =IFERROR(H26-(K101-H35)/K102/K201/12,"－") -> － | I34: =IFERROR(I26-(L101-I35)/L102/L201/12,"－") -> － | J34: =IFERROR(J26-(M101-J35)/M102/M201/12,"－") -> － | K34: =IFERROR(K26-(N101-K35)/N102/N201/12,"－") -> －
B35: 財政安定化基金償還金 | F35: =IF(F26="－","－",F21) -> － | G35: =IF(G26="－","－",G21) -> － | H35: =IF(H26="－","－",H21) -> － | I35: =IF(I26="－","－",I21) -> － | J35: =IF(J26="－","－",J21) -> － | K35: =IF(K26="－","－",K21) -> －
A36: 保険料基準額の伸び率（％） （対８期保険料） | F36: =IFERROR(F26/$F$8-1,"－") -> － | G36: =IFERROR(G26/$F$8-1,"－") -> － | H36: =IFERROR(H26/$F$8-1,"－") -> － | I36: =IFERROR(I26/$F$8-1,"－") -> － | J36: =IFERROR(J26/$F$8-1,"－") -> － | K36: =IFERROR(K26/$F$8-1,"－") -> －
A38: ４ 介護保険料基準額（月額）の内訳
F39: 金額 | L39: 構成比
F40: 第9期 | G40: 令和12年度 | H40: 令和17年度 | I40: 令和22年度 | J40: 令和27年度 | K40: 令和32年度 | L40: 第9期 | M40: 令和12年度 | N40: 令和17年度 | O40: 令和22年度 | P40: 令和27年度 | Q40: 令和32年度
A41: 総給付費 | F41: =(F69*'(参考)保険料の推計に要する係数'!D5+(F89-F90))/(F200*F102*12) -> 6919.9114 | G41: =(J69*'(参考)保険料の推計に要する係数'!E5+(J89-J90))/(J200*J102*12) -> 7933.2624 | H41: =(K69*'(参考)保険料の推計に要する係数'!F5+(K89-K90))/(K200*K102*12) -> 8406.188 | I41: =(L69*'(参考)保険料の推計に要する係数'!G5+(L89-L90))/(L200*L102*12) -> 8604.8957 | J41: =(M69*'(参考)保険料の推計に要する係数'!H5+(M89-M90))/(M200*M102*12) -> 8761.2297 | K41: =(N69*'(参考)保険料の推計に要する係数'!I5+(N89-N90))/(N200*N102*12) -> 9541.6212 | L41: =F41/$F$49 -> 0.90524848 | M41: =G41/$G$49 -> 0.90795334 | N41: =H41/$H$49 -> 0.89982344 | O41: =I41/$I$49 -> 0.89152044 | P41: =J41/$J$49 -> 0.88758779 | Q41: =K41/$K$49 -> 0.88984533
B42: 在宅サービス | F42: =$F$41*SUM('2_サービス別給付費'!G147:I147)/SUM('2_サービス別給付費'!$G$146:$I$146) -> 2391.5946 | G42: =$G$41*SUM('2_サービス別給付費'!J147)/SUM('2_サービス別給付費'!$J$146) -> 2689.8751 | H42: =$H$41*SUM('2_サービス別給付費'!K147)/SUM('2_サービス別給付費'!$K$146) -> 2872.2178 | I42: =$I$41*SUM('2_サービス別給付費'!L147)/SUM('2_サービス別給付費'!$L$146) -> 2896.6078 | J42: =$J$41*SUM('2_サービス別給付費'!M147)/SUM('2_サービス別給付費'!$M$146) -> 2922.9609 | K42: =$K$41*SUM('2_サービス別給付費'!N147)/SUM('2_サービス別給付費'!$N$146) -> 3138.0849 | L42: =F42/$F$49 -> 0.31286345 | M42: =G42/$G$49 -> 0.30785331 | N42: =H42/$H$49 -> 0.30745077 | O42: =I42/$I$49 -> 0.30010649 | P42: =J42/$J$49 -> 0.29612103 | Q42: =K42/$K$49 -> 0.29265574
B43: 居住系サービス | F43: =$F$41*SUM('2_サービス別給付費'!G148:I148)/SUM('2_サービス別給付費'!$G$146:$I$146) -> 556.57276 | G43: =$G$41*SUM('2_サービス別給付費'!J148)/SUM('2_サービス別給付費'!$J$146) -> 673.82307 | H43: =$H$41*SUM('2_サービス別給付費'!K148)/SUM('2_サービス別給付費'!$K$146) -> 703.80376 | I43: =$I$41*SUM('2_サービス別給付費'!L148)/SUM('2_サービス別給付費'!$L$146) -> 728.03193 | J43: =$J$41*SUM('2_サービス別給付費'!M148)/SUM('2_サービス別給付費'!$M$146) -> 693.72833 | K43: =$K$41*SUM('2_サービス別給付費'!N148)/SUM('2_サービス別給付費'!$N$146) -> 744.09688 | L43: =F43/$F$49 -> 0.072809695 | M43: =G43/$G$49 -> 0.077118325 | N43: =H43/$H$49 -> 0.075337254 | O43: =I43/$I$49 -> 0.075428612 | P43: =J43/$J$49 -> 0.070280637 | Q43: =K43/$K$49 -> 0.069393987
B44: 施設サービス | F44: =$F$41*SUM('2_サービス別給付費'!G149:I149)/SUM('2_サービス別給付費'!$G$146:$I$146) -> 3971.7441 | G44: =$G$41*SUM('2_サービス別給付費'!J149)/SUM('2_サービス別給付費'!$J$146) -> 4569.5642 | H44: =$H$41*SUM('2_サービス別給付費'!K149)/SUM('2_サービス別給付費'!$K$146) -> 4830.1664 | I44: =$I$41*SUM('2_サービス別給付費'!L149)/SUM('2_サービス別給付費'!$L$146) -> 4980.256 | J44: =$J$41*SUM('2_サービス別給付費'!M149)/SUM('2_サービス別給付費'!$M$146) -> 5144.5405 | K44: =$K$41*SUM('2_サービス別給付費'!N149)/SUM('2_サービス別給付費'!$N$146) -> 5659.4394 | L44: =F44/$F$49 -> 0.51957533 | M44: =G44/$G$49 -> 0.52298171 | N44: =H44/$H$49 -> 0.51703542 | O44: =I44/$I$49 -> 0.51598534 | P44: =J44/$J$49 -> 0.52118612 | Q44: =K44/$K$49 -> 0.52779561
A45: その他給付費 | F45: =((F73+F76+F79+F80)*'(参考)保険料の推計に要する係数'!D5+F83)/(F200*F102*12) -> 532.8067 | G45: =((J73+J76+J79+J80)*'(参考)保険料の推計に要する係数'!E5+J83)/(J200*J102*12) -> 600.49296 | H45: =((K73+K76+K79+K80)*'(参考)保険料の推計に要する係数'!F5+K83)/(K200*K102*12) -> 718.20406 | I45: =((L73+L76+L79+L80)*'(参考)保険料の推計に要する係数'!G5+L83)/(L200*L102*12) -> 819.99665 | J45: =((M73+M76+M79+M80)*'(参考)保険料の推計に要する係数'!H5+M83)/(M200*M102*12) -> 869.1688 | K45: =((N73+N76+N79+N80)*'(参考)保険料の推計に要する係数'!I5+N83)/(N200*N102*12) -> 929.05558 | L45: =F45/$F$49 -> 0.069700669 | M45: =G45/$G$49 -> 0.068725773 | N45: =H45/$H$49 -> 0.076878705 | O45: =I45/$I$49 -> 0.084956726 | P45: =J45/$J$49 -> 0.088054263 | Q45: =K45/$K$49 -> 0.086643114
...

Sheet (参考)保険料の推計に要する係数
B1: (参考)保険料の推計に要する係数
D4: R6～R8 | E4: R12 | F4: R17 | G4: R22 | H4: R27 | I4: R32
C5: 第１号被保険者負担割合（%） | D5: 0.23 | E5: 0.24 | F5: 0.25 | G5: 0.26 | H5: 0.27 | I5: 0.28
B7: 後期高齢者加入割合補正係数の算出に係る係数（全国値） （仮置値）
D8: R6 | E8: R7 | F8: R8 | G8: R12 | H8: R17 | I8: R22 | J8: R27 | K8: R32
C9: 前期高齢者加入割合 | D9: 0.4249 | E9: 0.4102 | F9: 0.3992 | G9: 0.3882 | H9: 0.4068 | I9: 0.433 | J9: 0.4228 | K9: 0.3742
C10: 85歳未満後期高齢者加入割合 | D10: 0.3867 | E10: 0.3962 | F10: 0.3997 | G10: 0.3921 | H10: 0.3332 | I10: 0.3109 | J10: 0.3343 | K10: 0.3786
C11: 85歳以上後期高齢者加入割合 | D11: 0.1884 | E11: 0.1936 | F11: 0.2011 | G11: 0.2197 | H11: 0.26 | I11: 0.2561 | J11: 0.2429 | K11: 0.2472
C12: 前期高齢者の1人あたり給付費 | D12: 4296 | E12: 4296 | F12: 4296 | G12: 4296 | H12: 4296 | I12: 4296 | J12: 4296 | K12: 4296
C13: 85歳未満後期高齢者の1人あたり給付費 | D13: 17647 | E13: 17647 | F13: 17647 | G13: 17647 | H13: 17647 | I13: 17647 | J13: 17647 | K13: 17647
C14: 85歳以上後期高齢者の1人あたり給付費 | D14: 80362 | E14: 80362 | F14: 80362 | G14: 80362 | H14: 80362 | I14: 80362 | J14: 80362 | K14: 80362
B16: 所得段階別加入割合補正係数の算出に係る係数（全国値）（％） （仮置値）
C17: 第1段階 | D17: 0.1731
C18: 第2段階 | D18: 0.0924
C19: 第3段階 | D19: 0.0839
C20: 第4段階 | D20: 0.1092
C21: 第5段階 | D21: 0.138
C22: 第6段階 | D22: 0.1245
C23: 第7段階 | D23: 0.147
C24: 第8段階 | D24: 0.0657
C25: 第9段階 | D25: 0.0231
C26: 第10段階 | D26: 0.0121
C27: 第11段階 | D27: 0.0065
C28: 第12段階 | D28: 0.0043
C29: 第13段階 | D29: 0.0204
B33: 費用負担の見直しに伴う調整に係る係数（参考値）（未定）
C34: 利用者負担の見直し等に伴う財政影響補正係数 | D34: 1
C35: 特定入所者介護サービス費等に係る制度改正に伴う財政影響補正係数 | D35: 1
C38: 国庫負担金等の算定の基準となる算定対象審査支払手数料単価（上限）（円） | D38: 95
