Workbook

Sheet 北塩原村_出典・推計メモ
A1: 第8期北塩原村障がい福祉計画・第4期北塩原村障がい児福祉計画 策定ワークシート（令和8年9月30日作成）
A3: 1. 凡例
B4: （着色セル） | C4: 推計値・仮置き値（R6～R8の実績推計、R9～R11の見込量案、村の台帳データがない項目）。村の実績データ受領後に差し替える。
B5: 無着色の数値 | C5: 計画書・統計等からの転記値（出典は下記）。
A7: 2. 主な出典
B8: 第4次北塩原村障がい者計画・第7期障がい福祉計画・第3期障がい児福祉計画（令和6年3月） | C8: 人口・手帳所持者数（H31～R5）、サービス実績（R3～R5）と第6期・第7期見込量、地域生活支援事業、成果目標、基本理念・目標・施策、協議会委員名簿、第7期アンケート結果（一部）
B9: 第8期障がい福祉計画・第4期障がい児福祉計画策定業務委託仕様書（令和8年6月） | C9: 調査対象（身体約130人・精神約40人・療育約20人）、事業所調査なし、協議会1回程度、担当課（保健福祉課福祉係）
B10: 第3次健康21・北塩原村グッドヘルスプラン（令和6～17年度） | C10: 関連計画の構成（食育推進計画・いのちを守る対策計画を包含）
B11: 総務省「住民基本台帳に基づく人口、人口動態及び世帯数」 | C11: 総人口（外国人含む・1月1日）：R6 2,427人、R7 2,394人、R8 2,342人。R7の5歳階級別男女別人口。日本人世帯数（R2～R8）
B12: 国の基本指針（令和8年こども家庭庁・厚生労働省告示第4号）・改正後概要 | C12: 第8期の成果目標・活動指標（地域移行6％・削減5％、一般就労1.31倍、定着支援1.47倍、就労選択支援、のぞまないセルフプラン等）
B13: 障害福祉サービス等情報検索（WAM NET）掲載情報ほか | C13: 事業所一覧（暫定・一部）
A15: 3. 推計の考え方
B16: 人口（R6～R8） | C16: 1月1日の住基人口から年度末の転出等（約▲25～30人）を差し引いて4月1日時点を推計。R9～R11は近年の減少（年約50人）を延長。
B17: 手帳所持者数 | C17: R6～R8は仕様書の調査対象者数（身体約130人・精神約40人・療育約20人）を目安に、R5実績から推移を推計。等級別・種類別・級別の内訳（R5以外）は構成比で按分。
B18: サービス実績（R6～R8） | C18: 第7期見込量、R3～R5実績、計画書の記述（新規利用予定・児童の就園等）から推計。R8は年度途中のため見込み。
B19: 見込量（R9～R11） | C19: R8実績見込みを基本に、特別支援学校卒業、医療的ケア児の就学、地域生活支援拠点の緊急受入れ、就労選択支援の開始、長期入院者の地域移行等を加味した案。
B20: 自立支援医療・支援区分・重度医療 | C20: 村の台帳データがないため、全国の出現率や手帳所持者の構成から設定した仮置き値。
B21: アンケート結果 | C21: 第8期調査（令和8年度）前の仮置き値。N=110（配布約190人×回収率約58％）を想定し、第7期調査の既知結果を参考に設定。
A23: 4. 村への照会事項
B24: 統計・台帳 | C24: R6～R8の住基人口（4月1日）・世帯数、手帳所持者数（等級・種類・級別）、自立支援医療、支援区分、重度医療等の受給者数
B25: サービス実績 | C25: R6～R8の障がい福祉サービス・障がい児通所支援・地域生活支援事業の利用者数・利用量（国保連データ等）
B26: 成果目標関連 | C26: 令和7年度末施設入所者数、令和6年度の一般就労移行者数・就労定着支援利用者数、基幹相談支援センター・専門部会・医療的ケア児コーディネーター等の状況、セルフプラン件数
B27: その他 | C27: 協議会委員（現任期）、総合振興計画の期間、子ども・子育て関係計画の名称・期間、事業所一覧の確認
A29: 5. テンプレートからの主な修正
B30: 自治体固有の記載 | C30: 小野町・阿蘇市（熊本県）の記載・画像を北塩原村・福島県の内容に置換（計画位置づけ図、関連計画図、構成図、基本理念、圏域図を含む）
B31: 区分・様式 | C31: 療育手帳区分をA・Bに変更、地域生活支援事業（必須・任意）を本村の実施事業に合わせて再構成、就労選択支援等の第8期項目を追加
B32: 誤りの修正 | C32: 日中活動系の説明文の入れ替わり、「療育介護」→「療養介護」、相談支援事業の見出し、アンケート割合式の分母、精神手帳の対人口比の参照列、用語集の誤字、国の基本指針の数値（第7期→第8期）

Sheet PDCA

Sheet 計画期間
A2: 計画＼年度 | B2: 令和３年度 | C2: 令和４年度 | D2: 令和５年度 | E2: 令和６年度 | F2: 令和７年度 | G2: 令和８年度 | H2: 令和９年度 | I2: 令和10年度 | J2: 令和11年度 | K2: 令和12年度 | L2: 令和13年度 | M2: 令和14年度
A4: 総合振興計画 | B4: 北塩原村第五次総合振興計画（平成29年度～令和8年度） | H4: 北塩原村次期総合振興計画（令和9年度～・予定）
A5: 高齢者福祉 | B5: 第8期高齢者福祉計画・介護保険事業計画 | E5: 第9期高齢者福祉計画・介護保険事業計画 | H5: 第10期高齢者福祉計画・介護保険事業計画 | K5: 第11期
A6: 障がい者計画 | B6: 第3次障がい者計画 | E6: 第4次北塩原村障がい者計画（令和6年度～令和11年度） | K6: 第5次障がい者計画
A8: 障がい福祉計画 | B8: 第6期障がい福祉計画 | E8: 第7期障がい福祉計画 | H8: 第8期北塩原村障がい福祉計画【本計画】 | K8: 第9期障がい福祉計画
A10: 障がい児福祉計画 | B10: 第2期障がい児福祉計画 | E10: 第3期障がい児福祉計画 | H10: 第4期北塩原村障がい児福祉計画【本計画】 | K10: 第5期障がい児福祉計画
A12: 健康21 | B12: 第2次健康21・グッドヘルスプラン | E12: 第3次健康21・北塩原村グッドヘルスプラン（令和6年度～令和17年度）
B14: ※総合振興計画の期間（第五次：平成29年3月策定）・次期計画の開始年度、健康21の前計画期間は村に要確認。太枠（R9～R11）が本計画期間。

Sheet Sheet1
A1: 区分 | B1: 令和4年度 | C1: 令和6年度 | D1: 令和8年度 | E1: 令和11年度（推計）
A2: 総人口 | B2: =人口状況!E4 -> 2535 | C2: =人口状況!G4 -> 2405 | D2: =人口状況!I4 -> 2316 | E2: =人口状況!L4 -> 2166
A3: 65歳以上人口割合 | B3: =人口状況!E6 -> 0.39566075 | C3: =人口状況!G6 -> 0.41580042 | D3: =人口状況!I6 -> 0.43091537 | E3: =人口状況!L6 -> 0.45152355
A5: ※人口状況シートから参照（令和4年度は実数、令和6年度以降は推計を含む）。

Sheet 日常生活アンケート
A1: 問4 日常生活で、次のことをするときに介助が必要ですか。①から⑩のそれぞれにお答えください。(①〜⑩それぞれに〇を一つ)
A3: 項 目 | C3: ひとりで できる | D3: 一部介助 が必要 | E3: 全部介助 が必要
A4: ① | B4: 食事をする | C4: □1 | D4: □2 | E4: □3
A5: ② | B5: トイレをする | C5: □1 | D5: □2 | E5: □3
A6: ③ | B6: 入浴をする | C6: □1 | D6: □2 | E6: □3
A7: ④ | B7: 衣服を着たり脱いだりする | C7: □1 | D7: □2 | E7: □3
A8: ⑤ | B8: 身だしなみを整える | C8: □1 | D8: □2 | E8: □3
A9: ⑥ | B9: 家の中を移動する | C9: □1 | D9: □2 | E9: □3
A10: ⑦ | B10: 住まいから目的地までの移動 | C10: □1 | D10: □2 | E10: □3
A11: ⑧ | B11: 家族以外の人との意思疎通 | C11: □1 | D11: □2 | E11: □3
A12: ⑨ | B12: お金の管理をする | C12: □1 | D12: □2 | E12: □3
A13: ⑩ | B13: 買物をする | C13: □1 | D13: □2 | E13: □3
A14: ⑪ | B14: 薬の管理をする | C14: □1 | D14: □2 | E14: □3
C16: ↓ | D16: ↓
B17: ①〜⑩の項目すべて「ひとりで できる」場合は問7へ | D17: 点線中に〇が一つ以上 ある場合は問5へ
A20: 番号 | B20: 選択肢
A21: □1. | B21: 在宅で医療ケアが適切（十分な回数や日数）に得られること
A22: □2. | B22: 障がい者に適した住居の確保
A23: □3. | B23: 必要な在宅サービスが適切（十分な回数や日数）に利用できること
A24: □4. | B24: 生活訓練の充実
A25: □5. | B25: 経済的な負担の軽減
A26: □6. | B26: 相談対応の充実
A27: □7. | B27: 地域住民の理解
A28: □8. | B28: 情報の取得利用や意思疎通についての支援
A29: □9. | B29: その他（ ）
A32: □1. | B32: 公共交通機関が少ない（ない）
A33: □2. | B33: 列車やバスの乗り降りが困難
... A42: □11. | B42: その他（ ）
A45: □1. | B45: 会社勤めや、自営業、家業などで収入を得て仕事をしている | C45: → | D45: 問26へ
A46: □2. | B46: ボランティアなど、収入を得ない仕事をしている
A47: □3. | B47: 専業主婦（主夫）をしている
A48: □4. | B48: 福祉施設、就労支援事業所に通っている
A49: □5. | B49: 病院などのデイケアに通っている
A50: □6. | B50: リハビリテーションを受けている
A51: □7. | B51: 自宅で過ごしている | D51: 問27へ
A52: □8. | B52: 入所している施設や病院で過ごしている
A53: □9. | B53: 大学、専門学校、職業訓練校に通っている
A54: □10. | B54: 特別支援学校（小中高等部）に通っている
A55: □11. | B55: 一般の高校、小中学校に通っている
A56: □12. | B56: 幼稚園、保育所、障がい児通園施設に通っている
...

Sheet 障害福祉サービス必要見込量
A1: ■訪問系サービス
A2: サービスの名称 | B2: 内容
A3: 居宅介護 | B3: 自宅で入浴や排泄、食事の介護、家事における支援等を行う。
A4: 重度訪問介護 | B4: 重度の障がいがあり、常に介護が必要な人に、自宅での介護から外出時の移動支援までを総合的に行う。
A5: 同行援護 | B5: 視覚障がいにより移動が著しく困難な人に、外出時同行し、必要な情報の提供や移動の支援を行う。
A6: 行動援護 | B6: 知的障がいや精神障がいにより行動が困難で、常に介護が必要な人に、外出時の移動の支援や行動の際に生じる危険回避のための援護等を行う。
A7: 重度障害者等包括支援 | B7: 介護の必要性がとても高い人に、居宅介護等の障害福祉サービスを包括的に行う。
A9: ■日中活動系サービス
A10: サービスの名称 | B10: 内容
A11: 生活介護 | B11: 常に介護を必要とする人に、主に昼間、施設等で入浴、排せつ、食事の介護等を行うとともに、創作的活動や生産活動の機会を提供する。
A12: 自立訓練（機能訓練） | B12: 自立した日常生活又は社会生活ができるよう、一定期間、身体機能の向上のために必要な訓練を行う。
A13: 自立訓練（生活訓練） | B13: 自立した日常生活又は社会生活ができるよう、一定期間、生活能力の向上のために必要な訓練を行う。
A14: 就労選択支援 | B14: 就労を希望する人に、就労能力や適性等の評価（アセスメント）を行い、本人の希望や能力に合った就労先・働き方の選択を支援する（令和7年10月開始）。
A15: 就労移行支援 | B15: 一般企業等への就労を希望する人に、一定期間、就労に必要な知識及び能力の向上のために必要な訓練を行う。
A16: 就労継続支援（A型） | B16: 一般企業等での就労が困難な人に、雇用契約に基づく就労の機会を提供するとともに、知識及び能力の向上のために必要な訓練を行う。
A17: 就労継続支援（B型） | B17: 一般企業等での就労が困難な人に、雇用契約を結ばずに就労や生産活動の機会を提供するとともに、知識及び能力の向上のために必要な訓練を行う。
A18: 就労定着支援 | B18: 一般就労へ移行した人に、就労に伴う生活面の課題に対応できるよう、企業や自宅への訪問等により必要な支援を行う。
A19: 療養介護 | B19: 医療と常時介護を必要とする人に、医療機関で機能訓練、療養上の管理、看護、介護及び日常生活の世話を行う。
A20: 短期入所（ショートステイ）福祉型 | B20: 自宅で介護する人の病気等の理由により、障害者支援施設等に短期間入所し、入浴、排せつ、食事の介護等を行う。
A21: 短期入所（ショートステイ）医療型 | B21: 医療的ケアが必要な人等が、病院・診療所・介護老人保健施設等に短期間入所し、介護や医療的な支援を受ける。
A23: ■居住系サービス
A24: サービスの名称 | B24: 内容
A25: 自立生活援助 | B25: 施設やグループホーム等から一人暮らしに移行した人に、定期的な巡回訪問や随時の対応により日常生活の課題を把握し、必要な支援を行う。
A26: 共同生活援助（グループホーム） | B26: 共同生活を行う住居で、主に夜間において相談や入浴、排せつ、食事の介護等の日常生活上の援助を行う。
A27: 施設入所支援 | B27: 施設に入所する人に、主に夜間において、入浴、排せつ、食事の介護等を行う。
A29: ■相談支援
A30: サービスの名称 | B30: 内容
A31: 計画相談支援 | B31: 障がい福祉サービス等を利用する人のサービス等利用計画を作成し、一定期間ごとにモニタリング（見直し）を行う。
A32: 地域移行支援 | B32: 障害者支援施設等に入所している人や精神科病院に入院している人に、住居の確保や地域生活への移行に関する相談・同行等の支援を行う。
A33: 地域定着支援 | B33: 単身等で生活する人に、常時の連絡体制を確保し、緊急時の相談や訪問等の支援を行う。
A35: ■障がい児支援
A36: サービスの名称 | B36: 内容
A37: 児童発達支援 | B37: 未就学の障がい児に、日常生活における基本的な動作の指導、知識技能の付与、集団生活への適応訓練等の支援を行う。
A38: 放課後等デイサービス | B38: 就学中の障がい児に、授業の終了後や休業日に、生活能力の向上のための訓練や社会との交流の促進等の支援を行う。
A39: 保育所等訪問支援 | B39: 保育所等を訪問し、障がい児に対して集団生活への適応のための専門的な支援等を行う。
A40: 居宅訪問型児童発達支援 | B40: 重度の障がい等により外出が著しく困難な障がい児の居宅を訪問し、発達支援を行う。
A41: 障がい児相談支援 | B41: 障がい児通所支援を利用する児童の障害児支援利用計画を作成し、一定期間ごとにモニタリングを行う。
A42: 障害児入所支援（福祉型・医療型） | B42: 施設に入所する障がい児に、保護、日常生活の指導、知識技能の付与（医療型は治療を含む）を行う。

Sheet 成果目標・活動指標
A1: １．福祉施設の入所者の地域生活への移行 | G1: 着色セル＝推計値（基準値・現状は村の実績で要確認）
B2: 成果目標 | C2: 基準値 （令和7年度末） | D2: 目標値 （令和11年度末） | E2: 国の基本指針（第8期）
B3: 地域生活移行者数 | C3: 4人 （施設入所者数） | D3: 0人（0％） | E3: 令和7年度末施設入所者数の6％以上
B4: 施設入所者数の削減 | C4: 4人 | D4: 4人（削減0人・0％） | E4: 令和7年度末から5％以上削減
B6: ※施設入所者（第7期時点4人）は全員が重度の身体障がい者又は知的障がい者であり、第7期と同様に地域移行・削減は困難と見込む（国の基準を下回る理由を計画書に記載）。
A8: ２．精神障がいにも対応した地域包括ケアシステムの構築
B9: （１）～（３）保健・医療・福祉関係者による協議の場
B10: 活動指標 | C10: 令和9年度 | D10: 令和10年度 | E10: 令和11年度
B11: 協議の場の開催回数（会津北部圏域・自立支援協議会等を活用） | C11: 1回 | D11: 1回 | E11: 1回
B12: 協議の場への関係者の参加者数 | C12: 10人 | D12: 10人 | E12: 10人
B13: 目標設定及び評価の実施回数 | C13: 1回 | D13: 1回 | E13: 1回
B15: （４）精神障がい者のサービス利用者数
B16: 活動指標 | C16: 令和9年度 | D16: 令和10年度 | E16: 令和11年度
B17: 地域移行支援 | C17: 0人／月 | D17: 1人／月 | E17: 1人／月
B18: 地域定着支援 | C18: 0人／月 | D18: 1人／月 | E18: 1人／月
B19: 共同生活援助 | C19: 3人／月 | D19: 4人／月 | E19: 4人／月
B20: 自立生活援助 | C20: 0人／月 | D20: 0人／月 | E20: 0人／月
B21: 自立訓練（生活訓練） | C21: 1人／月 | D21: 1人／月 | E21: 1人／月
B22: 短期入所【新規】 | C22: 0人／月 | D22: 0人／月 | E22: 0人／月
B24: （５）心のサポーター養成研修【新規】
B25: 活動指標 | C25: 令和9年度 | D25: 令和10年度 | E25: 令和11年度
B26: 心のサポーター養成研修の実施回数 | C26: 1回 | D26: 1回 | E26: 1回
B28: ※退院後1年以内の地域での平均生活日数（319.3日以上）、再入院率（退院後90日10.3％以下・180日17.4％以下・365日25.7％以下）、心のサポーター数（令和15年度末までに全国100万人以上）は国・県の目標。村は長期入院者（第7期時点5人）の退院支援を病院等と連携して継続する。
A30: ３．地域生活支援の充実
B31: 成果目標 | C31: 現状 （令和7年度末） | D31: 目標値 （令和11年度末） | E31: 国の基本指針（第8期）
B32: 地域生活支援拠点等の整備（会津北部4町村：猪苗代町・磐梯町・湯川村・北塩原村） | C32: 1カ所 | D32: 1カ所 | E32: 各市町村に整備（圏域での整備も可）
B33: コーディネーターの配置人数 | C33: 1人 | D33: 1人 | E33: コーディネーターの配置等による支援体制の構築
B34: 運用状況の検証・検討の実施回数 | C34: 1回／年 | D34: 1回／年以上 | E34: 年1回以上
B35: 強度行動障がいを有する者への支援体制の整備 | C35: 拠点の協議でニーズ把握に着手 | D35: 会津北部圏域で支援体制を整備 | E35: 各市町村又は圏域でニーズ把握・体制整備
A37: ４．福祉施設から一般就労への移行等
B38: 成果目標 | C38: 基準値 （令和6年度実績） | D38: 目標値 （令和11年度） | E38: 国の基本指針（第8期）
B39: 福祉施設から一般就労への移行者数 | C39: 0人 | D39: 1人 | E39: 令和6年度実績の1.31倍以上
B40: うち就労移行支援事業から | C40: 0人 | D40: 1人 | E40: 内訳目標は基本指針本文で要確認
B41: うち就労継続支援Ａ型事業から | C41: 0人 | D41: 0人 | E41: 同上
B42: うち就労継続支援Ｂ型事業から | C42: 0人 | D42: 0人 | E42: 同上
B43: 就労定着支援事業の利用者数 | C43: 1人 | D43: 2人 | E43: 令和6年度末実績の1.47倍以上
B45: 活動指標 | C45: 令和9年度 | D45: 令和10年度 | E45: 令和11年度
B46: 就労選択支援の利用者数【新規】 | C46: 1人 | D46: 1人 | E46: 2人
B48: ※国は協議会設置圏域ごとに就労選択支援事業所を設置し、令和11年度の全国利用者82,000人以上を目標とする。就労移行支援事業所の移行割合・就労定着支援事業所の定着率の目標は、村内に対象事業所がないため設定しない。
A50: ５．障がい児支援の提供体制の整備等
...

Sheet 用語集
A2: 行 | B2: 用語 | C2: 説明
A3: あ行 | B3: アセスメント | C3: 福祉分野において使われるアセスメントとは、サービス利用者の生活環境や困りごとを把握・情報収集し分析すること。
B4: 育成医療 | C4: 自立支援医療の一つ。身体障がいを除去、軽減する手術等の治療によって確実に効果が期待できる障がい児に対して提供される、生活の能力を得るために必要な医療費の助成を受けられる制度。
B5: 一般就労 | C5: 企業や公的機関など労働契約に基づいて働く一般的な就労形態。⇔福祉的就労
B6: 移動支援事業 | C6: 単独では外出困難な障がいのある人が、社会生活上必要不可欠な外出及び余暇活動や社会参加のため、必要な移動の介助及び外出に伴って必要となる介護を提供する事業。
B7: 医療的ケア | C7: 口腔内や鼻腔内のたんの吸引や、鼻などから管を通して栄養剤を流し込む経管栄養など、在宅で家族が日常的に行っている医療的介助行為を、医師法上の「医療行為」と区別して「医療的ケア」と呼ぶ。
B8: 医療的ケア児 | C8: 日常生活及び社会生活を営むために恒常的に医療的ケア（気管切開の管理、経管栄養など）を受けることが不可欠である子ども。
B9: インクルージョン | C9: 介護や障がいなどの有無を問わず、誰も排除されることなく、すべての人が差別なく受け入れられる共生社会を目指す理念、考え方。直訳で「包括」「包含」「包摂」などを意味する言葉。
B10: ADHD（注意欠陥多動性障害） | C10: 発達障がいの一つ。不注意、多動性と衝動性の症状を主な特徴とし、仕事や学業、友人関係の構築に困難を覚えることがある。
B11: LD（学習障がい） | C11: 発達障がいの一つ。知的発達の遅れはないものの、主に読字障がい（読みの困難）、書字表出障がい（書きの困難）、算数障がい（算数、推論の困難）の三つに分類される。
B12: オストメイト | C12: 様々な病気や事故などにより、お腹に排泄のためのストーマ（人工肛門・人工膀胱）を造設した人。
A13: か行 | B13: 介護支援専門員（ケアマネジャー） | C13: 介護認定を受け、介護保険サービス等を利用する人などからの相談に応じ、ケアプラン（介護サービス計画）の立案や、関係機関との連絡調整などを行う専門職。
B14: 介助者 | C14: 体に不自由がある人のお風呂や買い物などに付き添うなど、日常生活動作を手助けする人。
B15: 協議会 | C15: 障害者総合支援法に基づき、障がいのある人が、地域での自立した日常生活や社会生活を営むことができるよう、障がいのある人等の福祉施策や地域生活支援を推進するために設置された組織。（障害者自立支援協議会）
B16: 共生社会 | C16: 障がいの有無に関わらず、誰もがお互いに人格と個性を尊重し支えあう社会。
B17: 共同生活援助（グループホーム） | C17: 生活に必要な介護や支援を受けながら少人数で共同生活を送る障がいのある人に対し、主に夜間において、入浴や排せつ、食事の介護など生活上の援助や、相談や助言などを行うサービス。
B18: 居宅介護（ホームヘルプ） | C18: ホームヘルパーが障がいのある人の自宅を訪問し、入浴や排せつ、食事の介護、調理や洗濯、掃除、生活等に関する相談や助言、その他生活全般にわたる援助を行うサービス。
B19: ケアラー | C19: 高齢、障がい、疾病その他の理由により援助を必要とする家族や友人、その他の身近な人に対し、無償で介護や看護、日常生活上の世話、その他の援助を提供する人。
B20: 計画相談支援 | C20: ⇒サービス利用支援 … 障害福祉サービスの申請をする障がいのある人や保護者等の心身の状況や環境等を勘案し、利用する障害福祉サービス等の種類や内容を記載したサービス等利用計画案を作成するサービス。 ⇒継続サービス利用支援 … 継続して障害福祉サービス等を適切に利用することができるよう、作成されたサービス等利用計画が、適切かどうか一定期間ごとにモニタリング（効果の分析や評価）し、必要に応じて見直しを行うサービス。
B21: ゲートキーパー | C21: 「ゲートキーパー」とは、自殺の危険を示すサインに気づき、適切な対応（悩んでいる人に気づき、声をかけ、話を聞いて、必要な支援につなげ、見守る）を図ることができる人のことで、言わば「命の門番」とも位置付けられる人のこと。
B22: 高次脳機能障がい | C22: 脳卒中や事故などをきっかけとして脳の機能が著しく障がいを受けることにより、さまざまな状態を引き起こすこと。日常生活を送ることが難しくなる場合もある。
B23: 更生医療 | C23: 自立支援医療の一つ。身体障がいのある人が、その障がいを除去・軽減する手術等の治療によって確実に効果が期待できるものに対して提供される、更生のために必要な医療費の助成を受けられる制度。
B24: 行動援護 | C24: 知的障がいまたは精神障がいにより一人で行動することが著しく困難な人に、危険を回避するための必要な援護や外出時の移動中の介護、排せつや食事、その他行動する際に必要な援助を行うサービス。
B25: 合理的配慮 | C25: 障害者差別解消法により、行政や事業者が、障がいのある人に対し、正当な理由なく差別することを禁止するほか、障がいのある人から社会的障壁を取り除くために何らかの対応を必要としている意思が伝えられたときに、過重な負担にならない範囲で対応（事業者は対応に努める）すること。
A26: さ行 | B26: サービス等利用計画 | C26: 障害福祉サービスを利用する人を支援するため、サービスの種類や頻度、利用内容から目標達成までの過程のこと。サービス等利用計画は、相談支援事業所に作成を依頼する方法（計画相談支援給付）と、利用者本人または家族や支援者が作成する方法（セルフプラン）がある。相談支援事業所に依頼した場合は、作成した計画に対し、目標にどこまで近づいているのかなどの確認し、必要に応じて計画を見直すためのモニタリング（効果の分析や評価）を受ける。
B27: 指定特定相談支援事業所 | C27: 障害者総合支援法に基づき、市町村長の指定を受けた計画相談支援を実施する事業所。
B28: 児童発達支援 | C28: 就学していない障がい児に、日常生活における基本的な動作の指導や集団生活への適応訓練等の支援を行うサービス。
B29: 児童発達支援センター | C29: 地域の障がいのある児童を通所させて、日常生活における基本的動作の指導、自活に必要な知識や技能の付与または集団生活への適応のための訓練を行う施設。地域の中核的な療育支援施設。
B30: 社会的障壁 | C30: 障がいのある人にとって、日常生活または社会生活を営む上で障壁（バリア）となるような、社会における施設や建物、制度やルール、慣習や情報提供、理解や偏見など、その他一切のものをいう。
B31: 重症心身障がい児（者） | C31: 重度の肢体不自由と重度の知的障がいとが重複した状態を重症心身障がいといい、その状態の子どもを重症心身障がい児という。さらに成人した重症心身障がい児を含めて重症心身障がい児（者）という。
B32: 重度心身障害者医療事業 | C32: 重度の障がいのある人に対し、医療費の自己負担分を助成する事業（福島県補助事業）。対象要件は県の制度に準じる。
B33: 就労移行支援 | C33: 就労を希望する 65 歳未満の障がいのある人で、一般企業等への就労が可能と見込まれる人に、就労に必要な知識及び能力の向上のために必要な訓練や求職活動、その適性に応じた職場の開拓、就職後における職場への定着のために必要な相談等の支援を行うサービス。
B34: 就労継続支援Ａ型 | C34: 一般企業等に就労することが困難な 65 歳未満の障がいのある人に、雇用契約に基づく生産活動及びその他の活動の機会を提供するとともに、一般就労に向けて支援を行うサービス。
B35: 就労継続支援Ｂ型 | C35: 就労移行支援事業等を利用したが一般企業等の雇用に結びつかない人や、一定年齢に達している人であって、就労の機会等を通じ、生産活動にかかる知識及び能力の向上や維持が期待される人に、生産活動の機会の提供、知識及び能力の向上のために必要な訓練等を行うサービス。
B36: 障害者基本法 | C36: 障がいの有無によって分け隔てられることなく、相互に人格と個性を尊重し合いながら共生する社会を実現するため、障がいのある人の自立や社会参加等のための施策を総合的かつ計画的に推進することを目的とした法律。
B37: 障害者虐待防止法 | C37: 「障害者虐待の防止、障害者の養護者に対する支援等に関する法律」。虐待によって障がいのある人の権利や尊厳が脅かされることを防ぎ、安定した生活や社会参加を進めるための法律。
B38: 障がい者雇用 | C38: 障がいのある人が、一人ひとりの特性に合わせた働き方ができるように、企業や自治体などが障がいのある人を雇用する制度。
... B52: 相談支援専門員 | C52: 障がいのある人などの相談に応じ、助言や連絡調整等の必要な支援を行うほか、サービス等利用計画を作成する人をいう。
A53: た行 | B53: 短期入所（ショートステイ） | C53: 障がいのある人が障がい者支援施設や児童福祉施設等に短期間入所し、入浴や排せつ、食事の介護、その他の必要な介護を受けるサービス。
B54: 地域移行支援 | C54: 地域生活に移行するために必要な住居の確保や新生活への準備等に対する支援を行うサービス。
...

Sheet 策定委員会名簿
A1: 北塩原村障がい者自立支援協議会 委員名簿（第7期策定時：任期 令和3年11月25日～令和6年3月31日）※現任期の名簿に要差替
A2: NO. | B2: 役職等 | C2: 氏名 | D2: 所属 | E2: 部門
A3: 1 | B3: 会長 | C3: 酒井 康介 | D3: 福島県ばんだい荘 園長 | E3: 福祉
A4: 2 | B4: 副会長 | C4: 内田 政夫 | D4: 北塩原村民生児童委員協議会 会長 | E4: 地域
A5: 3 | C5: 大竹 建次 | D5: 福島県会津保健福祉事務所 健康福祉部保健福祉課 障がい者支援チーム 専門社会福祉主事 | E5: 県
A6: 4 | C6: 門脇 俊平 | D6: 会津児童相談所 児童福祉司 | E6: 県
A7: 5 | C7: 鈴木 敏美 | D7: 北塩原村身体障害者福祉会 会長 | E7: 当事者
A8: 6 | C8: 滝田 佑香 | D8: 福島県立猪苗代支援学校 特別支援教育コーディネーター | E8: 教育
A9: 7 | C9: 岡田 尚子 | D9: 北塩原村デイサービス 管理者 | E9: 福祉
A10: 8 | C10: 大竹 早苗 | D10: 北塩原村地域包括支援センター 所長 | E10: 福祉
A11: 9 | C11: 佐竹 麻衣 | D11: 地域生活支援センターいなわしろ 相談支援アドバイザー | E11: 相談支援

Sheet 事業所一覧 (2)
A1: 北塩原村及び近隣市町村の障がい福祉サービス事業所等一覧 | D1: 令和8年9月30日時点の把握分（要確認） | G1: 凡例（所在地）
A2: 種別 | B2: 名称 | C2: 住所 | D2: 電話番号 | E2: 法人等 | G2: 会津若松市・喜多方市ほか | H2: 猪苗代町・磐梯町 | I2: 北塩原村
A3: 計画相談支援・地域相談支援（地域生活支援拠点コーディネーター） | B3: 地域生活支援センターいなわしろ | C3: 猪苗代町大字長田字西五十滝3967-1 | D3: 要確認 | E3: 社会福祉法人 福島県社会福祉事業団
A4: 施設入所支援・生活介護等（障害者支援施設） | B4: 福島県ばんだい荘 | C4: 猪苗代町（番地要確認） | D4: 要確認 | E4: 社会福祉法人 福島県社会福祉事業団（要確認）
A5: 共同生活援助 | B5: 共同生活事業所いなわしろ | C5: 猪苗代町芦原（番地要確認） | D5: 要確認 | E5: 要確認
A6: 就労継続支援Ｂ型 | B6: さぎそうの家 | C6: 猪苗代町町尻（番地要確認） | D6: 要確認 | E6: 要確認
A7: 地域活動支援センター | B7: 猪苗代町地域活動支援センター | C7: 猪苗代町字町尻340番地3（工房ポプリ2階） | D7: 0242-62-2024 | E7: 猪苗代町
A8: 就労継続支援Ｂ型 | B8: 夢の樹 | C8: 会津若松市一箕町大字八幡字滝沢（番地要確認） | D8: 要確認 | E8: 要確認
A9: 就労継続支援Ｂ型 | B9: ＡＯＩ共同作業所 | C9: 会津若松市一箕町八角字中村東（番地要確認） | D9: 要確認 | E9: 要確認
A10: 共同生活援助 | B10: グループホームすまいる | C10: 会津若松市八角町（番地要確認） | D10: 要確認 | E10: 要確認
A11: 共同生活援助 | B11: 木の実寮 | C11: 会津若松市一箕町亀賀字藤原（番地要確認） | D11: 要確認 | E11: 要確認
A12: 共同生活援助 | B12: むつみ寮 | C12: 会津若松市相生町（番地要確認） | D12: 要確認 | E12: 要確認
A13: 計画相談支援 | B13: 障がい相談支援事業所 コパン・クラージュ | C13: 会津若松市一箕町鶴賀字村東（番地要確認） | D13: 要確認 | E13: 要確認
A14: 計画相談支援 | B14: 障がい者相談支援事業所アガッセ | C14: 会津若松市一箕町鶴賀字下柳原（番地要確認） | D14: 要確認 | E14: 要確認
... A21: 通所介護（障がい福祉サービス提供の有無要確認） | B21: 北塩原村デイサービス | C21: 北塩原村（要確認） | D21: 要確認 | E21: 要確認
A23: ※Web上の公開情報（障害福祉サービス等情報検索等）で把握できた範囲の暫定版。電話番号・番地・サービス種別・法人名は村及びWAM NETで要確認。

Sheet 障害者福祉関連計画一覧
A3: 区分 | B3: 障がい者基本計画 （市町村障がい者計画） | C3: 障がい福祉計画 （市町村障がい福祉計画） | D3: 障がい児福祉計画 （市町村障がい児福祉計画）
A4: 内容 | B4: 障害者施策の基本的方向について定める計画 | C4: 障害福祉サービス等の見込みとその確保策を定める計画（計画期間は3年） | D4: 障がい児サービス等の円滑な実施を確保するための基本的な指針を定める計画（計画期間は3年）
A5: 根拠法 | B5: 障害者基本法（第11条第3項） | C5: 障害者の日常生活及び社会生活を総合的に支援するための法律（第88条第1項） | D5: 児童福祉法（第33条の20第1項）
A6: 国 | B6: 障害者基本計画（第5次） 計画期間：R5年度～R9年度 | C6: 障害福祉サービス等及び障害児通所支援等の円滑な実施を確保するための基本的な指針 | D6: 障害福祉サービス等及び障害児通所支援等の円滑な実施を確保するための基本的な指針
A7: 県 | B7: 第5次福島県障がい者計画 （計画期間は県計画で要確認） | C7: 第8期福島県障がい福祉計画 計画期間：R9年度～R11年度 | D7: 第4期福島県障がい児福祉計画 計画期間：R9年度～R11年度
A8: 村 | B8: 第4次北塩原村障がい者計画 計画期間：R6年度～R11年度 | C8: 第8期北塩原村障がい福祉計画 計画期間：R9年度～R11年度 | D8: 第4期北塩原村障がい児福祉計画 計画期間：R9年度～R11年度

Sheet 対象定義一覧
A3: 分類 | B3: 根拠法・条項 | C3: 定義・要件 | D3: 年齢区分
A4: 身体障がい者 | B4: 身体障害者福祉法 第4条 | C4: 同法第4条に規定する身体障がい者 | D4: 制限なし
A5: 知的障がい者 | B5: 知的障害者福祉法 | C5: 同法にいう知的障がい者 | D5: 18歳以上
A6: 精神障がい者 | B6: 精神保健及び精神障害者福祉に関する法律 第5条 （発達障害者支援法 第2条第2項） | C6: 同法第5条に規定する精神障がい者。 ※発達障がい者を含み、知的障害者福祉法にいう知的障がい者を除く。 | D6: 18歳以上
A7: 難病患者等 （特定の疾病による障害） | B7: 障害者総合支援法等（政令・厚労省告示） | C7: 治療方法が確立していない疾病その他の特殊の疾病であって政令で定めるもの（指定難病等）による障がいの程度が、厚生労働大臣が定める程度である者。 | D7: 18歳以上
A8: 障がい児 | B8: 児童福祉法 第4条第2項 | C8: 同法第4条第2項に規定する障害児をいう。 | D8: 18歳未満（児童）

Sheet 計画位置づけ
B3: 北塩原村第五次総合振興計画（平成29年度～）／次期総合振興計画（令和9年度～予定）
B4: ↓ | D4: ↓
B5: 第4次北塩原村障がい者計画（R6～R11） | C5: ⇔ | D5: 第3次健康21・北塩原村グッドヘルスプラン（R6～R17）
B6: ↑相互関係↓ | C6: 連携
B7: 北塩原村の障がい福祉関係計画（本計画） | D7: その他関連計画
B8: 第8期北塩原村障がい福祉計画（R9～R11） | C8: 連携 | D8: 第2次北塩原村いのちを守る対策計画（自殺対策）
B9: 第4期北塩原村障がい児福祉計画（R9～R11） | C9: ⇔ | D9: 北塩原村子ども・子育て支援事業計画
B10: 北塩原村高齢者福祉計画・介護保険事業計画 | C10: 協調 | D10: 北塩原村保健事業実施計画（データヘルス計画）
B11: 第10期北塩原村高齢者福祉計画（R9～R11） | D11: 第2次北塩原村食育推進計画
B12: 第10期北塩原村介護保険事業計画（R9～R11） | D12: 北塩原村地域防災計画 ほか

Sheet 関連法規
A1: 法令名 | B1: 施行年 | C1: 計画との関連
A2: 障害者基本法 | B2: 昭和45年 | C2: 障害者施策の基本理念・基本原則。本計画の上位規範。
A3: 障害者総合支援法 | B3: 平成25年 | C3: 本計画（障害福祉計画）の根拠法。
A4: 児童福祉法 | B4: 昭和22年 | C4: 本計画（障害児福祉計画）の根拠法。
A5: 障害者虐待防止法 | B5: 平成23年 | C5: 虐待防止・通報・保護等の措置。
A6: 障害者差別解消法 | B6: 平成25年（令和６年改正） | C6: 差別禁止・合理的配慮の義務化。
A7: 障害者情報アクセシビリティ・コミュニケーション施策推進法 | B7: 令和４年 | C7: 情報アクセシビリティ・意思疎通支援の推進。
A8: 医療的ケア児支援法 | B8: 令和３年 | C8: 医療的ケア児の支援体制整備の責務。
A9: 精神保健福祉法 | B9: 昭和25年 | C9: 精神障害者の医療・福祉施策。
A10: こども基本法 | B10: 令和４年 | C10: こどもの権利擁護・障害児施策との関連。
A11: 発達障害者支援法 | B11: 平成16年（平成28年改正） | C11: 発達障害者の支援体制・早期発見。
A12: 成年後見制度利用促進法 | B12: 平成28年 | C12: 成年後見・権利擁護体制整備。
... A16: 医療的ケア児支援法の一部改正 | B16: 令和8年 | C16: 医療的ケア児等への支援の充実。基本指針の追加改正に反映。

Sheet 近年の障がい者施策（国）
A1: 施行年 | B1: 内容
A2: 平成15年 | B2: 「支援費制度」施行
A3: 平成18年 | B3: 「障害者自立支援法」施行 「高齢者、障害者等の移動等の円滑化の促進に関する法律」施行
A4: 平成19年 | B4: 「障害者の権利に関する条約」閣議決定
A5: 平成23年 | B5: 「合理的配慮」の概念や差別の禁止等を盛り込んだ「障害者基本法」の改正
A6: 平成24年 | B6: 「障害者の日常生活及び社会生活を総合的に支援するための法律（障害者総合支援法）」制定 「障害者虐待の防止、障害者の養護者に対する支援等に関する法律（障害者虐待防止法）」制定
A7: 平成25年 | B7: 「国等による障害者就労施設等からの物品等の調達の推進等に関する法律（障害者優先調達推進法）」制定 「障害者の日常生活及び社会生活を総合的に支援するための法律（障害者総合支援法）」施行 「成年被後見人の選挙権の回復等のための公職選挙法等の一部を改正する法律」施行
A8: 平成28年 | B8: 「障害を理由とする差別の解消の推進に関する法律」施行 「障害者の雇用の促進等に関する法律の一部を改正する法律」一部施行 「障害者の日常生活及び社会生活を総合的に支援するための法律及び児童福祉法の一部を改正する法律」成立 「成年後見制度の利用の促進に関する法律」施行 「発達障害者支援法の一部を改正する法律」施行
A9: 平成29年 | B9: 「ユニバーサルデザイン2020行動計画」策定 「成年後見制度利用促進基本計画」閣議決定
A10: 平成30年 | B10: 「障害者基本計画（第4次）」閣議決定 「障害者の日常生活及び社会生活を総合的に支援するための法律及び児童福祉法の一部を改定する法律」施行※平成28年一部施行 「高齢者、障害者等の移動等の円滑化の促進に関する法律の一部を改正する法律」成立 「障害者による文化芸術活動の推進に関する法律」施行 「ユニバーサル社会の実現に向けた諸施策の総合的かつ一体的な推進に関する法律（ユニバーサル社会実現推進法）」制定
A11: 令和元年 | B11: 「障害者の雇用の促進等に関する法律の一部を改正する法律」成立 「視覚障害者等の読書環境の整備の促進に関する法律」成立
A12: 令和2年 | B12: 「障害者の雇用の促進等に関する法律の一部を改正する法律」施行※令和元年一部施行 「高齢者、障害者等の移動等の円滑化の促進に関する法律の一部を改正する法律（バリアフリー法）」成立 「聴覚障害者等による電話の利用の円滑化に関する法律」成立
... A19: 令和9年 | B19: 第8期障害福祉計画・第4期障害児福祉計画の開始 就労継続支援Ａ型等の新規利用時に就労選択支援の利用が原則化（令和9年4月～）
A20: 令和10年
A21: 令和11年

Sheet 人口状況
B1: 総人口 | N1: 障がい者人口 | AA1: 人口ピラミッド（令和7年1月1日現在・住民基本台帳・外国人含む）
B2: ※R2～R5は第7期計画（住民基本台帳・各年4月1日）。R6～R8は総務省住基（1月1日）から4月1日時点を推計、R9～R11は推計。世帯数は総務省住基（1月1日・日本人世帯）の参考値。 | L2: 単位：人、世帯 | N2: ※R2～R5は第7期計画（各年4月1日）。R6以降は推計（下段の推計表を参照）。 | X2: 単位：人 | AA2: 出典：総務省「住民基本台帳に基づく人口、人口動態及び世帯数」（総数2,394人：男1,205人・女1,189人）
B3: 区分 | C3: 令和２年度 | D3: 令和3年度 | E3: 令和4年度 | F3: 令和5年度 | G3: 令和6年度 | H3: 令和7年度 | I3: 令和8年度 | J3: 令和9年度 | K3: 令和10年度 | L3: 令和11年度 | N3: 区分 | O3: 令和２年度 | P3: 令和3年度 | Q3: 令和4年度 | R3: 令和5年度 | S3: 令和6年度 | T3: 令和7年度 | U3: 令和8年度 | V3: 令和9年度 | W3: 令和10年度 | X3: 令和11年度 | AA3: 年齢階層 | AB3: 男性人口 [人] | AC3: 女性人口 [人] | AD3: 男女計 [人] | AE3: 男性人口比率 [%] | AF3: 女性人口比率 [%]
B4: 総人口 | C4: =C5+C7+C9 -> 2697 | D4: =D5+D7+D9 -> 2630 | E4: =E5+E7+E9 -> 2535 | F4: =F5+F7+F9 -> 2443 | G4: =G5+G7+G9 -> 2405 | H4: =H5+H7+H9 -> 2368 | I4: =I5+I7+I9 -> 2316 | J4: =J5+J7+J9 -> 2266 | ... L4: =L5+L7+L9 -> 2166 | N4: 合計 | O4: =O5+O7+O9 -> 162 | P4: =P5+P7+P9 -> 169 | Q4: =Q5+Q7+Q9 -> 160 | R4: =R5+R7+R9 -> 156 | S4: =S5+S7+S9 -> 163 | T4: =T5+T7+T9 -> 173 | U4: =U5+U7+U9 -> 181 | V4: =V5+V7+V9 -> 183 | ... X4: =X5+X7+X9 -> 188 | AA4: 0～4歳 | AB4: 11 | AC4: 22 | AD4: =AB4+AC4 -> 33 | AE4: =AB4/$AB$26 -> 0.0091286307 | AF4: =AC4/$AC$26 -> 0.018502944
B5: 老年人口（65歳以上） | C5: 984 | D5: 1006 | E5: 1003 | F5: 997 | G5: 1000 | H5: 1001 | I5: 998 | J5: =H40 -> 993 | K5: =I40 -> 986 | L5: =J40 -> 978 | N5: 身体障害者手帳所持者数 | O5: 121 | P5: 128 | Q5: 122 | R5: 114 | S5: 117 | T5: =T38 -> 122 | U5: =U38 -> 127 | V5: =V38 -> 127 | W5: =W38 -> 127 | X5: =X38 -> 127 | AA5: 5～9歳 | AB5: 29 | AC5: 32 | AD5: =AB5+AC5 -> 61 | AE5: =AB5/$AB$26 -> 0.02406639 | AF5: =AC5/$AC$26 -> 0.026913373
C6: =C5/C4 -> 0.36484983 | D6: =D5/D4 -> 0.38250951 | E6: =E5/E4 -> 0.39566075 | F6: =F5/F4 -> 0.40810479 | G6: =G5/G4 -> 0.41580042 | H6: =H5/H4 -> 0.42271959 | I6: =I5/I4 -> 0.43091537 | J6: =J5/J4 -> 0.43821712 | ... L6: =L5/L4 -> 0.45152355 | O6: =O5/O4 -> 0.74691358 | P6: =P5/P4 -> 0.75739645 | Q6: =Q5/Q4 -> 0.7625 | R6: =R5/R4 -> 0.73076923 | S6: =S5/S4 -> 0.71779141 | T6: =T5/T4 -> 0.70520231 | U6: =U5/U4 -> 0.70165746 | V6: =V5/V4 -> 0.69398907 | ... X6: =X5/X4 -> 0.67553191 | AA6: 10～14歳 | AB6: 39 | AC6: 32 | AD6: =AB6+AC6 -> 71 | AE6: =AB6/$AB$26 -> 0.032365145 | AF6: =AC6/$AC$26 -> 0.026913373
B7: 生産年齢人口（15～64歳） | C7: 1437 | D7: 1369 | E7: 1301 | F7: 1241 | G7: 1222 | H7: 1204 | I7: 1170 | J7: =H39 -> 1135 | K7: =I39 -> 1101 | L7: =J39 -> 1068 | N7: 療育手帳所持者数 | O7: 13 | P7: 14 | Q7: 12 | R7: 12 | S7: 13 | T7: =T39 -> 15 | U7: =U39 -> 16 | V7: =V39 -> 16 | W7: =W39 -> 17 | X7: =X39 -> 17 | AA7: 15～19歳 | AB7: 58 | AC7: 50 | AD7: =AB7+AC7 -> 108 | AE7: =AB7/$AB$26 -> 0.04813278 | AF7: =AC7/$AC$26 -> 0.042052145
C8: =C7/C4 -> 0.53281424 | D8: =D7/D4 -> 0.52053232 | E8: =E7/E4 -> 0.51321499 | F8: =F7/F4 -> 0.50798199 | G8: =G7/G4 -> 0.50810811 | H8: =H7/H4 -> 0.50844595 | I8: =I7/I4 -> 0.50518135 | J8: =J7/J4 -> 0.50088261 | ... L8: =L7/L4 -> 0.49307479 | O8: =O7/O4 -> 0.080246914 | P8: =P7/P4 -> 0.082840237 | Q8: =Q7/Q4 -> 0.075 | R8: =R7/R4 -> 0.076923077 | S8: =S7/S4 -> 0.079754601 | T8: =T7/T4 -> 0.086705202 | U8: =U7/U4 -> 0.08839779 | V8: =V7/V4 -> 0.087431694 | ... X8: =X7/X4 -> 0.090425532 | AA8: 20～24歳 | AB8: 53 | AC8: 49 | AD8: =AB8+AC8 -> 102 | AE8: =AB8/$AB$26 -> 0.043983402 | AF8: =AC8/$AC$26 -> 0.041211102
B9: 年少人口（0～14歳） | C9: 276 | D9: 255 | E9: 231 | F9: 205 | G9: 183 | H9: 163 | I9: 148 | J9: =H38 -> 138 | K9: =I38 -> 129 | L9: =J38 -> 120 | N9: 精神障害者保健福祉手帳所持者数 | O9: 28 | P9: 27 | Q9: 26 | R9: 30 | S9: 33 | T9: =T40 -> 36 | U9: =U40 -> 38 | V9: =V40 -> 40 | W9: =W40 -> 42 | X9: =X40 -> 44 | AA9: 25～29歳 | AB9: 36 | AC9: 32 | AD9: =AB9+AC9 -> 68 | AE9: =AB9/$AB$26 -> 0.029875519 | AF9: =AC9/$AC$26 -> 0.026913373
C10: =C9/C4 -> 0.10233593 | D10: =D9/D4 -> 0.096958175 | E10: =E9/E4 -> 0.09112426 | F10: =F9/F4 -> 0.083913221 | G10: =G9/G4 -> 0.076091476 | H10: =H9/H4 -> 0.068834459 | I10: =I9/I4 -> 0.063903282 | J10: =J9/J4 -> 0.060900265 | ... L10: =L9/L4 -> 0.055401662 | O10: =O9/O4 -> 0.17283951 | P10: =P9/P4 -> 0.15976331 | Q10: =Q9/Q4 -> 0.1625 | R10: =R9/R4 -> 0.19230769 | S10: =S9/S4 -> 0.20245399 | T10: =T9/T4 -> 0.20809249 | U10: =U9/U4 -> 0.20994475 | V10: =V9/V4 -> 0.21857923 | ... X10: =X9/X4 -> 0.23404255 | AA10: 30～34歳 | AB10: 43 | AC10: 34 | AD10: =AB10+AC10 -> 77 | AE10: =AB10/$AB$26 -> 0.035684647 | AF10: =AC10/$AC$26 -> 0.028595458
B11: 世帯数 | C11: 1064 | D11: 1058 | E11: 1056 | F11: 1036 | G11: 1029 | H11: 1038 | I11: 1047 | J11: 1040 | K11: 1033 | L11: 1026 | N11: 対人口比 | O11: =O4/C4 -> 0.060066741 | P11: =P4/D4 -> 0.064258555 | Q11: =Q4/E4 -> 0.063116371 | R11: =R4/F4 -> 0.063855915 | S11: =S4/G4 -> 0.067775468 | T11: =T4/H4 -> 0.073057432 | U11: =U4/I4 -> 0.078151986 | V11: =V4/J4 -> 0.080759047 | ... X11: =X4/L4 -> 0.086795937 | AA11: 35～39歳 | AB11: 41 | AC11: 41 | AD11: =AB11+AC11 -> 82 | AE11: =AB11/$AB$26 -> 0.034024896 | AF11: =AC11/$AC$26 -> 0.034482759
B12: 1世帯当たりの人口 | C12: =C4/C11 -> 2.5347744 | D12: =D4/D11 -> 2.4858223 | E12: =E4/E11 -> 2.4005682 | F12: =F4/F11 -> 2.3581081 | G12: =G4/G11 -> 2.3372206 | H12: =H4/H11 -> 2.2813102 | I12: =I4/I11 -> 2.2120344 | J12: =J4/J11 -> 2.1788462 | ... L12: =L4/L11 -> 2.1111111 | AA12: 40～44歳 | AB12: 82 | AC12: 60 | AD12: =AB12+AC12 -> 142 | AE12: =AB12/$AB$26 -> 0.068049793 | AF12: =AC12/$AC$26 -> 0.050462574
AA13: 45～49歳 | AB13: 83 | AC13: 62 | AD13: =AB13+AC13 -> 145 | AE13: =AB13/$AB$26 -> 0.068879668 | AF13: =AC13/$AC$26 -> 0.052144659
AA14: 50～54歳 | AB14: 87 | AC14: 71 | AD14: =AB14+AC14 -> 158 | AE14: =AB14/$AB$26 -> 0.07219917 | AF14: =AC14/$AC$26 -> 0.059714045
AA15: 55～59歳 | AB15: 76 | AC15: 78 | AD15: =AB15+AC15 -> 154 | AE15: =AB15/$AB$26 -> 0.063070539 | AF15: =AC15/$AC$26 -> 0.065601346
AA16: 60～64歳 | AB16: 101 | AC16: 89 | AD16: =AB16+AC16 -> 190 | AE16: =AB16/$AB$26 -> 0.083817427 | AF16: =AC16/$AC$26 -> 0.074852817
AA17: 65～69歳 | AB17: 122 | AC17: 105 | AD17: =AB17+AC17 -> 227 | AE17: =AB17/$AB$26 -> 0.10124481 | AF17: =AC17/$AC$26 -> 0.088309504
AA18: 70～74歳 | AB18: 126 | AC18: 135 | AD18: =AB18+AC18 -> 261 | AE18: =AB18/$AB$26 -> 0.10456432 | AF18: =AC18/$AC$26 -> 0.11354079
AA19: 75～79歳 | AB19: 105 | AC19: 83 | AD19: =AB19+AC19 -> 188 | AE19: =AB19/$AB$26 -> 0.087136929 | AF19: =AC19/$AC$26 -> 0.06980656
AA20: 80～84歳 | AB20: 53 | AC20: 72 | AD20: =AB20+AC20 -> 125 | AE20: =AB20/$AB$26 -> 0.043983402 | AF20: =AC20/$AC$26 -> 0.060555088
AA21: 85～89歳 | AB21: 38 | AC21: 72 | AD21: =AB21+AC21 -> 110 | AE21: =AB21/$AB$26 -> 0.03153527 | AF21: =AC21/$AC$26 -> 0.060555088
AA22: 90～94歳 | AB22: 20 | AC22: 48 | AD22: =AB22+AC22 -> 68 | AE22: =AB22/$AB$26 -> 0.01659751 | AF22: =AC22/$AC$26 -> 0.040370059
AA23: 95～99歳 | AB23: 2 | AC23: 17 | AD23: =AB23+AC23 -> 19 | AE23: =AB23/$AB$26 -> 0.001659751 | AF23: =AC23/$AC$26 -> 0.014297729
AA24: 100歳～ | AB24: 0 | AC24: 5 | AD24: =AB24+AC24 -> 5 | AE24: =AB24/$AB$26 -> 0 | AF24: =AC24/$AC$26 -> 0.0042052145
AA25: 不詳 | AB25: 0 | AC25: 0 | AD25: =AB25+AC25 -> 0 | AE25: =AB25/$AB$26 -> 0 | AF25: =AC25/$AC$26 -> 0
AA26: 合計 | AB26: =SUM(AB4:AB25) -> 1205 | AC26: =SUM(AC4:AC25) -> 1189 | AD26: =AB26+AC26 -> 2394 | AE26: =SUM(AE4:AE25) -> 1 | AF26: =SUM(AF4:AF25) -> 1
C35: 着色セル＝推計値（村の実績・台帳データで要差替）
B37: 区分 | C37: 令和4年度 | D37: 令和5年度 | E37: 令和6年度 | F37: 令和7年度 | G37: 令和8年度 | H37: 令和9年度(推計) | I37: 令和10年度(推計) | J37: 令和11年度(推計) | S37: 区分 | T37: 令和7年度 | U37: 令和8年度 | V37: 令和9年度(推計) | W37: 令和10年度(推計) | X37: 令和11年度(推計)
B38: 0～14歳 | C38: 231 | D38: 205 | E38: 183 | F38: 163 | G38: 148 | H38: 138 | I38: 129 | J38: 120 | S38: 身体障害者手帳所持者数 | T38: 122 | U38: 127 | V38: 127 | W38: 127 | X38: 127
B39: 15～64歳 | C39: 1301 | D39: 1241 | E39: 1222 | F39: 1204 | G39: 1170 | H39: 1135 | I39: 1101 | J39: 1068 | S39: 療育手帳所持者 | T39: 15 | U39: 16 | V39: 16 | W39: 17 | X39: 17
B40: 65歳以上 | C40: 1003 | D40: 997 | E40: 1000 | F40: 1001 | G40: 998 | H40: 993 | I40: 986 | J40: 978 | S40: 精神障害者保健福祉手帳所持者 | T40: 36 | U40: 38 | V40: 40 | W40: 42 | X40: 44
B41: 総人口 | C41: =SUM(C38:C40) -> 2535 | D41: =SUM(D38:D40) -> 2443 | E41: =SUM(E38:E40) -> 2405 | F41: =SUM(F38:F40) -> 2368 | G41: =SUM(G38:G40) -> 2316 | H41: =SUM(H38:H40) -> 2266 | I41: =SUM(I38:I40) -> 2216 | J41: =SUM(J38:J40) -> 2166 | S41: 総計 | T41: =SUM(T38:T40) -> 173 | U41: =SUM(U38:U40) -> 181 | V41: =SUM(V38:V40) -> 183 | W41: =SUM(W38:W40) -> 186 | X41: =SUM(X38:X40) -> 188

Sheet サービス見込量（訪問系） (2)
A1: ■居宅介護の実績と見込量
B2: 単位 | D2: 第6期 | E2: 第7期・第3期 | H2: 第8期・第4期 | M2: 着色セル＝R6～R8実績の推計値（村の実績で要差替）
D3: R5年度 | E3: R6年度 | F3: R7年度 | G3: R8年度 | H3: R9年度 | I3: R10年度 | J3: R11年度 | M3: R5・R6～R8見込量＝第7期計画書（R5見込は第6期）。R5実績＝第7期計画書。
A4: 利用者数 | B4: 人/月 | C4: 見込量 | D4: 2 | E4: 4 | F4: 4 | G4: 4 | H4: 4 | I4: 5 | J4: 5 | M4: 第8期・第4期（R9～R11）の見込量はすべて推計による案。
C5: 実績 | D5: 4 | E5: 4 | F5: 4 | G5: 4 | H5: - | I5: - | J5: -
A6: サービス量 | B6: 時間/月 | C6: 見込量 | D6: 110 | E6: 40 | F6: 40 | G6: 40 | H6: 44 | I6: 50 | J6: 50
C7: 実績 | D7: 33 | E7: 38 | F7: 40 | G7: 42 | H7: - | I7: - | J7: -
A10: ■重度訪問介護の実績と見込量
B11: 単位 | D11: 第6期 | E11: 第7期・第3期 | H11: 第8期・第4期
D12: R5年度 | E12: R6年度 | F12: R7年度 | G12: R8年度 | H12: R9年度 | I12: R10年度 | J12: R11年度
A13: 利用者数 | B13: 人/月 | C13: 見込量 | D13: 0 | E13: 0 | F13: 0 | G13: 0 | H13: 0 | I13: 0 | J13: 0
C14: 実績 | D14: 0 | E14: 0 | F14: 0 | G14: 0 | H14: - | I14: - | J14: -
A15: サービス量 | B15: 時間/月 | C15: 見込量 | D15: 0 | E15: 0 | F15: 0 | G15: 0 | H15: 0 | I15: 0 | J15: 0
C16: 実績 | D16: 0 | E16: 0 | F16: 0 | G16: 0 | H16: - | I16: - | J16: -
A19: ■同行援護の実績と見込量
B20: 単位 | D20: 第6期 | E20: 第7期・第3期 | H20: 第8期・第4期
D21: R5年度 | E21: R6年度 | F21: R7年度 | G21: R8年度 | H21: R9年度 | I21: R10年度 | J21: R11年度
A22: 利用者数 | B22: 人/月 | C22: 見込量 | D22: 0 | E22: 0 | F22: 0 | G22: 0 | H22: 0 | I22: 0 | J22: 0
C23: 実績 | D23: 0 | E23: 0 | F23: 0 | G23: 0 | H23: - | I23: - | J23: -
A24: サービス量 | B24: 時間/月 | C24: 見込量 | D24: 0 | E24: 0 | F24: 0 | G24: 0 | H24: 0 | I24: 0 | J24: 0
C25: 実績 | D25: 0 | E25: 0 | F25: 0 | G25: 0 | H25: - | I25: - | J25: -
A28: ■行動援護の実績と見込量
B29: 単位 | D29: 第6期 | E29: 第7期・第3期 | H29: 第8期・第4期
D30: R5年度 | E30: R6年度 | F30: R7年度 | G30: R8年度 | H30: R9年度 | I30: R10年度 | J30: R11年度
A31: 利用者数 | B31: 人/月 | C31: 見込量 | D31: 0 | E31: 0 | F31: 0 | G31: 0 | H31: 0 | I31: 0 | J31: 0
C32: 実績 | D32: 0 | E32: 0 | F32: 0 | G32: 0 | H32: - | I32: - | J32: -
A33: サービス量 | B33: 時間/月 | C33: 見込量 | D33: 0 | E33: 0 | F33: 0 | G33: 0 | H33: 0 | I33: 0 | J33: 0
C34: 実績 | D34: 0 | E34: 0 | F34: 0 | G34: 0 | H34: - | I34: - | J34: -
A37: ■重度障がい者等包括支援の実績と見込量
B38: 単位 | D38: 第6期 | E38: 第7期・第3期 | H38: 第8期・第4期
D39: R5年度 | E39: R6年度 | F39: R7年度 | G39: R8年度 | H39: R9年度 | I39: R10年度 | J39: R11年度
A40: 利用者数 | B40: 人/月 | C40: 見込量 | D40: 0 | E40: 0 | F40: 0 | G40: 0 | H40: 0 | I40: 0 | J40: 0
C41: 実績 | D41: 0 | E41: 0 | F41: 0 | G41: 0 | H41: - | I41: - | J41: -
A42: サービス量 | B42: 時間/月 | C42: 見込量 | D42: 0 | E42: 0 | F42: 0 | G42: 0 | H42: 0 | I42: 0 | J42: 0
C43: 実績 | D43: 0 | E43: 0 | F43: 0 | G43: 0 | H43: - | I43: - | J43: -

Sheet サービス見込量（日中活動系） (2)
A1: ■生活介護の実績と見込量
B2: 単位 | D2: 第6期 | E2: 第7期・第3期 | H2: 第8期・第4期 | M2: 着色セル＝R6～R8実績の推計値（村の実績で要差替）
D3: R5年度 | E3: R6年度 | F3: R7年度 | G3: R8年度 | H3: R9年度 | I3: R10年度 | J3: R11年度 | M3: R5・R6～R8見込量＝第7期計画書（R5見込は第6期）。R5実績＝第7期計画書。
A4: 利用者数 | B4: 人/月 | C4: 見込量 | D4: 5 | E4: 6 | F4: 6 | G4: 6 | H4: 6 | I4: 7 | J4: 7 | M4: 第8期・第4期（R9～R11）の見込量はすべて推計による案。
C5: 実績 | D5: 6 | E5: 6 | F5: 6 | G5: 6 | H5: - | I5: - | J5: -
A6: サービス量 | B6: 人日/月 | C6: 見込量 | D6: 110 | E6: 118 | F6: 118 | G6: 118 | H6: 118 | I6: 136 | J6: 136
C7: 実績 | D7: 120 | E7: 118 | F7: 120 | G7: 118 | H7: - | I7: - | J7: -
A10: ■自立訓練（機能訓練）の実績と見込量
B11: 単位 | D11: 第6期 | E11: 第7期・第3期 | H11: 第8期・第4期
D12: R5年度 | E12: R6年度 | F12: R7年度 | G12: R8年度 | H12: R9年度 | I12: R10年度 | J12: R11年度
A13: 利用者数 | B13: 人/月 | C13: 見込量 | D13: 0 | E13: 0 | F13: 0 | G13: 0 | H13: 0 | I13: 0 | J13: 0
C14: 実績 | D14: 0 | E14: 0 | F14: 0 | G14: 0 | H14: - | I14: - | J14: -
A15: サービス量 | B15: 人日/月 | C15: 見込量 | D15: 0 | E15: 0 | F15: 0 | G15: 0 | H15: 0 | I15: 0 | J15: 0
C16: 実績 | D16: 0 | E16: 0 | F16: 0 | G16: 0 | H16: - | I16: - | J16: -
A19: ■自立訓練（生活訓練）の実績と見込量
B20: 単位 | D20: 第6期 | E20: 第7期・第3期 | H20: 第8期・第4期
D21: R5年度 | E21: R6年度 | F21: R7年度 | G21: R8年度 | H21: R9年度 | I21: R10年度 | J21: R11年度
A22: 利用者数 | B22: 人/月 | C22: 見込量 | D22: 3 | E22: 0 | F22: 0 | G22: 1 | H22: 1 | I22: 1 | J22: 1
C23: 実績 | D23: 1 | E23: 1 | F23: 0 | G23: 1 | H23: - | I23: - | J23: -
A24: サービス量 | B24: 人日/月 | C24: 見込量 | D24: 30 | E24: 0 | F24: 0 | G24: 12 | H24: 12 | I24: 12 | J24: 12
C25: 実績 | D25: 12 | E25: 12 | F25: 0 | G25: 12 | H25: - | I25: - | J25: -
A28: ■就労選択支援の実績と見込量（令和7年10月開始）
B29: 単位 | D29: 第6期 | E29: 第7期・第3期 | H29: 第8期・第4期
D30: R5年度 | E30: R6年度 | F30: R7年度 | G30: R8年度 | H30: R9年度 | I30: R10年度 | J30: R11年度
A31: 利用者数 | B31: 人/月 | C31: 見込量 | D31: ― | E31: ― | F31: ― | G31: ― | H31: 1 | I31: 1 | J31: 2
C32: 実績 | D32: ― | E32: ― | F32: 0 | G32: 0 | H32: - | I32: - | J32: -
A33: サービス量 | B33: 人日/月 | C33: 見込量 | D33: ― | E33: ― | F33: ― | G33: ― | H33: 10 | I33: 10 | J33: 20
C34: 実績 | D34: ― | E34: ― | F34: 0 | G34: 0 | H34: - | I34: - | J34: -
A37: ■就労移行支援の実績と見込量
B38: 単位 | D38: 第6期 | E38: 第7期・第3期 | H38: 第8期・第4期
D39: R5年度 | E39: R6年度 | F39: R7年度 | G39: R8年度 | H39: R9年度 | I39: R10年度 | J39: R11年度
A40: 利用者数 | B40: 人/月 | C40: 見込量 | D40: 3 | E40: 0 | F40: 0 | G40: 1 | H40: 1 | I40: 1 | J40: 1
C41: 実績 | D41: 0 | E41: 0 | F41: 0 | G41: 1 | H41: - | I41: - | J41: -
A42: サービス量 | B42: 人日/月 | C42: 見込量 | D42: 36 | E42: 0 | F42: 0 | G42: 10 | H42: 12 | I42: 12 | J42: 12
C43: 実績 | D43: 0 | E43: 0 | F43: 0 | G43: 10 | H43: - | I43: - | J43: -
A46: ■就労継続支援Ａ型の実績と見込量
B47: 単位 | D47: 第6期 | E47: 第7期・第3期 | H47: 第8期・第4期
D48: R5年度 | E48: R6年度 | F48: R7年度 | G48: R8年度 | H48: R9年度 | I48: R10年度 | J48: R11年度
A49: 利用者数 | B49: 人/月 | C49: 見込量 | D49: 0 | E49: 1 | F49: 1 | G49: 1 | H49: 1 | I49: 1 | J49: 2
C50: 実績 | D50: 1 | E50: 1 | F50: 1 | G50: 1 | H50: - | I50: - | J50: -
...

Sheet サービス見込量（居住系・相談系） (2)
A1: ■自立生活援助の実績と見込量
B2: 単位 | D2: 第6期 | E2: 第7期・第3期 | H2: 第8期・第4期 | M2: 着色セル＝R6～R8実績の推計値（村の実績で要差替）
D3: R5年度 | E3: R6年度 | F3: R7年度 | G3: R8年度 | H3: R9年度 | I3: R10年度 | J3: R11年度 | M3: R5・R6～R8見込量＝第7期計画書（R5見込は第6期）。R5実績＝第7期計画書。
A4: 利用者数 | B4: 人/月 | C4: 見込量 | D4: ― | E4: 0 | F4: 0 | G4: 0 | H4: 0 | I4: 0 | J4: 0 | M4: 第8期・第4期（R9～R11）の見込量はすべて推計による案。
C5: 実績 | D5: 0 | E5: 0 | F5: 0 | G5: 0 | H5: - | I5: - | J5: -
A8: ■共同生活援助（グループホーム）の実績と見込量
B9: 単位 | D9: 第6期 | E9: 第7期・第3期 | H9: 第8期・第4期
D10: R5年度 | E10: R6年度 | F10: R7年度 | G10: R8年度 | H10: R9年度 | I10: R10年度 | J10: R11年度
A11: 利用者数 | B11: 人/月 | C11: 見込量 | D11: 8 | E11: 8 | F11: 8 | G11: 8 | H11: 8 | I11: 9 | J11: 9
C12: 実績 | D12: 7 | E12: 8 | F12: 8 | G12: 8 | H12: - | I12: - | J12: -
A15: ■施設入所支援の実績と見込量
B16: 単位 | D16: 第6期 | E16: 第7期・第3期 | H16: 第8期・第4期
D17: R5年度 | E17: R6年度 | F17: R7年度 | G17: R8年度 | H17: R9年度 | I17: R10年度 | J17: R11年度
A18: 利用者数 | B18: 人/月 | C18: 見込量 | D18: 4 | E18: 4 | F18: 4 | G18: 4 | H18: 4 | I18: 4 | J18: 4
C19: 実績 | D19: 4 | E19: 4 | F19: 4 | G19: 4 | H19: - | I19: - | J19: -
A22: ■計画相談支援（サービス等利用計画作成）の実績と見込量
B23: 単位 | D23: 第6期 | E23: 第7期・第3期 | H23: 第8期・第4期
D24: R5年度 | E24: R6年度 | F24: R7年度 | G24: R8年度 | H24: R9年度 | I24: R10年度 | J24: R11年度
A25: 利用者数 | B25: 人/月 | C25: 見込量 | D25: 22 | E25: 22 | F25: 22 | G25: 22 | H25: 23 | I25: 24 | J25: 24
C26: 実績 | D26: 19 | E26: 21 | F26: 22 | G26: 22 | H26: - | I26: - | J26: -
A29: ■地域移行支援の実績と見込量
B30: 単位 | D30: 第6期 | E30: 第7期・第3期 | H30: 第8期・第4期
D31: R5年度 | E31: R6年度 | F31: R7年度 | G31: R8年度 | H31: R9年度 | I31: R10年度 | J31: R11年度
A32: 利用者数 | B32: 人/月 | C32: 見込量 | D32: ― | E32: 0 | F32: 0 | G32: 0 | H32: 0 | I32: 1 | J32: 1
C33: 実績 | D33: 0 | E33: 0 | F33: 0 | G33: 0 | H33: - | I33: - | J33: -
A36: ■地域定着支援の実績と見込量
B37: 単位 | D37: 第6期 | E37: 第7期・第3期 | H37: 第8期・第4期
D38: R5年度 | E38: R6年度 | F38: R7年度 | G38: R8年度 | H38: R9年度 | I38: R10年度 | J38: R11年度
A39: 利用者数 | B39: 人/月 | C39: 見込量 | D39: ― | E39: 0 | F39: 0 | G39: 0 | H39: 0 | I39: 1 | J39: 1
C40: 実績 | D40: 0 | E40: 0 | F40: 0 | G40: 0 | H40: - | I40: - | J40: -
A43: ※地域移行支援・地域定着支援のR10～R11は、精神科病院の長期入院者（第7期時点5人）の退院支援を想定した案。

Sheet サービス見込量（精神障がい者） (2)
A1: ■精神障がい者の自立訓練（生活訓練）の実績と見込量
B2: 単位 | D2: 第7期・第3期 | G2: 第8期・第4期 | L2: 着色セル＝R6～R8実績の推計値（村の実績で要差替）
D3: R6年度 | E3: R7年度 | F3: R8年度 | G3: R9年度 | H3: R10年度 | I3: R11年度 | L3: R5・R6～R8見込量＝第7期計画書（R5見込は第6期）。R5実績＝第7期計画書。
A4: 利用者数 | B4: 人/月 | C4: 見込量 | D4: ― | E4: ― | F4: ― | G4: 1 | H4: 1 | I4: 1 | L4: 第8期・第4期（R9～R11）の見込量はすべて推計による案。
C5: 実績 | D5: 1 | E5: 0 | F5: 1 | G5: - | H5: - | I5: -
A6: サービス量 | B6: 人日/月 | C6: 見込量 | D6: ― | E6: ― | F6: ― | G6: 12 | H6: 12 | I6: 12
C7: 実績 | D7: 12 | E7: 0 | F7: 12 | G7: - | H7: - | I7: -
A10: ■精神障がい者の自立生活援助の実績と見込量
B11: 単位 | D11: 第7期・第3期 | G11: 第8期・第4期
D12: R6年度 | E12: R7年度 | F12: R8年度 | G12: R9年度 | H12: R10年度 | I12: R11年度
A13: 利用者数 | B13: 人/月 | C13: 見込量 | D13: ― | E13: ― | F13: ― | G13: 0 | H13: 0 | I13: 0
C14: 実績 | D14: 0 | E14: 0 | F14: 0 | G14: - | H14: - | I14: -
A17: ■精神障がい者の共同生活援助の実績と見込量
B18: 単位 | D18: 第7期・第3期 | G18: 第8期・第4期
D19: R6年度 | E19: R7年度 | F19: R8年度 | G19: R9年度 | H19: R10年度 | I19: R11年度
A20: 利用者数 | B20: 人/月 | C20: 見込量 | D20: ― | E20: ― | F20: ― | G20: 3 | H20: 4 | I20: 4
C21: 実績 | D21: 3 | E21: 3 | F21: 3 | G21: - | H21: - | I21: -
A24: ■精神障がい者の地域移行支援の実績と見込量
B25: 単位 | D25: 第7期・第3期 | G25: 第8期・第4期
D26: R6年度 | E26: R7年度 | F26: R8年度 | G26: R9年度 | H26: R10年度 | I26: R11年度
A27: 利用者数 | B27: 人/月 | C27: 見込量 | D27: ― | E27: ― | F27: ― | G27: 0 | H27: 1 | I27: 1
C28: 実績 | D28: 0 | E28: 0 | F28: 0 | G28: - | H28: - | I28: -
A31: ■精神障がい者の地域定着支援の実績と見込量
B32: 単位 | D32: 第7期・第3期 | G32: 第8期・第4期
D33: R6年度 | E33: R7年度 | F33: R8年度 | G33: R9年度 | H33: R10年度 | I33: R11年度
A34: 利用者数 | B34: 人/月 | C34: 見込量 | D34: ― | E34: ― | F34: ― | G34: 0 | H34: 1 | I34: 1
C35: 実績 | D35: 0 | E35: 0 | F35: 0 | G35: - | H35: - | I35: -
A38: ■精神障がい者の短期入所の実績と見込量（第8期新規の活動指標）
B39: 単位 | D39: 第7期・第3期 | G39: 第8期・第4期
D40: R6年度 | E40: R7年度 | F40: R8年度 | G40: R9年度 | H40: R10年度 | I40: R11年度
A41: 利用者数 | B41: 人/月 | C41: 見込量 | D41: ― | E41: ― | F41: ― | G41: 0 | H41: 0 | I41: 0
C42: 実績 | D42: 0 | E42: 0 | F42: 0 | G42: - | H42: - | I42: -
A45: ※第7期計画では精神障がい者に限った見込量を設定していないため「―」。R6～R8実績は全体の利用状況から按分した推計。

Sheet サービス見込量（障がい児） (2)
A1: ■児童発達支援の実績と見込量
B2: 単位 | D2: 第6期 | E2: 第7期・第3期 | H2: 第8期・第4期 | M2: 着色セル＝R6～R8実績の推計値（村の実績で要差替）
D3: R5年度 | E3: R6年度 | F3: R7年度 | G3: R8年度 | H3: R9年度 | I3: R10年度 | J3: R11年度 | M3: R5・R6～R8見込量＝第7期計画書（R5見込は第6期）。R5実績＝第7期計画書。
A4: 利用者数 | B4: 人/月 | C4: 見込量 | D4: 2 | E4: 1 | F4: 0 | G4: 0 | H4: 1 | I4: 1 | J4: 1 | M4: 第8期・第4期（R9～R11）の見込量はすべて推計による案。
C5: 実績 | D5: 1 | E5: 1 | F5: 0 | G5: 0 | H5: - | I5: - | J5: -
A6: サービス量 | B6: 人日/月 | C6: 見込量 | D6: 8 | E6: 7 | F6: 0 | G6: 0 | H6: 8 | I6: 8 | J6: 8
C7: 実績 | D7: 15 | E7: 7 | F7: 0 | G7: 0 | H7: - | I7: - | J7: -
A10: ■放課後等デイサービスの実績と見込量
B11: 単位 | D11: 第6期 | E11: 第7期・第3期 | H11: 第8期・第4期
D12: R5年度 | E12: R6年度 | F12: R7年度 | G12: R8年度 | H12: R9年度 | I12: R10年度 | J12: R11年度
A13: 利用者数 | B13: 人/月 | C13: 見込量 | D13: 3 | E13: 1 | F13: 1 | G13: 1 | H13: 2 | I13: 2 | J13: 2
C14: 実績 | D14: 1 | E14: 1 | F14: 1 | G14: 1 | H14: - | I14: - | J14: -
A15: サービス量 | B15: 人日/月 | C15: 見込量 | D15: 9 | E15: 2 | F15: 2 | G15: 2 | H15: 6 | I15: 6 | J15: 6
C16: 実績 | D16: 2 | E16: 2 | F16: 2 | G16: 2 | H16: - | I16: - | J16: -
A19: ■保育所等訪問支援の実績と見込量
B20: 単位 | D20: 第6期 | E20: 第7期・第3期 | H20: 第8期・第4期
D21: R5年度 | E21: R6年度 | F21: R7年度 | G21: R8年度 | H21: R9年度 | I21: R10年度 | J21: R11年度
A22: 利用者数 | B22: 人/月 | C22: 見込量 | D22: 0 | E22: 0 | F22: 0 | G22: 0 | H22: 0 | I22: 1 | J22: 1
C23: 実績 | D23: 0 | E23: 0 | F23: 0 | G23: 0 | H23: - | I23: - | J23: -
A24: サービス量 | B24: 人日/月 | C24: 見込量 | D24: 0 | E24: 0 | F24: 0 | G24: 0 | H24: 0 | I24: 2 | J24: 2
C25: 実績 | D25: 0 | E25: 0 | F25: 0 | G25: 0 | H25: - | I25: - | J25: -
A28: ■居宅訪問型児童発達支援の実績と見込量
B29: 単位 | D29: 第6期 | E29: 第7期・第3期 | H29: 第8期・第4期
D30: R5年度 | E30: R6年度 | F30: R7年度 | G30: R8年度 | H30: R9年度 | I30: R10年度 | J30: R11年度
A31: 利用者数 | B31: 人/月 | C31: 見込量 | D31: 0 | E31: 0 | F31: 0 | G31: 0 | H31: 0 | I31: 0 | J31: 0
C32: 実績 | D32: 0 | E32: 0 | F32: 0 | G32: 0 | H32: - | I32: - | J32: -
A33: サービス量 | B33: 人日/月 | C33: 見込量 | D33: 0 | E33: 0 | F33: 0 | G33: 0 | H33: 0 | I33: 0 | J33: 0
C34: 実績 | D34: 0 | E34: 0 | F34: 0 | G34: 0 | H34: - | I34: - | J34: -
A37: ■障がい児相談支援の実績と見込量
B38: 単位 | D38: 第6期 | E38: 第7期・第3期 | H38: 第8期・第4期
D39: R5年度 | E39: R6年度 | F39: R7年度 | G39: R8年度 | H39: R9年度 | I39: R10年度 | J39: R11年度
A40: 利用者数 | B40: 人/月 | C40: 見込量 | D40: 5 | E40: 2 | F40: 2 | G40: 2 | H40: 3 | I40: 3 | J40: 3
C41: 実績 | D41: 2 | E41: 2 | F41: 2 | G41: 2 | H41: - | I41: - | J41: -
A44: ■医療的ケア児等コーディネーター配置数の実績と見込量
B45: 単位 | D45: 第6期 | E45: 第7期・第3期 | H45: 第8期・第4期
D46: R5年度 | E46: R6年度 | F46: R7年度 | G46: R8年度 | H46: R9年度 | I46: R10年度 | J46: R11年度
A47: 配置人数 | B47: 人 | C47: 見込量 | D47: ― | E47: ― | F47: ― | G47: 1 | H47: 1 | I47: 1 | J47: 1
C48: 実績 | D48: 0 | E48: 0 | F48: 0 | G48: 1 | H48: - | I48: - | J48: -
A51: ■地域生活支援拠点等の実績と見込量（会津北部4町村）
B52: 単位 | D52: 第6期 | E52: 第7期・第3期 | H52: 第8期・第4期
...

Sheet サービス見込量（地域生活支援）必須 (2)
A1: ■理解促進研修・啓発事業の実績と見込量
B2: 単位 | D2: 第6期 | E2: 第7期・第3期 | H2: 第8期・第4期 | M2: 着色セル＝R6～R8実績の推計値（村の実績で要差替）
D3: R5年度 | E3: R6年度 | F3: R7年度 | G3: R8年度 | H3: R9年度 | I3: R10年度 | J3: R11年度 | M3: R5・R6～R8見込量＝第7期計画書（R5見込は第6期）。R5実績＝第7期計画書。
A4: 実施件数 | B4: 件/年 | C4: 見込量 | D4: 0 | E4: 0 | F4: 0 | G4: 0 | H4: 1 | I4: 1 | J4: 1 | M4: 第8期・第4期（R9～R11）の見込量はすべて推計による案。
C5: 実績 | D5: 0 | E5: 0 | F5: 0 | G5: 0 | H5: - | I5: - | J5: -
A8: ■自発的活動支援事業の実績と見込量
B9: 単位 | D9: 第6期 | E9: 第7期・第3期 | H9: 第8期・第4期
D10: R5年度 | E10: R6年度 | F10: R7年度 | G10: R8年度 | H10: R9年度 | I10: R10年度 | J10: R11年度
A11: 実施件数 | B11: 件/年 | C11: 見込量 | D11: ― | E11: 0 | F11: 0 | G11: 0 | H11: 0 | I11: 1 | J11: 1
C12: 実績 | D12: 0 | E12: 0 | F12: 0 | G12: 0 | H12: - | I12: - | J12: -
A15: ■相談支援事業の実績と見込量
B16: 単位 | D16: 第6期 | E16: 第7期・第3期 | H16: 第8期・第4期
D17: R5年度 | E17: R6年度 | F17: R7年度 | G17: R8年度 | H17: R9年度 | I17: R10年度 | J17: R11年度
A18: 障がい者相談支援事業 | B18: 実施箇所数 | D18: 2 | E18: 2 | F18: 2 | G18: 2 | H18: 2 | I18: 2 | J18: 2
A19: 基幹相談支援センター | B19: 設置の有無 | D19: × | E19: × | F19: × | G19: 検討中 | H19: 〇（広域） | I19: 〇（広域） | J19: 〇（広域）
A20: 障がい者虐待防止センター | B20: 設置の有無 | D20: 〇 | E20: 〇 | F20: 〇 | G20: 〇 | H20: 〇 | I20: 〇 | J20: 〇
A21: 障がい者自立支援協議会 | B21: 設置の有無 | D21: 〇 | E21: 〇 | F21: 〇 | G21: 〇 | H21: 〇 | I21: 〇 | J21: 〇
A22: 協議会専門部会 | B22: 設置数 | D22: 0 | E22: 0 | F22: 0 | G22: 1 | H22: 2 | I22: 2 | J22: 2
A25: ■成年後見制度利用支援事業の実績と見込量
B26: 単位 | D26: 第6期 | E26: 第7期・第3期 | H26: 第8期・第4期
D27: R5年度 | E27: R6年度 | F27: R7年度 | G27: R8年度 | H27: R9年度 | I27: R10年度 | J27: R11年度
A28: 利用者数 | B28: 人/年 | C28: 見込量 | D28: 2 | E28: 5 | F28: 5 | G28: 5 | H28: 4 | I28: 4 | J28: 5
C29: 実績 | D29: 1 | E29: 2 | F29: 3 | G29: 3 | H29: - | I29: - | J29: -
A32: ■意思疎通支援事業の実績と見込量
B33: 単位 | D33: 第6期 | E33: 第7期・第3期 | H33: 第8期・第4期
D34: R5年度 | E34: R6年度 | F34: R7年度 | G34: R8年度 | H34: R9年度 | I34: R10年度 | J34: R11年度
A35: 手話通訳者派遣事業 | B35: 件/年 | C35: 見込量 | D35: 0 | E35: 0 | F35: 0 | G35: 0 | H35: 1 | I35: 1 | J35: 1
C36: 実績 | D36: 0 | E36: 0 | F36: 0 | G36: 0 | H36: - | I36: - | J36: -
A37: 要約筆記者派遣事業 | B37: 件/年 | C37: 見込量 | D37: 0 | E37: 0 | F37: 0 | G37: 0 | H37: 0 | I37: 0 | J37: 0
C38: 実績 | D38: 0 | E38: 0 | F38: 0 | G38: 0 | H38: - | I38: - | J38: -
A39: 手話通訳者設置事業 | B39: 人 | C39: 見込量 | D39: 0 | E39: 0 | F39: 0 | G39: 0 | H39: 0 | I39: 0 | J39: 0
C40: 実績 | D40: 0 | E40: 0 | F40: 0 | G40: 0 | H40: - | I40: - | J40: -
A43: ■日常生活用具給付等事業の実績と見込量
B44: 単位 | D44: 第6期 | E44: 第7期・第3期 | H44: 第8期・第4期
D45: R5年度 | E45: R6年度 | F45: R7年度 | G45: R8年度 | H45: R9年度 | I45: R10年度 | J45: R11年度
A46: 介護・訓練支援用具（特殊寝台等） | B46: 件/年 | C46: 見込量 | D46: 1 | E46: 2 | F46: 2 | G46: 2 | H46: 1 | I46: 1 | J46: 1
C47: 実績 | D47: 0 | E47: 1 | F47: 1 | G47: 1 | H47: - | I47: - | J47: -
A48: 自立生活支援用具（入浴補助用具等） | B48: 件/年 | C48: 見込量 | D48: 1 | E48: 1 | F48: 1 | G48: 1 | H48: 1 | I48: 1 | J48: 1
C49: 実績 | D49: 3 | E49: 1 | F49: 1 | G49: 1 | H49: - | I49: - | J49: -
A50: 在宅療養等支援用具（電気式たん吸引器等） | B50: 件/年 | C50: 見込量 | D50: 0 | E50: 0 | F50: 0 | G50: 0 | H50: 1 | I50: 1 | J50: 1
...

Sheet サービス見込量（地域生活支援）任意 (2)
A1: ■訪問入浴サービス事業の実績と見込量
B2: 単位 | D2: 第6期 | E2: 第7期・第3期 | H2: 第8期・第4期 | M2: 着色セル＝R6～R8実績の推計値（村の実績で要差替）
D3: R5年度 | E3: R6年度 | F3: R7年度 | G3: R8年度 | H3: R9年度 | I3: R10年度 | J3: R11年度 | M3: R5・R6～R8見込量＝第7期計画書（R5見込は第6期）。R5実績＝第7期計画書。
A4: 利用者数 | B4: 人/年 | C4: 見込量 | D4: 0 | E4: 0 | F4: 0 | G4: 0 | H4: 0 | I4: 0 | J4: 0 | M4: 第8期・第4期（R9～R11）の見込量はすべて推計による案。
C5: 実績 | D5: 0 | E5: 0 | F5: 0 | G5: 0 | H5: - | I5: - | J5: -
A8: ■日中一時支援事業の実績と見込量
B9: 単位 | D9: 第6期 | E9: 第7期・第3期 | H9: 第8期・第4期
D10: R5年度 | E10: R6年度 | F10: R7年度 | G10: R8年度 | H10: R9年度 | I10: R10年度 | J10: R11年度
A11: 利用者数 | B11: 人/年 | C11: 見込量 | D11: 0 | E11: 2 | F11: 2 | G11: 2 | H11: 2 | I11: 2 | J11: 3
C12: 実績 | D12: 2 | E12: 2 | F12: 2 | G12: 2 | H12: - | I12: - | J12: -
A15: ■福祉ホーム事業の実績と見込量
B16: 単位 | D16: 第6期 | E16: 第7期・第3期 | H16: 第8期・第4期
D17: R5年度 | E17: R6年度 | F17: R7年度 | G17: R8年度 | H17: R9年度 | I17: R10年度 | J17: R11年度
A18: 利用者数 | B18: 人/年 | C18: 見込量 | D18: 0 | E18: 0 | F18: 0 | G18: 0 | H18: 1 | I18: 1 | J18: 1
C19: 実績 | D19: 2 | E19: 1 | F19: 1 | G19: 1 | H19: - | I19: - | J19: -
A22: （参考）更生訓練費給付事業、点字・声の広報等発行事業、自動車運転免許取得・改造助成事業、レクリエーション活動等支援事業等は本村では現在未実施（ニーズに応じ検討）。

Sheet 事業体型
B2: 自立支援給付 | D2: 地域生活支援事業
B3: 【訪問系サービス】 | D3: 【必須事業】
B4: ・居宅介護 | D4: ・理解促進研修・啓発事業
B5: ・重度訪問介護 | D5: ・自発的活動支援事業
B6: ・同行援護 | D6: ・相談支援事業
B7: ・行動援護 | D7: ・成年後見制度利用支援事業
B8: ・重度障がい者等包括支援 | D8: ・成年後見制度法人後見支援事業
B9: 【日中活動系サービス】 | D9: ・意思疎通支援事業
B10: ・生活介護 | D10: ・日常生活用具給付等事業
B11: ・自立訓練（機能訓練・生活訓練） | D11: ・手話奉仕員養成研修事業
B12: ・就労選択支援 | D12: ・移動支援事業
B13: ・就労移行支援 | D13: ・地域活動支援センター機能強化事業
... B17: ・共同生活援助（グループホーム） | D17: ・福祉ホーム事業
B18: ・施設入所支援
B19: 【相談支援】
B20: ・計画相談支援
B21: ・地域移行支援 | D21: 障がい児通所給付
B22: ・地域定着支援 | D22: 【障がい児】
D23: ・児童発達支援
B24: 【村単独事業（県補助含む）】 | D24: ・放課後等デイサービス
B25: ・重度心身障害者医療費助成 | D25: ・保育所等訪問支援
B26: ・在宅重度障害者対策事業 | D26: ・居宅訪問型児童発達支援
B27: ・人工透析患者通院交通費助成 | D27: 【障がい児相談支援】
D28: ・障がい児相談支援

Sheet 身体障がい者手帳保持者
B1: 等級別身体障がい者手帳所持者数 | M1: 障がい種類別身体障がい者手帳所持者数の推移
B2: ※総数はR2～R5が第7期計画（4月1日）、R6～R8は推計。等級別内訳は計画に記載がないため構成比で按分した推計。種類別はR5（P列）のみ実数。 | I2: 単位：人 | S2: 単位：人
B3: 区分 | C3: 令和２年度 | D3: 令和3年度 | E3: 令和4年度 | F3: 令和5年度 | G3: 令和6年度 | H3: 令和7年度 | I3: 令和8年度 | M3: 区分 | N3: 令和3年度 | O3: 令和4年度 | P3: 令和5年度 | Q3: 令和6年度 | R3: 令和7年度 | S3: 令和8年度
B4: 総計 | C4: =C5+C7+C9+C11+C13+C15 -> 121 | D4: =D5+D7+D9+D11+D13+D15 -> 128 | E4: =E5+E7+E9+E11+E13+E15 -> 122 | F4: =F5+F7+F9+F11+F13+F15 -> 114 | G4: =G5+G7+G9+G11+G13+G15 -> 117 | H4: =H5+H7+H9+H11+H13+H15 -> 122 | I4: =I5+I7+I9+I11+I13+I15 -> 127 | M4: 総計 | N4: =N5+N7+N9+N11+N13 -> 128 | O4: =O5+O7+O9+O11+O13 -> 122 | P4: =P5+P7+P9+P11+P13 -> 114 | Q4: =Q5+Q7+Q9+Q11+Q13 -> 117 | R4: =R5+R7+R9+R11+R13 -> 122 | S4: =S5+S7+S9+S11+S13 -> 127
B5: 1級 | C5: 40 | D5: 42 | E5: 40 | F5: 38 | G5: 39 | H5: 40 | I5: 42 | M5: 視覚障がい者 | N5: 3 | O5: 3 | P5: 3 | Q5: 3 | R5: 3 | S5: 3
C6: =C5/C4 -> 0.33057851 | D6: =D5/D4 -> 0.328125 | E6: =E5/E4 -> 0.32786885 | F6: =F5/F4 -> 0.33333333 | G6: =G5/G4 -> 0.33333333 | H6: =H5/H4 -> 0.32786885 | I6: =I5/I4 -> 0.33070866 | N6: =N5/N4 -> 0.0234375 | O6: =O5/O4 -> 0.024590164 | P6: =P5/P4 -> 0.026315789 | Q6: =Q5/Q4 -> 0.025641026 | R6: =R5/R4 -> 0.024590164 | S6: =S5/S4 -> 0.023622047
B7: 2級 | C7: 16 | D7: 17 | E7: 16 | F7: 15 | G7: 15 | H7: 16 | I7: 17 | M7: 聴覚・平衡機能障がい | N7: 18 | O7: 17 | P7: 16 | Q7: 16 | R7: 17 | S7: 18
C8: =C7/C4 -> 0.1322314 | D8: =D7/D4 -> 0.1328125 | E8: =E7/E4 -> 0.13114754 | F8: =F7/F4 -> 0.13157895 | G8: =G7/G4 -> 0.12820513 | H8: =H7/H4 -> 0.13114754 | I8: =I7/I4 -> 0.13385827 | N8: =N7/N4 -> 0.140625 | O8: =O7/O4 -> 0.13934426 | P8: =P7/P4 -> 0.14035088 | Q8: =Q7/Q4 -> 0.13675214 | R8: =R7/R4 -> 0.13934426 | S8: =S7/S4 -> 0.14173228
B9: 3級 | C9: 22 | D9: 23 | E9: 22 | F9: 20 | G9: 21 | H9: 22 | I9: 23 | M9: 音声・言語・そしゃく機能障がい | N9: 0 | O9: 0 | P9: 0 | Q9: 0 | R9: 0 | S9: 0
C10: =C9/C4 -> 0.18181818 | D10: =D9/D4 -> 0.1796875 | E10: =E9/E4 -> 0.18032787 | F10: =F9/F4 -> 0.1754386 | G10: =G9/G4 -> 0.17948718 | H10: =H9/H4 -> 0.18032787 | I10: =I9/I4 -> 0.18110236 | N10: =N9/N4 -> 0 | O10: =O9/O4 -> 0 | P10: =P9/P4 -> 0 | Q10: =Q9/Q4 -> 0 | R10: =R9/R4 -> 0 | S10: =S9/S4 -> 0
B11: 4級 | C11: 30 | D11: 32 | E11: 31 | F11: 29 | G11: 29 | H11: 31 | I11: 32 | M11: 肢体不自由 | N11: 57 | O11: 54 | P11: 50 | Q11: 51 | R11: 53 | S11: 55
C12: =C11/C4 -> 0.24793388 | D12: =D11/D4 -> 0.25 | E12: =E11/E4 -> 0.25409836 | F12: =F11/F4 -> 0.25438596 | G12: =G11/G4 -> 0.24786325 | H12: =H11/H4 -> 0.25409836 | I12: =I11/I4 -> 0.2519685 | N12: =N11/N4 -> 0.4453125 | O12: =O11/O4 -> 0.44262295 | P12: =P11/P4 -> 0.43859649 | Q12: =Q11/Q4 -> 0.43589744 | R12: =R11/R4 -> 0.43442623 | S12: =S11/S4 -> 0.43307087
B13: 5級 | C13: 6 | D13: 6 | E13: 6 | F13: 5 | G13: 6 | H13: 6 | I13: 6 | M13: 内部障がい | N13: 50 | O13: 48 | P13: 45 | Q13: 47 | R13: 49 | S13: 51
C14: =C13/C4 -> 0.049586777 | D14: =D13/D4 -> 0.046875 | E14: =E13/E4 -> 0.049180328 | F14: =F13/F4 -> 0.043859649 | G14: =G13/G4 -> 0.051282051 | H14: =H13/H4 -> 0.049180328 | I14: =I13/I4 -> 0.047244094 | N14: =N13/N4 -> 0.390625 | O14: =O13/O4 -> 0.39344262 | P14: =P13/P4 -> 0.39473684 | Q14: =Q13/Q4 -> 0.4017094 | R14: =R13/R4 -> 0.40163934 | S14: =S13/S4 -> 0.4015748
B15: 6級 | C15: 7 | D15: 8 | E15: 7 | F15: 7 | G15: 7 | H15: 7 | I15: 7 | M15: 対人口比 | N15: =N4/人口状況!D4 -> 0.048669202 | O15: =O4/人口状況!E4 -> 0.048126233 | P15: =P4/人口状況!F4 -> 0.046663938 | Q15: =Q4/人口状況!G4 -> 0.048648649 | R15: =R4/人口状況!H4 -> 0.05152027 | S15: =S4/人口状況!I4 -> 0.054835924
C16: =C15/C4 -> 0.05785124 | D16: =D15/D4 -> 0.0625 | E16: =E15/E4 -> 0.057377049 | F16: =F15/F4 -> 0.061403509 | G16: =G15/G4 -> 0.05982906 | H16: =H15/H4 -> 0.057377049 | I16: =I15/I4 -> 0.05511811
B17: 対人口比 | C17: =C4/人口状況!C4 -> 0.044864664 | D17: =D4/人口状況!D4 -> 0.048669202 | E17: =E4/人口状況!E4 -> 0.048126233 | F17: =F4/人口状況!F4 -> 0.046663938 | G17: =G4/人口状況!G4 -> 0.048648649 | H17: =H4/人口状況!H4 -> 0.05152027 | I17: =I4/人口状況!I4 -> 0.054835924
C18: 着色セル＝推計値（村の実績・台帳データで要差替）

Sheet 療育手帳所持者 
B1: 療育手帳所持者数
H2: 単位：人
B3: 区分 | C3: 令和3年度 | D3: 令和4年度 | E3: 令和5年度 | F3: 令和6年度 | G3: 令和7年度 | H3: 令和8年度
B4: 総計 | C4: =C5+C7 -> 14 | D4: =D5+D7 -> 12 | E4: =E5+E7 -> 12 | F4: =F5+F7 -> 13 | G4: =G5+G7 -> 15 | H4: =H5+H7 -> 16
B5: A（重度） | C5: 3 | D5: 3 | E5: 4 | F5: 4 | G5: 5 | H5: 5
C6: =C5/C4 -> 0.21428571 | D6: =D5/D4 -> 0.25 | E6: =E5/E4 -> 0.33333333 | F6: =F5/F4 -> 0.30769231 | G6: =G5/G4 -> 0.33333333 | H6: =H5/H4 -> 0.3125
B7: B（中度・軽度） | C7: 11 | D7: 9 | E7: 8 | F7: 9 | G7: 10 | H7: 11
C8: =C7/C4 -> 0.78571429 | D8: =D7/D4 -> 0.75 | E8: =E7/E4 -> 0.66666667 | F8: =F7/F4 -> 0.69230769 | G8: =G7/G4 -> 0.66666667 | H8: =H7/H4 -> 0.6875
B9: 対人口比 | C9: =C4/人口状況!D4 -> 0.0053231939 | D9: =D4/人口状況!E4 -> 0.0047337278 | E9: =E4/人口状況!F4 -> 0.0049119935 | F9: =F4/人口状況!G4 -> 0.0054054054 | G9: =G4/人口状況!H4 -> 0.0063344595 | H9: =H4/人口状況!I4 -> 0.0069084629
B11: ※R3～R5は第7期計画（4月1日）、R6～R8は推計。福島県の療育手帳区分（A：重度、B：中度・軽度）に合わせて区分を変更。
C12: 着色セル＝推計値（村の実績・台帳データで要差替）

Sheet 精神保健障がい者手帳所持者  
B1: 精神障害者保健福祉手帳所持者数
H2: 単位：人
B3: 区分 | C3: 令和3年度 | D3: 令和4年度 | E3: 令和5年度 | F3: 令和6年度 | G3: 令和7年度 | H3: 令和8年度
B4: 総計 | C4: =C5+C7+C9 -> 27 | D4: =D5+D7+D9 -> 26 | E4: =E5+E7+E9 -> 30 | F4: =F5+F7+F9 -> 33 | G4: =G5+G7+G9 -> 36 | H4: =H5+H7+H9 -> 38
B5: 1級 | C5: 1 | D5: 1 | E5: 1 | F5: 1 | G5: 1 | H5: 1
C6: =C5/C4 -> 0.037037037 | D6: =D5/D4 -> 0.038461538 | E6: =E5/E4 -> 0.033333333 | F6: =F5/F4 -> 0.03030303 | G6: =G5/G4 -> 0.027777778 | H6: =H5/H4 -> 0.026315789
B7: 2級 | C7: 15 | D7: 14 | E7: 16 | F7: 18 | G7: 19 | H7: 20
C8: =C7/C4 -> 0.55555556 | D8: =D7/D4 -> 0.53846154 | E8: =E7/E4 -> 0.53333333 | F8: =F7/F4 -> 0.54545455 | G8: =G7/G4 -> 0.52777778 | H8: =H7/H4 -> 0.52631579
B9: 3級 | C9: 11 | D9: 11 | E9: 13 | F9: 14 | G9: 16 | H9: 17
C10: =C9/C4 -> 0.40740741 | D10: =D9/D4 -> 0.42307692 | E10: =E9/E4 -> 0.43333333 | F10: =F9/F4 -> 0.42424242 | G10: =G9/G4 -> 0.44444444 | H10: =H9/H4 -> 0.44736842
B11: 対人口比 | C11: =C4/人口状況!D4 -> 0.01026616 | D11: =D4/人口状況!E4 -> 0.01025641 | E11: =E4/人口状況!F4 -> 0.012279984 | F11: =F4/人口状況!G4 -> 0.013721414 | G11: =G4/人口状況!H4 -> 0.015202703 | H11: =H4/人口状況!I4 -> 0.016407599
B13: ※総数はR3～R5が第7期計画（4月1日）、R6～R8は推計。級別内訳はR5（E列）のみ実数、他年度は構成比で按分した推計。
C14: 着色セル＝推計値（村の実績・台帳データで要差替）

Sheet 自立支援医療受給者数
B1: 自立支援医療受給者数
H2: 単位：人
B3: 区分 | C3: 令和3年度 | D3: 令和4年度 | E3: 令和5年度 | F3: 令和6年度 | G3: 令和7年度 | H3: 令和8年度
B4: 総計 | C4: =C5+C7+C9 -> 49 | D4: =D5+D7+D9 -> 50 | E4: =E5+E7+E9 -> 50 | F4: =F5+F7+F9 -> 53 | G4: =G5+G7+G9 -> 57 | H4: =H5+H7+H9 -> 58
B5: 育成医療 | C5: 1 | D5: 1 | E5: 0 | F5: 0 | G5: 1 | H5: 0
C6: =C5/C4 -> 0.020408163 | D6: =D5/D4 -> 0.02 | E6: =E5/E4 -> 0 | F6: =F5/F4 -> 0 | G6: =G5/G4 -> 0.01754386 | H6: =H5/H4 -> 0
B7: 更生医療 | C7: 6 | D7: 6 | E7: 5 | F7: 5 | G7: 5 | H7: 5
C8: =C7/C4 -> 0.12244898 | D8: =D7/D4 -> 0.12 | E8: =E7/E4 -> 0.1 | F8: =F7/F4 -> 0.094339623 | G8: =G7/G4 -> 0.087719298 | H8: =H7/H4 -> 0.086206897
B9: 精神通院医療 | C9: 42 | D9: 43 | E9: 45 | F9: 48 | G9: 51 | H9: 53
C10: =C9/C4 -> 0.85714286 | D10: =D9/D4 -> 0.86 | E10: =E9/E4 -> 0.9 | F10: =F9/F4 -> 0.90566038 | G10: =G9/G4 -> 0.89473684 | H10: =H9/H4 -> 0.9137931
B12: ※村の受給者台帳データがないため、全国の受給者出現率・手帳所持者数等から設定した仮置き値（要差替）。
C13: 着色セル＝推計値（村の実績・台帳データで要差替）

Sheet 障がい支援区分認定者数
B1: 障がい支援区分認定者数
H2: 単位：人
B3: 区分 | C3: 令和3年度 | D3: 令和4年度 | E3: 令和5年度 | F3: 令和6年度 | G3: 令和7年度 | H3: 令和8年度
B4: 総計 | C4: =C5+C7+C9+C11+C13+C15 -> 19 | D4: =D5+D7+D9+D11+D13+D15 -> 20 | E4: =E5+E7+E9+E11+E13+E15 -> 21 | F4: =F5+F7+F9+F11+F13+F15 -> 21 | G4: =G5+G7+G9+G11+G13+G15 -> 22 | H4: =H5+H7+H9+H11+H13+H15 -> 22
B5: 区分１ | C5: 1 | D5: 1 | E5: 1 | F5: 1 | G5: 1 | H5: 1
C6: =C5/C4 -> 0.052631579 | D6: =D5/D4 -> 0.05 | E6: =E5/E4 -> 0.047619048 | F6: =F5/F4 -> 0.047619048 | G6: =G5/G4 -> 0.045454545 | H6: =H5/H4 -> 0.045454545
B7: 区分２ | C7: 3 | D7: 3 | E7: 3 | F7: 3 | G7: 3 | H7: 3
C8: =C7/C4 -> 0.15789474 | D8: =D7/D4 -> 0.15 | E8: =E7/E4 -> 0.14285714 | F8: =F7/F4 -> 0.14285714 | G8: =G7/G4 -> 0.13636364 | H8: =H7/H4 -> 0.13636364
B9: 区分３ | C9: 4 | D9: 4 | E9: 5 | F9: 5 | G9: 5 | H9: 5
C10: =C9/C4 -> 0.21052632 | D10: =D9/D4 -> 0.2 | E10: =E9/E4 -> 0.23809524 | F10: =F9/F4 -> 0.23809524 | G10: =G9/G4 -> 0.22727273 | H10: =H9/H4 -> 0.22727273
B11: 区分４ | C11: 4 | D11: 5 | E11: 5 | F11: 5 | G11: 5 | H11: 5
C12: =C11/C4 -> 0.21052632 | D12: =D11/D4 -> 0.25 | E12: =E11/E4 -> 0.23809524 | F12: =F11/F4 -> 0.23809524 | G12: =G11/G4 -> 0.22727273 | H12: =H11/H4 -> 0.22727273
B13: 区分５ | C13: 3 | D13: 3 | E13: 3 | F13: 3 | G13: 4 | H13: 4
C14: =C13/C4 -> 0.15789474 | D14: =D13/D4 -> 0.15 | E14: =E13/E4 -> 0.14285714 | F14: =F13/F4 -> 0.14285714 | G14: =G13/G4 -> 0.18181818 | H14: =H13/H4 -> 0.18181818
B15: 区分６ | C15: 4 | D15: 4 | E15: 4 | F15: 4 | G15: 4 | H15: 4
C16: =C15/C4 -> 0.21052632 | D16: =D15/D4 -> 0.2 | E16: =E15/E4 -> 0.19047619 | F16: =F15/F4 -> 0.19047619 | G16: =G15/G4 -> 0.18181818 | H16: =H15/H4 -> 0.18181818
B18: ※区分認定者数は計画書に記載がないため、生活介護・施設入所支援・居宅介護等の利用者数から設定した仮置き値（要差替）。
C19: 着色セル＝推計値（村の実績・台帳データで要差替）

Sheet 重度心身障害者医療費助成受給者数
B1: 重度心身障害者医療費助成等受給者数
H2: 単位：人
B3: 区分 | C3: 令和3年度 | D3: 令和4年度 | E3: 令和5年度 | F3: 令和6年度 | G3: 令和7年度 | H3: 令和8年度
B4: 総計 | C4: =C5+C7+C9 -> 63 | D4: =D5+D7+D9 -> 61 | E4: =E5+E7+E9 -> 57 | F4: =F5+F7+F9 -> 61 | G4: =G5+G7+G9 -> 63 | H4: =H5+H7+H9 -> 65
B5: 重度心身障害者医療費助成受給者 | C5: 52 | D5: 50 | E5: 48 | F5: 50 | G5: 52 | H5: 54
C6: =C5/C4 -> 0.82539683 | D6: =D5/D4 -> 0.81967213 | E6: =E5/E4 -> 0.84210526 | F6: =F5/F4 -> 0.81967213 | G6: =G5/G4 -> 0.82539683 | H6: =H5/H4 -> 0.83076923
B7: 在宅重度障害者対策事業（紙おむつ等給付）受給者 | C7: 6 | D7: 6 | E7: 5 | F7: 6 | G7: 6 | H7: 6
C8: =C7/C4 -> 0.095238095 | D8: =D7/D4 -> 0.098360656 | E8: =E7/E4 -> 0.087719298 | F8: =F7/F4 -> 0.098360656 | G8: =G7/G4 -> 0.095238095 | H8: =H7/H4 -> 0.092307692
B9: 人工透析患者通院交通費助成受給者 | C9: 5 | D9: 5 | E9: 4 | F9: 5 | G9: 5 | H9: 5
C10: =C9/C4 -> 0.079365079 | D10: =D9/D4 -> 0.081967213 | E10: =E9/E4 -> 0.070175439 | F10: =F9/F4 -> 0.081967213 | G10: =G9/G4 -> 0.079365079 | H10: =H9/H4 -> 0.076923077
B12: ※いずれも村単独事業（県補助含む）。受給者数は手帳所持者の等級構成等から設定した仮置き値（要差替）。
C13: 着色セル＝推計値（村の実績・台帳データで要差替）

Sheet アンケート結果（本人・家族）
B1: N | C1: 110 | E1: ※第8期ニーズ調査（令和8年度実施）の結果が出るまでの仮置き値。配布約190人×回収率約58％（第7期57.9％）でN=110と想定（介助者設問はN=60）。差別経験は第7期調査（25.3％）を参考。 | P1: N | Q1: 110
B2: 日中に過ごしている場所 | C2: 無回答 | D2: その他 | E2: 友人と会うために外出 | F2: 買物や趣味等で外出 | G2: デイケアやリハビリ | H2: 病院・入院中 | I2: 通所施設・作業所 | J2: 職場・仕事 | K2: 学校（保育園・こども園等を含む） | L2: 入所施設・グループホーム | M2: 自宅 | P2: 日中に過ごしている場所 | Q2: 無回答 | R2: その他 | S2: 友人と会うために外出 | T2: 買物や趣味等で外出 | U2: デイケアやリハビリ | V2: 病院・入院中 | W2: 通所施設・作業所 | X2: 職場・仕事 | Y2: 学校（保育園・こども園等を含む） | Z2: 入所施設・グループホーム | AA2: 自宅
C3: =ROUND(Q3/$C$1,3) -> 0.036 | D3: =ROUND(R3/$C$1,3) -> 0.027 | E3: =ROUND(S3/$C$1,3) -> 0.045 | F3: =ROUND(T3/$C$1,3) -> 0.164 | G3: =ROUND(U3/$C$1,3) -> 0.073 | H3: =ROUND(V3/$C$1,3) -> 0.036 | I3: =ROUND(W3/$C$1,3) -> 0.109 | J3: =ROUND(X3/$C$1,3) -> 0.2 | ... M3: =ROUND(AA3/$C$1,3) -> 0.564 | Q3: 4 | R3: 3 | S3: 5 | T3: 18 | U3: 8 | V3: 4 | W3: 12 | X3: 22 | Y3: 3 | Z3: 9 | AA3: 62
B23: N | C23: =Q23 -> 110 | P23: N | Q23: =SUM(M25:S25) -> 110
B24: 外出の回数 | C24: 無回答 | D24: ほとんど外出しない | E24: 年に数回 | F24: 月に1～2回 | G24: 週に1～2回 | H24: 週に3～4回 | I24: ほとんど毎日 | L24: 外出の回数 | M24: 無回答 | N24: ほとんど外出しない | O24: 年に数回 | P24: 月に1～2回 | Q24: 週に1～2回 | R24: 週に3～4回 | S24: ほとんど毎日
C25: =ROUND(M25/$C$23,3) -> 0.027 | D25: =ROUND(N25/$C$23,3) -> 0.091 | E25: =ROUND(O25/$C$23,3) -> 0.045 | F25: =ROUND(P25/$C$23,3) -> 0.109 | G25: =ROUND(Q25/$C$23,3) -> 0.227 | H25: =ROUND(R25/$C$23,3) -> 0.2 | I25: =ROUND(S25/$C$23,3) -> 0.3 | M25: 3 | N25: 10 | O25: 5 | P25: 12 | Q25: 25 | R25: 22 | S25: 33
B40: N | C40: 110 | P40: N | Q40: 110
B41: 外出や交通手段で困っていること | C41: 無回答 | D41: 特にない | E41: その他 | F41: 体調が不安 | G41: 介助者がいない | H41: 外出による出費が多い | I41: 駐車場が少ない | J41: 外出先の建物の設備が使いにくい | K41: 乗り方、乗り換えがわかりにくい | L41: 道路や駅に段差が多い | M41: 電車やバスの乗り降りが困難 | N41: 公共交通機関・便数が少ない | P41: 外出や交通手段で困っていること | Q41: 無回答 | R41: 特にない | S41: その他 | T41: 体調が不安 | U41: 介助者がいない | V41: 外出による出費が多い | W41: 駐車場が少ない | X41: 外出先の建物の設備が使いにくい | Y41: 乗り方、乗り換えがわかりにく | Z41: 道路や駅に段差が多い | AA41: 電車やバスの乗り降りが困難 | AB41: 公共交通機関・便数が少ない
C42: =ROUND(Q42/$C$40,3) -> 0.055 | D42: =ROUND(R42/$C$40,3) -> 0.273 | E42: =ROUND(S42/$C$40,3) -> 0.045 | F42: =ROUND(T42/$C$40,3) -> 0.218 | G42: =ROUND(U42/$C$40,3) -> 0.091 | H42: =ROUND(V42/$C$40,3) -> 0.127 | I42: =ROUND(W42/$C$40,3) -> 0.055 | J42: =ROUND(X42/$C$40,3) -> 0.109 | ... N42: =ROUND(AB42/$C$40,3) -> 0.345 | Q42: 6 | R42: 30 | S42: 5 | T42: 24 | U42: 10 | V42: 14 | W42: 6 | X42: 12 | Y42: 7 | Z42: 9 | AA42: 15 | AB42: 38
B62: N | C62: 110 | P62: 110 | Q62: 1200
B63: 生活のしづらさを感じること | C63: 無回答 | D63: 特にない | E63: その他 | F63: 権利擁護や金銭管理に関すること | G63: 障がいへの理解・外出コミュニケーション | H63: 社会参加や仕事・訓練に関すること | I63: 学校生活や教育・保育に関すること | J63: 児童期の療育・教育に関すること | K63: 医療やリハビリに関すること | L63: 福祉サービスに関すること | M63: 日常生活に関すること | O63: 生活のしづらさを感じること | P63: 無回答 | Q63: 特にない | R63: その他 | S63: 権利擁護や金銭管理に関すること | T63: 障がいへの理解・外出コミュニケーション | U63: 社会参加や仕事・訓練に関すること | V63: 学校生活や教育・保育に関すること | W63: 児童期の療育・教育に関すること | X63: 医療やリハビリに関すること | Y63: 福祉サービスに関すること | Z63: 日常生活に関すること
C64: =ROUND(P64/$C$62,3) -> 0.045 | D64: =ROUND(Q64/$C$62,3) -> 0.255 | E64: =ROUND(R64/$C$62,3) -> 0.036 | F64: =ROUND(S64/$C$62,3) -> 0.073 | G64: =ROUND(T64/$C$62,3) -> 0.109 | H64: =ROUND(U64/$C$62,3) -> 0.127 | I64: =ROUND(V64/$C$62,3) -> 0.018 | J64: =ROUND(W64/$C$62,3) -> 0.018 | ... M64: =ROUND(Z64/$C$62,3) -> 0.327 | P64: 5 | Q64: 28 | R64: 4 | S64: 8 | T64: 12 | U64: 14 | V64: 2 | W64: 2 | X64: 30 | Y64: 22 | Z64: 36
B84: N | C84: =Q84 -> 110 | P84: N | Q84: =SUM(N86:V86) -> 110
B85: 現在の主な収入 | C85: 無回答 | D85: その他 | E85: 不動産収入 | F85: 家族からの援助 | G85: 生活保護 | H85: 各種手当 | I85: 年金 | J85: 障害年金 | K85: 給料・工賃 | M85: 現在の主な収入 | N85: 無回答 | O85: その他 | P85: 不動産収入 | Q85: 家族からの援助 | R85: 生活保護 | S85: 各種手当 | T85: 年金 | U85: 障害年金 | V85: 給料・工賃
C86: =ROUND(N86/$C$84,3) -> 0.045 | D86: =ROUND(O86/$C$84,3) -> 0.027 | E86: =ROUND(P86/$C$84,3) -> 0.009 | F86: =ROUND(Q86/$C$84,3) -> 0.055 | G86: =ROUND(R86/$C$84,3) -> 0.027 | H86: =ROUND(S86/$C$84,3) -> 0.036 | I86: =ROUND(T86/$C$84,3) -> 0.364 | J86: =ROUND(U86/$C$84,3) -> 0.236 | K86: =ROUND(V86/$C$84,3) -> 0.2 | N86: 5 | O86: 3 | P86: 1 | Q86: 6 | R86: 3 | S86: 4 | T86: 40 | U86: 26 | V86: 22
B99: N | C99: =Q99 -> 110 | P99: N | Q99: =SUM(N101:P101) -> 110
B100: 障がいがあることで差別や嫌な思いをする（した）こと | C100: 無回答 | D100: ない | E100: ある | M100: 障がいがあることで差別や嫌な思いをする（した）こと | N100: 無回答 | O100: 知らない | P100: 知っている
C101: =ROUND(N101/$C$99,3) -> 0.045 | D101: =ROUND(O101/$C$99,3) -> 0.7 | E101: =ROUND(P101/$C$99,3) -> 0.255 | N101: 5 | O101: 77 | P101: 28
B116: N | C116: =Q116 -> 110 | P116: N | Q116: =SUM(N118:P118) -> 110
B117: 成年後見制度の認知度 | C117: 無回答 | D117: 知らない | E117: 知っている | M117: 成年後見制度の認知度 | N117: 無回答 | O117: 知らない | P117: 知っている
C118: =ROUND(N118/$C$116,3) -> 0.055 | D118: =ROUND(O118/$C$116,3) -> 0.527 | E118: =ROUND(P118/$C$116,3) -> 0.418 | N118: 6 | O118: 58 | P118: 46
B132: N | C132: 110 | P132: 110 | Q132: 1200
B133: 福祉サービス等を相談しやすい体制にするために、必要なこと | C133: 無回答 | D133: その他 | E133: 専門的・継続的に相談対応できる人が配属されていること | F133: 1か所で要件を済ますことのできる総合的な窓口があること | G133: 平日の昼間以外も相談できること（休日や夜間の対応） | H133: 電話、ファックス、メールなどを使って相談できること | I133: 地域の身近なところで直接話をして相談できること | O133: 福祉サービス等を相談しやすい体制にするために、必要なこと | P133: 無回答 | Q133: その他 | R133: 専門的・継続的に相談対応できる人が配属されていること | S133: 1か所で要件を済ますことのできる総合的な窓口があること | T133: 平日の昼間以外も相談できること（休日や夜間の対応） | U133: 電話、ファックス、メールなどを使って相談できること | V133: 地域の身近なところで直接話をして相談できること
