Workbook

Sheet 設定
B2: 六戸町 農業集落排水事業 使用料改定シミュレーション
B4: ▼ 黄色セルを変更すると「財政計画（ベース）」「パターン別比較」が自動連動します
B6: ① 人口推計 | C6: 人口ビジョン
B8: ② 料金パターン | C8: パターン①（標準型）
B10: ③ 改定年数 | C10: 2か年
B13: 【連動先】
B14: ・「財政計画（ベース）」の使用料収入(A7) → 設定に応じた収入を自動反映
B15: ・「パターン別比較」の経常収支比率・経費回収率 → 人口推計の切替に連動
B16: ・各パターンシート（農集案①〜④）は元データのまま参照用として保持

Sheet 使用料マスタ
A1: 使用料収入マスタ（千円） ※設定シートから自動参照
A3: 人口推計 | B3: パターン | C3: 改定年数 | D3: 令和7年度 | E3: 令和8年度 | F3: 令和9年度 | G3: 令和10年度 | H3: 令和11年度 | I3: 令和12年度 | J3: 令和13年度 | K3: 令和14年度 | L3: 令和15年度 | M3: 令和16年度
A4: 人口ビジョン | B4: パターン①（標準型） | C4: 2か年 | D4: 14942 | E4: 17076 | F4: 19438 | G4: 19296 | H4: 19174 | I4: 19031 | J4: 18889 | K4: 18755 | L4: 18613 | M4: 18470
A5: 人口ビジョン | B5: パターン①（標準型） | C5: 3か年 | D5: 14942 | E5: 16285 | F5: 17626 | G5: 19296 | H5: 19174 | I5: 19031 | J5: 18889 | K5: 18755 | L5: 18613 | M5: 18470
A6: 人口ビジョン | B6: パターン②（家庭軽減型） | C6: 2か年 | D6: 14942 | E6: 18002 | F6: 21278 | G6: 21123 | H6: 20989 | I6: 20834 | J6: 20679 | K6: 20530 | L6: 20375 | M6: 20220
A7: 人口ビジョン | B7: パターン②（家庭軽減型） | C7: 3か年 | D7: 14942 | E7: 16903 | F7: 18853 | G7: 21123 | H7: 20989 | I7: 20834 | J7: 20679 | K7: 20530 | L7: 20375 | M7: 20220
A8: 人口ビジョン | B8: パターン④（段階累進型） | C8: 2か年 | D8: 14942 | E8: 17385 | F8: 20052 | G8: 19905 | H8: 19779 | I8: 19632 | J8: 19486 | K8: 19347 | L8: 19200 | M8: 19054
A9: 人口ビジョン | B9: パターン④（段階累進型） | C9: 3か年 | D9: 14942 | E9: 16346 | F9: 17747 | G9: 19905 | H9: 19779 | I9: 19632 | J9: 19486 | K9: 19347 | L9: 19200 | M9: 19054
A10: 社人研 | B10: パターン①（標準型） | C10: 2か年 | D10: 14976 | E10: 17104 | F10: 19471 | G10: 19316 | H10: 19186 | I10: 19052 | J10: 18877 | K10: 18734 | L10: 18580 | M10: 18414
A11: 社人研 | B11: パターン①（標準型） | C11: 3か年 | D11: 14976 | E11: 16312 | F11: 17656 | G11: 19316 | H11: 19186 | I11: 19052 | J11: 18877 | K11: 18734 | L11: 18580 | M11: 18414
A12: 社人研 | B12: パターン②（家庭軽減型） | C12: 2か年 | D12: 14976 | E12: 18032 | F12: 21314 | G12: 21144 | H12: 21003 | I12: 20855 | J12: 20664 | K12: 20509 | L12: 20340 | M12: 20156
A13: 社人研 | B13: パターン②（家庭軽減型） | C13: 3か年 | D13: 14976 | E13: 16931 | F13: 18884 | G13: 21144 | H13: 21003 | I13: 20855 | J13: 20664 | K13: 20509 | L13: 20340 | M13: 20156
A14: 社人研 | B14: パターン④（段階累進型） | C14: 2か年 | D14: 14976 | E14: 17414 | F14: 20085 | G14: 19926 | H14: 19792 | I14: 19653 | J14: 19473 | K14: 19326 | L14: 19166 | M14: 18995
A15: 社人研 | B15: パターン④（段階累進型） | C15: 3か年 | D15: 14976 | E15: 16373 | F15: 17777 | G15: 19926 | H15: 19792 | I15: 19653 | J15: 19473 | K15: 19326 | L15: 19166 | M15: 18995
A17: 現行収入（改定なし）
A18: 人口ビジョン | B18: 現行 | D18: 14942 | E18: 14834 | F18: 14742 | G18: 14634 | H18: 14541 | I18: 14433 | J18: 14326 | K18: 14223 | L18: 14116 | M18: 14008
A19: 社人研 | B19: 現行 | D19: 14976 | E19: 14859 | F19: 14766 | G19: 14649 | H19: 14550 | I19: 14449 | J19: 14316 | K19: 14208 | L19: 14091 | M19: 13964
A21: 有収水量（㎥）
A22: 人口ビジョン | D22: 94131 | E22: 93463 | F22: 92868 | G22: 92200 | H22: 91605 | I22: 90937 | J22: 90268 | K22: 89600 | L22: 88931 | M22: 88262
A23: 社人研 | D23: 94354 | E23: 93611 | F23: 93017 | G23: 92274 | H23: 91680 | I23: 91011 | J23: 90194 | K23: 89525 | L23: 88782 | M23: 87965

Sheet 料金テーブル
A1: 料金テーブル（税抜き・円） ※黄色セル編集可
A2: 単価を変更すると「使用料算定」→「財政計画（ベース）」に自動反映されます
A4: 水量区分 | B4: 現行 | C4: パターン① （標準型） | D4: パターン② （家庭軽減型） | E4: パターン④ （段階累進型）
A5: 基本(0〜10㎥) | B5: 1000 | C5: 1500 | D5: 1200 | E5: 1400
A6: 11〜20㎥ | B6: 120 | C6: 150 | D6: 180 | E6: 160
A7: 21〜30㎥ | B7: 120 | C7: 155 | D7: 185 | E7: 165
A8: 31〜40㎥ | B8: 130 | C8: 160 | D8: 190 | E8: 170
A9: 41〜50㎥ | B9: 130 | C9: 165 | D9: 195 | E9: 175
A10: 51〜70㎥ | B10: 140 | C10: 175 | D10: 205 | E10: 185
A11: 71〜100㎥ | B11: 140 | C11: 185 | D11: 215 | E11: 195
A12: 101〜150㎥ | B12: 140 | C12: 205 | D12: 235 | E12: 215
A13: 151㎥〜 | B13: 160 | C13: 225 | D13: 255 | E13: 235

Sheet 使用料算定
A1: 使用料収入算定（区分別積み上げ）
A2: =設定!C8&" "&設定!C10&"改定 （"&設定!C6&"推移）" -> パターン①（標準型） 2か年改定 （人口ビジョン推移）
A4: ■ 年度別適用単価（円）
A5: 水量区分 | B5: 令和7年度 | C5: 令和8年度 | D5: 令和9年度 | E5: 令和10年度 | F5: 令和11年度 | G5: 令和12年度 | H5: 令和13年度 | I5: 令和14年度 | J5: 令和15年度 | K5: 令和16年度
A6: 基本(0〜10㎥) | B6: =料金テーブル!$B$5 -> 1000 | C6: =IF(設定!$C$10="2か年",ROUND((料金テーブル!$B$5+IF(設定!$C$8="パターン①（標準型）",料金テーブル!$C$5,IF(設定!$C$8="パターン②（家庭軽減型）",料金テーブル!$D$5,料金テーブル!$E$5)))/2,0),IF(設定!$C$8="パターン①（標準型）",'段階単価(3か年)'!$B$6,IF(設定!$C$8="パターン②（家庭軽減型）",'段階単価(3か年)'!$B$18,'段階単価(3か年)'!$B$30))) -> 1250 | D6: =IF(設定!$C$10="2か年",IF(設定!$C$8="パターン①（標準型）",料金テーブル!$C$5,IF(設定!$C$8="パターン②（家庭軽減型）",料金テーブル!$D$5,料金テーブル!$E$5)),IF(設定!$C$8="パターン①（標準型）",'段階単価(3か年)'!$C$6,IF(設定!$C$8="パターン②（家庭軽減型）",'段階単価(3か年)'!$C$18,'段階単価(3か年)'!$C$30))) -> 1500 | E6: =IF(設定!$C$8="パターン①（標準型）",料金テーブル!$C$5,IF(設定!$C$8="パターン②（家庭軽減型）",料金テーブル!$D$5,料金テーブル!$E$5)) -> 1500 | F6: =IF(設定!$C$8="パターン①（標準型）",料金テーブル!$C$5,IF(設定!$C$8="パターン②（家庭軽減型）",料金テーブル!$D$5,料金テーブル!$E$5)) -> 1500 | G6: =IF(設定!$C$8="パターン①（標準型）",料金テーブル!$C$5,IF(設定!$C$8="パターン②（家庭軽減型）",料金テーブル!$D$5,料金テーブル!$E$5)) -> 1500 | H6: =IF(設定!$C$8="パターン①（標準型）",料金テーブル!$C$5,IF(設定!$C$8="パターン②（家庭軽減型）",料金テーブル!$D$5,料金テーブル!$E$5)) -> 1500 | I6: =IF(設定!$C$8="パターン①（標準型）",料金テーブル!$C$5,IF(設定!$C$8="パターン②（家庭軽減型）",料金テーブル!$D$5,料金テーブル!$E$5)) -> 1500 | J6: =IF(設定!$C$8="パターン①（標準型）",料金テーブル!$C$5,IF(設定!$C$8="パターン②（家庭軽減型）",料金テーブル!$D$5,料金テーブル!$E$5)) -> 1500 | K6: =IF(設定!$C$8="パターン①（標準型）",料金テーブル!$C$5,IF(設定!$C$8="パターン②（家庭軽減型）",料金テーブル!$D$5,料金テーブル!$E$5)) -> 1500
A7: 11〜20㎥ | B7: =料金テーブル!$B$6 -> 120 | C7: =IF(設定!$C$10="2か年",ROUND((料金テーブル!$B$6+IF(設定!$C$8="パターン①（標準型）",料金テーブル!$C$6,IF(設定!$C$8="パターン②（家庭軽減型）",料金テーブル!$D$6,料金テーブル!$E$6)))/2,0),IF(設定!$C$8="パターン①（標準型）",'段階単価(3か年)'!$B$7,IF(設定!$C$8="パターン②（家庭軽減型）",'段階単価(3か年)'!$B$19,'段階単価(3か年)'!$B$31))) -> 135 | D7: =IF(設定!$C$10="2か年",IF(設定!$C$8="パターン①（標準型）",料金テーブル!$C$6,IF(設定!$C$8="パターン②（家庭軽減型）",料金テーブル!$D$6,料金テーブル!$E$6)),IF(設定!$C$8="パターン①（標準型）",'段階単価(3か年)'!$C$7,IF(設定!$C$8="パターン②（家庭軽減型）",'段階単価(3か年)'!$C$19,'段階単価(3か年)'!$C$31))) -> 150 | E7: =IF(設定!$C$8="パターン①（標準型）",料金テーブル!$C$6,IF(設定!$C$8="パターン②（家庭軽減型）",料金テーブル!$D$6,料金テーブル!$E$6)) -> 150 | F7: =IF(設定!$C$8="パターン①（標準型）",料金テーブル!$C$6,IF(設定!$C$8="パターン②（家庭軽減型）",料金テーブル!$D$6,料金テーブル!$E$6)) -> 150 | G7: =IF(設定!$C$8="パターン①（標準型）",料金テーブル!$C$6,IF(設定!$C$8="パターン②（家庭軽減型）",料金テーブル!$D$6,料金テーブル!$E$6)) -> 150 | H7: =IF(設定!$C$8="パターン①（標準型）",料金テーブル!$C$6,IF(設定!$C$8="パターン②（家庭軽減型）",料金テーブル!$D$6,料金テーブル!$E$6)) -> 150 | I7: =IF(設定!$C$8="パターン①（標準型）",料金テーブル!$C$6,IF(設定!$C$8="パターン②（家庭軽減型）",料金テーブル!$D$6,料金テーブル!$E$6)) -> 150 | J7: =IF(設定!$C$8="パターン①（標準型）",料金テーブル!$C$6,IF(設定!$C$8="パターン②（家庭軽減型）",料金テーブル!$D$6,料金テーブル!$E$6)) -> 150 | K7: =IF(設定!$C$8="パターン①（標準型）",料金テーブル!$C$6,IF(設定!$C$8="パターン②（家庭軽減型）",料金テーブル!$D$6,料金テーブル!$E$6)) -> 150
A8: 21〜30㎥ | B8: =料金テーブル!$B$7 -> 120 | C8: =IF(設定!$C$10="2か年",ROUND((料金テーブル!$B$7+IF(設定!$C$8="パターン①（標準型）",料金テーブル!$C$7,IF(設定!$C$8="パターン②（家庭軽減型）",料金テーブル!$D$7,料金テーブル!$E$7)))/2,0),IF(設定!$C$8="パターン①（標準型）",'段階単価(3か年)'!$B$8,IF(設定!$C$8="パターン②（家庭軽減型）",'段階単価(3か年)'!$B$20,'段階単価(3か年)'!$B$32))) -> 138 | D8: =IF(設定!$C$10="2か年",IF(設定!$C$8="パターン①（標準型）",料金テーブル!$C$7,IF(設定!$C$8="パターン②（家庭軽減型）",料金テーブル!$D$7,料金テーブル!$E$7)),IF(設定!$C$8="パターン①（標準型）",'段階単価(3か年)'!$C$8,IF(設定!$C$8="パターン②（家庭軽減型）",'段階単価(3か年)'!$C$20,'段階単価(3か年)'!$C$32))) -> 155 | E8: =IF(設定!$C$8="パターン①（標準型）",料金テーブル!$C$7,IF(設定!$C$8="パターン②（家庭軽減型）",料金テーブル!$D$7,料金テーブル!$E$7)) -> 155 | F8: =IF(設定!$C$8="パターン①（標準型）",料金テーブル!$C$7,IF(設定!$C$8="パターン②（家庭軽減型）",料金テーブル!$D$7,料金テーブル!$E$7)) -> 155 | G8: =IF(設定!$C$8="パターン①（標準型）",料金テーブル!$C$7,IF(設定!$C$8="パターン②（家庭軽減型）",料金テーブル!$D$7,料金テーブル!$E$7)) -> 155 | H8: =IF(設定!$C$8="パターン①（標準型）",料金テーブル!$C$7,IF(設定!$C$8="パターン②（家庭軽減型）",料金テーブル!$D$7,料金テーブル!$E$7)) -> 155 | I8: =IF(設定!$C$8="パターン①（標準型）",料金テーブル!$C$7,IF(設定!$C$8="パターン②（家庭軽減型）",料金テーブル!$D$7,料金テーブル!$E$7)) -> 155 | J8: =IF(設定!$C$8="パターン①（標準型）",料金テーブル!$C$7,IF(設定!$C$8="パターン②（家庭軽減型）",料金テーブル!$D$7,料金テーブル!$E$7)) -> 155 | K8: =IF(設定!$C$8="パターン①（標準型）",料金テーブル!$C$7,IF(設定!$C$8="パターン②（家庭軽減型）",料金テーブル!$D$7,料金テーブル!$E$7)) -> 155
A9: 31〜40㎥ | B9: =料金テーブル!$B$8 -> 130 | C9: =IF(設定!$C$10="2か年",ROUND((料金テーブル!$B$8+IF(設定!$C$8="パターン①（標準型）",料金テーブル!$C$8,IF(設定!$C$8="パターン②（家庭軽減型）",料金テーブル!$D$8,料金テーブル!$E$8)))/2,0),IF(設定!$C$8="パターン①（標準型）",'段階単価(3か年)'!$B$9,IF(設定!$C$8="パターン②（家庭軽減型）",'段階単価(3か年)'!$B$21,'段階単価(3か年)'!$B$33))) -> 145 | D9: =IF(設定!$C$10="2か年",IF(設定!$C$8="パターン①（標準型）",料金テーブル!$C$8,IF(設定!$C$8="パターン②（家庭軽減型）",料金テーブル!$D$8,料金テーブル!$E$8)),IF(設定!$C$8="パターン①（標準型）",'段階単価(3か年)'!$C$9,IF(設定!$C$8="パターン②（家庭軽減型）",'段階単価(3か年)'!$C$21,'段階単価(3か年)'!$C$33))) -> 160 | E9: =IF(設定!$C$8="パターン①（標準型）",料金テーブル!$C$8,IF(設定!$C$8="パターン②（家庭軽減型）",料金テーブル!$D$8,料金テーブル!$E$8)) -> 160 | F9: =IF(設定!$C$8="パターン①（標準型）",料金テーブル!$C$8,IF(設定!$C$8="パターン②（家庭軽減型）",料金テーブル!$D$8,料金テーブル!$E$8)) -> 160 | G9: =IF(設定!$C$8="パターン①（標準型）",料金テーブル!$C$8,IF(設定!$C$8="パターン②（家庭軽減型）",料金テーブル!$D$8,料金テーブル!$E$8)) -> 160 | H9: =IF(設定!$C$8="パターン①（標準型）",料金テーブル!$C$8,IF(設定!$C$8="パターン②（家庭軽減型）",料金テーブル!$D$8,料金テーブル!$E$8)) -> 160 | I9: =IF(設定!$C$8="パターン①（標準型）",料金テーブル!$C$8,IF(設定!$C$8="パターン②（家庭軽減型）",料金テーブル!$D$8,料金テーブル!$E$8)) -> 160 | J9: =IF(設定!$C$8="パターン①（標準型）",料金テーブル!$C$8,IF(設定!$C$8="パターン②（家庭軽減型）",料金テーブル!$D$8,料金テーブル!$E$8)) -> 160 | K9: =IF(設定!$C$8="パターン①（標準型）",料金テーブル!$C$8,IF(設定!$C$8="パターン②（家庭軽減型）",料金テーブル!$D$8,料金テーブル!$E$8)) -> 160
A10: 41〜50㎥ | B10: =料金テーブル!$B$9 -> 130 | C10: =IF(設定!$C$10="2か年",ROUND((料金テーブル!$B$9+IF(設定!$C$8="パターン①（標準型）",料金テーブル!$C$9,IF(設定!$C$8="パターン②（家庭軽減型）",料金テーブル!$D$9,料金テーブル!$E$9)))/2,0),IF(設定!$C$8="パターン①（標準型）",'段階単価(3か年)'!$B$10,IF(設定!$C$8="パターン②（家庭軽減型）",'段階単価(3か年)'!$B$22,'段階単価(3か年)'!$B$34))) -> 148 | D10: =IF(設定!$C$10="2か年",IF(設定!$C$8="パターン①（標準型）",料金テーブル!$C$9,IF(設定!$C$8="パターン②（家庭軽減型）",料金テーブル!$D$9,料金テーブル!$E$9)),IF(設定!$C$8="パターン①（標準型）",'段階単価(3か年)'!$C$10,IF(設定!$C$8="パターン②（家庭軽減型）",'段階単価(3か年)'!$C$22,'段階単価(3か年)'!$C$34))) -> 165 | E10: =IF(設定!$C$8="パターン①（標準型）",料金テーブル!$C$9,IF(設定!$C$8="パターン②（家庭軽減型）",料金テーブル!$D$9,料金テーブル!$E$9)) -> 165 | F10: =IF(設定!$C$8="パターン①（標準型）",料金テーブル!$C$9,IF(設定!$C$8="パターン②（家庭軽減型）",料金テーブル!$D$9,料金テーブル!$E$9)) -> 165 | G10: =IF(設定!$C$8="パターン①（標準型）",料金テーブル!$C$9,IF(設定!$C$8="パターン②（家庭軽減型）",料金テーブル!$D$9,料金テーブル!$E$9)) -> 165 | H10: =IF(設定!$C$8="パターン①（標準型）",料金テーブル!$C$9,IF(設定!$C$8="パターン②（家庭軽減型）",料金テーブル!$D$9,料金テーブル!$E$9)) -> 165 | I10: =IF(設定!$C$8="パターン①（標準型）",料金テーブル!$C$9,IF(設定!$C$8="パターン②（家庭軽減型）",料金テーブル!$D$9,料金テーブル!$E$9)) -> 165 | J10: =IF(設定!$C$8="パターン①（標準型）",料金テーブル!$C$9,IF(設定!$C$8="パターン②（家庭軽減型）",料金テーブル!$D$9,料金テーブル!$E$9)) -> 165 | K10: =IF(設定!$C$8="パターン①（標準型）",料金テーブル!$C$9,IF(設定!$C$8="パターン②（家庭軽減型）",料金テーブル!$D$9,料金テーブル!$E$9)) -> 165
A11: 51〜70㎥ | B11: =料金テーブル!$B$10 -> 140 | C11: =IF(設定!$C$10="2か年",ROUND((料金テーブル!$B$10+IF(設定!$C$8="パターン①（標準型）",料金テーブル!$C$10,IF(設定!$C$8="パターン②（家庭軽減型）",料金テーブル!$D$10,料金テーブル!$E$10)))/2,0),IF(設定!$C$8="パターン①（標準型）",'段階単価(3か年)'!$B$11,IF(設定!$C$8="パターン②（家庭軽減型）",'段階単価(3か年)'!$B$23,'段階単価(3か年)'!$B$35))) -> 158 | D11: =IF(設定!$C$10="2か年",IF(設定!$C$8="パターン①（標準型）",料金テーブル!$C$10,IF(設定!$C$8="パターン②（家庭軽減型）",料金テーブル!$D$10,料金テーブル!$E$10)),IF(設定!$C$8="パターン①（標準型）",'段階単価(3か年)'!$C$11,IF(設定!$C$8="パターン②（家庭軽減型）",'段階単価(3か年)'!$C$23,'段階単価(3か年)'!$C$35))) -> 175 | E11: =IF(設定!$C$8="パターン①（標準型）",料金テーブル!$C$10,IF(設定!$C$8="パターン②（家庭軽減型）",料金テーブル!$D$10,料金テーブル!$E$10)) -> 175 | F11: =IF(設定!$C$8="パターン①（標準型）",料金テーブル!$C$10,IF(設定!$C$8="パターン②（家庭軽減型）",料金テーブル!$D$10,料金テーブル!$E$10)) -> 175 | G11: =IF(設定!$C$8="パターン①（標準型）",料金テーブル!$C$10,IF(設定!$C$8="パターン②（家庭軽減型）",料金テーブル!$D$10,料金テーブル!$E$10)) -> 175 | H11: =IF(設定!$C$8="パターン①（標準型）",料金テーブル!$C$10,IF(設定!$C$8="パターン②（家庭軽減型）",料金テーブル!$D$10,料金テーブル!$E$10)) -> 175 | I11: =IF(設定!$C$8="パターン①（標準型）",料金テーブル!$C$10,IF(設定!$C$8="パターン②（家庭軽減型）",料金テーブル!$D$10,料金テーブル!$E$10)) -> 175 | J11: =IF(設定!$C$8="パターン①（標準型）",料金テーブル!$C$10,IF(設定!$C$8="パターン②（家庭軽減型）",料金テーブル!$D$10,料金テーブル!$E$10)) -> 175 | K11: =IF(設定!$C$8="パターン①（標準型）",料金テーブル!$C$10,IF(設定!$C$8="パターン②（家庭軽減型）",料金テーブル!$D$10,料金テーブル!$E$10)) -> 175
A12: 71〜100㎥ | B12: =料金テーブル!$B$11 -> 140 | C12: =IF(設定!$C$10="2か年",ROUND((料金テーブル!$B$11+IF(設定!$C$8="パターン①（標準型）",料金テーブル!$C$11,IF(設定!$C$8="パターン②（家庭軽減型）",料金テーブル!$D$11,料金テーブル!$E$11)))/2,0),IF(設定!$C$8="パターン①（標準型）",'段階単価(3か年)'!$B$12,IF(設定!$C$8="パターン②（家庭軽減型）",'段階単価(3か年)'!$B$24,'段階単価(3か年)'!$B$36))) -> 163 | D12: =IF(設定!$C$10="2か年",IF(設定!$C$8="パターン①（標準型）",料金テーブル!$C$11,IF(設定!$C$8="パターン②（家庭軽減型）",料金テーブル!$D$11,料金テーブル!$E$11)),IF(設定!$C$8="パターン①（標準型）",'段階単価(3か年)'!$C$12,IF(設定!$C$8="パターン②（家庭軽減型）",'段階単価(3か年)'!$C$24,'段階単価(3か年)'!$C$36))) -> 185 | E12: =IF(設定!$C$8="パターン①（標準型）",料金テーブル!$C$11,IF(設定!$C$8="パターン②（家庭軽減型）",料金テーブル!$D$11,料金テーブル!$E$11)) -> 185 | F12: =IF(設定!$C$8="パターン①（標準型）",料金テーブル!$C$11,IF(設定!$C$8="パターン②（家庭軽減型）",料金テーブル!$D$11,料金テーブル!$E$11)) -> 185 | G12: =IF(設定!$C$8="パターン①（標準型）",料金テーブル!$C$11,IF(設定!$C$8="パターン②（家庭軽減型）",料金テーブル!$D$11,料金テーブル!$E$11)) -> 185 | H12: =IF(設定!$C$8="パターン①（標準型）",料金テーブル!$C$11,IF(設定!$C$8="パターン②（家庭軽減型）",料金テーブル!$D$11,料金テーブル!$E$11)) -> 185 | I12: =IF(設定!$C$8="パターン①（標準型）",料金テーブル!$C$11,IF(設定!$C$8="パターン②（家庭軽減型）",料金テーブル!$D$11,料金テーブル!$E$11)) -> 185 | J12: =IF(設定!$C$8="パターン①（標準型）",料金テーブル!$C$11,IF(設定!$C$8="パターン②（家庭軽減型）",料金テーブル!$D$11,料金テーブル!$E$11)) -> 185 | K12: =IF(設定!$C$8="パターン①（標準型）",料金テーブル!$C$11,IF(設定!$C$8="パターン②（家庭軽減型）",料金テーブル!$D$11,料金テーブル!$E$11)) -> 185
A13: 101〜150㎥ | B13: =料金テーブル!$B$12 -> 140 | C13: =IF(設定!$C$10="2か年",ROUND((料金テーブル!$B$12+IF(設定!$C$8="パターン①（標準型）",料金テーブル!$C$12,IF(設定!$C$8="パターン②（家庭軽減型）",料金テーブル!$D$12,料金テーブル!$E$12)))/2,0),IF(設定!$C$8="パターン①（標準型）",'段階単価(3か年)'!$B$13,IF(設定!$C$8="パターン②（家庭軽減型）",'段階単価(3か年)'!$B$25,'段階単価(3か年)'!$B$37))) -> 173 | D13: =IF(設定!$C$10="2か年",IF(設定!$C$8="パターン①（標準型）",料金テーブル!$C$12,IF(設定!$C$8="パターン②（家庭軽減型）",料金テーブル!$D$12,料金テーブル!$E$12)),IF(設定!$C$8="パターン①（標準型）",'段階単価(3か年)'!$C$13,IF(設定!$C$8="パターン②（家庭軽減型）",'段階単価(3か年)'!$C$25,'段階単価(3か年)'!$C$37))) -> 205 | E13: =IF(設定!$C$8="パターン①（標準型）",料金テーブル!$C$12,IF(設定!$C$8="パターン②（家庭軽減型）",料金テーブル!$D$12,料金テーブル!$E$12)) -> 205 | F13: =IF(設定!$C$8="パターン①（標準型）",料金テーブル!$C$12,IF(設定!$C$8="パターン②（家庭軽減型）",料金テーブル!$D$12,料金テーブル!$E$12)) -> 205 | G13: =IF(設定!$C$8="パターン①（標準型）",料金テーブル!$C$12,IF(設定!$C$8="パターン②（家庭軽減型）",料金テーブル!$D$12,料金テーブル!$E$12)) -> 205 | H13: =IF(設定!$C$8="パターン①（標準型）",料金テーブル!$C$12,IF(設定!$C$8="パターン②（家庭軽減型）",料金テーブル!$D$12,料金テーブル!$E$12)) -> 205 | I13: =IF(設定!$C$8="パターン①（標準型）",料金テーブル!$C$12,IF(設定!$C$8="パターン②（家庭軽減型）",料金テーブル!$D$12,料金テーブル!$E$12)) -> 205 | J13: =IF(設定!$C$8="パターン①（標準型）",料金テーブル!$C$12,IF(設定!$C$8="パターン②（家庭軽減型）",料金テーブル!$D$12,料金テーブル!$E$12)) -> 205 | K13: =IF(設定!$C$8="パターン①（標準型）",料金テーブル!$C$12,IF(設定!$C$8="パターン②（家庭軽減型）",料金テーブル!$D$12,料金テーブル!$E$12)) -> 205
A14: 151㎥〜 | B14: =料金テーブル!$B$13 -> 160 | C14: =IF(設定!$C$10="2か年",ROUND((料金テーブル!$B$13+IF(設定!$C$8="パターン①（標準型）",料金テーブル!$C$13,IF(設定!$C$8="パターン②（家庭軽減型）",料金テーブル!$D$13,料金テーブル!$E$13)))/2,0),IF(設定!$C$8="パターン①（標準型）",'段階単価(3か年)'!$B$14,IF(設定!$C$8="パターン②（家庭軽減型）",'段階単価(3か年)'!$B$26,'段階単価(3か年)'!$B$38))) -> 193 | D14: =IF(設定!$C$10="2か年",IF(設定!$C$8="パターン①（標準型）",料金テーブル!$C$13,IF(設定!$C$8="パターン②（家庭軽減型）",料金テーブル!$D$13,料金テーブル!$E$13)),IF(設定!$C$8="パターン①（標準型）",'段階単価(3か年)'!$C$14,IF(設定!$C$8="パターン②（家庭軽減型）",'段階単価(3か年)'!$C$26,'段階単価(3か年)'!$C$38))) -> 225 | E14: =IF(設定!$C$8="パターン①（標準型）",料金テーブル!$C$13,IF(設定!$C$8="パターン②（家庭軽減型）",料金テーブル!$D$13,料金テーブル!$E$13)) -> 225 | F14: =IF(設定!$C$8="パターン①（標準型）",料金テーブル!$C$13,IF(設定!$C$8="パターン②（家庭軽減型）",料金テーブル!$D$13,料金テーブル!$E$13)) -> 225 | G14: =IF(設定!$C$8="パターン①（標準型）",料金テーブル!$C$13,IF(設定!$C$8="パターン②（家庭軽減型）",料金テーブル!$D$13,料金テーブル!$E$13)) -> 225 | H14: =IF(設定!$C$8="パターン①（標準型）",料金テーブル!$C$13,IF(設定!$C$8="パターン②（家庭軽減型）",料金テーブル!$D$13,料金テーブル!$E$13)) -> 225 | I14: =IF(設定!$C$8="パターン①（標準型）",料金テーブル!$C$13,IF(設定!$C$8="パターン②（家庭軽減型）",料金テーブル!$D$13,料金テーブル!$E$13)) -> 225 | J14: =IF(設定!$C$8="パターン①（標準型）",料金テーブル!$C$13,IF(設定!$C$8="パターン②（家庭軽減型）",料金テーブル!$D$13,料金テーブル!$E$13)) -> 225 | K14: =IF(設定!$C$8="パターン①（標準型）",料金テーブル!$C$13,IF(設定!$C$8="パターン②（家庭軽減型）",料金テーブル!$D$13,料金テーブル!$E$13)) -> 225
A16: ■ 調定口数・有収水量推計
A17: 調定口数（口） | B17: =IF(設定!$C$6="人口ビジョン",523,524) -> 523 | C17: =IF(設定!$C$6="人口ビジョン",519,520) -> 519 | D17: =IF(設定!$C$6="人口ビジョン",516,517) -> 516 | E17: =IF(設定!$C$6="人口ビジョン",512,513) -> 512 | F17: =IF(設定!$C$6="人口ビジョン",509,509) -> 509 | G17: =IF(設定!$C$6="人口ビジョン",505,506) -> 505 | H17: =IF(設定!$C$6="人口ビジョン",501,501) -> 501 | I17: =IF(設定!$C$6="人口ビジョン",498,497) -> 498 | J17: =IF(設定!$C$6="人口ビジョン",494,493) -> 494 | K17: =IF(設定!$C$6="人口ビジョン",490,489) -> 490
A18: 有収水量合計（㎥） | B18: =IF(設定!$C$6="人口ビジョン",94131,94354) -> 94131 | C18: =IF(設定!$C$6="人口ビジョン",93463,93611) -> 93463 | D18: =IF(設定!$C$6="人口ビジョン",92868,93017) -> 92868 | E18: =IF(設定!$C$6="人口ビジョン",92200,92274) -> 92200 | F18: =IF(設定!$C$6="人口ビジョン",91605,91680) -> 91605 | G18: =IF(設定!$C$6="人口ビジョン",90937,91011) -> 90937 | H18: =IF(設定!$C$6="人口ビジョン",90268,90194) -> 90268 | I18: =IF(設定!$C$6="人口ビジョン",89600,89525) -> 89600 | J18: =IF(設定!$C$6="人口ビジョン",88931,88782) -> 88931 | K18: =IF(設定!$C$6="人口ビジョン",88262,87965) -> 88262
A20: ■ 区分別有収水量（㎥） ※R6比率固定
A21: 基本(0〜10㎥) | B21: =ROUND(B18*0.295786,0) -> 27843 | C21: =ROUND(C18*0.295786,0) -> 27645 | D21: =ROUND(D18*0.295786,0) -> 27469 | E21: =ROUND(E18*0.295786,0) -> 27271 | F21: =ROUND(F18*0.295786,0) -> 27095 | G21: =ROUND(G18*0.295786,0) -> 26898 | H21: =ROUND(H18*0.295786,0) -> 26700 | I21: =ROUND(I18*0.295786,0) -> 26502 | ... K21: =ROUND(K18*0.295786,0) -> 26107
A22: 11〜20㎥ | B22: =ROUND(B18*0.249802,0) -> 23514 | C22: =ROUND(C18*0.249802,0) -> 23347 | D22: =ROUND(D18*0.249802,0) -> 23199 | E22: =ROUND(E18*0.249802,0) -> 23032 | F22: =ROUND(F18*0.249802,0) -> 22883 | G22: =ROUND(G18*0.249802,0) -> 22716 | H22: =ROUND(H18*0.249802,0) -> 22549 | I22: =ROUND(I18*0.249802,0) -> 22382 | ... K22: =ROUND(K18*0.249802,0) -> 22048
A23: 21〜30㎥ | B23: =ROUND(B18*0.180081,0) -> 16951 | C23: =ROUND(C18*0.180081,0) -> 16831 | D23: =ROUND(D18*0.180081,0) -> 16724 | E23: =ROUND(E18*0.180081,0) -> 16603 | F23: =ROUND(F18*0.180081,0) -> 16496 | G23: =ROUND(G18*0.180081,0) -> 16376 | H23: =ROUND(H18*0.180081,0) -> 16256 | I23: =ROUND(I18*0.180081,0) -> 16135 | ... K23: =ROUND(K18*0.180081,0) -> 15894
A24: 31〜40㎥ | B24: =ROUND(B18*0.113113,0) -> 10647 | C24: =ROUND(C18*0.113113,0) -> 10572 | D24: =ROUND(D18*0.113113,0) -> 10505 | E24: =ROUND(E18*0.113113,0) -> 10429 | F24: =ROUND(F18*0.113113,0) -> 10362 | G24: =ROUND(G18*0.113113,0) -> 10286 | H24: =ROUND(H18*0.113113,0) -> 10210 | I24: =ROUND(I18*0.113113,0) -> 10135 | ... K24: =ROUND(K18*0.113113,0) -> 9984
A25: 41〜50㎥ | B25: =ROUND(B18*0.068836,0) -> 6480 | C25: =ROUND(C18*0.068836,0) -> 6434 | D25: =ROUND(D18*0.068836,0) -> 6393 | E25: =ROUND(E18*0.068836,0) -> 6347 | F25: =ROUND(F18*0.068836,0) -> 6306 | G25: =ROUND(G18*0.068836,0) -> 6260 | H25: =ROUND(H18*0.068836,0) -> 6214 | I25: =ROUND(I18*0.068836,0) -> 6168 | ... K25: =ROUND(K18*0.068836,0) -> 6076
A26: 51〜70㎥ | B26: =ROUND(B18*0.054322,0) -> 5113 | C26: =ROUND(C18*0.054322,0) -> 5077 | D26: =ROUND(D18*0.054322,0) -> 5045 | E26: =ROUND(E18*0.054322,0) -> 5008 | F26: =ROUND(F18*0.054322,0) -> 4976 | G26: =ROUND(G18*0.054322,0) -> 4940 | H26: =ROUND(H18*0.054322,0) -> 4904 | I26: =ROUND(I18*0.054322,0) -> 4867 | ... K26: =ROUND(K18*0.054322,0) -> 4795
A27: 71〜100㎥ | B27: =ROUND(B18*0.026809,0) -> 2524 | C27: =ROUND(C18*0.026809,0) -> 2506 | D27: =ROUND(D18*0.026809,0) -> 2490 | E27: =ROUND(E18*0.026809,0) -> 2472 | F27: =ROUND(F18*0.026809,0) -> 2456 | G27: =ROUND(G18*0.026809,0) -> 2438 | H27: =ROUND(H18*0.026809,0) -> 2420 | I27: =ROUND(I18*0.026809,0) -> 2402 | ... K27: =ROUND(K18*0.026809,0) -> 2366
A28: 101〜150㎥ | B28: =ROUND(B18*0.005093,0) -> 479 | C28: =ROUND(C18*0.005093,0) -> 476 | D28: =ROUND(D18*0.005093,0) -> 473 | E28: =ROUND(E18*0.005093,0) -> 470 | F28: =ROUND(F18*0.005093,0) -> 467 | G28: =ROUND(G18*0.005093,0) -> 463 | H28: =ROUND(H18*0.005093,0) -> 460 | I28: =ROUND(I18*0.005093,0) -> 456 | ... K28: =ROUND(K18*0.005093,0) -> 450
A29: 151㎥〜 | B29: =ROUND(B18*0.003074,0) -> 289 | C29: =ROUND(C18*0.003074,0) -> 287 | D29: =ROUND(D18*0.003074,0) -> 285 | E29: =ROUND(E18*0.003074,0) -> 283 | F29: =ROUND(F18*0.003074,0) -> 282 | G29: =ROUND(G18*0.003074,0) -> 280 | H29: =ROUND(H18*0.003074,0) -> 277 | I29: =ROUND(I18*0.003074,0) -> 275 | ... K29: =ROUND(K18*0.003074,0) -> 271
A31: ■ 使用料収入算定（千円）
A32: 基本使用料収入 | B32: =ROUND(B6*B17*12/1000,1) -> 6276 | C32: =ROUND(C6*C17*12/1000,1) -> 7785 | D32: =ROUND(D6*D17*12/1000,1) -> 9288 | E32: =ROUND(E6*E17*12/1000,1) -> 9216 | F32: =ROUND(F6*F17*12/1000,1) -> 9162 | G32: =ROUND(G6*G17*12/1000,1) -> 9090 | H32: =ROUND(H6*H17*12/1000,1) -> 9018 | I32: =ROUND(I6*I17*12/1000,1) -> 8964 | ... K32: =ROUND(K6*K17*12/1000,1) -> 8820
A33: 11〜20㎥ | B33: =ROUND(B7*B22/1000,1) -> 2821.7 | C33: =ROUND(C7*C22/1000,1) -> 3151.8 | D33: =ROUND(D7*D22/1000,1) -> 3479.9 | E33: =ROUND(E7*E22/1000,1) -> 3454.8 | F33: =ROUND(F7*F22/1000,1) -> 3432.5 | G33: =ROUND(G7*G22/1000,1) -> 3407.4 | H33: =ROUND(H7*H22/1000,1) -> 3382.4 | I33: =ROUND(I7*I22/1000,1) -> 3357.3 | ... K33: =ROUND(K7*K22/1000,1) -> 3307.2
A34: 21〜30㎥ | B34: =ROUND(B8*B23/1000,1) -> 2034.1 | C34: =ROUND(C8*C23/1000,1) -> 2322.7 | D34: =ROUND(D8*D23/1000,1) -> 2592.2 | E34: =ROUND(E8*E23/1000,1) -> 2573.5 | F34: =ROUND(F8*F23/1000,1) -> 2556.9 | G34: =ROUND(G8*G23/1000,1) -> 2538.3 | H34: =ROUND(H8*H23/1000,1) -> 2519.7 | I34: =ROUND(I8*I23/1000,1) -> 2500.9 | ... K34: =ROUND(K8*K23/1000,1) -> 2463.6
A35: 31〜40㎥ | B35: =ROUND(B9*B24/1000,1) -> 1384.1 | C35: =ROUND(C9*C24/1000,1) -> 1532.9 | D35: =ROUND(D9*D24/1000,1) -> 1680.8 | E35: =ROUND(E9*E24/1000,1) -> 1668.6 | F35: =ROUND(F9*F24/1000,1) -> 1657.9 | G35: =ROUND(G9*G24/1000,1) -> 1645.8 | H35: =ROUND(H9*H24/1000,1) -> 1633.6 | I35: =ROUND(I9*I24/1000,1) -> 1621.6 | ... K35: =ROUND(K9*K24/1000,1) -> 1597.4
A36: 41〜50㎥ | B36: =ROUND(B10*B25/1000,1) -> 842.4 | C36: =ROUND(C10*C25/1000,1) -> 952.2 | D36: =ROUND(D10*D25/1000,1) -> 1054.8 | E36: =ROUND(E10*E25/1000,1) -> 1047.3 | F36: =ROUND(F10*F25/1000,1) -> 1040.5 | G36: =ROUND(G10*G25/1000,1) -> 1032.9 | H36: =ROUND(H10*H25/1000,1) -> 1025.3 | I36: =ROUND(I10*I25/1000,1) -> 1017.7 | ... K36: =ROUND(K10*K25/1000,1) -> 1002.5
A37: 51〜70㎥ | B37: =ROUND(B11*B26/1000,1) -> 715.8 | C37: =ROUND(C11*C26/1000,1) -> 802.2 | D37: =ROUND(D11*D26/1000,1) -> 882.9 | E37: =ROUND(E11*E26/1000,1) -> 876.4 | F37: =ROUND(F11*F26/1000,1) -> 870.8 | G37: =ROUND(G11*G26/1000,1) -> 864.5 | H37: =ROUND(H11*H26/1000,1) -> 858.2 | I37: =ROUND(I11*I26/1000,1) -> 851.7 | ... K37: =ROUND(K11*K26/1000,1) -> 839.1
A38: 71〜100㎥ | B38: =ROUND(B12*B27/1000,1) -> 353.4 | C38: =ROUND(C12*C27/1000,1) -> 408.5 | D38: =ROUND(D12*D27/1000,1) -> 460.7 | E38: =ROUND(E12*E27/1000,1) -> 457.3 | F38: =ROUND(F12*F27/1000,1) -> 454.4 | G38: =ROUND(G12*G27/1000,1) -> 451 | H38: =ROUND(H12*H27/1000,1) -> 447.7 | I38: =ROUND(I12*I27/1000,1) -> 444.4 | ... K38: =ROUND(K12*K27/1000,1) -> 437.7
A39: 101〜150㎥ | B39: =ROUND(B13*B28/1000,1) -> 67.1 | C39: =ROUND(C13*C28/1000,1) -> 82.3 | D39: =ROUND(D13*D28/1000,1) -> 97 | E39: =ROUND(E13*E28/1000,1) -> 96.4 | F39: =ROUND(F13*F28/1000,1) -> 95.7 | G39: =ROUND(G13*G28/1000,1) -> 94.9 | H39: =ROUND(H13*H28/1000,1) -> 94.3 | I39: =ROUND(I13*I28/1000,1) -> 93.5 | ... K39: =ROUND(K13*K28/1000,1) -> 92.3
A40: 151㎥〜 | B40: =ROUND(B14*B29/1000,1) -> 46.2 | C40: =ROUND(C14*C29/1000,1) -> 55.4 | D40: =ROUND(D14*D29/1000,1) -> 64.1 | E40: =ROUND(E14*E29/1000,1) -> 63.7 | F40: =ROUND(F14*F29/1000,1) -> 63.5 | G40: =ROUND(G14*G29/1000,1) -> 63 | H40: =ROUND(H14*H29/1000,1) -> 62.3 | I40: =ROUND(I14*I29/1000,1) -> 61.9 | ... K40: =ROUND(K14*K29/1000,1) -> 61
A41: 超過使用料収入 小計 | B41: =SUM(B33:B40) -> 8264.8 | C41: =SUM(C33:C40) -> 9308 | D41: =SUM(D33:D40) -> 10312.4 | E41: =SUM(E33:E40) -> 10238 | F41: =SUM(F33:F40) -> 10172.2 | G41: =SUM(G33:G40) -> 10097.8 | H41: =SUM(H33:H40) -> 10023.5 | I41: =SUM(I33:I40) -> 9949 | ... K41: =SUM(K33:K40) -> 9800.8
A42: 使用料収入 合計（税抜き） | B42: =ROUND(B32+B41,0) -> 14541 | C42: =ROUND(C32+C41,0) -> 17093 | D42: =ROUND(D32+D41,0) -> 19600 | E42: =ROUND(E32+E41,0) -> 19454 | F42: =ROUND(F32+F41,0) -> 19334 | G42: =ROUND(G32+G41,0) -> 19188 | H42: =ROUND(H32+H41,0) -> 19042 | I42: =ROUND(I32+I41,0) -> 18913 | ... K42: =ROUND(K32+K41,0) -> 18621
A44: ■ R6実績補正
A45: R6実績 使用料収入（千円） | B45: 15802
...

Sheet 料金改定計画案
A1: 料金改定計画案・財政計画案
A3: １．料金改定計画案
A5: １－１．改定の背景と目的
A7: ・人口減少に伴い使用料収入は減収傾向であり、水洗化率の向上は厳しい見込みである。継続的な使用料改定の検討が必要である。
A8: ・物価高騰の影響から汚水処理費が増加傾向となっている。今後も労務費単価が増加することが懸念されるため、費用削減の検討が必要である。
A9: ・今回の料金改定では資産維持費は見込まないが、国の動向を踏まえ今後の検討が必要である。
A10: ・社会資本整備総合交付金の交付要件を満たすためにも、5年に1回の頻度で改定の必要性の検証を行う。
A12: ・以上を踏まえ、経費回収率の改善と事業の安定的運営を図るため、使用料改定を行うものとする。
A14: １－２．料金体系の検討結果
A16: ・総括原価を需要家費、固定費、変動費の3費目に分解し、設定した基準に基づき個別原価による料金体系の検討を行った。
A17: ・基本水量制の廃止及び基本水量の引き下げ、使用水量に応じた負担を適切に求めることができる使用料体系への移行を検討した。
A18: ・超過使用料における区分数をより細かく設定し、各使用者群に適切に負担を賦課する体系とした。
... A23: １－３．改定料金表（３パターン比較）
B25: 水量区分 | C25: 現行単価（円） | D25: パターン① （標準型） | E25: パターン② （家庭軽減型） | F25: パターン④ （段階累進型）
B26: 基本使用料 (0〜10㎥) | C26: 1,000円 | D26: 1,500円 | E26: 1,200円 | F26: 1,400円
B27: 11〜20㎥ | C27: 120円 | D27: 150円 | E27: 180円 | F27: 160円
B28: 21〜30㎥ | C28: 120円 | D28: 155円 | E28: 185円 | F28: 165円
B29: 31〜40㎥ | C29: 130円 | D29: 160円 | E29: 190円 | F29: 170円
B30: 41〜50㎥ | C30: 130円 | D30: 165円 | E30: 195円 | F30: 175円
B31: 51〜70㎥ | C31: 140円 | D31: 175円 | E31: 205円 | F31: 185円
B32: 71〜100㎥ | C32: 140円 | D32: 185円 | E32: 215円 | F32: 195円
B33: 101〜150㎥ | C33: 140円 | D33: 205円 | E33: 235円 | F33: 215円
B34: 151㎥〜 | C34: 160円 | D34: 225円 | E34: 255円 | F34: 235円
B35: 区分数 | C35: 4区分 | D35: 8区分 | E35: 8区分 | F35: 8区分
B36: 累進度 | C36: 1.33倍 | D36: 1.50倍 | E36: 1.42倍 | F36: 1.47倍
A38: １－４．改定スケジュール（激変緩和措置：２年または３年の段階的引き上げ）
A40: 【A】２か年段階改定
C41: 令和6年度 （現行） | D41: 令和7年度 （1年目） | E41: 令和8年度 （2年目・完了） | F41: 令和9年度〜
B42: 改定段階 | C42: 現行料金 | D42: 第1段階 | E42: 第2段階（完了） | F42: 改定後料金
B43: 改定率 | C43: ― | D43: 約1/2 | E43: 全額改定 | F43: ―
B44: 20㎥時例（①） | C44: 2,200円 | D44: 約2,600円 | E44: 3,000円 | F44: 3,000円
B45: 基本使用料例（①） | C45: 1,000円 | D45: 1,250円 | E45: 1,500円 | F45: 1,500円
A47: 【B】３か年段階改定
C48: 令和6年度 （現行） | D48: 令和7年度 （1年目） | E48: 令和8年度 （2年目） | F48: 令和9年度 （3年目・完了） | G48: 令和10年度〜
B49: 改定段階 | C49: 現行料金 | D49: 第1段階 | E49: 第2段階 | F49: 第3段階（完了） | G49: 改定後料金
B50: 改定率 | C50: ― | D50: 約1/3 | E50: 約2/3 | F50: 全額改定 | G50: ―
B51: 20㎥時例（①） | C51: 2,200円 | D51: 約2,470円 | E51: 約2,730円 | F51: 3,000円 | G51: 3,000円
B52: 基本使用料例（①） | C52: 1,000円 | D52: 約1,170円 | E52: 約1,330円 | F52: 1,500円 | G52: 1,500円

Sheet モデルケース別影響額
A1: １－５．モデルケース別影響額（３パターン比較）
A2: いずれのパターンも20㎥使用時に3,000円（税抜き）を達成する
A4: 使用水量 | B4: 現行料金 | C4: パターン① （標準型） | D4: 増加額 | E4: パターン② （家庭軽減型） | F4: 増加額 | G4: パターン④ （段階累進型） | H4: 増加額
A5: 10㎥ | B5: 1,000円 | C5: 1,500円 | D5: +500円 | E5: 1,200円 | F5: +200円 | G5: 1,400円 | H5: +400円
A6: 20㎥ | B6: 2,200円 | C6: 3,000円 | D6: +800円 | E6: 3,000円 | F6: +800円 | G6: 3,000円 | H6: +800円
A7: 30㎥ | B7: 3,400円 | C7: 4,550円 | D7: +1,150円 | E7: 4,850円 | F7: +1,450円 | G7: 4,650円 | H7: +1,250円
A8: 50㎥ | B8: 6,000円 | C8: 7,800円 | D8: +1,800円 | E8: 8,700円 | F8: +2,700円 | G8: 8,100円 | H8: +2,100円
A10: 特徴 | C10: バランス重視 | E10: 少量使用者へ配慮 | G10: 緩急が明確

Sheet 財政計画（ベース）
A1: ３条 収益的収支（令和7年度～令和16年度）
A2: =設定!C8&" "&設定!C10&"改定 （"&設定!C6&"推移） ※使用料収入は設定シート連動" -> パターン①（標準型） 2か年改定 （人口ビジョン推移） ※使用料収入は設定シート連動
A4: 区 分 | B4: 令和7年度 | C4: 令和8年度 | D4: 令和9年度 | E4: 令和10年度 | F4: 令和11年度 | G4: 令和12年度 | H4: 令和13年度 | I4: 令和14年度 | J4: 令和15年度 | K4: 令和16年度
A5: （単位：千円） | B5: 2025 | C5: 2026 | D5: 2027 | E5: 2028 | F5: 2029 | G5: 2030 | H5: 2031 | I5: 2032 | J5: 2033 | K5: 2034
A6: 【収入の部】
A7: 営業収益 (A) | B7: =B8+B9+B10 -> 15754 | C7: =C8+C9+C10 -> 18380 | D7: =D8+D9+D10 -> 20963 | E7: =E8+E9+E10 -> 20808 | F7: =F8+F9+F10 -> 20685 | G7: =G8+G9+G10 -> 20536 | H7: =H8+H9+H10 -> 20385 | I7: =I8+I9+I10 -> 20254 | ... K7: =K8+K9+K10 -> 19953
A8: (1) 使用料収入 | B8: =使用料算定!B49 -> 14943 | C8: =使用料算定!C49 -> 17565 | D8: =使用料算定!D49 -> 20142 | E8: =使用料算定!E49 -> 19992 | F8: =使用料算定!F49 -> 19868 | G8: =使用料算定!G49 -> 19718 | H8: =使用料算定!H49 -> 19568 | I8: =使用料算定!I49 -> 19436 | ... K8: =使用料算定!K49 -> 19136
A9: (2) 雨水処理負担金 | B9: 799 | C9: 799 | D9: 799 | E9: 799 | F9: 799 | G9: 799 | H9: 799 | I9: 799 | J9: 799 | K9: 799
A10: (3) その他 | B10: 12 | C10: 16 | D10: 22 | E10: 17 | F10: 18 | G10: 19 | H10: 18 | I10: 19 | J10: 19 | K10: 18
A11: 営業外収益 | B11: =B12+B13+B14 -> 74552 | C11: =C12+C13+C14 -> 72722 | D11: =D12+D13+D14 -> 70328 | E11: =E12+E13+E14 -> 68623 | F11: =F12+F13+F14 -> 68233 | G11: =G12+G13+G14 -> 70039 | H11: =H12+H13+H14 -> 71429 | I11: =I12+I13+I14 -> 71237 | ... K11: =K12+K13+K14 -> 71127
A12: (1) 補助金 | B12: 19236 | C12: 17406 | D12: 16252 | E12: 15096 | F12: 14864 | G12: 16067 | H12: 16944 | I12: 16879 | J12: 16885 | K12: 16871
A13: (2) 長期前受金戻入 | B13: 55286 | C13: 55286 | D13: 54046 | E13: 53497 | F13: 53339 | G13: 53942 | H13: 54455 | I13: 54328 | J13: 54265 | K13: 54226
A14: (3) その他 | B14: 30 | C14: 30 | D14: 30 | E14: 30 | F14: 30 | G14: 30 | H14: 30 | I14: 30 | J14: 30 | K14: 30
A15: 経常収入 (C) | B15: =B7+B11 -> 90306 | C15: =C7+C11 -> 91102 | D15: =D7+D11 -> 91291 | E15: =E7+E11 -> 89431 | F15: =F7+F11 -> 88918 | G15: =G7+G11 -> 90575 | H15: =H7+H11 -> 91814 | I15: =I7+I11 -> 91491 | ... K15: =K7+K11 -> 91080
A17: 【支出の部】
A18: 営業費用 | B18: =B19+B23 -> 105309 | C18: =C19+C23 -> 105588 | D18: =D19+D23 -> 106021 | E18: =E19+E23 -> 104538 | F18: =F19+F23 -> 104463 | G18: =G19+G23 -> 106466 | H18: =H19+H23 -> 107989 | I18: =I19+I23 -> 108068 | ... K18: =K19+K23 -> 108395
A19: (1) 経費 | B19: 37580 | C19: 37842 | D19: 39293 | E19: 38659 | F19: 38996 | G19: 39398 | H19: 39427 | I19: 39689 | J19: 39920 | K19: 40097
A20: 動力費 | B20: 6082 | C20: 6192 | D20: 6198 | E20: 6257 | F20: 6290 | G20: 6336 | H20: 6376 | I20: 6420 | J20: 6462 | K20: 6506
A21: 修繕費 | B21: 195 | C21: 256 | D21: 311 | E21: 257 | F21: 277 | G21: 284 | H21: 275 | I21: 282 | J21: 283 | K21: 283
A22: その他 | B22: 31303 | C22: 31394 | D22: 32784 | E22: 32145 | F22: 32429 | G22: 32777 | H22: 32775 | I22: 32987 | J22: 33175 | K22: 33309
A23: (2) 減価償却費 | B23: 67729 | C23: 67746 | D23: 66728 | E23: 65879 | F23: 65467 | G23: 67068 | H23: 68562 | I23: 68379 | J23: 68331 | K23: 68298
A24: 営業外費用 | B24: =B25+B26 -> 4922 | C24: =C25+C26 -> 3118 | D24: =D25+D26 -> 1800 | E24: =E25+E26 -> 891 | F24: =F25+F26 -> 929 | G24: =G25+G26 -> 1141 | H24: =H25+H26 -> 1027 | I24: =I25+I26 -> 1023 | ... K24: =K25+K26 -> 992
A25: (1) 支払利息 | B25: 4793 | C25: 2946 | D25: 1570 | E25: 714 | F25: 736 | G25: 941 | H25: 837 | I25: 828 | J25: 819 | K25: 799
A26: (2) その他 | B26: 129 | C26: 172 | D26: 230 | E26: 177 | F26: 193 | G26: 200 | H26: 190 | I26: 195 | J26: 195 | K26: 193
A27: 経常支出 (D) | B27: =B18+B24 -> 110231 | C27: =C18+C24 -> 108706 | D27: =D18+D24 -> 107821 | E27: =E18+E24 -> 105429 | F27: =F18+F24 -> 105392 | G27: =G18+G24 -> 107607 | H27: =H18+H24 -> 109016 | I27: =I18+I24 -> 109091 | ... K27: =K18+K24 -> 109387
A29: 経常損益 (C)-(D) | B29: =B15-B27 -> -19925 | C29: =C15-C27 -> -17604 | D29: =D15-D27 -> -16530 | E29: =E15-E27 -> -15998 | F29: =F15-F27 -> -16474 | G29: =G15-G27 -> -17032 | H29: =H15-H27 -> -17202 | I29: =I15-I27 -> -17600 | ... K29: =K15-K27 -> -18307
A31: 経常収支比率 | B31: =IF(B27=0,"-",B15/B27) -> 0.81924323 | C31: =IF(C27=0,"-",C15/C27) -> 0.83805862 | D31: =IF(D27=0,"-",D15/D27) -> 0.84669035 | E31: =IF(E27=0,"-",E15/E27) -> 0.84825807 | F31: =IF(F27=0,"-",F15/F27) -> 0.84368833 | G31: =IF(G27=0,"-",G15/G27) -> 0.84172033 | H31: =IF(H27=0,"-",H15/H27) -> 0.84220665 | I31: =IF(I27=0,"-",I15/I27) -> 0.8386668 | ... K31: =IF(K27=0,"-",K15/K27) -> 0.83264008
A32: 汚水処理費 | B32: =B19 -> 37580 | C32: =C19 -> 37842 | D32: =D19 -> 39293 | E32: =E19 -> 38659 | F32: =F19 -> 38996 | G32: =G19 -> 39398 | H32: =H19 -> 39427 | I32: =I19 -> 39689 | ... K32: =K19 -> 40097
A33: 経費回収率 | B33: =IF(B32=0,"-",B8/B32) -> 0.39763172 | C33: =IF(C32=0,"-",C8/C32) -> 0.4641668 | D33: =IF(D32=0,"-",D8/D32) -> 0.51261039 | E33: =IF(E32=0,"-",E8/E32) -> 0.51713702 | F33: =IF(F32=0,"-",F8/F32) -> 0.50948815 | G33: =IF(G32=0,"-",G8/G32) -> 0.50048226 | H33: =IF(H32=0,"-",H8/H32) -> 0.49630964 | I33: =IF(I32=0,"-",I8/I32) -> 0.48970748 | ... K33: =IF(K32=0,"-",K8/K32) -> 0.47724269
A34: 有収水量（㎥） | B34: =使用料算定!B18 -> 94131 | C34: =使用料算定!C18 -> 93463 | D34: =使用料算定!D18 -> 92868 | E34: =使用料算定!E18 -> 92200 | F34: =使用料算定!F18 -> 91605 | G34: =使用料算定!G18 -> 90937 | H34: =使用料算定!H18 -> 90268 | I34: =使用料算定!I18 -> 89600 | ... K34: =使用料算定!K18 -> 88262

Sheet パターン別比較
A1: パターン別 経常収支比率・経費回収率 比較（農業集落排水事業）
A2: ="※使用料収入のみパターンにより変動。その他の費用項目は全パターン共通。"&設定!C6&"推移ベース。" -> ※使用料収入のみパターンにより変動。その他の費用項目は全パターン共通。人口ビジョン推移ベース。
A4: 指標 ／ パターン | B4: 令和7年度 | C4: 令和8年度 | D4: 令和9年度 | E4: 令和10年度 | F4: 令和11年度 | G4: 令和12年度 | H4: 令和13年度 | I4: 令和14年度 | J4: 令和15年度 | K4: 令和16年度
A6: 【経常収支比率】
A7: 現行（改定なし） | B7: =(B26+75363)/110231 -> 0.81923415 | C7: =(C26+73537)/108706 -> 0.81293581 | D7: =(D26+71149)/107821 -> 0.79660734 | E7: =(E26+69439)/105430 -> 0.79742957 | F7: =(F26+69050)/105393 -> 0.79313617 | G7: =(G26+70857)/107607 -> 0.79260643 | H7: =(H26+72246)/109016 -> 0.79412196 | I7: =(I26+72055)/109090 -> 0.79088826 | J7: =(J26+71998)/109265 -> 0.78812062 | K7: =(K26+71944)/109387 -> 0.78576065
A8: パターン①（標準型）2か年 | B8: =(B27+75363)/110231 -> 0.81923415 | C8: =(C27+73537)/108706 -> 0.83356025 | D8: =(D27+71149)/107821 -> 0.84016101 | E8: =(E27+69439)/105430 -> 0.84164849 | F8: =(F27+69050)/105393 -> 0.83709544 | G8: =(G27+70857)/107607 -> 0.83533599 | H8: =(H27+72246)/109016 -> 0.83597821 | I8: =(I27+72055)/109090 -> 0.83243194 | J8: =(J27+71998)/109265 -> 0.82927744 | K8: =(K27+71944)/109387 -> 0.8265516
A9: パターン①（標準型）3か年 | B9: =(B28+75363)/110231 -> 0.81923415 | C9: =(C28+73537)/108706 -> 0.82628374 | D9: =(D28+71149)/107821 -> 0.82335538 | E9: =(E28+69439)/105430 -> 0.84164849 | F9: =(F28+69050)/105393 -> 0.83709544 | G9: =(G28+70857)/107607 -> 0.83533599 | H9: =(H28+72246)/109016 -> 0.83597821 | I9: =(I28+72055)/109090 -> 0.83243194 | J9: =(J28+71998)/109265 -> 0.82927744 | K9: =(K28+71944)/109387 -> 0.8265516
A10: パターン②（家庭軽減型）2か年 | B10: =(B29+75363)/110231 -> 0.81923415 | C10: =(C29+73537)/108706 -> 0.84207863 | D10: =(D29+71149)/107821 -> 0.85722633 | E10: =(E29+69439)/105430 -> 0.85897752 | F10: =(F29+69050)/105393 -> 0.8543167 | G10: =(G29+70857)/107607 -> 0.85209141 | H10: =(H29+72246)/109016 -> 0.85239781 | I10: =(I29+72055)/109090 -> 0.84870291 | J10: =(J29+71998)/109265 -> 0.84540338 | K10: =(K29+71944)/109387 -> 0.84254985
A11: パターン②（家庭軽減型）3か年 | B11: =(B30+75363)/110231 -> 0.81923415 | C11: =(C30+73537)/108706 -> 0.8319688 | D11: =(D30+71149)/107821 -> 0.83473535 | E11: =(E30+69439)/105430 -> 0.85897752 | F11: =(F30+69050)/105393 -> 0.8543167 | G11: =(G30+70857)/107607 -> 0.85209141 | H11: =(H30+72246)/109016 -> 0.85239781 | I11: =(I30+72055)/109090 -> 0.84870291 | J11: =(J30+71998)/109265 -> 0.84540338 | K11: =(K30+71944)/109387 -> 0.84254985
A12: パターン④（段階累進型）2か年 | B12: =(B31+75363)/110231 -> 0.81923415 | C12: =(C31+73537)/108706 -> 0.83640277 | D12: =(D31+71149)/107821 -> 0.84585563 | E12: =(E31+69439)/105430 -> 0.84742483 | F12: =(F31+69050)/105393 -> 0.84283586 | G12: =(G31+70857)/107607 -> 0.84092113 | H12: =(H31+72246)/109016 -> 0.84145447 | I12: =(I31+72055)/109090 -> 0.83785865 | J12: =(J31+71998)/109265 -> 0.8346497 | K12: =(K31+71944)/109387 -> 0.83189044
A13: パターン④（段階累進型）3か年 | B13: =(B32+75363)/110231 -> 0.81923415 | C13: =(C32+73537)/108706 -> 0.82684488 | D13: =(D32+71149)/107821 -> 0.82447761 | E13: =(E32+69439)/105430 -> 0.84742483 | F13: =(F32+69050)/105393 -> 0.84283586 | G13: =(G32+70857)/107607 -> 0.84092113 | H13: =(H32+72246)/109016 -> 0.84145447 | I13: =(I32+72055)/109090 -> 0.83785865 | J13: =(J32+71998)/109265 -> 0.8346497 | K13: =(K32+71944)/109387 -> 0.83189044
A15: 【経費回収率】
A16: 現行（改定なし） | B16: =B26/37580 -> 0.39760511 | C16: =C26/37842 -> 0.39199831 | D16: =D26/39293 -> 0.37518133 | E16: =E26/38659 -> 0.37854057 | F16: =F26/38996 -> 0.3728844 | G16: =G26/39398 -> 0.36633839 | H16: =H26/39427 -> 0.36335506 | I16: =I26/39689 -> 0.35836126 | J16: =J26/39920 -> 0.35360721 | K16: =K26/40097 -> 0.34935282
A17: パターン①（標準型）2か年 | B17: =B27/37580 -> 0.39760511 | C17: =C27/37842 -> 0.45124465 | D17: =D27/39293 -> 0.49469371 | E17: =E27/38659 -> 0.49913345 | F17: =F27/38996 -> 0.49169146 | G17: =G27/39398 -> 0.48304482 | H17: =H27/39427 -> 0.47908793 | I17: =I27/39689 -> 0.47254907 | J17: =J27/39920 -> 0.46625752 | K17: =K27/40097 -> 0.46063297
A18: パターン①（標準型）3か年 | B18: =B28/37580 -> 0.39760511 | C18: =C28/37842 -> 0.43034195 | D18: =D28/39293 -> 0.44857863 | E18: =E28/38659 -> 0.49913345 | F18: =F28/38996 -> 0.49169146 | G18: =G28/39398 -> 0.48304482 | H18: =H28/39427 -> 0.47908793 | I18: =I28/39689 -> 0.47254907 | J18: =J28/39920 -> 0.46625752 | K18: =K28/40097 -> 0.46063297
A19: パターン②（家庭軽減型）2か年 | B19: =B29/37580 -> 0.39760511 | C19: =C29/37842 -> 0.47571481 | D19: =D29/39293 -> 0.54152139 | E19: =E29/38659 -> 0.54639282 | F19: =F29/38996 -> 0.53823469 | G19: =G29/39398 -> 0.52880857 | H19: =H29/39427 -> 0.52448829 | I19: =I29/39689 -> 0.51727179 | J19: =J29/39920 -> 0.51039579 | K19: =K29/40097 -> 0.50427713
A20: パターン②（家庭軽減型）3か年 | B20: =B30/37580 -> 0.39760511 | C20: =C30/37842 -> 0.44667301 | D20: =D30/39293 -> 0.47980556 | E20: =E30/38659 -> 0.54639282 | F20: =F30/38996 -> 0.53823469 | G20: =G30/39398 -> 0.52880857 | H20: =H30/39427 -> 0.52448829 | I20: =I30/39689 -> 0.51727179 | J20: =J30/39920 -> 0.51039579 | K20: =K30/40097 -> 0.50427713
A21: パターン④（段階累進型）2か年 | B21: =B31/37580 -> 0.39760511 | C21: =C31/37842 -> 0.45941018 | D21: =D31/39293 -> 0.5103199 | E21: =E31/38659 -> 0.51488657 | F21: =F31/38996 -> 0.50720587 | G21: =G31/39398 -> 0.49829941 | H21: =H31/39427 -> 0.49422984 | I21: =I31/39689 -> 0.48746504 | J21: =J31/39920 -> 0.48096192 | K21: =K31/40097 -> 0.47519765
A22: パターン④（段階累進型）3か年 | B22: =B32/37580 -> 0.39760511 | C22: =C32/37842 -> 0.43195391 | D22: =D32/39293 -> 0.45165806 | E22: =E32/38659 -> 0.51488657 | F22: =F32/38996 -> 0.50720587 | G22: =G32/39398 -> 0.49829941 | H22: =H32/39427 -> 0.49422984 | I22: =I32/39689 -> 0.48746504 | J22: =J32/39920 -> 0.48096192 | K22: =K32/40097 -> 0.47519765
A24: 【参考】パターン別 使用料収入（千円）
A25: パターン | B25: 令和7年度 | C25: 令和8年度 | D25: 令和9年度 | E25: 令和10年度 | F25: 令和11年度 | G25: 令和12年度 | H25: 令和13年度 | I25: 令和14年度 | J25: 令和15年度 | K25: 令和16年度
A26: 現行（改定なし） | B26: =IF(設定!$C$6="人口ビジョン",使用料マスタ!D18,使用料マスタ!D19) -> 14942 | C26: =IF(設定!$C$6="人口ビジョン",使用料マスタ!E18,使用料マスタ!E19) -> 14834 | D26: =IF(設定!$C$6="人口ビジョン",使用料マスタ!F18,使用料マスタ!F19) -> 14742 | E26: =IF(設定!$C$6="人口ビジョン",使用料マスタ!G18,使用料マスタ!G19) -> 14634 | F26: =IF(設定!$C$6="人口ビジョン",使用料マスタ!H18,使用料マスタ!H19) -> 14541 | G26: =IF(設定!$C$6="人口ビジョン",使用料マスタ!I18,使用料マスタ!I19) -> 14433 | H26: =IF(設定!$C$6="人口ビジョン",使用料マスタ!J18,使用料マスタ!J19) -> 14326 | I26: =IF(設定!$C$6="人口ビジョン",使用料マスタ!K18,使用料マスタ!K19) -> 14223 | ... K26: =IF(設定!$C$6="人口ビジョン",使用料マスタ!M18,使用料マスタ!M19) -> 14008
A27: パターン①（標準型）2か年 | B27: =IF(設定!$C$6="人口ビジョン",使用料マスタ!D4,使用料マスタ!D10) -> 14942 | C27: =IF(設定!$C$6="人口ビジョン",使用料マスタ!E4,使用料マスタ!E10) -> 17076 | D27: =IF(設定!$C$6="人口ビジョン",使用料マスタ!F4,使用料マスタ!F10) -> 19438 | E27: =IF(設定!$C$6="人口ビジョン",使用料マスタ!G4,使用料マスタ!G10) -> 19296 | F27: =IF(設定!$C$6="人口ビジョン",使用料マスタ!H4,使用料マスタ!H10) -> 19174 | G27: =IF(設定!$C$6="人口ビジョン",使用料マスタ!I4,使用料マスタ!I10) -> 19031 | H27: =IF(設定!$C$6="人口ビジョン",使用料マスタ!J4,使用料マスタ!J10) -> 18889 | I27: =IF(設定!$C$6="人口ビジョン",使用料マスタ!K4,使用料マスタ!K10) -> 18755 | ... K27: =IF(設定!$C$6="人口ビジョン",使用料マスタ!M4,使用料マスタ!M10) -> 18470
A28: パターン①（標準型）3か年 | B28: =IF(設定!$C$6="人口ビジョン",使用料マスタ!D5,使用料マスタ!D11) -> 14942 | C28: =IF(設定!$C$6="人口ビジョン",使用料マスタ!E5,使用料マスタ!E11) -> 16285 | D28: =IF(設定!$C$6="人口ビジョン",使用料マスタ!F5,使用料マスタ!F11) -> 17626 | E28: =IF(設定!$C$6="人口ビジョン",使用料マスタ!G5,使用料マスタ!G11) -> 19296 | F28: =IF(設定!$C$6="人口ビジョン",使用料マスタ!H5,使用料マスタ!H11) -> 19174 | G28: =IF(設定!$C$6="人口ビジョン",使用料マスタ!I5,使用料マスタ!I11) -> 19031 | H28: =IF(設定!$C$6="人口ビジョン",使用料マスタ!J5,使用料マスタ!J11) -> 18889 | I28: =IF(設定!$C$6="人口ビジョン",使用料マスタ!K5,使用料マスタ!K11) -> 18755 | ... K28: =IF(設定!$C$6="人口ビジョン",使用料マスタ!M5,使用料マスタ!M11) -> 18470
A29: パターン②（家庭軽減型）2か年 | B29: =IF(設定!$C$6="人口ビジョン",使用料マスタ!D6,使用料マスタ!D12) -> 14942 | C29: =IF(設定!$C$6="人口ビジョン",使用料マスタ!E6,使用料マスタ!E12) -> 18002 | D29: =IF(設定!$C$6="人口ビジョン",使用料マスタ!F6,使用料マスタ!F12) -> 21278 | E29: =IF(設定!$C$6="人口ビジョン",使用料マスタ!G6,使用料マスタ!G12) -> 21123 | F29: =IF(設定!$C$6="人口ビジョン",使用料マスタ!H6,使用料マスタ!H12) -> 20989 | G29: =IF(設定!$C$6="人口ビジョン",使用料マスタ!I6,使用料マスタ!I12) -> 20834 | H29: =IF(設定!$C$6="人口ビジョン",使用料マスタ!J6,使用料マスタ!J12) -> 20679 | I29: =IF(設定!$C$6="人口ビジョン",使用料マスタ!K6,使用料マスタ!K12) -> 20530 | ... K29: =IF(設定!$C$6="人口ビジョン",使用料マスタ!M6,使用料マスタ!M12) -> 20220
A30: パターン②（家庭軽減型）3か年 | B30: =IF(設定!$C$6="人口ビジョン",使用料マスタ!D7,使用料マスタ!D13) -> 14942 | C30: =IF(設定!$C$6="人口ビジョン",使用料マスタ!E7,使用料マスタ!E13) -> 16903 | D30: =IF(設定!$C$6="人口ビジョン",使用料マスタ!F7,使用料マスタ!F13) -> 18853 | E30: =IF(設定!$C$6="人口ビジョン",使用料マスタ!G7,使用料マスタ!G13) -> 21123 | F30: =IF(設定!$C$6="人口ビジョン",使用料マスタ!H7,使用料マスタ!H13) -> 20989 | G30: =IF(設定!$C$6="人口ビジョン",使用料マスタ!I7,使用料マスタ!I13) -> 20834 | H30: =IF(設定!$C$6="人口ビジョン",使用料マスタ!J7,使用料マスタ!J13) -> 20679 | I30: =IF(設定!$C$6="人口ビジョン",使用料マスタ!K7,使用料マスタ!K13) -> 20530 | ... K30: =IF(設定!$C$6="人口ビジョン",使用料マスタ!M7,使用料マスタ!M13) -> 20220
A31: パターン④（段階累進型）2か年 | B31: =IF(設定!$C$6="人口ビジョン",使用料マスタ!D8,使用料マスタ!D14) -> 14942 | C31: =IF(設定!$C$6="人口ビジョン",使用料マスタ!E8,使用料マスタ!E14) -> 17385 | D31: =IF(設定!$C$6="人口ビジョン",使用料マスタ!F8,使用料マスタ!F14) -> 20052 | E31: =IF(設定!$C$6="人口ビジョン",使用料マスタ!G8,使用料マスタ!G14) -> 19905 | F31: =IF(設定!$C$6="人口ビジョン",使用料マスタ!H8,使用料マスタ!H14) -> 19779 | G31: =IF(設定!$C$6="人口ビジョン",使用料マスタ!I8,使用料マスタ!I14) -> 19632 | H31: =IF(設定!$C$6="人口ビジョン",使用料マスタ!J8,使用料マスタ!J14) -> 19486 | I31: =IF(設定!$C$6="人口ビジョン",使用料マスタ!K8,使用料マスタ!K14) -> 19347 | ... K31: =IF(設定!$C$6="人口ビジョン",使用料マスタ!M8,使用料マスタ!M14) -> 19054
A32: パターン④（段階累進型）3か年 | B32: =IF(設定!$C$6="人口ビジョン",使用料マスタ!D9,使用料マスタ!D15) -> 14942 | C32: =IF(設定!$C$6="人口ビジョン",使用料マスタ!E9,使用料マスタ!E15) -> 16346 | D32: =IF(設定!$C$6="人口ビジョン",使用料マスタ!F9,使用料マスタ!F15) -> 17747 | E32: =IF(設定!$C$6="人口ビジョン",使用料マスタ!G9,使用料マスタ!G15) -> 19905 | F32: =IF(設定!$C$6="人口ビジョン",使用料マスタ!H9,使用料マスタ!H15) -> 19779 | G32: =IF(設定!$C$6="人口ビジョン",使用料マスタ!I9,使用料マスタ!I15) -> 19632 | H32: =IF(設定!$C$6="人口ビジョン",使用料マスタ!J9,使用料マスタ!J15) -> 19486 | I32: =IF(設定!$C$6="人口ビジョン",使用料マスタ!K9,使用料マスタ!K15) -> 19347 | ... K32: =IF(設定!$C$6="人口ビジョン",使用料マスタ!M9,使用料マスタ!M15) -> 19054
A34: 汚水処理費（共通） | B34: 37580 | C34: 37842 | D34: 39293 | E34: 38659 | F34: 38996 | G34: 39398 | H34: 39427 | I34: 39689 | J34: 39920 | K34: 40097
A35: 経常支出（共通） | B35: 110231 | C35: 108706 | D35: 107821 | E35: 105430 | F35: 105393 | G35: 107607 | H35: 109016 | I35: 109090 | J35: 109266 | K35: 109387

Sheet 農集案①2か年
A1: 農業集落排水事業 投資財政計画 パターン①（標準型）2か年改定
A2: ３条 収益的収支（令和7年度～令和16年度）
A4: 区 分 | B4: 令和7年度 | C4: 令和8年度 | D4: 令和9年度 | E4: 令和10年度 | F4: 令和11年度 | G4: 令和12年度 | H4: 令和13年度 | I4: 令和14年度 | J4: 令和15年度 | K4: 令和16年度
A5: （単位：千円） | B5: 2025 | C5: 2026 | D5: 2027 | E5: 2028 | F5: 2029 | G5: 2030 | H5: 2031 | I5: 2032 | J5: 2033 | K5: 2034
A6: 【収入の部】
A7: 営業収益 (A) | B7: =SUM(B8:B10) -> 17886.9 | C7: =SUM(C8:C10) -> 20253.3 | D7: =SUM(D8:D10) -> 20116.8 | E7: =SUM(E8:E10) -> 19989.9 | F7: =SUM(F8:F10) -> 19848.4 | G7: =SUM(G8:G10) -> 19707.2 | H7: =SUM(H8:H10) -> 19572.2 | I7: =SUM(I8:I10) -> 19430.9 | ... K7: =SUM(K8:K10) -> 19165.4
A8: (1) 使用料収入 | B8: 17075.9 | C8: 19438.3 | D8: 19295.8 | E8: 19173.9 | F8: 19031.4 | G8: 18889.2 | H8: 18755.2 | I8: 18612.9 | J8: 18470.3 | K8: 18348.4
A9: (2) 雨水処理負担金 | B9: 799 | C9: 799 | D9: 799 | E9: 799 | F9: 799 | G9: 799 | H9: 799 | I9: 799 | J9: 799 | K9: 799
A10: (3) その他 | B10: 12 | C10: 16 | D10: 22 | E10: 17 | F10: 18 | G10: 19 | H10: 18 | I10: 19 | J10: 19 | K10: 18
A11: 営業外収益 | B11: 74552 | C11: 72722 | D11: 70328 | E11: 68623 | F11: 68233 | G11: 70039 | H11: 71429 | I11: 71237 | J11: 71180 | K11: 71127
A12: (1) 補助金 | B12: 19236 | C12: 17406 | D12: 16252 | E12: 15096 | F12: 14864 | G12: 16067 | H12: 16944 | I12: 16879 | J12: 16885 | K12: 16871
A13: (2) 長期前受金戻入 | B13: 55286 | C13: 55286 | D13: 54046 | E13: 53497 | F13: 53339 | G13: 53942 | H13: 54455 | I13: 54328 | J13: 54265 | K13: 54226
A14: (3) その他 | B14: 30 | C14: 30 | D14: 30 | E14: 30 | F14: 30 | G14: 30 | H14: 30 | I14: 30 | J14: 30 | K14: 30
A15: 経常収入 (C) | B15: =B7+B11 -> 92438.9 | C15: =C7+C11 -> 92975.3 | D15: =D7+D11 -> 90444.8 | E15: =E7+E11 -> 88612.9 | F15: =F7+F11 -> 88081.4 | G15: =G7+G11 -> 89746.2 | H15: =H7+H11 -> 91001.2 | I15: =I7+I11 -> 90667.9 | ... K15: =K7+K11 -> 90292.4
A17: 【支出の部】
A18: 営業費用 | B18: 105309 | C18: 105588 | D18: 106021 | E18: 104538 | F18: 104463 | G18: 106466 | H18: 107989 | I18: 108068 | J18: 108251 | K18: 108395
A19: (1) 経費 | B19: 37580 | C19: 37842 | D19: 39293 | E19: 38659 | F19: 38996 | G19: 39398 | H19: 39427 | I19: 39689 | J19: 39920 | K19: 40097
A20: 動力費 | B20: 6082 | C20: 6192 | D20: 6198 | E20: 6257 | F20: 6290 | G20: 6336 | H20: 6376 | I20: 6420 | J20: 6462 | K20: 6506
A21: 修繕費 | B21: 195 | C21: 256 | D21: 311 | E21: 257 | F21: 277 | G21: 284 | H21: 275 | I21: 282 | J21: 283 | K21: 283
A22: その他 | B22: 31303 | C22: 31394 | D22: 32784 | E22: 32145 | F22: 32429 | G22: 32777 | H22: 32775 | I22: 32987 | J22: 33175 | K22: 33309
A23: (2) 減価償却費 | B23: 67729 | C23: 67746 | D23: 66728 | E23: 65879 | F23: 65467 | G23: 67068 | H23: 68562 | I23: 68379 | J23: 68331 | K23: 68298
A24: 営業外費用 | B24: 4922 | C24: 3118 | D24: 1800 | E24: 892 | F24: 930 | G24: 1141 | H24: 1027 | I24: 1022 | J24: 1014 | K24: 992
A25: (1) 支払利息 | B25: 4793 | C25: 2946 | D25: 1570 | E25: 714 | F25: 736 | G25: 941 | H25: 837 | I25: 828 | J25: 819 | K25: 799
A26: (2) その他 | B26: 129 | C26: 172 | D26: 230 | E26: 177 | F26: 193 | G26: 200 | H26: 190 | I26: 195 | J26: 195 | K26: 193
A27: 経常支出 (D) | B27: =B18+B24 -> 110231 | C27: =C18+C24 -> 108706 | D27: =D18+D24 -> 107821 | E27: =E18+E24 -> 105430 | F27: =F18+F24 -> 105393 | G27: =G18+G24 -> 107607 | H27: =H18+H24 -> 109016 | I27: =I18+I24 -> 109090 | ... K27: =K18+K24 -> 109387
A29: 経常損益 (C)-(D) | B29: =B15-B27 -> -17792.1 | C29: =C15-C27 -> -15730.7 | D29: =D15-D27 -> -17376.2 | E29: =E15-E27 -> -16817.1 | F29: =F15-F27 -> -17311.6 | G29: =G15-G27 -> -17860.8 | H29: =H15-H27 -> -18014.8 | I29: =I15-I27 -> -18422.1 | ... K29: =K15-K27 -> -19094.6
A31: 経常収支比率 | B31: =B15/B27 -> 0.83859259 | C31: =C15/C27 -> 0.85529134 | D31: =D15/D27 -> 0.83884216 | E31: =E15/E27 -> 0.84049037 | F31: =F15/F27 -> 0.83574241 | G31: =G15/G27 -> 0.83401823 | H31: =H15/H27 -> 0.83475086 | I31: =I15/I27 -> 0.83112934 | ... K31: =K15/K27 -> 0.82543995
A32: 汚水処理費 | B32: 37580 | C32: 37842 | D32: 39293 | E32: 38659 | F32: 38996 | G32: 39398 | H32: 39427 | I32: 39689 | J32: 39920 | K32: 40097
A33: 経費回収率 | B33: =B8/B32 -> 0.45438797 | C33: =C8/C32 -> 0.51367 | D33: =D8/D32 -> 0.49107475 | E33: =E8/E32 -> 0.49597506 | F33: =F8/F32 -> 0.48803467 | G33: =G8/G32 -> 0.47944566 | H33: =H8/H32 -> 0.47569432 | I33: =I8/I32 -> 0.46896873 | ... K33: =K8/K32 -> 0.45760032
A34: 有収水量（㎥） | B34: 94131 | C34: 93463 | D34: 92868 | E34: 92200 | F34: 91605 | G34: 90937 | H34: 90268 | I34: 89600 | J34: 88931 | K34: 88262
A36: ４条 資本的収支（令和7年度～令和16年度）
A37: ※ 打合せ資料より転記予定
A39: 【資本的収入】
A40: 企業債
A41: 国庫補助金
A42: 他会計負担金
A43: その他
A44: 資本的収入 合計 (E)
A46: 【資本的支出】
A47: 建設改良費
...

Sheet 農集案①3か年
A1: 農業集落排水事業 投資財政計画 パターン①（標準型）3か年改定
A2: ３条 収益的収支（令和7年度～令和16年度）
A4: 区 分 | B4: 令和7年度 | C4: 令和8年度 | D4: 令和9年度 | E4: 令和10年度 | F4: 令和11年度 | G4: 令和12年度 | H4: 令和13年度 | I4: 令和14年度 | J4: 令和15年度 | K4: 令和16年度
A5: （単位：千円） | B5: 2025 | C5: 2026 | D5: 2027 | E5: 2028 | F5: 2029 | G5: 2030 | H5: 2031 | I5: 2032 | J5: 2033 | K5: 2034
A6: 【収入の部】
A7: 営業収益 (A) | B7: =SUM(B8:B10) -> 17096.2 | C7: =SUM(C8:C10) -> 18441 | D7: =SUM(D8:D10) -> 20116.8 | E7: =SUM(E8:E10) -> 19989.9 | F7: =SUM(F8:F10) -> 19848.4 | G7: =SUM(G8:G10) -> 19707.2 | H7: =SUM(H8:H10) -> 19572.2 | I7: =SUM(I8:I10) -> 19430.9 | ... K7: =SUM(K8:K10) -> 19165.4
A8: (1) 使用料収入 | B8: 16285.2 | C8: 17626 | D8: 19295.8 | E8: 19173.9 | F8: 19031.4 | G8: 18889.2 | H8: 18755.2 | I8: 18612.9 | J8: 18470.3 | K8: 18348.4
A9: (2) 雨水処理負担金 | B9: 799 | C9: 799 | D9: 799 | E9: 799 | F9: 799 | G9: 799 | H9: 799 | I9: 799 | J9: 799 | K9: 799
A10: (3) その他 | B10: 12 | C10: 16 | D10: 22 | E10: 17 | F10: 18 | G10: 19 | H10: 18 | I10: 19 | J10: 19 | K10: 18
A11: 営業外収益 | B11: 74552 | C11: 72722 | D11: 70328 | E11: 68623 | F11: 68233 | G11: 70039 | H11: 71429 | I11: 71237 | J11: 71180 | K11: 71127
A12: (1) 補助金 | B12: 19236 | C12: 17406 | D12: 16252 | E12: 15096 | F12: 14864 | G12: 16067 | H12: 16944 | I12: 16879 | J12: 16885 | K12: 16871
A13: (2) 長期前受金戻入 | B13: 55286 | C13: 55286 | D13: 54046 | E13: 53497 | F13: 53339 | G13: 53942 | H13: 54455 | I13: 54328 | J13: 54265 | K13: 54226
A14: (3) その他 | B14: 30 | C14: 30 | D14: 30 | E14: 30 | F14: 30 | G14: 30 | H14: 30 | I14: 30 | J14: 30 | K14: 30
A15: 経常収入 (C) | B15: =B7+B11 -> 91648.2 | C15: =C7+C11 -> 91163 | D15: =D7+D11 -> 90444.8 | E15: =E7+E11 -> 88612.9 | F15: =F7+F11 -> 88081.4 | G15: =G7+G11 -> 89746.2 | H15: =H7+H11 -> 91001.2 | I15: =I7+I11 -> 90667.9 | ... K15: =K7+K11 -> 90292.4
A17: 【支出の部】
A18: 営業費用 | B18: 105309 | C18: 105588 | D18: 106021 | E18: 104538 | F18: 104463 | G18: 106466 | H18: 107989 | I18: 108068 | J18: 108251 | K18: 108395
A19: (1) 経費 | B19: 37580 | C19: 37842 | D19: 39293 | E19: 38659 | F19: 38996 | G19: 39398 | H19: 39427 | I19: 39689 | J19: 39920 | K19: 40097
A20: 動力費 | B20: 6082 | C20: 6192 | D20: 6198 | E20: 6257 | F20: 6290 | G20: 6336 | H20: 6376 | I20: 6420 | J20: 6462 | K20: 6506
A21: 修繕費 | B21: 195 | C21: 256 | D21: 311 | E21: 257 | F21: 277 | G21: 284 | H21: 275 | I21: 282 | J21: 283 | K21: 283
A22: その他 | B22: 31303 | C22: 31394 | D22: 32784 | E22: 32145 | F22: 32429 | G22: 32777 | H22: 32775 | I22: 32987 | J22: 33175 | K22: 33309
A23: (2) 減価償却費 | B23: 67729 | C23: 67746 | D23: 66728 | E23: 65879 | F23: 65467 | G23: 67068 | H23: 68562 | I23: 68379 | J23: 68331 | K23: 68298
A24: 営業外費用 | B24: 4922 | C24: 3118 | D24: 1800 | E24: 892 | F24: 930 | G24: 1141 | H24: 1027 | I24: 1022 | J24: 1014 | K24: 992
A25: (1) 支払利息 | B25: 4793 | C25: 2946 | D25: 1570 | E25: 714 | F25: 736 | G25: 941 | H25: 837 | I25: 828 | J25: 819 | K25: 799
A26: (2) その他 | B26: 129 | C26: 172 | D26: 230 | E26: 177 | F26: 193 | G26: 200 | H26: 190 | I26: 195 | J26: 195 | K26: 193
A27: 経常支出 (D) | B27: =B18+B24 -> 110231 | C27: =C18+C24 -> 108706 | D27: =D18+D24 -> 107821 | E27: =E18+E24 -> 105430 | F27: =F18+F24 -> 105393 | G27: =G18+G24 -> 107607 | H27: =H18+H24 -> 109016 | I27: =I18+I24 -> 109090 | ... K27: =K18+K24 -> 109387
A29: 経常損益 (C)-(D) | B29: =B15-B27 -> -18582.8 | C29: =C15-C27 -> -17543 | D29: =D15-D27 -> -17376.2 | E29: =E15-E27 -> -16817.1 | F29: =F15-F27 -> -17311.6 | G29: =G15-G27 -> -17860.8 | H29: =H15-H27 -> -18014.8 | I29: =I15-I27 -> -18422.1 | ... K29: =K15-K27 -> -19094.6
A31: 経常収支比率 | B31: =B15/B27 -> 0.83141947 | C31: =C15/C27 -> 0.83861976 | D31: =D15/D27 -> 0.83884216 | E31: =E15/E27 -> 0.84049037 | F31: =F15/F27 -> 0.83574241 | G31: =G15/G27 -> 0.83401823 | H31: =H15/H27 -> 0.83475086 | I31: =I15/I27 -> 0.83112934 | ... K31: =K15/K27 -> 0.82543995
A32: 汚水処理費 | B32: 37580 | C32: 37842 | D32: 39293 | E32: 38659 | F32: 38996 | G32: 39398 | H32: 39427 | I32: 39689 | J32: 39920 | K32: 40097
A33: 経費回収率 | B33: =B8/B32 -> 0.43334753 | C33: =C8/C32 -> 0.46577876 | D33: =D8/D32 -> 0.49107475 | E33: =E8/E32 -> 0.49597506 | F33: =F8/F32 -> 0.48803467 | G33: =G8/G32 -> 0.47944566 | H33: =H8/H32 -> 0.47569432 | I33: =I8/I32 -> 0.46896873 | ... K33: =K8/K32 -> 0.45760032
A34: 有収水量（㎥） | B34: 94131 | C34: 93463 | D34: 92868 | E34: 92200 | F34: 91605 | G34: 90937 | H34: 90268 | I34: 89600 | J34: 88931 | K34: 88262
A36: ４条 資本的収支（令和7年度～令和16年度）
A37: ※ 打合せ資料より転記予定
A39: 【資本的収入】
A40: 企業債
A41: 国庫補助金
A42: 他会計負担金
A43: その他
A44: 資本的収入 合計 (E)
A46: 【資本的支出】
A47: 建設改良費
...

Sheet 農集案②2か年
A1: 農業集落排水事業 投資財政計画 パターン②（家庭軽減型）2か年改定
A2: ３条 収益的収支（令和7年度～令和16年度）
A4: 区 分 | B4: 令和7年度 | C4: 令和8年度 | D4: 令和9年度 | E4: 令和10年度 | F4: 令和11年度 | G4: 令和12年度 | H4: 令和13年度 | I4: 令和14年度 | J4: 令和15年度 | K4: 令和16年度
A5: （単位：千円） | B5: 2025 | C5: 2026 | D5: 2027 | E5: 2028 | F5: 2029 | G5: 2030 | H5: 2031 | I5: 2032 | J5: 2033 | K5: 2034
A6: 【収入の部】
A7: 営業収益 (A) | B7: =SUM(B8:B10) -> 18813.1 | C7: =SUM(C8:C10) -> 22093.5 | D7: =SUM(D8:D10) -> 21944.1 | E7: =SUM(E8:E10) -> 21804.9 | F7: =SUM(F8:F10) -> 21650.7 | G7: =SUM(G8:G10) -> 21496.8 | H7: =SUM(H8:H10) -> 21347.2 | I7: =SUM(I8:I10) -> 21193.3 | ... K7: =SUM(K8:K10) -> 20902.6
A8: (1) 使用料収入 | B8: 18002.1 | C8: 21278.5 | D8: 21123.1 | E8: 20988.9 | F8: 20833.7 | G8: 20678.8 | H8: 20530.2 | I8: 20375.3 | J8: 20219.9 | K8: 20085.6
A9: (2) 雨水処理負担金 | B9: 799 | C9: 799 | D9: 799 | E9: 799 | F9: 799 | G9: 799 | H9: 799 | I9: 799 | J9: 799 | K9: 799
A10: (3) その他 | B10: 12 | C10: 16 | D10: 22 | E10: 17 | F10: 18 | G10: 19 | H10: 18 | I10: 19 | J10: 19 | K10: 18
A11: 営業外収益 | B11: 74552 | C11: 72722 | D11: 70328 | E11: 68623 | F11: 68233 | G11: 70039 | H11: 71429 | I11: 71237 | J11: 71180 | K11: 71127
A12: (1) 補助金 | B12: 19236 | C12: 17406 | D12: 16252 | E12: 15096 | F12: 14864 | G12: 16067 | H12: 16944 | I12: 16879 | J12: 16885 | K12: 16871
A13: (2) 長期前受金戻入 | B13: 55286 | C13: 55286 | D13: 54046 | E13: 53497 | F13: 53339 | G13: 53942 | H13: 54455 | I13: 54328 | J13: 54265 | K13: 54226
A14: (3) その他 | B14: 30 | C14: 30 | D14: 30 | E14: 30 | F14: 30 | G14: 30 | H14: 30 | I14: 30 | J14: 30 | K14: 30
A15: 経常収入 (C) | B15: =B7+B11 -> 93365.1 | C15: =C7+C11 -> 94815.5 | D15: =D7+D11 -> 92272.1 | E15: =E7+E11 -> 90427.9 | F15: =F7+F11 -> 89883.7 | G15: =G7+G11 -> 91535.8 | H15: =H7+H11 -> 92776.2 | I15: =I7+I11 -> 92430.3 | ... K15: =K7+K11 -> 92029.6
A17: 【支出の部】
A18: 営業費用 | B18: 105309 | C18: 105588 | D18: 106021 | E18: 104538 | F18: 104463 | G18: 106466 | H18: 107989 | I18: 108068 | J18: 108251 | K18: 108395
A19: (1) 経費 | B19: 37580 | C19: 37842 | D19: 39293 | E19: 38659 | F19: 38996 | G19: 39398 | H19: 39427 | I19: 39689 | J19: 39920 | K19: 40097
A20: 動力費 | B20: 6082 | C20: 6192 | D20: 6198 | E20: 6257 | F20: 6290 | G20: 6336 | H20: 6376 | I20: 6420 | J20: 6462 | K20: 6506
A21: 修繕費 | B21: 195 | C21: 256 | D21: 311 | E21: 257 | F21: 277 | G21: 284 | H21: 275 | I21: 282 | J21: 283 | K21: 283
A22: その他 | B22: 31303 | C22: 31394 | D22: 32784 | E22: 32145 | F22: 32429 | G22: 32777 | H22: 32775 | I22: 32987 | J22: 33175 | K22: 33309
A23: (2) 減価償却費 | B23: 67729 | C23: 67746 | D23: 66728 | E23: 65879 | F23: 65467 | G23: 67068 | H23: 68562 | I23: 68379 | J23: 68331 | K23: 68298
A24: 営業外費用 | B24: 4922 | C24: 3118 | D24: 1800 | E24: 892 | F24: 930 | G24: 1141 | H24: 1027 | I24: 1022 | J24: 1014 | K24: 992
A25: (1) 支払利息 | B25: 4793 | C25: 2946 | D25: 1570 | E25: 714 | F25: 736 | G25: 941 | H25: 837 | I25: 828 | J25: 819 | K25: 799
A26: (2) その他 | B26: 129 | C26: 172 | D26: 230 | E26: 177 | F26: 193 | G26: 200 | H26: 190 | I26: 195 | J26: 195 | K26: 193
A27: 経常支出 (D) | B27: =B18+B24 -> 110231 | C27: =C18+C24 -> 108706 | D27: =D18+D24 -> 107821 | E27: =E18+E24 -> 105430 | F27: =F18+F24 -> 105393 | G27: =G18+G24 -> 107607 | H27: =H18+H24 -> 109016 | I27: =I18+I24 -> 109090 | ... K27: =K18+K24 -> 109387
A29: 経常損益 (C)-(D) | B29: =B15-B27 -> -16865.9 | C29: =C15-C27 -> -13890.5 | D29: =D15-D27 -> -15548.9 | E29: =E15-E27 -> -15002.1 | F29: =F15-F27 -> -15509.3 | G29: =G15-G27 -> -16071.2 | H29: =H15-H27 -> -16239.8 | I29: =I15-I27 -> -16659.7 | ... K29: =K15-K27 -> -17357.4
A31: 経常収支比率 | B31: =B15/B27 -> 0.84699495 | C31: =C15/C27 -> 0.87221956 | D31: =D15/D27 -> 0.85578969 | E31: =E15/E27 -> 0.85770559 | F31: =F15/F27 -> 0.85284317 | G31: =G15/G27 -> 0.85064912 | H31: =H15/H27 -> 0.85103288 | I31: =I15/I27 -> 0.84728481 | ... K31: =K15/K27 -> 0.84132118
A32: 汚水処理費 | B32: 37580 | C32: 37842 | D32: 39293 | E32: 38659 | F32: 38996 | G32: 39398 | H32: 39427 | I32: 39689 | J32: 39920 | K32: 40097
A33: 経費回収率 | B33: =B8/B32 -> 0.47903406 | C33: =C8/C32 -> 0.5622985 | D33: =D8/D32 -> 0.53757921 | E33: =E8/E32 -> 0.54292403 | F33: =F8/F32 -> 0.53425223 | G33: =G8/G32 -> 0.52486928 | H33: =H8/H32 -> 0.52071423 | I33: =I8/I32 -> 0.51337398 | ... K33: =K8/K32 -> 0.50092526
A34: 有収水量（㎥） | B34: 94131 | C34: 93463 | D34: 92868 | E34: 92200 | F34: 91605 | G34: 90937 | H34: 90268 | I34: 89600 | J34: 88931 | K34: 88262
A36: ４条 資本的収支（令和7年度～令和16年度）
A37: ※ 打合せ資料より転記予定
A39: 【資本的収入】
A40: 企業債
A41: 国庫補助金
A42: 他会計負担金
A43: その他
A44: 資本的収入 合計 (E)
A46: 【資本的支出】
A47: 建設改良費
...

Sheet 農集案②3か年
A1: 農業集落排水事業 投資財政計画 パターン②（家庭軽減型）3か年改定
A2: ３条 収益的収支（令和7年度～令和16年度）
A4: 区 分 | B4: 令和7年度 | C4: 令和8年度 | D4: 令和9年度 | E4: 令和10年度 | F4: 令和11年度 | G4: 令和12年度 | H4: 令和13年度 | I4: 令和14年度 | J4: 令和15年度 | K4: 令和16年度
A5: （単位：千円） | B5: 2025 | C5: 2026 | D5: 2027 | E5: 2028 | F5: 2029 | G5: 2030 | H5: 2031 | I5: 2032 | J5: 2033 | K5: 2034
A6: 【収入の部】
A7: 営業収益 (A) | B7: =SUM(B8:B10) -> 17713.6 | C7: =SUM(C8:C10) -> 19667.8 | D7: =SUM(D8:D10) -> 21944.1 | E7: =SUM(E8:E10) -> 21804.9 | F7: =SUM(F8:F10) -> 21650.7 | G7: =SUM(G8:G10) -> 21496.8 | H7: =SUM(H8:H10) -> 21347.2 | I7: =SUM(I8:I10) -> 21193.3 | ... K7: =SUM(K8:K10) -> 20902.6
A8: (1) 使用料収入 | B8: 16902.6 | C8: 18852.8 | D8: 21123.1 | E8: 20988.9 | F8: 20833.7 | G8: 20678.8 | H8: 20530.2 | I8: 20375.3 | J8: 20219.9 | K8: 20085.6
A9: (2) 雨水処理負担金 | B9: 799 | C9: 799 | D9: 799 | E9: 799 | F9: 799 | G9: 799 | H9: 799 | I9: 799 | J9: 799 | K9: 799
A10: (3) その他 | B10: 12 | C10: 16 | D10: 22 | E10: 17 | F10: 18 | G10: 19 | H10: 18 | I10: 19 | J10: 19 | K10: 18
A11: 営業外収益 | B11: 74552 | C11: 72722 | D11: 70328 | E11: 68623 | F11: 68233 | G11: 70039 | H11: 71429 | I11: 71237 | J11: 71180 | K11: 71127
A12: (1) 補助金 | B12: 19236 | C12: 17406 | D12: 16252 | E12: 15096 | F12: 14864 | G12: 16067 | H12: 16944 | I12: 16879 | J12: 16885 | K12: 16871
A13: (2) 長期前受金戻入 | B13: 55286 | C13: 55286 | D13: 54046 | E13: 53497 | F13: 53339 | G13: 53942 | H13: 54455 | I13: 54328 | J13: 54265 | K13: 54226
A14: (3) その他 | B14: 30 | C14: 30 | D14: 30 | E14: 30 | F14: 30 | G14: 30 | H14: 30 | I14: 30 | J14: 30 | K14: 30
A15: 経常収入 (C) | B15: =B7+B11 -> 92265.6 | C15: =C7+C11 -> 92389.8 | D15: =D7+D11 -> 92272.1 | E15: =E7+E11 -> 90427.9 | F15: =F7+F11 -> 89883.7 | G15: =G7+G11 -> 91535.8 | H15: =H7+H11 -> 92776.2 | I15: =I7+I11 -> 92430.3 | ... K15: =K7+K11 -> 92029.6
A17: 【支出の部】
A18: 営業費用 | B18: 105309 | C18: 105588 | D18: 106021 | E18: 104538 | F18: 104463 | G18: 106466 | H18: 107989 | I18: 108068 | J18: 108251 | K18: 108395
A19: (1) 経費 | B19: 37580 | C19: 37842 | D19: 39293 | E19: 38659 | F19: 38996 | G19: 39398 | H19: 39427 | I19: 39689 | J19: 39920 | K19: 40097
A20: 動力費 | B20: 6082 | C20: 6192 | D20: 6198 | E20: 6257 | F20: 6290 | G20: 6336 | H20: 6376 | I20: 6420 | J20: 6462 | K20: 6506
A21: 修繕費 | B21: 195 | C21: 256 | D21: 311 | E21: 257 | F21: 277 | G21: 284 | H21: 275 | I21: 282 | J21: 283 | K21: 283
A22: その他 | B22: 31303 | C22: 31394 | D22: 32784 | E22: 32145 | F22: 32429 | G22: 32777 | H22: 32775 | I22: 32987 | J22: 33175 | K22: 33309
A23: (2) 減価償却費 | B23: 67729 | C23: 67746 | D23: 66728 | E23: 65879 | F23: 65467 | G23: 67068 | H23: 68562 | I23: 68379 | J23: 68331 | K23: 68298
A24: 営業外費用 | B24: 4922 | C24: 3118 | D24: 1800 | E24: 892 | F24: 930 | G24: 1141 | H24: 1027 | I24: 1022 | J24: 1014 | K24: 992
A25: (1) 支払利息 | B25: 4793 | C25: 2946 | D25: 1570 | E25: 714 | F25: 736 | G25: 941 | H25: 837 | I25: 828 | J25: 819 | K25: 799
A26: (2) その他 | B26: 129 | C26: 172 | D26: 230 | E26: 177 | F26: 193 | G26: 200 | H26: 190 | I26: 195 | J26: 195 | K26: 193
A27: 経常支出 (D) | B27: =B18+B24 -> 110231 | C27: =C18+C24 -> 108706 | D27: =D18+D24 -> 107821 | E27: =E18+E24 -> 105430 | F27: =F18+F24 -> 105393 | G27: =G18+G24 -> 107607 | H27: =H18+H24 -> 109016 | I27: =I18+I24 -> 109090 | ... K27: =K18+K24 -> 109387
A29: 経常損益 (C)-(D) | B29: =B15-B27 -> -17965.4 | C29: =C15-C27 -> -16316.2 | D29: =D15-D27 -> -15548.9 | E29: =E15-E27 -> -15002.1 | F29: =F15-F27 -> -15509.3 | G29: =G15-G27 -> -16071.2 | H29: =H15-H27 -> -16239.8 | I29: =I15-I27 -> -16659.7 | ... K29: =K15-K27 -> -17357.4
A31: 経常収支比率 | B31: =B15/B27 -> 0.83702044 | C31: =C15/C27 -> 0.84990525 | D31: =D15/D27 -> 0.85578969 | E31: =E15/E27 -> 0.85770559 | F31: =F15/F27 -> 0.85284317 | G31: =G15/G27 -> 0.85064912 | H31: =H15/H27 -> 0.85103288 | I31: =I15/I27 -> 0.84728481 | ... K31: =K15/K27 -> 0.84132118
A32: 汚水処理費 | B32: 37580 | C32: 37842 | D32: 39293 | E32: 38659 | F32: 38996 | G32: 39398 | H32: 39427 | I32: 39689 | J32: 39920 | K32: 40097
A33: 経費回収率 | B33: =B8/B32 -> 0.44977648 | C33: =C8/C32 -> 0.49819777 | D33: =D8/D32 -> 0.53757921 | E33: =E8/E32 -> 0.54292403 | F33: =F8/F32 -> 0.53425223 | G33: =G8/G32 -> 0.52486928 | H33: =H8/H32 -> 0.52071423 | I33: =I8/I32 -> 0.51337398 | ... K33: =K8/K32 -> 0.50092526
A34: 有収水量（㎥） | B34: 94131 | C34: 93463 | D34: 92868 | E34: 92200 | F34: 91605 | G34: 90937 | H34: 90268 | I34: 89600 | J34: 88931 | K34: 88262
A36: ４条 資本的収支（令和7年度～令和16年度）
A37: ※ 打合せ資料より転記予定
A39: 【資本的収入】
A40: 企業債
A41: 国庫補助金
A42: 他会計負担金
A43: その他
A44: 資本的収入 合計 (E)
A46: 【資本的支出】
A47: 建設改良費
...

Sheet 農集案④2か年
A1: 農業集落排水事業 投資財政計画 パターン④（段階累進型）2か年改定
A2: ３条 収益的収支（令和7年度～令和16年度）
A4: 区 分 | B4: 令和7年度 | C4: 令和8年度 | D4: 令和9年度 | E4: 令和10年度 | F4: 令和11年度 | G4: 令和12年度 | H4: 令和13年度 | I4: 令和14年度 | J4: 令和15年度 | K4: 令和16年度
