Workbook

Sheet 設定
B2: 六戸町 公共下水道事業 使用料改定シミュレーション
B4: ▼ 黄色セルを変更すると「財政計画（ベース）」「パターン別比較」が自動連動します
B6: ① 人口推計 | C6: 社人研
B8: ② 料金パターン | C8: パターン①（標準型）
B10: ③ 改定年数 | C10: 3か年

Sheet 使用料マスタ
A1: 使用料収入マスタ（千円） ※設定シートから自動参照
A3: 人口推計 | B3: パターン | C3: 改定年数 | D3: 令和7年度 | E3: 令和8年度 | F3: 令和9年度 | G3: 令和10年度 | H3: 令和11年度 | I3: 令和12年度 | J3: 令和13年度 | K3: 令和14年度 | L3: 令和15年度 | M3: 令和16年度
A4: 人口ビジョン | B4: パターン①（標準型） | C4: 2か年 | D4: 57781 | E4: 66470 | F4: 76162 | G4: 75645 | H4: 75110 | I4: 74592 | J4: 74047 | K4: 73501 | L4: 72956 | M4: 72391
A5: 人口ビジョン | B5: パターン①（標準型） | C5: 3か年 | D5: 57781 | E5: 63223 | F5: 68570 | G5: 75645 | H5: 75110 | I5: 74592 | J5: 74047 | K5: 73501 | L5: 72956 | M5: 72391
A6: 人口ビジョン | B6: パターン②（家庭軽減型） | C6: 2か年 | D6: 57781 | E6: 69111 | F6: 81408 | G6: 80856 | H6: 80284 | I6: 79731 | J6: 79147 | K6: 78564 | L6: 77980 | M6: 77378
A7: 人口ビジョン | B7: パターン②（家庭軽減型） | C7: 3か年 | D7: 57781 | E7: 64984 | F7: 72068 | G7: 80856 | H7: 80284 | I7: 79731 | J7: 79147 | K7: 78564 | L7: 77980 | M7: 77378
A8: 人口ビジョン | B8: パターン④（段階累進型） | C8: 2か年 | D8: 57781 | E8: 67350 | F8: 77911 | G8: 77382 | H8: 76834 | I8: 76305 | J8: 75747 | K8: 75189 | L8: 74630 | M8: 74054
A9: 人口ビジョン | B9: パターン④（段階累進型） | C9: 3か年 | D9: 57781 | E9: 63514 | F9: 69149 | G9: 77382 | H9: 76834 | I9: 76305 | J9: 75747 | K9: 75189 | L9: 74630 | M9: 74054
A10: 社人研 | B10: パターン①（標準型） | C10: 2か年 | D10: 57895 | E10: 66578 | F10: 76277 | G10: 75712 | H10: 75167 | I10: 74631 | J10: 74018 | K10: 73405 | L10: 72802 | M10: 72181
A11: 社人研 | B11: パターン①（標準型） | C11: 3か年 | D11: 57895 | E11: 63326 | F11: 68674 | G11: 75712 | H11: 75167 | I11: 74631 | J11: 74018 | K11: 73405 | L11: 72802 | M11: 72181
A12: 社人研 | B12: パターン②（家庭軽減型） | C12: 2か年 | D12: 57895 | E12: 69223 | F12: 81531 | G12: 80928 | H12: 80345 | I12: 79773 | J12: 79117 | K12: 78461 | L12: 77816 | M12: 77153
A13: 社人研 | B13: パターン②（家庭軽減型） | C13: 3か年 | D13: 57895 | E13: 65090 | F13: 72176 | G13: 80928 | H13: 80345 | I13: 79773 | J13: 79117 | K13: 78461 | L13: 77816 | M13: 77153
A14: 社人研 | B14: パターン④（段階累進型） | C14: 2か年 | D14: 57895 | E14: 67460 | F14: 78028 | G14: 77451 | H14: 76893 | I14: 76345 | J14: 75718 | K14: 75090 | L14: 74474 | M14: 73838
A15: 社人研 | B15: パターン④（段階累進型） | C15: 3か年 | D15: 57895 | E15: 63618 | F15: 69254 | G15: 77451 | H15: 76893 | I15: 76345 | J15: 75718 | K15: 75090 | L15: 74474 | M15: 73838
A17: 現行収入（改定なし）
A18: 人口ビジョン | B18: 現行 | D18: 57781 | E18: 57393 | F18: 56993 | G18: 56606 | H18: 56205 | I18: 55818 | J18: 55410 | K18: 55001 | L18: 54593 | M18: 54171
A19: 社人研 | B19: 現行 | D19: 57895 | E19: 57487 | F19: 57079 | G19: 56656 | H19: 56248 | I19: 55847 | J19: 55388 | K19: 54930 | L19: 54478 | M19: 54014
A21: 有収水量（㎥）
A22: 人口ビジョン | D22: 452089 | E22: 449052 | F22: 445934 | G22: 442898 | H22: 439779 | I22: 436743 | J22: 433542 | K22: 430342 | L22: 427141 | M22: 423859
A23: 社人研 | D23: 452992 | E23: 449791 | F23: 446591 | G23: 443308 | H23: 440108 | I23: 436989 | J23: 433378 | K23: 429767 | L23: 426239 | M23: 422628

Sheet 料金テーブル
A1: 料金テーブル（税抜き・円） ※黄色セル編集可
A2: 単価を変更すると「使用料算定」→「財政計画（ベース）」に自動反映されます
A4: 水量区分 | B4: 現行 | C4: パターン① （標準型） | D4: パターン② （家庭軽減型） | E4: パターン④ （段階累進型）
A5: 基本(0〜10㎥) | B5: 1000 | C5: 1500 | D5: 1200 | E5: 1400
A6: 11〜20㎥ | B6: 120 | C6: 150 | D6: 180 | E6: 160
A7: 21〜30㎥ | B7: 120 | C7: 155 | D7: 185 | E7: 165
A8: 31〜40㎥ | B8: 130 | C8: 160 | D8: 190 | E8: 170
A9: 41〜50㎥ | B9: 130 | C9: 165 | D9: 195 | E9: 175
A10: 51〜70㎥ | B10: 140 | C10: 175 | D10: 205 | E10: 185
A11: 71〜100㎥ | B11: 140 | C11: 185 | D11: 215 | E11: 195
A12: 101〜150㎥ | B12: 140 | C12: 205 | D12: 235 | E12: 215
A13: 151㎥〜 | B13: 160 | C13: 225 | D13: 255 | E13: 235

Sheet 使用料算定
A1: 使用料収入算定（区分別積み上げ）
A2: =設定!C8&" "&設定!C10&"改定 （"&設定!C6&"推移）" -> パターン①（標準型） 3か年改定 （社人研推移）
A4: ■ 年度別適用単価（円）
A5: 水量区分 | B5: 令和7年度 | C5: 令和8年度 | D5: 令和9年度 | E5: 令和10年度 | F5: 令和11年度 | G5: 令和12年度 | H5: 令和13年度 | I5: 令和14年度 | J5: 令和15年度 | K5: 令和16年度
A6: 基本(0〜10㎥) | B6: =料金テーブル!$B$5 -> 1000 | C6: =IF(設定!$C$10="2か年",ROUND((料金テーブル!$B$5+IF(設定!$C$8="パターン①（標準型）",料金テーブル!$C$5,IF(設定!$C$8="パターン②（家庭軽減型）",料金テーブル!$D$5,料金テーブル!$E$5)))/2,0),IF(設定!$C$8="パターン①（標準型）",'段階単価(3か年)'!$B$6,IF(設定!$C$8="パターン②（家庭軽減型）",'段階単価(3か年)'!$B$18,'段階単価(3か年)'!$B$30))) -> 1150 | D6: =IF(設定!$C$10="2か年",IF(設定!$C$8="パターン①（標準型）",料金テーブル!$C$5,IF(設定!$C$8="パターン②（家庭軽減型）",料金テーブル!$D$5,料金テーブル!$E$5)),IF(設定!$C$8="パターン①（標準型）",'段階単価(3か年)'!$C$6,IF(設定!$C$8="パターン②（家庭軽減型）",'段階単価(3か年)'!$C$18,'段階単価(3か年)'!$C$30))) -> 1300 | E6: =IF(設定!$C$8="パターン①（標準型）",料金テーブル!$C$5,IF(設定!$C$8="パターン②（家庭軽減型）",料金テーブル!$D$5,料金テーブル!$E$5)) -> 1500 | F6: =IF(設定!$C$8="パターン①（標準型）",料金テーブル!$C$5,IF(設定!$C$8="パターン②（家庭軽減型）",料金テーブル!$D$5,料金テーブル!$E$5)) -> 1500 | G6: =IF(設定!$C$8="パターン①（標準型）",料金テーブル!$C$5,IF(設定!$C$8="パターン②（家庭軽減型）",料金テーブル!$D$5,料金テーブル!$E$5)) -> 1500 | H6: =IF(設定!$C$8="パターン①（標準型）",料金テーブル!$C$5,IF(設定!$C$8="パターン②（家庭軽減型）",料金テーブル!$D$5,料金テーブル!$E$5)) -> 1500 | I6: =IF(設定!$C$8="パターン①（標準型）",料金テーブル!$C$5,IF(設定!$C$8="パターン②（家庭軽減型）",料金テーブル!$D$5,料金テーブル!$E$5)) -> 1500 | J6: =IF(設定!$C$8="パターン①（標準型）",料金テーブル!$C$5,IF(設定!$C$8="パターン②（家庭軽減型）",料金テーブル!$D$5,料金テーブル!$E$5)) -> 1500 | K6: =IF(設定!$C$8="パターン①（標準型）",料金テーブル!$C$5,IF(設定!$C$8="パターン②（家庭軽減型）",料金テーブル!$D$5,料金テーブル!$E$5)) -> 1500
A7: 11〜20㎥ | B7: =料金テーブル!$B$6 -> 120 | C7: =IF(設定!$C$10="2か年",ROUND((料金テーブル!$B$6+IF(設定!$C$8="パターン①（標準型）",料金テーブル!$C$6,IF(設定!$C$8="パターン②（家庭軽減型）",料金テーブル!$D$6,料金テーブル!$E$6)))/2,0),IF(設定!$C$8="パターン①（標準型）",'段階単価(3か年)'!$B$7,IF(設定!$C$8="パターン②（家庭軽減型）",'段階単価(3か年)'!$B$19,'段階単価(3か年)'!$B$31))) -> 130 | D7: =IF(設定!$C$10="2か年",IF(設定!$C$8="パターン①（標準型）",料金テーブル!$C$6,IF(設定!$C$8="パターン②（家庭軽減型）",料金テーブル!$D$6,料金テーブル!$E$6)),IF(設定!$C$8="パターン①（標準型）",'段階単価(3か年)'!$C$7,IF(設定!$C$8="パターン②（家庭軽減型）",'段階単価(3か年)'!$C$19,'段階単価(3か年)'!$C$31))) -> 140 | E7: =IF(設定!$C$8="パターン①（標準型）",料金テーブル!$C$6,IF(設定!$C$8="パターン②（家庭軽減型）",料金テーブル!$D$6,料金テーブル!$E$6)) -> 150 | F7: =IF(設定!$C$8="パターン①（標準型）",料金テーブル!$C$6,IF(設定!$C$8="パターン②（家庭軽減型）",料金テーブル!$D$6,料金テーブル!$E$6)) -> 150 | G7: =IF(設定!$C$8="パターン①（標準型）",料金テーブル!$C$6,IF(設定!$C$8="パターン②（家庭軽減型）",料金テーブル!$D$6,料金テーブル!$E$6)) -> 150 | H7: =IF(設定!$C$8="パターン①（標準型）",料金テーブル!$C$6,IF(設定!$C$8="パターン②（家庭軽減型）",料金テーブル!$D$6,料金テーブル!$E$6)) -> 150 | I7: =IF(設定!$C$8="パターン①（標準型）",料金テーブル!$C$6,IF(設定!$C$8="パターン②（家庭軽減型）",料金テーブル!$D$6,料金テーブル!$E$6)) -> 150 | J7: =IF(設定!$C$8="パターン①（標準型）",料金テーブル!$C$6,IF(設定!$C$8="パターン②（家庭軽減型）",料金テーブル!$D$6,料金テーブル!$E$6)) -> 150 | K7: =IF(設定!$C$8="パターン①（標準型）",料金テーブル!$C$6,IF(設定!$C$8="パターン②（家庭軽減型）",料金テーブル!$D$6,料金テーブル!$E$6)) -> 150
A8: 21〜30㎥ | B8: =料金テーブル!$B$7 -> 120 | C8: =IF(設定!$C$10="2か年",ROUND((料金テーブル!$B$7+IF(設定!$C$8="パターン①（標準型）",料金テーブル!$C$7,IF(設定!$C$8="パターン②（家庭軽減型）",料金テーブル!$D$7,料金テーブル!$E$7)))/2,0),IF(設定!$C$8="パターン①（標準型）",'段階単価(3か年)'!$B$8,IF(設定!$C$8="パターン②（家庭軽減型）",'段階単価(3か年)'!$B$20,'段階単価(3か年)'!$B$32))) -> 130 | D8: =IF(設定!$C$10="2か年",IF(設定!$C$8="パターン①（標準型）",料金テーブル!$C$7,IF(設定!$C$8="パターン②（家庭軽減型）",料金テーブル!$D$7,料金テーブル!$E$7)),IF(設定!$C$8="パターン①（標準型）",'段階単価(3か年)'!$C$8,IF(設定!$C$8="パターン②（家庭軽減型）",'段階単価(3か年)'!$C$20,'段階単価(3か年)'!$C$32))) -> 140 | E8: =IF(設定!$C$8="パターン①（標準型）",料金テーブル!$C$7,IF(設定!$C$8="パターン②（家庭軽減型）",料金テーブル!$D$7,料金テーブル!$E$7)) -> 155 | F8: =IF(設定!$C$8="パターン①（標準型）",料金テーブル!$C$7,IF(設定!$C$8="パターン②（家庭軽減型）",料金テーブル!$D$7,料金テーブル!$E$7)) -> 155 | G8: =IF(設定!$C$8="パターン①（標準型）",料金テーブル!$C$7,IF(設定!$C$8="パターン②（家庭軽減型）",料金テーブル!$D$7,料金テーブル!$E$7)) -> 155 | H8: =IF(設定!$C$8="パターン①（標準型）",料金テーブル!$C$7,IF(設定!$C$8="パターン②（家庭軽減型）",料金テーブル!$D$7,料金テーブル!$E$7)) -> 155 | I8: =IF(設定!$C$8="パターン①（標準型）",料金テーブル!$C$7,IF(設定!$C$8="パターン②（家庭軽減型）",料金テーブル!$D$7,料金テーブル!$E$7)) -> 155 | J8: =IF(設定!$C$8="パターン①（標準型）",料金テーブル!$C$7,IF(設定!$C$8="パターン②（家庭軽減型）",料金テーブル!$D$7,料金テーブル!$E$7)) -> 155 | K8: =IF(設定!$C$8="パターン①（標準型）",料金テーブル!$C$7,IF(設定!$C$8="パターン②（家庭軽減型）",料金テーブル!$D$7,料金テーブル!$E$7)) -> 155
A9: 31〜40㎥ | B9: =料金テーブル!$B$8 -> 130 | C9: =IF(設定!$C$10="2か年",ROUND((料金テーブル!$B$8+IF(設定!$C$8="パターン①（標準型）",料金テーブル!$C$8,IF(設定!$C$8="パターン②（家庭軽減型）",料金テーブル!$D$8,料金テーブル!$E$8)))/2,0),IF(設定!$C$8="パターン①（標準型）",'段階単価(3か年)'!$B$9,IF(設定!$C$8="パターン②（家庭軽減型）",'段階単価(3か年)'!$B$21,'段階単価(3か年)'!$B$33))) -> 140 | D9: =IF(設定!$C$10="2か年",IF(設定!$C$8="パターン①（標準型）",料金テーブル!$C$8,IF(設定!$C$8="パターン②（家庭軽減型）",料金テーブル!$D$8,料金テーブル!$E$8)),IF(設定!$C$8="パターン①（標準型）",'段階単価(3か年)'!$C$9,IF(設定!$C$8="パターン②（家庭軽減型）",'段階単価(3か年)'!$C$21,'段階単価(3か年)'!$C$33))) -> 150 | E9: =IF(設定!$C$8="パターン①（標準型）",料金テーブル!$C$8,IF(設定!$C$8="パターン②（家庭軽減型）",料金テーブル!$D$8,料金テーブル!$E$8)) -> 160 | F9: =IF(設定!$C$8="パターン①（標準型）",料金テーブル!$C$8,IF(設定!$C$8="パターン②（家庭軽減型）",料金テーブル!$D$8,料金テーブル!$E$8)) -> 160 | G9: =IF(設定!$C$8="パターン①（標準型）",料金テーブル!$C$8,IF(設定!$C$8="パターン②（家庭軽減型）",料金テーブル!$D$8,料金テーブル!$E$8)) -> 160 | H9: =IF(設定!$C$8="パターン①（標準型）",料金テーブル!$C$8,IF(設定!$C$8="パターン②（家庭軽減型）",料金テーブル!$D$8,料金テーブル!$E$8)) -> 160 | I9: =IF(設定!$C$8="パターン①（標準型）",料金テーブル!$C$8,IF(設定!$C$8="パターン②（家庭軽減型）",料金テーブル!$D$8,料金テーブル!$E$8)) -> 160 | J9: =IF(設定!$C$8="パターン①（標準型）",料金テーブル!$C$8,IF(設定!$C$8="パターン②（家庭軽減型）",料金テーブル!$D$8,料金テーブル!$E$8)) -> 160 | K9: =IF(設定!$C$8="パターン①（標準型）",料金テーブル!$C$8,IF(設定!$C$8="パターン②（家庭軽減型）",料金テーブル!$D$8,料金テーブル!$E$8)) -> 160
A10: 41〜50㎥ | B10: =料金テーブル!$B$9 -> 130 | C10: =IF(設定!$C$10="2か年",ROUND((料金テーブル!$B$9+IF(設定!$C$8="パターン①（標準型）",料金テーブル!$C$9,IF(設定!$C$8="パターン②（家庭軽減型）",料金テーブル!$D$9,料金テーブル!$E$9)))/2,0),IF(設定!$C$8="パターン①（標準型）",'段階単価(3か年)'!$B$10,IF(設定!$C$8="パターン②（家庭軽減型）",'段階単価(3か年)'!$B$22,'段階単価(3か年)'!$B$34))) -> 140 | D10: =IF(設定!$C$10="2か年",IF(設定!$C$8="パターン①（標準型）",料金テーブル!$C$9,IF(設定!$C$8="パターン②（家庭軽減型）",料金テーブル!$D$9,料金テーブル!$E$9)),IF(設定!$C$8="パターン①（標準型）",'段階単価(3か年)'!$C$10,IF(設定!$C$8="パターン②（家庭軽減型）",'段階単価(3か年)'!$C$22,'段階単価(3か年)'!$C$34))) -> 150 | E10: =IF(設定!$C$8="パターン①（標準型）",料金テーブル!$C$9,IF(設定!$C$8="パターン②（家庭軽減型）",料金テーブル!$D$9,料金テーブル!$E$9)) -> 165 | F10: =IF(設定!$C$8="パターン①（標準型）",料金テーブル!$C$9,IF(設定!$C$8="パターン②（家庭軽減型）",料金テーブル!$D$9,料金テーブル!$E$9)) -> 165 | G10: =IF(設定!$C$8="パターン①（標準型）",料金テーブル!$C$9,IF(設定!$C$8="パターン②（家庭軽減型）",料金テーブル!$D$9,料金テーブル!$E$9)) -> 165 | H10: =IF(設定!$C$8="パターン①（標準型）",料金テーブル!$C$9,IF(設定!$C$8="パターン②（家庭軽減型）",料金テーブル!$D$9,料金テーブル!$E$9)) -> 165 | I10: =IF(設定!$C$8="パターン①（標準型）",料金テーブル!$C$9,IF(設定!$C$8="パターン②（家庭軽減型）",料金テーブル!$D$9,料金テーブル!$E$9)) -> 165 | J10: =IF(設定!$C$8="パターン①（標準型）",料金テーブル!$C$9,IF(設定!$C$8="パターン②（家庭軽減型）",料金テーブル!$D$9,料金テーブル!$E$9)) -> 165 | K10: =IF(設定!$C$8="パターン①（標準型）",料金テーブル!$C$9,IF(設定!$C$8="パターン②（家庭軽減型）",料金テーブル!$D$9,料金テーブル!$E$9)) -> 165
A11: 51〜70㎥ | B11: =料金テーブル!$B$10 -> 140 | C11: =IF(設定!$C$10="2か年",ROUND((料金テーブル!$B$10+IF(設定!$C$8="パターン①（標準型）",料金テーブル!$C$10,IF(設定!$C$8="パターン②（家庭軽減型）",料金テーブル!$D$10,料金テーブル!$E$10)))/2,0),IF(設定!$C$8="パターン①（標準型）",'段階単価(3か年)'!$B$11,IF(設定!$C$8="パターン②（家庭軽減型）",'段階単価(3か年)'!$B$23,'段階単価(3か年)'!$B$35))) -> 150 | D11: =IF(設定!$C$10="2か年",IF(設定!$C$8="パターン①（標準型）",料金テーブル!$C$10,IF(設定!$C$8="パターン②（家庭軽減型）",料金テーブル!$D$10,料金テーブル!$E$10)),IF(設定!$C$8="パターン①（標準型）",'段階単価(3か年)'!$C$11,IF(設定!$C$8="パターン②（家庭軽減型）",'段階単価(3か年)'!$C$23,'段階単価(3か年)'!$C$35))) -> 160 | E11: =IF(設定!$C$8="パターン①（標準型）",料金テーブル!$C$10,IF(設定!$C$8="パターン②（家庭軽減型）",料金テーブル!$D$10,料金テーブル!$E$10)) -> 175 | F11: =IF(設定!$C$8="パターン①（標準型）",料金テーブル!$C$10,IF(設定!$C$8="パターン②（家庭軽減型）",料金テーブル!$D$10,料金テーブル!$E$10)) -> 175 | G11: =IF(設定!$C$8="パターン①（標準型）",料金テーブル!$C$10,IF(設定!$C$8="パターン②（家庭軽減型）",料金テーブル!$D$10,料金テーブル!$E$10)) -> 175 | H11: =IF(設定!$C$8="パターン①（標準型）",料金テーブル!$C$10,IF(設定!$C$8="パターン②（家庭軽減型）",料金テーブル!$D$10,料金テーブル!$E$10)) -> 175 | I11: =IF(設定!$C$8="パターン①（標準型）",料金テーブル!$C$10,IF(設定!$C$8="パターン②（家庭軽減型）",料金テーブル!$D$10,料金テーブル!$E$10)) -> 175 | J11: =IF(設定!$C$8="パターン①（標準型）",料金テーブル!$C$10,IF(設定!$C$8="パターン②（家庭軽減型）",料金テーブル!$D$10,料金テーブル!$E$10)) -> 175 | K11: =IF(設定!$C$8="パターン①（標準型）",料金テーブル!$C$10,IF(設定!$C$8="パターン②（家庭軽減型）",料金テーブル!$D$10,料金テーブル!$E$10)) -> 175
A12: 71〜100㎥ | B12: =料金テーブル!$B$11 -> 140 | C12: =IF(設定!$C$10="2か年",ROUND((料金テーブル!$B$11+IF(設定!$C$8="パターン①（標準型）",料金テーブル!$C$11,IF(設定!$C$8="パターン②（家庭軽減型）",料金テーブル!$D$11,料金テーブル!$E$11)))/2,0),IF(設定!$C$8="パターン①（標準型）",'段階単価(3か年)'!$B$12,IF(設定!$C$8="パターン②（家庭軽減型）",'段階単価(3か年)'!$B$24,'段階単価(3か年)'!$B$36))) -> 155 | D12: =IF(設定!$C$10="2か年",IF(設定!$C$8="パターン①（標準型）",料金テーブル!$C$11,IF(設定!$C$8="パターン②（家庭軽減型）",料金テーブル!$D$11,料金テーブル!$E$11)),IF(設定!$C$8="パターン①（標準型）",'段階単価(3か年)'!$C$12,IF(設定!$C$8="パターン②（家庭軽減型）",'段階単価(3か年)'!$C$24,'段階単価(3か年)'!$C$36))) -> 170 | E12: =IF(設定!$C$8="パターン①（標準型）",料金テーブル!$C$11,IF(設定!$C$8="パターン②（家庭軽減型）",料金テーブル!$D$11,料金テーブル!$E$11)) -> 185 | F12: =IF(設定!$C$8="パターン①（標準型）",料金テーブル!$C$11,IF(設定!$C$8="パターン②（家庭軽減型）",料金テーブル!$D$11,料金テーブル!$E$11)) -> 185 | G12: =IF(設定!$C$8="パターン①（標準型）",料金テーブル!$C$11,IF(設定!$C$8="パターン②（家庭軽減型）",料金テーブル!$D$11,料金テーブル!$E$11)) -> 185 | H12: =IF(設定!$C$8="パターン①（標準型）",料金テーブル!$C$11,IF(設定!$C$8="パターン②（家庭軽減型）",料金テーブル!$D$11,料金テーブル!$E$11)) -> 185 | I12: =IF(設定!$C$8="パターン①（標準型）",料金テーブル!$C$11,IF(設定!$C$8="パターン②（家庭軽減型）",料金テーブル!$D$11,料金テーブル!$E$11)) -> 185 | J12: =IF(設定!$C$8="パターン①（標準型）",料金テーブル!$C$11,IF(設定!$C$8="パターン②（家庭軽減型）",料金テーブル!$D$11,料金テーブル!$E$11)) -> 185 | K12: =IF(設定!$C$8="パターン①（標準型）",料金テーブル!$C$11,IF(設定!$C$8="パターン②（家庭軽減型）",料金テーブル!$D$11,料金テーブル!$E$11)) -> 185
A13: 101〜150㎥ | B13: =料金テーブル!$B$12 -> 140 | C13: =IF(設定!$C$10="2か年",ROUND((料金テーブル!$B$12+IF(設定!$C$8="パターン①（標準型）",料金テーブル!$C$12,IF(設定!$C$8="パターン②（家庭軽減型）",料金テーブル!$D$12,料金テーブル!$E$12)))/2,0),IF(設定!$C$8="パターン①（標準型）",'段階単価(3か年)'!$B$13,IF(設定!$C$8="パターン②（家庭軽減型）",'段階単価(3か年)'!$B$25,'段階単価(3か年)'!$B$37))) -> 160 | D13: =IF(設定!$C$10="2か年",IF(設定!$C$8="パターン①（標準型）",料金テーブル!$C$12,IF(設定!$C$8="パターン②（家庭軽減型）",料金テーブル!$D$12,料金テーブル!$E$12)),IF(設定!$C$8="パターン①（標準型）",'段階単価(3か年)'!$C$13,IF(設定!$C$8="パターン②（家庭軽減型）",'段階単価(3か年)'!$C$25,'段階単価(3か年)'!$C$37))) -> 180 | E13: =IF(設定!$C$8="パターン①（標準型）",料金テーブル!$C$12,IF(設定!$C$8="パターン②（家庭軽減型）",料金テーブル!$D$12,料金テーブル!$E$12)) -> 205 | F13: =IF(設定!$C$8="パターン①（標準型）",料金テーブル!$C$12,IF(設定!$C$8="パターン②（家庭軽減型）",料金テーブル!$D$12,料金テーブル!$E$12)) -> 205 | G13: =IF(設定!$C$8="パターン①（標準型）",料金テーブル!$C$12,IF(設定!$C$8="パターン②（家庭軽減型）",料金テーブル!$D$12,料金テーブル!$E$12)) -> 205 | H13: =IF(設定!$C$8="パターン①（標準型）",料金テーブル!$C$12,IF(設定!$C$8="パターン②（家庭軽減型）",料金テーブル!$D$12,料金テーブル!$E$12)) -> 205 | I13: =IF(設定!$C$8="パターン①（標準型）",料金テーブル!$C$12,IF(設定!$C$8="パターン②（家庭軽減型）",料金テーブル!$D$12,料金テーブル!$E$12)) -> 205 | J13: =IF(設定!$C$8="パターン①（標準型）",料金テーブル!$C$12,IF(設定!$C$8="パターン②（家庭軽減型）",料金テーブル!$D$12,料金テーブル!$E$12)) -> 205 | K13: =IF(設定!$C$8="パターン①（標準型）",料金テーブル!$C$12,IF(設定!$C$8="パターン②（家庭軽減型）",料金テーブル!$D$12,料金テーブル!$E$12)) -> 205
A14: 151㎥〜 | B14: =料金テーブル!$B$13 -> 160 | C14: =IF(設定!$C$10="2か年",ROUND((料金テーブル!$B$13+IF(設定!$C$8="パターン①（標準型）",料金テーブル!$C$13,IF(設定!$C$8="パターン②（家庭軽減型）",料金テーブル!$D$13,料金テーブル!$E$13)))/2,0),IF(設定!$C$8="パターン①（標準型）",'段階単価(3か年)'!$B$14,IF(設定!$C$8="パターン②（家庭軽減型）",'段階単価(3か年)'!$B$26,'段階単価(3か年)'!$B$38))) -> 180 | D14: =IF(設定!$C$10="2か年",IF(設定!$C$8="パターン①（標準型）",料金テーブル!$C$13,IF(設定!$C$8="パターン②（家庭軽減型）",料金テーブル!$D$13,料金テーブル!$E$13)),IF(設定!$C$8="パターン①（標準型）",'段階単価(3か年)'!$C$14,IF(設定!$C$8="パターン②（家庭軽減型）",'段階単価(3か年)'!$C$26,'段階単価(3か年)'!$C$38))) -> 200 | E14: =IF(設定!$C$8="パターン①（標準型）",料金テーブル!$C$13,IF(設定!$C$8="パターン②（家庭軽減型）",料金テーブル!$D$13,料金テーブル!$E$13)) -> 225 | F14: =IF(設定!$C$8="パターン①（標準型）",料金テーブル!$C$13,IF(設定!$C$8="パターン②（家庭軽減型）",料金テーブル!$D$13,料金テーブル!$E$13)) -> 225 | G14: =IF(設定!$C$8="パターン①（標準型）",料金テーブル!$C$13,IF(設定!$C$8="パターン②（家庭軽減型）",料金テーブル!$D$13,料金テーブル!$E$13)) -> 225 | H14: =IF(設定!$C$8="パターン①（標準型）",料金テーブル!$C$13,IF(設定!$C$8="パターン②（家庭軽減型）",料金テーブル!$D$13,料金テーブル!$E$13)) -> 225 | I14: =IF(設定!$C$8="パターン①（標準型）",料金テーブル!$C$13,IF(設定!$C$8="パターン②（家庭軽減型）",料金テーブル!$D$13,料金テーブル!$E$13)) -> 225 | J14: =IF(設定!$C$8="パターン①（標準型）",料金テーブル!$C$13,IF(設定!$C$8="パターン②（家庭軽減型）",料金テーブル!$D$13,料金テーブル!$E$13)) -> 225 | K14: =IF(設定!$C$8="パターン①（標準型）",料金テーブル!$C$13,IF(設定!$C$8="パターン②（家庭軽減型）",料金テーブル!$D$13,料金テーブル!$E$13)) -> 225
A16: ■ 調定口数・有収水量推計
A17: 調定口数（口） | B17: =IF(設定!$C$6="人口ビジョン",2558,2563) -> 2563 | C17: =IF(設定!$C$6="人口ビジョン",2541,2545) -> 2545 | D17: =IF(設定!$C$6="人口ビジョン",2523,2527) -> 2527 | E17: =IF(設定!$C$6="人口ビジョン",2506,2508) -> 2508 | F17: =IF(設定!$C$6="人口ビジョン",2488,2490) -> 2490 | G17: =IF(設定!$C$6="人口ビジョン",2471,2472) -> 2472 | H17: =IF(設定!$C$6="人口ビジョン",2453,2452) -> 2452 | I17: =IF(設定!$C$6="人口ビジョン",2435,2432) -> 2432 | J17: =IF(設定!$C$6="人口ビジョン",2417,2412) -> 2412 | K17: =IF(設定!$C$6="人口ビジョン",2398,2391) -> 2391
A18: 有収水量合計（㎥） | B18: =IF(設定!$C$6="人口ビジョン",452089,452992) -> 452992 | C18: =IF(設定!$C$6="人口ビジョン",449052,449791) -> 449791 | D18: =IF(設定!$C$6="人口ビジョン",445934,446591) -> 446591 | E18: =IF(設定!$C$6="人口ビジョン",442898,443308) -> 443308 | F18: =IF(設定!$C$6="人口ビジョン",439779,440108) -> 440108 | G18: =IF(設定!$C$6="人口ビジョン",436743,436989) -> 436989 | H18: =IF(設定!$C$6="人口ビジョン",433542,433378) -> 433378 | I18: =IF(設定!$C$6="人口ビジョン",430342,429767) -> 429767 | J18: =IF(設定!$C$6="人口ビジョン",427141,426239) -> 426239 | K18: =IF(設定!$C$6="人口ビジョン",423859,422628) -> 422628
A20: ■ 区分別有収水量（㎥） ※R6比率固定
A21: 基本(0〜10㎥) | B21: =ROUND(B18*0.03184,0) -> 14423 | C21: =ROUND(C18*0.03184,0) -> 14321 | D21: =ROUND(D18*0.03184,0) -> 14219 | E21: =ROUND(E18*0.03184,0) -> 14115 | F21: =ROUND(F18*0.03184,0) -> 14013 | G21: =ROUND(G18*0.03184,0) -> 13914 | H21: =ROUND(H18*0.03184,0) -> 13799 | I21: =ROUND(I18*0.03184,0) -> 13684 | ... K21: =ROUND(K18*0.03184,0) -> 13456
A22: 11〜20㎥ | B22: =ROUND(B18*0.254673,0) -> 115365 | C22: =ROUND(C18*0.254673,0) -> 114550 | D22: =ROUND(D18*0.254673,0) -> 113735 | E22: =ROUND(E18*0.254673,0) -> 112899 | F22: =ROUND(F18*0.254673,0) -> 112084 | G22: =ROUND(G18*0.254673,0) -> 111289 | H22: =ROUND(H18*0.254673,0) -> 110370 | I22: =ROUND(I18*0.254673,0) -> 109450 | ... K22: =ROUND(K18*0.254673,0) -> 107632
A23: 21〜30㎥ | B23: =ROUND(B18*0.18661,0) -> 84533 | C23: =ROUND(C18*0.18661,0) -> 83935 | D23: =ROUND(D18*0.18661,0) -> 83338 | E23: =ROUND(E18*0.18661,0) -> 82726 | F23: =ROUND(F18*0.18661,0) -> 82129 | G23: =ROUND(G18*0.18661,0) -> 81547 | H23: =ROUND(H18*0.18661,0) -> 80873 | I23: =ROUND(I18*0.18661,0) -> 80199 | ... K23: =ROUND(K18*0.18661,0) -> 78867
A24: 31〜40㎥ | B24: =ROUND(B18*0.115417,0) -> 52283 | C24: =ROUND(C18*0.115417,0) -> 51914 | D24: =ROUND(D18*0.115417,0) -> 51544 | E24: =ROUND(E18*0.115417,0) -> 51165 | F24: =ROUND(F18*0.115417,0) -> 50796 | G24: =ROUND(G18*0.115417,0) -> 50436 | H24: =ROUND(H18*0.115417,0) -> 50019 | I24: =ROUND(I18*0.115417,0) -> 49602 | ... K24: =ROUND(K18*0.115417,0) -> 48778
A25: 41〜50㎥ | B25: =ROUND(B18*0.063915,0) -> 28953 | C25: =ROUND(C18*0.063915,0) -> 28748 | D25: =ROUND(D18*0.063915,0) -> 28544 | E25: =ROUND(E18*0.063915,0) -> 28334 | F25: =ROUND(F18*0.063915,0) -> 28130 | G25: =ROUND(G18*0.063915,0) -> 27930 | H25: =ROUND(H18*0.063915,0) -> 27699 | I25: =ROUND(I18*0.063915,0) -> 27469 | ... K25: =ROUND(K18*0.063915,0) -> 27012
A26: 51〜70㎥ | B26: =ROUND(B18*0.043817,0) -> 19849 | C26: =ROUND(C18*0.043817,0) -> 19708 | D26: =ROUND(D18*0.043817,0) -> 19568 | E26: =ROUND(E18*0.043817,0) -> 19424 | F26: =ROUND(F18*0.043817,0) -> 19284 | G26: =ROUND(G18*0.043817,0) -> 19148 | H26: =ROUND(H18*0.043817,0) -> 18989 | I26: =ROUND(I18*0.043817,0) -> 18831 | ... K26: =ROUND(K18*0.043817,0) -> 18518
A27: 71〜100㎥ | B27: =ROUND(B18*0.026321,0) -> 11923 | C27: =ROUND(C18*0.026321,0) -> 11839 | D27: =ROUND(D18*0.026321,0) -> 11755 | E27: =ROUND(E18*0.026321,0) -> 11668 | F27: =ROUND(F18*0.026321,0) -> 11584 | G27: =ROUND(G18*0.026321,0) -> 11502 | H27: =ROUND(H18*0.026321,0) -> 11407 | I27: =ROUND(I18*0.026321,0) -> 11312 | ... K27: =ROUND(K18*0.026321,0) -> 11124
A28: 101〜150㎥ | B28: =ROUND(B18*0.00904,0) -> 4095 | C28: =ROUND(C18*0.00904,0) -> 4066 | D28: =ROUND(D18*0.00904,0) -> 4037 | E28: =ROUND(E18*0.00904,0) -> 4008 | F28: =ROUND(F18*0.00904,0) -> 3979 | G28: =ROUND(G18*0.00904,0) -> 3950 | H28: =ROUND(H18*0.00904,0) -> 3918 | I28: =ROUND(I18*0.00904,0) -> 3885 | ... K28: =ROUND(K18*0.00904,0) -> 3821
A29: 151㎥〜 | B29: =ROUND(B18*0.021102,0) -> 9559 | C29: =ROUND(C18*0.021102,0) -> 9491 | D29: =ROUND(D18*0.021102,0) -> 9424 | E29: =ROUND(E18*0.021102,0) -> 9355 | F29: =ROUND(F18*0.021102,0) -> 9287 | G29: =ROUND(G18*0.021102,0) -> 9221 | H29: =ROUND(H18*0.021102,0) -> 9145 | I29: =ROUND(I18*0.021102,0) -> 9069 | ... K29: =ROUND(K18*0.021102,0) -> 8918
A31: ■ 使用料収入算定（千円）
A32: 基本使用料収入 | B32: =ROUND(B6*B17*6/1000,1) -> 15378 | C32: =ROUND(C6*C17*6/1000,1) -> 17560.5 | D32: =ROUND(D6*D17*6/1000,1) -> 19710.6 | E32: =ROUND(E6*E17*6/1000,1) -> 22572 | F32: =ROUND(F6*F17*6/1000,1) -> 22410 | G32: =ROUND(G6*G17*6/1000,1) -> 22248 | H32: =ROUND(H6*H17*6/1000,1) -> 22068 | I32: =ROUND(I6*I17*6/1000,1) -> 21888 | ... K32: =ROUND(K6*K17*6/1000,1) -> 21519
A33: 11〜20㎥ | B33: =ROUND(B7*B22/1000,1) -> 13843.8 | C33: =ROUND(C7*C22/1000,1) -> 14891.5 | D33: =ROUND(D7*D22/1000,1) -> 15922.9 | E33: =ROUND(E7*E22/1000,1) -> 16934.9 | F33: =ROUND(F7*F22/1000,1) -> 16812.6 | G33: =ROUND(G7*G22/1000,1) -> 16693.4 | H33: =ROUND(H7*H22/1000,1) -> 16555.5 | I33: =ROUND(I7*I22/1000,1) -> 16417.5 | ... K33: =ROUND(K7*K22/1000,1) -> 16144.8
A34: 21〜30㎥ | B34: =ROUND(B8*B23/1000,1) -> 10144 | C34: =ROUND(C8*C23/1000,1) -> 10911.6 | D34: =ROUND(D8*D23/1000,1) -> 11667.3 | E34: =ROUND(E8*E23/1000,1) -> 12822.5 | F34: =ROUND(F8*F23/1000,1) -> 12730 | G34: =ROUND(G8*G23/1000,1) -> 12639.8 | H34: =ROUND(H8*H23/1000,1) -> 12535.3 | I34: =ROUND(I8*I23/1000,1) -> 12430.8 | ... K34: =ROUND(K8*K23/1000,1) -> 12224.4
A35: 31〜40㎥ | B35: =ROUND(B9*B24/1000,1) -> 6796.8 | C35: =ROUND(C9*C24/1000,1) -> 7268 | D35: =ROUND(D9*D24/1000,1) -> 7731.6 | E35: =ROUND(E9*E24/1000,1) -> 8186.4 | F35: =ROUND(F9*F24/1000,1) -> 8127.4 | G35: =ROUND(G9*G24/1000,1) -> 8069.8 | H35: =ROUND(H9*H24/1000,1) -> 8003 | I35: =ROUND(I9*I24/1000,1) -> 7936.3 | ... K35: =ROUND(K9*K24/1000,1) -> 7804.5
A36: 41〜50㎥ | B36: =ROUND(B10*B25/1000,1) -> 3763.9 | C36: =ROUND(C10*C25/1000,1) -> 4024.7 | D36: =ROUND(D10*D25/1000,1) -> 4281.6 | E36: =ROUND(E10*E25/1000,1) -> 4675.1 | F36: =ROUND(F10*F25/1000,1) -> 4641.5 | G36: =ROUND(G10*G25/1000,1) -> 4608.5 | H36: =ROUND(H10*H25/1000,1) -> 4570.3 | I36: =ROUND(I10*I25/1000,1) -> 4532.4 | ... K36: =ROUND(K10*K25/1000,1) -> 4457
A37: 51〜70㎥ | B37: =ROUND(B11*B26/1000,1) -> 2778.9 | C37: =ROUND(C11*C26/1000,1) -> 2956.2 | D37: =ROUND(D11*D26/1000,1) -> 3130.9 | E37: =ROUND(E11*E26/1000,1) -> 3399.2 | F37: =ROUND(F11*F26/1000,1) -> 3374.7 | G37: =ROUND(G11*G26/1000,1) -> 3350.9 | H37: =ROUND(H11*H26/1000,1) -> 3323.1 | I37: =ROUND(I11*I26/1000,1) -> 3295.4 | ... K37: =ROUND(K11*K26/1000,1) -> 3240.7
A38: 71〜100㎥ | B38: =ROUND(B12*B27/1000,1) -> 1669.2 | C38: =ROUND(C12*C27/1000,1) -> 1835 | D38: =ROUND(D12*D27/1000,1) -> 1998.4 | E38: =ROUND(E12*E27/1000,1) -> 2158.6 | F38: =ROUND(F12*F27/1000,1) -> 2143 | G38: =ROUND(G12*G27/1000,1) -> 2127.9 | H38: =ROUND(H12*H27/1000,1) -> 2110.3 | I38: =ROUND(I12*I27/1000,1) -> 2092.7 | ... K38: =ROUND(K12*K27/1000,1) -> 2057.9
A39: 101〜150㎥ | B39: =ROUND(B13*B28/1000,1) -> 573.3 | C39: =ROUND(C13*C28/1000,1) -> 650.6 | D39: =ROUND(D13*D28/1000,1) -> 726.7 | E39: =ROUND(E13*E28/1000,1) -> 821.6 | F39: =ROUND(F13*F28/1000,1) -> 815.7 | G39: =ROUND(G13*G28/1000,1) -> 809.8 | H39: =ROUND(H13*H28/1000,1) -> 803.2 | I39: =ROUND(I13*I28/1000,1) -> 796.4 | ... K39: =ROUND(K13*K28/1000,1) -> 783.3
A40: 151㎥〜 | B40: =ROUND(B14*B29/1000,1) -> 1529.4 | C40: =ROUND(C14*C29/1000,1) -> 1708.4 | D40: =ROUND(D14*D29/1000,1) -> 1884.8 | E40: =ROUND(E14*E29/1000,1) -> 2104.9 | F40: =ROUND(F14*F29/1000,1) -> 2089.6 | G40: =ROUND(G14*G29/1000,1) -> 2074.7 | H40: =ROUND(H14*H29/1000,1) -> 2057.6 | I40: =ROUND(I14*I29/1000,1) -> 2040.5 | ... K40: =ROUND(K14*K29/1000,1) -> 2006.6
A41: 超過使用料収入 小計 | B41: =SUM(B33:B40) -> 41099.3 | C41: =SUM(C33:C40) -> 44246 | D41: =SUM(D33:D40) -> 47344.2 | E41: =SUM(E33:E40) -> 51103.2 | F41: =SUM(F33:F40) -> 50734.5 | G41: =SUM(G33:G40) -> 50374.8 | H41: =SUM(H33:H40) -> 49958.3 | I41: =SUM(I33:I40) -> 49542 | ... K41: =SUM(K33:K40) -> 48719.2
A42: 使用料収入 合計（税抜き） | B42: =ROUND(B32+B41,0) -> 56477 | C42: =ROUND(C32+C41,0) -> 61807 | D42: =ROUND(D32+D41,0) -> 67055 | E42: =ROUND(E32+E41,0) -> 73675 | F42: =ROUND(F32+F41,0) -> 73145 | G42: =ROUND(G32+G41,0) -> 72623 | H42: =ROUND(H32+H41,0) -> 72026 | I42: =ROUND(I32+I41,0) -> 71430 | ... K42: =ROUND(K32+K41,0) -> 70238
A44: ■ R6実績補正
A45: R6実績 使用料収入（千円） | B45: 61104
...

Sheet 財政計画（ベース）
A1: ３条 収益的収支（令和7年度～令和16年度） 公共下水道事業
A2: =設定!C8&" "&設定!C10&"改定 （"&設定!C6&"推移） ※使用料収入は設定シート連動" -> パターン①（標準型） 3か年改定 （社人研推移） ※使用料収入は設定シート連動
A3: 区 分 | B3: 令和7年度 | C3: 令和8年度 | D3: 令和9年度 | E3: 令和10年度 | F3: 令和11年度 | G3: 令和12年度 | H3: 令和13年度 | I3: 令和14年度 | J3: 令和15年度 | K3: 令和16年度
A4: （単位：千円） | B4: 2025 | C4: 2026 | D4: 2027 | E4: 2028 | F4: 2029 | G4: 2030 | H4: 2031 | I4: 2032 | J4: 2033 | K4: 2034
A5: 【収入の部】
A6: 営業収益 (A) | B6: =B7+B8+B9 -> 58054 | C6: =C7+C8+C9 -> 63571 | D6: =D7+D8+D9 -> 69022 | E6: =E7+E8+E9 -> 75743 | F6: =F7+F8+F9 -> 75220 | G6: =G7+G8+G9 -> 74693 | H6: =H7+H8+H9 -> 74069 | I6: =I7+I8+I9 -> 73463 | ... K6: =K7+K8+K9 -> 72240
A7: (1) 使用料収入 | B7: =使用料算定!B49 -> 57895 | C7: =使用料算定!C49 -> 63359 | D7: =使用料算定!D49 -> 68739 | E7: =使用料算定!E49 -> 75525 | F7: =使用料算定!F49 -> 74982 | G7: =使用料算定!G49 -> 74447 | H7: =使用料算定!H49 -> 73835 | I7: =使用料算定!I49 -> 73224 | ... K7: =使用料算定!K49 -> 72002
A8: (2) 雨水処理負担金 | B8: 0 | C8: 0 | D8: 0 | E8: 0 | F8: 0 | G8: 0 | H8: 0 | I8: 0 | J8: 0 | K8: 0
A9: (3) その他 | B9: 159 | C9: 212 | D9: 283 | E9: 218 | F9: 238 | G9: 246 | H9: 234 | I9: 239 | J9: 240 | K9: 238
A10: 営業外収益 | B10: =B11+B12+B13 -> 478588 | C10: =C11+C12+C13 -> 479130 | D10: =D11+D12+D13 -> 390774 | E10: =E11+E12+E13 -> 323775 | F10: =F11+F12+F13 -> 310672 | G10: =G11+G12+G13 -> 310608 | H10: =H11+H12+H13 -> 311431 | I10: =I11+I12+I13 -> 312227 | ... K10: =K11+K12+K13 -> 312117
A11: (1) 補助金 | B11: 151133 | C11: 151437 | D11: 169454 | E11: 183394 | F11: 186588 | G11: 186657 | H11: 186749 | I11: 186849 | J11: 187381 | K11: 188114
A12: (2) 長期前受金戻入 | B12: 309898 | C12: 311906 | D12: 208677 | E12: 125052 | F12: 109497 | G12: 109765 | H12: 109981 | I12: 110887 | J12: 110446 | K12: 109452
A13: (3) その他 | B13: 17557 | C13: 15787 | D13: 12643 | E13: 15329 | F13: 14587 | G13: 14186 | H13: 14701 | I13: 14491 | J13: 14460 | K13: 14551
A14: 経常収入 (C) | B14: =B6+B10 -> 536642 | C14: =C6+C10 -> 542701 | D14: =D6+D10 -> 459796 | E14: =E6+E10 -> 399518 | F14: =F6+F10 -> 385892 | G14: =G6+G10 -> 385301 | H14: =H6+H10 -> 385500 | I14: =I6+I10 -> 385690 | ... K14: =K6+K10 -> 384357
A16: 【支出の部】
A17: 営業費用 | B17: =B18+B19+B24 -> 520872 | C17: =C18+C19+C24 -> 530785 | D17: =D18+D19+D24 -> 445840 | E17: =E18+E19+E24 -> 373726 | F17: =F18+F19+F24 -> 363986 | G17: =G18+G19+G24 -> 365356 | H17: =H18+H19+H24 -> 365923 | I17: =I18+I19+I24 -> 368372 | ... K17: =K18+K19+K24 -> 367149
A18: (1) 職員給与費 | B18: 5936 | C18: 5788 | D18: 5793 | E18: 5839 | F18: 5806 | G18: 5813 | H18: 5819 | I18: 5813 | J18: 5815 | K18: 5816
A19: (2) 経費 | B19: 162395 | C19: 167240 | D19: 171181 | E19: 168553 | F19: 170733 | G19: 171855 | H19: 172110 | I19: 173294 | J19: 174163 | K19: 174936
A20: 動力費 | B20: 4975 | C20: 4724 | D20: 4898 | E20: 4859 | F20: 4927 | G20: 4942 | H20: 4984 | I20: 5013 | J20: 5048 | K20: 5081
A21: 修繕費 | B21: 912 | C21: 983 | D21: 1223 | E21: 1050 | F21: 1096 | G21: 1134 | H21: 1104 | I21: 1122 | J21: 1131 | K21: 1131
A22: 材料費 | B22: 1228 | C22: 1197 | D22: 1206 | E22: 1222 | F22: 1220 | G22: 1228 | H22: 1236 | I22: 1240 | J22: 1247 | K22: 1253
A23: その他 | B23: 155280 | C23: 160337 | D23: 163854 | E23: 161422 | F23: 163490 | G23: 164551 | H23: 164786 | I23: 165918 | J23: 166736 | K23: 167472
A24: (3) 減価償却費 | B24: 352541 | C24: 357757 | D24: 268866 | E24: 199334 | F24: 187447 | G24: 187688 | H24: 187994 | I24: 189265 | J24: 188456 | K24: 186397
A25: 営業外費用 | B25: =B26+B27 -> 24189 | C25: =C26+C27 -> 28352 | D25: =D26+D27 -> 21428 | E25: =E26+E27 -> 21542 | F25: =F26+F27 -> 20337 | G25: =G26+G27 -> 19272 | H25: =H26+H27 -> 18037 | I25: =I26+I27 -> 17018 | ... K25: =K26+K27 -> 15309
A26: (1) 支払利息 | B26: 22189 | C26: 26352 | D26: 19428 | E26: 19542 | F26: 18337 | G26: 17272 | H26: 16037 | I26: 15018 | J26: 14145 | K26: 13309
A27: (2) その他 | B27: 2000 | C27: 2000 | D27: 2000 | E27: 2000 | F27: 2000 | G27: 2000 | H27: 2000 | I27: 2000 | J27: 2000 | K27: 2000
A28: 経常支出 (D) | B28: =B17+B25 -> 545061 | C28: =C17+C25 -> 559137 | D28: =D17+D25 -> 467268 | E28: =E17+E25 -> 395268 | F28: =F17+F25 -> 384323 | G28: =G17+G25 -> 384628 | H28: =H17+H25 -> 383960 | I28: =I17+I25 -> 385390 | ... K28: =K17+K25 -> 382458
A30: 経常損益 (C)-(D) | B30: =B14-B28 -> -8419 | C30: =C14-C28 -> -16436 | D30: =D14-D28 -> -7472 | E30: =E14-E28 -> 4250 | F30: =F14-F28 -> 1569 | G30: =G14-G28 -> 673 | H30: =H14-H28 -> 1540 | I30: =I14-I28 -> 300 | ... K30: =K14-K28 -> 1899
A32: 経常収支比率 | B32: =IF(B28=0,"-",B14/B28) -> 0.98455402 | C32: =IF(C28=0,"-",C14/C28) -> 0.9706047 | D32: =IF(D28=0,"-",D14/D28) -> 0.98400918 | E32: =IF(E28=0,"-",E14/E28) -> 1.0107522 | F32: =IF(F28=0,"-",F14/F28) -> 1.0040825 | G32: =IF(G28=0,"-",G14/G28) -> 1.0017497 | H32: =IF(H28=0,"-",H14/H28) -> 1.0040108 | I32: =IF(I28=0,"-",I14/I28) -> 1.0007784 | ... K32: =IF(K28=0,"-",K14/K28) -> 1.0049653
A33: 汚水処理費 | B33: =B18+B19 -> 168331 | C33: =C18+C19 -> 173028 | D33: =D18+D19 -> 176974 | E33: =E18+E19 -> 174392 | F33: =F18+F19 -> 176539 | G33: =G18+G19 -> 177668 | H33: =H18+H19 -> 177929 | I33: =I18+I19 -> 179107 | ... K33: =K18+K19 -> 180752
A34: 経費回収率 | B34: =IF(B33=0,"-",B7/B33) -> 0.34393546 | C34: =IF(C33=0,"-",C7/C33) -> 0.36617773 | D34: =IF(D33=0,"-",D7/D33) -> 0.38841299 | E34: =IF(E33=0,"-",E7/E33) -> 0.43307606 | F34: =IF(F33=0,"-",F7/F33) -> 0.42473335 | G34: =IF(G33=0,"-",G7/G33) -> 0.41902312 | H34: =IF(H33=0,"-",H7/H33) -> 0.41496889 | I34: =IF(I33=0,"-",I7/I33) -> 0.40882824 | ... K34: =IF(K33=0,"-",K7/K33) -> 0.39834691
A35: 有収水量（㎥） | B35: =使用料算定!B18 -> 452992 | C35: =使用料算定!C18 -> 449791 | D35: =使用料算定!D18 -> 446591 | E35: =使用料算定!E18 -> 443308 | F35: =使用料算定!F18 -> 440108 | G35: =使用料算定!G18 -> 436989 | H35: =使用料算定!H18 -> 433378 | I35: =使用料算定!I18 -> 429767 | ... K35: =使用料算定!K18 -> 422628

Sheet パターン別比較
A1: パターン別 経常収支比率・経費回収率 比較（公共下水道事業）
A2: ="※使用料収入のみパターンにより変動。その他の費用項目は全パターン共通。"&設定!C6&"推移ベース。" -> ※使用料収入のみパターンにより変動。その他の費用項目は全パターン共通。社人研推移ベース。
A4: 指標 ／ パターン | B4: 令和7年度 | C4: 令和8年度 | D4: 令和9年度 | E4: 令和10年度 | F4: 令和11年度 | G4: 令和12年度 | H4: 令和13年度 | I4: 令和14年度 | J4: 令和15年度 | K4: 令和16年度
A6: 【経常収支比率】
A7: 現行（改定なし） | B7: =(B26+478747)/545061 -> 0.98455402 | C7: =(C26+479342)/559137 -> 0.9601028 | D7: =(D26+391057)/467268 -> 0.95905562 | E7: =(E26+323993)/395268 -> 0.96301497 | F7: =(F26+310910)/384323 -> 0.95533705 | G7: =(G26+310854)/384628 -> 0.95339133 | H7: =(H26+311665)/383960 -> 0.95596677 | I7: =(I26+312466)/385390 -> 0.95330963 | J7: =(J26+312527)/384579 -> 0.95430328 | K7: =(K26+312355)/382458 -> 0.95793264
A8: パターン①（標準型）2か年 | B8: =(B27+478747)/545061 -> 0.98455402 | C8: =(C27+479342)/559137 -> 0.97636179 | D8: =(D27+391057)/467268 -> 1.0001412 | E8: =(E27+323993)/395268 -> 1.0112253 | F8: =(F27+310910)/384323 -> 1.0045639 | G8: =(G27+310854)/384628 -> 1.0022281 | H8: =(H27+311665)/383960 -> 1.0044874 | I8: =(I27+312466)/385390 -> 1.0012481 | J8: =(J27+312527)/384579 -> 1.0019502 | K8: =(K27+312355)/382458 -> 1.0054333
A9: パターン①（標準型）3か年 | B9: =(B28+478747)/545061 -> 0.98455402 | C9: =(C28+479342)/559137 -> 0.97054568 | D9: =(D28+391057)/467268 -> 0.98387007 | E9: =(E28+323993)/395268 -> 1.0112253 | F9: =(F28+310910)/384323 -> 1.0045639 | G9: =(G28+310854)/384628 -> 1.0022281 | H9: =(H28+311665)/383960 -> 1.0044874 | I9: =(I28+312466)/385390 -> 1.0012481 | J9: =(J28+312527)/384579 -> 1.0019502 | K9: =(K28+312355)/382458 -> 1.0054333
A10: パターン②（家庭軽減型）2か年 | B10: =(B29+478747)/545061 -> 0.98455402 | C10: =(C29+479342)/559137 -> 0.98109229 | D10: =(D29+391057)/467268 -> 1.0113853 | E10: =(E29+323993)/395268 -> 1.0244214 | F10: =(F29+310910)/384323 -> 1.0180369 | G10: =(G29+310854)/384628 -> 1.0155969 | H10: =(H29+311665)/383960 -> 1.0177675 | I10: =(I29+312466)/385390 -> 1.0143673 | J10: =(J29+312527)/384579 -> 1.0149878 | K10: =(K29+312355)/382458 -> 1.0184334
A11: パターン②（家庭軽減型）3か年 | B11: =(B30+478747)/545061 -> 0.98455402 | C11: =(C30+479342)/559137 -> 0.97370054 | D11: =(D30+391057)/467268 -> 0.9913647 | E11: =(E30+323993)/395268 -> 1.0244214 | F11: =(F30+310910)/384323 -> 1.0180369 | G11: =(G30+310854)/384628 -> 1.0155969 | H11: =(H30+311665)/383960 -> 1.0177675 | I11: =(I30+312466)/385390 -> 1.0143673 | J11: =(J30+312527)/384579 -> 1.0149878 | K11: =(K30+312355)/382458 -> 1.0184334
A12: パターン④（段階累進型）2か年 | B12: =(B31+478747)/545061 -> 0.98455402 | C12: =(C31+479342)/559137 -> 0.97793922 | D12: =(D31+391057)/467268 -> 1.0038886 | E12: =(E31+323993)/395268 -> 1.0156248 | F12: =(F31+310910)/384323 -> 1.0090549 | G12: =(G31+310854)/384628 -> 1.0066844 | H12: =(H31+311665)/383960 -> 1.008915 | I12: =(I31+312466)/385390 -> 1.0056203 | J12: =(J31+312527)/384579 -> 1.0062978 | K12: =(K31+312355)/382458 -> 1.0097658
A13: パターン④（段階累進型）3か年 | B13: =(B32+478747)/545061 -> 0.98455402 | C13: =(C32+479342)/559137 -> 0.97106791 | D13: =(D32+391057)/467268 -> 0.98511133 | E13: =(E32+323993)/395268 -> 1.0156248 | F13: =(F32+310910)/384323 -> 1.0090549 | G13: =(G32+310854)/384628 -> 1.0066844 | H13: =(H32+311665)/383960 -> 1.008915 | I13: =(I32+312466)/385390 -> 1.0056203 | J13: =(J32+312527)/384579 -> 1.0062978 | K13: =(K32+312355)/382458 -> 1.0097658
A15: 【経費回収率】
A16: 現行（改定なし） | B16: =B26/168331 -> 0.34393546 | C16: =C26/173028 -> 0.33224102 | D16: =D26/176974 -> 0.3225276 | E16: =E26/174392 -> 0.32487729 | F16: =F26/176539 -> 0.31861515 | G16: =G26/177668 -> 0.31433348 | H16: =H26/177929 -> 0.31129271 | I16: =I26/179107 -> 0.30668818 | J16: =J26/179978 -> 0.30269255 | K16: =K26/180752 -> 0.29882934
A17: パターン①（標準型）2か年 | B17: =B27/168331 -> 0.34393546 | C17: =C27/173028 -> 0.38478165 | D17: =D27/176974 -> 0.43100681 | E17: =E27/174392 -> 0.43414836 | F17: =F27/176539 -> 0.42578127 | G17: =G27/177668 -> 0.42005876 | H17: =H27/177929 -> 0.41599739 | I17: =I27/179107 -> 0.40983881 | J17: =J27/179978 -> 0.404505 | K17: =K27/180752 -> 0.39933721
A18: パターン①（標準型）3か年 | B18: =B28/168331 -> 0.34393546 | C18: =C28/173028 -> 0.36598701 | D18: =D28/176974 -> 0.3880457 | E18: =E28/174392 -> 0.43414836 | F18: =F28/176539 -> 0.42578127 | G18: =G28/177668 -> 0.42005876 | H18: =H28/177929 -> 0.41599739 | I18: =I28/179107 -> 0.40983881 | J18: =J28/179978 -> 0.404505 | K18: =K28/180752 -> 0.39933721
A19: パターン②（家庭軽減型）2か年 | B19: =B29/168331 -> 0.34393546 | C19: =C29/173028 -> 0.4000682 | D19: =D29/176974 -> 0.46069479 | E19: =E29/174392 -> 0.46405798 | F19: =F29/176539 -> 0.4551119 | G19: =G29/177668 -> 0.44900038 | H19: =H29/177929 -> 0.44465489 | I19: =I29/179107 -> 0.43806775 | J19: =J29/179978 -> 0.43236396 | K19: =K29/180752 -> 0.42684452
A20: パターン②（家庭軽減型）3か年 | B20: =B30/168331 -> 0.34393546 | C20: =C30/173028 -> 0.37618189 | D20: =D30/176974 -> 0.40783392 | E20: =E30/174392 -> 0.46405798 | F20: =F30/176539 -> 0.4551119 | G20: =G30/177668 -> 0.44900038 | H20: =H30/177929 -> 0.44465489 | I20: =I30/179107 -> 0.43806775 | J20: =J30/179978 -> 0.43236396 | K20: =K30/180752 -> 0.42684452
A21: パターン④（段階累進型）2か年 | B21: =B31/168331 -> 0.34393546 | C21: =C31/173028 -> 0.38987909 | D21: =D31/176974 -> 0.44090092 | E21: =E31/174392 -> 0.44412014 | F21: =F31/176539 -> 0.43555815 | G21: =G31/177668 -> 0.42970597 | H21: =H31/177929 -> 0.42555177 | I21: =I31/179107 -> 0.4192466 | J21: =J31/179978 -> 0.41379502 | K21: =K31/180752 -> 0.40850447
A22: パターン④（段階累進型）3か年 | B22: =B32/168331 -> 0.34393546 | C22: =C32/173028 -> 0.3676746 | D22: =D32/176974 -> 0.39132302 | E22: =E32/174392 -> 0.44412014 | F22: =F32/176539 -> 0.43555815 | G22: =G32/177668 -> 0.42970597 | H22: =H32/177929 -> 0.42555177 | I22: =I32/179107 -> 0.4192466 | J22: =J32/179978 -> 0.41379502 | K22: =K32/180752 -> 0.40850447
A24: 【参考】パターン別 使用料収入（千円）
A25: パターン | B25: 令和7年度 | C25: 令和8年度 | D25: 令和9年度 | E25: 令和10年度 | F25: 令和11年度 | G25: 令和12年度 | H25: 令和13年度 | I25: 令和14年度 | J25: 令和15年度 | K25: 令和16年度
A26: 現行（改定なし） | B26: =IF(設定!$C$6="人口ビジョン",使用料マスタ!D18,使用料マスタ!D19) -> 57895 | C26: =IF(設定!$C$6="人口ビジョン",使用料マスタ!E18,使用料マスタ!E19) -> 57487 | D26: =IF(設定!$C$6="人口ビジョン",使用料マスタ!F18,使用料マスタ!F19) -> 57079 | E26: =IF(設定!$C$6="人口ビジョン",使用料マスタ!G18,使用料マスタ!G19) -> 56656 | F26: =IF(設定!$C$6="人口ビジョン",使用料マスタ!H18,使用料マスタ!H19) -> 56248 | G26: =IF(設定!$C$6="人口ビジョン",使用料マスタ!I18,使用料マスタ!I19) -> 55847 | H26: =IF(設定!$C$6="人口ビジョン",使用料マスタ!J18,使用料マスタ!J19) -> 55388 | I26: =IF(設定!$C$6="人口ビジョン",使用料マスタ!K18,使用料マスタ!K19) -> 54930 | ... K26: =IF(設定!$C$6="人口ビジョン",使用料マスタ!M18,使用料マスタ!M19) -> 54014
A27: パターン①（標準型）2か年 | B27: =IF(設定!$C$6="人口ビジョン",使用料マスタ!D4,使用料マスタ!D10) -> 57895 | C27: =IF(設定!$C$6="人口ビジョン",使用料マスタ!E4,使用料マスタ!E10) -> 66578 | D27: =IF(設定!$C$6="人口ビジョン",使用料マスタ!F4,使用料マスタ!F10) -> 76277 | E27: =IF(設定!$C$6="人口ビジョン",使用料マスタ!G4,使用料マスタ!G10) -> 75712 | F27: =IF(設定!$C$6="人口ビジョン",使用料マスタ!H4,使用料マスタ!H10) -> 75167 | G27: =IF(設定!$C$6="人口ビジョン",使用料マスタ!I4,使用料マスタ!I10) -> 74631 | H27: =IF(設定!$C$6="人口ビジョン",使用料マスタ!J4,使用料マスタ!J10) -> 74018 | I27: =IF(設定!$C$6="人口ビジョン",使用料マスタ!K4,使用料マスタ!K10) -> 73405 | ... K27: =IF(設定!$C$6="人口ビジョン",使用料マスタ!M4,使用料マスタ!M10) -> 72181
A28: パターン①（標準型）3か年 | B28: =IF(設定!$C$6="人口ビジョン",使用料マスタ!D5,使用料マスタ!D11) -> 57895 | C28: =IF(設定!$C$6="人口ビジョン",使用料マスタ!E5,使用料マスタ!E11) -> 63326 | D28: =IF(設定!$C$6="人口ビジョン",使用料マスタ!F5,使用料マスタ!F11) -> 68674 | E28: =IF(設定!$C$6="人口ビジョン",使用料マスタ!G5,使用料マスタ!G11) -> 75712 | F28: =IF(設定!$C$6="人口ビジョン",使用料マスタ!H5,使用料マスタ!H11) -> 75167 | G28: =IF(設定!$C$6="人口ビジョン",使用料マスタ!I5,使用料マスタ!I11) -> 74631 | H28: =IF(設定!$C$6="人口ビジョン",使用料マスタ!J5,使用料マスタ!J11) -> 74018 | I28: =IF(設定!$C$6="人口ビジョン",使用料マスタ!K5,使用料マスタ!K11) -> 73405 | ... K28: =IF(設定!$C$6="人口ビジョン",使用料マスタ!M5,使用料マスタ!M11) -> 72181
A29: パターン②（家庭軽減型）2か年 | B29: =IF(設定!$C$6="人口ビジョン",使用料マスタ!D6,使用料マスタ!D12) -> 57895 | C29: =IF(設定!$C$6="人口ビジョン",使用料マスタ!E6,使用料マスタ!E12) -> 69223 | D29: =IF(設定!$C$6="人口ビジョン",使用料マスタ!F6,使用料マスタ!F12) -> 81531 | E29: =IF(設定!$C$6="人口ビジョン",使用料マスタ!G6,使用料マスタ!G12) -> 80928 | F29: =IF(設定!$C$6="人口ビジョン",使用料マスタ!H6,使用料マスタ!H12) -> 80345 | G29: =IF(設定!$C$6="人口ビジョン",使用料マスタ!I6,使用料マスタ!I12) -> 79773 | H29: =IF(設定!$C$6="人口ビジョン",使用料マスタ!J6,使用料マスタ!J12) -> 79117 | I29: =IF(設定!$C$6="人口ビジョン",使用料マスタ!K6,使用料マスタ!K12) -> 78461 | ... K29: =IF(設定!$C$6="人口ビジョン",使用料マスタ!M6,使用料マスタ!M12) -> 77153
A30: パターン②（家庭軽減型）3か年 | B30: =IF(設定!$C$6="人口ビジョン",使用料マスタ!D7,使用料マスタ!D13) -> 57895 | C30: =IF(設定!$C$6="人口ビジョン",使用料マスタ!E7,使用料マスタ!E13) -> 65090 | D30: =IF(設定!$C$6="人口ビジョン",使用料マスタ!F7,使用料マスタ!F13) -> 72176 | E30: =IF(設定!$C$6="人口ビジョン",使用料マスタ!G7,使用料マスタ!G13) -> 80928 | F30: =IF(設定!$C$6="人口ビジョン",使用料マスタ!H7,使用料マスタ!H13) -> 80345 | G30: =IF(設定!$C$6="人口ビジョン",使用料マスタ!I7,使用料マスタ!I13) -> 79773 | H30: =IF(設定!$C$6="人口ビジョン",使用料マスタ!J7,使用料マスタ!J13) -> 79117 | I30: =IF(設定!$C$6="人口ビジョン",使用料マスタ!K7,使用料マスタ!K13) -> 78461 | ... K30: =IF(設定!$C$6="人口ビジョン",使用料マスタ!M7,使用料マスタ!M13) -> 77153
A31: パターン④（段階累進型）2か年 | B31: =IF(設定!$C$6="人口ビジョン",使用料マスタ!D8,使用料マスタ!D14) -> 57895 | C31: =IF(設定!$C$6="人口ビジョン",使用料マスタ!E8,使用料マスタ!E14) -> 67460 | D31: =IF(設定!$C$6="人口ビジョン",使用料マスタ!F8,使用料マスタ!F14) -> 78028 | E31: =IF(設定!$C$6="人口ビジョン",使用料マスタ!G8,使用料マスタ!G14) -> 77451 | F31: =IF(設定!$C$6="人口ビジョン",使用料マスタ!H8,使用料マスタ!H14) -> 76893 | G31: =IF(設定!$C$6="人口ビジョン",使用料マスタ!I8,使用料マスタ!I14) -> 76345 | H31: =IF(設定!$C$6="人口ビジョン",使用料マスタ!J8,使用料マスタ!J14) -> 75718 | I31: =IF(設定!$C$6="人口ビジョン",使用料マスタ!K8,使用料マスタ!K14) -> 75090 | ... K31: =IF(設定!$C$6="人口ビジョン",使用料マスタ!M8,使用料マスタ!M14) -> 73838
A32: パターン④（段階累進型）3か年 | B32: =IF(設定!$C$6="人口ビジョン",使用料マスタ!D9,使用料マスタ!D15) -> 57895 | C32: =IF(設定!$C$6="人口ビジョン",使用料マスタ!E9,使用料マスタ!E15) -> 63618 | D32: =IF(設定!$C$6="人口ビジョン",使用料マスタ!F9,使用料マスタ!F15) -> 69254 | E32: =IF(設定!$C$6="人口ビジョン",使用料マスタ!G9,使用料マスタ!G15) -> 77451 | F32: =IF(設定!$C$6="人口ビジョン",使用料マスタ!H9,使用料マスタ!H15) -> 76893 | G32: =IF(設定!$C$6="人口ビジョン",使用料マスタ!I9,使用料マスタ!I15) -> 76345 | H32: =IF(設定!$C$6="人口ビジョン",使用料マスタ!J9,使用料マスタ!J15) -> 75718 | I32: =IF(設定!$C$6="人口ビジョン",使用料マスタ!K9,使用料マスタ!K15) -> 75090 | ... K32: =IF(設定!$C$6="人口ビジョン",使用料マスタ!M9,使用料マスタ!M15) -> 73838

Sheet 公共案①2か年
A1: 公共下水道事業 投資財政計画 パターン①（標準型）2か年改定
A2: ３条 収益的収支（令和7年度～令和16年度）
A4: 区 分 | B4: 令和7年度 | C4: 令和8年度 | D4: 令和9年度 | E4: 令和10年度 | F4: 令和11年度 | G4: 令和12年度 | H4: 令和13年度 | I4: 令和14年度 | J4: 令和15年度 | K4: 令和16年度
A5: （単位：千円） | B5: 2025 | C5: 2026 | D5: 2027 | E5: 2028 | F5: 2029 | G5: 2030 | H5: 2031 | I5: 2032 | J5: 2033 | K5: 2034
A6: 【収入の部】
A7: 営業収益 (A) | B7: =B8+B9+B10 -> 66628.5 | C7: =C8+C9+C10 -> 76374.1 | D7: =D8+D9+D10 -> 75928.3 | E7: =E8+E9+E10 -> 75327.7 | F7: =F8+F9+F10 -> 74830.5 | G7: =G8+G9+G10 -> 74292.8 | H7: =H8+H9+H10 -> 73735.2 | I7: =I8+I9+I10 -> 73194.5 | ... K7: =K8+K9+K10 -> 72093.2
A8: (1) 使用料収入 | B8: 66469.5 | C8: 76162.1 | D8: 75645.3 | E8: 75109.7 | F8: 74592.5 | G8: 74046.8 | H8: 73501.2 | I8: 72955.5 | J8: 72391.3 | K8: 71855.2
A9: (2) 雨水処理負担金 | B9: 0 | C9: 0 | D9: 0 | E9: 0 | F9: 0 | G9: 0 | H9: 0 | I9: 0 | J9: 0 | K9: 0
A10: (3) その他 | B10: 159 | C10: 212 | D10: 283 | E10: 218 | F10: 238 | G10: 246 | H10: 234 | I10: 239 | J10: 240 | K10: 238
A11: 営業外収益 | B11: =B12+B13+B14 -> 478588 | C11: =C12+C13+C14 -> 479130 | D11: =D12+D13+D14 -> 390774 | E11: =E12+E13+E14 -> 323775 | F11: =F12+F13+F14 -> 310672 | G11: =G12+G13+G14 -> 310608 | H11: =H12+H13+H14 -> 311431 | I11: =I12+I13+I14 -> 312227 | ... K11: =K12+K13+K14 -> 312117
A12: (1) 補助金 | B12: 151133 | C12: 151437 | D12: 169454 | E12: 183394 | F12: 186588 | G12: 186657 | H12: 186749 | I12: 186849 | J12: 187381 | K12: 188114
A13: (2) 長期前受金戻入 | B13: 309898 | C13: 311906 | D13: 208677 | E13: 125052 | F13: 109497 | G13: 109765 | H13: 109981 | I13: 110887 | J13: 110446 | K13: 109452
A14: (3) その他 | B14: 17557 | C14: 15787 | D14: 12643 | E14: 15329 | F14: 14587 | G14: 14186 | H14: 14701 | I14: 14491 | J14: 14460 | K14: 14551
A15: 経常収入 (C) | B15: =B7+B11 -> 545216.5 | C15: =C7+C11 -> 555504.1 | D15: =D7+D11 -> 466702.3 | E15: =E7+E11 -> 399102.7 | F15: =F7+F11 -> 385502.5 | G15: =G7+G11 -> 384900.8 | H15: =H7+H11 -> 385166.2 | I15: =I7+I11 -> 385421.5 | ... K15: =K7+K11 -> 384210.2
A17: 【支出の部】
A18: 営業費用 | B18: =B19+B20+B25 -> 520872 | C18: =C19+C20+C25 -> 530785 | D18: =D19+D20+D25 -> 445840 | E18: =E19+E20+E25 -> 373726 | F18: =F19+F20+F25 -> 363986 | G18: =G19+G20+G25 -> 365356 | H18: =H19+H20+H25 -> 365923 | I18: =I19+I20+I25 -> 368372 | ... K18: =K19+K20+K25 -> 367149
A19: (1) 職員給与費 | B19: 5936 | C19: 5788 | D19: 5793 | E19: 5839 | F19: 5806 | G19: 5813 | H19: 5819 | I19: 5813 | J19: 5815 | K19: 5816
A20: (2) 経費 | B20: 162395 | C20: 167240 | D20: 171181 | E20: 168553 | F20: 170733 | G20: 171855 | H20: 172110 | I20: 173294 | J20: 174163 | K20: 174936
A21: 動力費 | B21: 4975 | C21: 4724 | D21: 4898 | E21: 4859 | F21: 4927 | G21: 4942 | H21: 4984 | I21: 5013 | J21: 5048 | K21: 5081
A22: 修繕費 | B22: 912 | C22: 983 | D22: 1223 | E22: 1050 | F22: 1096 | G22: 1134 | H22: 1104 | I22: 1122 | J22: 1131 | K22: 1131
A23: 材料費 | B23: 1228 | C23: 1197 | D23: 1206 | E23: 1222 | F23: 1220 | G23: 1228 | H23: 1236 | I23: 1240 | J23: 1247 | K23: 1253
A24: その他 | B24: 155280 | C24: 160337 | D24: 163854 | E24: 161422 | F24: 163490 | G24: 164551 | H24: 164786 | I24: 165918 | J24: 166736 | K24: 167472
A25: (3) 減価償却費 | B25: 352541 | C25: 357757 | D25: 268866 | E25: 199334 | F25: 187447 | G25: 187688 | H25: 187994 | I25: 189265 | J25: 188456 | K25: 186397
A26: 営業外費用 | B26: =B27+B28 -> 24189 | C26: =C27+C28 -> 28352 | D26: =D27+D28 -> 21428 | E26: =E27+E28 -> 21542 | F26: =F27+F28 -> 20337 | G26: =G27+G28 -> 19272 | H26: =H27+H28 -> 18037 | I26: =I27+I28 -> 17018 | ... K26: =K27+K28 -> 15309
A27: (1) 支払利息 | B27: 22189 | C27: 26352 | D27: 19428 | E27: 19542 | F27: 18337 | G27: 17272 | H27: 16037 | I27: 15018 | J27: 14145 | K27: 13309
A28: (2) その他 | B28: 2000 | C28: 2000 | D28: 2000 | E28: 2000 | F28: 2000 | G28: 2000 | H28: 2000 | I28: 2000 | J28: 2000 | K28: 2000
A29: 経常支出 (D) | B29: =B18+B26 -> 545061 | C29: =C18+C26 -> 559137 | D29: =D18+D26 -> 467268 | E29: =E18+E26 -> 395268 | F29: =F18+F26 -> 384323 | G29: =G18+G26 -> 384628 | H29: =H18+H26 -> 383960 | I29: =I18+I26 -> 385390 | ... K29: =K18+K26 -> 382458
A31: 経常損益 (C)-(D) | B31: =B15-B29 -> 155.5 | C31: =C15-C29 -> -3632.9 | D31: =D15-D29 -> -565.7 | E31: =E15-E29 -> 3834.7 | F31: =F15-F29 -> 1179.5 | G31: =G15-G29 -> 272.8 | H31: =H15-H29 -> 1206.2 | I31: =I15-I29 -> 31.5 | ... K31: =K15-K29 -> 1752.2
A33: 経常収支比率 | B33: =IF(B29=0,"-",B15/B29) -> 1.0002853 | C33: =IF(C29=0,"-",C15/C29) -> 0.99350267 | D33: =IF(D29=0,"-",D15/D29) -> 0.99878935 | E33: =IF(E29=0,"-",E15/E29) -> 1.0097015 | F33: =IF(F29=0,"-",F15/F29) -> 1.003069 | G33: =IF(G29=0,"-",G15/G29) -> 1.0007093 | H33: =IF(H29=0,"-",H15/H29) -> 1.0031415 | I33: =IF(I29=0,"-",I15/I29) -> 1.0000817 | ... K33: =IF(K29=0,"-",K15/K29) -> 1.0045814
A34: 汚水処理費 | B34: =B19+B20 -> 168331 | C34: =C19+C20 -> 173028 | D34: =D19+D20 -> 176974 | E34: =E19+E20 -> 174392 | F34: =F19+F20 -> 176539 | G34: =G19+G20 -> 177668 | H34: =H19+H20 -> 177929 | I34: =I19+I20 -> 179107 | ... K34: =K19+K20 -> 180752
A35: 経費回収率 | B35: =IF(B34=0,"-",B8/B34) -> 0.39487379 | C35: =IF(C34=0,"-",C8/C34) -> 0.44017211 | D35: =IF(D34=0,"-",D8/D34) -> 0.42743736 | E35: =IF(E34=0,"-",E8/E34) -> 0.43069464 | F35: =IF(F34=0,"-",F8/F34) -> 0.42252703 | G35: =IF(G34=0,"-",G8/G34) -> 0.41677061 | H35: =IF(H34=0,"-",H8/H34) -> 0.41309286 | I35: =IF(I34=0,"-",I8/I34) -> 0.40732914 | ... K35: =IF(K34=0,"-",K8/K34) -> 0.39753474
A36: 有収水量（㎥） | B36: 452089 | C36: 449052 | D36: 445934 | E36: 442898 | F36: 439779 | G36: 436743 | H36: 433542 | I36: 430342 | J36: 427141 | K36: 423859
A38: ４条 資本的収支（令和7年度～令和16年度）
A39: ※ 打合せ資料より転記予定
A41: 【資本的収入】
A42: 企業債
A43: 国庫補助金
A44: 他会計負担金
A45: その他
A46: 資本的収入 合計 (E)
...

Sheet 公共案①3か年
A1: 公共下水道事業 投資財政計画 パターン①（標準型）3か年改定
A2: ３条 収益的収支（令和7年度～令和16年度）
A4: 区 分 | B4: 令和7年度 | C4: 令和8年度 | D4: 令和9年度 | E4: 令和10年度 | F4: 令和11年度 | G4: 令和12年度 | H4: 令和13年度 | I4: 令和14年度 | J4: 令和15年度 | K4: 令和16年度
A5: （単位：千円） | B5: 2025 | C5: 2026 | D5: 2027 | E5: 2028 | F5: 2029 | G5: 2030 | H5: 2031 | I5: 2032 | J5: 2033 | K5: 2034
A6: 【収入の部】
A7: 営業収益 (A) | B7: =B8+B9+B10 -> 63381.8 | C7: =C8+C9+C10 -> 68782.1 | D7: =D8+D9+D10 -> 75928.3 | E7: =E8+E9+E10 -> 75327.7 | F7: =F8+F9+F10 -> 74830.5 | G7: =G8+G9+G10 -> 74292.8 | H7: =H8+H9+H10 -> 73735.2 | I7: =I8+I9+I10 -> 73194.5 | ... K7: =K8+K9+K10 -> 72093.2
A8: (1) 使用料収入 | B8: 63222.8 | C8: 68570.1 | D8: 75645.3 | E8: 75109.7 | F8: 74592.5 | G8: 74046.8 | H8: 73501.2 | I8: 72955.5 | J8: 72391.3 | K8: 71855.2
A9: (2) 雨水処理負担金 | B9: 0 | C9: 0 | D9: 0 | E9: 0 | F9: 0 | G9: 0 | H9: 0 | I9: 0 | J9: 0 | K9: 0
A10: (3) その他 | B10: 159 | C10: 212 | D10: 283 | E10: 218 | F10: 238 | G10: 246 | H10: 234 | I10: 239 | J10: 240 | K10: 238
A11: 営業外収益 | B11: =B12+B13+B14 -> 478588 | C11: =C12+C13+C14 -> 479130 | D11: =D12+D13+D14 -> 390774 | E11: =E12+E13+E14 -> 323775 | F11: =F12+F13+F14 -> 310672 | G11: =G12+G13+G14 -> 310608 | H11: =H12+H13+H14 -> 311431 | I11: =I12+I13+I14 -> 312227 | ... K11: =K12+K13+K14 -> 312117
A12: (1) 補助金 | B12: 151133 | C12: 151437 | D12: 169454 | E12: 183394 | F12: 186588 | G12: 186657 | H12: 186749 | I12: 186849 | J12: 187381 | K12: 188114
A13: (2) 長期前受金戻入 | B13: 309898 | C13: 311906 | D13: 208677 | E13: 125052 | F13: 109497 | G13: 109765 | H13: 109981 | I13: 110887 | J13: 110446 | K13: 109452
A14: (3) その他 | B14: 17557 | C14: 15787 | D14: 12643 | E14: 15329 | F14: 14587 | G14: 14186 | H14: 14701 | I14: 14491 | J14: 14460 | K14: 14551
A15: 経常収入 (C) | B15: =B7+B11 -> 541969.8 | C15: =C7+C11 -> 547912.1 | D15: =D7+D11 -> 466702.3 | E15: =E7+E11 -> 399102.7 | F15: =F7+F11 -> 385502.5 | G15: =G7+G11 -> 384900.8 | H15: =H7+H11 -> 385166.2 | I15: =I7+I11 -> 385421.5 | ... K15: =K7+K11 -> 384210.2
A17: 【支出の部】
A18: 営業費用 | B18: =B19+B20+B25 -> 520872 | C18: =C19+C20+C25 -> 530785 | D18: =D19+D20+D25 -> 445840 | E18: =E19+E20+E25 -> 373726 | F18: =F19+F20+F25 -> 363986 | G18: =G19+G20+G25 -> 365356 | H18: =H19+H20+H25 -> 365923 | I18: =I19+I20+I25 -> 368372 | ... K18: =K19+K20+K25 -> 367149
A19: (1) 職員給与費 | B19: 5936 | C19: 5788 | D19: 5793 | E19: 5839 | F19: 5806 | G19: 5813 | H19: 5819 | I19: 5813 | J19: 5815 | K19: 5816
A20: (2) 経費 | B20: 162395 | C20: 167240 | D20: 171181 | E20: 168553 | F20: 170733 | G20: 171855 | H20: 172110 | I20: 173294 | J20: 174163 | K20: 174936
A21: 動力費 | B21: 4975 | C21: 4724 | D21: 4898 | E21: 4859 | F21: 4927 | G21: 4942 | H21: 4984 | I21: 5013 | J21: 5048 | K21: 5081
A22: 修繕費 | B22: 912 | C22: 983 | D22: 1223 | E22: 1050 | F22: 1096 | G22: 1134 | H22: 1104 | I22: 1122 | J22: 1131 | K22: 1131
A23: 材料費 | B23: 1228 | C23: 1197 | D23: 1206 | E23: 1222 | F23: 1220 | G23: 1228 | H23: 1236 | I23: 1240 | J23: 1247 | K23: 1253
A24: その他 | B24: 155280 | C24: 160337 | D24: 163854 | E24: 161422 | F24: 163490 | G24: 164551 | H24: 164786 | I24: 165918 | J24: 166736 | K24: 167472
A25: (3) 減価償却費 | B25: 352541 | C25: 357757 | D25: 268866 | E25: 199334 | F25: 187447 | G25: 187688 | H25: 187994 | I25: 189265 | J25: 188456 | K25: 186397
A26: 営業外費用 | B26: =B27+B28 -> 24189 | C26: =C27+C28 -> 28352 | D26: =D27+D28 -> 21428 | E26: =E27+E28 -> 21542 | F26: =F27+F28 -> 20337 | G26: =G27+G28 -> 19272 | H26: =H27+H28 -> 18037 | I26: =I27+I28 -> 17018 | ... K26: =K27+K28 -> 15309
A27: (1) 支払利息 | B27: 22189 | C27: 26352 | D27: 19428 | E27: 19542 | F27: 18337 | G27: 17272 | H27: 16037 | I27: 15018 | J27: 14145 | K27: 13309
A28: (2) その他 | B28: 2000 | C28: 2000 | D28: 2000 | E28: 2000 | F28: 2000 | G28: 2000 | H28: 2000 | I28: 2000 | J28: 2000 | K28: 2000
A29: 経常支出 (D) | B29: =B18+B26 -> 545061 | C29: =C18+C26 -> 559137 | D29: =D18+D26 -> 467268 | E29: =E18+E26 -> 395268 | F29: =F18+F26 -> 384323 | G29: =G18+G26 -> 384628 | H29: =H18+H26 -> 383960 | I29: =I18+I26 -> 385390 | ... K29: =K18+K26 -> 382458
A31: 経常損益 (C)-(D) | B31: =B15-B29 -> -3091.2 | C31: =C15-C29 -> -11224.9 | D31: =D15-D29 -> -565.7 | E31: =E15-E29 -> 3834.7 | F31: =F15-F29 -> 1179.5 | G31: =G15-G29 -> 272.8 | H31: =H15-H29 -> 1206.2 | I31: =I15-I29 -> 31.5 | ... K31: =K15-K29 -> 1752.2
A33: 経常収支比率 | B33: =IF(B29=0,"-",B15/B29) -> 0.99432871 | C33: =IF(C29=0,"-",C15/C29) -> 0.9799246 | D33: =IF(D29=0,"-",D15/D29) -> 0.99878935 | E33: =IF(E29=0,"-",E15/E29) -> 1.0097015 | F33: =IF(F29=0,"-",F15/F29) -> 1.003069 | G33: =IF(G29=0,"-",G15/G29) -> 1.0007093 | H33: =IF(H29=0,"-",H15/H29) -> 1.0031415 | I33: =IF(I29=0,"-",I15/I29) -> 1.0000817 | ... K33: =IF(K29=0,"-",K15/K29) -> 1.0045814
A34: 汚水処理費 | B34: =B19+B20 -> 168331 | C34: =C19+C20 -> 173028 | D34: =D19+D20 -> 176974 | E34: =E19+E20 -> 174392 | F34: =F19+F20 -> 176539 | G34: =G19+G20 -> 177668 | H34: =H19+H20 -> 177929 | I34: =I19+I20 -> 179107 | ... K34: =K19+K20 -> 180752
A35: 経費回収率 | B35: =IF(B34=0,"-",B8/B34) -> 0.3755862 | C35: =IF(C34=0,"-",C8/C34) -> 0.39629482 | D35: =IF(D34=0,"-",D8/D34) -> 0.42743736 | E35: =IF(E34=0,"-",E8/E34) -> 0.43069464 | F35: =IF(F34=0,"-",F8/F34) -> 0.42252703 | G35: =IF(G34=0,"-",G8/G34) -> 0.41677061 | H35: =IF(H34=0,"-",H8/H34) -> 0.41309286 | I35: =IF(I34=0,"-",I8/I34) -> 0.40732914 | ... K35: =IF(K34=0,"-",K8/K34) -> 0.39753474
A36: 有収水量（㎥） | B36: 452089 | C36: 449052 | D36: 445934 | E36: 442898 | F36: 439779 | G36: 436743 | H36: 433542 | I36: 430342 | J36: 427141 | K36: 423859
A38: ４条 資本的収支（令和7年度～令和16年度）
A39: ※ 打合せ資料より転記予定
A41: 【資本的収入】
A42: 企業債
A43: 国庫補助金
A44: 他会計負担金
A45: その他
A46: 資本的収入 合計 (E)
...

Sheet 公共案②2か年
A1: 公共下水道事業 投資財政計画 パターン②（家庭軽減型）2か年改定
A2: ３条 収益的収支（令和7年度～令和16年度）
A4: 区 分 | B4: 令和7年度 | C4: 令和8年度 | D4: 令和9年度 | E4: 令和10年度 | F4: 令和11年度 | G4: 令和12年度 | H4: 令和13年度 | I4: 令和14年度 | J4: 令和15年度 | K4: 令和16年度
A5: （単位：千円） | B5: 2025 | C5: 2026 | D5: 2027 | E5: 2028 | F5: 2029 | G5: 2030 | H5: 2031 | I5: 2032 | J5: 2033 | K5: 2034
A6: 【収入の部】
A7: 営業収益 (A) | B7: =B8+B9+B10 -> 69269.7 | C7: =C8+C9+C10 -> 81620.5 | D7: =D8+D9+D10 -> 81138.6 | E7: =E8+E9+E10 -> 80502.1 | F7: =F8+F9+F10 -> 79968.7 | G7: =G8+G9+G10 -> 79393.1 | H7: =H8+H9+H10 -> 78797.8 | I7: =I8+I9+I10 -> 78219.2 | ... K7: =K8+K9+K10 -> 77044
A8: (1) 使用料収入 | B8: 69110.7 | C8: 81408.5 | D8: 80855.6 | E8: 80284.1 | F8: 79730.7 | G8: 79147.1 | H8: 78563.8 | I8: 77980.2 | J8: 77378.2 | K8: 76806
A9: (2) 雨水処理負担金 | B9: 0 | C9: 0 | D9: 0 | E9: 0 | F9: 0 | G9: 0 | H9: 0 | I9: 0 | J9: 0 | K9: 0
A10: (3) その他 | B10: 159 | C10: 212 | D10: 283 | E10: 218 | F10: 238 | G10: 246 | H10: 234 | I10: 239 | J10: 240 | K10: 238
A11: 営業外収益 | B11: =B12+B13+B14 -> 478588 | C11: =C12+C13+C14 -> 479130 | D11: =D12+D13+D14 -> 390774 | E11: =E12+E13+E14 -> 323775 | F11: =F12+F13+F14 -> 310672 | G11: =G12+G13+G14 -> 310608 | H11: =H12+H13+H14 -> 311431 | I11: =I12+I13+I14 -> 312227 | ... K11: =K12+K13+K14 -> 312117
A12: (1) 補助金 | B12: 151133 | C12: 151437 | D12: 169454 | E12: 183394 | F12: 186588 | G12: 186657 | H12: 186749 | I12: 186849 | J12: 187381 | K12: 188114
A13: (2) 長期前受金戻入 | B13: 309898 | C13: 311906 | D13: 208677 | E13: 125052 | F13: 109497 | G13: 109765 | H13: 109981 | I13: 110887 | J13: 110446 | K13: 109452
A14: (3) その他 | B14: 17557 | C14: 15787 | D14: 12643 | E14: 15329 | F14: 14587 | G14: 14186 | H14: 14701 | I14: 14491 | J14: 14460 | K14: 14551
A15: 経常収入 (C) | B15: =B7+B11 -> 547857.7 | C15: =C7+C11 -> 560750.5 | D15: =D7+D11 -> 471912.6 | E15: =E7+E11 -> 404277.1 | F15: =F7+F11 -> 390640.7 | G15: =G7+G11 -> 390001.1 | H15: =H7+H11 -> 390228.8 | I15: =I7+I11 -> 390446.2 | ... K15: =K7+K11 -> 389161
A17: 【支出の部】
A18: 営業費用 | B18: =B19+B20+B25 -> 520872 | C18: =C19+C20+C25 -> 530785 | D18: =D19+D20+D25 -> 445840 | E18: =E19+E20+E25 -> 373726 | F18: =F19+F20+F25 -> 363986 | G18: =G19+G20+G25 -> 365356 | H18: =H19+H20+H25 -> 365923 | I18: =I19+I20+I25 -> 368372 | ... K18: =K19+K20+K25 -> 367149
A19: (1) 職員給与費 | B19: 5936 | C19: 5788 | D19: 5793 | E19: 5839 | F19: 5806 | G19: 5813 | H19: 5819 | I19: 5813 | J19: 5815 | K19: 5816
A20: (2) 経費 | B20: 162395 | C20: 167240 | D20: 171181 | E20: 168553 | F20: 170733 | G20: 171855 | H20: 172110 | I20: 173294 | J20: 174163 | K20: 174936
A21: 動力費 | B21: 4975 | C21: 4724 | D21: 4898 | E21: 4859 | F21: 4927 | G21: 4942 | H21: 4984 | I21: 5013 | J21: 5048 | K21: 5081
A22: 修繕費 | B22: 912 | C22: 983 | D22: 1223 | E22: 1050 | F22: 1096 | G22: 1134 | H22: 1104 | I22: 1122 | J22: 1131 | K22: 1131
A23: 材料費 | B23: 1228 | C23: 1197 | D23: 1206 | E23: 1222 | F23: 1220 | G23: 1228 | H23: 1236 | I23: 1240 | J23: 1247 | K23: 1253
A24: その他 | B24: 155280 | C24: 160337 | D24: 163854 | E24: 161422 | F24: 163490 | G24: 164551 | H24: 164786 | I24: 165918 | J24: 166736 | K24: 167472
A25: (3) 減価償却費 | B25: 352541 | C25: 357757 | D25: 268866 | E25: 199334 | F25: 187447 | G25: 187688 | H25: 187994 | I25: 189265 | J25: 188456 | K25: 186397
A26: 営業外費用 | B26: =B27+B28 -> 24189 | C26: =C27+C28 -> 28352 | D26: =D27+D28 -> 21428 | E26: =E27+E28 -> 21542 | F26: =F27+F28 -> 20337 | G26: =G27+G28 -> 19272 | H26: =H27+H28 -> 18037 | I26: =I27+I28 -> 17018 | ... K26: =K27+K28 -> 15309
A27: (1) 支払利息 | B27: 22189 | C27: 26352 | D27: 19428 | E27: 19542 | F27: 18337 | G27: 17272 | H27: 16037 | I27: 15018 | J27: 14145 | K27: 13309
A28: (2) その他 | B28: 2000 | C28: 2000 | D28: 2000 | E28: 2000 | F28: 2000 | G28: 2000 | H28: 2000 | I28: 2000 | J28: 2000 | K28: 2000
A29: 経常支出 (D) | B29: =B18+B26 -> 545061 | C29: =C18+C26 -> 559137 | D29: =D18+D26 -> 467268 | E29: =E18+E26 -> 395268 | F29: =F18+F26 -> 384323 | G29: =G18+G26 -> 384628 | H29: =H18+H26 -> 383960 | I29: =I18+I26 -> 385390 | ... K29: =K18+K26 -> 382458
A31: 経常損益 (C)-(D) | B31: =B15-B29 -> 2796.7 | C31: =C15-C29 -> 1613.5 | D31: =D15-D29 -> 4644.6 | E31: =E15-E29 -> 9009.1 | F31: =F15-F29 -> 6317.7 | G31: =G15-G29 -> 5373.1 | H31: =H15-H29 -> 6268.8 | I31: =I15-I29 -> 5056.2 | ... K31: =K15-K29 -> 6703
A33: 経常収支比率 | B33: =IF(B29=0,"-",B15/B29) -> 1.005131 | C33: =IF(C29=0,"-",C15/C29) -> 1.0028857 | D33: =IF(D29=0,"-",D15/D29) -> 1.0099399 | E33: =IF(E29=0,"-",E15/E29) -> 1.0227924 | F33: =IF(F29=0,"-",F15/F29) -> 1.0164385 | G33: =IF(G29=0,"-",G15/G29) -> 1.0139696 | H33: =IF(H29=0,"-",H15/H29) -> 1.0163267 | I33: =IF(I29=0,"-",I15/I29) -> 1.0131197 | ... K33: =IF(K29=0,"-",K15/K29) -> 1.0175261
A34: 汚水処理費 | B34: =B19+B20 -> 168331 | C34: =C19+C20 -> 173028 | D34: =D19+D20 -> 176974 | E34: =E19+E20 -> 174392 | F34: =F19+F20 -> 176539 | G34: =G19+G20 -> 177668 | H34: =H19+H20 -> 177929 | I34: =I19+I20 -> 179107 | ... K34: =K19+K20 -> 180752
A35: 経費回収率 | B35: =IF(B34=0,"-",B8/B34) -> 0.4105643 | C35: =IF(C34=0,"-",C8/C34) -> 0.47049321 | D35: =IF(D34=0,"-",D8/D34) -> 0.45687841 | E35: =IF(E34=0,"-",E8/E34) -> 0.46036573 | F35: =IF(F34=0,"-",F8/F34) -> 0.45163222 | G35: =IF(G34=0,"-",G8/G34) -> 0.44547752 | H35: =IF(H34=0,"-",H8/H34) -> 0.44154579 | I35: =IF(I34=0,"-",I8/I34) -> 0.43538332 | ... K35: =IF(K34=0,"-",K8/K34) -> 0.42492476
A36: 有収水量（㎥） | B36: 452089 | C36: 449052 | D36: 445934 | E36: 442898 | F36: 439779 | G36: 436743 | H36: 433542 | I36: 430342 | J36: 427141 | K36: 423859
A38: ４条 資本的収支（令和7年度～令和16年度）
A39: ※ 打合せ資料より転記予定
A41: 【資本的収入】
A42: 企業債
A43: 国庫補助金
A44: 他会計負担金
A45: その他
A46: 資本的収入 合計 (E)
...

Sheet 公共案②3か年
A1: 公共下水道事業 投資財政計画 パターン②（家庭軽減型）3か年改定
A2: ３条 収益的収支（令和7年度～令和16年度）
A4: 区 分 | B4: 令和7年度 | C4: 令和8年度 | D4: 令和9年度 | E4: 令和10年度 | F4: 令和11年度 | G4: 令和12年度 | H4: 令和13年度 | I4: 令和14年度 | J4: 令和15年度 | K4: 令和16年度
A5: （単位：千円） | B5: 2025 | C5: 2026 | D5: 2027 | E5: 2028 | F5: 2029 | G5: 2030 | H5: 2031 | I5: 2032 | J5: 2033 | K5: 2034
A6: 【収入の部】
A7: 営業収益 (A) | B7: =B8+B9+B10 -> 65142.6 | C7: =C8+C9+C10 -> 72279.6 | D7: =D8+D9+D10 -> 81138.6 | E7: =E8+E9+E10 -> 80502.1 | F7: =F8+F9+F10 -> 79968.7 | G7: =G8+G9+G10 -> 79393.1 | H7: =H8+H9+H10 -> 78797.8 | I7: =I8+I9+I10 -> 78219.2 | ... K7: =K8+K9+K10 -> 77044
A8: (1) 使用料収入 | B8: 64983.6 | C8: 72067.6 | D8: 80855.6 | E8: 80284.1 | F8: 79730.7 | G8: 79147.1 | H8: 78563.8 | I8: 77980.2 | J8: 77378.2 | K8: 76806
A9: (2) 雨水処理負担金 | B9: 0 | C9: 0 | D9: 0 | E9: 0 | F9: 0 | G9: 0 | H9: 0 | I9: 0 | J9: 0 | K9: 0
A10: (3) その他 | B10: 159 | C10: 212 | D10: 283 | E10: 218 | F10: 238 | G10: 246 | H10: 234 | I10: 239 | J10: 240 | K10: 238
A11: 営業外収益 | B11: =B12+B13+B14 -> 478588 | C11: =C12+C13+C14 -> 479130 | D11: =D12+D13+D14 -> 390774 | E11: =E12+E13+E14 -> 323775 | F11: =F12+F13+F14 -> 310672 | G11: =G12+G13+G14 -> 310608 | H11: =H12+H13+H14 -> 311431 | I11: =I12+I13+I14 -> 312227 | ... K11: =K12+K13+K14 -> 312117
A12: (1) 補助金 | B12: 151133 | C12: 151437 | D12: 169454 | E12: 183394 | F12: 186588 | G12: 186657 | H12: 186749 | I12: 186849 | J12: 187381 | K12: 188114
A13: (2) 長期前受金戻入 | B13: 309898 | C13: 311906 | D13: 208677 | E13: 125052 | F13: 109497 | G13: 109765 | H13: 109981 | I13: 110887 | J13: 110446 | K13: 109452
A14: (3) その他 | B14: 17557 | C14: 15787 | D14: 12643 | E14: 15329 | F14: 14587 | G14: 14186 | H14: 14701 | I14: 14491 | J14: 14460 | K14: 14551
A15: 経常収入 (C) | B15: =B7+B11 -> 543730.6 | C15: =C7+C11 -> 551409.6 | D15: =D7+D11 -> 471912.6 | E15: =E7+E11 -> 404277.1 | F15: =F7+F11 -> 390640.7 | G15: =G7+G11 -> 390001.1 | H15: =H7+H11 -> 390228.8 | I15: =I7+I11 -> 390446.2 | ... K15: =K7+K11 -> 389161
A17: 【支出の部】
A18: 営業費用 | B18: =B19+B20+B25 -> 520872 | C18: =C19+C20+C25 -> 530785 | D18: =D19+D20+D25 -> 445840 | E18: =E19+E20+E25 -> 373726 | F18: =F19+F20+F25 -> 363986 | G18: =G19+G20+G25 -> 365356 | H18: =H19+H20+H25 -> 365923 | I18: =I19+I20+I25 -> 368372 | ... K18: =K19+K20+K25 -> 367149
A19: (1) 職員給与費 | B19: 5936 | C19: 5788 | D19: 5793 | E19: 5839 | F19: 5806 | G19: 5813 | H19: 5819 | I19: 5813 | J19: 5815 | K19: 5816
A20: (2) 経費 | B20: 162395 | C20: 167240 | D20: 171181 | E20: 168553 | F20: 170733 | G20: 171855 | H20: 172110 | I20: 173294 | J20: 174163 | K20: 174936
A21: 動力費 | B21: 4975 | C21: 4724 | D21: 4898 | E21: 4859 | F21: 4927 | G21: 4942 | H21: 4984 | I21: 5013 | J21: 5048 | K21: 5081
A22: 修繕費 | B22: 912 | C22: 983 | D22: 1223 | E22: 1050 | F22: 1096 | G22: 1134 | H22: 1104 | I22: 1122 | J22: 1131 | K22: 1131
A23: 材料費 | B23: 1228 | C23: 1197 | D23: 1206 | E23: 1222 | F23: 1220 | G23: 1228 | H23: 1236 | I23: 1240 | J23: 1247 | K23: 1253
A24: その他 | B24: 155280 | C24: 160337 | D24: 163854 | E24: 161422 | F24: 163490 | G24: 164551 | H24: 164786 | I24: 165918 | J24: 166736 | K24: 167472
A25: (3) 減価償却費 | B25: 352541 | C25: 357757 | D25: 268866 | E25: 199334 | F25: 187447 | G25: 187688 | H25: 187994 | I25: 189265 | J25: 188456 | K25: 186397
A26: 営業外費用 | B26: =B27+B28 -> 24189 | C26: =C27+C28 -> 28352 | D26: =D27+D28 -> 21428 | E26: =E27+E28 -> 21542 | F26: =F27+F28 -> 20337 | G26: =G27+G28 -> 19272 | H26: =H27+H28 -> 18037 | I26: =I27+I28 -> 17018 | ... K26: =K27+K28 -> 15309
A27: (1) 支払利息 | B27: 22189 | C27: 26352 | D27: 19428 | E27: 19542 | F27: 18337 | G27: 17272 | H27: 16037 | I27: 15018 | J27: 14145 | K27: 13309
A28: (2) その他 | B28: 2000 | C28: 2000 | D28: 2000 | E28: 2000 | F28: 2000 | G28: 2000 | H28: 2000 | I28: 2000 | J28: 2000 | K28: 2000
A29: 経常支出 (D) | B29: =B18+B26 -> 545061 | C29: =C18+C26 -> 559137 | D29: =D18+D26 -> 467268 | E29: =E18+E26 -> 395268 | F29: =F18+F26 -> 384323 | G29: =G18+G26 -> 384628 | H29: =H18+H26 -> 383960 | I29: =I18+I26 -> 385390 | ... K29: =K18+K26 -> 382458
