Workbook

Sheet 目次
B1: 北塩原村 障がい福祉に関するアンケート調査 分析報告書 図表データ集（編集用）
B3: ・このブックは、分析報告書に掲載した図表（図61点・表23点）を、Excelで編集できる形式で収録したものです。図表番号は報告書と対応しています。
B4: ・グラフはすべてExcelのグラフ機能で作成しています。色・フォント・ラベル・サイズ等を通常どおり編集でき、そのままWordに貼り付けて使用できます。
B5: ・青字のセルが入力値（件数・回答者数）、黒字のセルは計算式です。「集計_障がい者」「集計_障がい児」シートの件数を修正すると、各章シートの表とグラフに自動で反映されます。
B6: ・第4章のクロス集計は、各表の【件数】欄（青字）が入力値で、【割合】欄は計算式です。
B7: ・割合は表示上、小数点第2位を四捨五入しています。グラフの項目の並び順は、報告書作成時点の件数順で固定しています。
B8: ・出典：北塩原村_障がい福祉アンケート_単純集計_クロス分析.xlsx、北塩原村_障がい児福祉アンケート_単純集計_クロス分析.xlsx（いずれも単純集計・クロス分析シート）
B10: 図表番号 | C10: タイトル | D10: 収録シート | E10: 移動
B11: 表1-1 | C11: 調査の概要 | D11: 1-2章_概要・要点 | E11: → 表示
B12: 表1-2 | C12: 調査項目の構成 | D12: 1-2章_概要・要点 | E12: → 表示
B13: 表2-1 | C13: 障がい者調査の主要指標 | D13: 1-2章_概要・要点 | E13: → 表示
B14: 図3-1 | C14: 調査票の記入者（問1） | D14: 3章_1属性 | E14: → 表示
B15: 図3-2 | C15: 回答への本人意向の反映（問1-2） | D15: 3章_1属性 | E15: → 表示
B16: 図3-3 | C16: 年齢（問2） | D16: 3章_1属性 | E16: → 表示
B17: 図3-4 | C17: お住まいの地区（問3） | D17: 3章_1属性 | E17: → 表示
B18: 図3-5 | C18: 性別（問4） | D18: 3章_1属性 | E18: → 表示
B19: 図3-6 | C19: 所持している手帳等（問5） | D19: 3章_1属性 | E19: → 表示
B20: 図3-7 | C20: 主たる障がい種別（問6） | D20: 3章_1属性 | E20: → 表示
B21: 図3-8 | C21: 現在の暮らしの場（問7） | D21: 3章_1属性 | E21: → 表示
... B96: 入力データ | C96: 障がい児調査 単純集計（入力用） | D96: 集計_障がい児 | E96: → 表示

Sheet 1-2章_概要・要点
B2: 表1-1 調査の概要
B3: 項目 | C3: 障がい者調査 | G3: 障がい児調査
B4: 調査対象 | C4: 村内在住の18歳以上の障がいのある方 【対象要件を記入】 | G4: 村内在住の18歳未満の障がいのある児童とその保護者 【対象要件を記入】
B5: 調査方法 | C5: 【例：郵送配布・郵送回収】 | G5: 【例：郵送配布・郵送回収】
B6: 調査期間 | C6: 令和8年○月○日～令和8年○月○日 | G6: 令和8年○月○日～令和8年○月○日
B7: 配布数 | C7: ○○件 | G7: ○○件
B8: 有効回答数 | C8: 38件 | G8: 3件
B9: 有効回答率 | C9: ○○.○％ | G9: ○○.○％
B10: ※黄色の網掛け部分は、集計データに含まれていないため、実施状況に合わせて記入してください。
B12: 表1-2 調査項目の構成
B13: 分野 | C13: 障がい者調査 | F13: 障がい児調査
B14: 回答者の属性 | C14: 問1～問9 | F14: 問1～問9
B15: 日常生活と将来の暮らし | C15: 問10～問11 | F15: 問10～問11
B16: 外出・移動 | C16: 問12～問14 | F16: 問12～問14
B17: 医療・医療的ケア等 | C17: 問15～問20 | F17: 問15～問18、問26
B18: 意思決定支援・相談・情報 | C18: 問21～問26 | F18: 問19～問22
B19: 通園・通学、放課後の過ごし方 | C19: ― | F19: 問23～問25、問31
B20: 福祉サービスの利用 | C20: 問27～問30 | F20: 問27～問30
B21: 日中活動・就労 | C21: 問31～問33 | F21: ―
B22: 18歳以降の生活 | C22: ― | F22: 問32
B23: 差別解消・権利擁護 | C23: 問34～問37 | F23: 問33～問36
B24: 災害時の対応 | C24: 問38～問41 | F24: 問37～問40
... B26: 自由意見 | C26: 問10-2、問45 | F26: 問10-2、問32-1、問44
B28: 表2-1 障がい者調査の主要指標
B29: 分野 | C29: 指標 | H29: 結果 | I29: 設問
B30: 回答者 | C30: 65歳以上の割合 | H30: =IF('集計_障がい者'!$F$18=0,0,SUM('集計_障がい者'!$D$18)/'集計_障がい者'!$F$18) -> 0.67567568 | I30: 問2
B31: 回答者 | C31: 主たる障がいが「身体障がい」 | H31: =IF('集計_障がい者'!$F$34=0,0,SUM('集計_障がい者'!$D$34)/'集計_障がい者'!$F$34) -> 0.7027027 | I31: 問6
B32: 日常生活 | C32: 困っていること「将来の生活」（「特にない」を除き第1位） | H32: =IF('集計_障がい者'!$F$77=0,0,SUM('集計_障がい者'!$D$77)/'集計_障がい者'!$F$77) -> 0.30555556 | I32: 問10
B33: 将来の暮らし | C33: 「今の自宅で暮らしたい」 | H33: =IF('集計_障がい者'!$F$80=0,0,SUM('集計_障がい者'!$D$80)/'集計_障がい者'!$F$80) -> 0.41666667 | I33: 問11
B34: 外出・移動 | C34: 外出時に困ること「冬季・積雪時に外出しにくい」 | H34: =IF('集計_障がい者'!$F$105=0,0,SUM('集計_障がい者'!$D$105)/'集計_障がい者'!$F$105) -> 0.38235294 | I34: 問14
B35: 相談 | C35: 困ったときの相談相手「家族・親族」 | H35: =IF('集計_障がい者'!$F$162=0,0,SUM('集計_障がい者'!$D$162)/'集計_障がい者'!$F$162) -> 0.78378378 | I35: 問22
B36: 相談 | C36: 相談支援への期待「わかりやすい情報提供」 | H36: =IF('集計_障がい者'!$F$203=0,0,SUM('集計_障がい者'!$D$203)/'集計_障がい者'!$F$203) -> 0.48275862 | I36: 問26
B37: 意思決定支援 | C37: 「必要である」＋「将来的には必要になると思う」 | H37: =IF('集計_障がい者'!$F$158=0,0,SUM('集計_障がい者'!$D$158,'集計_障がい者'!$D$159)/'集計_障がい者'!$F$158) -> 0.60606061 | I37: 問21
B38: サービス | C38: 現在利用しているサービスは「特にない」 | H38: =IF('集計_障がい者'!$F$223=0,0,SUM('集計_障がい者'!$D$223)/'集計_障がい者'!$F$223) -> 0.56666667 | I38: 問27-1
B39: サービス | C39: 今後3年間で「施設入所支援」を利用したい | H39: =IF('集計_障がい者'!$F$255=0,0,SUM('集計_障がい者'!$D$255)/'集計_障がい者'!$F$255) -> 0.32142857 | I39: 問27-3
B40: 地域生活支援拠点 | C40: 期待する機能「緊急時の受入れ」 | H40: =IF('集計_障がい者'!$F$272=0,0,SUM('集計_障がい者'!$D$272)/'集計_障がい者'!$F$272) -> 0.41935484 | I40: 問29
B41: 権利擁護 | C41: 差別・偏見・不利益を感じたことがある | H41: =IF('集計_障がい者'!$F$315=0,0,SUM('集計_障がい者'!$D$315,'集計_障がい者'!$D$316,'集計_障がい者'!$D$317)/'集計_障がい者'!$F$315) -> 0.29032258 | I41: 問34
B42: 権利擁護 | C42: 成年後見制度等を「知らない」 | H42: =IF('集計_障がい者'!$F$344=0,0,SUM('集計_障がい者'!$D$344)/'集計_障がい者'!$F$344) -> 0.42424242 | I42: 問37
B43: 災害 | C43: 避難行動要支援者名簿・個別避難計画を「知らない」 | H43: =IF('集計_障がい者'!$F$357=0,0,SUM('集計_障がい者'!$D$357)/'集計_障がい者'!$F$357) -> 0.76470588 | I43: 問39
B44: 災害 | C44: 災害時の不安「避難先での生活」 | H44: =IF('集計_障がい者'!$F$346=0,0,SUM('集計_障がい者'!$D$346)/'集計_障がい者'!$F$346) -> 0.70588235 | I44: 問38
...

Sheet 3章_1属性
B2: 図3-1 調査票の記入者（問1）
B3: ="n="&'集計_障がい者'!$F$5&"（単一回答）" -> n=38（単一回答）
B4: 選択肢 | C4: 件数 | D4: 割合
B5: 宛名のご本人 | C5: ='集計_障がい者'!$D$5 -> 24 | D5: ='集計_障がい者'!$E$5 -> 0.63157895
B6: ご家族 | C6: ='集計_障がい者'!$D$6 -> 9 | D6: ='集計_障がい者'!$E$6 -> 0.23684211
B7: 支援者・事業所職員 | C7: ='集計_障がい者'!$D$7 -> 4 | D7: ='集計_障がい者'!$E$7 -> 0.10526316
B8: その他 | C8: ='集計_障がい者'!$D$8 -> 1 | D8: ='集計_障がい者'!$E$8 -> 0.026315789
B13: 図3-2 回答への本人意向の反映（問1-2）
B14: ="n="&'集計_障がい者'!$F$9&"（単一回答）" -> n=38（単一回答）
B15: 選択肢 | C15: 件数 | D15: 割合
B16: 本人が回答した | C16: ='集計_障がい者'!$D$9 -> 22 | D16: ='集計_障がい者'!$E$9 -> 0.57894737
B17: 本人に確認して代理記入した | C17: ='集計_障がい者'!$D$10 -> 8 | D17: ='集計_障がい者'!$E$10 -> 0.21052632
B18: 本人の様子や日頃の意向を踏まえて代理記入した | C18: ='集計_障がい者'!$D$11 -> 2 | D18: ='集計_障がい者'!$E$11 -> 0.052631579
B19: 本人に確認することが難しく、家族・支援者の判断で記入した | C19: ='集計_障がい者'!$D$12 -> 6 | D19: ='集計_障がい者'!$E$12 -> 0.15789474
B20: その他 | C20: ='集計_障がい者'!$D$13 -> 0 | D20: ='集計_障がい者'!$E$13 -> 0
B23: 図3-3 年齢（問2）
B24: ="n="&'集計_障がい者'!$F$14&"（単一回答）" -> n=37（単一回答）
B25: 選択肢 | C25: 件数 | D25: 割合
B26: 18～29歳 | C26: ='集計_障がい者'!$D$14 -> 0 | D26: ='集計_障がい者'!$E$14 -> 0
B27: 30～39歳 | C27: ='集計_障がい者'!$D$15 -> 3 | D27: ='集計_障がい者'!$E$15 -> 0.081081081
B28: 40～49歳 | C28: ='集計_障がい者'!$D$16 -> 2 | D28: ='集計_障がい者'!$E$16 -> 0.054054054
B29: 50～64歳 | C29: ='集計_障がい者'!$D$17 -> 7 | D29: ='集計_障がい者'!$E$17 -> 0.18918919
B30: 65歳以上 | C30: ='集計_障がい者'!$D$18 -> 25 | D30: ='集計_障がい者'!$E$18 -> 0.67567568
B34: 図3-4 お住まいの地区（問3）
B35: ="n="&'集計_障がい者'!$F$19&"（単一回答）" -> n=38（単一回答）
B36: 選択肢 | C36: 件数 | D36: 割合
B37: 北山地区 | C37: ='集計_障がい者'!$D$19 -> 17 | D37: ='集計_障がい者'!$E$19 -> 0.44736842
B38: 大塩地区 | C38: ='集計_障がい者'!$D$20 -> 7 | D38: ='集計_障がい者'!$E$20 -> 0.18421053
B39: 桧原地区 | C39: ='集計_障がい者'!$D$21 -> 3 | D39: ='集計_障がい者'!$E$21 -> 0.078947368
B40: 裏磐梯地区 | C40: ='集計_障がい者'!$D$22 -> 10 | D40: ='集計_障がい者'!$E$22 -> 0.26315789
B41: その他 | C41: ='集計_障がい者'!$D$23 -> 1 | D41: ='集計_障がい者'!$E$23 -> 0.026315789
B45: 図3-5 性別（問4）
B46: ="n="&'集計_障がい者'!$F$24&"（単一回答）" -> n=38（単一回答）
B47: 選択肢 | C47: 件数 | D47: 割合
B48: 男性 | C48: ='集計_障がい者'!$D$24 -> 16 | D48: ='集計_障がい者'!$E$24 -> 0.42105263
B49: 女性 | C49: ='集計_障がい者'!$D$25 -> 22 | D49: ='集計_障がい者'!$E$25 -> 0.57894737
B50: 回答しない | C50: ='集計_障がい者'!$D$26 -> 0 | D50: ='集計_障がい者'!$E$26 -> 0
B57: 図3-6 所持している手帳等（問5）
B58: ="n="&'集計_障がい者'!$F$27&"（複数回答）" -> n=37（複数回答）
B59: 選択肢 | C59: 件数 | D59: 割合
...

Sheet 3章_2生活・外出
B2: 図3-11 日常生活で困っていること（問10）
B3: ="n="&'集計_障がい者'!$F$77&"（複数回答）" -> n=36（複数回答）
B4: 選択肢 | C4: 件数 | D4: 割合
B5: 将来の生活 | C5: ='集計_障がい者'!$D$77 -> 11 | D5: ='集計_障がい者'!$E$77 -> 0.30555556
B6: 外出・移動 | C6: ='集計_障がい者'!$D$73 -> 10 | D6: ='集計_障がい者'!$E$73 -> 0.27777778
B7: 災害時の避難 | C7: ='集計_障がい者'!$D$75 -> 10 | D7: ='集計_障がい者'!$E$75 -> 0.27777778
B8: 通院 | C8: ='集計_障がい者'!$D$72 -> 7 | D8: ='集計_障がい者'!$E$72 -> 0.19444444
B9: 服薬管理 | C9: ='集計_障がい者'!$D$70 -> 5 | D9: ='集計_障がい者'!$E$70 -> 0.13888889
B10: 買い物 | C10: ='集計_障がい者'!$D$74 -> 5 | D10: ='集計_障がい者'!$E$74 -> 0.13888889
B11: 食事 | C11: ='集計_障がい者'!$D$67 -> 4 | D11: ='集計_障がい者'!$E$67 -> 0.11111111
B12: 入浴 | C12: ='集計_障がい者'!$D$68 -> 4 | D12: ='集計_障がい者'!$E$68 -> 0.11111111
B13: 金銭管理 | C13: ='集計_障がい者'!$D$71 -> 4 | D13: ='集計_障がい者'!$E$71 -> 0.11111111
B14: 排せつ | C14: ='集計_障がい者'!$D$69 -> 2 | D14: ='集計_障がい者'!$E$69 -> 0.055555556
B15: 家事 | C15: ='集計_障がい者'!$D$66 -> 1 | D15: ='集計_障がい者'!$E$66 -> 0.027777778
B16: 相談先がない | C16: ='集計_障がい者'!$D$76 -> 1 | D16: ='集計_障がい者'!$E$76 -> 0.027777778
B17: 特にない | C17: ='集計_障がい者'!$D$78 -> 13 | D17: ='集計_障がい者'!$E$78 -> 0.36111111
B18: その他 | C18: ='集計_障がい者'!$D$79 -> 1 | D18: ='集計_障がい者'!$E$79 -> 0.027777778
B22: 図3-12 将来希望する暮らし方（問11）
B23: ="n="&'集計_障がい者'!$F$80&"（単一回答）" -> n=36（単一回答）
B24: 選択肢 | C24: 件数 | D24: 割合
B25: 今の自宅で暮らしたい | C25: ='集計_障がい者'!$D$80 -> 15 | D25: ='集計_障がい者'!$E$80 -> 0.41666667
B26: 家族と一緒に暮らしたい | C26: ='集計_障がい者'!$D$81 -> 6 | D26: ='集計_障がい者'!$E$81 -> 0.16666667
B27: 一人暮らしをしたい | C27: ='集計_障がい者'!$D$82 -> 2 | D27: ='集計_障がい者'!$E$82 -> 0.055555556
B28: グループホームで暮らしたい | C28: ='集計_障がい者'!$D$83 -> 2 | D28: ='集計_障がい者'!$E$83 -> 0.055555556
B29: 施設で暮らしたい | C29: ='集計_障がい者'!$D$84 -> 4 | D29: ='集計_障がい者'!$E$84 -> 0.11111111
B30: 病院・施設から地域で暮らしたい | C30: ='集計_障がい者'!$D$85 -> 0 | D30: ='集計_障がい者'!$E$85 -> 0
B31: まだわからない | C31: ='集計_障がい者'!$D$86 -> 6 | D31: ='集計_障がい者'!$E$86 -> 0.16666667
B32: その他 | C32: ='集計_障がい者'!$D$87 -> 1 | D32: ='集計_障がい者'!$E$87 -> 0.027777778
B36: 図3-13 外出の頻度（問12）
B37: ="n="&'集計_障がい者'!$F$88&"（単一回答）" -> n=37（単一回答）
B38: 選択肢 | C38: 件数 | D38: 割合
B39: ほぼ毎日 | C39: ='集計_障がい者'!$D$88 -> 11 | D39: ='集計_障がい者'!$E$88 -> 0.2972973
B40: 週に2～4回 | C40: ='集計_障がい者'!$D$89 -> 6 | D40: ='集計_障がい者'!$E$89 -> 0.16216216
B41: 週に1回程度 | C41: ='集計_障がい者'!$D$90 -> 6 | D41: ='集計_障がい者'!$E$90 -> 0.16216216
B42: 月に数回 | C42: ='集計_障がい者'!$D$91 -> 6 | D42: ='集計_障がい者'!$E$91 -> 0.16216216
B43: ほとんど外出しない | C43: ='集計_障がい者'!$D$92 -> 8 | D43: ='集計_障がい者'!$E$92 -> 0.21621622
B47: 図3-14 外出時の主な移動手段（問13）
B48: ="n="&'集計_障がい者'!$F$93&"（複数回答）" -> n=34（複数回答）
B49: 選択肢 | C49: 件数 | D49: 割合
B50: 自分で運転 | C50: ='集計_障がい者'!$D$93 -> 17 | D50: ='集計_障がい者'!$E$93 -> 0.5
...

Sheet 3章_3医療
B2: 図3-16 定期的な通院（問15）
B3: ="n="&'集計_障がい者'!$F$112&"（単一回答）" -> n=36（単一回答）
B4: 選択肢 | C4: 件数 | D4: 割合
B5: 通院している | C5: ='集計_障がい者'!$D$112 -> 27 | D5: ='集計_障がい者'!$E$112 -> 0.75
B6: 通院していない | C6: ='集計_障がい者'!$D$113 -> 4 | D6: ='集計_障がい者'!$E$113 -> 0.11111111
B7: 訪問診療・往診を受けている | C7: ='集計_障がい者'!$D$114 -> 3 | D7: ='集計_障がい者'!$E$114 -> 0.083333333
B8: わからない | C8: ='集計_障がい者'!$D$115 -> 2 | D8: ='集計_障がい者'!$E$115 -> 0.055555556
B13: 図3-17 通院や医療で困っていること（問16）
B14: ="n="&'集計_障がい者'!$F$116&"（複数回答）" -> n=36（複数回答）
B15: 選択肢 | C15: 件数 | D15: 割合
B16: 専門医療機関が遠い | C16: ='集計_障がい者'!$D$116 -> 8 | D16: ='集計_障がい者'!$E$116 -> 0.22222222
B17: 付き添いが必要 | C17: ='集計_障がい者'!$D$118 -> 8 | D17: ='集計_障がい者'!$E$118 -> 0.22222222
B18: 医療費や交通費の負担が大きい | C18: ='集計_障がい者'!$D$119 -> 6 | D18: ='集計_障がい者'!$E$119 -> 0.16666667
B19: 緊急時の対応が不安 | C19: ='集計_障がい者'!$D$121 -> 6 | D19: ='集計_障がい者'!$E$121 -> 0.16666667
B20: 通院の交通手段がない | C20: ='集計_障がい者'!$D$117 -> 3 | D20: ='集計_障がい者'!$E$117 -> 0.083333333
B21: 予約・受診手続きが難しい | C21: ='集計_障がい者'!$D$120 -> 2 | D21: ='集計_障がい者'!$E$120 -> 0.055555556
B22: 特に困っていない | C22: ='集計_障がい者'!$D$122 -> 16 | D22: ='集計_障がい者'!$E$122 -> 0.44444444
B23: その他 | C23: ='集計_障がい者'!$D$123 -> 0 | D23: ='集計_障がい者'!$E$123 -> 0
B27: 図3-18 医療的ケアの必要性（問17）
B28: ="n="&'集計_障がい者'!$F$124&"（複数回答）" -> n=35（複数回答）
B29: 選択肢 | C29: 件数 | D29: 割合
B30: 必要としていない | C30: ='集計_障がい者'!$D$124 -> 29 | D30: ='集計_障がい者'!$E$124 -> 0.82857143
B31: 吸引 | C31: ='集計_障がい者'!$D$125 -> 1 | D31: ='集計_障がい者'!$E$125 -> 0.028571429
B32: 酸素療法 | C32: ='集計_障がい者'!$D$126 -> 1 | D32: ='集計_障がい者'!$E$126 -> 0.028571429
B33: 人工呼吸器（レスピレーター） | C33: ='集計_障がい者'!$D$127 -> 0 | D33: ='集計_障がい者'!$E$127 -> 0
B34: 導尿 | C34: ='集計_障がい者'!$D$128 -> 1 | D34: ='集計_障がい者'!$E$128 -> 0.028571429
B35: ストマ（人工肛門・人工膀胱） | C35: ='集計_障がい者'!$D$129 -> 0 | D35: ='集計_障がい者'!$E$129 -> 0
B36: 服薬管理等の継続支援 | C36: ='集計_障がい者'!$D$130 -> 3 | D36: ='集計_障がい者'!$E$130 -> 0.085714286
B37: 気管切開 | C37: ='集計_障がい者'!$D$131 -> 0 | D37: ='集計_障がい者'!$E$131 -> 0
B38: 胃ろう・腸ろう | C38: ='集計_障がい者'!$D$132 -> 1 | D38: ='集計_障がい者'!$E$132 -> 0.028571429
B39: 鼻腔管栄養 | C39: ='集計_障がい者'!$D$133 -> 0 | D39: ='集計_障がい者'!$E$133 -> 0
B40: 中心静脈栄養（IVH） | C40: ='集計_障がい者'!$D$134 -> 0 | D40: ='集計_障がい者'!$E$134 -> 0
B41: 透析 | C41: ='集計_障がい者'!$D$135 -> 0 | D41: ='集計_障がい者'!$E$135 -> 0
B42: カテーテル留置 | C42: ='集計_障がい者'!$D$136 -> 0 | D42: ='集計_障がい者'!$E$136 -> 0
B43: その他 | C43: ='集計_障がい者'!$D$137 -> 0 | D43: ='集計_障がい者'!$E$137 -> 0
B47: 図3-19 医療的ケアや重い障がいに関して必要な支援（問18）
B48: ="n="&'集計_障がい者'!$F$143&"（複数回答）" -> n=33（複数回答）
B49: 選択肢 | C49: 件数 | D49: 割合
B50: 家族の負担軽減 | C50: ='集計_障がい者'!$D$143 -> 8 | D50: ='集計_障がい者'!$E$143 -> 0.24242424
B51: 身近な相談先 | C51: ='集計_障がい者'!$D$138 -> 5 | D51: ='集計_障がい者'!$E$138 -> 0.15151515
...

Sheet 3章_4相談・情報
B2: 図3-22 意思決定支援の必要性（問21）
B3: ="n="&'集計_障がい者'!$F$158&"（単一回答）" -> n=33（単一回答）
B4: 選択肢 | C4: 件数 | D4: 割合
B5: 必要である（現在すでに支援を受けている、または今後受けたい） | C5: ='集計_障がい者'!$D$158 -> 8 | D5: ='集計_障がい者'!$E$158 -> 0.24242424
B6: 今は必要ないが、将来的には必要になると思う | C6: ='集計_障がい者'!$D$159 -> 12 | D6: ='集計_障がい者'!$E$159 -> 0.36363636
B7: 必要ない（自分や家族等と相談して意思決定ができる） | C7: ='集計_障がい者'!$D$160 -> 8 | D7: ='集計_障がい者'!$E$160 -> 0.24242424
B8: わからない（意思決定支援がどのようなものか知らない） | C8: ='集計_障がい者'!$D$161 -> 5 | D8: ='集計_障がい者'!$E$161 -> 0.15151515
B11: 図3-23 困ったときの相談相手・場所（問22）
B12: ="n="&'集計_障がい者'!$F$162&"（複数回答）" -> n=37（複数回答）
B13: 選択肢 | C13: 件数 | D13: 割合
B14: 家族・親族 | C14: ='集計_障がい者'!$D$162 -> 29 | D14: ='集計_障がい者'!$E$162 -> 0.78378378
B15: 医療機関 | C15: ='集計_障がい者'!$D$167 -> 12 | D15: ='集計_障がい者'!$E$167 -> 0.32432432
B16: 相談支援専門員 | C16: ='集計_障がい者'!$D$165 -> 9 | D16: ='集計_障がい者'!$E$165 -> 0.24324324
B17: 友人・知人 | C17: ='集計_障がい者'!$D$163 -> 6 | D17: ='集計_障がい者'!$E$163 -> 0.16216216
B18: 村役場 | C18: ='集計_障がい者'!$D$164 -> 5 | D18: ='集計_障がい者'!$E$164 -> 0.13513514
B19: 福祉サービス事業所 | C19: ='集計_障がい者'!$D$166 -> 5 | D19: ='集計_障がい者'!$E$166 -> 0.13513514
B20: 社会福祉協議会 | C20: ='集計_障がい者'!$D$169 -> 4 | D20: ='集計_障がい者'!$E$169 -> 0.10810811
B21: SNS・インターネット・AI | C21: ='集計_障がい者'!$D$168 -> 1 | D21: ='集計_障がい者'!$E$168 -> 0.027027027
B22: 民生委員・児童委員 | C22: ='集計_障がい者'!$D$170 -> 1 | D22: ='集計_障がい者'!$E$170 -> 0.027027027
B23: 相談する相手がいない | C23: ='集計_障がい者'!$D$171 -> 1 | D23: ='集計_障がい者'!$E$171 -> 0.027027027
B24: その他 | C24: ='集計_障がい者'!$D$172 -> 1 | D24: ='集計_障がい者'!$E$172 -> 0.027027027
B28: 図3-24 相談しにくい・相談できない理由（問23）
B29: ="n="&'集計_障がい者'!$F$178&"（複数回答）" -> n=31（複数回答）
B30: 選択肢 | C30: 件数 | D30: 割合
B31: 家族が対応している | C31: ='集計_障がい者'!$D$178 -> 8 | D31: ='集計_障がい者'!$E$178 -> 0.25806452
B32: 相談しても解決しないと思う | C32: ='集計_障がい者'!$D$176 -> 6 | D32: ='集計_障がい者'!$E$176 -> 0.19354839
B33: 何を相談してよいかわからない | C33: ='集計_障がい者'!$D$175 -> 4 | D33: ='集計_障がい者'!$E$175 -> 0.12903226
B34: プライバシーが不安 | C34: ='集計_障がい者'!$D$179 -> 4 | D34: ='集計_障がい者'!$E$179 -> 0.12903226
B35: 身近に相談先がない | C35: ='集計_障がい者'!$D$174 -> 1 | D35: ='集計_障がい者'!$E$174 -> 0.032258065
B36: 交通手段がない | C36: ='集計_障がい者'!$D$177 -> 1 | D36: ='集計_障がい者'!$E$177 -> 0.032258065
B37: 相談先がわからない | C37: ='集計_障がい者'!$D$173 -> 0 | D37: ='集計_障がい者'!$E$173 -> 0
B38: 特に困っていない | C38: ='集計_障がい者'!$D$180 -> 15 | D38: ='集計_障がい者'!$E$180 -> 0.48387097
B39: その他 | C39: ='集計_障がい者'!$D$181 -> 0 | D39: ='集計_障がい者'!$E$181 -> 0
B43: 図3-25 同じ障がいのある人（ピアサポーター）への相談意向（問24）
B44: ="n="&'集計_障がい者'!$F$182&"（単一回答）" -> n=34（単一回答）
B45: 選択肢 | C45: 件数 | D45: 割合
B46: 相談したい（現在も相談している） | C46: ='集計_障がい者'!$D$182 -> 0 | D46: ='集計_障がい者'!$E$182 -> 0
B47: 機会があれば相談してみたい | C47: ='集計_障がい者'!$D$183 -> 12 | D47: ='集計_障がい者'!$E$183 -> 0.35294118
B48: あまり相談したいとは思わない | C48: ='集計_障がい者'!$D$184 -> 9 | D48: ='集計_障がい者'!$E$184 -> 0.26470588
B49: まったく相談したいとは思わない | C49: ='集計_障がい者'!$D$185 -> 6 | D49: ='集計_障がい者'!$E$185 -> 0.17647059
...

Sheet 3章_5サービス
B2: 表3-1 サービス別の利用状況・認知度・今後の利用意向
B3: サービス | C3: 現在利用している（問27-1） | E3: 内容をよく知らない（問27-2） | G3: 今後3年間で利用したい（問27-3） | I3: 差（今後－現在） ポイント
C4: 件数 | D4: 割合 | E4: 件数 | F4: 割合 | G4: 件数 | H4: 割合
B5: 回答者数（n） | C5: ='集計_障がい者'!$F$205 -> 30 | E5: ='集計_障がい者'!$F$224 -> 24 | G5: ='集計_障がい者'!$F$243 -> 28
B6: 居宅介護（ホームヘルプ） | C6: ='集計_障がい者'!$D$205 -> 1 | D6: ='集計_障がい者'!$E$205 -> 0.033333333 | E6: ='集計_障がい者'!$D$224 -> 6 | F6: ='集計_障がい者'!$E$224 -> 0.25 | G6: ='集計_障がい者'!$D$243 -> 3 | H6: ='集計_障がい者'!$E$243 -> 0.10714286 | I6: =ROUND(H6*100,1)-ROUND(D6*100,1) -> 7.4
B7: 重度訪問介護 | C7: ='集計_障がい者'!$D$206 -> 0 | D7: ='集計_障がい者'!$E$206 -> 0 | E7: ='集計_障がい者'!$D$225 -> 9 | F7: ='集計_障がい者'!$E$225 -> 0.375 | G7: ='集計_障がい者'!$D$244 -> 0 | H7: ='集計_障がい者'!$E$244 -> 0 | I7: =ROUND(H7*100,1)-ROUND(D7*100,1) -> 0
B8: 同行援護・行動援護 | C8: ='集計_障がい者'!$D$207 -> 1 | D8: ='集計_障がい者'!$E$207 -> 0.033333333 | E8: ='集計_障がい者'!$D$226 -> 9 | F8: ='集計_障がい者'!$E$226 -> 0.375 | G8: ='集計_障がい者'!$D$245 -> 1 | H8: ='集計_障がい者'!$E$245 -> 0.035714286 | I8: =ROUND(H8*100,1)-ROUND(D8*100,1) -> 0.3
B9: 生活介護 | C9: ='集計_障がい者'!$D$208 -> 4 | D9: ='集計_障がい者'!$E$208 -> 0.13333333 | E9: ='集計_障がい者'!$D$227 -> 6 | F9: ='集計_障がい者'!$E$227 -> 0.25 | G9: ='集計_障がい者'!$D$246 -> 3 | H9: ='集計_障がい者'!$E$246 -> 0.10714286 | I9: =ROUND(H9*100,1)-ROUND(D9*100,1) -> -2.6
B10: 自立訓練 | C10: ='集計_障がい者'!$D$209 -> 2 | D10: ='集計_障がい者'!$E$209 -> 0.066666667 | E10: ='集計_障がい者'!$D$228 -> 8 | F10: ='集計_障がい者'!$E$228 -> 0.33333333 | G10: ='集計_障がい者'!$D$247 -> 2 | H10: ='集計_障がい者'!$E$247 -> 0.071428571 | I10: =ROUND(H10*100,1)-ROUND(D10*100,1) -> 0.4
B11: 就労移行支援 | C11: ='集計_障がい者'!$D$210 -> 0 | D11: ='集計_障がい者'!$E$210 -> 0 | E11: ='集計_障がい者'!$D$229 -> 8 | F11: ='集計_障がい者'!$E$229 -> 0.33333333 | G11: ='集計_障がい者'!$D$248 -> 1 | H11: ='集計_障がい者'!$E$248 -> 0.035714286 | I11: =ROUND(H11*100,1)-ROUND(D11*100,1) -> 3.6
B12: 就労継続支援A型 | C12: ='集計_障がい者'!$D$211 -> 1 | D12: ='集計_障がい者'!$E$211 -> 0.033333333 | E12: ='集計_障がい者'!$D$230 -> 8 | F12: ='集計_障がい者'!$E$230 -> 0.33333333 | G12: ='集計_障がい者'!$D$249 -> 0 | H12: ='集計_障がい者'!$E$249 -> 0 | I12: =ROUND(H12*100,1)-ROUND(D12*100,1) -> -3.3
B13: 就労継続支援B型 | C13: ='集計_障がい者'!$D$212 -> 2 | D13: ='集計_障がい者'!$E$212 -> 0.066666667 | E13: ='集計_障がい者'!$D$231 -> 8 | F13: ='集計_障がい者'!$E$231 -> 0.33333333 | G13: ='集計_障がい者'!$D$250 -> 1 | H13: ='集計_障がい者'!$E$250 -> 0.035714286 | I13: =ROUND(H13*100,1)-ROUND(D13*100,1) -> -3.1
B14: 就労選択支援 | C14: ='集計_障がい者'!$D$213 -> 1 | D14: ='集計_障がい者'!$E$213 -> 0.033333333 | E14: ='集計_障がい者'!$D$232 -> 9 | F14: ='集計_障がい者'!$E$232 -> 0.375 | G14: ='集計_障がい者'!$D$251 -> 0 | H14: ='集計_障がい者'!$E$251 -> 0 | I14: =ROUND(H14*100,1)-ROUND(D14*100,1) -> -3.3
B15: 就労定着支援 | C15: ='集計_障がい者'!$D$214 -> 0 | D15: ='集計_障がい者'!$E$214 -> 0 | E15: ='集計_障がい者'!$D$233 -> 8 | F15: ='集計_障がい者'!$E$233 -> 0.33333333 | G15: ='集計_障がい者'!$D$252 -> 0 | H15: ='集計_障がい者'!$E$252 -> 0 | I15: =ROUND(H15*100,1)-ROUND(D15*100,1) -> 0
B16: 短期入所（ショートステイ） | C16: ='集計_障がい者'!$D$215 -> 2 | D16: ='集計_障がい者'!$E$215 -> 0.066666667 | E16: ='集計_障がい者'!$D$234 -> 4 | F16: ='集計_障がい者'!$E$234 -> 0.16666667 | G16: ='集計_障がい者'!$D$253 -> 4 | H16: ='集計_障がい者'!$E$253 -> 0.14285714 | I16: =ROUND(H16*100,1)-ROUND(D16*100,1) -> 7.6
B17: グループホーム | C17: ='集計_障がい者'!$D$216 -> 3 | D17: ='集計_障がい者'!$E$216 -> 0.1 | E17: ='集計_障がい者'!$D$235 -> 5 | F17: ='集計_障がい者'!$E$235 -> 0.20833333 | G17: ='集計_障がい者'!$D$254 -> 5 | H17: ='集計_障がい者'!$E$254 -> 0.17857143 | I17: =ROUND(H17*100,1)-ROUND(D17*100,1) -> 7.9
B18: 施設入所支援 | C18: ='集計_障がい者'!$D$217 -> 5 | D18: ='集計_障がい者'!$E$217 -> 0.16666667 | E18: ='集計_障がい者'!$D$236 -> 6 | F18: ='集計_障がい者'!$E$236 -> 0.25 | G18: ='集計_障がい者'!$D$255 -> 9 | H18: ='集計_障がい者'!$E$255 -> 0.32142857 | I18: =ROUND(H18*100,1)-ROUND(D18*100,1) -> 15.4
B19: 計画相談支援 | C19: ='集計_障がい者'!$D$218 -> 2 | D19: ='集計_障がい者'!$E$218 -> 0.066666667 | E19: ='集計_障がい者'!$D$237 -> 7 | F19: ='集計_障がい者'!$E$237 -> 0.29166667 | G19: ='集計_障がい者'!$D$256 -> 3 | H19: ='集計_障がい者'!$E$256 -> 0.10714286 | I19: =ROUND(H19*100,1)-ROUND(D19*100,1) -> 4
B20: 移動支援 | C20: ='集計_障がい者'!$D$219 -> 1 | D20: ='集計_障がい者'!$E$219 -> 0.033333333 | E20: ='集計_障がい者'!$D$238 -> 9 | F20: ='集計_障がい者'!$E$238 -> 0.375 | G20: ='集計_障がい者'!$D$257 -> 2 | H20: ='集計_障がい者'!$E$257 -> 0.071428571 | I20: =ROUND(H20*100,1)-ROUND(D20*100,1) -> 3.8
B21: 日中一時支援 | C21: ='集計_障がい者'!$D$220 -> 1 | D21: ='集計_障がい者'!$E$220 -> 0.033333333 | E21: ='集計_障がい者'!$D$239 -> 8 | F21: ='集計_障がい者'!$E$239 -> 0.33333333 | G21: ='集計_障がい者'!$D$258 -> 1 | H21: ='集計_障がい者'!$E$258 -> 0.035714286 | I21: =ROUND(H21*100,1)-ROUND(D21*100,1) -> 0.3
B22: 日常生活用具 | C22: ='集計_障がい者'!$D$221 -> 1 | D22: ='集計_障がい者'!$E$221 -> 0.033333333 | E22: ='集計_障がい者'!$D$240 -> 6 | F22: ='集計_障がい者'!$E$240 -> 0.25 | G22: ='集計_障がい者'!$D$259 -> 1 | H22: ='集計_障がい者'!$E$259 -> 0.035714286 | I22: =ROUND(H22*100,1)-ROUND(D22*100,1) -> 0.3
B23: 訪問入浴 | C23: ='集計_障がい者'!$D$222 -> 0 | D23: ='集計_障がい者'!$E$222 -> 0 | E23: ='集計_障がい者'!$D$241 -> 5 | F23: ='集計_障がい者'!$E$241 -> 0.20833333 | G23: ='集計_障がい者'!$D$260 -> 0 | H23: ='集計_障がい者'!$E$260 -> 0 | I23: =ROUND(H23*100,1)-ROUND(D23*100,1) -> 0
B24: 特にない（各設問） | C24: ='集計_障がい者'!$D$223 -> 17 | D24: ='集計_障がい者'!$E$223 -> 0.56666667 | E24: ='集計_障がい者'!$D$242 -> 7 | F24: ='集計_障がい者'!$E$242 -> 0.29166667 | G24: ='集計_障がい者'!$D$261 -> 12 | H24: ='集計_障がい者'!$E$261 -> 0.42857143
B25: ※割合はいずれも複数回答。「差」は今後の利用意向（問27-3）と現在の利用（問27-1）の割合の差（ポイント）で、5ポイント以上の増加を赤字で示しています。（ ）内は件数です。 差は割合を小数点第1位に四捨五入したうえでの差です。
B27: 図3-28 現在利用しているサービスと今後3年間で利用したいサービス（問27-1・問27-3）
B29: サービス | C29: 現在利用している（問27-1） | D29: 今後3年間で利用したい（問27-3）
B30: 居宅介護（ホームヘルプ） | C30: ='集計_障がい者'!$E$205 -> 0.033333333 | D30: ='集計_障がい者'!$E$243 -> 0.10714286
B31: 同行援護・行動援護 | C31: ='集計_障がい者'!$E$207 -> 0.033333333 | D31: ='集計_障がい者'!$E$245 -> 0.035714286
B32: 生活介護 | C32: ='集計_障がい者'!$E$208 -> 0.13333333 | D32: ='集計_障がい者'!$E$246 -> 0.10714286
B33: 自立訓練 | C33: ='集計_障がい者'!$E$209 -> 0.066666667 | D33: ='集計_障がい者'!$E$247 -> 0.071428571
B34: 就労移行支援 | C34: ='集計_障がい者'!$E$210 -> 0 | D34: ='集計_障がい者'!$E$248 -> 0.035714286
B35: 就労継続支援A型 | C35: ='集計_障がい者'!$E$211 -> 0.033333333 | D35: ='集計_障がい者'!$E$249 -> 0
B36: 就労継続支援B型 | C36: ='集計_障がい者'!$E$212 -> 0.066666667 | D36: ='集計_障がい者'!$E$250 -> 0.035714286
B37: 就労選択支援 | C37: ='集計_障がい者'!$E$213 -> 0.033333333 | D37: ='集計_障がい者'!$E$251 -> 0
B38: 短期入所（ショートステイ） | C38: ='集計_障がい者'!$E$215 -> 0.066666667 | D38: ='集計_障がい者'!$E$253 -> 0.14285714
B39: グループホーム | C39: ='集計_障がい者'!$E$216 -> 0.1 | D39: ='集計_障がい者'!$E$254 -> 0.17857143
B40: 施設入所支援 | C40: ='集計_障がい者'!$E$217 -> 0.16666667 | D40: ='集計_障がい者'!$E$255 -> 0.32142857
B41: 計画相談支援 | C41: ='集計_障がい者'!$E$218 -> 0.066666667 | D41: ='集計_障がい者'!$E$256 -> 0.10714286
B42: 移動支援 | C42: ='集計_障がい者'!$E$219 -> 0.033333333 | D42: ='集計_障がい者'!$E$257 -> 0.071428571
B43: 日中一時支援 | C43: ='集計_障がい者'!$E$220 -> 0.033333333 | D43: ='集計_障がい者'!$E$258 -> 0.035714286
...

Sheet 3章_6日中・権利
B2: 図3-33 現在の日中の過ごし方（問31）
B3: ="n="&'集計_障がい者'!$F$287&"（単一回答）" -> n=34（単一回答）
B4: 選択肢 | C4: 件数 | D4: 割合
B5: 一般企業等で働いている | C5: ='集計_障がい者'!$D$287 -> 2 | D5: ='集計_障がい者'!$E$287 -> 0.058823529
B6: 自営業・農業等をしている | C6: ='集計_障がい者'!$D$288 -> 4 | D6: ='集計_障がい者'!$E$288 -> 0.11764706
B7: 就労継続支援A型を利用 | C7: ='集計_障がい者'!$D$289 -> 0 | D7: ='集計_障がい者'!$E$289 -> 0
B8: 就労継続支援B型を利用 | C8: ='集計_障がい者'!$D$290 -> 2 | D8: ='集計_障がい者'!$E$290 -> 0.058823529
B9: 生活介護を利用 | C9: ='集計_障がい者'!$D$291 -> 2 | D9: ='集計_障がい者'!$E$291 -> 0.058823529
B10: 学校に通っている | C10: ='集計_障がい者'!$D$292 -> 0 | D10: ='集計_障がい者'!$E$292 -> 0
B11: 自宅で過ごすことが多い | C11: ='集計_障がい者'!$D$293 -> 14 | D11: ='集計_障がい者'!$E$293 -> 0.41176471
B12: 入院・入所中 | C12: ='集計_障がい者'!$D$294 -> 5 | D12: ='集計_障がい者'!$E$294 -> 0.14705882
B13: その他 | C13: ='集計_障がい者'!$D$295 -> 5 | D13: ='集計_障がい者'!$E$295 -> 0.14705882
B17: 図3-34 今後希望する日中活動・働き方（問32）
B18: ="n="&'集計_障がい者'!$F$296&"（単一回答）" -> n=32（単一回答）
B19: 選択肢 | C19: 件数 | D19: 割合
B20: 一般企業等で働きたい | C20: ='集計_障がい者'!$D$296 -> 1 | D20: ='集計_障がい者'!$E$296 -> 0.03125
B21: 短時間・体調に合わせて働きたい | C21: ='集計_障がい者'!$D$297 -> 3 | D21: ='集計_障がい者'!$E$297 -> 0.09375
B22: 就労継続支援A型を利用したい | C22: ='集計_障がい者'!$D$298 -> 0 | D22: ='集計_障がい者'!$E$298 -> 0
B23: 就労継続支援B型を利用したい | C23: ='集計_障がい者'!$D$299 -> 1 | D23: ='集計_障がい者'!$E$299 -> 0.03125
B24: 生活介護を利用したい | C24: ='集計_障がい者'!$D$300 -> 1 | D24: ='集計_障がい者'!$E$300 -> 0.03125
B25: 訓練を受けたい | C25: ='集計_障がい者'!$D$301 -> 0 | D25: ='集計_障がい者'!$E$301 -> 0
B26: 今のままでよい | C26: ='集計_障がい者'!$D$302 -> 21 | D26: ='集計_障がい者'!$E$302 -> 0.65625
B27: まだわからない | C27: ='集計_障がい者'!$D$303 -> 3 | D27: ='集計_障がい者'!$E$303 -> 0.09375
B28: その他 | C28: ='集計_障がい者'!$D$304 -> 2 | D28: ='集計_障がい者'!$E$304 -> 0.0625
B32: 図3-35 働くため・日中活動を続けるために必要な支援（問33）
B33: ="n="&'集計_障がい者'!$F$309&"（複数回答）" -> n=31（複数回答）
B34: 選択肢 | C34: 件数 | D34: 割合
B35: 職場の障がい理解 | C35: ='集計_障がい者'!$D$309 -> 7 | D35: ='集計_障がい者'!$E$309 -> 0.22580645
B36: 体調に合わせた勤務 | C36: ='集計_障がい者'!$D$308 -> 6 | D36: ='集計_障がい者'!$E$308 -> 0.19354839
B37: 通勤・通所の支援 | C37: ='集計_障がい者'!$D$307 -> 5 | D37: ='集計_障がい者'!$E$307 -> 0.16129032
B38: 職場・作業内容の体験 | C38: ='集計_障がい者'!$D$305 -> 4 | D38: ='集計_障がい者'!$E$305 -> 0.12903226
B39: 就労に向けた相談 | C39: ='集計_障がい者'!$D$306 -> 4 | D39: ='集計_障がい者'!$E$306 -> 0.12903226
B40: 生活リズムの支援 | C40: ='集計_障がい者'!$D$311 -> 4 | D40: ='集計_障がい者'!$E$311 -> 0.12903226
B41: 仕事後の相談・定着支援 | C41: ='集計_障がい者'!$D$310 -> 2 | D41: ='集計_障がい者'!$E$310 -> 0.064516129
B42: 家族への説明 | C42: ='集計_障がい者'!$D$312 -> 0 | D42: ='集計_障がい者'!$E$312 -> 0
B43: 特にない | C43: ='集計_障がい者'!$D$313 -> 19 | D43: ='集計_障がい者'!$E$313 -> 0.61290323
B44: その他 | C44: ='集計_障がい者'!$D$314 -> 0 | D44: ='集計_障がい者'!$E$314 -> 0
B48: 図3-36 差別や偏見、不利益を感じた経験（問34）
B49: ="n="&'集計_障がい者'!$F$315&"（単一回答）" -> n=31（単一回答）
B50: 選択肢 | C50: 件数 | D50: 割合
...

Sheet 3章_7災害・施策
B2: 図3-40 災害時に不安なこと（問38）
B3: ="n="&'集計_障がい者'!$F$346&"（複数回答）" -> n=34（複数回答）
B4: 選択肢 | C4: 件数 | D4: 割合
B5: 避難先での生活 | C5: ='集計_障がい者'!$D$346 -> 24 | D5: ='集計_障がい者'!$E$346 -> 0.70588235
B6: 薬・医療機器 | C6: ='集計_障がい者'!$D$347 -> 17 | D6: ='集計_障がい者'!$E$347 -> 0.5
B7: 冬季・積雪時の避難 | C7: ='集計_障がい者'!$D$351 -> 16 | D7: ='集計_障がい者'!$E$351 -> 0.47058824
B8: 避難する方法 | C8: ='集計_障がい者'!$D$345 -> 13 | D8: ='集計_障がい者'!$E$345 -> 0.38235294
B9: 電源の確保 | C9: ='集計_障がい者'!$D$348 -> 6 | D9: ='集計_障がい者'!$E$348 -> 0.17647059
B10: 情報が届かないこと | C10: ='集計_障がい者'!$D$350 -> 5 | D10: ='集計_障がい者'!$E$350 -> 0.14705882
B11: 介助者がいないこと | C11: ='集計_障がい者'!$D$349 -> 3 | D11: ='集計_障がい者'!$E$349 -> 0.088235294
B12: ペット・補助犬等 | C12: ='集計_障がい者'!$D$352 -> 0 | D12: ='集計_障がい者'!$E$352 -> 0
B13: 特に不安はない | C13: ='集計_障がい者'!$D$353 -> 3 | D13: ='集計_障がい者'!$E$353 -> 0.088235294
B14: その他 | C14: ='集計_障がい者'!$D$354 -> 0 | D14: ='集計_障がい者'!$E$354 -> 0
B18: 図3-41 避難行動要支援者名簿・個別避難計画の認知（問39）
B19: ="n="&'集計_障がい者'!$F$355&"（単一回答）" -> n=34（単一回答）
B20: 選択肢 | C20: 件数 | D20: 割合
B21: 制度を知っており作成したい | C21: ='集計_障がい者'!$D$355 -> 2 | D21: ='集計_障がい者'!$E$355 -> 0.058823529
B22: 名前だけ聞いたことがある | C22: ='集計_障がい者'!$D$356 -> 5 | D22: ='集計_障がい者'!$E$356 -> 0.14705882
B23: 知らない | C23: ='集計_障がい者'!$D$357 -> 26 | D23: ='集計_障がい者'!$E$357 -> 0.76470588
B24: 必要ない | C24: ='集計_障がい者'!$D$358 -> 1 | D24: ='集計_障がい者'!$E$358 -> 0.029411765
B29: 図3-42 災害時に支援してくれる人や機関（問40）
B30: ="n="&'集計_障がい者'!$F$359&"（複数回答）" -> n=35（複数回答）
B31: 選択肢 | C31: 件数 | D31: 割合
B32: 同居家族 | C32: ='集計_障がい者'!$D$359 -> 23 | D32: ='集計_障がい者'!$E$359 -> 0.65714286
B33: 別居家族・親族 | C33: ='集計_障がい者'!$D$360 -> 10 | D33: ='集計_障がい者'!$E$360 -> 0.28571429
B34: 近所の人 | C34: ='集計_障がい者'!$D$361 -> 6 | D34: ='集計_障がい者'!$E$361 -> 0.17142857
B35: 福祉サービス事業所 | C35: ='集計_障がい者'!$D$363 -> 6 | D35: ='集計_障がい者'!$E$363 -> 0.17142857
B36: 医療機関 | C36: ='集計_障がい者'!$D$364 -> 4 | D36: ='集計_障がい者'!$E$364 -> 0.11428571
B37: 消防・警察 | C37: ='集計_障がい者'!$D$365 -> 4 | D37: ='集計_障がい者'!$E$365 -> 0.11428571
B38: 民生委員・児童委員 | C38: ='集計_障がい者'!$D$362 -> 3 | D38: ='集計_障がい者'!$E$362 -> 0.085714286
B39: いない・わからない | C39: ='集計_障がい者'!$D$366 -> 1 | D39: ='集計_障がい者'!$E$366 -> 0.028571429
B40: その他 | C40: ='集計_障がい者'!$D$367 -> 1 | D40: ='集計_障がい者'!$E$367 -> 0.028571429
B44: 図3-43 災害時に必要だと思う支援（問41）
B45: ="n="&'集計_障がい者'!$F$371&"（複数回答）" -> n=33（複数回答）
B46: 選択肢 | C46: 件数 | D46: 割合
B47: 薬・医療機器・電源の確保 | C47: ='集計_障がい者'!$D$371 -> 21 | D47: ='集計_障がい者'!$E$371 -> 0.63636364
B48: 福祉避難所の情報提供 | C48: ='集計_障がい者'!$D$370 -> 12 | D48: ='集計_障がい者'!$E$370 -> 0.36363636
B49: 冬季避難の支援 | C49: ='集計_障がい者'!$D$372 -> 12 | D49: ='集計_障がい者'!$E$372 -> 0.36363636
B50: 安否確認 | C50: ='集計_障がい者'!$D$373 -> 12 | D50: ='集計_障がい者'!$E$373 -> 0.36363636
B51: 文字・掲示・字幕等の目で見てわかる災害情報 | C51: ='集計_障がい者'!$D$375 -> 12 | D51: ='集計_障がい者'!$E$375 -> 0.36363636
...

Sheet 4章_クロス集計
B2: 表4-1 クロス集計の分析テーマ
B3: No. | C3: 分析テーマ | H3: クロス軸（区分 × 集計項目）
B4: C01 | C4: 障がい種別ごとの今後のサービス利用ニーズ | H4: 問6 × 問27-3
B5: C02 | C5: 地区別の外出・交通上の課題 | H5: 問3 × 問14
B6: C03 | C6: 地区別のサービス利用阻害要因 | H6: 問3 × 問28
B7: C04 | C7: 現在の暮らしと将来希望のギャップ | H7: 問7 × 問11
B8: C05 | C8: 年齢別の日常生活上の困りごと | H8: 問2 × 問10
B9: C06 | C9: 現在の日中活動と希望する働き方・活動 | H9: 問31 × 問32
B10: C07 | C10: 個別避難計画の認知と災害時不安 | H10: 問39 × 問38
B11: C08 | C11: 障がい種別ごとに必要な合理的配慮 | H11: 問6 × 問36
B12: C09 | C12: 相談先別の相談支援への期待 | H12: 問22 × 問26
B13: C10 | C13: 主な介助者別の地域生活支援拠点への期待 | H13: 問9 × 問29
B15: 表4-2 障がい種別 × 今後3年間で利用したいサービス（問6×問27-3）
B16: 【件数】青字のセルが入力値です
B17: 区分 | C17: 身体障がい | D17: 知的障がい | E17: 精神障がい | F17: 発達障がい | G17: わからない・その他
B18: 回答者数（n） | C18: 26 | D18: 2 | E18: 4 | F18: 3 | G18: 2
B19: 居宅介護（ホームヘルプ） | C19: 3 | D19: 0 | E19: 0 | F19: 0 | G19: 0
B20: 同行援護・行動援護 | C20: 1 | D20: 0 | E20: 0 | F20: 0 | G20: 0
B21: 生活介護 | C21: 0 | D21: 2 | E21: 1 | F21: 0 | G21: 0
B22: 自立訓練 | C22: 1 | D22: 0 | E22: 0 | F22: 0 | G22: 1
B23: 就労移行支援 | C23: 0 | D23: 0 | E23: 0 | F23: 1 | G23: 0
B24: 就労継続支援B型 | C24: 0 | D24: 0 | E24: 0 | F24: 0 | G24: 1
B25: 短期入所（ショートステイ） | C25: 3 | D25: 0 | E25: 0 | F25: 0 | G25: 1
B26: グループホーム | C26: 3 | D26: 0 | E26: 1 | F26: 0 | G26: 1
B27: 施設入所支援 | C27: 5 | D27: 2 | E27: 1 | F27: 0 | G27: 1
B28: 計画相談支援 | C28: 1 | D28: 1 | E28: 0 | F28: 0 | G28: 1
B29: 移動支援 | C29: 0 | D29: 0 | E29: 2 | F29: 0 | G29: 0
... B32: 利用したいサービスは特にない | C32: 9 | D32: 0 | E32: 2 | F32: 1 | G32: 0
B34: 【割合】各区分の回答者数（n）に占める割合（計算式）
B35: 区分 | C35: 身体障がい | D35: 知的障がい | E35: 精神障がい | F35: 発達障がい | G35: わからない・その他
B36: 居宅介護（ホームヘルプ） | C36: =IF($C$18=0,0,$C$19/$C$18) -> 0.11538462 | D36: =IF($D$18=0,0,$D$19/$D$18) -> 0 | E36: =IF($E$18=0,0,$E$19/$E$18) -> 0 | F36: =IF($F$18=0,0,$F$19/$F$18) -> 0 | G36: =IF($G$18=0,0,$G$19/$G$18) -> 0
B37: 同行援護・行動援護 | C37: =IF($C$18=0,0,$C$20/$C$18) -> 0.038461538 | D37: =IF($D$18=0,0,$D$20/$D$18) -> 0 | E37: =IF($E$18=0,0,$E$20/$E$18) -> 0 | F37: =IF($F$18=0,0,$F$20/$F$18) -> 0 | G37: =IF($G$18=0,0,$G$20/$G$18) -> 0
B38: 生活介護 | C38: =IF($C$18=0,0,$C$21/$C$18) -> 0 | D38: =IF($D$18=0,0,$D$21/$D$18) -> 1 | E38: =IF($E$18=0,0,$E$21/$E$18) -> 0.25 | F38: =IF($F$18=0,0,$F$21/$F$18) -> 0 | G38: =IF($G$18=0,0,$G$21/$G$18) -> 0
B39: 自立訓練 | C39: =IF($C$18=0,0,$C$22/$C$18) -> 0.038461538 | D39: =IF($D$18=0,0,$D$22/$D$18) -> 0 | E39: =IF($E$18=0,0,$E$22/$E$18) -> 0 | F39: =IF($F$18=0,0,$F$22/$F$18) -> 0 | G39: =IF($G$18=0,0,$G$22/$G$18) -> 0.5
B40: 就労移行支援 | C40: =IF($C$18=0,0,$C$23/$C$18) -> 0 | D40: =IF($D$18=0,0,$D$23/$D$18) -> 0 | E40: =IF($E$18=0,0,$E$23/$E$18) -> 0 | F40: =IF($F$18=0,0,$F$23/$F$18) -> 0.33333333 | G40: =IF($G$18=0,0,$G$23/$G$18) -> 0
B41: 就労継続支援B型 | C41: =IF($C$18=0,0,$C$24/$C$18) -> 0 | D41: =IF($D$18=0,0,$D$24/$D$18) -> 0 | E41: =IF($E$18=0,0,$E$24/$E$18) -> 0 | F41: =IF($F$18=0,0,$F$24/$F$18) -> 0 | G41: =IF($G$18=0,0,$G$24/$G$18) -> 0.5
B42: 短期入所（ショートステイ） | C42: =IF($C$18=0,0,$C$25/$C$18) -> 0.11538462 | D42: =IF($D$18=0,0,$D$25/$D$18) -> 0 | E42: =IF($E$18=0,0,$E$25/$E$18) -> 0 | F42: =IF($F$18=0,0,$F$25/$F$18) -> 0 | G42: =IF($G$18=0,0,$G$25/$G$18) -> 0.5
B43: グループホーム | C43: =IF($C$18=0,0,$C$26/$C$18) -> 0.11538462 | D43: =IF($D$18=0,0,$D$26/$D$18) -> 0 | E43: =IF($E$18=0,0,$E$26/$E$18) -> 0.25 | F43: =IF($F$18=0,0,$F$26/$F$18) -> 0 | G43: =IF($G$18=0,0,$G$26/$G$18) -> 0.5
B44: 施設入所支援 | C44: =IF($C$18=0,0,$C$27/$C$18) -> 0.19230769 | D44: =IF($D$18=0,0,$D$27/$D$18) -> 1 | E44: =IF($E$18=0,0,$E$27/$E$18) -> 0.25 | F44: =IF($F$18=0,0,$F$27/$F$18) -> 0 | G44: =IF($G$18=0,0,$G$27/$G$18) -> 0.5
B45: 計画相談支援 | C45: =IF($C$18=0,0,$C$28/$C$18) -> 0.038461538 | D45: =IF($D$18=0,0,$D$28/$D$18) -> 0.5 | E45: =IF($E$18=0,0,$E$28/$E$18) -> 0 | F45: =IF($F$18=0,0,$F$28/$F$18) -> 0 | G45: =IF($G$18=0,0,$G$28/$G$18) -> 0.5
...

Sheet 5章_障がい児
B2: 表5-1 回答者の属性（障がい児調査）
B3: 項目 | C3: 回答（件数）
B4: 記入者（問1） | C4: 「ご家族」2件、「宛名のご本人」1件
B5: 本人意向の反映（問1-2） | C5: 「本人が回答した」1件、「本人の様子や日頃の意向を踏まえて代理記入した」1件、「本人に確認することが難しく、家族・支援者の判断で記入した」1件
B6: 年齢（問2） | C6: 「6～11歳」1件、「12～14歳」1件、「15～17歳」1件
B7: お住まいの地区（問3） | C7: 「北山地区」2件、「裏磐梯地区」1件
B8: 性別（問4） | C8: 「男性」2件、「女性」1件
B9: 所持している手帳等（問5・複数回答、n=2） | C9: 「身体障がい者手帳」2件、「療育手帳」1件、「精神障がい者保健福祉手帳」1件
B10: 主たる障がい種別（問6） | C10: 「身体障がい」1件、「知的障がい」1件、「発達障がい」1件
B11: 障害児通所支援等の支給決定（問7） | C11: 「受けている」2件、「受けていない」1件
B12: 主な支援・介助・見守りをしている方（問8） | C12: 「親」3件
B13: 現在の暮らし（問9） | C13: 「自宅で家族と暮らしている」3件
B15: 図5-1 日常生活で困っていること（問10）
B16: ="n="&'集計_障がい児'!$F$66&"（複数回答）" -> n=3（複数回答）
B17: 選択肢 | C17: 件数
B18: 将来の生活 | C18: ='集計_障がい児'!$D$66 -> 3
B19: 家事 | C19: ='集計_障がい児'!$D$55 -> 1
B20: 食事 | C20: ='集計_障がい児'!$D$56 -> 1
B21: 入浴 | C21: ='集計_障がい児'!$D$57 -> 1
B22: 排せつ | C22: ='集計_障がい児'!$D$58 -> 1
B23: 服薬管理 | C23: ='集計_障がい児'!$D$59 -> 1
B24: 金銭管理 | C24: ='集計_障がい児'!$D$60 -> 1
B25: 通院 | C25: ='集計_障がい児'!$D$61 -> 1
B26: 外出・移動 | C26: ='集計_障がい児'!$D$62 -> 1
B27: 買い物 | C27: ='集計_障がい児'!$D$63 -> 1
B28: 災害時の避難 | C28: ='集計_障がい児'!$D$64 -> 1
B29: 相談先がない | C29: ='集計_障がい児'!$D$65 -> 0
B30: 特にない | C30: ='集計_障がい児'!$D$67 -> 0
B31: その他 | C31: ='集計_障がい児'!$D$68 -> 1
B35: 図5-2 外出するときに困ること（問14）
B36: ="n="&'集計_障がい児'!$F$89&"（複数回答）" -> n=3（複数回答）
B37: 選択肢 | C37: 件数
B38: 交通手段が少ない | C38: ='集計_障がい児'!$D$89 -> 2
B39: 家族等の付き添いが必要 | C39: ='集計_障がい児'!$D$90 -> 2
B40: 送迎がない | C40: ='集計_障がい児'!$D$91 -> 1
B41: 冬季・積雪時に外出しにくい | C41: ='集計_障がい児'!$D$92 -> 1
B42: 体調面が不安 | C42: ='集計_障がい児'!$D$95 -> 1
B43: 費用がかかる | C43: ='集計_障がい児'!$D$96 -> 1
B44: その他 | C44: ='集計_障がい児'!$D$98 -> 1
B45: ※回答のなかった選択肢は省略しています。
...

Sheet 6章_課題
B2: 表6-1 課題と計画上の主な取組・指標の関係
B3: 課題 | C3: 関連する主な取組・指標の領域（例） | G3: 主な根拠設問
B4: 1 相談支援体制・情報提供 | C4: 相談支援体制の充実・強化、計画相談支援、意思決定支援の推進 | G4: 問22・問23・問26・問27-2・問44
B5: 2 移動・外出支援 | C5: 移動支援事業（地域生活支援事業）、同行援護・行動援護、関係部署との連携 | G5: 問13・問14・問16・児問24・児問29
B6: 3 災害時の支援体制 | C6: 個別避難計画の作成推進、福祉避難所の確保、防災分野との連携 | G6: 問38～問41・児問37～児問40
B7: 4 地域生活支援拠点・将来の暮らし | C7: 地域生活支援の充実（地域生活支援拠点等）、施設入所者の地域生活への移行、共同生活援助・短期入所の見込量 | G7: 問10・問11・問27-3・問29
B8: 5 障がい児・家族支援 | C8: 障がい児支援の提供体制の整備、放課後等デイサービス・障がい児相談支援の見込量、医療的ケア児支援 | G8: 児問18・児問24・児問25・児問29・児問31
B9: 6 権利擁護・合理的配慮 | C9: 成年後見制度利用支援事業、意思疎通支援事業、理解促進研修・啓発事業 | G9: 問34～問37・問43
B10: 7 日中活動・就労・社会参加 | C10: 福祉施設から一般就労への移行等、就労選択支援・就労系サービスの見込量 | G10: 問31～問33・問42・児問32
B11: 8 専門的支援 | C11: 精神障がいにも対応した地域包括ケアシステムの構築、強度行動障がい・医療的ケアへの対応 | G11: 問17～問20
B12: ※「児問」は障がい児調査の設問を示します。関連する取組・指標の領域は例示であり、国の基本指針の内容に応じて整理してください。

Sheet 集計_障がい者
A1: 障がい者調査（18歳以上） 単純集計（入力データ）
A2: 青字のセル（件数・有効回答数）が入力値です。割合は計算式で、各章シートの表・グラフに自動で反映されます。有効回答数は各設問の先頭行に入力し、2行目以降は先頭行を参照しています。
A4: 設問番号 | B4: 設問 | C4: 選択肢 | D4: 件数 | E4: 割合 | F4: 有効回答数（n） | G4: 回答形式
A5: 問1 | B5: この調査票を記入された方はどなたですか | C5: 宛名のご本人 | D5: 24 | E5: =IF($F5=0,0,D5/$F5) -> 0.63157895 | F5: 38 | G5: 単一回答
A6: 問1 | B6: この調査票を記入された方はどなたですか | C6: ご家族 | D6: 9 | E6: =IF($F6=0,0,D6/$F6) -> 0.23684211 | F6: =$F$5 -> 38 | G6: 単一回答
A7: 問1 | B7: この調査票を記入された方はどなたですか | C7: 支援者・事業所職員 | D7: 4 | E7: =IF($F7=0,0,D7/$F7) -> 0.10526316 | F7: =$F$5 -> 38 | G7: 単一回答
A8: 問1 | B8: この調査票を記入された方はどなたですか | C8: その他 | D8: 1 | E8: =IF($F8=0,0,D8/$F8) -> 0.026315789 | F8: =$F$5 -> 38 | G8: 単一回答
A9: 問1-2 | B9: この回答は、宛名のご本人の意向をどのように反映していますか | C9: 本人が回答した | D9: 22 | E9: =IF($F9=0,0,D9/$F9) -> 0.57894737 | F9: 38 | G9: 単一回答
A10: 問1-2 | B10: この回答は、宛名のご本人の意向をどのように反映していますか | C10: 本人に確認して代理記入した | D10: 8 | E10: =IF($F10=0,0,D10/$F10) -> 0.21052632 | F10: =$F$9 -> 38 | G10: 単一回答
A11: 問1-2 | B11: この回答は、宛名のご本人の意向をどのように反映していますか | C11: 本人の様子や日頃の意向を踏まえて代理記入した | D11: 2 | E11: =IF($F11=0,0,D11/$F11) -> 0.052631579 | F11: =$F$9 -> 38 | G11: 単一回答
A12: 問1-2 | B12: この回答は、宛名のご本人の意向をどのように反映していますか | C12: 本人に確認することが難しく、家族・支援者の判断で記入した | D12: 6 | E12: =IF($F12=0,0,D12/$F12) -> 0.15789474 | F12: =$F$9 -> 38 | G12: 単一回答
A13: 問1-2 | B13: この回答は、宛名のご本人の意向をどのように反映していますか | C13: その他 | D13: 0 | E13: =IF($F13=0,0,D13/$F13) -> 0 | F13: =$F$9 -> 38 | G13: 単一回答
A14: 問2 | B14: あなた（宛名の方）の年齢を教えてください | C14: 18～29歳 | D14: 0 | E14: =IF($F14=0,0,D14/$F14) -> 0 | F14: 37 | G14: 単一回答
A15: 問2 | B15: あなた（宛名の方）の年齢を教えてください | C15: 30～39歳 | D15: 3 | E15: =IF($F15=0,0,D15/$F15) -> 0.081081081 | F15: =$F$14 -> 37 | G15: 単一回答
A16: 問2 | B16: あなた（宛名の方）の年齢を教えてください | C16: 40～49歳 | D16: 2 | E16: =IF($F16=0,0,D16/$F16) -> 0.054054054 | F16: =$F$14 -> 37 | G16: 単一回答
A17: 問2 | B17: あなた（宛名の方）の年齢を教えてください | C17: 50～64歳 | D17: 7 | E17: =IF($F17=0,0,D17/$F17) -> 0.18918919 | F17: =$F$14 -> 37 | G17: 単一回答
A18: 問2 | B18: あなた（宛名の方）の年齢を教えてください | C18: 65歳以上 | D18: 25 | E18: =IF($F18=0,0,D18/$F18) -> 0.67567568 | F18: =$F$14 -> 37 | G18: 単一回答
A19: 問3 | B19: あなたのお住まいの地区を教えてください | C19: 北山地区 | D19: 17 | E19: =IF($F19=0,0,D19/$F19) -> 0.44736842 | F19: 38 | G19: 単一回答
A20: 問3 | B20: あなたのお住まいの地区を教えてください | C20: 大塩地区 | D20: 7 | E20: =IF($F20=0,0,D20/$F20) -> 0.18421053 | F20: =$F$19 -> 38 | G20: 単一回答
A21: 問3 | B21: あなたのお住まいの地区を教えてください | C21: 桧原地区 | D21: 3 | E21: =IF($F21=0,0,D21/$F21) -> 0.078947368 | F21: =$F$19 -> 38 | G21: 単一回答
A22: 問3 | B22: あなたのお住まいの地区を教えてください | C22: 裏磐梯地区 | D22: 10 | E22: =IF($F22=0,0,D22/$F22) -> 0.26315789 | F22: =$F$19 -> 38 | G22: 単一回答
A23: 問3 | B23: あなたのお住まいの地区を教えてください | C23: その他 | D23: 1 | E23: =IF($F23=0,0,D23/$F23) -> 0.026315789 | F23: =$F$19 -> 38 | G23: 単一回答
A24: 問4 | B24: あなたの性別を教えてください | C24: 男性 | D24: 16 | E24: =IF($F24=0,0,D24/$F24) -> 0.42105263 | F24: 38 | G24: 単一回答
A25: 問4 | B25: あなたの性別を教えてください | C25: 女性 | D25: 22 | E25: =IF($F25=0,0,D25/$F25) -> 0.57894737 | F25: =$F$24 -> 38 | G25: 単一回答
A26: 問4 | B26: あなたの性別を教えてください | C26: 回答しない | D26: 0 | E26: =IF($F26=0,0,D26/$F26) -> 0 | F26: =$F$24 -> 38 | G26: 単一回答
A27: 問5 | B27: お持ちの手帳等を教えてください（あてはまるものすべて） | C27: 身体障がい者手帳 | D27: 29 | E27: =IF($F27=0,0,D27/$F27) -> 0.78378378 | F27: 37 | G27: 複数回答
A28: 問5 | B28: お持ちの手帳等を教えてください（あてはまるものすべて） | C28: 療育手帳 | D28: 2 | E28: =IF($F28=0,0,D28/$F28) -> 0.054054054 | F28: =$F$27 -> 37 | G28: 複数回答
A29: 問5 | B29: お持ちの手帳等を教えてください（あてはまるものすべて） | C29: 精神障がい者保健福祉手帳 | D29: 6 | E29: =IF($F29=0,0,D29/$F29) -> 0.16216216 | F29: =$F$27 -> 37 | G29: 複数回答
A30: 問5 | B30: お持ちの手帳等を教えてください（あてはまるものすべて） | C30: 自立支援医療受給者証 | D30: 4 | E30: =IF($F30=0,0,D30/$F30) -> 0.10810811 | F30: =$F$27 -> 37 | G30: 複数回答
A31: 問5 | B31: お持ちの手帳等を教えてください（あてはまるものすべて） | C31: 難病に関する医療受給者証等 | D31: 0 | E31: =IF($F31=0,0,D31/$F31) -> 0 | F31: =$F$27 -> 37 | G31: 複数回答
A32: 問5 | B32: お持ちの手帳等を教えてください（あてはまるものすべて） | C32: 手帳等は持っていないが障がい福祉サービスを利用している | D32: 0 | E32: =IF($F32=0,0,D32/$F32) -> 0 | F32: =$F$27 -> 37 | G32: 複数回答
A33: 問5 | B33: お持ちの手帳等を教えてください（あてはまるものすべて） | C33: その他 | D33: 2 | E33: =IF($F33=0,0,D33/$F33) -> 0.054054054 | F33: =$F$27 -> 37 | G33: 複数回答
A34: 問6 | B34: 主たる障がい種別を1つ選ぶとすれば、どれにあたりますか | C34: 身体障がい | D34: 26 | E34: =IF($F34=0,0,D34/$F34) -> 0.7027027 | F34: 37 | G34: 単一回答
A35: 問6 | B35: 主たる障がい種別を1つ選ぶとすれば、どれにあたりますか | C35: 知的障がい | D35: 2 | E35: =IF($F35=0,0,D35/$F35) -> 0.054054054 | F35: =$F$34 -> 37 | G35: 単一回答
A36: 問6 | B36: 主たる障がい種別を1つ選ぶとすれば、どれにあたりますか | C36: 精神障がい | D36: 4 | E36: =IF($F36=0,0,D36/$F36) -> 0.10810811 | F36: =$F$34 -> 37 | G36: 単一回答
A37: 問6 | B37: 主たる障がい種別を1つ選ぶとすれば、どれにあたりますか | C37: 発達障がい | D37: 3 | E37: =IF($F37=0,0,D37/$F37) -> 0.081081081 | F37: =$F$34 -> 37 | G37: 単一回答
A38: 問6 | B38: 主たる障がい種別を1つ選ぶとすれば、どれにあたりますか | C38: 難病 | D38: 0 | E38: =IF($F38=0,0,D38/$F38) -> 0 | F38: =$F$34 -> 37 | G38: 単一回答
A39: 問6 | B39: 主たる障がい種別を1つ選ぶとすれば、どれにあたりますか | C39: 高次脳機能障がい | D39: 0 | E39: =IF($F39=0,0,D39/$F39) -> 0 | F39: =$F$34 -> 37 | G39: 単一回答
A40: 問6 | B40: 主たる障がい種別を1つ選ぶとすれば、どれにあたりますか | C40: 重症心身障がい | D40: 0 | E40: =IF($F40=0,0,D40/$F40) -> 0 | F40: =$F$34 -> 37 | G40: 単一回答
A41: 問6 | B41: 主たる障がい種別を1つ選ぶとすれば、どれにあたりますか | C41: わからない・その他 | D41: 2 | E41: =IF($F41=0,0,D41/$F41) -> 0.054054054 | F41: =$F$34 -> 37 | G41: 単一回答
...

Sheet 集計_障がい児
A1: 障がい児調査（18歳未満） 単純集計（入力データ）
A2: 青字のセル（件数・有効回答数）が入力値です。割合は計算式で、各章シートの表・グラフに自動で反映されます。有効回答数は各設問の先頭行に入力し、2行目以降は先頭行を参照しています。
A4: 設問番号 | B4: 設問 | C4: 選択肢 | D4: 件数 | E4: 割合 | F4: 有効回答数（n） | G4: 回答形式
A5: 問1 | B5: この調査票を記入された方はどなたですか | C5: 宛名のご本人 | D5: 1 | E5: =IF($F5=0,0,D5/$F5) -> 0.33333333 | F5: 3 | G5: 単一回答
A6: 問1 | B6: この調査票を記入された方はどなたですか | C6: ご家族 | D6: 2 | E6: =IF($F6=0,0,D6/$F6) -> 0.66666667 | F6: =$F$5 -> 3 | G6: 単一回答
A7: 問1 | B7: この調査票を記入された方はどなたですか | C7: 支援者・事業所職員 | D7: 0 | E7: =IF($F7=0,0,D7/$F7) -> 0 | F7: =$F$5 -> 3 | G7: 単一回答
A8: 問1 | B8: この調査票を記入された方はどなたですか | C8: その他 | D8: 0 | E8: =IF($F8=0,0,D8/$F8) -> 0 | F8: =$F$5 -> 3 | G8: 単一回答
A9: 問1-2 | B9: この回答は、宛名のご本人の意向をどのように反映していますか | C9: 本人が回答した | D9: 1 | E9: =IF($F9=0,0,D9/$F9) -> 0.33333333 | F9: 3 | G9: 単一回答
A10: 問1-2 | B10: この回答は、宛名のご本人の意向をどのように反映していますか | C10: 本人に確認して代理記入した | D10: 0 | E10: =IF($F10=0,0,D10/$F10) -> 0 | F10: =$F$9 -> 3 | G10: 単一回答
A11: 問1-2 | B11: この回答は、宛名のご本人の意向をどのように反映していますか | C11: 本人の様子や日頃の意向を踏まえて代理記入した | D11: 1 | E11: =IF($F11=0,0,D11/$F11) -> 0.33333333 | F11: =$F$9 -> 3 | G11: 単一回答
A12: 問1-2 | B12: この回答は、宛名のご本人の意向をどのように反映していますか | C12: 本人に確認することが難しく、家族・支援者の判断で記入した | D12: 1 | E12: =IF($F12=0,0,D12/$F12) -> 0.33333333 | F12: =$F$9 -> 3 | G12: 単一回答
A13: 問1-2 | B13: この回答は、宛名のご本人の意向をどのように反映していますか | C13: その他 | D13: 0 | E13: =IF($F13=0,0,D13/$F13) -> 0 | F13: =$F$9 -> 3 | G13: 単一回答
A14: 問2 | B14: お子さん（宛名の方）の年齢を教えてください | C14: 0～5歳 | D14: 0 | E14: =IF($F14=0,0,D14/$F14) -> 0 | F14: 3 | G14: 単一回答
A15: 問2 | B15: お子さん（宛名の方）の年齢を教えてください | C15: 6～11歳 | D15: 1 | E15: =IF($F15=0,0,D15/$F15) -> 0.33333333 | F15: =$F$14 -> 3 | G15: 単一回答
A16: 問2 | B16: お子さん（宛名の方）の年齢を教えてください | C16: 12～14歳 | D16: 1 | E16: =IF($F16=0,0,D16/$F16) -> 0.33333333 | F16: =$F$14 -> 3 | G16: 単一回答
A17: 問2 | B17: お子さん（宛名の方）の年齢を教えてください | C17: 15～17歳 | D17: 1 | E17: =IF($F17=0,0,D17/$F17) -> 0.33333333 | F17: =$F$14 -> 3 | G17: 単一回答
A18: 問3 | B18: あなたのお住まいの地区を教えてください | C18: 北山地区 | D18: 2 | E18: =IF($F18=0,0,D18/$F18) -> 0.66666667 | F18: 3 | G18: 単一回答
A19: 問3 | B19: あなたのお住まいの地区を教えてください | C19: 大塩地区 | D19: 0 | E19: =IF($F19=0,0,D19/$F19) -> 0 | F19: =$F$18 -> 3 | G19: 単一回答
A20: 問3 | B20: あなたのお住まいの地区を教えてください | C20: 桧原地区 | D20: 0 | E20: =IF($F20=0,0,D20/$F20) -> 0 | F20: =$F$18 -> 3 | G20: 単一回答
A21: 問3 | B21: あなたのお住まいの地区を教えてください | C21: 裏磐梯地区 | D21: 1 | E21: =IF($F21=0,0,D21/$F21) -> 0.33333333 | F21: =$F$18 -> 3 | G21: 単一回答
A22: 問3 | B22: あなたのお住まいの地区を教えてください | C22: その他 | D22: 0 | E22: =IF($F22=0,0,D22/$F22) -> 0 | F22: =$F$18 -> 3 | G22: 単一回答
A23: 問4 | B23: あなたの性別を教えてください | C23: 男性 | D23: 2 | E23: =IF($F23=0,0,D23/$F23) -> 0.66666667 | F23: 3 | G23: 単一回答
A24: 問4 | B24: あなたの性別を教えてください | C24: 女性 | D24: 1 | E24: =IF($F24=0,0,D24/$F24) -> 0.33333333 | F24: =$F$23 -> 3 | G24: 単一回答
A25: 問4 | B25: あなたの性別を教えてください | C25: 回答しない | D25: 0 | E25: =IF($F25=0,0,D25/$F25) -> 0 | F25: =$F$23 -> 3 | G25: 単一回答
A26: 問5 | B26: お持ちの手帳等を教えてください（あてはまるものすべて） | C26: 身体障がい者手帳 | D26: 2 | E26: =IF($F26=0,0,D26/$F26) -> 1 | F26: 2 | G26: 複数回答
A27: 問5 | B27: お持ちの手帳等を教えてください（あてはまるものすべて） | C27: 療育手帳 | D27: 1 | E27: =IF($F27=0,0,D27/$F27) -> 0.5 | F27: =$F$26 -> 2 | G27: 複数回答
A28: 問5 | B28: お持ちの手帳等を教えてください（あてはまるものすべて） | C28: 精神障がい者保健福祉手帳 | D28: 1 | E28: =IF($F28=0,0,D28/$F28) -> 0.5 | F28: =$F$26 -> 2 | G28: 複数回答
A29: 問5 | B29: お持ちの手帳等を教えてください（あてはまるものすべて） | C29: 難病に関する医療受給者証等 | D29: 0 | E29: =IF($F29=0,0,D29/$F29) -> 0 | F29: =$F$26 -> 2 | G29: 複数回答
A30: 問5 | B30: お持ちの手帳等を教えてください（あてはまるものすべて） | C30: 手帳等は持っていないが障がい福祉サービスを利用している | D30: 0 | E30: =IF($F30=0,0,D30/$F30) -> 0 | F30: =$F$26 -> 2 | G30: 複数回答
A31: 問5 | B31: お持ちの手帳等を教えてください（あてはまるものすべて） | C31: その他 | D31: 0 | E31: =IF($F31=0,0,D31/$F31) -> 0 | F31: =$F$26 -> 2 | G31: 複数回答
A32: 問6 | B32: 主たる障がい種別を1つ選ぶとすれば、どれにあたりますか | C32: 身体障がい | D32: 1 | E32: =IF($F32=0,0,D32/$F32) -> 0.33333333 | F32: 3 | G32: 単一回答
A33: 問6 | B33: 主たる障がい種別を1つ選ぶとすれば、どれにあたりますか | C33: 知的障がい | D33: 1 | E33: =IF($F33=0,0,D33/$F33) -> 0.33333333 | F33: =$F$32 -> 3 | G33: 単一回答
A34: 問6 | B34: 主たる障がい種別を1つ選ぶとすれば、どれにあたりますか | C34: 精神障がい | D34: 0 | E34: =IF($F34=0,0,D34/$F34) -> 0 | F34: =$F$32 -> 3 | G34: 単一回答
A35: 問6 | B35: 主たる障がい種別を1つ選ぶとすれば、どれにあたりますか | C35: 発達障がい | D35: 1 | E35: =IF($F35=0,0,D35/$F35) -> 0.33333333 | F35: =$F$32 -> 3 | G35: 単一回答
A36: 問6 | B36: 主たる障がい種別を1つ選ぶとすれば、どれにあたりますか | C36: 難病 | D36: 0 | E36: =IF($F36=0,0,D36/$F36) -> 0 | F36: =$F$32 -> 3 | G36: 単一回答
A37: 問6 | B37: 主たる障がい種別を1つ選ぶとすれば、どれにあたりますか | C37: 高次脳機能障がい | D37: 0 | E37: =IF($F37=0,0,D37/$F37) -> 0 | F37: =$F$32 -> 3 | G37: 単一回答
A38: 問6 | B38: 主たる障がい種別を1つ選ぶとすれば、どれにあたりますか | C38: 重症心身障がい | D38: 0 | E38: =IF($F38=0,0,D38/$F38) -> 0 | F38: =$F$32 -> 3 | G38: 単一回答
A39: 問6 | B39: 主たる障がい種別を1つ選ぶとすれば、どれにあたりますか | C39: わからない・その他 | D39: 0 | E39: =IF($F39=0,0,D39/$F39) -> 0 | F39: =$F$32 -> 3 | G39: 単一回答
A40: 問7 | B40: 障害児通所支援等の支給決定を受けていますか | C40: 受けている | D40: 2 | E40: =IF($F40=0,0,D40/$F40) -> 0.66666667 | F40: 3 | G40: 単一回答
A41: 問7 | B41: 障害児通所支援等の支給決定を受けていますか | C41: 受けていない | D41: 1 | E41: =IF($F41=0,0,D41/$F41) -> 0.33333333 | F41: =$F$40 -> 3 | G41: 単一回答
...
