Workbook

Sheet 目次
B1: 北塩原村 障がい福祉に関するアンケート調査 分析報告書 図表データ集（編集用）
B3: ・このブックは、分析報告書に掲載した図表（図61点・表23点）を、Excelで編集できる形式で収録したものです。図表番号は報告書と対応しています。
B4: ・グラフはすべてExcelのグラフ機能で作成しています。色・フォント・ラベル・サイズ等を通常どおり編集でき、そのままWordに貼り付けて使用できます。
B5: ・斜体のセルが入力値（件数・回答者数）、斜体でないセルは計算式です。「集計_障がい者」「集計_障がい児」シートの件数を修正すると、各章シートの表とグラフに自動で反映されます。
B6: ・第4章のクロス集計は、各表の【件数】欄（斜体）が入力値で、【割合】欄は計算式です。
B7: ・第3章の【障がい別】の図表は、「集計_障がい別」シート（手帳の所持により身体・知的・精神に区分、重複所持は各区分に計上）の件数（斜体）を参照しています。
B8: ・割合は、各設問の回答者数（無回答を含む）を基数として算出し、表示上、小数点第2位を四捨五入しています。全ての設問に「無回答」を設けています。グラフの項目の並び順は、報告書作成時点の件数順で固定しています。
B9: ・出典：北塩原村_障がい福祉アンケート_単純集計_クロス分析.xlsx、北塩原村_障がい児福祉アンケート_単純集計_クロス分析.xlsx（いずれも単純集計・クロス分析シート）
B11: 図表番号 | C11: タイトル | D11: 収録シート | E11: 移動
B12: 表1-1 | C12: 調査の概要 | D12: 1-2章_概要・要点 | E12: → 表示
B13: 表1-2 | C13: 調査項目の構成 | D13: 1-2章_概要・要点 | E13: → 表示
B14: 表2-1 | C14: 障がい者調査の主要指標 | D14: 1-2章_概要・要点 | E14: → 表示
B15: 図3-1 | C15: 調査票の記入者（問1） | D15: 3章_1属性 | E15: → 表示
B16: 図3-2 | C16: 回答への本人意向の反映（問1-2） | D16: 3章_1属性 | E16: → 表示
B17: 図3-3 | C17: 年齢（問2） | D17: 3章_1属性 | E17: → 表示
B18: 図3-4 | C18: 年齢【障がい別】（問2） | D18: 3章_1属性 | E18: → 表示
B19: 図3-5 | C19: お住まいの地区（問3） | D19: 3章_1属性 | E19: → 表示
B20: 図3-6 | C20: 性別（問4） | D20: 3章_1属性 | E20: → 表示
B21: 図3-7 | C21: 性別【障がい別】（問4） | D21: 3章_1属性 | E21: → 表示
B22: 図3-8 | C22: 所持している手帳等（問5） | D22: 3章_1属性 | E22: → 表示
... B138: 入力データ | C138: 障がい児調査 単純集計（入力用） | D138: 集計_障がい児 | E138: → 表示

Sheet 1-2章_概要・要点
B2: 表1-1 調査の概要
B3: 項目 | C3: 障がい者調査 | G3: 障がい児調査
B4: 調査対象 | C4: 村内在住の18歳以上の障がいのある方 身体（118名）・精神（34名）・療育（8名）・入所等（12名） | G4: 村内在住の18歳未満の障がいのある児童とその保護者 身体（2名）・精神（1名）・療育（1名）・入所等（2名）
B5: 調査方法 | C5: 郵送配布・郵送回収及びWEB回答 | G5: 郵送配布・郵送回収及びWEB回答
B6: 調査期間 | C6: 令和8年8月31日～令和8年9月25日 | G6: 令和8年8月31日～令和8年9月25日
B7: 配布数 | C7: 172 | G7: 6
B8: 有効回答数 | C8: ='集計_障がい者'!$F$5 -> 40 | G8: ='集計_障がい児'!$F$5 -> 3
B9: 有効回答率 | C9: =IF(C7=0,0,C8/C7) -> 0.23255814 | G9: =IF(G7=0,0,G8/G7) -> 0.5
B11: 表1-2 調査項目の構成
B12: 分野 | C12: 障がい者調査 | F12: 障がい児調査
B13: 回答者の属性 | C13: 問1～問9 | F13: 問1～問9
B14: 日常生活と将来の暮らし | C14: 問10～問11 | F14: 問10～問11
B15: 外出・移動 | C15: 問12～問14 | F15: 問12～問14
B16: 医療・医療的ケア等 | C16: 問15～問20 | F16: 問15～問18、問26
B17: 意思決定支援・相談・情報 | C17: 問21～問26 | F17: 問19～問22
B18: 通園・通学、放課後の過ごし方 | C18: ― | F18: 問23～問25、問31
B19: 福祉サービスの利用 | C19: 問27～問30 | F19: 問27～問30
B20: 日中活動・就労 | C20: 問31～問33 | F20: ―
B21: 18歳以降の生活 | C21: ― | F21: 問32
B22: 差別解消・権利擁護 | C22: 問34～問37 | F22: 問33～問36
B23: 災害時の対応 | C23: 問38～問41 | F23: 問37～問40
... B25: 自由意見 | C25: 問10-2、問45 | F25: 問10-2、問32-1、問44
B27: 表2-1 障がい者調査の主要指標
B28: 分野 | C28: 指標 | H28: 結果 | I28: 設問
B29: 回答者 | C29: 65歳以上の割合 | H29: =IF('集計_障がい者'!$F$20=0,0,SUM('集計_障がい者'!$D$20)/'集計_障がい者'!$F$20) -> 0.65 | I29: 問2
B30: 回答者 | C30: 主たる障がいが「身体障がい」 | H30: =IF('集計_障がい者'!$F$40=0,0,SUM('集計_障がい者'!$D$40)/'集計_障がい者'!$F$40) -> 0.675 | I30: 問6
B31: 日常生活 | C31: 困っていること「将来の生活」（「特にない」を除き第1位） | H31: =IF('集計_障がい者'!$F$87=0,0,SUM('集計_障がい者'!$D$87)/'集計_障がい者'!$F$87) -> 0.3 | I31: 問10
B32: 将来の暮らし | C32: 「今の自宅で暮らしたい」 | H32: =IF('集計_障がい者'!$F$91=0,0,SUM('集計_障がい者'!$D$91)/'集計_障がい者'!$F$91) -> 0.4 | I32: 問11
B33: 外出・移動 | C33: 外出時に困ること「冬季・積雪時に外出しにくい」 | H33: =IF('集計_障がい者'!$F$119=0,0,SUM('集計_障がい者'!$D$119)/'集計_障がい者'!$F$119) -> 0.35 | I33: 問14
B34: 相談 | C34: 困ったときの相談相手「家族・親族」 | H34: =IF('集計_障がい者'!$F$184=0,0,SUM('集計_障がい者'!$D$184)/'集計_障がい者'!$F$184) -> 0.775 | I34: 問22
B35: 相談 | C35: 相談支援への期待「わかりやすい情報提供」 | H35: =IF('集計_障がい者'!$F$229=0,0,SUM('集計_障がい者'!$D$229)/'集計_障がい者'!$F$229) -> 0.35 | I35: 問26
B36: 意思決定支援 | C36: 「必要である」＋「将来的には必要になると思う」 | H36: =IF('集計_障がい者'!$F$179=0,0,SUM('集計_障がい者'!$D$179,'集計_障がい者'!$D$180)/'集計_障がい者'!$F$179) -> 0.5 | I36: 問21
B37: サービス | C37: 現在利用しているサービスは「特にない」 | H37: =IF('集計_障がい者'!$F$250=0,0,SUM('集計_障がい者'!$D$250)/'集計_障がい者'!$F$250) -> 0.45 | I37: 問27-1
B38: サービス | C38: 今後3年間で「施設入所支援」を利用したい | H38: =IF('集計_障がい者'!$F$284=0,0,SUM('集計_障がい者'!$D$284)/'集計_障がい者'!$F$284) -> 0.225 | I38: 問27-3
B39: 地域生活支援拠点 | C39: 期待する機能「緊急時の受入れ」 | H39: =IF('集計_障がい者'!$F$303=0,0,SUM('集計_障がい者'!$D$303)/'集計_障がい者'!$F$303) -> 0.35 | I39: 問29
B40: 権利擁護 | C40: 差別・偏見・不利益を感じたことがある | H40: =IF('集計_障がい者'!$F$351=0,0,SUM('集計_障がい者'!$D$351,'集計_障がい者'!$D$352,'集計_障がい者'!$D$353)/'集計_障がい者'!$F$351) -> 0.225 | I40: 問34
B41: 権利擁護 | C41: 成年後見制度等を「知らない」 | H41: =IF('集計_障がい者'!$F$383=0,0,SUM('集計_障がい者'!$D$383)/'集計_障がい者'!$F$383) -> 0.375 | I41: 問37
B42: 災害 | C42: 避難行動要支援者名簿・個別避難計画を「知らない」 | H42: =IF('集計_障がい者'!$F$398=0,0,SUM('集計_障がい者'!$D$398)/'集計_障がい者'!$F$398) -> 0.7 | I42: 問39
B43: 災害 | C43: 災害時の不安「避難先での生活」 | H43: =IF('集計_障がい者'!$F$386=0,0,SUM('集計_障がい者'!$D$386)/'集計_障がい者'!$F$386) -> 0.625 | I43: 問38
B44: 村の施策 | C44: 力を入れるべきこと「相談支援体制」 | H44: =IF('集計_障がい者'!$F$440=0,0,SUM('集計_障がい者'!$D$440)/'集計_障がい者'!$F$440) -> 0.375 | I44: 問44
...

Sheet 3章_1属性
B2: 図3-1 調査票の記入者（問1）
B3: ="n="&'集計_障がい者'!$F$5&"（単一回答）" -> n=40（単一回答）
B4: 選択肢 | C4: 件数 | D4: 割合
B5: 宛名のご本人 | C5: ='集計_障がい者'!$D$5 -> 25 | D5: ='集計_障がい者'!$E$5 -> 0.625
B6: ご家族 | C6: ='集計_障がい者'!$D$6 -> 9 | D6: ='集計_障がい者'!$E$6 -> 0.225
B7: 支援者・事業所職員 | C7: ='集計_障がい者'!$D$7 -> 4 | D7: ='集計_障がい者'!$E$7 -> 0.1
B8: その他 | C8: ='集計_障がい者'!$D$8 -> 1 | D8: ='集計_障がい者'!$E$8 -> 0.025
B9: 無回答 | C9: ='集計_障がい者'!$D$9 -> 1 | D9: ='集計_障がい者'!$E$9 -> 0.025
B13: 図3-2 回答への本人意向の反映（問1-2）
B14: ="n="&'集計_障がい者'!$F$10&"（単一回答）" -> n=40（単一回答）
B15: 選択肢 | C15: 件数 | D15: 割合
B16: 本人が回答した | C16: ='集計_障がい者'!$D$10 -> 23 | D16: ='集計_障がい者'!$E$10 -> 0.575
B17: 本人に確認して代理記入した | C17: ='集計_障がい者'!$D$11 -> 8 | D17: ='集計_障がい者'!$E$11 -> 0.2
B18: 本人の様子や日頃の意向を踏まえて代理記入した | C18: ='集計_障がい者'!$D$12 -> 2 | D18: ='集計_障がい者'!$E$12 -> 0.05
B19: 本人に確認することが難しく、家族・支援者の判断で記入した | C19: ='集計_障がい者'!$D$13 -> 6 | D19: ='集計_障がい者'!$E$13 -> 0.15
B20: その他 | C20: ='集計_障がい者'!$D$14 -> 0 | D20: ='集計_障がい者'!$E$14 -> 0
B21: 無回答 | C21: ='集計_障がい者'!$D$15 -> 1 | D21: ='集計_障がい者'!$E$15 -> 0.025
B24: 図3-3 年齢（問2）
B25: ="n="&'集計_障がい者'!$F$16&"（単一回答）" -> n=40（単一回答）
B26: 選択肢 | C26: 件数 | D26: 割合
B27: 18～29歳 | C27: ='集計_障がい者'!$D$16 -> 0 | D27: ='集計_障がい者'!$E$16 -> 0
B28: 30～39歳 | C28: ='集計_障がい者'!$D$17 -> 3 | D28: ='集計_障がい者'!$E$17 -> 0.075
B29: 40～49歳 | C29: ='集計_障がい者'!$D$18 -> 2 | D29: ='集計_障がい者'!$E$18 -> 0.05
B30: 50～64歳 | C30: ='集計_障がい者'!$D$19 -> 8 | D30: ='集計_障がい者'!$E$19 -> 0.2
B31: 65歳以上 | C31: ='集計_障がい者'!$D$20 -> 26 | D31: ='集計_障がい者'!$E$20 -> 0.65
B32: 無回答 | C32: ='集計_障がい者'!$D$21 -> 1 | D32: ='集計_障がい者'!$E$21 -> 0.025
B35: 図3-4 年齢【障がい別】（問2）
B37: 区分 | C37: 18～29歳 | D37: 30～39歳 | E37: 40～49歳 | F37: 50～64歳 | G37: 65歳以上 | H37: 無回答
B38: 全体 | C38: ='集計_障がい者'!$E$16 -> 0 | D38: ='集計_障がい者'!$E$17 -> 0.075 | E38: ='集計_障がい者'!$E$18 -> 0.05 | F38: ='集計_障がい者'!$E$19 -> 0.2 | G38: ='集計_障がい者'!$E$20 -> 0.65 | H38: ='集計_障がい者'!$E$21 -> 0.025
B39: 身体障がい（n=29） | C39: ='集計_障がい別'!$G$17 -> 0 | D39: ='集計_障がい別'!$G$18 -> 0.034482759 | E39: ='集計_障がい別'!$G$19 -> 0.034482759 | F39: ='集計_障がい別'!$G$20 -> 0.17241379 | G39: ='集計_障がい別'!$G$21 -> 0.72413793 | H39: ='集計_障がい別'!$G$22 -> 0.034482759
B40: 知的障がい（n=2） | C40: ='集計_障がい別'!$H$17 -> 0 | D40: ='集計_障がい別'!$H$18 -> 0 | E40: ='集計_障がい別'!$H$19 -> 0 | F40: ='集計_障がい別'!$H$20 -> 0.5 | G40: ='集計_障がい別'!$H$21 -> 0.5 | H40: ='集計_障がい別'!$H$22 -> 0
B41: 精神障がい（n=6） | C41: ='集計_障がい別'!$I$17 -> 0 | D41: ='集計_障がい別'!$I$18 -> 0.33333333 | E41: ='集計_障がい別'!$I$19 -> 0.16666667 | F41: ='集計_障がい別'!$I$20 -> 0.33333333 | G41: ='集計_障がい別'!$I$21 -> 0.16666667 | H41: ='集計_障がい別'!$I$22 -> 0
B50: 図3-5 お住まいの地区（問3）
B51: ="n="&'集計_障がい者'!$F$22&"（単一回答）" -> n=40（単一回答）
B52: 選択肢 | C52: 件数 | D52: 割合
B53: 北山地区 | C53: ='集計_障がい者'!$D$22 -> 17 | D53: ='集計_障がい者'!$E$22 -> 0.425
B54: 大塩地区 | C54: ='集計_障がい者'!$D$23 -> 8 | D54: ='集計_障がい者'!$E$23 -> 0.2
B55: 桧原地区 | C55: ='集計_障がい者'!$D$24 -> 3 | D55: ='集計_障がい者'!$E$24 -> 0.075
B56: 裏磐梯地区 | C56: ='集計_障がい者'!$D$25 -> 11 | D56: ='集計_障がい者'!$E$25 -> 0.275
B57: その他 | C57: ='集計_障がい者'!$D$26 -> 1 | D57: ='集計_障がい者'!$E$26 -> 0.025
...

Sheet 3章_2生活・外出
B2: 図3-16 日常生活で困っていること（問10）
B3: ="n="&'集計_障がい者'!$F$87&"（複数回答）" -> n=40（複数回答）
B4: 選択肢 | C4: 件数 | D4: 割合
B5: 将来の生活 | C5: ='集計_障がい者'!$D$87 -> 12 | D5: ='集計_障がい者'!$E$87 -> 0.3
B6: 外出・移動 | C6: ='集計_障がい者'!$D$83 -> 10 | D6: ='集計_障がい者'!$E$83 -> 0.25
B7: 災害時の避難 | C7: ='集計_障がい者'!$D$85 -> 10 | D7: ='集計_障がい者'!$E$85 -> 0.25
B8: 通院 | C8: ='集計_障がい者'!$D$82 -> 8 | D8: ='集計_障がい者'!$E$82 -> 0.2
B9: 食事 | C9: ='集計_障がい者'!$D$77 -> 5 | D9: ='集計_障がい者'!$E$77 -> 0.125
B10: 服薬管理 | C10: ='集計_障がい者'!$D$80 -> 5 | D10: ='集計_障がい者'!$E$80 -> 0.125
B11: 買い物 | C11: ='集計_障がい者'!$D$84 -> 5 | D11: ='集計_障がい者'!$E$84 -> 0.125
B12: 入浴 | C12: ='集計_障がい者'!$D$78 -> 4 | D12: ='集計_障がい者'!$E$78 -> 0.1
B13: 金銭管理 | C13: ='集計_障がい者'!$D$81 -> 4 | D13: ='集計_障がい者'!$E$81 -> 0.1
B14: 家事 | C14: ='集計_障がい者'!$D$76 -> 2 | D14: ='集計_障がい者'!$E$76 -> 0.05
B15: 排せつ | C15: ='集計_障がい者'!$D$79 -> 2 | D15: ='集計_障がい者'!$E$79 -> 0.05
B16: 相談先がない | C16: ='集計_障がい者'!$D$86 -> 1 | D16: ='集計_障がい者'!$E$86 -> 0.025
B17: 特にない | C17: ='集計_障がい者'!$D$88 -> 14 | D17: ='集計_障がい者'!$E$88 -> 0.35
B18: その他 | C18: ='集計_障がい者'!$D$89 -> 1 | D18: ='集計_障がい者'!$E$89 -> 0.025
B19: 無回答 | C19: ='集計_障がい者'!$D$90 -> 2 | D19: ='集計_障がい者'!$E$90 -> 0.05
B23: 図3-17 日常生活で困っていること【障がい別】（問10）
B25: 選択肢 | C25: 身体障がい（n=29） | D25: 知的障がい（n=2） | E25: 精神障がい（n=6）
B26: 将来の生活 | C26: ='集計_障がい別'!$G$88 -> 0.24137931 | D26: ='集計_障がい別'!$H$88 -> 1 | E26: ='集計_障がい別'!$I$88 -> 0.5
B27: 外出・移動 | C27: ='集計_障がい別'!$G$84 -> 0.27586207 | D27: ='集計_障がい別'!$H$84 -> 1 | E27: ='集計_障がい別'!$I$84 -> 0.16666667
B28: 災害時の避難 | C28: ='集計_障がい別'!$G$86 -> 0.27586207 | D28: ='集計_障がい別'!$H$86 -> 1 | E28: ='集計_障がい別'!$I$86 -> 0.16666667
B29: 通院 | C29: ='集計_障がい別'!$G$83 -> 0.17241379 | D29: ='集計_障がい別'!$H$83 -> 0.5 | E29: ='集計_障がい別'!$I$83 -> 0.16666667
B30: 食事 | C30: ='集計_障がい別'!$G$78 -> 0.10344828 | D30: ='集計_障がい別'!$H$78 -> 0.5 | E30: ='集計_障がい別'!$I$78 -> 0
B31: 服薬管理 | C31: ='集計_障がい別'!$G$81 -> 0.13793103 | D31: ='集計_障がい別'!$H$81 -> 0.5 | E31: ='集計_障がい別'!$I$81 -> 0
B32: 買い物 | C32: ='集計_障がい別'!$G$85 -> 0.10344828 | D32: ='集計_障がい別'!$H$85 -> 0.5 | E32: ='集計_障がい別'!$I$85 -> 0.16666667
B33: 入浴 | C33: ='集計_障がい別'!$G$79 -> 0.10344828 | D33: ='集計_障がい別'!$H$79 -> 0.5 | E33: ='集計_障がい別'!$I$79 -> 0
B34: 金銭管理 | C34: ='集計_障がい別'!$G$82 -> 0.034482759 | D34: ='集計_障がい別'!$H$82 -> 0.5 | E34: ='集計_障がい別'!$I$82 -> 0.33333333
B35: 家事 | C35: ='集計_障がい別'!$G$77 -> 0 | D35: ='集計_障がい別'!$H$77 -> 0.5 | E35: ='集計_障がい別'!$I$77 -> 0
B36: 排せつ | C36: ='集計_障がい別'!$G$80 -> 0.068965517 | D36: ='集計_障がい別'!$H$80 -> 0 | E36: ='集計_障がい別'!$I$80 -> 0
B37: 相談先がない | C37: ='集計_障がい別'!$G$87 -> 0 | D37: ='集計_障がい別'!$H$87 -> 0 | E37: ='集計_障がい別'!$I$87 -> 0.16666667
B38: 特にない | C38: ='集計_障がい別'!$G$89 -> 0.31034483 | D38: ='集計_障がい別'!$H$89 -> 0 | E38: ='集計_障がい別'!$I$89 -> 0.5
B39: その他 | C39: ='集計_障がい別'!$G$90 -> 0.034482759 | D39: ='集計_障がい別'!$H$90 -> 0 | E39: ='集計_障がい別'!$I$90 -> 0
B40: 無回答 | C40: ='集計_障がい別'!$G$91 -> 0.034482759 | D40: ='集計_障がい別'!$H$91 -> 0 | E40: ='集計_障がい別'!$I$91 -> 0
B70: 図3-18 将来希望する暮らし方（問11）
B71: ="n="&'集計_障がい者'!$F$91&"（単一回答）" -> n=40（単一回答）
B72: 選択肢 | C72: 件数 | D72: 割合
B73: 今の自宅で暮らしたい | C73: ='集計_障がい者'!$D$91 -> 16 | D73: ='集計_障がい者'!$E$91 -> 0.4
B74: 家族と一緒に暮らしたい | C74: ='集計_障がい者'!$D$92 -> 6 | D74: ='集計_障がい者'!$E$92 -> 0.15
...

Sheet 3章_3医療
B2: 図3-26 定期的な通院（問15）
B3: ="n="&'集計_障がい者'!$F$127&"（単一回答）" -> n=40（単一回答）
B4: 選択肢 | C4: 件数 | D4: 割合
B5: 通院している | C5: ='集計_障がい者'!$D$127 -> 28 | D5: ='集計_障がい者'!$E$127 -> 0.7
B6: 通院していない | C6: ='集計_障がい者'!$D$128 -> 5 | D6: ='集計_障がい者'!$E$128 -> 0.125
B7: 訪問診療・往診を受けている | C7: ='集計_障がい者'!$D$129 -> 3 | D7: ='集計_障がい者'!$E$129 -> 0.075
B8: わからない | C8: ='集計_障がい者'!$D$130 -> 2 | D8: ='集計_障がい者'!$E$130 -> 0.05
B9: 無回答 | C9: ='集計_障がい者'!$D$131 -> 2 | D9: ='集計_障がい者'!$E$131 -> 0.05
B13: 図3-27 定期的な通院【障がい別】（問15）
B15: 区分 | C15: 通院している | D15: 通院していない | E15: 訪問診療・往診を受けている | F15: わからない | G15: 無回答
B16: 全体 | C16: ='集計_障がい者'!$E$127 -> 0.7 | D16: ='集計_障がい者'!$E$128 -> 0.125 | E16: ='集計_障がい者'!$E$129 -> 0.075 | F16: ='集計_障がい者'!$E$130 -> 0.05 | G16: ='集計_障がい者'!$E$131 -> 0.05
B17: 身体障がい（n=29） | C17: ='集計_障がい別'!$G$128 -> 0.75862069 | D17: ='集計_障がい別'!$G$129 -> 0.068965517 | E17: ='集計_障がい別'!$G$130 -> 0.034482759 | F17: ='集計_障がい別'!$G$131 -> 0.068965517 | G17: ='集計_障がい別'!$G$132 -> 0.068965517
B18: 知的障がい（n=2） | C18: ='集計_障がい別'!$H$128 -> 0.5 | D18: ='集計_障がい別'!$H$129 -> 0 | E18: ='集計_障がい別'!$H$130 -> 0.5 | F18: ='集計_障がい別'!$H$131 -> 0 | G18: ='集計_障がい別'!$H$132 -> 0
B19: 精神障がい（n=6） | C19: ='集計_障がい別'!$I$128 -> 0.66666667 | D19: ='集計_障がい別'!$I$129 -> 0.16666667 | E19: ='集計_障がい別'!$I$130 -> 0.16666667 | F19: ='集計_障がい別'!$I$131 -> 0 | G19: ='集計_障がい別'!$I$132 -> 0
B26: 図3-28 通院や医療で困っていること（問16）
B27: ="n="&'集計_障がい者'!$F$132&"（複数回答）" -> n=40（複数回答）
B28: 選択肢 | C28: 件数 | D28: 割合
B29: 専門医療機関が遠い | C29: ='集計_障がい者'!$D$132 -> 9 | D29: ='集計_障がい者'!$E$132 -> 0.225
B30: 付き添いが必要 | C30: ='集計_障がい者'!$D$134 -> 8 | D30: ='集計_障がい者'!$E$134 -> 0.2
B31: 医療費や交通費の負担が大きい | C31: ='集計_障がい者'!$D$135 -> 6 | D31: ='集計_障がい者'!$E$135 -> 0.15
B32: 緊急時の対応が不安 | C32: ='集計_障がい者'!$D$137 -> 6 | D32: ='集計_障がい者'!$E$137 -> 0.15
B33: 通院の交通手段がない | C33: ='集計_障がい者'!$D$133 -> 3 | D33: ='集計_障がい者'!$E$133 -> 0.075
B34: 予約・受診手続きが難しい | C34: ='集計_障がい者'!$D$136 -> 2 | D34: ='集計_障がい者'!$E$136 -> 0.05
B35: 特に困っていない | C35: ='集計_障がい者'!$D$138 -> 17 | D35: ='集計_障がい者'!$E$138 -> 0.425
B36: その他 | C36: ='集計_障がい者'!$D$139 -> 0 | D36: ='集計_障がい者'!$E$139 -> 0
B37: 無回答 | C37: ='集計_障がい者'!$D$140 -> 2 | D37: ='集計_障がい者'!$E$140 -> 0.05
B41: 図3-29 通院や医療で困っていること【障がい別】（問16）
B43: 選択肢 | C43: 身体障がい（n=29） | D43: 知的障がい（n=2） | E43: 精神障がい（n=6）
B44: 専門医療機関が遠い | C44: ='集計_障がい別'!$G$133 -> 0.20689655 | D44: ='集計_障がい別'!$H$133 -> 0 | E44: ='集計_障がい別'!$I$133 -> 0.33333333
B45: 付き添いが必要 | C45: ='集計_障がい別'!$G$135 -> 0.24137931 | D45: ='集計_障がい別'!$H$135 -> 1 | E45: ='集計_障がい別'!$I$135 -> 0
B46: 医療費や交通費の負担が大きい | C46: ='集計_障がい別'!$G$136 -> 0.13793103 | D46: ='集計_障がい別'!$H$136 -> 0 | E46: ='集計_障がい別'!$I$136 -> 0.33333333
B47: 緊急時の対応が不安 | C47: ='集計_障がい別'!$G$138 -> 0.17241379 | D47: ='集計_障がい別'!$H$138 -> 0 | E47: ='集計_障がい別'!$I$138 -> 0.16666667
B48: 通院の交通手段がない | C48: ='集計_障がい別'!$G$134 -> 0.068965517 | D48: ='集計_障がい別'!$H$134 -> 0 | E48: ='集計_障がい別'!$I$134 -> 0.16666667
B49: 予約・受診手続きが難しい | C49: ='集計_障がい別'!$G$137 -> 0.034482759 | D49: ='集計_障がい別'!$H$137 -> 0.5 | E49: ='集計_障がい別'!$I$137 -> 0
B50: 特に困っていない | C50: ='集計_障がい別'!$G$139 -> 0.4137931 | D50: ='集計_障がい別'!$H$139 -> 0 | E50: ='集計_障がい別'!$I$139 -> 0.33333333
B51: 無回答 | C51: ='集計_障がい別'!$G$141 -> 0.068965517 | D51: ='集計_障がい別'!$H$141 -> 0 | E51: ='集計_障がい別'!$I$141 -> 0
B52: ※いずれの区分にも回答のなかった選択肢は省略しています。
B69: 図3-30 医療的ケアの必要性（問17）
B70: ="n="&'集計_障がい者'!$F$141&"（複数回答）" -> n=40（複数回答）
B71: 選択肢 | C71: 件数 | D71: 割合
...

Sheet 3章_4相談・情報
B2: 図3-38 意思決定支援の必要性（問21）
B3: ="n="&'集計_障がい者'!$F$179&"（単一回答）" -> n=40（単一回答）
B4: 選択肢 | C4: 件数 | D4: 割合
B5: 必要である（現在すでに支援を受けている、または今後受けたい） | C5: ='集計_障がい者'!$D$179 -> 8 | D5: ='集計_障がい者'!$E$179 -> 0.2
B6: 今は必要ないが、将来的には必要になると思う | C6: ='集計_障がい者'!$D$180 -> 12 | D6: ='集計_障がい者'!$E$180 -> 0.3
B7: 必要ない（自分や家族等と相談して意思決定ができる） | C7: ='集計_障がい者'!$D$181 -> 9 | D7: ='集計_障がい者'!$E$181 -> 0.225
B8: わからない（意思決定支援がどのようなものか知らない） | C8: ='集計_障がい者'!$D$182 -> 6 | D8: ='集計_障がい者'!$E$182 -> 0.15
B9: 無回答 | C9: ='集計_障がい者'!$D$183 -> 5 | D9: ='集計_障がい者'!$E$183 -> 0.125
B12: 図3-39 意思決定支援の必要性【障がい別】（問21）
B14: 区分 | C14: 必要である（現在すでに支援を受けている、または今後受けたい） | D14: 今は必要ないが、将来的には必要になると思う | E14: 必要ない（自分や家族等と相談して意思決定ができる） | F14: わからない（意思決定支援がどのようなものか知らない） | G14: 無回答
B15: 全体 | C15: ='集計_障がい者'!$E$179 -> 0.2 | D15: ='集計_障がい者'!$E$180 -> 0.3 | E15: ='集計_障がい者'!$E$181 -> 0.225 | F15: ='集計_障がい者'!$E$182 -> 0.15 | G15: ='集計_障がい者'!$E$183 -> 0.125
B16: 身体障がい（n=29） | C16: ='集計_障がい別'!$G$180 -> 0.17241379 | D16: ='集計_障がい別'!$G$181 -> 0.31034483 | E16: ='集計_障がい別'!$G$182 -> 0.20689655 | F16: ='集計_障がい別'!$G$183 -> 0.13793103 | G16: ='集計_障がい別'!$G$184 -> 0.17241379
B17: 知的障がい（n=2） | C17: ='集計_障がい別'!$H$180 -> 0.5 | D17: ='集計_障がい別'!$H$181 -> 0.5 | E17: ='集計_障がい別'!$H$182 -> 0 | F17: ='集計_障がい別'!$H$183 -> 0 | G17: ='集計_障がい別'!$H$184 -> 0
B18: 精神障がい（n=6） | C18: ='集計_障がい別'!$I$180 -> 0.33333333 | D18: ='集計_障がい別'!$I$181 -> 0.16666667 | E18: ='集計_障がい別'!$I$182 -> 0.33333333 | F18: ='集計_障がい別'!$I$183 -> 0.16666667 | G18: ='集計_障がい別'!$I$184 -> 0
B23: 図3-40 困ったときの相談相手・場所（問22）
B24: ="n="&'集計_障がい者'!$F$184&"（複数回答）" -> n=40（複数回答）
B25: 選択肢 | C25: 件数 | D25: 割合
B26: 家族・親族 | C26: ='集計_障がい者'!$D$184 -> 31 | D26: ='集計_障がい者'!$E$184 -> 0.775
B27: 医療機関 | C27: ='集計_障がい者'!$D$189 -> 12 | D27: ='集計_障がい者'!$E$189 -> 0.3
B28: 相談支援専門員 | C28: ='集計_障がい者'!$D$187 -> 10 | D28: ='集計_障がい者'!$E$187 -> 0.25
B29: 友人・知人 | C29: ='集計_障がい者'!$D$185 -> 6 | D29: ='集計_障がい者'!$E$185 -> 0.15
B30: 村役場 | C30: ='集計_障がい者'!$D$186 -> 5 | D30: ='集計_障がい者'!$E$186 -> 0.125
B31: 福祉サービス事業所 | C31: ='集計_障がい者'!$D$188 -> 5 | D31: ='集計_障がい者'!$E$188 -> 0.125
B32: 社会福祉協議会 | C32: ='集計_障がい者'!$D$191 -> 4 | D32: ='集計_障がい者'!$E$191 -> 0.1
B33: SNS・インターネット・AI | C33: ='集計_障がい者'!$D$190 -> 1 | D33: ='集計_障がい者'!$E$190 -> 0.025
B34: 民生委員・児童委員 | C34: ='集計_障がい者'!$D$192 -> 1 | D34: ='集計_障がい者'!$E$192 -> 0.025
B35: 相談する相手がいない | C35: ='集計_障がい者'!$D$193 -> 1 | D35: ='集計_障がい者'!$E$193 -> 0.025
B36: その他 | C36: ='集計_障がい者'!$D$194 -> 1 | D36: ='集計_障がい者'!$E$194 -> 0.025
B37: 無回答 | C37: ='集計_障がい者'!$D$195 -> 1 | D37: ='集計_障がい者'!$E$195 -> 0.025
B41: 図3-41 困ったときの相談相手・場所【障がい別】（問22）
B43: 選択肢 | C43: 身体障がい（n=29） | D43: 知的障がい（n=2） | E43: 精神障がい（n=6）
B44: 家族・親族 | C44: ='集計_障がい別'!$G$185 -> 0.75862069 | D44: ='集計_障がい別'!$H$185 -> 0.5 | E44: ='集計_障がい別'!$I$185 -> 0.66666667
B45: 医療機関 | C45: ='集計_障がい別'!$G$190 -> 0.31034483 | D45: ='集計_障がい別'!$H$190 -> 0.5 | E45: ='集計_障がい別'!$I$190 -> 0.33333333
B46: 相談支援専門員 | C46: ='集計_障がい別'!$G$188 -> 0.17241379 | D46: ='集計_障がい別'!$H$188 -> 1 | E46: ='集計_障がい別'!$I$188 -> 0.33333333
B47: 友人・知人 | C47: ='集計_障がい別'!$G$186 -> 0.17241379 | D47: ='集計_障がい別'!$H$186 -> 0 | E47: ='集計_障がい別'!$I$186 -> 0
B48: 村役場 | C48: ='集計_障がい別'!$G$187 -> 0.13793103 | D48: ='集計_障がい別'!$H$187 -> 0 | E48: ='集計_障がい別'!$I$187 -> 0.16666667
B49: 福祉サービス事業所 | C49: ='集計_障がい別'!$G$189 -> 0.10344828 | D49: ='集計_障がい別'!$H$189 -> 1 | E49: ='集計_障がい別'!$I$189 -> 0.16666667
B50: 社会福祉協議会 | C50: ='集計_障がい別'!$G$192 -> 0.13793103 | D50: ='集計_障がい別'!$H$192 -> 0 | E50: ='集計_障がい別'!$I$192 -> 0
B51: SNS・インターネット・AI | C51: ='集計_障がい別'!$G$191 -> 0.034482759 | D51: ='集計_障がい別'!$H$191 -> 0 | E51: ='集計_障がい別'!$I$191 -> 0
B52: 民生委員・児童委員 | C52: ='集計_障がい別'!$G$193 -> 0.034482759 | D52: ='集計_障がい別'!$H$193 -> 0 | E52: ='集計_障がい別'!$I$193 -> 0
...

Sheet 3章_5サービス
B2: 表3-1 サービス別の利用状況・認知度・今後の利用意向
B3: サービス | C3: 現在利用している（問27-1） | E3: 内容をよく知らない（問27-2） | G3: 今後3年間で利用したい（問27-3） | I3: 差（今後－現在） ポイント
C4: 件数 | D4: 割合 | E4: 件数 | F4: 割合 | G4: 件数 | H4: 割合
B5: 回答者数（n） | C5: ='集計_障がい者'!$F$232 -> 40 | E5: ='集計_障がい者'!$F$252 -> 40 | G5: ='集計_障がい者'!$F$272 -> 40
B6: 居宅介護（ホームヘルプ） | C6: ='集計_障がい者'!$D$232 -> 1 | D6: ='集計_障がい者'!$E$232 -> 0.025 | E6: ='集計_障がい者'!$D$252 -> 6 | F6: ='集計_障がい者'!$E$252 -> 0.15 | G6: ='集計_障がい者'!$D$272 -> 3 | H6: ='集計_障がい者'!$E$272 -> 0.075 | I6: =ROUND(H6*100,1)-ROUND(D6*100,1) -> 5
B7: 重度訪問介護 | C7: ='集計_障がい者'!$D$233 -> 0 | D7: ='集計_障がい者'!$E$233 -> 0 | E7: ='集計_障がい者'!$D$253 -> 9 | F7: ='集計_障がい者'!$E$253 -> 0.225 | G7: ='集計_障がい者'!$D$273 -> 0 | H7: ='集計_障がい者'!$E$273 -> 0 | I7: =ROUND(H7*100,1)-ROUND(D7*100,1) -> 0
B8: 同行援護・行動援護 | C8: ='集計_障がい者'!$D$234 -> 1 | D8: ='集計_障がい者'!$E$234 -> 0.025 | E8: ='集計_障がい者'!$D$254 -> 9 | F8: ='集計_障がい者'!$E$254 -> 0.225 | G8: ='集計_障がい者'!$D$274 -> 1 | H8: ='集計_障がい者'!$E$274 -> 0.025 | I8: =ROUND(H8*100,1)-ROUND(D8*100,1) -> 0
B9: 生活介護 | C9: ='集計_障がい者'!$D$235 -> 4 | D9: ='集計_障がい者'!$E$235 -> 0.1 | E9: ='集計_障がい者'!$D$255 -> 6 | F9: ='集計_障がい者'!$E$255 -> 0.15 | G9: ='集計_障がい者'!$D$275 -> 3 | H9: ='集計_障がい者'!$E$275 -> 0.075 | I9: =ROUND(H9*100,1)-ROUND(D9*100,1) -> -2.5
B10: 自立訓練 | C10: ='集計_障がい者'!$D$236 -> 2 | D10: ='集計_障がい者'!$E$236 -> 0.05 | E10: ='集計_障がい者'!$D$256 -> 8 | F10: ='集計_障がい者'!$E$256 -> 0.2 | G10: ='集計_障がい者'!$D$276 -> 2 | H10: ='集計_障がい者'!$E$276 -> 0.05 | I10: =ROUND(H10*100,1)-ROUND(D10*100,1) -> 0
B11: 就労移行支援 | C11: ='集計_障がい者'!$D$237 -> 0 | D11: ='集計_障がい者'!$E$237 -> 0 | E11: ='集計_障がい者'!$D$257 -> 8 | F11: ='集計_障がい者'!$E$257 -> 0.2 | G11: ='集計_障がい者'!$D$277 -> 1 | H11: ='集計_障がい者'!$E$277 -> 0.025 | I11: =ROUND(H11*100,1)-ROUND(D11*100,1) -> 2.5
B12: 就労継続支援A型 | C12: ='集計_障がい者'!$D$238 -> 1 | D12: ='集計_障がい者'!$E$238 -> 0.025 | E12: ='集計_障がい者'!$D$258 -> 8 | F12: ='集計_障がい者'!$E$258 -> 0.2 | G12: ='集計_障がい者'!$D$278 -> 0 | H12: ='集計_障がい者'!$E$278 -> 0 | I12: =ROUND(H12*100,1)-ROUND(D12*100,1) -> -2.5
B13: 就労継続支援B型 | C13: ='集計_障がい者'!$D$239 -> 2 | D13: ='集計_障がい者'!$E$239 -> 0.05 | E13: ='集計_障がい者'!$D$259 -> 8 | F13: ='集計_障がい者'!$E$259 -> 0.2 | G13: ='集計_障がい者'!$D$279 -> 1 | H13: ='集計_障がい者'!$E$279 -> 0.025 | I13: =ROUND(H13*100,1)-ROUND(D13*100,1) -> -2.5
B14: 就労選択支援 | C14: ='集計_障がい者'!$D$240 -> 1 | D14: ='集計_障がい者'!$E$240 -> 0.025 | E14: ='集計_障がい者'!$D$260 -> 9 | F14: ='集計_障がい者'!$E$260 -> 0.225 | G14: ='集計_障がい者'!$D$280 -> 0 | H14: ='集計_障がい者'!$E$280 -> 0 | I14: =ROUND(H14*100,1)-ROUND(D14*100,1) -> -2.5
B15: 就労定着支援 | C15: ='集計_障がい者'!$D$241 -> 0 | D15: ='集計_障がい者'!$E$241 -> 0 | E15: ='集計_障がい者'!$D$261 -> 8 | F15: ='集計_障がい者'!$E$261 -> 0.2 | G15: ='集計_障がい者'!$D$281 -> 0 | H15: ='集計_障がい者'!$E$281 -> 0 | I15: =ROUND(H15*100,1)-ROUND(D15*100,1) -> 0
B16: 短期入所（ショートステイ） | C16: ='集計_障がい者'!$D$242 -> 2 | D16: ='集計_障がい者'!$E$242 -> 0.05 | E16: ='集計_障がい者'!$D$262 -> 4 | F16: ='集計_障がい者'!$E$262 -> 0.1 | G16: ='集計_障がい者'!$D$282 -> 4 | H16: ='集計_障がい者'!$E$282 -> 0.1 | I16: =ROUND(H16*100,1)-ROUND(D16*100,1) -> 5
B17: グループホーム | C17: ='集計_障がい者'!$D$243 -> 3 | D17: ='集計_障がい者'!$E$243 -> 0.075 | E17: ='集計_障がい者'!$D$263 -> 5 | F17: ='集計_障がい者'!$E$263 -> 0.125 | G17: ='集計_障がい者'!$D$283 -> 5 | H17: ='集計_障がい者'!$E$283 -> 0.125 | I17: =ROUND(H17*100,1)-ROUND(D17*100,1) -> 5
B18: 施設入所支援 | C18: ='集計_障がい者'!$D$244 -> 5 | D18: ='集計_障がい者'!$E$244 -> 0.125 | E18: ='集計_障がい者'!$D$264 -> 6 | F18: ='集計_障がい者'!$E$264 -> 0.15 | G18: ='集計_障がい者'!$D$284 -> 9 | H18: ='集計_障がい者'!$E$284 -> 0.225 | I18: =ROUND(H18*100,1)-ROUND(D18*100,1) -> 10
B19: 計画相談支援 | C19: ='集計_障がい者'!$D$245 -> 2 | D19: ='集計_障がい者'!$E$245 -> 0.05 | E19: ='集計_障がい者'!$D$265 -> 7 | F19: ='集計_障がい者'!$E$265 -> 0.175 | G19: ='集計_障がい者'!$D$285 -> 4 | H19: ='集計_障がい者'!$E$285 -> 0.1 | I19: =ROUND(H19*100,1)-ROUND(D19*100,1) -> 5
B20: 移動支援 | C20: ='集計_障がい者'!$D$246 -> 1 | D20: ='集計_障がい者'!$E$246 -> 0.025 | E20: ='集計_障がい者'!$D$266 -> 9 | F20: ='集計_障がい者'!$E$266 -> 0.225 | G20: ='集計_障がい者'!$D$286 -> 2 | H20: ='集計_障がい者'!$E$286 -> 0.05 | I20: =ROUND(H20*100,1)-ROUND(D20*100,1) -> 2.5
B21: 日中一時支援 | C21: ='集計_障がい者'!$D$247 -> 1 | D21: ='集計_障がい者'!$E$247 -> 0.025 | E21: ='集計_障がい者'!$D$267 -> 8 | F21: ='集計_障がい者'!$E$267 -> 0.2 | G21: ='集計_障がい者'!$D$287 -> 1 | H21: ='集計_障がい者'!$E$287 -> 0.025 | I21: =ROUND(H21*100,1)-ROUND(D21*100,1) -> 0
B22: 日常生活用具 | C22: ='集計_障がい者'!$D$248 -> 1 | D22: ='集計_障がい者'!$E$248 -> 0.025 | E22: ='集計_障がい者'!$D$268 -> 6 | F22: ='集計_障がい者'!$E$268 -> 0.15 | G22: ='集計_障がい者'!$D$288 -> 2 | H22: ='集計_障がい者'!$E$288 -> 0.05 | I22: =ROUND(H22*100,1)-ROUND(D22*100,1) -> 2.5
B23: 訪問入浴 | C23: ='集計_障がい者'!$D$249 -> 0 | D23: ='集計_障がい者'!$E$249 -> 0 | E23: ='集計_障がい者'!$D$269 -> 5 | F23: ='集計_障がい者'!$E$269 -> 0.125 | G23: ='集計_障がい者'!$D$289 -> 0 | H23: ='集計_障がい者'!$E$289 -> 0 | I23: =ROUND(H23*100,1)-ROUND(D23*100,1) -> 0
B24: 特にない（各設問） | C24: ='集計_障がい者'!$D$250 -> 18 | D24: ='集計_障がい者'!$E$250 -> 0.45 | E24: ='集計_障がい者'!$D$270 -> 7 | F24: ='集計_障がい者'!$E$270 -> 0.175 | G24: ='集計_障がい者'!$D$290 -> 12 | H24: ='集計_障がい者'!$E$290 -> 0.3
B25: 無回答（各設問） | C25: ='集計_障がい者'!$D$251 -> 9 | D25: ='集計_障がい者'!$E$251 -> 0.225 | E25: ='集計_障がい者'!$D$271 -> 16 | F25: ='集計_障がい者'!$E$271 -> 0.4 | G25: ='集計_障がい者'!$D$291 -> 10 | H25: ='集計_障がい者'!$E$291 -> 0.25
B26: ※割合はいずれも複数回答。「差」は今後の利用意向（問27-3）と現在の利用（問27-1）の割合の差（ポイント）で、5ポイント以上の増加を太字で示しています。（ ）内は件数です。 差は割合を小数点第1位に四捨五入したうえでの差です。
B28: 図3-50 現在利用しているサービスと今後3年間で利用したいサービス（問27-1・問27-3）
B30: サービス | C30: 現在利用している（問27-1） | D30: 今後3年間で利用したい（問27-3）
B31: 居宅介護（ホームヘルプ） | C31: ='集計_障がい者'!$E$232 -> 0.025 | D31: ='集計_障がい者'!$E$272 -> 0.075
B32: 同行援護・行動援護 | C32: ='集計_障がい者'!$E$234 -> 0.025 | D32: ='集計_障がい者'!$E$274 -> 0.025
B33: 生活介護 | C33: ='集計_障がい者'!$E$235 -> 0.1 | D33: ='集計_障がい者'!$E$275 -> 0.075
B34: 自立訓練 | C34: ='集計_障がい者'!$E$236 -> 0.05 | D34: ='集計_障がい者'!$E$276 -> 0.05
B35: 就労移行支援 | C35: ='集計_障がい者'!$E$237 -> 0 | D35: ='集計_障がい者'!$E$277 -> 0.025
B36: 就労継続支援A型 | C36: ='集計_障がい者'!$E$238 -> 0.025 | D36: ='集計_障がい者'!$E$278 -> 0
B37: 就労継続支援B型 | C37: ='集計_障がい者'!$E$239 -> 0.05 | D37: ='集計_障がい者'!$E$279 -> 0.025
B38: 就労選択支援 | C38: ='集計_障がい者'!$E$240 -> 0.025 | D38: ='集計_障がい者'!$E$280 -> 0
B39: 短期入所（ショートステイ） | C39: ='集計_障がい者'!$E$242 -> 0.05 | D39: ='集計_障がい者'!$E$282 -> 0.1
B40: グループホーム | C40: ='集計_障がい者'!$E$243 -> 0.075 | D40: ='集計_障がい者'!$E$283 -> 0.125
B41: 施設入所支援 | C41: ='集計_障がい者'!$E$244 -> 0.125 | D41: ='集計_障がい者'!$E$284 -> 0.225
B42: 計画相談支援 | C42: ='集計_障がい者'!$E$245 -> 0.05 | D42: ='集計_障がい者'!$E$285 -> 0.1
B43: 移動支援 | C43: ='集計_障がい者'!$E$246 -> 0.025 | D43: ='集計_障がい者'!$E$286 -> 0.05
...

Sheet 3章_6日中・権利
B2: 図3-58 現在の日中の過ごし方（問31）
B3: ="n="&'集計_障がい者'!$F$320&"（単一回答）" -> n=40（単一回答）
B4: 選択肢 | C4: 件数 | D4: 割合
B5: 一般企業等で働いている | C5: ='集計_障がい者'!$D$320 -> 3 | D5: ='集計_障がい者'!$E$320 -> 0.075
B6: 自営業・農業等をしている | C6: ='集計_障がい者'!$D$321 -> 4 | D6: ='集計_障がい者'!$E$321 -> 0.1
B7: 就労継続支援A型を利用 | C7: ='集計_障がい者'!$D$322 -> 0 | D7: ='集計_障がい者'!$E$322 -> 0
B8: 就労継続支援B型を利用 | C8: ='集計_障がい者'!$D$323 -> 2 | D8: ='集計_障がい者'!$E$323 -> 0.05
B9: 生活介護を利用 | C9: ='集計_障がい者'!$D$324 -> 2 | D9: ='集計_障がい者'!$E$324 -> 0.05
B10: 学校に通っている | C10: ='集計_障がい者'!$D$325 -> 0 | D10: ='集計_障がい者'!$E$325 -> 0
B11: 自宅で過ごすことが多い | C11: ='集計_障がい者'!$D$326 -> 15 | D11: ='集計_障がい者'!$E$326 -> 0.375
B12: 入院・入所中 | C12: ='集計_障がい者'!$D$327 -> 5 | D12: ='集計_障がい者'!$E$327 -> 0.125
B13: その他 | C13: ='集計_障がい者'!$D$328 -> 5 | D13: ='集計_障がい者'!$E$328 -> 0.125
B14: 無回答 | C14: ='集計_障がい者'!$D$329 -> 4 | D14: ='集計_障がい者'!$E$329 -> 0.1
B18: 図3-59 現在の日中の過ごし方【障がい別】（問31）
B20: 区分 | C20: 一般企業等で働いている | D20: 自営業・農業等をしている | E20: 就労継続支援A型を利用 | F20: 就労継続支援B型を利用 | G20: 生活介護を利用 | H20: 学校に通っている | I20: 自宅で過ごすことが多い | J20: 入院・入所中 | K20: その他 | L20: 無回答
B21: 全体 | C21: ='集計_障がい者'!$E$320 -> 0.075 | D21: ='集計_障がい者'!$E$321 -> 0.1 | E21: ='集計_障がい者'!$E$322 -> 0 | F21: ='集計_障がい者'!$E$323 -> 0.05 | G21: ='集計_障がい者'!$E$324 -> 0.05 | H21: ='集計_障がい者'!$E$325 -> 0 | I21: ='集計_障がい者'!$E$326 -> 0.375 | J21: ='集計_障がい者'!$E$327 -> 0.125 | K21: ='集計_障がい者'!$E$328 -> 0.125 | L21: ='集計_障がい者'!$E$329 -> 0.1
B22: 身体障がい（n=29） | C22: ='集計_障がい別'!$G$321 -> 0.068965517 | D22: ='集計_障がい別'!$G$322 -> 0.10344828 | E22: ='集計_障がい別'!$G$323 -> 0 | F22: ='集計_障がい別'!$G$324 -> 0.034482759 | G22: ='集計_障がい別'!$G$325 -> 0.034482759 | H22: ='集計_障がい別'!$G$326 -> 0 | I22: ='集計_障がい別'!$G$327 -> 0.34482759 | J22: ='集計_障がい別'!$G$328 -> 0.13793103 | K22: ='集計_障がい別'!$G$329 -> 0.13793103 | L22: ='集計_障がい別'!$G$330 -> 0.13793103
B23: 知的障がい（n=2） | C23: ='集計_障がい別'!$H$321 -> 0 | D23: ='集計_障がい別'!$H$322 -> 0 | E23: ='集計_障がい別'!$H$323 -> 0 | F23: ='集計_障がい別'!$H$324 -> 0 | G23: ='集計_障がい別'!$H$325 -> 0.5 | H23: ='集計_障がい別'!$H$326 -> 0 | I23: ='集計_障がい別'!$H$327 -> 0 | J23: ='集計_障がい別'!$H$328 -> 0.5 | K23: ='集計_障がい別'!$H$329 -> 0 | L23: ='集計_障がい別'!$H$330 -> 0
B24: 精神障がい（n=6） | C24: ='集計_障がい別'!$I$321 -> 0 | D24: ='集計_障がい別'!$I$322 -> 0 | E24: ='集計_障がい別'!$I$323 -> 0 | F24: ='集計_障がい別'!$I$324 -> 0.16666667 | G24: ='集計_障がい別'!$I$325 -> 0 | H24: ='集計_障がい別'!$I$326 -> 0 | I24: ='集計_障がい別'!$I$327 -> 0.5 | J24: ='集計_障がい別'!$I$328 -> 0.16666667 | K24: ='集計_障がい別'!$I$329 -> 0.16666667 | L24: ='集計_障がい別'!$I$330 -> 0
B31: 図3-60 今後希望する日中活動・働き方（問32）
B32: ="n="&'集計_障がい者'!$F$330&"（単一回答）" -> n=40（単一回答）
B33: 選択肢 | C33: 件数 | D33: 割合
B34: 一般企業等で働きたい | C34: ='集計_障がい者'!$D$330 -> 1 | D34: ='集計_障がい者'!$E$330 -> 0.025
B35: 短時間・体調に合わせて働きたい | C35: ='集計_障がい者'!$D$331 -> 3 | D35: ='集計_障がい者'!$E$331 -> 0.075
B36: 就労継続支援A型を利用したい | C36: ='集計_障がい者'!$D$332 -> 0 | D36: ='集計_障がい者'!$E$332 -> 0
B37: 就労継続支援B型を利用したい | C37: ='集計_障がい者'!$D$333 -> 1 | D37: ='集計_障がい者'!$E$333 -> 0.025
B38: 生活介護を利用したい | C38: ='集計_障がい者'!$D$334 -> 2 | D38: ='集計_障がい者'!$E$334 -> 0.05
B39: 訓練を受けたい | C39: ='集計_障がい者'!$D$335 -> 0 | D39: ='集計_障がい者'!$E$335 -> 0
B40: 今のままでよい | C40: ='集計_障がい者'!$D$336 -> 22 | D40: ='集計_障がい者'!$E$336 -> 0.55
B41: まだわからない | C41: ='集計_障がい者'!$D$337 -> 3 | D41: ='集計_障がい者'!$E$337 -> 0.075
B42: その他 | C42: ='集計_障がい者'!$D$338 -> 2 | D42: ='集計_障がい者'!$E$338 -> 0.05
B43: 無回答 | C43: ='集計_障がい者'!$D$339 -> 6 | D43: ='集計_障がい者'!$E$339 -> 0.15
B47: 図3-61 今後希望する日中活動・働き方【障がい別】（問32）
B49: 区分 | C49: 一般企業等で働きたい | D49: 短時間・体調に合わせて働きたい | E49: 就労継続支援A型を利用したい | F49: 就労継続支援B型を利用したい | G49: 生活介護を利用したい | H49: 訓練を受けたい | I49: 今のままでよい | J49: まだわからない | K49: その他 | L49: 無回答
B50: 全体 | C50: ='集計_障がい者'!$E$330 -> 0.025 | D50: ='集計_障がい者'!$E$331 -> 0.075 | E50: ='集計_障がい者'!$E$332 -> 0 | F50: ='集計_障がい者'!$E$333 -> 0.025 | G50: ='集計_障がい者'!$E$334 -> 0.05 | H50: ='集計_障がい者'!$E$335 -> 0 | I50: ='集計_障がい者'!$E$336 -> 0.55 | J50: ='集計_障がい者'!$E$337 -> 0.075 | K50: ='集計_障がい者'!$E$338 -> 0.05 | L50: ='集計_障がい者'!$E$339 -> 0.15
B51: 身体障がい（n=29） | C51: ='集計_障がい別'!$G$331 -> 0.034482759 | D51: ='集計_障がい別'!$G$332 -> 0.034482759 | E51: ='集計_障がい別'!$G$333 -> 0 | F51: ='集計_障がい別'!$G$334 -> 0.034482759 | G51: ='集計_障がい別'!$G$335 -> 0.034482759 | H51: ='集計_障がい別'!$G$336 -> 0 | I51: ='集計_障がい別'!$G$337 -> 0.55172414 | J51: ='集計_障がい別'!$G$338 -> 0.068965517 | K51: ='集計_障がい別'!$G$339 -> 0.034482759 | L51: ='集計_障がい別'!$G$340 -> 0.20689655
B52: 知的障がい（n=2） | C52: ='集計_障がい別'!$H$331 -> 0 | D52: ='集計_障がい別'!$H$332 -> 0 | E52: ='集計_障がい別'!$H$333 -> 0 | F52: ='集計_障がい別'!$H$334 -> 0 | G52: ='集計_障がい別'!$H$335 -> 0 | H52: ='集計_障がい別'!$H$336 -> 0 | I52: ='集計_障がい別'!$H$337 -> 1 | J52: ='集計_障がい別'!$H$338 -> 0 | K52: ='集計_障がい別'!$H$339 -> 0 | L52: ='集計_障がい別'!$H$340 -> 0
B53: 精神障がい（n=6） | C53: ='集計_障がい別'!$I$331 -> 0 | D53: ='集計_障がい別'!$I$332 -> 0.33333333 | E53: ='集計_障がい別'!$I$333 -> 0 | F53: ='集計_障がい別'!$I$334 -> 0 | G53: ='集計_障がい別'!$I$335 -> 0 | H53: ='集計_障がい別'!$I$336 -> 0 | I53: ='集計_障がい別'!$I$337 -> 0.5 | J53: ='集計_障がい別'!$I$338 -> 0 | K53: ='集計_障がい別'!$I$339 -> 0.16666667 | L53: ='集計_障がい別'!$I$340 -> 0
B60: 図3-62 働くため・日中活動を続けるために必要な支援（問33）
B61: ="n="&'集計_障がい者'!$F$344&"（複数回答）" -> n=40（複数回答）
...

Sheet 3章_7災害・施策
B2: 図3-72 災害時に不安なこと（問38）
B3: ="n="&'集計_障がい者'!$F$386&"（複数回答）" -> n=40（複数回答）
B4: 選択肢 | C4: 件数 | D4: 割合
B5: 避難先での生活 | C5: ='集計_障がい者'!$D$386 -> 25 | D5: ='集計_障がい者'!$E$386 -> 0.625
B6: 薬・医療機器 | C6: ='集計_障がい者'!$D$387 -> 18 | D6: ='集計_障がい者'!$E$387 -> 0.45
B7: 冬季・積雪時の避難 | C7: ='集計_障がい者'!$D$391 -> 17 | D7: ='集計_障がい者'!$E$391 -> 0.425
B8: 避難する方法 | C8: ='集計_障がい者'!$D$385 -> 15 | D8: ='集計_障がい者'!$E$385 -> 0.375
B9: 電源の確保 | C9: ='集計_障がい者'!$D$388 -> 6 | D9: ='集計_障がい者'!$E$388 -> 0.15
B10: 情報が届かないこと | C10: ='集計_障がい者'!$D$390 -> 5 | D10: ='集計_障がい者'!$E$390 -> 0.125
B11: 介助者がいないこと | C11: ='集計_障がい者'!$D$389 -> 3 | D11: ='集計_障がい者'!$E$389 -> 0.075
B12: ペット・補助犬等 | C12: ='集計_障がい者'!$D$392 -> 0 | D12: ='集計_障がい者'!$E$392 -> 0
B13: 特に不安はない | C13: ='集計_障がい者'!$D$393 -> 3 | D13: ='集計_障がい者'!$E$393 -> 0.075
B14: その他 | C14: ='集計_障がい者'!$D$394 -> 0 | D14: ='集計_障がい者'!$E$394 -> 0
B15: 無回答 | C15: ='集計_障がい者'!$D$395 -> 4 | D15: ='集計_障がい者'!$E$395 -> 0.1
B19: 図3-73 災害時に不安なこと【障がい別】（問38）
B21: 選択肢 | C21: 身体障がい（n=29） | D21: 知的障がい（n=2） | E21: 精神障がい（n=6）
B22: 避難先での生活 | C22: ='集計_障がい別'!$G$387 -> 0.55172414 | D22: ='集計_障がい別'!$H$387 -> 1 | E22: ='集計_障がい別'!$I$387 -> 1
B23: 薬・医療機器 | C23: ='集計_障がい別'!$G$388 -> 0.37931034 | D23: ='集計_障がい別'!$H$388 -> 1 | E23: ='集計_障がい別'!$I$388 -> 0.5
B24: 冬季・積雪時の避難 | C24: ='集計_障がい別'!$G$392 -> 0.34482759 | D24: ='集計_障がい別'!$H$392 -> 0.5 | E24: ='集計_障がい別'!$I$392 -> 0.66666667
B25: 避難する方法 | C25: ='集計_障がい別'!$G$386 -> 0.31034483 | D25: ='集計_障がい別'!$H$386 -> 0.5 | E25: ='集計_障がい別'!$I$386 -> 0.33333333
B26: 電源の確保 | C26: ='集計_障がい別'!$G$389 -> 0.17241379 | D26: ='集計_障がい別'!$H$389 -> 0.5 | E26: ='集計_障がい別'!$I$389 -> 0
B27: 情報が届かないこと | C27: ='集計_障がい別'!$G$391 -> 0.17241379 | D27: ='集計_障がい別'!$H$391 -> 0 | E27: ='集計_障がい別'!$I$391 -> 0
B28: 介助者がいないこと | C28: ='集計_障がい別'!$G$390 -> 0.068965517 | D28: ='集計_障がい別'!$H$390 -> 0.5 | E28: ='集計_障がい別'!$I$390 -> 0
B29: 特に不安はない | C29: ='集計_障がい別'!$G$394 -> 0.10344828 | D29: ='集計_障がい別'!$H$394 -> 0 | E29: ='集計_障がい別'!$I$394 -> 0
B30: 無回答 | C30: ='集計_障がい別'!$G$396 -> 0.13793103 | D30: ='集計_障がい別'!$H$396 -> 0 | E30: ='集計_障がい別'!$I$396 -> 0
B31: ※いずれの区分にも回答のなかった選択肢は省略しています。
B50: 図3-74 避難行動要支援者名簿・個別避難計画の認知（問39）
B51: ="n="&'集計_障がい者'!$F$396&"（単一回答）" -> n=40（単一回答）
B52: 選択肢 | C52: 件数 | D52: 割合
B53: 制度を知っており作成したい | C53: ='集計_障がい者'!$D$396 -> 2 | D53: ='集計_障がい者'!$E$396 -> 0.05
B54: 名前だけ聞いたことがある | C54: ='集計_障がい者'!$D$397 -> 5 | D54: ='集計_障がい者'!$E$397 -> 0.125
B55: 知らない | C55: ='集計_障がい者'!$D$398 -> 28 | D55: ='集計_障がい者'!$E$398 -> 0.7
B56: 必要ない | C56: ='集計_障がい者'!$D$399 -> 1 | D56: ='集計_障がい者'!$E$399 -> 0.025
B57: 無回答 | C57: ='集計_障がい者'!$D$400 -> 4 | D57: ='集計_障がい者'!$E$400 -> 0.1
B61: 図3-75 避難行動要支援者名簿・個別避難計画の認知【障がい別】（問39）
B63: 区分 | C63: 制度を知っており作成したい | D63: 名前だけ聞いたことがある | E63: 知らない | F63: 必要ない | G63: 無回答
B64: 全体 | C64: ='集計_障がい者'!$E$396 -> 0.05 | D64: ='集計_障がい者'!$E$397 -> 0.125 | E64: ='集計_障がい者'!$E$398 -> 0.7 | F64: ='集計_障がい者'!$E$399 -> 0.025 | G64: ='集計_障がい者'!$E$400 -> 0.1
B65: 身体障がい（n=29） | C65: ='集計_障がい別'!$G$397 -> 0.068965517 | D65: ='集計_障がい別'!$G$398 -> 0.17241379 | E65: ='集計_障がい別'!$G$399 -> 0.62068966 | F65: ='集計_障がい別'!$G$400 -> 0.034482759 | G65: ='集計_障がい別'!$G$401 -> 0.10344828
B66: 知的障がい（n=2） | C66: ='集計_障がい別'!$H$397 -> 0 | D66: ='集計_障がい別'!$H$398 -> 0 | E66: ='集計_障がい別'!$H$399 -> 1 | F66: ='集計_障がい別'!$H$400 -> 0 | G66: ='集計_障がい別'!$H$401 -> 0
B67: 精神障がい（n=6） | C67: ='集計_障がい別'!$I$397 -> 0 | D67: ='集計_障がい別'!$I$398 -> 0 | E67: ='集計_障がい別'!$I$399 -> 1 | F67: ='集計_障がい別'!$I$400 -> 0 | G67: ='集計_障がい別'!$I$401 -> 0
...

Sheet 4章_クロス集計
B2: 表4-1 クロス集計の分析テーマ
B3: No. | C3: 分析テーマ | H3: クロス軸（区分 × 集計項目）
B4: C01 | C4: 障がい種別ごとの今後のサービス利用ニーズ | H4: 問6 × 問27-3
B5: C02 | C5: 地区別の外出・交通上の課題 | H5: 問3 × 問14
B6: C03 | C6: 地区別のサービス利用阻害要因 | H6: 問3 × 問28
B7: C04 | C7: 現在の暮らしと将来希望のギャップ | H7: 問7 × 問11
B8: C05 | C8: 年齢別の日常生活上の困りごと | H8: 問2 × 問10
B9: C06 | C9: 現在の日中活動と希望する働き方・活動 | H9: 問31 × 問32
B10: C07 | C10: 個別避難計画の認知と災害時不安 | H10: 問39 × 問38
B11: C08 | C11: 障がい種別ごとに必要な合理的配慮 | H11: 問6 × 問36
B12: C09 | C12: 相談先別の相談支援への期待 | H12: 問22 × 問26
B13: C10 | C13: 主な介助者別の地域生活支援拠点への期待 | H13: 問9 × 問29
B15: 表4-2 障がい種別 × 今後3年間で利用したいサービス（問6×問27-3）
B16: 【件数】斜体のセルが入力値です
B17: 区分 | C17: 身体障がい | D17: 知的障がい | E17: 精神障がい | F17: 発達障がい | G17: わからない・その他
B18: 回答者数（n） | C18: 27 | D18: 2 | E18: 5 | F18: 3 | G18: 2
B19: 居宅介護（ホームヘルプ） | C19: 3 | D19: 0 | E19: 0 | F19: 0 | G19: 0
B20: 同行援護・行動援護 | C20: 1 | D20: 0 | E20: 0 | F20: 0 | G20: 0
B21: 生活介護 | C21: 0 | D21: 2 | E21: 1 | F21: 0 | G21: 0
B22: 自立訓練 | C22: 1 | D22: 0 | E22: 0 | F22: 0 | G22: 1
B23: 就労移行支援 | C23: 0 | D23: 0 | E23: 0 | F23: 1 | G23: 0
B24: 就労継続支援B型 | C24: 0 | D24: 0 | E24: 0 | F24: 0 | G24: 1
B25: 短期入所（ショートステイ） | C25: 3 | D25: 0 | E25: 0 | F25: 0 | G25: 1
B26: グループホーム | C26: 3 | D26: 0 | E26: 1 | F26: 0 | G26: 1
B27: 施設入所支援 | C27: 5 | D27: 2 | E27: 1 | F27: 0 | G27: 1
B28: 計画相談支援 | C28: 1 | D28: 1 | E28: 1 | F28: 0 | G28: 1
B29: 移動支援 | C29: 0 | D29: 0 | E29: 2 | F29: 0 | G29: 0
... B33: 無回答 | C33: 8 | D33: 0 | E33: 0 | F33: 1 | G33: 0
B35: 【割合】各区分の回答者数（n）に占める割合（計算式）
B36: 区分 | C36: 身体障がい | D36: 知的障がい | E36: 精神障がい | F36: 発達障がい | G36: わからない・その他
B37: 居宅介護（ホームヘルプ） | C37: =IF($C$18=0,0,$C$19/$C$18) -> 0.11111111 | D37: =IF($D$18=0,0,$D$19/$D$18) -> 0 | E37: =IF($E$18=0,0,$E$19/$E$18) -> 0 | F37: =IF($F$18=0,0,$F$19/$F$18) -> 0 | G37: =IF($G$18=0,0,$G$19/$G$18) -> 0
B38: 同行援護・行動援護 | C38: =IF($C$18=0,0,$C$20/$C$18) -> 0.037037037 | D38: =IF($D$18=0,0,$D$20/$D$18) -> 0 | E38: =IF($E$18=0,0,$E$20/$E$18) -> 0 | F38: =IF($F$18=0,0,$F$20/$F$18) -> 0 | G38: =IF($G$18=0,0,$G$20/$G$18) -> 0
B39: 生活介護 | C39: =IF($C$18=0,0,$C$21/$C$18) -> 0 | D39: =IF($D$18=0,0,$D$21/$D$18) -> 1 | E39: =IF($E$18=0,0,$E$21/$E$18) -> 0.2 | F39: =IF($F$18=0,0,$F$21/$F$18) -> 0 | G39: =IF($G$18=0,0,$G$21/$G$18) -> 0
B40: 自立訓練 | C40: =IF($C$18=0,0,$C$22/$C$18) -> 0.037037037 | D40: =IF($D$18=0,0,$D$22/$D$18) -> 0 | E40: =IF($E$18=0,0,$E$22/$E$18) -> 0 | F40: =IF($F$18=0,0,$F$22/$F$18) -> 0 | G40: =IF($G$18=0,0,$G$22/$G$18) -> 0.5
B41: 就労移行支援 | C41: =IF($C$18=0,0,$C$23/$C$18) -> 0 | D41: =IF($D$18=0,0,$D$23/$D$18) -> 0 | E41: =IF($E$18=0,0,$E$23/$E$18) -> 0 | F41: =IF($F$18=0,0,$F$23/$F$18) -> 0.33333333 | G41: =IF($G$18=0,0,$G$23/$G$18) -> 0
B42: 就労継続支援B型 | C42: =IF($C$18=0,0,$C$24/$C$18) -> 0 | D42: =IF($D$18=0,0,$D$24/$D$18) -> 0 | E42: =IF($E$18=0,0,$E$24/$E$18) -> 0 | F42: =IF($F$18=0,0,$F$24/$F$18) -> 0 | G42: =IF($G$18=0,0,$G$24/$G$18) -> 0.5
B43: 短期入所（ショートステイ） | C43: =IF($C$18=0,0,$C$25/$C$18) -> 0.11111111 | D43: =IF($D$18=0,0,$D$25/$D$18) -> 0 | E43: =IF($E$18=0,0,$E$25/$E$18) -> 0 | F43: =IF($F$18=0,0,$F$25/$F$18) -> 0 | G43: =IF($G$18=0,0,$G$25/$G$18) -> 0.5
B44: グループホーム | C44: =IF($C$18=0,0,$C$26/$C$18) -> 0.11111111 | D44: =IF($D$18=0,0,$D$26/$D$18) -> 0 | E44: =IF($E$18=0,0,$E$26/$E$18) -> 0.2 | F44: =IF($F$18=0,0,$F$26/$F$18) -> 0 | G44: =IF($G$18=0,0,$G$26/$G$18) -> 0.5
B45: 施設入所支援 | C45: =IF($C$18=0,0,$C$27/$C$18) -> 0.18518519 | D45: =IF($D$18=0,0,$D$27/$D$18) -> 1 | E45: =IF($E$18=0,0,$E$27/$E$18) -> 0.2 | F45: =IF($F$18=0,0,$F$27/$F$18) -> 0 | G45: =IF($G$18=0,0,$G$27/$G$18) -> 0.5
B46: 計画相談支援 | C46: =IF($C$18=0,0,$C$28/$C$18) -> 0.037037037 | D46: =IF($D$18=0,0,$D$28/$D$18) -> 0.5 | E46: =IF($E$18=0,0,$E$28/$E$18) -> 0.2 | F46: =IF($F$18=0,0,$F$28/$F$18) -> 0 | G46: =IF($G$18=0,0,$G$28/$G$18) -> 0.5
...

Sheet 5章_障がい児
B2: 表5-1 回答者の属性（障がい児調査）
B3: 項目 | C3: 回答（件数）
B4: 記入者（問1） | C4: 「ご家族」2件、「宛名のご本人」1件
B5: 本人意向の反映（問1-2） | C5: 「本人が回答した」1件、「本人の様子や日頃の意向を踏まえて代理記入した」1件、「本人に確認することが難しく、家族・支援者の判断で記入した」1件
B6: 年齢（問2） | C6: 「6～11歳」1件、「12～14歳」1件、「15～17歳」1件
B7: お住まいの地区（問3） | C7: 「北山地区」2件、「裏磐梯地区」1件
B8: 性別（問4） | C8: 「男性」2件、「女性」1件
B9: 所持している手帳等（問5・複数回答、n=3） | C9: 「身体障がい者手帳」2件、「療育手帳」1件、「精神障がい者保健福祉手帳」1件、「無回答」1件
B10: 主たる障がい種別（問6） | C10: 「身体障がい」1件、「知的障がい」1件、「発達障がい」1件
B11: 障害児通所支援等の支給決定（問7） | C11: 「受けている」2件、「受けていない」1件
B12: 主な支援・介助・見守りをしている方（問8） | C12: 「親」3件
B13: 現在の暮らし（問9） | C13: 「自宅で家族と暮らしている」3件
B15: 図5-1 日常生活で困っていること（問10）
B16: ="n="&'集計_障がい児'!$F$76&"（複数回答）" -> n=3（複数回答）
B17: 選択肢 | C17: 件数
B18: 将来の生活 | C18: ='集計_障がい児'!$D$76 -> 3
B19: 家事 | C19: ='集計_障がい児'!$D$65 -> 1
B20: 食事 | C20: ='集計_障がい児'!$D$66 -> 1
B21: 入浴 | C21: ='集計_障がい児'!$D$67 -> 1
B22: 排せつ | C22: ='集計_障がい児'!$D$68 -> 1
B23: 服薬管理 | C23: ='集計_障がい児'!$D$69 -> 1
B24: 金銭管理 | C24: ='集計_障がい児'!$D$70 -> 1
B25: 通院 | C25: ='集計_障がい児'!$D$71 -> 1
B26: 外出・移動 | C26: ='集計_障がい児'!$D$72 -> 1
B27: 買い物 | C27: ='集計_障がい児'!$D$73 -> 1
B28: 災害時の避難 | C28: ='集計_障がい児'!$D$74 -> 1
B29: 相談先がない | C29: ='集計_障がい児'!$D$75 -> 0
B30: 特にない | C30: ='集計_障がい児'!$D$77 -> 0
B31: その他 | C31: ='集計_障がい児'!$D$78 -> 1
B32: 無回答 | C32: ='集計_障がい児'!$D$79 -> 0
B36: 図5-2 外出するときに困ること（問14）
B37: ="n="&'集計_障がい児'!$F$103&"（複数回答）" -> n=3（複数回答）
B38: 選択肢 | C38: 件数
B39: 交通手段が少ない | C39: ='集計_障がい児'!$D$103 -> 2
B40: 家族等の付き添いが必要 | C40: ='集計_障がい児'!$D$104 -> 2
B41: 送迎がない | C41: ='集計_障がい児'!$D$105 -> 1
B42: 冬季・積雪時に外出しにくい | C42: ='集計_障がい児'!$D$106 -> 1
B43: 体調面が不安 | C43: ='集計_障がい児'!$D$109 -> 1
B44: 費用がかかる | C44: ='集計_障がい児'!$D$110 -> 1
B45: その他 | C45: ='集計_障がい児'!$D$112 -> 1
...

Sheet 6章_課題
B2: 表6-1 課題と計画上の主な取組・指標の関係
B3: 課題 | C3: 関連する主な取組・指標の領域（例） | G3: 主な根拠設問
B4: 1 相談支援体制・情報提供 | C4: 相談支援体制の充実・強化、計画相談支援、意思決定支援の推進 | G4: 問22・問23・問26・問27-2・問44
B5: 2 移動・外出支援 | C5: 移動支援事業（地域生活支援事業）、同行援護・行動援護、関係部署との連携 | G5: 問13・問14・問16・児問24・児問29
B6: 3 災害時の支援体制 | C6: 個別避難計画の作成推進、福祉避難所の確保、防災分野との連携 | G6: 問38～問41・児問37～児問40
B7: 4 地域生活支援拠点・将来の暮らし | C7: 地域生活支援の充実（地域生活支援拠点等）、施設入所者の地域生活への移行、共同生活援助・短期入所の見込量 | G7: 問10・問11・問27-3・問29
B8: 5 障がい児・家族支援 | C8: 障がい児支援の提供体制の整備、放課後等デイサービス・障がい児相談支援の見込量、医療的ケア児支援 | G8: 児問18・児問24・児問25・児問29・児問31
B9: 6 権利擁護・合理的配慮 | C9: 成年後見制度利用支援事業、意思疎通支援事業、理解促進研修・啓発事業 | G9: 問34～問37・問43
B10: 7 日中活動・就労・社会参加 | C10: 福祉施設から一般就労への移行等、就労選択支援・就労系サービスの見込量 | G10: 問31～問33・問42・児問32
B11: 8 専門的支援 | C11: 精神障がいにも対応した地域包括ケアシステムの構築、強度行動障がい・医療的ケアへの対応 | G11: 問17～問20
B12: ※「児問」は障がい児調査の設問を示します。関連する取組・指標の領域は例示であり、国の基本指針の内容に応じて整理してください。

Sheet 集計_障がい者
A1: 障がい者調査（18歳以上） 単純集計（入力データ）
A2: 斜体のセル（件数・回答者数）が入力値です。割合は計算式で、各章シートの表・グラフに自動で反映されます。回答者数（n）は無回答を含む人数で、各設問の先頭行に入力し、2行目以降は先頭行を参照しています。「無回答」は各設問の最終行です。
A4: 設問番号 | B4: 設問 | C4: 選択肢 | D4: 件数 | E4: 割合 | F4: 回答者数（n） | G4: 回答形式
A5: 問1 | B5: この調査票を記入された方はどなたですか | C5: 宛名のご本人 | D5: 25 | E5: =IF($F5=0,0,D5/$F5) -> 0.625 | F5: 40 | G5: 単一回答
A6: 問1 | B6: この調査票を記入された方はどなたですか | C6: ご家族 | D6: 9 | E6: =IF($F6=0,0,D6/$F6) -> 0.225 | F6: =$F$5 -> 40 | G6: 単一回答
A7: 問1 | B7: この調査票を記入された方はどなたですか | C7: 支援者・事業所職員 | D7: 4 | E7: =IF($F7=0,0,D7/$F7) -> 0.1 | F7: =$F$5 -> 40 | G7: 単一回答
A8: 問1 | B8: この調査票を記入された方はどなたですか | C8: その他 | D8: 1 | E8: =IF($F8=0,0,D8/$F8) -> 0.025 | F8: =$F$5 -> 40 | G8: 単一回答
A9: 問1 | B9: この調査票を記入された方はどなたですか | C9: 無回答 | D9: 1 | E9: =IF($F9=0,0,D9/$F9) -> 0.025 | F9: =$F$5 -> 40 | G9: 単一回答
A10: 問1-2 | B10: この回答は、宛名のご本人の意向をどのように反映していますか | C10: 本人が回答した | D10: 23 | E10: =IF($F10=0,0,D10/$F10) -> 0.575 | F10: 40 | G10: 単一回答
A11: 問1-2 | B11: この回答は、宛名のご本人の意向をどのように反映していますか | C11: 本人に確認して代理記入した | D11: 8 | E11: =IF($F11=0,0,D11/$F11) -> 0.2 | F11: =$F$10 -> 40 | G11: 単一回答
A12: 問1-2 | B12: この回答は、宛名のご本人の意向をどのように反映していますか | C12: 本人の様子や日頃の意向を踏まえて代理記入した | D12: 2 | E12: =IF($F12=0,0,D12/$F12) -> 0.05 | F12: =$F$10 -> 40 | G12: 単一回答
A13: 問1-2 | B13: この回答は、宛名のご本人の意向をどのように反映していますか | C13: 本人に確認することが難しく、家族・支援者の判断で記入した | D13: 6 | E13: =IF($F13=0,0,D13/$F13) -> 0.15 | F13: =$F$10 -> 40 | G13: 単一回答
A14: 問1-2 | B14: この回答は、宛名のご本人の意向をどのように反映していますか | C14: その他 | D14: 0 | E14: =IF($F14=0,0,D14/$F14) -> 0 | F14: =$F$10 -> 40 | G14: 単一回答
A15: 問1-2 | B15: この回答は、宛名のご本人の意向をどのように反映していますか | C15: 無回答 | D15: 1 | E15: =IF($F15=0,0,D15/$F15) -> 0.025 | F15: =$F$10 -> 40 | G15: 単一回答
A16: 問2 | B16: あなた（宛名の方）の年齢を教えてください | C16: 18～29歳 | D16: 0 | E16: =IF($F16=0,0,D16/$F16) -> 0 | F16: 40 | G16: 単一回答
A17: 問2 | B17: あなた（宛名の方）の年齢を教えてください | C17: 30～39歳 | D17: 3 | E17: =IF($F17=0,0,D17/$F17) -> 0.075 | F17: =$F$16 -> 40 | G17: 単一回答
A18: 問2 | B18: あなた（宛名の方）の年齢を教えてください | C18: 40～49歳 | D18: 2 | E18: =IF($F18=0,0,D18/$F18) -> 0.05 | F18: =$F$16 -> 40 | G18: 単一回答
A19: 問2 | B19: あなた（宛名の方）の年齢を教えてください | C19: 50～64歳 | D19: 8 | E19: =IF($F19=0,0,D19/$F19) -> 0.2 | F19: =$F$16 -> 40 | G19: 単一回答
A20: 問2 | B20: あなた（宛名の方）の年齢を教えてください | C20: 65歳以上 | D20: 26 | E20: =IF($F20=0,0,D20/$F20) -> 0.65 | F20: =$F$16 -> 40 | G20: 単一回答
A21: 問2 | B21: あなた（宛名の方）の年齢を教えてください | C21: 無回答 | D21: 1 | E21: =IF($F21=0,0,D21/$F21) -> 0.025 | F21: =$F$16 -> 40 | G21: 単一回答
A22: 問3 | B22: あなたのお住まいの地区を教えてください | C22: 北山地区 | D22: 17 | E22: =IF($F22=0,0,D22/$F22) -> 0.425 | F22: 40 | G22: 単一回答
A23: 問3 | B23: あなたのお住まいの地区を教えてください | C23: 大塩地区 | D23: 8 | E23: =IF($F23=0,0,D23/$F23) -> 0.2 | F23: =$F$22 -> 40 | G23: 単一回答
A24: 問3 | B24: あなたのお住まいの地区を教えてください | C24: 桧原地区 | D24: 3 | E24: =IF($F24=0,0,D24/$F24) -> 0.075 | F24: =$F$22 -> 40 | G24: 単一回答
A25: 問3 | B25: あなたのお住まいの地区を教えてください | C25: 裏磐梯地区 | D25: 11 | E25: =IF($F25=0,0,D25/$F25) -> 0.275 | F25: =$F$22 -> 40 | G25: 単一回答
A26: 問3 | B26: あなたのお住まいの地区を教えてください | C26: その他 | D26: 1 | E26: =IF($F26=0,0,D26/$F26) -> 0.025 | F26: =$F$22 -> 40 | G26: 単一回答
A27: 問3 | B27: あなたのお住まいの地区を教えてください | C27: 無回答 | D27: 0 | E27: =IF($F27=0,0,D27/$F27) -> 0 | F27: =$F$22 -> 40 | G27: 単一回答
A28: 問4 | B28: あなたの性別を教えてください | C28: 男性 | D28: 17 | E28: =IF($F28=0,0,D28/$F28) -> 0.425 | F28: 40 | G28: 単一回答
A29: 問4 | B29: あなたの性別を教えてください | C29: 女性 | D29: 23 | E29: =IF($F29=0,0,D29/$F29) -> 0.575 | F29: =$F$28 -> 40 | G29: 単一回答
A30: 問4 | B30: あなたの性別を教えてください | C30: 回答しない | D30: 0 | E30: =IF($F30=0,0,D30/$F30) -> 0 | F30: =$F$28 -> 40 | G30: 単一回答
A31: 問4 | B31: あなたの性別を教えてください | C31: 無回答 | D31: 0 | E31: =IF($F31=0,0,D31/$F31) -> 0 | F31: =$F$28 -> 40 | G31: 単一回答
A32: 問5 | B32: お持ちの手帳等を教えてください（あてはまるものすべて） | C32: 身体障がい者手帳 | D32: 29 | E32: =IF($F32=0,0,D32/$F32) -> 0.725 | F32: 40 | G32: 複数回答
A33: 問5 | B33: お持ちの手帳等を教えてください（あてはまるものすべて） | C33: 療育手帳 | D33: 2 | E33: =IF($F33=0,0,D33/$F33) -> 0.05 | F33: =$F$32 -> 40 | G33: 複数回答
A34: 問5 | B34: お持ちの手帳等を教えてください（あてはまるものすべて） | C34: 精神障がい者保健福祉手帳 | D34: 6 | E34: =IF($F34=0,0,D34/$F34) -> 0.15 | F34: =$F$32 -> 40 | G34: 複数回答
A35: 問5 | B35: お持ちの手帳等を教えてください（あてはまるものすべて） | C35: 自立支援医療受給者証 | D35: 5 | E35: =IF($F35=0,0,D35/$F35) -> 0.125 | F35: =$F$32 -> 40 | G35: 複数回答
A36: 問5 | B36: お持ちの手帳等を教えてください（あてはまるものすべて） | C36: 難病に関する医療受給者証等 | D36: 0 | E36: =IF($F36=0,0,D36/$F36) -> 0 | F36: =$F$32 -> 40 | G36: 複数回答
A37: 問5 | B37: お持ちの手帳等を教えてください（あてはまるものすべて） | C37: 手帳等は持っていないが障がい福祉サービスを利用している | D37: 1 | E37: =IF($F37=0,0,D37/$F37) -> 0.025 | F37: =$F$32 -> 40 | G37: 複数回答
A38: 問5 | B38: お持ちの手帳等を教えてください（あてはまるものすべて） | C38: その他 | D38: 2 | E38: =IF($F38=0,0,D38/$F38) -> 0.05 | F38: =$F$32 -> 40 | G38: 複数回答
A39: 問5 | B39: お持ちの手帳等を教えてください（あてはまるものすべて） | C39: 無回答 | D39: 1 | E39: =IF($F39=0,0,D39/$F39) -> 0.025 | F39: =$F$32 -> 40 | G39: 複数回答
A40: 問6 | B40: 主たる障がい種別を1つ選ぶとすれば、どれにあたりますか | C40: 身体障がい | D40: 27 | E40: =IF($F40=0,0,D40/$F40) -> 0.675 | F40: 40 | G40: 単一回答
A41: 問6 | B41: 主たる障がい種別を1つ選ぶとすれば、どれにあたりますか | C41: 知的障がい | D41: 2 | E41: =IF($F41=0,0,D41/$F41) -> 0.05 | F41: =$F$40 -> 40 | G41: 単一回答
...

Sheet 集計_障がい児
A1: 障がい児調査（18歳未満） 単純集計（入力データ）
A2: 斜体のセル（件数・回答者数）が入力値です。割合は計算式で、各章シートの表・グラフに自動で反映されます。回答者数（n）は無回答を含む人数で、各設問の先頭行に入力し、2行目以降は先頭行を参照しています。「無回答」は各設問の最終行です。
A4: 設問番号 | B4: 設問 | C4: 選択肢 | D4: 件数 | E4: 割合 | F4: 回答者数（n） | G4: 回答形式
A5: 問1 | B5: この調査票を記入された方はどなたですか | C5: 宛名のご本人 | D5: 1 | E5: =IF($F5=0,0,D5/$F5) -> 0.33333333 | F5: 3 | G5: 単一回答
A6: 問1 | B6: この調査票を記入された方はどなたですか | C6: ご家族 | D6: 2 | E6: =IF($F6=0,0,D6/$F6) -> 0.66666667 | F6: =$F$5 -> 3 | G6: 単一回答
A7: 問1 | B7: この調査票を記入された方はどなたですか | C7: 支援者・事業所職員 | D7: 0 | E7: =IF($F7=0,0,D7/$F7) -> 0 | F7: =$F$5 -> 3 | G7: 単一回答
A8: 問1 | B8: この調査票を記入された方はどなたですか | C8: その他 | D8: 0 | E8: =IF($F8=0,0,D8/$F8) -> 0 | F8: =$F$5 -> 3 | G8: 単一回答
A9: 問1 | B9: この調査票を記入された方はどなたですか | C9: 無回答 | D9: 0 | E9: =IF($F9=0,0,D9/$F9) -> 0 | F9: =$F$5 -> 3 | G9: 単一回答
A10: 問1-2 | B10: この回答は、宛名のご本人の意向をどのように反映していますか | C10: 本人が回答した | D10: 1 | E10: =IF($F10=0,0,D10/$F10) -> 0.33333333 | F10: 3 | G10: 単一回答
A11: 問1-2 | B11: この回答は、宛名のご本人の意向をどのように反映していますか | C11: 本人に確認して代理記入した | D11: 0 | E11: =IF($F11=0,0,D11/$F11) -> 0 | F11: =$F$10 -> 3 | G11: 単一回答
A12: 問1-2 | B12: この回答は、宛名のご本人の意向をどのように反映していますか | C12: 本人の様子や日頃の意向を踏まえて代理記入した | D12: 1 | E12: =IF($F12=0,0,D12/$F12) -> 0.33333333 | F12: =$F$10 -> 3 | G12: 単一回答
A13: 問1-2 | B13: この回答は、宛名のご本人の意向をどのように反映していますか | C13: 本人に確認することが難しく、家族・支援者の判断で記入した | D13: 1 | E13: =IF($F13=0,0,D13/$F13) -> 0.33333333 | F13: =$F$10 -> 3 | G13: 単一回答
A14: 問1-2 | B14: この回答は、宛名のご本人の意向をどのように反映していますか | C14: その他 | D14: 0 | E14: =IF($F14=0,0,D14/$F14) -> 0 | F14: =$F$10 -> 3 | G14: 単一回答
A15: 問1-2 | B15: この回答は、宛名のご本人の意向をどのように反映していますか | C15: 無回答 | D15: 0 | E15: =IF($F15=0,0,D15/$F15) -> 0 | F15: =$F$10 -> 3 | G15: 単一回答
A16: 問2 | B16: お子さん（宛名の方）の年齢を教えてください | C16: 0～5歳 | D16: 0 | E16: =IF($F16=0,0,D16/$F16) -> 0 | F16: 3 | G16: 単一回答
A17: 問2 | B17: お子さん（宛名の方）の年齢を教えてください | C17: 6～11歳 | D17: 1 | E17: =IF($F17=0,0,D17/$F17) -> 0.33333333 | F17: =$F$16 -> 3 | G17: 単一回答
A18: 問2 | B18: お子さん（宛名の方）の年齢を教えてください | C18: 12～14歳 | D18: 1 | E18: =IF($F18=0,0,D18/$F18) -> 0.33333333 | F18: =$F$16 -> 3 | G18: 単一回答
A19: 問2 | B19: お子さん（宛名の方）の年齢を教えてください | C19: 15～17歳 | D19: 1 | E19: =IF($F19=0,0,D19/$F19) -> 0.33333333 | F19: =$F$16 -> 3 | G19: 単一回答
A20: 問2 | B20: お子さん（宛名の方）の年齢を教えてください | C20: 無回答 | D20: 0 | E20: =IF($F20=0,0,D20/$F20) -> 0 | F20: =$F$16 -> 3 | G20: 単一回答
A21: 問3 | B21: あなたのお住まいの地区を教えてください | C21: 北山地区 | D21: 2 | E21: =IF($F21=0,0,D21/$F21) -> 0.66666667 | F21: 3 | G21: 単一回答
A22: 問3 | B22: あなたのお住まいの地区を教えてください | C22: 大塩地区 | D22: 0 | E22: =IF($F22=0,0,D22/$F22) -> 0 | F22: =$F$21 -> 3 | G22: 単一回答
A23: 問3 | B23: あなたのお住まいの地区を教えてください | C23: 桧原地区 | D23: 0 | E23: =IF($F23=0,0,D23/$F23) -> 0 | F23: =$F$21 -> 3 | G23: 単一回答
A24: 問3 | B24: あなたのお住まいの地区を教えてください | C24: 裏磐梯地区 | D24: 1 | E24: =IF($F24=0,0,D24/$F24) -> 0.33333333 | F24: =$F$21 -> 3 | G24: 単一回答
A25: 問3 | B25: あなたのお住まいの地区を教えてください | C25: その他 | D25: 0 | E25: =IF($F25=0,0,D25/$F25) -> 0 | F25: =$F$21 -> 3 | G25: 単一回答
A26: 問3 | B26: あなたのお住まいの地区を教えてください | C26: 無回答 | D26: 0 | E26: =IF($F26=0,0,D26/$F26) -> 0 | F26: =$F$21 -> 3 | G26: 単一回答
A27: 問4 | B27: あなたの性別を教えてください | C27: 男性 | D27: 2 | E27: =IF($F27=0,0,D27/$F27) -> 0.66666667 | F27: 3 | G27: 単一回答
A28: 問4 | B28: あなたの性別を教えてください | C28: 女性 | D28: 1 | E28: =IF($F28=0,0,D28/$F28) -> 0.33333333 | F28: =$F$27 -> 3 | G28: 単一回答
A29: 問4 | B29: あなたの性別を教えてください | C29: 回答しない | D29: 0 | E29: =IF($F29=0,0,D29/$F29) -> 0 | F29: =$F$27 -> 3 | G29: 単一回答
A30: 問4 | B30: あなたの性別を教えてください | C30: 無回答 | D30: 0 | E30: =IF($F30=0,0,D30/$F30) -> 0 | F30: =$F$27 -> 3 | G30: 単一回答
A31: 問5 | B31: お持ちの手帳等を教えてください（あてはまるものすべて） | C31: 身体障がい者手帳 | D31: 2 | E31: =IF($F31=0,0,D31/$F31) -> 0.66666667 | F31: 3 | G31: 複数回答
A32: 問5 | B32: お持ちの手帳等を教えてください（あてはまるものすべて） | C32: 療育手帳 | D32: 1 | E32: =IF($F32=0,0,D32/$F32) -> 0.33333333 | F32: =$F$31 -> 3 | G32: 複数回答
A33: 問5 | B33: お持ちの手帳等を教えてください（あてはまるものすべて） | C33: 精神障がい者保健福祉手帳 | D33: 1 | E33: =IF($F33=0,0,D33/$F33) -> 0.33333333 | F33: =$F$31 -> 3 | G33: 複数回答
A34: 問5 | B34: お持ちの手帳等を教えてください（あてはまるものすべて） | C34: 難病に関する医療受給者証等 | D34: 0 | E34: =IF($F34=0,0,D34/$F34) -> 0 | F34: =$F$31 -> 3 | G34: 複数回答
A35: 問5 | B35: お持ちの手帳等を教えてください（あてはまるものすべて） | C35: 手帳等は持っていないが障がい福祉サービスを利用している | D35: 0 | E35: =IF($F35=0,0,D35/$F35) -> 0 | F35: =$F$31 -> 3 | G35: 複数回答
A36: 問5 | B36: お持ちの手帳等を教えてください（あてはまるものすべて） | C36: その他 | D36: 0 | E36: =IF($F36=0,0,D36/$F36) -> 0 | F36: =$F$31 -> 3 | G36: 複数回答
A37: 問5 | B37: お持ちの手帳等を教えてください（あてはまるものすべて） | C37: 無回答 | D37: 1 | E37: =IF($F37=0,0,D37/$F37) -> 0.33333333 | F37: =$F$31 -> 3 | G37: 複数回答
A38: 問6 | B38: 主たる障がい種別を1つ選ぶとすれば、どれにあたりますか | C38: 身体障がい | D38: 1 | E38: =IF($F38=0,0,D38/$F38) -> 0.33333333 | F38: 3 | G38: 単一回答
A39: 問6 | B39: 主たる障がい種別を1つ選ぶとすれば、どれにあたりますか | C39: 知的障がい | D39: 1 | E39: =IF($F39=0,0,D39/$F39) -> 0.33333333 | F39: =$F$38 -> 3 | G39: 単一回答
A40: 問6 | B40: 主たる障がい種別を1つ選ぶとすれば、どれにあたりますか | C40: 精神障がい | D40: 0 | E40: =IF($F40=0,0,D40/$F40) -> 0 | F40: =$F$38 -> 3 | G40: 単一回答
A41: 問6 | B41: 主たる障がい種別を1つ選ぶとすれば、どれにあたりますか | C41: 発達障がい | D41: 1 | E41: =IF($F41=0,0,D41/$F41) -> 0.33333333 | F41: =$F$38 -> 3 | G41: 単一回答
...

Sheet 集計_障がい別
A1: 障がい者調査 障がい別集計（入力データ）
A2: 障がい別は、第７期計画策定時の調査と同様に、問5で所持していると回答した手帳により区分しています（身体障がい者手帳＝身体障がい、療育手帳＝知的障がい、精神障がい者保健福祉手帳＝精神障がい）。複数の手帳を所持している方は各区分に計上。斜体が入力値（件数・回答者数）、割合は各区分の回答者数を基数とする計算式です。
A4: 設問番号 | B4: 設問 | C4: 選択肢 | D4: 身体障がい （件数） | E4: 知的障がい （件数） | F4: 精神障がい （件数） | G4: 身体障がい （割合） | H4: 知的障がい （割合） | I4: 精神障がい （割合）
C5: 回答者数（n） | D5: 29 | E5: 2 | F5: 6
A6: 問1 | B6: この調査票を記入された方はどなたですか | C6: 宛名のご本人 | D6: 18 | E6: 0 | F6: 4 | G6: =IF(D$5=0,0,D6/D$5) -> 0.62068966 | H6: =IF(E$5=0,0,E6/E$5) -> 0 | I6: =IF(F$5=0,0,F6/F$5) -> 0.66666667
A7: 問1 | C7: ご家族 | D7: 8 | E7: 0 | F7: 1 | G7: =IF(D$5=0,0,D7/D$5) -> 0.27586207 | H7: =IF(E$5=0,0,E7/E$5) -> 0 | I7: =IF(F$5=0,0,F7/F$5) -> 0.16666667
A8: 問1 | C8: 支援者・事業所職員 | D8: 3 | E8: 2 | F8: 0 | G8: =IF(D$5=0,0,D8/D$5) -> 0.10344828 | H8: =IF(E$5=0,0,E8/E$5) -> 1 | I8: =IF(F$5=0,0,F8/F$5) -> 0
A9: 問1 | C9: その他 | D9: 0 | E9: 0 | F9: 1 | G9: =IF(D$5=0,0,D9/D$5) -> 0 | H9: =IF(E$5=0,0,E9/E$5) -> 0 | I9: =IF(F$5=0,0,F9/F$5) -> 0.16666667
A10: 問1 | C10: 無回答 | D10: 0 | E10: 0 | F10: 0 | G10: =IF(D$5=0,0,D10/D$5) -> 0 | H10: =IF(E$5=0,0,E10/E$5) -> 0 | I10: =IF(F$5=0,0,F10/F$5) -> 0
A11: 問1-2 | B11: この回答は、宛名のご本人の意向をどのように反映していますか | C11: 本人が回答した | D11: 16 | E11: 0 | F11: 4 | G11: =IF(D$5=0,0,D11/D$5) -> 0.55172414 | H11: =IF(E$5=0,0,E11/E$5) -> 0 | I11: =IF(F$5=0,0,F11/F$5) -> 0.66666667
A12: 問1-2 | C12: 本人に確認して代理記入した | D12: 7 | E12: 0 | F12: 1 | G12: =IF(D$5=0,0,D12/D$5) -> 0.24137931 | H12: =IF(E$5=0,0,E12/E$5) -> 0 | I12: =IF(F$5=0,0,F12/F$5) -> 0.16666667
A13: 問1-2 | C13: 本人の様子や日頃の意向を踏まえて代理記入した | D13: 1 | E13: 0 | F13: 1 | G13: =IF(D$5=0,0,D13/D$5) -> 0.034482759 | H13: =IF(E$5=0,0,E13/E$5) -> 0 | I13: =IF(F$5=0,0,F13/F$5) -> 0.16666667
A14: 問1-2 | C14: 本人に確認することが難しく、家族・支援者の判断で記入した | D14: 5 | E14: 2 | F14: 0 | G14: =IF(D$5=0,0,D14/D$5) -> 0.17241379 | H14: =IF(E$5=0,0,E14/E$5) -> 1 | I14: =IF(F$5=0,0,F14/F$5) -> 0
A15: 問1-2 | C15: その他 | D15: 0 | E15: 0 | F15: 0 | G15: =IF(D$5=0,0,D15/D$5) -> 0 | H15: =IF(E$5=0,0,E15/E$5) -> 0 | I15: =IF(F$5=0,0,F15/F$5) -> 0
A16: 問1-2 | C16: 無回答 | D16: 0 | E16: 0 | F16: 0 | G16: =IF(D$5=0,0,D16/D$5) -> 0 | H16: =IF(E$5=0,0,E16/E$5) -> 0 | I16: =IF(F$5=0,0,F16/F$5) -> 0
A17: 問2 | B17: あなた（宛名の方）の年齢を教えてください | C17: 18～29歳 | D17: 0 | E17: 0 | F17: 0 | G17: =IF(D$5=0,0,D17/D$5) -> 0 | H17: =IF(E$5=0,0,E17/E$5) -> 0 | I17: =IF(F$5=0,0,F17/F$5) -> 0
A18: 問2 | C18: 30～39歳 | D18: 1 | E18: 0 | F18: 2 | G18: =IF(D$5=0,0,D18/D$5) -> 0.034482759 | H18: =IF(E$5=0,0,E18/E$5) -> 0 | I18: =IF(F$5=0,0,F18/F$5) -> 0.33333333
A19: 問2 | C19: 40～49歳 | D19: 1 | E19: 0 | F19: 1 | G19: =IF(D$5=0,0,D19/D$5) -> 0.034482759 | H19: =IF(E$5=0,0,E19/E$5) -> 0 | I19: =IF(F$5=0,0,F19/F$5) -> 0.16666667
A20: 問2 | C20: 50～64歳 | D20: 5 | E20: 1 | F20: 2 | G20: =IF(D$5=0,0,D20/D$5) -> 0.17241379 | H20: =IF(E$5=0,0,E20/E$5) -> 0.5 | I20: =IF(F$5=0,0,F20/F$5) -> 0.33333333
A21: 問2 | C21: 65歳以上 | D21: 21 | E21: 1 | F21: 1 | G21: =IF(D$5=0,0,D21/D$5) -> 0.72413793 | H21: =IF(E$5=0,0,E21/E$5) -> 0.5 | I21: =IF(F$5=0,0,F21/F$5) -> 0.16666667
A22: 問2 | C22: 無回答 | D22: 1 | E22: 0 | F22: 0 | G22: =IF(D$5=0,0,D22/D$5) -> 0.034482759 | H22: =IF(E$5=0,0,E22/E$5) -> 0 | I22: =IF(F$5=0,0,F22/F$5) -> 0
A23: 問3 | B23: あなたのお住まいの地区を教えてください | C23: 北山地区 | D23: 14 | E23: 1 | F23: 2 | G23: =IF(D$5=0,0,D23/D$5) -> 0.48275862 | H23: =IF(E$5=0,0,E23/E$5) -> 0.5 | I23: =IF(F$5=0,0,F23/F$5) -> 0.33333333
A24: 問3 | C24: 大塩地区 | D24: 4 | E24: 1 | F24: 1 | G24: =IF(D$5=0,0,D24/D$5) -> 0.13793103 | H24: =IF(E$5=0,0,E24/E$5) -> 0.5 | I24: =IF(F$5=0,0,F24/F$5) -> 0.16666667
A25: 問3 | C25: 桧原地区 | D25: 3 | E25: 0 | F25: 0 | G25: =IF(D$5=0,0,D25/D$5) -> 0.10344828 | H25: =IF(E$5=0,0,E25/E$5) -> 0 | I25: =IF(F$5=0,0,F25/F$5) -> 0
A26: 問3 | C26: 裏磐梯地区 | D26: 8 | E26: 0 | F26: 2 | G26: =IF(D$5=0,0,D26/D$5) -> 0.27586207 | H26: =IF(E$5=0,0,E26/E$5) -> 0 | I26: =IF(F$5=0,0,F26/F$5) -> 0.33333333
A27: 問3 | C27: その他 | D27: 0 | E27: 0 | F27: 1 | G27: =IF(D$5=0,0,D27/D$5) -> 0 | H27: =IF(E$5=0,0,E27/E$5) -> 0 | I27: =IF(F$5=0,0,F27/F$5) -> 0.16666667
A28: 問3 | C28: 無回答 | D28: 0 | E28: 0 | F28: 0 | G28: =IF(D$5=0,0,D28/D$5) -> 0 | H28: =IF(E$5=0,0,E28/E$5) -> 0 | I28: =IF(F$5=0,0,F28/F$5) -> 0
A29: 問4 | B29: あなたの性別を教えてください | C29: 男性 | D29: 10 | E29: 1 | F29: 5 | G29: =IF(D$5=0,0,D29/D$5) -> 0.34482759 | H29: =IF(E$5=0,0,E29/E$5) -> 0.5 | I29: =IF(F$5=0,0,F29/F$5) -> 0.83333333
A30: 問4 | C30: 女性 | D30: 19 | E30: 1 | F30: 1 | G30: =IF(D$5=0,0,D30/D$5) -> 0.65517241 | H30: =IF(E$5=0,0,E30/E$5) -> 0.5 | I30: =IF(F$5=0,0,F30/F$5) -> 0.16666667
A31: 問4 | C31: 回答しない | D31: 0 | E31: 0 | F31: 0 | G31: =IF(D$5=0,0,D31/D$5) -> 0 | H31: =IF(E$5=0,0,E31/E$5) -> 0 | I31: =IF(F$5=0,0,F31/F$5) -> 0
A32: 問4 | C32: 無回答 | D32: 0 | E32: 0 | F32: 0 | G32: =IF(D$5=0,0,D32/D$5) -> 0 | H32: =IF(E$5=0,0,E32/E$5) -> 0 | I32: =IF(F$5=0,0,F32/F$5) -> 0
A33: 問5 | B33: お持ちの手帳等を教えてください（あてはまるものすべて） | C33: 身体障がい者手帳 | D33: 29 | E33: 1 | F33: 0 | G33: =IF(D$5=0,0,D33/D$5) -> 1 | H33: =IF(E$5=0,0,E33/E$5) -> 0.5 | I33: =IF(F$5=0,0,F33/F$5) -> 0
A34: 問5 | C34: 療育手帳 | D34: 1 | E34: 2 | F34: 0 | G34: =IF(D$5=0,0,D34/D$5) -> 0.034482759 | H34: =IF(E$5=0,0,E34/E$5) -> 1 | I34: =IF(F$5=0,0,F34/F$5) -> 0
A35: 問5 | C35: 精神障がい者保健福祉手帳 | D35: 0 | E35: 0 | F35: 6 | G35: =IF(D$5=0,0,D35/D$5) -> 0 | H35: =IF(E$5=0,0,E35/E$5) -> 0 | I35: =IF(F$5=0,0,F35/F$5) -> 1
A36: 問5 | C36: 自立支援医療受給者証 | D36: 3 | E36: 0 | F36: 1 | G36: =IF(D$5=0,0,D36/D$5) -> 0.10344828 | H36: =IF(E$5=0,0,E36/E$5) -> 0 | I36: =IF(F$5=0,0,F36/F$5) -> 0.16666667
A37: 問5 | C37: 難病に関する医療受給者証等 | D37: 0 | E37: 0 | F37: 0 | G37: =IF(D$5=0,0,D37/D$5) -> 0 | H37: =IF(E$5=0,0,E37/E$5) -> 0 | I37: =IF(F$5=0,0,F37/F$5) -> 0
A38: 問5 | C38: 手帳等は持っていないが障がい福祉サービスを利用している | D38: 0 | E38: 0 | F38: 0 | G38: =IF(D$5=0,0,D38/D$5) -> 0 | H38: =IF(E$5=0,0,E38/E$5) -> 0 | I38: =IF(F$5=0,0,F38/F$5) -> 0
A39: 問5 | C39: その他 | D39: 1 | E39: 0 | F39: 0 | G39: =IF(D$5=0,0,D39/D$5) -> 0.034482759 | H39: =IF(E$5=0,0,E39/E$5) -> 0 | I39: =IF(F$5=0,0,F39/F$5) -> 0
A40: 問5 | C40: 無回答 | D40: 0 | E40: 0 | F40: 0 | G40: =IF(D$5=0,0,D40/D$5) -> 0 | H40: =IF(E$5=0,0,E40/E$5) -> 0 | I40: =IF(F$5=0,0,F40/F$5) -> 0
A41: 問6 | B41: 主たる障がい種別を1つ選ぶとすれば、どれにあたりますか | C41: 身体障がい | D41: 26 | E41: 0 | F41: 0 | G41: =IF(D$5=0,0,D41/D$5) -> 0.89655172 | H41: =IF(E$5=0,0,E41/E$5) -> 0 | I41: =IF(F$5=0,0,F41/F$5) -> 0
...
