Workbook

Sheet 概要
A1: 将来推計ワーニングチェック結果概要 | D1: 出力日： | E1: 2026/09/28
D2: 推計名： | E2: 将来推計0925-2
B11: No. | C11: 施策反映を画面上で既に実施した項目名（画面名） | D11: ワーニング発生件数
B12: 1 | C12: 施策反映 認定者数 | D12: =IF('施策反映 認定者数'!O43="","",IF(COUNTIF('施策反映 認定者数'!N37:N42,1)=0,"該当無し",COUNTIF('施策反映 認定者数'!N37:N42,1))) -> 該当無し
B13: 2 | C13: 施策反映 施設・居住系サービス利用者数 | D13: =IF('施策反映 施設・居住系サービス利用者数'!N58="","",IF(COUNTIF('施策反映 施設・居住系サービス利用者数'!M37:M60,1)=0,"該当無し",COUNTIF('施策反映 施設・居住系サービス利用者数'!M37:M60,1))) -> 該当無し
B14: 3 | C14: 施策反映 在宅サービス利用者数 | D14: =IF('施策反映 在宅サービス利用者数'!N108="","",IF(COUNTIF('施策反映 在宅サービス利用者数'!M37:M104,1)=0,"該当無し",COUNTIF('施策反映 在宅サービス利用者数'!M37:M104,1))) -> 該当無し
B17: （ご参考）以下については、参考資料として必要に応じて確認してください。
B19: １）在宅サービス／居住系サービス／施設サービス毎の要介護度別1人1月あたり給付費
B20: No. | C20: 項目名 | D20: ワーニング発生件数
B21: 1 | C21: 在宅サービス／居住系サービス／施設サービス | D21: =IF('(参考)在宅・居住系・施設1人1月あたり給付費'!N73="","",IF(COUNTIF('(参考)在宅・居住系・施設1人1月あたり給付費'!$M$7:$M$72,1)=0,"該当無し",COUNTIF('(参考)在宅・居住系・施設1人1月あたり給付費'!$M$7:$M$72,1))) -> 該当無し
B23: ２）サービス種類毎の要介護度別1人(1回(日))1月あたり給付費
B24: No. | C24: 項目名 | D24: ワーニング発生件数
B25: 1 | C25: 在宅サービス | D25: =IF('(参考)1人(1回(日))1月あたり給付費(在宅)'!O517="","",IF(COUNTIF('(参考)1人(1回(日))1月あたり給付費(在宅)'!N7:N498,1)=0,"該当無し",COUNTIF('(参考)1人(1回(日))1月あたり給付費(在宅)'!N7:N498,1))) -> 該当無し
B26: 2 | C26: 居住系サービス | D26: =IF('(参考)1人(1回(日))1月あたり給付費(居住系)'!O91="","",IF(COUNTIF('(参考)1人(1回(日))1月あたり給付費(居住系)'!N7:N90,1)=0,"該当無し",COUNTIF('(参考)1人(1回(日))1月あたり給付費(居住系)'!N7:N90,1))) -> 該当無し
B27: 3 | C27: 施設サービス | D27: =IF('(参考)1人(1回(日))1月あたり給付費(施設)'!O61="","",IF(COUNTIF('(参考)1人(1回(日))1月あたり給付費(施設)'!N7:N42,1)=0,"該当無し",COUNTIF('(参考)1人(1回(日))1月あたり給付費(施設)'!N7:N42,1))) -> 該当無し
B29: ３）在宅サービス1人1月あたり利用回（日）数
B30: No. | C30: 項目名 | D30: ワーニング発生件数
B31: 1 | C31: 在宅サービス | D31: =IF('在宅サービス1人1月あたり利用回（日）数'!L271="","",IF(COUNTIF('在宅サービス1人1月あたり利用回（日）数'!K7:K270,1)=0,"該当無し",COUNTIF('在宅サービス1人1月あたり利用回（日）数'!K7:K270,1))) -> 33

Sheet data
I1: 下限 | J1: 上限
A2: シート名 | C2: MIN | D2: Q1 | E2: Q2 | F2: Q3 | G2: MAX | H2: Q（=Q3-Q1） | I2: Q1-Q*2 | J2: Q3+Q*2
A3: 施策反映 認定者数 | B3: 認定者数 男 | C3: -22.352941 | D3: -0.54406964 | E3: 2.0562771 | F3: 4.1925466 | G3: 34.375 | H3: =F3-D3 -> 4.7366162 | I3: -0.11 | J3: 0.14
A4: 施策反映 認定者数 | B4: 認定者数 女 | C4: -13.824885 | D4: -0.97656401 | E4: 1.091399 | F4: 2.8908325 | G4: 12.290503 | H4: =F4-D4 -> 3.8673965 | I4: -0.09 | J4: 0.11
A5: 施策反映 施設・居住系サービス利用者数 | B5: 居宅サービス 特定施設入居者生活介護 | C5: -100 | D5: -3.3877502 | E5: 2.9035013 | F5: 9.3070721 | G5: 2039.1304 | H5: =F5-D5 -> 12.694822 | I5: -0.25 | J5: 0.35
A6: 施策反映 施設・居住系サービス利用者数 | B6: 地域密着型サービス 認知症対応型共同生活介護 | C6: -100 | D6: -2.5593797 | E6: 0.5131807 | F6: 3.2132709 | G6: 93.75 | H6: =F6-D6 -> 5.7726506 | I6: -0.1 | J6: 0.15
A7: 施策反映 施設・居住系サービス利用者数 | B7: 地域密着型サービス 地域密着型特定施設入居者生活介護 | C7: -100 | D7: -3.197755 | E7: 0.91326105 | F7: 5.8734583 | G7: 1100 | H7: =F7-D7 -> 9.0712133 | I7: -0.2 | J7: 0.25
A8: 施策反映 施設・居住系サービス利用者数 | B8: 地域密着型サービス 地域密着型介護老人福祉施設入所者生活介護 | C8: -100 | D8: -1.5705788 | E8: 0.43399644 | F8: 2.5177677 | G8: 2091.6667 | H8: =F8-D8 -> 4.0883466 | I8: -0.05 | J8: 0.15
A9: 施策反映 施設・居住系サービス利用者数 | B9: 施設サービス 介護老人福祉施設 | C9: -45.011086 | D9: -1.5504536 | E9: 0.86844887 | F9: 3.5259 | G9: 75.195143 | H9: =F9-D9 -> 5.0763537 | I9: -0.1 | J9: 0.15
A10: 施策反映 施設・居住系サービス利用者数 | B10: 施設サービス 介護老人保健施設 | C10: -100 | D10: -4.8555377 | E10: -0.2739726 | F10: 3.5936751 | G10: 266.66667 | H10: =F10-D10 -> 8.4492129 | I10: -0.2 | J10: 0.25
A11: 施策反映 施設・居住系サービス利用者数 | B11: 施設サービス 介護医療院 | C11: -100 | D11: -8.2474144 | E11: 3.9955654 | F11: 20.284959 | G11: 1745.4545 | H11: =F11-D11 -> 28.532373 | I11: -0.65 | J11: 0.8
A12: 施策反映 在宅サービス利用者数 | B12: 居宅サービス 訪問介護 | C12: -37.878788 | D12: -3.2667301 | E12: 0.9469697 | F12: 4.6026547 | G12: 66.666667 | H12: =F12-D12 -> 7.8693848 | I12: -0.15 | J12: 0.25
A13: 施策反映 在宅サービス利用者数 | B13: 居宅サービス 訪問入浴介護 | C13: -100 | D13: -16.124435 | E13: -3.875969 | F13: 7.6108442 | G13: 2200 | H13: =F13-D13 -> 23.735279 | I13: -0.6 | J13: 0.6
A14: 施策反映 在宅サービス利用者数 | B14: 居宅サービス 訪問看護 | C14: -78.347578 | D14: 2.3720511 | E14: 7.7659911 | F14: 12.851493 | G14: 157.14286 | H14: =F14-D14 -> 10.479442 | I14: -0.15 | J14: 0.35
... A26: 施策反映 在宅サービス利用者数 | B26: 居宅サービス 介護予防支援・居宅介護支援 | C26: -17.604913 | D26: -0.43014825 | E26: 1.7926461 | F26: 3.7242035 | G26: 14.373717 | H26: =F26-D26 -> 4.1543517 | I26: -0.05 | J26: 0.15
A27: 施策反映 在宅サービス利用者数 | B27: 居宅サービス 登録施設介護支援 | H27: =F27-D27 -> 0 | I27: 0 | J27: 0
A28: 施策反映 在宅サービス利用者数 | B28: 地域密着型サービス 定期巡回・随時対応型訪問介護看護 | C28: -100 | D28: -11.767316 | E28: 8.3333333 | F28: 33.171521 | G28: 4500 | H28: =F28-D28 -> 44.938837 | I28: -1 | J28: 1.25
A29: 施策反映 在宅サービス利用者数 | B29: 地域密着型サービス 夜間対応型訪問介護 | C29: -100 | D29: -28.571429 | E29: -3.1576356 | F29: 10.454528 | G29: 1100 | H29: =F29-D29 -> 39.025957 | I29: -1.05 | J29: 0.9
A30: 施策反映 在宅サービス利用者数 | B30: 地域密着型サービス 地域密着型通所介護 | C30: -100 | D30: -6.3916545 | E30: 0.35837958 | F30: 7.364761 | G30: 4200 | H30: =F30-D30 -> 13.756415 | I30: -0.3 | J30: 0.35
A31: 施策反映 在宅サービス利用者数 | B31: 地域密着型サービス 認知症対応型通所介護 | C31: -100 | D31: -15.201629 | E31: -3.875969 | F31: 8.3333333 | G31: 1100 | H31: =F31-D31 -> 23.534962 | I31: -0.6 | J31: 0.6
A32: 施策反映 在宅サービス利用者数 | B32: 地域密着型サービス 小規模多機能型居宅介護 | C32: -100 | D32: -8.3333333 | E32: -1.2234182 | F32: 5.1428286 | G32: 1400 | H32: =F32-D32 -> 13.476162 | I32: -0.35 | J32: 0.35
A33: 施策反映 在宅サービス利用者数 | B33: 地域密着型サービス 看護小規模多機能型居宅介護 | C33: -100 | D33: -10.197368 | E33: 3.3670034 | F33: 21.248143 | G33: 6825 | H33: =F33-D33 -> 31.445511 | I33: -0.7 | J33: 0.85
A34: (参考)在宅・居住系・施設1人1月あたり給付費 | B34: 在宅サービス 要支援1 | C34: 3715 | D34: 9064.4146 | E34: 9986.2364 | F34: 10950.118 | G34: 23555.425 | H34: =F34-D34 -> 1885.7036 | I34: 5290 | J34: 14725
A35: (参考)在宅・居住系・施設1人1月あたり給付費 | B35: 在宅サービス 要支援2 | C35: 4090.1508 | D35: 11447.06 | E35: 12857.596 | F35: 14392.096 | G35: 38059.37 | H35: =F35-D35 -> 2945.0355 | I35: 5555 | J35: 20285
A36: (参考)在宅・居住系・施設1人1月あたり給付費 | B36: 在宅サービス 要介護1 | C36: 19238.59 | D36: 29242.596 | E36: 31730.193 | F36: 34145.208 | G36: 48932.404 | H36: =F36-D36 -> 4902.6124 | I36: 19435 | J36: 43955
A37: (参考)在宅・居住系・施設1人1月あたり給付費 | B37: 在宅サービス 要介護2 | C37: 20797.245 | D37: 35204.176 | E37: 37854.243 | F37: 40522.503 | G37: 68999.206 | H37: =F37-D37 -> 5318.3279 | I37: 24565 | J37: 51160
A38: (参考)在宅・居住系・施設1人1月あたり給付費 | B38: 在宅サービス 要介護3 | C38: 29345.439 | D38: 47981.893 | E38: 51446.952 | F38: 55322.452 | G38: 157851.46 | H38: =F38-D38 -> 7340.5593 | I38: 33300 | J38: 70005
A39: (参考)在宅・居住系・施設1人1月あたり給付費 | B39: 在宅サービス 要介護4 | C39: 22971.689 | D39: 52966.272 | E39: 56943.724 | F39: 61420.256 | G39: 98701.561 | H39: =F39-D39 -> 8453.9841 | I39: 36055 | J39: 78330
... A171: (参考)1人(1回(日))1月あたり給付費(在宅) | B171: 介護予防支援・居宅介護支援 合計 | C171: 8813.6317 | D171: 12062.191 | E171: 12882.274 | F171: 13662.578 | G171: 16862.669 | H171: =F171-D171 -> 1600.3862 | I171: 8860 | J171: 16865
A172: (参考)1人(1回(日))1月あたり給付費(在宅) | B172: 登録施設介護支援 要支援1 | H172: =F172-D172 -> 0 | I172: 0 | J172: 0
A173: (参考)1人(1回(日))1月あたり給付費(在宅) | B173: 登録施設介護支援 要支援2 | H173: =F173-D173 -> 0 | I173: 0 | J173: 0
A174: (参考)1人(1回(日))1月あたり給付費(在宅) | B174: 登録施設介護支援 要介護1 | H174: =F174-D174 -> 0 | I174: 0 | J174: 0
A175: (参考)1人(1回(日))1月あたり給付費(在宅) | B175: 登録施設介護支援 要介護2 | H175: =F175-D175 -> 0 | I175: 0 | J175: 0
A176: (参考)1人(1回(日))1月あたり給付費(在宅) | B176: 登録施設介護支援 要介護3 | H176: =F176-D176 -> 0 | I176: 0 | J176: 0
A177: (参考)1人(1回(日))1月あたり給付費(在宅) | B177: 登録施設介護支援 要介護4 | H177: =F177-D177 -> 0 | I177: 0 | J177: 0
A178: (参考)1人(1回(日))1月あたり給付費(在宅) | B178: 登録施設介護支援 要介護5 | H178: =F178-D178 -> 0 | I178: 0 | J178: 0
A179: (参考)1人(1回(日))1月あたり給付費(在宅) | B179: 登録施設介護支援 合計 | H179: =F179-D179 -> 0 | I179: 0 | J179: 0
A180: (参考)1人(1回(日))1月あたり給付費(在宅) | B180: 定期巡回・随時対応型訪問介護看護 要介護1 | C180: 21375 | D180: 68912.752 | E180: 76099.446 | F180: 83705.901 | G180: 185222 | H180: =F180-D180 -> 14793.15 | I180: 39325 | J180: 113295
A181: (参考)1人(1回(日))1月あたり給付費(在宅) | B181: 定期巡回・随時対応型訪問介護看護 要介護2 | C181: 24129 | D181: 111324.39 | E181: 120344.58 | F181: 132291.64 | G181: 340515 | H181: =F181-D181 -> 20967.256 | I181: 69385 | J181: 174230
A182: (参考)1人(1回(日))1月あたり給付費(在宅) | B182: 定期巡回・随時対応型訪問介護看護 要介護3 | C182: 24543 | D182: 173274.88 | E182: 185926.25 | F182: 202412.16 | G182: 841323 | H182: =F182-D182 -> 29137.28 | I182: 115000 | J182: 260690
...

Sheet 施策反映 認定者数
A1: 将来推計ワーニングチェック結果詳細
B3: １．施策反映 認定者数
C5: 本シートでは、以下に示す認定者数(第1号被保険者)の施策反映値について、前年度からの変化率のチェックを行っています(画面イメージはサンプルです)。
C6: 変化率(%)＝(当該年度認定者数－前年度認定者数)÷前年度認定者数×100
B34: ワーニングチェック結果
B35: No. | C35: ワーニング対象指標値 | D35: 認定者数 | I35: 変化率 (チェック対象) | J35: 閾値 | L35: チェック結果
J36: 下限値 | K36: 上限値
B37: 1 | C37: 認定者数 | E37: 令和8年度 | F37: 254 | G37: 令和9年度 | H37: 256 | I37: =IF(ISERROR(ROUND((H37-F37)/F37*1,3))=TRUE,"－",ROUND((H37-F37)/F37*1,3)) -> 0.008 | J37: =J38 -> -0.11 | K37: =K38 -> 0.14 | L37: =IF(I37="－","",IF(I37<J37,"下限値を"&ROUND((J37-I37)*100,1)&"％下回っています。",IF(I37>K37,"上限値を"&ROUND((I37-K37)*100,1)&"％上回っています。","閾値の範囲内です。"))) -> 閾値の範囲内です。 | N37: =IF(OR(I37="－",AND(J37="－",K37="－")),"",IF(OR(I37<J37,I37>K37),1,"")) | O37: =IF(AND(F37="",H37=""),"",1) -> 1
C38: =C37 -> 認定者数 | D38: 男 | E38: 令和9年度 | F38: =IF(H37="","",H37) -> 256 | G38: 令和10年度 | H38: 258 | I38: =IF(ISERROR(ROUND((H38-F38)/F38*1,3))=TRUE,"－",ROUND((H38-F38)/F38*1,3)) -> 0.008 | J38: =data!I3 -> -0.11 | K38: =data!J3 -> 0.14 | L38: =IF(I38="－","",IF(I38<J38,"下限値を"&ROUND((J38-I38)*100,1)&"％下回っています。",IF(I38>K38,"上限値を"&ROUND((I38-K38)*100,1)&"％上回っています。","閾値の範囲内です。"))) -> 閾値の範囲内です。 | N38: =IF(OR(I38="－",AND(J38="－",K38="－")),"",IF(OR(I38<J38,I38>K38),1,"")) | O38: =IF(AND(F38="",H38=""),"",1) -> 1
C39: =C38 -> 認定者数 | E39: 令和10年度 | F39: =IF(H38="","",H38) -> 258 | G39: 令和11年度 | H39: 263 | I39: =IF(ISERROR(ROUND((H39-F39)/F39*1,3))=TRUE,"－",ROUND((H39-F39)/F39*1,3)) -> 0.019 | J39: =J38 -> -0.11 | K39: =K38 -> 0.14 | L39: =IF(I39="－","",IF(I39<J39,"下限値を"&ROUND((J39-I39)*100,1)&"％下回っています。",IF(I39>K39,"上限値を"&ROUND((I39-K39)*100,1)&"％上回っています。","閾値の範囲内です。"))) -> 閾値の範囲内です。 | N39: =IF(OR(I39="－",AND(J39="－",K39="－")),"",IF(OR(I39<J39,I39>K39),1,"")) | O39: =IF(AND(F39="",H39=""),"",1) -> 1
C40: =C39 -> 認定者数 | E40: 令和8年度 | F40: 527 | G40: 令和9年度 | H40: 522 | I40: =IF(ISERROR(ROUND((H40-F40)/F40*1,3))=TRUE,"－",ROUND((H40-F40)/F40*1,3)) -> -0.009 | J40: =J41 -> -0.09 | K40: =K41 -> 0.11 | L40: =IF(I40="－","",IF(I40<J40,"下限値を"&ROUND((J40-I40)*100,1)&"％下回っています。",IF(I40>K40,"上限値を"&ROUND((I40-K40)*100,1)&"％上回っています。","閾値の範囲内です。"))) -> 閾値の範囲内です。 | N40: =IF(OR(I40="－",AND(J40="－",K40="－")),"",IF(OR(I40<J40,I40>K40),1,"")) | O40: =IF(AND(F40="",H40=""),"",1) -> 1
C41: =C40 -> 認定者数 | D41: 女 | E41: 令和9年度 | F41: =IF(H40="","",H40) -> 522 | G41: 令和10年度 | H41: 516 | I41: =IF(ISERROR(ROUND((H41-F41)/F41*1,3))=TRUE,"－",ROUND((H41-F41)/F41*1,3)) -> -0.011 | J41: =data!I4 -> -0.09 | K41: =data!J4 -> 0.11 | L41: =IF(I41="－","",IF(I41<J41,"下限値を"&ROUND((J41-I41)*100,1)&"％下回っています。",IF(I41>K41,"上限値を"&ROUND((I41-K41)*100,1)&"％上回っています。","閾値の範囲内です。"))) -> 閾値の範囲内です。 | N41: =IF(OR(I41="－",AND(J41="－",K41="－")),"",IF(OR(I41<J41,I41>K41),1,"")) | O41: =IF(AND(F41="",H41=""),"",1) -> 1
C42: =C41 -> 認定者数 | E42: 令和10年度 | F42: =IF(H41="","",H41) -> 516 | G42: 令和11年度 | H42: 511 | I42: =IF(ISERROR(ROUND((H42-F42)/F42*1,3))=TRUE,"－",ROUND((H42-F42)/F42*1,3)) -> -0.01 | J42: =J41 -> -0.09 | K42: =K41 -> 0.11 | L42: =IF(I42="－","",IF(I42<J42,"下限値を"&ROUND((J42-I42)*100,1)&"％下回っています。",IF(I42>K42,"上限値を"&ROUND((I42-K42)*100,1)&"％上回っています。","閾値の範囲内です。"))) -> 閾値の範囲内です。 | N42: =IF(OR(I42="－",AND(J42="－",K42="－")),"",IF(OR(I42<J42,I42>K42),1,"")) | O42: =IF(AND(F42="",H42=""),"",1) -> 1
O43: =IF(COUNTIF(O37:O42,1)>0,1,"") -> 1

Sheet 施策反映 施設・居住系サービス利用者数
A1: 将来推計ワーニングチェック結果詳細
B3: ２．施策反映 施設・居住系サービス利用者数
C5: 本シートでは、以下に示す施設・居住系サービス毎の利用者数の施策反映値について、前年度からの変化率のチェックを行っています(画面イメージはサンプルです)。
C6: 変化率(%)＝(当該年度利用者数－前年度利用者数)÷前年度利用者数×100
B34: ワーニングチェック結果
B35: No. | C35: ワーニング対象指標値 | D35: 利用者数 | H35: 変化率 (チェック対象) | I35: 閾値 | K35: チェック結果
I36: 下限値 | J36: 上限値
B37: 居宅サービス
B38: 1 | C38: 特定施設入居者生活介護 | D38: 令和8年度 | E38: 2 | F38: 令和9年度 | G38: 2 | H38: =IF(ISERROR(ROUND((G38-E38)/E38*1,3))=TRUE,"－",ROUND((G38-E38)/E38*1,3)) -> 0 | I38: =I39 -> -0.25 | J38: =J39 -> 0.35 | K38: =IF(H38="－","",IF(H38<I38,"下限値を"&ROUND((I38-H38)*100,1)&"％下回っています。",IF(H38>J38,"上限値を"&ROUND((H38-J38)*100,1)&"％上回っています。","閾値の範囲内です。"))) -> 閾値の範囲内です。 | M38: =IF(OR(H38="－",AND(I38="－",J38="－")),"",IF(OR(H38<I38,H38>J38),1,"")) | N38: =IF(AND(E38="",G38=""),"",1) -> 1
C39: =C38 -> 特定施設入居者生活介護 | D39: 令和9年度 | E39: =IF(G38="","",G38) -> 2 | F39: 令和10年度 | G39: 2 | H39: =IF(ISERROR(ROUND((G39-E39)/E39*1,3))=TRUE,"－",ROUND((G39-E39)/E39*1,3)) -> 0 | I39: =data!I5 -> -0.25 | J39: =data!J5 -> 0.35 | K39: =IF(H39="－","",IF(H39<I39,"下限値を"&ROUND((I39-H39)*100,1)&"％下回っています。",IF(H39>J39,"上限値を"&ROUND((H39-J39)*100,1)&"％上回っています。","閾値の範囲内です。"))) -> 閾値の範囲内です。 | M39: =IF(OR(H39="－",AND(I39="－",J39="－")),"",IF(OR(H39<I39,H39>J39),1,"")) | N39: =IF(AND(E39="",G39=""),"",1) -> 1
C40: =C39 -> 特定施設入居者生活介護 | D40: 令和10年度 | E40: =IF(G39="","",G39) -> 2 | F40: 令和11年度 | G40: 2 | H40: =IF(ISERROR(ROUND((G40-E40)/E40*1,3))=TRUE,"－",ROUND((G40-E40)/E40*1,3)) -> 0 | I40: =I39 -> -0.25 | J40: =J39 -> 0.35 | K40: =IF(H40="－","",IF(H40<I40,"下限値を"&ROUND((I40-H40)*100,1)&"％下回っています。",IF(H40>J40,"上限値を"&ROUND((H40-J40)*100,1)&"％上回っています。","閾値の範囲内です。"))) -> 閾値の範囲内です。 | M40: =IF(OR(H40="－",AND(I40="－",J40="－")),"",IF(OR(H40<I40,H40>J40),1,"")) | N40: =IF(AND(E40="",G40=""),"",1) -> 1
B41: 地域密着型サービス
B42: 2 | C42: 認知症対応型共同生活介護 | D42: 令和8年度 | E42: 44 | F42: 令和9年度 | G42: 46 | H42: =IF(ISERROR(ROUND((G42-E42)/E42*1,3))=TRUE,"－",ROUND((G42-E42)/E42*1,3)) -> 0.045 | I42: =I43 -> -0.1 | J42: =J43 -> 0.15 | K42: =IF(H42="－","",IF(H42<I42,"下限値を"&ROUND((I42-H42)*100,1)&"％下回っています。",IF(H42>J42,"上限値を"&ROUND((H42-J42)*100,1)&"％上回っています。","閾値の範囲内です。"))) -> 閾値の範囲内です。 | M42: =IF(OR(H42="－",AND(I42="－",J42="－")),"",IF(OR(H42<I42,H42>J42),1,"")) | N42: =IF(AND(E42="",G42=""),"",1) -> 1
C43: =C42 -> 認知症対応型共同生活介護 | D43: 令和9年度 | E43: =IF(G42="","",G42) -> 46 | F43: 令和10年度 | G43: 45 | H43: =IF(ISERROR(ROUND((G43-E43)/E43*1,3))=TRUE,"－",ROUND((G43-E43)/E43*1,3)) -> -0.022 | I43: =data!I6 -> -0.1 | J43: =data!J6 -> 0.15 | K43: =IF(H43="－","",IF(H43<I43,"下限値を"&ROUND((I43-H43)*100,1)&"％下回っています。",IF(H43>J43,"上限値を"&ROUND((H43-J43)*100,1)&"％上回っています。","閾値の範囲内です。"))) -> 閾値の範囲内です。 | M43: =IF(OR(H43="－",AND(I43="－",J43="－")),"",IF(OR(H43<I43,H43>J43),1,"")) | N43: =IF(AND(E43="",G43=""),"",1) -> 1
C44: =C43 -> 認知症対応型共同生活介護 | D44: 令和10年度 | E44: =IF(G43="","",G43) -> 45 | F44: 令和11年度 | G44: 45 | H44: =IF(ISERROR(ROUND((G44-E44)/E44*1,3))=TRUE,"－",ROUND((G44-E44)/E44*1,3)) -> 0 | I44: =I43 -> -0.1 | J44: =J43 -> 0.15 | K44: =IF(H44="－","",IF(H44<I44,"下限値を"&ROUND((I44-H44)*100,1)&"％下回っています。",IF(H44>J44,"上限値を"&ROUND((H44-J44)*100,1)&"％上回っています。","閾値の範囲内です。"))) -> 閾値の範囲内です。 | M44: =IF(OR(H44="－",AND(I44="－",J44="－")),"",IF(OR(H44<I44,H44>J44),1,"")) | N44: =IF(AND(E44="",G44=""),"",1) -> 1
B45: 3 | C45: 地域密着型特定施設入居者生活介護 | D45: 令和8年度 | E45: 0 | F45: 令和9年度 | G45: 0 | H45: =IF(ISERROR(ROUND((G45-E45)/E45*1,3))=TRUE,"－",ROUND((G45-E45)/E45*1,3)) -> － | I45: =I46 -> -0.2 | J45: =J46 -> 0.25 | K45: =IF(H45="－","",IF(H45<I45,"下限値を"&ROUND((I45-H45)*100,1)&"％下回っています。",IF(H45>J45,"上限値を"&ROUND((H45-J45)*100,1)&"％上回っています。","閾値の範囲内です。"))) | M45: =IF(OR(H45="－",AND(I45="－",J45="－")),"",IF(OR(H45<I45,H45>J45),1,"")) | N45: =IF(AND(E45="",G45=""),"",1) -> 1
C46: =C45 -> 地域密着型特定施設入居者生活介護 | D46: 令和9年度 | E46: =IF(G45="","",G45) -> 0 | F46: 令和10年度 | G46: 0 | H46: =IF(ISERROR(ROUND((G46-E46)/E46*1,3))=TRUE,"－",ROUND((G46-E46)/E46*1,3)) -> － | I46: =data!I7 -> -0.2 | J46: =data!J7 -> 0.25 | K46: =IF(H46="－","",IF(H46<I46,"下限値を"&ROUND((I46-H46)*100,1)&"％下回っています。",IF(H46>J46,"上限値を"&ROUND((H46-J46)*100,1)&"％上回っています。","閾値の範囲内です。"))) | M46: =IF(OR(H46="－",AND(I46="－",J46="－")),"",IF(OR(H46<I46,H46>J46),1,"")) | N46: =IF(AND(E46="",G46=""),"",1) -> 1
C47: =C46 -> 地域密着型特定施設入居者生活介護 | D47: 令和10年度 | E47: =IF(G46="","",G46) -> 0 | F47: 令和11年度 | G47: 0 | H47: =IF(ISERROR(ROUND((G47-E47)/E47*1,3))=TRUE,"－",ROUND((G47-E47)/E47*1,3)) -> － | I47: =I46 -> -0.2 | J47: =J46 -> 0.25 | K47: =IF(H47="－","",IF(H47<I47,"下限値を"&ROUND((I47-H47)*100,1)&"％下回っています。",IF(H47>J47,"上限値を"&ROUND((H47-J47)*100,1)&"％上回っています。","閾値の範囲内です。"))) | M47: =IF(OR(H47="－",AND(I47="－",J47="－")),"",IF(OR(H47<I47,H47>J47),1,"")) | N47: =IF(AND(E47="",G47=""),"",1) -> 1
B48: 4 | C48: 地域密着型介護老人福祉施設入所者生活介護 | D48: 令和8年度 | E48: 40 | F48: 令和9年度 | G48: 40 | H48: =IF(ISERROR(ROUND((G48-E48)/E48*1,3))=TRUE,"－",ROUND((G48-E48)/E48*1,3)) -> 0 | I48: =I49 -> -0.05 | J48: =J49 -> 0.15 | K48: =IF(H48="－","",IF(H48<I48,"下限値を"&ROUND((I48-H48)*100,1)&"％下回っています。",IF(H48>J48,"上限値を"&ROUND((H48-J48)*100,1)&"％上回っています。","閾値の範囲内です。"))) -> 閾値の範囲内です。 | M48: =IF(OR(H48="－",AND(I48="－",J48="－")),"",IF(OR(H48<I48,H48>J48),1,"")) | N48: =IF(AND(E48="",G48=""),"",1) -> 1
C49: =C48 -> 地域密着型介護老人福祉施設入所者生活介護 | D49: 令和9年度 | E49: =IF(G48="","",G48) -> 40 | F49: 令和10年度 | G49: 40 | H49: =IF(ISERROR(ROUND((G49-E49)/E49*1,3))=TRUE,"－",ROUND((G49-E49)/E49*1,3)) -> 0 | I49: =data!I8 -> -0.05 | J49: =data!J8 -> 0.15 | K49: =IF(H49="－","",IF(H49<I49,"下限値を"&ROUND((I49-H49)*100,1)&"％下回っています。",IF(H49>J49,"上限値を"&ROUND((H49-J49)*100,1)&"％上回っています。","閾値の範囲内です。"))) -> 閾値の範囲内です。 | M49: =IF(OR(H49="－",AND(I49="－",J49="－")),"",IF(OR(H49<I49,H49>J49),1,"")) | N49: =IF(AND(E49="",G49=""),"",1) -> 1
C50: =C49 -> 地域密着型介護老人福祉施設入所者生活介護 | D50: 令和10年度 | E50: =IF(G49="","",G49) -> 40 | F50: 令和11年度 | G50: 40 | H50: =IF(ISERROR(ROUND((G50-E50)/E50*1,3))=TRUE,"－",ROUND((G50-E50)/E50*1,3)) -> 0 | I50: =I49 -> -0.05 | J50: =J49 -> 0.15 | K50: =IF(H50="－","",IF(H50<I50,"下限値を"&ROUND((I50-H50)*100,1)&"％下回っています。",IF(H50>J50,"上限値を"&ROUND((H50-J50)*100,1)&"％上回っています。","閾値の範囲内です。"))) -> 閾値の範囲内です。 | M50: =IF(OR(H50="－",AND(I50="－",J50="－")),"",IF(OR(H50<I50,H50>J50),1,"")) | N50: =IF(AND(E50="",G50=""),"",1) -> 1
B51: 施設サービス | N51: =IF(AND(E51="",G51=""),"",1)
B52: 5 | C52: 介護老人福祉施設 | D52: 令和8年度 | E52: 59 | F52: 令和9年度 | G52: 59 | H52: =IF(ISERROR(ROUND((G52-E52)/E52*1,3))=TRUE,"－",ROUND((G52-E52)/E52*1,3)) -> 0 | I52: =I53 -> -0.1 | J52: =J53 -> 0.15 | K52: =IF(H52="－","",IF(AND(I52<>"－",H52<I52),"下限値を"&ROUND((I52-H52)*100,1)&"％下回っています。",IF(AND(J52<>"－",H52>J52),"上限値を"&ROUND((H52-J52)*100,1)&"％上回っています。","閾値の範囲内です。"))) -> 閾値の範囲内です。 | M52: =IF(OR(H52="－",AND(I52="－",J52="－")),"",IF(AND(K52<>"チェック対象外",OR(AND(I52<>"－",H52<I52),AND(J52<>"－",H52>J52))),1,"")) | N52: =IF(AND(E52="",G52=""),"",1) -> 1
D53: 令和9年度 | E53: =IF(G52="","",G52) -> 59 | F53: 令和10年度 | G53: 59 | H53: =IF(ISERROR(ROUND((G53-E53)/E53*1,3))=TRUE,"－",ROUND((G53-E53)/E53*1,3)) -> 0 | I53: =data!I9 -> -0.1 | J53: =data!J9 -> 0.15 | K53: =IF(H53="－","",IF(AND(I53<>"－",H53<I53),"下限値を"&ROUND((I53-H53)*100,1)&"％下回っています。",IF(AND(J53<>"－",H53>J53),"上限値を"&ROUND((H53-J53)*100,1)&"％上回っています。","閾値の範囲内です。"))) -> 閾値の範囲内です。 | M53: =IF(OR(H53="－",AND(I53="－",J53="－")),"",IF(AND(K53<>"チェック対象外",OR(AND(I53<>"－",H53<I53),AND(J53<>"－",H53>J53))),1,"")) | N53: =IF(AND(E53="",G53=""),"",1) -> 1
C54: =C53 -> 0 | D54: 令和10年度 | E54: =IF(G53="","",G53) -> 59 | F54: 令和11年度 | G54: 59 | H54: =IF(ISERROR(ROUND((G54-E54)/E54*1,3))=TRUE,"－",ROUND((G54-E54)/E54*1,3)) -> 0 | I54: =I53 -> -0.1 | J54: =J53 -> 0.15 | K54: =IF(H54="－","",IF(AND(I54<>"－",H54<I54),"下限値を"&ROUND((I54-H54)*100,1)&"％下回っています。",IF(AND(J54<>"－",H54>J54),"上限値を"&ROUND((H54-J54)*100,1)&"％上回っています。","閾値の範囲内です。"))) -> 閾値の範囲内です。 | M54: =IF(OR(H54="－",AND(I54="－",J54="－")),"",IF(AND(K54<>"チェック対象外",OR(AND(I54<>"－",H54<I54),AND(J54<>"－",H54>J54))),1,"")) | N54: =IF(AND(E54="",G54=""),"",1) -> 1
B55: 6 | C55: 介護老人保健施設 | D55: 令和8年度 | E55: 26 | F55: 令和9年度 | G55: 26 | H55: =IF(ISERROR(ROUND((G55-E55)/E55*1,3))=TRUE,"－",ROUND((G55-E55)/E55*1,3)) -> 0 | I55: =I56 -> -0.2 | J55: =J56 -> 0.25 | K55: =IF(H55="－","",IF(AND(I55<>"－",H55<I55),"下限値を"&ROUND((I55-H55)*100,1)&"％下回っています。",IF(AND(J55<>"－",H55>J55),"上限値を"&ROUND((H55-J55)*100,1)&"％上回っています。","閾値の範囲内です。"))) -> 閾値の範囲内です。 | M55: =IF(OR(H55="－",AND(I55="－",J55="－")),"",IF(AND(K55<>"チェック対象外",OR(AND(I55<>"－",H55<I55),AND(J55<>"－",H55>J55))),1,"")) | N55: =IF(AND(E55="",G55=""),"",1) -> 1
D56: 令和9年度 | E56: =IF(G55="","",G55) -> 26 | F56: 令和10年度 | G56: 26 | H56: =IF(ISERROR(ROUND((G56-E56)/E56*1,3))=TRUE,"－",ROUND((G56-E56)/E56*1,3)) -> 0 | I56: =data!I10 -> -0.2 | J56: =data!J10 -> 0.25 | K56: =IF(H56="－","",IF(AND(I56<>"－",H56<I56),"下限値を"&ROUND((I56-H56)*100,1)&"％下回っています。",IF(AND(J56<>"－",H56>J56),"上限値を"&ROUND((H56-J56)*100,1)&"％上回っています。","閾値の範囲内です。"))) -> 閾値の範囲内です。 | M56: =IF(OR(H56="－",AND(I56="－",J56="－")),"",IF(AND(K56<>"チェック対象外",OR(AND(I56<>"－",H56<I56),AND(J56<>"－",H56>J56))),1,"")) | N56: =IF(AND(E56="",G56=""),"",1) -> 1
C57: =C56 -> 0 | D57: 令和10年度 | E57: =IF(G56="","",G56) -> 26 | F57: 令和11年度 | G57: 26 | H57: =IF(ISERROR(ROUND((G57-E57)/E57*1,3))=TRUE,"－",ROUND((G57-E57)/E57*1,3)) -> 0 | I57: =I56 -> -0.2 | J57: =J56 -> 0.25 | K57: =IF(H57="－","",IF(AND(I57<>"－",H57<I57),"下限値を"&ROUND((I57-H57)*100,1)&"％下回っています。",IF(AND(J57<>"－",H57>J57),"上限値を"&ROUND((H57-J57)*100,1)&"％上回っています。","閾値の範囲内です。"))) -> 閾値の範囲内です。 | M57: =IF(OR(H57="－",AND(I57="－",J57="－")),"",IF(AND(K57<>"チェック対象外",OR(AND(I57<>"－",H57<I57),AND(J57<>"－",H57>J57))),1,"")) | N57: =IF(AND(E57="",G57=""),"",1) -> 1
B58: 7 | C58: 介護医療院 | D58: 令和8年度 | E58: 0 | F58: 令和9年度 | G58: 0 | H58: =IF(ISERROR(ROUND((G58-E58)/E58*1,3))=TRUE,"－",ROUND((G58-E58)/E58*1,3)) -> － | I58: =I59 -> -0.65 | J58: =J59 -> 0.8 | K58: =IF(H58="－","",IF(AND(I58<>"－",H58<I58),"下限値を"&ROUND((I58-H58)*100,1)&"％下回っています。",IF(AND(J58<>"－",H58>J58),"上限値を"&ROUND((H58-J58)*100,1)&"％上回っています。","閾値の範囲内です。"))) | N58: =IF(AND(E58="",G58=""),"",1) -> 1
D59: 令和9年度 | E59: =IF(G58="","",G58) -> 0 | F59: 令和10年度 | G59: 0 | H59: =IF(ISERROR(ROUND((G59-E59)/E59*1,3))=TRUE,"－",ROUND((G59-E59)/E59*1,3)) -> － | I59: =data!I11 -> -0.65 | J59: =data!J11 -> 0.8 | K59: =IF(H59="－","",IF(AND(I59<>"－",H59<I59),"下限値を"&ROUND((I59-H59)*100,1)&"％下回っています。",IF(AND(J59<>"－",H59>J59),"上限値を"&ROUND((H59-J59)*100,1)&"％上回っています。","閾値の範囲内です。"))) | N59: =IF(AND(E59="",G59=""),"",1) -> 1
D60: 令和10年度 | E60: =IF(G59="","",G59) -> 0 | F60: 令和11年度 | G60: 0 | H60: =IF(ISERROR(ROUND((G60-E60)/E60*1,3))=TRUE,"－",ROUND((G60-E60)/E60*1,3)) -> － | I60: =I59 -> -0.65 | J60: =J59 -> 0.8 | K60: =IF(H60="－","",IF(AND(I60<>"－",H60<I60),"下限値を"&ROUND((I60-H60)*100,1)&"％下回っています。",IF(AND(J60<>"－",H60>J60),"上限値を"&ROUND((H60-J60)*100,1)&"％上回っています。","閾値の範囲内です。"))) | N60: =IF(AND(E60="",G60=""),"",1) -> 1

Sheet 施策反映 在宅サービス利用者数
A1: 将来推計ワーニングチェック結果詳細
B3: ３．施策反映 在宅サービス利用者数
C5: 本シートでは、以下に示す在宅サービス毎の利用者数の施策反映値について、前年度からの変化率のチェックを行っています(画面イメージはサンプルです)。
C6: 変化率(%)＝(当該年度利用者数－前年度利用者数)÷前年度利用者数×100
B34: ワーニングチェック結果
B35: No. | C35: ワーニング対象指標値 | D35: 利用者数(総数) | H35: 変化率 (チェック対象) | I35: 閾値 | K35: チェック結果
I36: 下限値 | J36: 上限値
B37: 居宅サービス
B38: 1 | C38: 訪問介護 | D38: 令和8年度 | E38: 67 | F38: 令和9年度 | G38: 65 | H38: =IF(ISERROR(ROUND((G38-E38)/E38*1,3))=TRUE,"－",ROUND((G38-E38)/E38*1,3)) -> -0.03 | I38: =I39 -> -0.15 | J38: =J39 -> 0.25 | K38: =IF(H38="－","",IF(H38<I38,"下限値を"&ROUND((I38-H38)*100,1)&"％下回っています。",IF(H38>J38,"上限値を"&ROUND((H38-J38)*100,1)&"％上回っています。","閾値の範囲内です。"))) -> 閾値の範囲内です。 | M38: =IF(OR(H38="－",AND(I38="－",J38="－")),"",IF(OR(H38<I38,H38>J38),1,"")) | N38: =IF(AND(E38="",G38=""),"",1) -> 1
C39: =C38 -> 訪問介護 | D39: 令和9年度 | E39: =IF(G38="","",G38) -> 65 | F39: 令和10年度 | G39: 64 | H39: =IF(ISERROR(ROUND((G39-E39)/E39*1,3))=TRUE,"－",ROUND((G39-E39)/E39*1,3)) -> -0.015 | I39: =data!I12 -> -0.15 | J39: =data!J12 -> 0.25 | K39: =IF(H39="－","",IF(H39<I39,"下限値を"&ROUND((I39-H39)*100,1)&"％下回っています。",IF(H39>J39,"上限値を"&ROUND((H39-J39)*100,1)&"％上回っています。","閾値の範囲内です。"))) -> 閾値の範囲内です。 | M39: =IF(OR(H39="－",AND(I39="－",J39="－")),"",IF(OR(H39<I39,H39>J39),1,"")) | N39: =IF(AND(E39="",G39=""),"",1) -> 1
C40: =C39 -> 訪問介護 | D40: 令和10年度 | E40: =IF(G39="","",G39) -> 64 | F40: 令和11年度 | G40: 63 | H40: =IF(ISERROR(ROUND((G40-E40)/E40*1,3))=TRUE,"－",ROUND((G40-E40)/E40*1,3)) -> -0.016 | I40: =I39 -> -0.15 | J40: =J39 -> 0.25 | K40: =IF(H40="－","",IF(H40<I40,"下限値を"&ROUND((I40-H40)*100,1)&"％下回っています。",IF(H40>J40,"上限値を"&ROUND((H40-J40)*100,1)&"％上回っています。","閾値の範囲内です。"))) -> 閾値の範囲内です。 | M40: =IF(OR(H40="－",AND(I40="－",J40="－")),"",IF(OR(H40<I40,H40>J40),1,"")) | N40: =IF(AND(E40="",G40=""),"",1) -> 1
B41: =B38+1 -> 2 | C41: 訪問入浴介護 | D41: 令和8年度 | E41: 5 | F41: 令和9年度 | G41: 5 | H41: =IF(ISERROR(ROUND((G41-E41)/E41*1,3))=TRUE,"－",ROUND((G41-E41)/E41*1,3)) -> 0 | I41: =I42 -> -0.6 | J41: =J42 -> 0.6 | K41: =IF(H41="－","",IF(H41<I41,"下限値を"&ROUND((I41-H41)*100,1)&"％下回っています。",IF(H41>J41,"上限値を"&ROUND((H41-J41)*100,1)&"％上回っています。","閾値の範囲内です。"))) -> 閾値の範囲内です。 | M41: =IF(OR(H41="－",AND(I41="－",J41="－")),"",IF(OR(H41<I41,H41>J41),1,"")) | N41: =IF(AND(E41="",G41=""),"",1) -> 1
C42: =C41 -> 訪問入浴介護 | D42: 令和9年度 | E42: =IF(G41="","",G41) -> 5 | F42: 令和10年度 | G42: 5 | H42: =IF(ISERROR(ROUND((G42-E42)/E42*1,3))=TRUE,"－",ROUND((G42-E42)/E42*1,3)) -> 0 | I42: =data!I13 -> -0.6 | J42: =data!J13 -> 0.6 | K42: =IF(H42="－","",IF(H42<I42,"下限値を"&ROUND((I42-H42)*100,1)&"％下回っています。",IF(H42>J42,"上限値を"&ROUND((H42-J42)*100,1)&"％上回っています。","閾値の範囲内です。"))) -> 閾値の範囲内です。 | M42: =IF(OR(H42="－",AND(I42="－",J42="－")),"",IF(OR(H42<I42,H42>J42),1,"")) | N42: =IF(AND(E42="",G42=""),"",1) -> 1
C43: =C42 -> 訪問入浴介護 | D43: 令和10年度 | E43: =IF(G42="","",G42) -> 5 | F43: 令和11年度 | G43: 5 | H43: =IF(ISERROR(ROUND((G43-E43)/E43*1,3))=TRUE,"－",ROUND((G43-E43)/E43*1,3)) -> 0 | I43: =I42 -> -0.6 | J43: =J42 -> 0.6 | K43: =IF(H43="－","",IF(H43<I43,"下限値を"&ROUND((I43-H43)*100,1)&"％下回っています。",IF(H43>J43,"上限値を"&ROUND((H43-J43)*100,1)&"％上回っています。","閾値の範囲内です。"))) -> 閾値の範囲内です。 | M43: =IF(OR(H43="－",AND(I43="－",J43="－")),"",IF(OR(H43<I43,H43>J43),1,"")) | N43: =IF(AND(E43="",G43=""),"",1) -> 1
B44: =B41+1 -> 3 | C44: 訪問看護 | D44: 令和8年度 | E44: 52 | F44: 令和9年度 | G44: 56 | H44: =IF(ISERROR(ROUND((G44-E44)/E44*1,3))=TRUE,"－",ROUND((G44-E44)/E44*1,3)) -> 0.077 | I44: =I45 -> -0.15 | J44: =J45 -> 0.35 | K44: =IF(H44="－","",IF(H44<I44,"下限値を"&ROUND((I44-H44)*100,1)&"％下回っています。",IF(H44>J44,"上限値を"&ROUND((H44-J44)*100,1)&"％上回っています。","閾値の範囲内です。"))) -> 閾値の範囲内です。 | M44: =IF(OR(H44="－",AND(I44="－",J44="－")),"",IF(OR(H44<I44,H44>J44),1,"")) | N44: =IF(AND(E44="",G44=""),"",1) -> 1
C45: =C44 -> 訪問看護 | D45: 令和9年度 | E45: =IF(G44="","",G44) -> 56 | F45: 令和10年度 | G45: 53 | H45: =IF(ISERROR(ROUND((G45-E45)/E45*1,3))=TRUE,"－",ROUND((G45-E45)/E45*1,3)) -> -0.054 | I45: =data!I14 -> -0.15 | J45: =data!J14 -> 0.35 | K45: =IF(H45="－","",IF(H45<I45,"下限値を"&ROUND((I45-H45)*100,1)&"％下回っています。",IF(H45>J45,"上限値を"&ROUND((H45-J45)*100,1)&"％上回っています。","閾値の範囲内です。"))) -> 閾値の範囲内です。 | M45: =IF(OR(H45="－",AND(I45="－",J45="－")),"",IF(OR(H45<I45,H45>J45),1,"")) | N45: =IF(AND(E45="",G45=""),"",1) -> 1
C46: =C45 -> 訪問看護 | D46: 令和10年度 | E46: =IF(G45="","",G45) -> 53 | F46: 令和11年度 | G46: 54 | H46: =IF(ISERROR(ROUND((G46-E46)/E46*1,3))=TRUE,"－",ROUND((G46-E46)/E46*1,3)) -> 0.019 | I46: =I45 -> -0.15 | J46: =J45 -> 0.35 | K46: =IF(H46="－","",IF(H46<I46,"下限値を"&ROUND((I46-H46)*100,1)&"％下回っています。",IF(H46>J46,"上限値を"&ROUND((H46-J46)*100,1)&"％上回っています。","閾値の範囲内です。"))) -> 閾値の範囲内です。 | M46: =IF(OR(H46="－",AND(I46="－",J46="－")),"",IF(OR(H46<I46,H46>J46),1,"")) | N46: =IF(AND(E46="",G46=""),"",1) -> 1
B47: =B44+1 -> 4 | C47: 訪問リハビリテーション | D47: 令和8年度 | E47: 0 | F47: 令和9年度 | G47: 0 | H47: =IF(ISERROR(ROUND((G47-E47)/E47*1,3))=TRUE,"－",ROUND((G47-E47)/E47*1,3)) -> － | I47: =I48 -> -0.4 | J47: =J48 -> 0.55 | K47: =IF(H47="－","",IF(H47<I47,"下限値を"&ROUND((I47-H47)*100,1)&"％下回っています。",IF(H47>J47,"上限値を"&ROUND((H47-J47)*100,1)&"％上回っています。","閾値の範囲内です。"))) | M47: =IF(OR(H47="－",AND(I47="－",J47="－")),"",IF(OR(H47<I47,H47>J47),1,"")) | N47: =IF(AND(E47="",G47=""),"",1) -> 1
C48: =C47 -> 訪問リハビリテーション | D48: 令和9年度 | E48: =IF(G47="","",G47) -> 0 | F48: 令和10年度 | G48: 0 | H48: =IF(ISERROR(ROUND((G48-E48)/E48*1,3))=TRUE,"－",ROUND((G48-E48)/E48*1,3)) -> － | I48: =data!I15 -> -0.4 | J48: =data!J15 -> 0.55 | K48: =IF(H48="－","",IF(H48<I48,"下限値を"&ROUND((I48-H48)*100,1)&"％下回っています。",IF(H48>J48,"上限値を"&ROUND((H48-J48)*100,1)&"％上回っています。","閾値の範囲内です。"))) | M48: =IF(OR(H48="－",AND(I48="－",J48="－")),"",IF(OR(H48<I48,H48>J48),1,"")) | N48: =IF(AND(E48="",G48=""),"",1) -> 1
C49: =C48 -> 訪問リハビリテーション | D49: 令和10年度 | E49: =IF(G48="","",G48) -> 0 | F49: 令和11年度 | G49: 0 | H49: =IF(ISERROR(ROUND((G49-E49)/E49*1,3))=TRUE,"－",ROUND((G49-E49)/E49*1,3)) -> － | I49: =I48 -> -0.4 | J49: =J48 -> 0.55 | K49: =IF(H49="－","",IF(H49<I49,"下限値を"&ROUND((I49-H49)*100,1)&"％下回っています。",IF(H49>J49,"上限値を"&ROUND((H49-J49)*100,1)&"％上回っています。","閾値の範囲内です。"))) | M49: =IF(OR(H49="－",AND(I49="－",J49="－")),"",IF(OR(H49<I49,H49>J49),1,"")) | N49: =IF(AND(E49="",G49=""),"",1) -> 1
B50: =B47+1 -> 5 | C50: 居宅療養管理指導 | D50: 令和8年度 | E50: 9 | F50: 令和9年度 | G50: 9 | H50: =IF(ISERROR(ROUND((G50-E50)/E50*1,3))=TRUE,"－",ROUND((G50-E50)/E50*1,3)) -> 0 | I50: =I51 -> -0.15 | J50: =J51 -> 0.35 | K50: =IF(H50="－","",IF(H50<I50,"下限値を"&ROUND((I50-H50)*100,1)&"％下回っています。",IF(H50>J50,"上限値を"&ROUND((H50-J50)*100,1)&"％上回っています。","閾値の範囲内です。"))) -> 閾値の範囲内です。 | M50: =IF(OR(H50="－",AND(I50="－",J50="－")),"",IF(OR(H50<I50,H50>J50),1,"")) | N50: =IF(AND(E50="",G50=""),"",1) -> 1
C51: =C50 -> 居宅療養管理指導 | D51: 令和9年度 | E51: =IF(G50="","",G50) -> 9 | F51: 令和10年度 | G51: 9 | H51: =IF(ISERROR(ROUND((G51-E51)/E51*1,3))=TRUE,"－",ROUND((G51-E51)/E51*1,3)) -> 0 | I51: =data!I16 -> -0.15 | J51: =data!J16 -> 0.35 | K51: =IF(H51="－","",IF(H51<I51,"下限値を"&ROUND((I51-H51)*100,1)&"％下回っています。",IF(H51>J51,"上限値を"&ROUND((H51-J51)*100,1)&"％上回っています。","閾値の範囲内です。"))) -> 閾値の範囲内です。 | M51: =IF(OR(H51="－",AND(I51="－",J51="－")),"",IF(OR(H51<I51,H51>J51),1,"")) | N51: =IF(AND(E51="",G51=""),"",1) -> 1
C52: =C51 -> 居宅療養管理指導 | D52: 令和10年度 | E52: =IF(G51="","",G51) -> 9 | F52: 令和11年度 | G52: 9 | H52: =IF(ISERROR(ROUND((G52-E52)/E52*1,3))=TRUE,"－",ROUND((G52-E52)/E52*1,3)) -> 0 | I52: =I51 -> -0.15 | J52: =J51 -> 0.35 | K52: =IF(H52="－","",IF(H52<I52,"下限値を"&ROUND((I52-H52)*100,1)&"％下回っています。",IF(H52>J52,"上限値を"&ROUND((H52-J52)*100,1)&"％上回っています。","閾値の範囲内です。"))) -> 閾値の範囲内です。 | M52: =IF(OR(H52="－",AND(I52="－",J52="－")),"",IF(OR(H52<I52,H52>J52),1,"")) | N52: =IF(AND(E52="",G52=""),"",1) -> 1
B53: =B50+1 -> 6 | C53: 通所介護 | D53: 令和8年度 | E53: 169 | F53: 令和9年度 | G53: 168 | H53: =IF(ISERROR(ROUND((G53-E53)/E53*1,3))=TRUE,"－",ROUND((G53-E53)/E53*1,3)) -> -0.006 | I53: =I54 -> -0.15 | J53: =J54 -> 0.2 | K53: =IF(H53="－","",IF(H53<I53,"下限値を"&ROUND((I53-H53)*100,1)&"％下回っています。",IF(H53>J53,"上限値を"&ROUND((H53-J53)*100,1)&"％上回っています。","閾値の範囲内です。"))) -> 閾値の範囲内です。 | M53: =IF(OR(H53="－",AND(I53="－",J53="－")),"",IF(OR(H53<I53,H53>J53),1,"")) | N53: =IF(AND(E53="",G53=""),"",1) -> 1
C54: =C53 -> 通所介護 | D54: 令和9年度 | E54: =IF(G53="","",G53) -> 168 | F54: 令和10年度 | G54: 164 | H54: =IF(ISERROR(ROUND((G54-E54)/E54*1,3))=TRUE,"－",ROUND((G54-E54)/E54*1,3)) -> -0.024 | I54: =data!I17 -> -0.15 | J54: =data!J17 -> 0.2 | K54: =IF(H54="－","",IF(H54<I54,"下限値を"&ROUND((I54-H54)*100,1)&"％下回っています。",IF(H54>J54,"上限値を"&ROUND((H54-J54)*100,1)&"％上回っています。","閾値の範囲内です。"))) -> 閾値の範囲内です。 | M54: =IF(OR(H54="－",AND(I54="－",J54="－")),"",IF(OR(H54<I54,H54>J54),1,"")) | N54: =IF(AND(E54="",G54=""),"",1) -> 1
C55: =C54 -> 通所介護 | D55: 令和10年度 | E55: =IF(G54="","",G54) -> 164 | F55: 令和11年度 | G55: 162 | H55: =IF(ISERROR(ROUND((G55-E55)/E55*1,3))=TRUE,"－",ROUND((G55-E55)/E55*1,3)) -> -0.012 | I55: =I54 -> -0.15 | J55: =J54 -> 0.2 | K55: =IF(H55="－","",IF(H55<I55,"下限値を"&ROUND((I55-H55)*100,1)&"％下回っています。",IF(H55>J55,"上限値を"&ROUND((H55-J55)*100,1)&"％上回っています。","閾値の範囲内です。"))) -> 閾値の範囲内です。 | M55: =IF(OR(H55="－",AND(I55="－",J55="－")),"",IF(OR(H55<I55,H55>J55),1,"")) | N55: =IF(AND(E55="",G55=""),"",1) -> 1
B56: =B53+1 -> 7 | C56: 通所リハビリテーション | D56: 令和8年度 | E56: 66 | F56: 令和9年度 | G56: 71 | H56: =IF(ISERROR(ROUND((G56-E56)/E56*1,3))=TRUE,"－",ROUND((G56-E56)/E56*1,3)) -> 0.076 | I56: =I57 -> -0.2 | J56: =J57 -> 0.25 | K56: =IF(H56="－","",IF(H56<I56,"下限値を"&ROUND((I56-H56)*100,1)&"％下回っています。",IF(H56>J56,"上限値を"&ROUND((H56-J56)*100,1)&"％上回っています。","閾値の範囲内です。"))) -> 閾値の範囲内です。 | M56: =IF(OR(H56="－",AND(I56="－",J56="－")),"",IF(OR(H56<I56,H56>J56),1,"")) | N56: =IF(AND(E56="",G56=""),"",1) -> 1
C57: =C56 -> 通所リハビリテーション | D57: 令和9年度 | E57: =IF(G56="","",G56) -> 71 | F57: 令和10年度 | G57: 72 | H57: =IF(ISERROR(ROUND((G57-E57)/E57*1,3))=TRUE,"－",ROUND((G57-E57)/E57*1,3)) -> 0.014 | I57: =data!I18 -> -0.2 | J57: =data!J18 -> 0.25 | K57: =IF(H57="－","",IF(H57<I57,"下限値を"&ROUND((I57-H57)*100,1)&"％下回っています。",IF(H57>J57,"上限値を"&ROUND((H57-J57)*100,1)&"％上回っています。","閾値の範囲内です。"))) -> 閾値の範囲内です。 | M57: =IF(OR(H57="－",AND(I57="－",J57="－")),"",IF(OR(H57<I57,H57>J57),1,"")) | N57: =IF(AND(E57="",G57=""),"",1) -> 1
C58: =C57 -> 通所リハビリテーション | D58: 令和10年度 | E58: =IF(G57="","",G57) -> 72 | F58: 令和11年度 | G58: 72 | H58: =IF(ISERROR(ROUND((G58-E58)/E58*1,3))=TRUE,"－",ROUND((G58-E58)/E58*1,3)) -> 0 | I58: =I57 -> -0.2 | J58: =J57 -> 0.25 | K58: =IF(H58="－","",IF(H58<I58,"下限値を"&ROUND((I58-H58)*100,1)&"％下回っています。",IF(H58>J58,"上限値を"&ROUND((H58-J58)*100,1)&"％上回っています。","閾値の範囲内です。"))) -> 閾値の範囲内です。 | M58: =IF(OR(H58="－",AND(I58="－",J58="－")),"",IF(OR(H58<I58,H58>J58),1,"")) | N58: =IF(AND(E58="",G58=""),"",1) -> 1
B59: =B56+1 -> 8 | C59: 短期入所生活介護 | D59: 令和8年度 | E59: 60 | F59: 令和9年度 | G59: 61 | H59: =IF(ISERROR(ROUND((G59-E59)/E59*1,3))=TRUE,"－",ROUND((G59-E59)/E59*1,3)) -> 0.017 | I59: =I60 -> -0.25 | J59: =J60 -> 0.3 | K59: =IF(H59="－","",IF(H59<I59,"下限値を"&ROUND((I59-H59)*100,1)&"％下回っています。",IF(H59>J59,"上限値を"&ROUND((H59-J59)*100,1)&"％上回っています。","閾値の範囲内です。"))) -> 閾値の範囲内です。 | M59: =IF(OR(H59="－",AND(I59="－",J59="－")),"",IF(OR(H59<I59,H59>J59),1,"")) | N59: =IF(AND(E59="",G59=""),"",1) -> 1
C60: =C59 -> 短期入所生活介護 | D60: 令和9年度 | E60: =IF(G59="","",G59) -> 61 | F60: 令和10年度 | G60: 60 | H60: =IF(ISERROR(ROUND((G60-E60)/E60*1,3))=TRUE,"－",ROUND((G60-E60)/E60*1,3)) -> -0.016 | I60: =data!I19 -> -0.25 | J60: =data!J19 -> 0.3 | K60: =IF(H60="－","",IF(H60<I60,"下限値を"&ROUND((I60-H60)*100,1)&"％下回っています。",IF(H60>J60,"上限値を"&ROUND((H60-J60)*100,1)&"％上回っています。","閾値の範囲内です。"))) -> 閾値の範囲内です。 | M60: =IF(OR(H60="－",AND(I60="－",J60="－")),"",IF(OR(H60<I60,H60>J60),1,"")) | N60: =IF(AND(E60="",G60=""),"",1) -> 1
C61: =C60 -> 短期入所生活介護 | D61: 令和10年度 | E61: =IF(G60="","",G60) -> 60 | F61: 令和11年度 | G61: 60 | H61: =IF(ISERROR(ROUND((G61-E61)/E61*1,3))=TRUE,"－",ROUND((G61-E61)/E61*1,3)) -> 0 | I61: =I60 -> -0.25 | J61: =J60 -> 0.3 | K61: =IF(H61="－","",IF(H61<I61,"下限値を"&ROUND((I61-H61)*100,1)&"％下回っています。",IF(H61>J61,"上限値を"&ROUND((H61-J61)*100,1)&"％上回っています。","閾値の範囲内です。"))) -> 閾値の範囲内です。 | M61: =IF(OR(H61="－",AND(I61="－",J61="－")),"",IF(OR(H61<I61,H61>J61),1,"")) | N61: =IF(AND(E61="",G61=""),"",1) -> 1
B62: =B59+1 -> 9 | C62: 短期入所療養介護（老健） | D62: 令和8年度 | E62: 2 | F62: 令和9年度 | G62: 2 | H62: =IF(ISERROR(ROUND((G62-E62)/E62*1,3))=TRUE,"－",ROUND((G62-E62)/E62*1,3)) -> 0 | I62: =I63 -> -0.7 | J62: =J63 -> 0.75 | K62: =IF(H62="－","",IF(H62<I62,"下限値を"&ROUND((I62-H62)*100,1)&"％下回っています。",IF(H62>J62,"上限値を"&ROUND((H62-J62)*100,1)&"％上回っています。","閾値の範囲内です。"))) -> 閾値の範囲内です。 | M62: =IF(OR(H62="－",AND(I62="－",J62="－")),"",IF(OR(H62<I62,H62>J62),1,"")) | N62: =IF(AND(E62="",G62=""),"",1) -> 1
C63: =C62 -> 短期入所療養介護（老健） | D63: 令和9年度 | E63: =IF(G62="","",G62) -> 2 | F63: 令和10年度 | G63: 2 | H63: =IF(ISERROR(ROUND((G63-E63)/E63*1,3))=TRUE,"－",ROUND((G63-E63)/E63*1,3)) -> 0 | I63: =data!I20 -> -0.7 | J63: =data!J20 -> 0.75 | K63: =IF(H63="－","",IF(H63<I63,"下限値を"&ROUND((I63-H63)*100,1)&"％下回っています。",IF(H63>J63,"上限値を"&ROUND((H63-J63)*100,1)&"％上回っています。","閾値の範囲内です。"))) -> 閾値の範囲内です。 | M63: =IF(OR(H63="－",AND(I63="－",J63="－")),"",IF(OR(H63<I63,H63>J63),1,"")) | N63: =IF(AND(E63="",G63=""),"",1) -> 1
C64: =C63 -> 短期入所療養介護（老健） | D64: 令和10年度 | E64: =IF(G63="","",G63) -> 2 | F64: 令和11年度 | G64: 2 | H64: =IF(ISERROR(ROUND((G64-E64)/E64*1,3))=TRUE,"－",ROUND((G64-E64)/E64*1,3)) -> 0 | I64: =I63 -> -0.7 | J64: =J63 -> 0.75 | K64: =IF(H64="－","",IF(H64<I64,"下限値を"&ROUND((I64-H64)*100,1)&"％下回っています。",IF(H64>J64,"上限値を"&ROUND((H64-J64)*100,1)&"％上回っています。","閾値の範囲内です。"))) -> 閾値の範囲内です。 | M64: =IF(OR(H64="－",AND(I64="－",J64="－")),"",IF(OR(H64<I64,H64>J64),1,"")) | N64: =IF(AND(E64="",G64=""),"",1) -> 1
B65: =B62+1 -> 10 | C65: 短期入所療養介護（病院等） | D65: 令和8年度 | E65: 0 | F65: 令和9年度 | G65: 0 | H65: =IF(ISERROR(ROUND((G65-E65)/E65*1,3))=TRUE,"－",ROUND((G65-E65)/E65*1,3)) -> － | I65: =I66 -> -2.9 | J65: =J66 -> 1.95 | K65: =IF(H65="－","",IF(H65<I65,"下限値を"&ROUND((I65-H65)*100,1)&"％下回っています。",IF(H65>J65,"上限値を"&ROUND((H65-J65)*100,1)&"％上回っています。","閾値の範囲内です。"))) | M65: =IF(OR(H65="－",AND(I65="－",J65="－")),"",IF(OR(H65<I65,H65>J65),1,"")) | N65: =IF(AND(E65="",G65=""),"",1) -> 1
C66: =C65 -> 短期入所療養介護（病院等） | D66: 令和9年度 | E66: =IF(G65="","",G65) -> 0 | F66: 令和10年度 | G66: 0 | H66: =IF(ISERROR(ROUND((G66-E66)/E66*1,3))=TRUE,"－",ROUND((G66-E66)/E66*1,3)) -> － | I66: =data!I21 -> -2.9 | J66: =data!J21 -> 1.95 | K66: =IF(H66="－","",IF(H66<I66,"下限値を"&ROUND((I66-H66)*100,1)&"％下回っています。",IF(H66>J66,"上限値を"&ROUND((H66-J66)*100,1)&"％上回っています。","閾値の範囲内です。"))) | M66: =IF(OR(H66="－",AND(I66="－",J66="－")),"",IF(OR(H66<I66,H66>J66),1,"")) | N66: =IF(AND(E66="",G66=""),"",1) -> 1
C67: =C66 -> 短期入所療養介護（病院等） | D67: 令和10年度 | E67: =IF(G66="","",G66) -> 0 | F67: 令和11年度 | G67: 0 | H67: =IF(ISERROR(ROUND((G67-E67)/E67*1,3))=TRUE,"－",ROUND((G67-E67)/E67*1,3)) -> － | I67: =I66 -> -2.9 | J67: =J66 -> 1.95 | K67: =IF(H67="－","",IF(H67<I67,"下限値を"&ROUND((I67-H67)*100,1)&"％下回っています。",IF(H67>J67,"上限値を"&ROUND((H67-J67)*100,1)&"％上回っています。","閾値の範囲内です。"))) | M67: =IF(OR(H67="－",AND(I67="－",J67="－")),"",IF(OR(H67<I67,H67>J67),1,"")) | N67: =IF(AND(E67="",G67=""),"",1) -> 1
B68: =B65+1 -> 11 | C68: 短期入所療養介護（介護医療院） | D68: 令和8年度 | E68: 0 | F68: 令和9年度 | G68: 0 | H68: =IF(ISERROR(ROUND((G68-E68)/E68*1,3))=TRUE,"－",ROUND((G68-E68)/E68*1,3)) -> － | I68: =I69 -> -3.35 | J68: =J69 -> 2.8 | K68: =IF(H68="－","",IF(H68<I68,"下限値を"&ROUND((I68-H68)*100,1)&"％下回っています。",IF(H68>J68,"上限値を"&ROUND((H68-J68)*100,1)&"％上回っています。","閾値の範囲内です。"))) | M68: =IF(OR(H68="－",AND(I68="－",J68="－")),"",IF(OR(H68<I68,H68>J68),1,"")) | N68: =IF(AND(E68="",G68=""),"",1) -> 1
C69: =C68 -> 短期入所療養介護（介護医療院） | D69: 令和9年度 | E69: =IF(G68="","",G68) -> 0 | F69: 令和10年度 | G69: 0 | H69: =IF(ISERROR(ROUND((G69-E69)/E69*1,3))=TRUE,"－",ROUND((G69-E69)/E69*1,3)) -> － | I69: =data!I22 -> -3.35 | J69: =data!J22 -> 2.8 | K69: =IF(H69="－","",IF(H69<I69,"下限値を"&ROUND((I69-H69)*100,1)&"％下回っています。",IF(H69>J69,"上限値を"&ROUND((H69-J69)*100,1)&"％上回っています。","閾値の範囲内です。"))) | M69: =IF(OR(H69="－",AND(I69="－",J69="－")),"",IF(OR(H69<I69,H69>J69),1,"")) | N69: =IF(AND(E69="",G69=""),"",1) -> 1
...

Sheet (参考)在宅・居住系・施設1人1月あたり給付費
A1: 将来推計ワーニングチェック結果詳細
B3: （参考）在宅サービス／居住系サービス／施設サービス別の1人1月あたり給付費
B5: No. | C5: ワーニング対象指標値 | D5: 年度／要介護(支援) | F5: 給付費 | G5: 利用者数 | H5: 給付費÷利用者数÷12 (チェック対象) | I5: 閾値 | K5: チェック結果
I6: 下限値 | J6: 上限値
B7: 1 | C7: 在宅サービス | D7: 令和9年度 | E7: 要支援1 | F7: =IF('(参考)1人(1回(日))1月あたり給付費(在宅)'!$O$517="","",O7) -> 9737340 | G7: =IF('(参考)1人(1回(日))1月あたり給付費(在宅)'!$O$517="","",P7) -> 78 | H7: =IF(ISERROR((F7/G7)/12)=TRUE,"－",(F7/G7)/12) -> 10403.141 | I7: =data!I34 -> 5290 | J7: =data!J34 -> 14725 | K7: =IF(H7="－","",IF(H7<I7,"下限値を\"&TEXT(ROUND(I7-H7,0),"#,##0")&"下回っています。",IF(H7>J7,"上限値を\"&TEXT(ROUND(H7-J7,0),"#,##0")&"上回っています。","閾値の範囲内です。"))) -> 閾値の範囲内です。 | M7: =IF(OR(H7="－",AND(I7="－",J7="－")),"",IF(OR(H7<I7,H7>J7),1,"")) | N7: =IF(AND(F7="",G7=""),"",1) -> 1 | O7: =SUM('(参考)1人(1回(日))1月あたり給付費(在宅)'!F25,'(参考)1人(1回(日))1月あたり給付費(在宅)'!F49,'(参考)1人(1回(日))1月あたり給付費(在宅)'!F73,'(参考)1人(1回(日))1月あたり給付費(在宅)'!F97,'(参考)1人(1回(日))1月あたり給付費(在宅)'!F139,'(参考)1人(1回(日))1月あたり給付費(在宅)'!F163,'(参考)1人(1回(日))1月あたり給付費(在宅)'!F187,'(参考)1人(1回(日))1月あたり給付費(在宅)'!F211,'(参考)1人(1回(日))1月あたり給付費(在宅)'!F259,'(参考)1人(1回(日))1月あたり給付費(在宅)'!F283,'(参考)1人(1回(日))1月あたり給付費(在宅)'!F307,'(参考)1人(1回(日))1月あたり給付費(在宅)'!F331,'(参考)1人(1回(日))1月あたり給付費(在宅)'!F433,'(参考)1人(1回(日))1月あたり給付費(在宅)'!F457) -> 9737340 | P7: =SUM('(参考)1人(1回(日))1月あたり給付費(在宅)'!G25,'(参考)1人(1回(日))1月あたり給付費(在宅)'!G49,'(参考)1人(1回(日))1月あたり給付費(在宅)'!G73,'(参考)1人(1回(日))1月あたり給付費(在宅)'!G97,'(参考)1人(1回(日))1月あたり給付費(在宅)'!G139,'(参考)1人(1回(日))1月あたり給付費(在宅)'!G163,'(参考)1人(1回(日))1月あたり給付費(在宅)'!G187,'(参考)1人(1回(日))1月あたり給付費(在宅)'!G211,'(参考)1人(1回(日))1月あたり給付費(在宅)'!G259,'(参考)1人(1回(日))1月あたり給付費(在宅)'!G283,'(参考)1人(1回(日))1月あたり給付費(在宅)'!G307,'(参考)1人(1回(日))1月あたり給付費(在宅)'!G331,'(参考)1人(1回(日))1月あたり給付費(在宅)'!G433,'(参考)1人(1回(日))1月あたり給付費(在宅)'!G457) -> 78
C8: =C7 -> 在宅サービス | E8: 要支援2 | F8: =IF('(参考)1人(1回(日))1月あたり給付費(在宅)'!$O$517="","",O8) -> 27885607 | G8: =IF('(参考)1人(1回(日))1月あたり給付費(在宅)'!$O$517="","",P8) -> 146 | H8: =IF(ISERROR((F8/G8)/12)=TRUE,"－",(F8/G8)/12) -> 15916.442 | I8: =data!I35 -> 5555 | J8: =data!J35 -> 20285 | K8: =IF(H8="－","",IF(H8<I8,"下限値を\"&TEXT(ROUND(I8-H8,0),"#,##0")&"下回っています。",IF(H8>J8,"上限値を\"&TEXT(ROUND(H8-J8,0),"#,##0")&"上回っています。","閾値の範囲内です。"))) -> 閾値の範囲内です。 | M8: =IF(OR(H8="－",AND(I8="－",J8="－")),"",IF(OR(H8<I8,H8>J8),1,"")) | N8: =IF(AND(F8="",G8=""),"",1) -> 1 | O8: =SUM('(参考)1人(1回(日))1月あたり給付費(在宅)'!F26,'(参考)1人(1回(日))1月あたり給付費(在宅)'!F50,'(参考)1人(1回(日))1月あたり給付費(在宅)'!F74,'(参考)1人(1回(日))1月あたり給付費(在宅)'!F98,'(参考)1人(1回(日))1月あたり給付費(在宅)'!F140,'(参考)1人(1回(日))1月あたり給付費(在宅)'!F164,'(参考)1人(1回(日))1月あたり給付費(在宅)'!F188,'(参考)1人(1回(日))1月あたり給付費(在宅)'!F212,'(参考)1人(1回(日))1月あたり給付費(在宅)'!F260,'(参考)1人(1回(日))1月あたり給付費(在宅)'!F284,'(参考)1人(1回(日))1月あたり給付費(在宅)'!F308,'(参考)1人(1回(日))1月あたり給付費(在宅)'!F332,'(参考)1人(1回(日))1月あたり給付費(在宅)'!F434,'(参考)1人(1回(日))1月あたり給付費(在宅)'!F458) -> 27885607 | P8: =SUM('(参考)1人(1回(日))1月あたり給付費(在宅)'!G26,'(参考)1人(1回(日))1月あたり給付費(在宅)'!G50,'(参考)1人(1回(日))1月あたり給付費(在宅)'!G74,'(参考)1人(1回(日))1月あたり給付費(在宅)'!G98,'(参考)1人(1回(日))1月あたり給付費(在宅)'!G140,'(参考)1人(1回(日))1月あたり給付費(在宅)'!G164,'(参考)1人(1回(日))1月あたり給付費(在宅)'!G188,'(参考)1人(1回(日))1月あたり給付費(在宅)'!G212,'(参考)1人(1回(日))1月あたり給付費(在宅)'!G260,'(参考)1人(1回(日))1月あたり給付費(在宅)'!G284,'(参考)1人(1回(日))1月あたり給付費(在宅)'!G308,'(参考)1人(1回(日))1月あたり給付費(在宅)'!G332,'(参考)1人(1回(日))1月あたり給付費(在宅)'!G434,'(参考)1人(1回(日))1月あたり給付費(在宅)'!G458) -> 146
C9: =C8 -> 在宅サービス | E9: 要介護1 | F9: =IF('(参考)1人(1回(日))1月あたり給付費(在宅)'!$O$517="","",O9) -> 98526185 | G9: =IF('(参考)1人(1回(日))1月あたり給付費(在宅)'!$O$517="","",P9) -> 267 | H9: =IF(ISERROR((F9/G9)/12)=TRUE,"－",(F9/G9)/12) -> 30750.994 | I9: =data!I36 -> 19435 | J9: =data!J36 -> 43955 | K9: =IF(H9="－","",IF(H9<I9,"下限値を\"&TEXT(ROUND(I9-H9,0),"#,##0")&"下回っています。",IF(H9>J9,"上限値を\"&TEXT(ROUND(H9-J9,0),"#,##0")&"上回っています。","閾値の範囲内です。"))) -> 閾値の範囲内です。 | M9: =IF(OR(H9="－",AND(I9="－",J9="－")),"",IF(OR(H9<I9,H9>J9),1,"")) | N9: =IF(AND(F9="",G9=""),"",1) -> 1 | O9: =SUM('(参考)1人(1回(日))1月あたり給付費(在宅)'!F7,'(参考)1人(1回(日))1月あたり給付費(在宅)'!F27,'(参考)1人(1回(日))1月あたり給付費(在宅)'!F51,'(参考)1人(1回(日))1月あたり給付費(在宅)'!F75,'(参考)1人(1回(日))1月あたり給付費(在宅)'!F99,'(参考)1人(1回(日))1月あたり給付費(在宅)'!F121,'(参考)1人(1回(日))1月あたり給付費(在宅)'!F141,'(参考)1人(1回(日))1月あたり給付費(在宅)'!F165,'(参考)1人(1回(日))1月あたり給付費(在宅)'!F189,'(参考)1人(1回(日))1月あたり給付費(在宅)'!F213,'(参考)1人(1回(日))1月あたり給付費(在宅)'!F261,'(参考)1人(1回(日))1月あたり給付費(在宅)'!F285,'(参考)1人(1回(日))1月あたり給付費(在宅)'!F309,'(参考)1人(1回(日))1月あたり給付費(在宅)'!F333,'(参考)1人(1回(日))1月あたり給付費(在宅)'!F379,'(参考)1人(1回(日))1月あたり給付費(在宅)'!F397,'(参考)1人(1回(日))1月あたり給付費(在宅)'!F435,'(参考)1人(1回(日))1月あたり給付費(在宅)'!F459,'(参考)1人(1回(日))1月あたり給付費(在宅)'!F481,'(参考)1人(1回(日))1月あたり給付費(在宅)'!F415) -> 98526185 | P9: =SUM('(参考)1人(1回(日))1月あたり給付費(在宅)'!G7,'(参考)1人(1回(日))1月あたり給付費(在宅)'!G27,'(参考)1人(1回(日))1月あたり給付費(在宅)'!G51,'(参考)1人(1回(日))1月あたり給付費(在宅)'!G75,'(参考)1人(1回(日))1月あたり給付費(在宅)'!G99,'(参考)1人(1回(日))1月あたり給付費(在宅)'!G121,'(参考)1人(1回(日))1月あたり給付費(在宅)'!G141,'(参考)1人(1回(日))1月あたり給付費(在宅)'!G165,'(参考)1人(1回(日))1月あたり給付費(在宅)'!G189,'(参考)1人(1回(日))1月あたり給付費(在宅)'!G213,'(参考)1人(1回(日))1月あたり給付費(在宅)'!G261,'(参考)1人(1回(日))1月あたり給付費(在宅)'!G285,'(参考)1人(1回(日))1月あたり給付費(在宅)'!G309,'(参考)1人(1回(日))1月あたり給付費(在宅)'!G333,'(参考)1人(1回(日))1月あたり給付費(在宅)'!G379,'(参考)1人(1回(日))1月あたり給付費(在宅)'!G397,'(参考)1人(1回(日))1月あたり給付費(在宅)'!G435,'(参考)1人(1回(日))1月あたり給付費(在宅)'!G459,'(参考)1人(1回(日))1月あたり給付費(在宅)'!G481,'(参考)1人(1回(日))1月あたり給付費(在宅)'!G415) -> 267
C10: =C9 -> 在宅サービス | E10: 要介護2 | F10: =IF('(参考)1人(1回(日))1月あたり給付費(在宅)'!$O$517="","",O10) -> 101057376 | G10: =IF('(参考)1人(1回(日))1月あたり給付費(在宅)'!$O$517="","",P10) -> 216 | H10: =IF(ISERROR((F10/G10)/12)=TRUE,"－",(F10/G10)/12) -> 38988.185 | I10: =data!I37 -> 24565 | J10: =data!J37 -> 51160 | K10: =IF(H10="－","",IF(H10<I10,"下限値を\"&TEXT(ROUND(I10-H10,0),"#,##0")&"下回っています。",IF(H10>J10,"上限値を\"&TEXT(ROUND(H10-J10,0),"#,##0")&"上回っています。","閾値の範囲内です。"))) -> 閾値の範囲内です。 | M10: =IF(OR(H10="－",AND(I10="－",J10="－")),"",IF(OR(H10<I10,H10>J10),1,"")) | N10: =IF(AND(F10="",G10=""),"",1) -> 1 | O10: =SUM('(参考)1人(1回(日))1月あたり給付費(在宅)'!F8,'(参考)1人(1回(日))1月あたり給付費(在宅)'!F28,'(参考)1人(1回(日))1月あたり給付費(在宅)'!F52,'(参考)1人(1回(日))1月あたり給付費(在宅)'!F76,'(参考)1人(1回(日))1月あたり給付費(在宅)'!F100,'(参考)1人(1回(日))1月あたり給付費(在宅)'!F122,'(参考)1人(1回(日))1月あたり給付費(在宅)'!F142,'(参考)1人(1回(日))1月あたり給付費(在宅)'!F166,'(参考)1人(1回(日))1月あたり給付費(在宅)'!F190,'(参考)1人(1回(日))1月あたり給付費(在宅)'!F214,'(参考)1人(1回(日))1月あたり給付費(在宅)'!F262,'(参考)1人(1回(日))1月あたり給付費(在宅)'!F286,'(参考)1人(1回(日))1月あたり給付費(在宅)'!F310,'(参考)1人(1回(日))1月あたり給付費(在宅)'!F334,'(参考)1人(1回(日))1月あたり給付費(在宅)'!F380,'(参考)1人(1回(日))1月あたり給付費(在宅)'!F398,'(参考)1人(1回(日))1月あたり給付費(在宅)'!F436,'(参考)1人(1回(日))1月あたり給付費(在宅)'!F460,'(参考)1人(1回(日))1月あたり給付費(在宅)'!F482,'(参考)1人(1回(日))1月あたり給付費(在宅)'!F416) -> 101057376 | P10: =SUM('(参考)1人(1回(日))1月あたり給付費(在宅)'!G8,'(参考)1人(1回(日))1月あたり給付費(在宅)'!G28,'(参考)1人(1回(日))1月あたり給付費(在宅)'!G52,'(参考)1人(1回(日))1月あたり給付費(在宅)'!G76,'(参考)1人(1回(日))1月あたり給付費(在宅)'!G100,'(参考)1人(1回(日))1月あたり給付費(在宅)'!G122,'(参考)1人(1回(日))1月あたり給付費(在宅)'!G142,'(参考)1人(1回(日))1月あたり給付費(在宅)'!G166,'(参考)1人(1回(日))1月あたり給付費(在宅)'!G190,'(参考)1人(1回(日))1月あたり給付費(在宅)'!G214,'(参考)1人(1回(日))1月あたり給付費(在宅)'!G262,'(参考)1人(1回(日))1月あたり給付費(在宅)'!G286,'(参考)1人(1回(日))1月あたり給付費(在宅)'!G310,'(参考)1人(1回(日))1月あたり給付費(在宅)'!G334,'(参考)1人(1回(日))1月あたり給付費(在宅)'!G380,'(参考)1人(1回(日))1月あたり給付費(在宅)'!G398,'(参考)1人(1回(日))1月あたり給付費(在宅)'!G436,'(参考)1人(1回(日))1月あたり給付費(在宅)'!G460,'(参考)1人(1回(日))1月あたり給付費(在宅)'!G482,'(参考)1人(1回(日))1月あたり給付費(在宅)'!G416) -> 216
C11: =C10 -> 在宅サービス | E11: 要介護3 | F11: =IF('(参考)1人(1回(日))1月あたり給付費(在宅)'!$O$517="","",O11) -> 1.6155892e+08 | G11: =IF('(参考)1人(1回(日))1月あたり給付費(在宅)'!$O$517="","",P11) -> 246 | H11: =IF(ISERROR((F11/G11)/12)=TRUE,"－",(F11/G11)/12) -> 54728.631 | I11: =data!I38 -> 33300 | J11: =data!J38 -> 70005 | K11: =IF(H11="－","",IF(H11<I11,"下限値を\"&TEXT(ROUND(I11-H11,0),"#,##0")&"下回っています。",IF(H11>J11,"上限値を\"&TEXT(ROUND(H11-J11,0),"#,##0")&"上回っています。","閾値の範囲内です。"))) -> 閾値の範囲内です。 | M11: =IF(OR(H11="－",AND(I11="－",J11="－")),"",IF(OR(H11<I11,H11>J11),1,"")) | N11: =IF(AND(F11="",G11=""),"",1) -> 1 | O11: =SUM('(参考)1人(1回(日))1月あたり給付費(在宅)'!F9,'(参考)1人(1回(日))1月あたり給付費(在宅)'!F29,'(参考)1人(1回(日))1月あたり給付費(在宅)'!F53,'(参考)1人(1回(日))1月あたり給付費(在宅)'!F77,'(参考)1人(1回(日))1月あたり給付費(在宅)'!F101,'(参考)1人(1回(日))1月あたり給付費(在宅)'!F123,'(参考)1人(1回(日))1月あたり給付費(在宅)'!F143,'(参考)1人(1回(日))1月あたり給付費(在宅)'!F167,'(参考)1人(1回(日))1月あたり給付費(在宅)'!F191,'(参考)1人(1回(日))1月あたり給付費(在宅)'!F215,'(参考)1人(1回(日))1月あたり給付費(在宅)'!F263,'(参考)1人(1回(日))1月あたり給付費(在宅)'!F287,'(参考)1人(1回(日))1月あたり給付費(在宅)'!F311,'(参考)1人(1回(日))1月あたり給付費(在宅)'!F335,'(参考)1人(1回(日))1月あたり給付費(在宅)'!F381,'(参考)1人(1回(日))1月あたり給付費(在宅)'!F399,'(参考)1人(1回(日))1月あたり給付費(在宅)'!F437,'(参考)1人(1回(日))1月あたり給付費(在宅)'!F461,'(参考)1人(1回(日))1月あたり給付費(在宅)'!F483,'(参考)1人(1回(日))1月あたり給付費(在宅)'!F417) -> 1.6155892e+08 | P11: =SUM('(参考)1人(1回(日))1月あたり給付費(在宅)'!G9,'(参考)1人(1回(日))1月あたり給付費(在宅)'!G29,'(参考)1人(1回(日))1月あたり給付費(在宅)'!G53,'(参考)1人(1回(日))1月あたり給付費(在宅)'!G77,'(参考)1人(1回(日))1月あたり給付費(在宅)'!G101,'(参考)1人(1回(日))1月あたり給付費(在宅)'!G123,'(参考)1人(1回(日))1月あたり給付費(在宅)'!G143,'(参考)1人(1回(日))1月あたり給付費(在宅)'!G167,'(参考)1人(1回(日))1月あたり給付費(在宅)'!G191,'(参考)1人(1回(日))1月あたり給付費(在宅)'!G215,'(参考)1人(1回(日))1月あたり給付費(在宅)'!G263,'(参考)1人(1回(日))1月あたり給付費(在宅)'!G287,'(参考)1人(1回(日))1月あたり給付費(在宅)'!G311,'(参考)1人(1回(日))1月あたり給付費(在宅)'!G335,'(参考)1人(1回(日))1月あたり給付費(在宅)'!G381,'(参考)1人(1回(日))1月あたり給付費(在宅)'!G399,'(参考)1人(1回(日))1月あたり給付費(在宅)'!G437,'(参考)1人(1回(日))1月あたり給付費(在宅)'!G461,'(参考)1人(1回(日))1月あたり給付費(在宅)'!G483,'(参考)1人(1回(日))1月あたり給付費(在宅)'!G417) -> 246
C12: =C11 -> 在宅サービス | E12: 要介護4 | F12: =IF('(参考)1人(1回(日))1月あたり給付費(在宅)'!$O$517="","",O12) -> 96423727 | G12: =IF('(参考)1人(1回(日))1月あたり給付費(在宅)'!$O$517="","",P12) -> 137 | H12: =IF(ISERROR((F12/G12)/12)=TRUE,"－",(F12/G12)/12) -> 58651.902 | I12: =data!I39 -> 36055 | J12: =data!J39 -> 78330 | K12: =IF(H12="－","",IF(H12<I12,"下限値を\"&TEXT(ROUND(I12-H12,0),"#,##0")&"下回っています。",IF(H12>J12,"上限値を\"&TEXT(ROUND(H12-J12,0),"#,##0")&"上回っています。","閾値の範囲内です。"))) -> 閾値の範囲内です。 | M12: =IF(OR(H12="－",AND(I12="－",J12="－")),"",IF(OR(H12<I12,H12>J12),1,"")) | N12: =IF(AND(F12="",G12=""),"",1) -> 1 | O12: =SUM('(参考)1人(1回(日))1月あたり給付費(在宅)'!F10,'(参考)1人(1回(日))1月あたり給付費(在宅)'!F30,'(参考)1人(1回(日))1月あたり給付費(在宅)'!F54,'(参考)1人(1回(日))1月あたり給付費(在宅)'!F78,'(参考)1人(1回(日))1月あたり給付費(在宅)'!F102,'(参考)1人(1回(日))1月あたり給付費(在宅)'!F124,'(参考)1人(1回(日))1月あたり給付費(在宅)'!F144,'(参考)1人(1回(日))1月あたり給付費(在宅)'!F168,'(参考)1人(1回(日))1月あたり給付費(在宅)'!F192,'(参考)1人(1回(日))1月あたり給付費(在宅)'!F216,'(参考)1人(1回(日))1月あたり給付費(在宅)'!F264,'(参考)1人(1回(日))1月あたり給付費(在宅)'!F288,'(参考)1人(1回(日))1月あたり給付費(在宅)'!F312,'(参考)1人(1回(日))1月あたり給付費(在宅)'!F336,'(参考)1人(1回(日))1月あたり給付費(在宅)'!F382,'(参考)1人(1回(日))1月あたり給付費(在宅)'!F400,'(参考)1人(1回(日))1月あたり給付費(在宅)'!F438,'(参考)1人(1回(日))1月あたり給付費(在宅)'!F462,'(参考)1人(1回(日))1月あたり給付費(在宅)'!F484,'(参考)1人(1回(日))1月あたり給付費(在宅)'!F418) -> 96423727 | P12: =SUM('(参考)1人(1回(日))1月あたり給付費(在宅)'!G10,'(参考)1人(1回(日))1月あたり給付費(在宅)'!G30,'(参考)1人(1回(日))1月あたり給付費(在宅)'!G54,'(参考)1人(1回(日))1月あたり給付費(在宅)'!G78,'(参考)1人(1回(日))1月あたり給付費(在宅)'!G102,'(参考)1人(1回(日))1月あたり給付費(在宅)'!G124,'(参考)1人(1回(日))1月あたり給付費(在宅)'!G144,'(参考)1人(1回(日))1月あたり給付費(在宅)'!G168,'(参考)1人(1回(日))1月あたり給付費(在宅)'!G192,'(参考)1人(1回(日))1月あたり給付費(在宅)'!G216,'(参考)1人(1回(日))1月あたり給付費(在宅)'!G264,'(参考)1人(1回(日))1月あたり給付費(在宅)'!G288,'(参考)1人(1回(日))1月あたり給付費(在宅)'!G312,'(参考)1人(1回(日))1月あたり給付費(在宅)'!G336,'(参考)1人(1回(日))1月あたり給付費(在宅)'!G382,'(参考)1人(1回(日))1月あたり給付費(在宅)'!G400,'(参考)1人(1回(日))1月あたり給付費(在宅)'!G438,'(参考)1人(1回(日))1月あたり給付費(在宅)'!G462,'(参考)1人(1回(日))1月あたり給付費(在宅)'!G484,'(参考)1人(1回(日))1月あたり給付費(在宅)'!G418) -> 137
C13: =C12 -> 在宅サービス | E13: 要介護5 | F13: =IF('(参考)1人(1回(日))1月あたり給付費(在宅)'!$O$517="","",O13) -> 28218767 | G13: =IF('(参考)1人(1回(日))1月あたり給付費(在宅)'!$O$517="","",P13) -> 37 | H13: =IF(ISERROR((F13/G13)/12)=TRUE,"－",(F13/G13)/12) -> 63555.781 | I13: =data!I40 -> 35705 | J13: =data!J40 -> 90745 | K13: =IF(H13="－","",IF(H13<I13,"下限値を\"&TEXT(ROUND(I13-H13,0),"#,##0")&"下回っています。",IF(H13>J13,"上限値を\"&TEXT(ROUND(H13-J13,0),"#,##0")&"上回っています。","閾値の範囲内です。"))) -> 閾値の範囲内です。 | M13: =IF(OR(H13="－",AND(I13="－",J13="－")),"",IF(OR(H13<I13,H13>J13),1,"")) | N13: =IF(AND(F13="",G13=""),"",1) -> 1 | O13: =SUM('(参考)1人(1回(日))1月あたり給付費(在宅)'!F11,'(参考)1人(1回(日))1月あたり給付費(在宅)'!F31,'(参考)1人(1回(日))1月あたり給付費(在宅)'!F55,'(参考)1人(1回(日))1月あたり給付費(在宅)'!F79,'(参考)1人(1回(日))1月あたり給付費(在宅)'!F103,'(参考)1人(1回(日))1月あたり給付費(在宅)'!F125,'(参考)1人(1回(日))1月あたり給付費(在宅)'!F145,'(参考)1人(1回(日))1月あたり給付費(在宅)'!F169,'(参考)1人(1回(日))1月あたり給付費(在宅)'!F193,'(参考)1人(1回(日))1月あたり給付費(在宅)'!F217,'(参考)1人(1回(日))1月あたり給付費(在宅)'!F265,'(参考)1人(1回(日))1月あたり給付費(在宅)'!F289,'(参考)1人(1回(日))1月あたり給付費(在宅)'!F313,'(参考)1人(1回(日))1月あたり給付費(在宅)'!F337,'(参考)1人(1回(日))1月あたり給付費(在宅)'!F383,'(参考)1人(1回(日))1月あたり給付費(在宅)'!F401,'(参考)1人(1回(日))1月あたり給付費(在宅)'!F439,'(参考)1人(1回(日))1月あたり給付費(在宅)'!F463,'(参考)1人(1回(日))1月あたり給付費(在宅)'!F485,'(参考)1人(1回(日))1月あたり給付費(在宅)'!F419) -> 28218767 | P13: =SUM('(参考)1人(1回(日))1月あたり給付費(在宅)'!G11,'(参考)1人(1回(日))1月あたり給付費(在宅)'!G31,'(参考)1人(1回(日))1月あたり給付費(在宅)'!G55,'(参考)1人(1回(日))1月あたり給付費(在宅)'!G79,'(参考)1人(1回(日))1月あたり給付費(在宅)'!G103,'(参考)1人(1回(日))1月あたり給付費(在宅)'!G125,'(参考)1人(1回(日))1月あたり給付費(在宅)'!G145,'(参考)1人(1回(日))1月あたり給付費(在宅)'!G169,'(参考)1人(1回(日))1月あたり給付費(在宅)'!G193,'(参考)1人(1回(日))1月あたり給付費(在宅)'!G217,'(参考)1人(1回(日))1月あたり給付費(在宅)'!G265,'(参考)1人(1回(日))1月あたり給付費(在宅)'!G289,'(参考)1人(1回(日))1月あたり給付費(在宅)'!G313,'(参考)1人(1回(日))1月あたり給付費(在宅)'!G337,'(参考)1人(1回(日))1月あたり給付費(在宅)'!G383,'(参考)1人(1回(日))1月あたり給付費(在宅)'!G401,'(参考)1人(1回(日))1月あたり給付費(在宅)'!G439,'(参考)1人(1回(日))1月あたり給付費(在宅)'!G463,'(参考)1人(1回(日))1月あたり給付費(在宅)'!G485,'(参考)1人(1回(日))1月あたり給付費(在宅)'!G419) -> 37
C14: =C13 -> 在宅サービス | E14: 合計 | F14: =SUM(F7:F13) -> 5.2340792e+08 | G14: =SUM(G7:G13) -> 1127 | H14: =IF(ISERROR((F14/G14)/12)=TRUE,"－",(F14/G14)/12) -> 38702.153 | I14: =data!I41 -> 24765 | J14: =data!J41 -> 51080 | K14: =IF(H14="－","",IF(H14<I14,"下限値を\"&TEXT(ROUND(I14-H14,0),"#,##0")&"下回っています。",IF(H14>J14,"上限値を\"&TEXT(ROUND(H14-J14,0),"#,##0")&"上回っています。","閾値の範囲内です。"))) -> 閾値の範囲内です。 | M14: =IF(OR(H14="－",AND(I14="－",J14="－")),"",IF(OR(H14<I14,H14>J14),1,""))
C15: =C14 -> 在宅サービス | D15: 令和10年度 | E15: 要支援1 | F15: =IF('(参考)1人(1回(日))1月あたり給付費(在宅)'!$O$517="","",O15) -> 9792024 | G15: =IF('(参考)1人(1回(日))1月あたり給付費(在宅)'!$O$517="","",P15) -> 79 | H15: =IF(ISERROR((F15/G15)/12)=TRUE,"－",(F15/G15)/12) -> 10329.139 | I15: =I7 -> 5290 | J15: =J7 -> 14725 | K15: =IF(H15="－","",IF(H15<I15,"下限値を\"&TEXT(ROUND(I15-H15,0),"#,##0")&"下回っています。",IF(H15>J15,"上限値を\"&TEXT(ROUND(H15-J15,0),"#,##0")&"上回っています。","閾値の範囲内です。"))) -> 閾値の範囲内です。 | M15: =IF(OR(H15="－",AND(I15="－",J15="－")),"",IF(OR(H15<I15,H15>J15),1,"")) | N15: =IF(AND(F15="",G15=""),"",1) -> 1 | O15: =SUM('(参考)1人(1回(日))1月あたり給付費(在宅)'!F33,'(参考)1人(1回(日))1月あたり給付費(在宅)'!F57,'(参考)1人(1回(日))1月あたり給付費(在宅)'!F81,'(参考)1人(1回(日))1月あたり給付費(在宅)'!F105,'(参考)1人(1回(日))1月あたり給付費(在宅)'!F147,'(参考)1人(1回(日))1月あたり給付費(在宅)'!F171,'(参考)1人(1回(日))1月あたり給付費(在宅)'!F195,'(参考)1人(1回(日))1月あたり給付費(在宅)'!F219,'(参考)1人(1回(日))1月あたり給付費(在宅)'!F267,'(参考)1人(1回(日))1月あたり給付費(在宅)'!F291,'(参考)1人(1回(日))1月あたり給付費(在宅)'!F315,'(参考)1人(1回(日))1月あたり給付費(在宅)'!F339,'(参考)1人(1回(日))1月あたり給付費(在宅)'!F441,'(参考)1人(1回(日))1月あたり給付費(在宅)'!F465) -> 9792024 | P15: =SUM('(参考)1人(1回(日))1月あたり給付費(在宅)'!G33,'(参考)1人(1回(日))1月あたり給付費(在宅)'!G57,'(参考)1人(1回(日))1月あたり給付費(在宅)'!G81,'(参考)1人(1回(日))1月あたり給付費(在宅)'!G105,'(参考)1人(1回(日))1月あたり給付費(在宅)'!G147,'(参考)1人(1回(日))1月あたり給付費(在宅)'!G171,'(参考)1人(1回(日))1月あたり給付費(在宅)'!G195,'(参考)1人(1回(日))1月あたり給付費(在宅)'!G219,'(参考)1人(1回(日))1月あたり給付費(在宅)'!G267,'(参考)1人(1回(日))1月あたり給付費(在宅)'!G291,'(参考)1人(1回(日))1月あたり給付費(在宅)'!G315,'(参考)1人(1回(日))1月あたり給付費(在宅)'!G339,'(参考)1人(1回(日))1月あたり給付費(在宅)'!G441,'(参考)1人(1回(日))1月あたり給付費(在宅)'!G465) -> 79
C16: =C15 -> 在宅サービス | E16: 要支援2 | F16: =IF('(参考)1人(1回(日))1月あたり給付費(在宅)'!$O$517="","",O16) -> 30048703 | G16: =IF('(参考)1人(1回(日))1月あたり給付費(在宅)'!$O$517="","",P16) -> 152 | H16: =IF(ISERROR((F16/G16)/12)=TRUE,"－",(F16/G16)/12) -> 16474.07 | I16: =I8 -> 5555 | J16: =J8 -> 20285 | K16: =IF(H16="－","",IF(H16<I16,"下限値を\"&TEXT(ROUND(I16-H16,0),"#,##0")&"下回っています。",IF(H16>J16,"上限値を\"&TEXT(ROUND(H16-J16,0),"#,##0")&"上回っています。","閾値の範囲内です。"))) -> 閾値の範囲内です。 | M16: =IF(OR(H16="－",AND(I16="－",J16="－")),"",IF(OR(H16<I16,H16>J16),1,"")) | N16: =IF(AND(F16="",G16=""),"",1) -> 1 | O16: =SUM('(参考)1人(1回(日))1月あたり給付費(在宅)'!F34,'(参考)1人(1回(日))1月あたり給付費(在宅)'!F58,'(参考)1人(1回(日))1月あたり給付費(在宅)'!F82,'(参考)1人(1回(日))1月あたり給付費(在宅)'!F106,'(参考)1人(1回(日))1月あたり給付費(在宅)'!F148,'(参考)1人(1回(日))1月あたり給付費(在宅)'!F172,'(参考)1人(1回(日))1月あたり給付費(在宅)'!F196,'(参考)1人(1回(日))1月あたり給付費(在宅)'!F220,'(参考)1人(1回(日))1月あたり給付費(在宅)'!F268,'(参考)1人(1回(日))1月あたり給付費(在宅)'!F292,'(参考)1人(1回(日))1月あたり給付費(在宅)'!F316,'(参考)1人(1回(日))1月あたり給付費(在宅)'!F340,'(参考)1人(1回(日))1月あたり給付費(在宅)'!F442,'(参考)1人(1回(日))1月あたり給付費(在宅)'!F466) -> 30048703 | P16: =SUM('(参考)1人(1回(日))1月あたり給付費(在宅)'!G34,'(参考)1人(1回(日))1月あたり給付費(在宅)'!G58,'(参考)1人(1回(日))1月あたり給付費(在宅)'!G82,'(参考)1人(1回(日))1月あたり給付費(在宅)'!G106,'(参考)1人(1回(日))1月あたり給付費(在宅)'!G148,'(参考)1人(1回(日))1月あたり給付費(在宅)'!G172,'(参考)1人(1回(日))1月あたり給付費(在宅)'!G196,'(参考)1人(1回(日))1月あたり給付費(在宅)'!G220,'(参考)1人(1回(日))1月あたり給付費(在宅)'!G268,'(参考)1人(1回(日))1月あたり給付費(在宅)'!G292,'(参考)1人(1回(日))1月あたり給付費(在宅)'!G316,'(参考)1人(1回(日))1月あたり給付費(在宅)'!G340,'(参考)1人(1回(日))1月あたり給付費(在宅)'!G442,'(参考)1人(1回(日))1月あたり給付費(在宅)'!G466) -> 152
C17: =C16 -> 在宅サービス | E17: 要介護1 | F17: =IF('(参考)1人(1回(日))1月あたり給付費(在宅)'!$O$517="","",O17) -> 97197245 | G17: =IF('(参考)1人(1回(日))1月あたり給付費(在宅)'!$O$517="","",P17) -> 266 | H17: =IF(ISERROR((F17/G17)/12)=TRUE,"－",(F17/G17)/12) -> 30450.265 | I17: =I9 -> 19435 | J17: =J9 -> 43955 | K17: =IF(H17="－","",IF(H17<I17,"下限値を\"&TEXT(ROUND(I17-H17,0),"#,##0")&"下回っています。",IF(H17>J17,"上限値を\"&TEXT(ROUND(H17-J17,0),"#,##0")&"上回っています。","閾値の範囲内です。"))) -> 閾値の範囲内です。 | M17: =IF(OR(H17="－",AND(I17="－",J17="－")),"",IF(OR(H17<I17,H17>J17),1,"")) | N17: =IF(AND(F17="",G17=""),"",1) -> 1 | O17: =SUM('(参考)1人(1回(日))1月あたり給付費(在宅)'!F13,'(参考)1人(1回(日))1月あたり給付費(在宅)'!F35,'(参考)1人(1回(日))1月あたり給付費(在宅)'!F59,'(参考)1人(1回(日))1月あたり給付費(在宅)'!F83,'(参考)1人(1回(日))1月あたり給付費(在宅)'!F107,'(参考)1人(1回(日))1月あたり給付費(在宅)'!F127,'(参考)1人(1回(日))1月あたり給付費(在宅)'!F149,'(参考)1人(1回(日))1月あたり給付費(在宅)'!F173,'(参考)1人(1回(日))1月あたり給付費(在宅)'!F197,'(参考)1人(1回(日))1月あたり給付費(在宅)'!F221,'(参考)1人(1回(日))1月あたり給付費(在宅)'!F269,'(参考)1人(1回(日))1月あたり給付費(在宅)'!F293,'(参考)1人(1回(日))1月あたり給付費(在宅)'!F317,'(参考)1人(1回(日))1月あたり給付費(在宅)'!F341,'(参考)1人(1回(日))1月あたり給付費(在宅)'!F385,'(参考)1人(1回(日))1月あたり給付費(在宅)'!F403,'(参考)1人(1回(日))1月あたり給付費(在宅)'!F443,'(参考)1人(1回(日))1月あたり給付費(在宅)'!F467,'(参考)1人(1回(日))1月あたり給付費(在宅)'!F487,'(参考)1人(1回(日))1月あたり給付費(在宅)'!F421) -> 97197245 | P17: =SUM('(参考)1人(1回(日))1月あたり給付費(在宅)'!G13,'(参考)1人(1回(日))1月あたり給付費(在宅)'!G35,'(参考)1人(1回(日))1月あたり給付費(在宅)'!G59,'(参考)1人(1回(日))1月あたり給付費(在宅)'!G83,'(参考)1人(1回(日))1月あたり給付費(在宅)'!G107,'(参考)1人(1回(日))1月あたり給付費(在宅)'!G127,'(参考)1人(1回(日))1月あたり給付費(在宅)'!G149,'(参考)1人(1回(日))1月あたり給付費(在宅)'!G173,'(参考)1人(1回(日))1月あたり給付費(在宅)'!G197,'(参考)1人(1回(日))1月あたり給付費(在宅)'!G221,'(参考)1人(1回(日))1月あたり給付費(在宅)'!G269,'(参考)1人(1回(日))1月あたり給付費(在宅)'!G293,'(参考)1人(1回(日))1月あたり給付費(在宅)'!G317,'(参考)1人(1回(日))1月あたり給付費(在宅)'!G341,'(参考)1人(1回(日))1月あたり給付費(在宅)'!G385,'(参考)1人(1回(日))1月あたり給付費(在宅)'!G403,'(参考)1人(1回(日))1月あたり給付費(在宅)'!G443,'(参考)1人(1回(日))1月あたり給付費(在宅)'!G467,'(参考)1人(1回(日))1月あたり給付費(在宅)'!G487,'(参考)1人(1回(日))1月あたり給付費(在宅)'!G421) -> 266
C18: =C17 -> 在宅サービス | E18: 要介護2 | F18: =IF('(参考)1人(1回(日))1月あたり給付費(在宅)'!$O$517="","",O18) -> 99349368 | G18: =IF('(参考)1人(1回(日))1月あたり給付費(在宅)'!$O$517="","",P18) -> 212 | H18: =IF(ISERROR((F18/G18)/12)=TRUE,"－",(F18/G18)/12) -> 39052.425 | I18: =I10 -> 24565 | J18: =J10 -> 51160 | K18: =IF(H18="－","",IF(H18<I18,"下限値を\"&TEXT(ROUND(I18-H18,0),"#,##0")&"下回っています。",IF(H18>J18,"上限値を\"&TEXT(ROUND(H18-J18,0),"#,##0")&"上回っています。","閾値の範囲内です。"))) -> 閾値の範囲内です。 | M18: =IF(OR(H18="－",AND(I18="－",J18="－")),"",IF(OR(H18<I18,H18>J18),1,"")) | N18: =IF(AND(F18="",G18=""),"",1) -> 1 | O18: =SUM('(参考)1人(1回(日))1月あたり給付費(在宅)'!F14,'(参考)1人(1回(日))1月あたり給付費(在宅)'!F36,'(参考)1人(1回(日))1月あたり給付費(在宅)'!F60,'(参考)1人(1回(日))1月あたり給付費(在宅)'!F84,'(参考)1人(1回(日))1月あたり給付費(在宅)'!F108,'(参考)1人(1回(日))1月あたり給付費(在宅)'!F128,'(参考)1人(1回(日))1月あたり給付費(在宅)'!F150,'(参考)1人(1回(日))1月あたり給付費(在宅)'!F174,'(参考)1人(1回(日))1月あたり給付費(在宅)'!F198,'(参考)1人(1回(日))1月あたり給付費(在宅)'!F222,'(参考)1人(1回(日))1月あたり給付費(在宅)'!F270,'(参考)1人(1回(日))1月あたり給付費(在宅)'!F294,'(参考)1人(1回(日))1月あたり給付費(在宅)'!F318,'(参考)1人(1回(日))1月あたり給付費(在宅)'!F342,'(参考)1人(1回(日))1月あたり給付費(在宅)'!F386,'(参考)1人(1回(日))1月あたり給付費(在宅)'!F404,'(参考)1人(1回(日))1月あたり給付費(在宅)'!F444,'(参考)1人(1回(日))1月あたり給付費(在宅)'!F468,'(参考)1人(1回(日))1月あたり給付費(在宅)'!F488,'(参考)1人(1回(日))1月あたり給付費(在宅)'!F422) -> 99349368 | P18: =SUM('(参考)1人(1回(日))1月あたり給付費(在宅)'!G14,'(参考)1人(1回(日))1月あたり給付費(在宅)'!G36,'(参考)1人(1回(日))1月あたり給付費(在宅)'!G60,'(参考)1人(1回(日))1月あたり給付費(在宅)'!G84,'(参考)1人(1回(日))1月あたり給付費(在宅)'!G108,'(参考)1人(1回(日))1月あたり給付費(在宅)'!G128,'(参考)1人(1回(日))1月あたり給付費(在宅)'!G150,'(参考)1人(1回(日))1月あたり給付費(在宅)'!G174,'(参考)1人(1回(日))1月あたり給付費(在宅)'!G198,'(参考)1人(1回(日))1月あたり給付費(在宅)'!G222,'(参考)1人(1回(日))1月あたり給付費(在宅)'!G270,'(参考)1人(1回(日))1月あたり給付費(在宅)'!G294,'(参考)1人(1回(日))1月あたり給付費(在宅)'!G318,'(参考)1人(1回(日))1月あたり給付費(在宅)'!G342,'(参考)1人(1回(日))1月あたり給付費(在宅)'!G386,'(参考)1人(1回(日))1月あたり給付費(在宅)'!G404,'(参考)1人(1回(日))1月あたり給付費(在宅)'!G444,'(参考)1人(1回(日))1月あたり給付費(在宅)'!G468,'(参考)1人(1回(日))1月あたり給付費(在宅)'!G488,'(参考)1人(1回(日))1月あたり給付費(在宅)'!G422) -> 212
