Workbook
Name _01: #REF!
Name _01: PullDown!$AA$6:$AA$188
Name _02: #REF!
Name _02: PullDown!$AB$6:$AB$45
Name _03: #REF!
Name _03: PullDown!$AC$6:$AC$42
Name _04: #REF!
Name _04: PullDown!$AD$6:$AD$40
Name _05: #REF!
Name _05: PullDown!$AE$6:$AE$32
Name _06: #REF!
Name _06: PullDown!$AF$6:$AF$40
Name _07: #REF!
Name _07: PullDown!$AG$6:$AG$64
Name _08: #REF!
Name _08: PullDown!$AH$6:$AH$49
Name _09: #REF!
Name _09: PullDown!$AI$6:$AI$30
Name _10: #REF!
Name _10: PullDown!$AJ$6:$AJ$40
Name _11: #REF!
Name _11: PullDown!$AK$6:$AK$69
Name _12: #REF!
Name _12: PullDown!$AL$6:$AL$59
Name _13: #REF!
Name _13: PullDown!$AM$6:$AM$67
Name _14: #REF!
Name _14: PullDown!$AN$6:$AN$38
Name _15: #REF!
Name _15: PullDown!$AO$6:$AO$35
Name _16: #REF!
Name _16: PullDown!$AP$6:$AP$23
Name _17: #REF!
Name _17: PullDown!$AQ$6:$AQ$24
Name _18: #REF!
Name _18: PullDown!$AR$6:$AR$23
Name _19: #REF!
Name _19: PullDown!$AS$6:$AS$32
Name _20: #REF!
Name _20: PullDown!$AT$6:$AT$85
Name _21: #REF!
Name _21: PullDown!$AU$6:$AU$50
Name _22: #REF!
Name _22: PullDown!$AV$6:$AV$40
Name _23: #REF!
Name _23: PullDown!$AW$6:$AW$61
Name _24: #REF!
Name _24: PullDown!$AX$6:$AX$37
Name _25: #REF!
Name _25: PullDown!$AY$6:$AY$24
Name _26: #REF!
Name _26: PullDown!$AZ$6:$AZ$31
Name _27: #REF!
Name _27: PullDown!$BA$6:$BA$48
Name _28: #REF!
Name _28: PullDown!$BB$6:$BB$46
Name _29: #REF!
Name _29: PullDown!$BC$6:$BC$44
Name _30: #REF!
Name _30: PullDown!$BD$6:$BD$35

Sheet 所要額データ
A1: 01項番 | B1: 01通し番号 | C1: 01厚生（支）局名 | D1: 01都道府県名 | E1: 01保険者名 | F1: 01保険者番号 | G1: 01市区町村ｺｰﾄﾞ | H1: 01都道府県ｺｰﾄﾞ | I1: 01H27総合事業上限設定 | J1: 01H28総合事業上限設定 | K1: 01H29総合事業上限設定 | L1: 01H30総合事業上限設定 | M1: 01R1総合事業上限設定 | N1: 01R2総合事業上限設定 | O1: 01R3総合事業上限設定 | P1: 01R4総合事業上限設定 | Q1: 01R5総合事業上限設定 | R1: 01R6総合事業上限設定 | S1: 01総合事業移行年 | T1: 01総合事業移行月 | U1: 01総合事業移行日 | V1: 01総合事業移行年月日 | W1: 01総合事業移行年度 | X1: 01総合事業移行前年度 | Y1: 01指定都市 | Z1: 01広域連合等 | AA1: 01上記以外の市町村 | AB1: 01重層実施 | AC1: 01①地域介護予防活動支援事業に要する費用相当額を交付率で除して得た額 | AD1: 01②地域包括支援センターの運営に要する費用相当額を交付率で除して得た額 | AE1: 01③生活支援体制整備事業に要する費用相当額を交付率で除して得た額 | AF1: A1000 | AG1: A1100 | AH1: A1110 | AI1: A1120 | AJ1: A1130 | AK1: A1140 | AL1: A1150 | AM1: A1160 | AN1: A1200 | AO1: A1210 | AP1: A1220 | AQ1: A1230 | AR1: A1240 | AS1: A1250 | AT1: A1300 | AU1: A1310 | AV1: A1320 | AW1: A1330 | AX1: A1340 | AY1: A1400 | AZ1: A1500 | BA1: A1600 | BB1: A1700 | BC1: A1710 | BD1: A1720 | BE1: A1730 | BF1: A1740 | BG1: A1750 | BH1: A2000 | BI1: A2100 | BJ1: A2200 | BK1: A2210 | BL1: A2220 | BM1: A2230 | BN1: A3000 | BO1: A4000 | BP1: A4100 | BQ1: A4200 | BR1: A4210 | BS1: A4220 | BT1: A4230 | BU1: A4240 | BV1: A4300 | BW1: A4310 | BX1: A4320 | BY1: A4330 | BZ1: A4400 | CA1: A5000 | CB1: B1000 | CC1: B1100 | CD1: B1110 | CE1: B1120 | CF1: B1130 | CG1: B1140 | CH1: B1150 | CI1: B1160 | CJ1: B1200 | CK1: B1210 | CL1: B1220 | CM1: B1230 | CN1: B1240 | CO1: B1250 | CP1: B1300 | CQ1: B1310 | CR1: B1320 | CS1: B1330 | CT1: B1340 | CU1: B1400 | CV1: B1500 | CW1: B1600 | CX1: B1700 | CY1: B1710 | CZ1: B1720 | DA1: B1730 | DB1: B1740 | DC1: B1750 | DD1: B2000 | DE1: B2100 | DF1: B2200 | DG1: B2210 | DH1: B2220 | DI1: B2230 | DJ1: B3000 | DK1: B4000 | DL1: B4100 | DM1: B4200 | DN1: B4210 | DO1: B4220 | DP1: B4230 | DQ1: B4240 | DR1: B4300 | DS1: B4310 | DT1: B4320 | DU1: B4330 | DV1: B4400 | DW1: B5000 | DX1: C1000 | DY1: C1100 | DZ1: C1110 | EA1: C1120 | EB1: C1130 | EC1: C1140 | ED1: C1150 | EE1: C1160 | EF1: C1200 | EG1: C1210 | EH1: C1220 | EI1: C1230 | EJ1: C1240 | EK1: C1250 | EL1: C1300 | EM1: C1310 | EN1: C1320 | EO1: C1330 | EP1: C1340 | EQ1: C1400 | ER1: C1500 | ES1: C1600 | ET1: C1700 | EU1: C1710 | EV1: C1720 | EW1: C1730 | EX1: C1740 | EY1: C1750 | EZ1: C2000 | FA1: C2100 | FB1: C2200 | FC1: C2210 | FD1: C2220 | FE1: C2230 | FF1: C3000 | FG1: C4000 | FH1: C4100 | FI1: C4200 | FJ1: C4210 | FK1: C4220 | FL1: C4230 | FM1: C4240 | FN1: C4300 | FO1: C4310 | FP1: C4320 | FQ1: C4330 | FR1: C4400 | FS1: C5000 | FT1: D1000 | FU1: D1100 | FV1: D1110 | FW1: D1120 | FX1: D1130 | FY1: D1140 | FZ1: D1150 | GA1: D1160 | GB1: D1200 | GC1: D1210 | GD1: D1220 | GE1: D1230 | GF1: D1240 | GG1: D1250 | GH1: D1300 | GI1: D1310 | GJ1: D1320 | GK1: D1330 | GL1: D1340 | GM1: D1400 | GN1: D1500 | GO1: D1600 | GP1: D1700 | GQ1: D1710 | GR1: D1720 | GS1: D1730 | GT1: D1740 | GU1: D1750 | GV1: D2000 | GW1: D2100 | GX1: D2200 | GY1: D2210 | GZ1: D2220 | HA1: D2230 | HB1: D3000 | HC1: D4000 | HD1: D4100 | HE1: D4200 | HF1: D4210 | HG1: D4220 | HH1: D4230 | HI1: D4240 | HJ1: D4300 | HK1: D4310 | HL1: D4320 | HM1: D4330 | HN1: D4400 | HO1: D5000 | HP1: E1000 | HQ1: E2000 | HR1: E4000 | HS1: E4100 | HT1: E4200 | HU1: E4210 | HV1: E4220 | HW1: E4230 | HX1: E4240 | HY1: E4300 | HZ1: E4310 | IA1: E4320 | IB1: E4330 | IC1: E4400 | ID1: F1000 | IE1: F2000 | IF1: F3000 | IG1: F4000 | IH1: F5000 | II1: G1000 | IJ1: G2000 | IK1: G3000 | IL1: G4000 | IM1: G5000 | IN1: H1000 | IO1: H2000 | IP1: H3000 | IQ1: H4000 | IR1: H5000 | IS1: I1000 | IT1: I2000 | IU1: I3000 | IV1: I4000 | IW1: I5000 | IX1: J1000 | IY1: J2000 | IZ1: J3000 | JA1: J4000 | JB1: J5000 | JC1: K1000 | JD1: K2000 | JE1: K3000 | JF1: K4000 | JG1: K5000 | JH1: 備考欄1000 | JI1: 備考欄1100 | JJ1: 備考欄1110 | JK1: 備考欄1120 | JL1: 備考欄1130 | JM1: 備考欄1140 | JN1: 備考欄1150 | JO1: 備考欄1160 | JP1: 備考欄1200 | JQ1: 備考欄1210 | JR1: 備考欄1220 | JS1: 備考欄1230 | JT1: 備考欄1240 | JU1: 備考欄1250 | JV1: 備考欄1300 | JW1: 備考欄1310 | JX1: 備考欄1320 | JY1: 備考欄1330 | JZ1: 備考欄1340 | KA1: 備考欄1400 | KB1: 備考欄1500 | KC1: 備考欄1600 | KD1: 備考欄1700 | KE1: 備考欄1710 | KF1: 備考欄1720 | KG1: 備考欄1730 | KH1: 備考欄1740 | KI1: 備考欄1750 | KJ1: 備考欄2000 | KK1: 備考欄2100 | KL1: 備考欄2200 | KM1: 備考欄2210 | KN1: 備考欄2220 | KO1: 備考欄2230 | KP1: 備考欄3000 | KQ1: 備考欄4000 | KR1: 備考欄4100 | KS1: 備考欄4200 | KT1: 備考欄4210 | KU1: 備考欄4220 | KV1: 備考欄4230 | KW1: 備考欄4240 | KX1: 備考欄4300 | KY1: 備考欄4310 | KZ1: 備考欄4320 | LA1: 備考欄4330 | LB1: 備考欄4400 | LC1: 備考欄5000 | LD1: 総合事業の上限額設定状況 | LE1: 包括的支援事業（地域包括支援センターの運営）及び任意事業上限額設定状況 | LF1: 包括的支援事業（社会保障充実分）上限額設定状況 | LG1: 総合事業調整交付金調整基準標準事業費額 | LH1: 総合事業調整交付金所要額 | LI1: 重層的支援体制整備事業の実施有無 | LJ1: 重層的支援体制整備事業に要する費用相当額総額 | LK1: 重層的支援体制整備事業に要する地域介護予防活動支援事業費相当額 | LL1: 重層的支援体制整備事業に要する地域包括支援センターの運営費相当額 | LM1: 重層的支援体制整備事業に要する生活支援体制整備事業費相当額 | LN1: 重層Kセンター運営対象経費基本額（影響額調整後） | LO1: 重層aセンター運営地域支援事業で実施される任意事業に要する費用 | LP1: 重層K'センター運営小計（ K + a ） | LQ1: 重層Lセンター運営基準額 | LR1: 重層bセンター運営K’とLで、いずれか少ない額 | LS1: 重層Mセンター運営交付基本額（ b - a ） | LT1: 重層K'エラーセンター運営 | LU1: 重層bエラーセンター運営 | LV1: 重層Mエラーセンター運営 | LW1: 重層K地域介護予防対象経費基本額（影響額調整後） | LX1: 重層a地域介護予防地域支援事業で実施される介護予防・日常生活支援総合事業に要する費用 | LY1: 重層K'地域介護予防小計（ K + a ） | LZ1: 重層L地域介護予防基準額 | MA1: 重層b地域介護予防K’とLで、いずれか少ない額 | MB1: 重層M地域介護予防交付基本額（ b - a ） | MC1: 重層K'エラー地域介護予防 | MD1: 重層bエラー地域介護予防 | ME1: 重層Mエラー地域介護予防 | MF1: 重層K生活支援体制整備対象経費基本額（影響額調整後） | MG1: 重層a生活支援体制整備地域支援事業で実施される包括的支援事業（社会保障充実分）に要する費用 | MH1: 重層K'生活支援体制整備小計（ K + a ） | MI1: 重層L生活支援体制整備基準額 | MJ1: 重層b生活支援体制整備K’とLで、いずれか少ない額 | MK1: 重層M生活支援体制整備交付基本額（ b - a ） | ML1: 重層K'エラー生活支援体制整備 | MM1: 重層bエラー生活支援体制整備 | MN1: 重層Mエラー生活支援体制整備 | MO1: 02基本の上限額 | MP1: 02介護予防給付全体の伸びを考慮する上限額 | MQ1: 02特例イ | MR1: 02特例ロ | MS1: 02原則の上限額 | MT1: 02予防給付＋介護予防等事業の額 | MU1: 02予防給付の額 | MV1: 02予防給付全体の額（移行前年度） | MW1: 02予防給付全体の額（今年度） | MX1: 0275歳人口(平成２３年１０月１日) | MY1: 0275歳人口(平成２４年１０月１日) | MZ1: 0275歳人口(平成２５年１０月１日) | NA1: 0275歳人口(平成２６年１０月１日) | NB1: 0275歳人口(平成２７年１０月１日) | NC1: 0275歳人口(平成２８年１０月１日) | ND1: 0275歳人口(平成２９年１０月１日) | NE1: 0275歳人口(平成３０年１０月１日) | NF1: 0275歳人口(令和元年１０月１日) | NG1: 0275歳人口(令和２年１０月１日) | NH1: 0275歳人口(令和３年１０月１日) | NI1: 0275歳人口(令和４年１０月１日) | NJ1: 025歳人口(令和５年１０月１日) | NK1: 025歳人口(令和６年１０月１日) | NL1: 0275歳以上高齢者伸び率使用値（基本の上限額を算定するにあたって参照する値） | NM1: 0275歳以上高齢者伸び率使用値（特例イ・ロの額を算定するにあたって参照する値） | NN1: 02平成２９年度の介護予防・日常生活支援総合事業費額 | NO1: 02平成29年度の予防給付費額（介護予防訪問介護・介護予防通所介護・介護予防支援の合計額） | NP1: 02平成２９年度の予防給付費額全体 | NQ1: 02対象経費実支出額（清算書D欄） | NR1: 02実績に基づく上限超過額 | NS1: 02個別協議の要否 | NT1: 02個別協議希望の有無 | NU1: 02事前の個別協議を行わない場合の政令で定める上限額 | NV1: 02前年10月１日人口 | NW1: 02前年10月１日65歳以上人口 | NX1: 02交付申請時における事前の個別協議の承認有無 | NY1: 02事由④の該当性 | NZ1: 02上限超過承認希望額（事由④） | OA1: 02高齢者１人あたり事業費 | OB1: 02「離島等の市町村」への該当性 | OC1: 02事由⑤の該当性 | OD1: 02上限超過承認希望額（事由⑤） | OE1: 0275歳以上被保険者数変動率 | OF1: 02将来における介護予防・日常生活支援総合事業に要する費用の低減に資すると見込まれる事業の実施の有無 | OG1: 02前年度における当該③による個別協議の有無 | OH1: 02前年度における上限超過承認額・・・ア | OI1: 02前年10月１日における75歳以上の人口 | OJ1: 02前年10月１日における75歳以上80歳未満人口 | OK1: 02前年10月１日における80歳以上85歳未満人口 | OL1: 02前年10月１日における85歳以上の人口 | OM1: 02前年度の10月１日における75歳以上80歳未満人口を同日における75歳以上人口で除して得た率・・・X1 | ON1: 02前年度の10月１日における80歳以上85歳未満人口を同日における75歳以上人口で除して得た率・・・Y1 | OO1: 02前年度の10月１日における85歳以上人口を同日における75歳以上人口で除して得た率・・・Z1 | OP1: 令和３年10月１日における75歳以上の人口 | OQ1: 02当該年度の初日の属する年の４年前の４月１日の属する年度の10月１日における75歳以上80歳未満人口 | OR1: 02当該年度の初日の属する年の４年前の４月１日の属する年度の10月１日における80歳以上85歳未満人口 | OS1: 02当該年度の初日の属する年の４年前の４月１日の属する年度の10月１日における85歳以上の人口 | OT1: 02当該年度の初日の属する年の４年前の４月１日の属する年度の10月１日における75歳以上80歳未満人口を同日における75歳以上人口で除して得た率・・・X2 | OU1: 02当該年度の初日の属する年の４年前の４月１日の属する年度の10月１日における80歳以上85歳未満人口を同日における75歳以上人口で除して得た率・・・Y2 | OV1: 02当該年度の初日の属する年の４年前の４月１日の属する年度の10月１日における85歳以上人口を同日における75歳以上人口で除して得た率・・・Z2 | OW1: 02 A×0.9×(X1＋Y1×2＋Z1×3)/(X2＋Y2×2＋Z2×3)＋A×0.1－A・・・イ | OX1: 02事由③の該当性 | OY1: 02上限超過承認希望額（事由③） | OZ1: 02介護予防の効果が高く、かつ、将来における介護予防・日常生活支援総合事業に要する費用の低減に資すると見込まれる新たな事業の開始年度 | PA1: 02事由②の該当性（1年度目） | PB1: 02新たなプログラム等の実施に要する額（１年度目の上限超過承認希望額） | PC1: 02前年度における本事由に係る上限超過承認額（２年度目） | PD1: 02当該年度における新たなプログラム等の実施に要する額 | PE1: 02前年度における個別協議の際に申請した当該見込み額 | PF1: 02事由②の該当性（2年度目） | PG1: 02 ２年度目の上限超過承認希望額 | PH1: 02前年度における本事由に係る上限超過承認額（３年度目） | PI1: 02当該年度年度における新たなプログラム等の実施に要する額 | PJ1: 02事由②の該当性（３年度目） | PK1: 02 ３年度目の上限超過承認希望額 | PL1: 02 事由②による上限超過承認希望額 | PM1: 02従前相当サービス以外の第一号訪問事業の対象経費支出予定額 | PN1: 02従前相当サービス以外の第一号通所事業の対象経費支出予定額 | PO1: 02要介護認定又は要支援認定の状況把握 | PP1: 02数の把握 | PQ1: 02認定率（前々年度末日） | PR1: 02サービス利用率（前々年度末日） | PS1: 02認定率（前前々年度末日） | PT1: 02サービス利用率（前前々年度末日） | PU1: 02前々年度の末日における認定率－前々々年度年度の末日における認定率≦０ | PV1: 02前々年度の末日におけるサービス利用率－前々々年度の末日におけるサービス利用率≦０ | PW1: 02調整済み認定率（前々年度末日） | PX1: 02全国の調整済み認定率の平均（前々年度末日） | PY1: 02全国の調整済みサービス利用率の平均（前々年度末日） | PZ1: 02前々年度の末日における調整済み認定率－前々々年度の末日における全国の調整済み認定率の平均≦０ | QA1: 02前々年度の末日における調整済みサービス利用率－前々々年度の末日における全国の調整済みサービス利用率の平均≦０ | QB1: 02事由⑨の該当性 | QC1: 02前々年度の末日に要介護認定を受けていた第１号被保険者であって、前年度の末日に要支援認定を受けている又は要介護認定及び要支援認定のいずれも受けていない者の数 | QD1: 02前年度の介護予防・日常生活支援総合事業のうち従前相当サービスに要する費用の額として、前年度の交付申請に計上した額 | QE1: 02前年度において、従前相当サービスを利用した者の数 | QF1: 02上限超過承認額（事由⑨） | QG1: 02(4)１、(4)２又は(4)３による個別協議を行う場合の上限超過の承認を希望する額 | QH1: 02(4)１、(4)２又は(4)３による個別協議を行う場合の政令で定める上限額 | QI1: 02(4)４のみによる個別協議を行う場合の上限超過の承認を希望する額 | QJ1: 02(4)４のみによる個別協議を行う場合の政令で定める上限額 | QK1: 02(4)５のみによる個別協議を行う場合の上限超過の承認を希望する額 | QL1: 02(4)５のみによる個別協議を行う場合の政令で定める上限額 | QM1: 02事由４による上限超過の承認を希望する額と事由５による上限超過の承認を希望する額の合計 | QN1: 02事由４による上限超過の承認を希望する額と事由５による上限超過の承認を希望する額の合計ー上限超過額 | QO1: 02149行目が０以下である場合の事由４による上限超過の承認を希望する額 | QP1: 02149行目が０以下である場合の事由５による上限超過の承認を希望する額 | QQ1: 02149行目が０以下である場合の政令で定める上限額 | QR1: 02149行目が０を上回る場合、上限超過額ー事由４による上限超過の承認を希望する額 | QS1: 02153行目と147行目のいずれか少ない方の額 | QT1: 02149行目が０を上回る場合の事由４による上限超過の承認を希望する額 | QU1: 02149行目が０を上回る場合の事由５による上限超過の承認を希望する額 | QV1: 02149行目が０を上回る場合の政令で定める上限額 | QW1: 02事前協議後の上限額（原則の上限額及び①～④のうち最も高い金額） | QX1: 02実際の上限超過額（事前協議後の上限超過額：196行目－192行目） | QY1: 02事後の個別協議の要否 | QZ1: 02事後の個別協議希望の有無 | RA1: 02事後の個別協議を行わない場合の政令で定める上限額 | RB1: 02災害による居宅要支援被保険者等の数の増加有無 | RC1: 02ア～ウのうち該当する項目 | RD1: 02ア・イに該当する場合には災害・感染症の名称、ウに該当する場合には具体的な内容 | RE1: 02事由①の該当性 | RF1: 02ア 災害により増加した居宅要支援被保険者等に対して実施した介護予防・日常生活支援総合事業に要した費用の額 | RG1: 02令和７年４月１日から令和７年９月30日における災害等にかかる令和６年度の介護予防・日常生活支援総合事業特別調整交付金の額 | RH1: 02令和７年10月１日から令和８年３月31日における災害等にかかる令和７年度に交付される予定の介護予防・日常生活支援総合事業特別調整交付金の額 | RI1: 02イ 介護保険法第122条の２第２項に規定する交付金の額の算定に関する省令（平成27年厚生労働省令第58号）第７条各号に定める介護予防・日常 生活支援総合事業特別調整交付金の額 | RJ1: 02上限超過承認希望額（事由①） | RK1: 第一号訪問事業介護職員等処遇改善加算(Ⅰ)a | RL1: 第一号訪問事業介護職員等処遇改善加算(Ⅱ)a | RM1: 第一号訪問事業介護職員等処遇改善加算(Ⅲ)a | RN1: 第一号訪問事業介護職員等処遇改善加算(Ⅳ)a | RO1: 第一号通所事業介護職員等処遇改善加算(Ⅰ)a | RP1: 第一号通所事業介護職員等処遇改善加算(Ⅱ)a | RQ1: 第一号通所事業介護職員等処遇改善加算(Ⅲ)a | RR1: 第一号通所事業介護職員等処遇改善加算(Ⅳ)a | RS1: 第一号訪問事業介護職員等処遇改善加算(Ⅰ)c | RT1: 第一号訪問事業介護職員等処遇改善加算(Ⅱ)c | RU1: 第一号訪問事業介護職員等処遇改善加算(Ⅲ)c | RV1: 第一号訪問事業介護職員等処遇改善加算(Ⅳ)c | RW1: 第一号通所事業介護職員等処遇改善加算(Ⅰ)c | RX1: 第一号通所事業介護職員等処遇改善加算(Ⅱ)c | RY1: 第一号通所事業介護職員等処遇改善加算(Ⅲ)c | RZ1: 第一号通所事業介護職員等処遇改善加算(Ⅳ)c | SA1: 02介護職員等処遇改善加算等の支給に要した費用 | SB1: 02事由⑦の該当性 | SC1: 02上限超過承認希望額（事由⑦） | SD1: 02継続利用要介護者に係る第一号訪問事業の実施に要した額 | SE1: 02継続利用要介護者に係る第一号通所事業の実施に要した額 | SF1: 02継続利用要介護者に係る第一号生活支援事業の実施に要した額 | SG1: 02継続利用要介護者に係る第一号介護予防支援事業の実施に要した額 | SH1: 02事由⑧の該当性 | SI1: 02上限超過承認希望額（事由⑧） | SJ1: 02令和３年度における介護予防支援に係る保険給付に要する費用の額 | SK1: 02令和６年度における介護予防支援に係る保険給付に要する費用の額 | SL1: 02令和７年度の介護予防支援費変動率（（252行目/251行目）+1） | SM1: 02令和７年度の介護予防支援費変動率－75歳以上被保険者数変動率（253行目－250行目） | SN1: 02令和７年度における介護予防支援に係る保険給付に要した費用の額 | SO1: 02イ 令和７年度の当該市町村の被保険者に対する介護予防支援に係る保険給付に要する費用の額に令和７年度の介護予防支援費変動率から令和７年度の75歳以上被保険者数変動率を減じて得た数（当該数が０以下である場合は０とする。）を乗じて得た額（254行目×256行目） | SP1: 02ウ 令和７年度の原則の上限額に、本項に定める事由以外の上限額告示及び本通知に定める事由により増加する当該年度の介護予防・日常生活支援総合事業に要する費用の額を加えた額（192行目+217行目+234行目+244行目） | SQ1: 02事由⑥の該当性 | SR1: 02上限超過承認希望額（事由⑥） | SS1: 02事前の個別協議における上限超過承認額 | ST1: 02事後の個別協議における上限超過承認希望額の合計額 | SU1: 02事後の個別協議における上限超過承認希望額 | SV1: 02事後（または事前・事後両方）の個別協議を行う場合の政令で定める上限額 | SW1: 02（うち事前・事後の個別協議における上限超過承認希望額） | SX1: 02令和７年度実績に基づく政令で定める上限額 | SY1: 低減計画H30事業費 | SZ1: 低減計画H30上限超過額 | TA1: 低減計画R1事業費 | TB1: 低減計画R1上限超過額 | TC1: 低減計画R2事業費 | TD1: 低減計画R2上限超過額 | TE1: 低減計画R3事業費 | TF1: 低減計画R3上限超過額 | TG1: 低減計画R4事業費 | TH1: 低減計画R4上限超過額 | TI1: 低減計画R5事業費 | TJ1: 低減計画R5上限超過額 | TK1: 低減計画R6事業費 | TL1: 低減計画R6上限超過額 | TM1: 03①新たなプログラム | TN1: 03②75歳以上被保険者数変動率1以下 | TO1: 03③1万人未満 | TP1: 03④離島 | TQ1: 03⑤効果的な総合事業 | TR1: 03⑥災害 | TS1: 03⑦介護予防支援の増加率＞75歳以上被保険者数変動率 | TT1: 03⑧処遇改善 | TU1: 03⑨継続利用要介護者 | TV1: 031(1)新たなプログラムの類型 | TW1: 031(2)新たなプログラムの開始年度 | TX1: 031(3)新たなプログラムの開始３年度目の事業費（見込額） | TY1: 031(4)新たなプログラムの開始３年度目の翌年度の事業費（見込額） | TZ1: 031(5)開始２年度目の新たなプログラム等の実施に要する額が開始１年度目の当該額を上回る見込みの有無 | UA1: 03費用低減が見込まれる年度 | UB1: 03費用を低減させる方法 | UC1: 03前々年度認定率 | UD1: 03前々年度調整済み認定率 | UE1: 03前々々年度認定率 | UF1: 03前々年度サービス利用率 | UG1: 03前々々年度サービス利用率 | UH1: 03災害による居宅要支援被保険者等の数の増加有無（有の場合に○） | UI1: 03介護予防支援費変動率 | UJ1: 03介護職員等処遇改善加算等の支給に要した費用 | UK1: 03継続利用要介護者に係る第一号事業の実施に要した額 | UL1: 034(1)30事業費 | UM1: 034(1)30個別 | UN1: 034(1)30超過 | UO1: 034(1)１事業費 | UP1: 034(1)１個別 | UQ1: 034(1)１超過 | UR1: 034(1)2事業費 | US1: 034(1)2個別 | UT1: 034(1)2超過 | UU1: 034(1)3事業費 | UV1: 034(1)3個別 | UW1: 034(1)3超過 | UX1: 034(1)4事業費 | UY1: 034(1)4個別 | UZ1: 034(1)4超過 | VA1: 034(1)5事業費 | VB1: 034(1)5個別 | VC1: 034(1)5超過 | VD1: 034(1)6事業費 | VE1: 034(1)6個別 | VF1: 034(1)6超過 | VG1: 034(1)7事業費 | VH1: 034(1)7個別 | VI1: 034(1)7超過 | VJ1: 03(2)３年度目の翌年度には、介護予防・日常生活支援総合事業に要する費用が令和６年度の原則の上限額以下となるための方策（理由①のみ） | VK1: 03（1(5)が○の場合のみ）新たなプログラムを開始した日が１年度目の途中であること又は２年度目以降に新たなプログラムの実施対象地域の拡大を予定していること等の事情により、予め２年度目の新たなプログラム等の実施に要する額が１年度目の当該額を上回ることが見込まれる場合、上回る理由と上回る額 | VL1: 04通し番号1 | VM1: 04市町村名1 | VN1: 04適用する上限式1 | VO1: 04A1 | VP1: 04B1 | VQ1: 04C1 | VR1: 04D1 | VS1: 40 | VT1: 04F1 | VU1: 04G1 | VV1: 04H1 | VW1: 04I1 | VX1: 04J1 | VY1: 04(a)1 | VZ1: 04K1 | WA1: 04(b)1 | WB1: 04(a)、(b)のいずれか高い方の金額1 | WC1: 04上限式適否1 | WD1: 04通し番号2 | WE1: 04市町村名2 | WF1: 04適用する上限式2 | WG1: 04A2 | WH1: 04B2 | WI1: 04C2 | WJ1: 04D2 | WK1: 400 | WL1: 04F2 | WM1: 04G2 | WN1: 04H2 | WO1: 04I2 | WP1: 04J2 | WQ1: 04(a)2 | WR1: 04K2 | WS1: 04(b)2 | WT1: 04(a)、(b)のいずれか高い方の金額2 | WU1: 04上限式適否2 | WV1: 04通し番号3 | WW1: 04市町村名3 | WX1: 04適用する上限式3 | WY1: 04A3 | WZ1: 04B3 | XA1: 04C3 | XB1: 04D3 | XC1: 4000 | XD1: 04F3 | XE1: 04G3 | XF1: 04H3 | XG1: 04I3 | XH1: 04J3 | XI1: 04(a)3 | XJ1: 04K3 | XK1: 04(b)3 | XL1: 04(a)、(b)のいずれか高い方の金額3 | XM1: 04上限式適否3 | XN1: 04通し番号4 | XO1: 04市町村名4 | XP1: 04適用する上限式4 | XQ1: 04A4 | XR1: 04B4 | XS1: 04C4 | XT1: 04D4 | XU1: 40000 | XV1: 04F4 | XW1: 04G4 | XX1: 04H4 | XY1: 04I4 | XZ1: 04J4 | YA1: 04(a)4 | YB1: 04K4 | YC1: 04(b)4 | YD1: 04(a)、(b)のいずれか高い方の金額4 | YE1: 04上限式適否4 | YF1: 04通し番号5 | YG1: 04市町村名5 | YH1: 04適用する上限式5 | YI1: 04A5 | YJ1: 04B5 | YK1: 04C5 | YL1: 04D5 | YM1: 400000 | YN1: 04F5 | YO1: 04G5 | YP1: 04H5 | YQ1: 04I5 | YR1: 04J5 | YS1: 04(a)5 | YT1: 04K5 | YU1: 04(b)5 | YV1: 04(a)、(b)のいずれか高い方の金額5 | YW1: 04上限式適否5 | YX1: 04通し番号6 | YY1: 04市町村名6 | YZ1: 04適用する上限式6 | ZA1: 04A6 | ZB1: 04B6 | ZC1: 04C6 | ZD1: 04D6 | ZE1: 4000000 | ZF1: 04F6 | ZG1: 04G6 | ZH1: 04H6 | ZI1: 04I6 | ZJ1: 04J6 | ZK1: 04(a)6 | ZL1: 04K6 | ZM1: 04(b)6 | ZN1: 04(a)、(b)のいずれか高い方の金額6 | ZO1: 04上限式適否6 | ZP1: 04通し番号7 | ZQ1: 04市町村名7 | ZR1: 04適用する上限式7 | ZS1: 04A7 | ZT1: 04B7 | ZU1: 04C7 | ZV1: 04D7 | ZW1: 40000000 | ZX1: 04F7 | ZY1: 04G7 | ZZ1: 04H7 | AAA1: 04I7 | AAB1: 04J7 | AAC1: 04(a)7 | AAD1: 04K7 | AAE1: 04(b)7 | AAF1: 04(a)、(b)のいずれか高い方の金額7 | AAG1: 04上限式適否7 | AAH1: 04通し番号8 | AAI1: 04市町村名8 | AAJ1: 04適用する上限式8 | AAK1: 04A8 | AAL1: 04B8 | AAM1: 04C8 | AAN1: 04D8 | AAO1: 400000000 | AAP1: 04F8 | AAQ1: 04G8 | AAR1: 04H8 | AAS1: 04I8 | AAT1: 04J8 | AAU1: 04(a)8 | AAV1: 04K8 | AAW1: 04(b)8 | AAX1: 04(a)、(b)のいずれか高い方の金額8 | AAY1: 04上限式適否8 | AAZ1: 04通し番号9 | ABA1: 04市町村名9 | ABB1: 04適用する上限式9 | ABC1: 04A9 | ABD1: 04B9 | ABE1: 04C9 | ABF1: 04D9 | ABG1: 4000000000 | ABH1: 04F9 | ABI1: 04G9 | ABJ1: 04H9 | ABK1: 04I9 | ABL1: 04J9 | ABM1: 04(a)9 | ABN1: 04K9 | ABO1: 04(b)9 | ABP1: 04(a)、(b)のいずれか高い方の金額9 | ABQ1: 04上限式適否9 | ABR1: 04通し番号10 | ABS1: 04市町村名10 | ABT1: 04適用する上限式10 | ABU1: 04A10 | ABV1: 04B10 | ABW1: 04C10 | ABX1: 04D10 | ABY1: 40000000000 | ABZ1: 04F10 | ACA1: 04G10 | ACB1: 04H10 | ACC1: 04I10 | ACD1: 04J10 | ACE1: 04(a)10 | ACF1: 04K10 | ACG1: 04(b)10 | ACH1: 04(a)、(b)のいずれか高い方の金額10 | ACI1: 04上限式適否10 | ACJ1: 04通し番号11 | ACK1: 04市町村名11 | ACL1: 04適用する上限式11 | ACM1: 04A11 | ACN1: 04B11 | ACO1: 04C11 | ACP1: 04D11 | ACQ1: 400000000000 | ACR1: 04F11 | ACS1: 04G11 | ACT1: 04H11 | ACU1: 04I11 | ACV1: 04J11 | ACW1: 04(a)11 | ACX1: 04K11 | ACY1: 04(b)11 | ACZ1: 04(a)、(b)のいずれか高い方の金額11 | ADA1: 04上限式適否11 | ADB1: 04通し番号12 | ADC1: 04市町村名12 | ADD1: 04適用する上限式12 | ADE1: 04A12 | ADF1: 04B12 | ADG1: 04C12 | ADH1: 04D12 | ADI1: 4000000000000 | ADJ1: 04F12 | ADK1: 04G12 | ADL1: 04H12 | ADM1: 04I12 | ADN1: 04J12 | ADO1: 04(a)12 | ADP1: 04K12 | ADQ1: 04(b)12 | ADR1: 04(a)、(b)のいずれか高い方の金額12 | ADS1: 04上限式適否12 | ADT1: 04通し番号13 | ADU1: 04市町村名13 | ADV1: 04適用する上限式13 | ADW1: 04A13 | ADX1: 04B13 | ADY1: 04C13 | ADZ1: 04D13 | AEA1: 40000000000000 | AEB1: 04F13 | AEC1: 04G13 | AED1: 04H13 | AEE1: 04I13 | AEF1: 04J13 | AEG1: 04(a)13 | AEH1: 04K13 | AEI1: 04(b)13 | AEJ1: 04(a)、(b)のいずれか高い方の金額13 | AEK1: 04上限式適否13 | AEL1: 04通し番号14 | AEM1: 04市町村名14 | AEN1: 04適用する上限式14 | AEO1: 04A14 | AEP1: 04B14 | AEQ1: 04C14 | AER1: 04D14 | AES1: 400000000000000 | AET1: 04F14 | AEU1: 04G14 | AEV1: 04H14 | AEW1: 04I14 | AEX1: 04J14 | AEY1: 04(a)14 | AEZ1: 04K14 | AFA1: 04(b)14 | AFB1: 04(a)、(b)のいずれか高い方の金額14 | AFC1: 04上限式適否14 | AFD1: 04通し番号15 | AFE1: 04市町村名15 | AFF1: 04適用する上限式15 | AFG1: 04A15 | AFH1: 04B15 | AFI1: 04C15 | AFJ1: 04D15 | AFK1: 4e+15 | AFL1: 04F15 | AFM1: 04G15 | AFN1: 04H15 | AFO1: 04I15 | AFP1: 04J15 | AFQ1: 04(a)15 | AFR1: 04K15 | AFS1: 04(b)15 | AFT1: 04(a)、(b)のいずれか高い方の金額15 | AFU1: 04上限式適否15 | AFV1: 04通し番号16 | AFW1: 04市町村名16 | AFX1: 04適用する上限式16 | AFY1: 04A16 | AFZ1: 04B16 | AGA1: 04C16 | AGB1: 04D16 | AGC1: 4e+16 | AGD1: 04F16 | AGE1: 04G16 | AGF1: 04H16 | AGG1: 04I16 | AGH1: 04J16 | AGI1: 04(a)16 | AGJ1: 04K16 | AGK1: 04(b)16 | AGL1: 04(a)、(b)のいずれか高い方の金額16 | AGM1: 04上限式適否16 | AGN1: 04通し番号17 | AGO1: 04市町村名17 | AGP1: 04適用する上限式17 | AGQ1: 04A17 | AGR1: 04B17 | AGS1: 04C17 | AGT1: 04D17 | AGU1: 4e+17 | AGV1: 04F17 | AGW1: 04G17 | AGX1: 04H17 | AGY1: 04I17 | AGZ1: 04J17 | AHA1: 04(a)17 | AHB1: 04K17 | AHC1: 04(b)17 | AHD1: 04(a)、(b)のいずれか高い方の金額17 | AHE1: 04上限式適否17 | AHF1: 04通し番号18 | AHG1: 04市町村名18 | AHH1: 04適用する上限式18 | AHI1: 04A18 | AHJ1: 04B18 | AHK1: 04C18 | AHL1: 04D18 | AHM1: 4e+18 | AHN1: 04F18 | AHO1: 04G18 | AHP1: 04H18 | AHQ1: 04I18 | AHR1: 04J18 | AHS1: 04(a)18 | AHT1: 04K18 | AHU1: 04(b)18 | AHV1: 04(a)、(b)のいずれか高い方の金額18 | AHW1: 04上限式適否18 | AHX1: 04通し番号19 | AHY1: 04市町村名19 | AHZ1: 04適用する上限式19 | AIA1: 04A19 | AIB1: 04B19 | AIC1: 04C19 | AID1: 04D19 | AIE1: 4e+19 | AIF1: 04F19 | AIG1: 04G19 | AIH1: 04H19 | AII1: 04I19 | AIJ1: 04J19 | AIK1: 04(a)19 | AIL1: 04K19 | AIM1: 04(b)19 | AIN1: 04(a)、(b)のいずれか高い方の金額19 | AIO1: 04上限式適否19 | AIP1: 04通し番号20 | AIQ1: 04市町村名20 | AIR1: 04適用する上限式20 | AIS1: 04A20 | AIT1: 04B20 | AIU1: 04C20 | AIV1: 04D20 | AIW1: 4e+20 | AIX1: 04F20 | AIY1: 04G20 | AIZ1: 04H20 | AJA1: 04I20 | AJB1: 04J20 | AJC1: 04(a)20 | AJD1: 04K20 | AJE1: 04(b)20 | AJF1: 04(a)、(b)のいずれか高い方の金額20 | AJG1: 04上限式適否20 | AJH1: 04通し番号21 | AJI1: 04市町村名21 | AJJ1: 04適用する上限式21 | AJK1: 04A21 | AJL1: 04B21 | AJM1: 04C21 | AJN1: 04D21 | AJO1: 4e+21 | AJP1: 04F21 | AJQ1: 04G21 | AJR1: 04H21 | AJS1: 04I21 | AJT1: 04J21 | AJU1: 04(a)21 | AJV1: 04K21 | AJW1: 04(b)21 | AJX1: 04(a)、(b)のいずれか高い方の金額21 | AJY1: 04上限式適否21 | AJZ1: 04通し番号22 | AKA1: 04市町村名22 | AKB1: 04適用する上限式22 | AKC1: 04A22 | AKD1: 04B22 | AKE1: 04C22 | AKF1: 04D22 | AKG1: 4e+22 | AKH1: 04F22 | AKI1: 04G22 | AKJ1: 04H22 | AKK1: 04I22 | AKL1: 04J22 | AKM1: 04(a)22 | AKN1: 04K22 | AKO1: 04(b)22 | AKP1: 04(a)、(b)のいずれか高い方の金額22 | AKQ1: 04上限式適否22 | AKR1: 04通し番号23 | AKS1: 04市町村名23 | AKT1: 04適用する上限式23 | AKU1: 04A23 | AKV1: 04B23 | AKW1: 04C23 | AKX1: 04D23 | AKY1: 4e+23 | AKZ1: 04F23 | ALA1: 04G23 | ALB1: 04H23 | ALC1: 04I23 | ALD1: 04J23 | ALE1: 04(a)23 | ALF1: 04K23 | ALG1: 04(b)23 | ALH1: 04(a)、(b)のいずれか高い方の金額23 | ALI1: 04上限式適否23 | ALJ1: 04通し番号24 | ALK1: 04市町村名24 | ALL1: 04適用する上限式24 | ALM1: 04A24 | ALN1: 04B24 | ALO1: 04C24 | ALP1: 04D24 | ALQ1: 4e+24 | ALR1: 04F24 | ALS1: 04G24 | ALT1: 04H24 | ALU1: 04I24 | ALV1: 04J24 | ALW1: 04(a)24 | ALX1: 04K24 | ALY1: 04(b)24 | ALZ1: 04(a)、(b)のいずれか高い方の金額24 | AMA1: 04上限式適否24 | AMB1: 04通し番号25 | AMC1: 04市町村名25 | AMD1: 04適用する上限式25 | AME1: 04A25 | AMF1: 04B25 | AMG1: 04C25 | AMH1: 04D25 | AMI1: 4e+25 | AMJ1: 04F25 | AMK1: 04G25 | AML1: 04H25 | AMM1: 04I25 | AMN1: 04J25 | AMO1: 04(a)25 | AMP1: 04K25 | AMQ1: 04(b)25 | AMR1: 04(a)、(b)のいずれか高い方の金額25 | AMS1: 04上限式適否25 | AMT1: 04通し番号26 | AMU1: 04市町村名26 | AMV1: 04適用する上限式26 | AMW1: 04A26 | AMX1: 04B26 | AMY1: 04C26 | AMZ1: 04D26 | ANA1: 4e+26 | ANB1: 04F26 | ANC1: 04G26 | AND1: 04H26 | ANE1: 04I26 | ANF1: 04J26 | ANG1: 04(a)26 | ANH1: 04K26 | ANI1: 04(b)26 | ANJ1: 04(a)、(b)のいずれか高い方の金額26 | ANK1: 04上限式適否26 | ANL1: 04通し番号27 | ANM1: 04市町村名27 | ANN1: 04適用する上限式27 | ANO1: 04A27 | ANP1: 04B27 | ANQ1: 04C27 | ANR1: 04D27 | ANS1: 4e+27 | ANT1: 04F27 | ANU1: 04G27 | ANV1: 04H27 | ANW1: 04I27 | ANX1: 04J27 | ANY1: 04(a)27 | ANZ1: 04K27 | AOA1: 04(b)27 | AOB1: 04(a)、(b)のいずれか高い方の金額27 | AOC1: 04上限式適否27 | AOD1: 04通し番号28 | AOE1: 04市町村名28 | AOF1: 04適用する上限式28 | AOG1: 04A28 | AOH1: 04B28 | AOI1: 04C28 | AOJ1: 04D28 | AOK1: 4e+28 | AOL1: 04F28 | AOM1: 04G28 | AON1: 04H28 | AOO1: 04I28 | AOP1: 04J28 | AOQ1: 04(a)28 | AOR1: 04K28 | AOS1: 04(b)28 | AOT1: 04(a)、(b)のいずれか高い方の金額28 | AOU1: 04上限式適否28 | AOV1: 04通し番号29 | AOW1: 04市町村名29 | AOX1: 04適用する上限式29 | AOY1: 04A29 | AOZ1: 04B29 | APA1: 04C29 | APB1: 04D29 | APC1: 4e+29 | APD1: 04F29 | APE1: 04G29 | APF1: 04H29 | APG1: 04I29 | APH1: 04J29 | API1: 04(a)29 | APJ1: 04K29 | APK1: 04(b)29 | APL1: 04(a)、(b)のいずれか高い方の金額29 | APM1: 04上限式適否29 | APN1: 04通し番号30 | APO1: 04市町村名30 | APP1: 04適用する上限式30 | APQ1: 04A30 | APR1: 04B30 | APS1: 04C30 | APT1: 04D30 | APU1: 4e+30 | APV1: 04F30 | APW1: 04G30 | APX1: 04H30 | APY1: 04I30 | APZ1: 04J30 | AQA1: 04(a)30 | AQB1: 04K30 | AQC1: 04(b)30 | AQD1: 04(a)、(b)のいずれか高い方の金額30 | AQE1: 04上限式適否30 | AQF1: 04通し番号31 | AQG1: 04市町村名31 | AQH1: 04適用する上限式31 | AQI1: 04A31 | AQJ1: 04B31 | AQK1: 04C31 | AQL1: 04D31 | AQM1: 4e+31 | AQN1: 04F31 | AQO1: 04G31 | AQP1: 04H31 | AQQ1: 04I31 | AQR1: 04J31 | AQS1: 04(a)31 | AQT1: 04K31 | AQU1: 04(b)31 | AQV1: 04(a)、(b)のいずれか高い方の金額31 | AQW1: 04上限式適否31 | AQX1: 04通し番号32 | AQY1: 04市町村名32 | AQZ1: 04適用する上限式32 | ARA1: 04A32 | ARB1: 04B32 | ARC1: 04C32 | ARD1: 04D32 | ARE1: 4e+32 | ARF1: 04F32 | ARG1: 04G32 | ARH1: 04H32 | ARI1: 04I32 | ARJ1: 04J32 | ARK1: 04(a)32 | ARL1: 04K32 | ARM1: 04(b)32 | ARN1: 04(a)、(b)のいずれか高い方の金額32 | ARO1: 04上限式適否32 | ARP1: 04通し番号33 | ARQ1: 04市町村名33 | ARR1: 04適用する上限式33 | ARS1: 04A33 | ART1: 04B33 | ARU1: 04C33 | ARV1: 04D33 | ARW1: 4e+33 | ARX1: 04F33 | ARY1: 04G33 | ARZ1: 04H33 | ASA1: 04I33 | ASB1: 04J33 | ASC1: 04(a)33 | ASD1: 04K33 | ASE1: 04(b)33 | ASF1: 04(a)、(b)のいずれか高い方の金額33 | ASG1: 04上限式適否33 | ASH1: 04通し番号34 | ASI1: 04市町村名34 | ASJ1: 04適用する上限式34 | ASK1: 04A34 | ASL1: 04B34 | ASM1: 04C34 | ASN1: 04D34 | ASO1: 4e+34 | ASP1: 04F34 | ASQ1: 04G34 | ASR1: 04H34 | ASS1: 04I34 | AST1: 04J34 | ASU1: 04(a)34 | ASV1: 04K34 | ASW1: 04(b)34 | ASX1: 04(a)、(b)のいずれか高い方の金額34 | ASY1: 04上限式適否34 | ASZ1: 05①総事業費 | ATA1: 05②対象経費額（様式１B欄） | ATB1: 05③寄付金その他の収入額 | ATC1: 05④指定介護予防支援等にかかる収入額 | ATD1: 05⑤総合相談支援事業の一部委託にかかる委託費 | ATE1: 05⑥委託費を除いた総事業費 | ATF1: 05⑦様式１A欄 | ATG1: 05⑧様式１C欄 | ATH1: 05⑩様式１D欄 | ATI1: 05設置する地域包括支援センター数 | ATJ1: 06地域包括支援センター数 | ATK1: 06日常生活圏域数 | ATL1: 06専任の認知症地域支援推進員 | ATM1: 06第１層(市町村圏域）の数 | ATN1: 06行政区数 | ATO1: 06構成市町村数 | ATP1: 06（広域）専任の認知症地域支援推進員 | ATQ1: 06在宅医療・介護連携推進事業の実施 | ATR1: 06生活支援コーディネーター・協議体の実施 | ATS1: 06相談支援連携体制構築事業の実施 | ATT1: 06住民参画・官民連携推進事業の実施 | ATU1: 06就労的活動支援コーディネーターの実施 | ATV1: 06認知症初期集中支援事業の実施 | ATW1: 06認知症地域支援・ケア向上事業の実施 | ATX1: 06認知症サポーター活動促進・地域づくり推進事業の実施 | ATY1: 06地域ケア会議推進事業の実施 | ATZ1: 06居住支援連携の実施 | AUA1: 06標準額 | AUB1: 06個別協議額 | AUC1: 06在宅医療・介護連携推進事業標準額 | AUD1: 06生活支援コーディネーター・協議体標準額 | AUE1: 06相談支援連携体制構築事業標準額 | AUF1: 06住民参画・官民連携推進事業標準額 | AUG1: 06就労的活動支援コーディネーター標準額 | AUH1: 06認知症初期集中支援事業標準額 | AUI1: 06認知症地域支援・ケア向上事業標準額 | AUJ1: 06認知症サポーター活動促進・地域づくり推進事業標準額 | AUK1: 06地域ケア会議推進事業標準額 | AUL1: 06（再掲）居住支援加算標準額 | AUM1: 06【令和６年度包括的支援事業（社会保障充実分）上限額設定】 | AUN1: 06エラー | AUO1: 06-1（一般市町村）SCをセンターに配置 | AUP1: 06-1（指定都市）実施行政区数 | AUQ1: 06-1（指定都市）うちSCをセンターに配置している数 | AUR1: 06-1（広域）実施構成市町村数 | AUS1: 06-1（広域）うちSCをセンターに配置している数 | AUT1: 06-1（広域）うち重層実施数 | AUU1: 06-2（指定都市）連携体制構築されている行政区数 | AUV1: 06-2（広域）連携体制構築されている構成市町村数 | AUW1: 07社会保障充実分対象経費額 | AUX1: 07標準額 | AUY1: 07①在宅医療・介護連携推進対象経費額 | AUZ1: 07①ア（イ）等の会議 | AVA1: 07①イ（ア）の相談窓口 | AVB1: 07①イ（ア）のコーディネーター | AVC1: 07①イ（ウ）②多職種研修 | AVD1: 07①イ（ウ）②その他の研修 | AVE1: 07②生活支援体制整備対象経費額 | AVF1: 07②第１層生活支援コーディネーター | AVG1: 07②第２層生活支援コーディネーター | AVH1: 07②住民参画・官民連携推進事業 | AVI1: 07②生活支援コーディネーターを中心とした相談支援連携体制構築事業 | AVJ1: 07②就労的活動支援コーディネーター | AVK1: 07③認知症総合支援対象経費額 | AVL1: 07③認知症初期集中支援チーム設置 | AVM1: 07③認知症地域支援推進員設置 | AVN1: 07③うち専任の認知症地域支援推進員 | AVO1: 07③チームオレンジコーディネーター | AVP1: 07④地域ケア会議推進事業対象経費額 | AVQ1: 07④地域ケア個別会議 | AVR1: 07④居住支援連携 | AVS1: 08①対象経費額 | AVT1: 08①事業内容 | AVU1: 08①効果 | AVV1: 08②対象経費額 | AVW1: 08②事業内容 | AVX1: 08②効果 | AVY1: 08③対象経費額 | AVZ1: 08③事業内容 | AWA1: 08③効果 | AWB1: 08④対象経費額 | AWC1: 08④事業内容 | AWD1: 08④効果 | AWE1: 08⑤対象経費額 | AWF1: 08⑤事業内容 | AWG1: 08⑤効果 | AWH1: 08⑥対象経費額 | AWI1: 08⑥事業内容 | AWJ1: 08⑥効果 | AWK1: 08⑦対象経費額 | AWL1: 08⑦事業内容 | AWM1: 08⑦効果 | AWN1: 08⑧対象経費額 | AWO1: 08⑧事業内容 | AWP1: 08⑧効果 | AWQ1: 08⑨対象経費額 | AWR1: 08⑨事業内容 | AWS1: 08⑨効果 | AWT1: 08⑩対象経費額 | AWU1: 08⑩事業内容 | AWV1: 08⑩効果 | AWW1: 08⑪対象経費額 | AWX1: 08⑪事業内容 | AWY1: 08⑪効果 | AWZ1: 08⑫対象経費額 | AXA1: 08⑫事業内容 | AXB1: 08⑫効果 | AXC1: 08⑬対象経費額 | AXD1: 08⑬事業内容 | AXE1: 08⑬効果 | AXF1: 08⑭対象経費額 | AXG1: 08⑭事業内容 | AXH1: 08⑭効果 | AXI1: 08⑮対象経費額 | AXJ1: 08⑮事業内容 | AXK1: 08⑮効果 | AXL1: 08⑯対象経費額 | AXM1: 08⑯事業内容 | AXN1: 08⑯効果 | AXO1: 08⑰対象経費額 | AXP1: 08⑰事業内容 | AXQ1: 08⑰効果 | AXR1: 08⑱対象経費額 | AXS1: 08⑱事業内容 | AXT1: 08⑱効果 | AXU1: 08⑲対象経費額 | AXV1: 08⑲事業内容 | AXW1: 08⑲効果 | AXX1: 08⑳対象経費額 | AXY1: 08⑳事業内容 | AXZ1: 08⑳効果 | AYA1: 08㉑対象経費額 | AYB1: 08㉑事業内容 | AYC1: 08㉑効果 | AYD1: 08事業名（特区等） | AYE1: 08対象経費額（特区等） | AYF1: 08事業内容（特区等） | AYG1: 08効果（特区等） | AYH1: 08合計 | AYI1: 保険者No | AYJ1: 市町村 | AYK1: 有 | AYL1: (1)R2対象経費支出予定額 | AYM1: (1)R3対象経費支出予定額 | AYN1: (1)R4対象経費支出予定額 | AYO1: (1)R5対象経費支出予定額 | AYP1: (1)R6対象経費支出予定額 | AYQ1: (2)交付上限額 | AYR1: (3)やむを得ない事情の場合の交付上限額 | AYS1: (4)①下方変動 | AYT1: (4)①上方変動 | AYU1: (4)①その他 | AYV1: (4)②その他の内容 | AYW1: 介護用品上限 | AYX1: (5)合計人数 | AYY1: (5)人数（地域支援事業） | AYZ1: (5)人数（市町村特別給付） | AZA1: (5)人数（保健福祉事業） | AZB1: (5)人数（一般財源） | AZC1: (5)合計額 | AZD1: (5)支出予定額（地域支援事業） | AZE1: (5)支出予定額（市町村特別給付） | AZF1: (5)支出予定額（保健福祉事業） | AZG1: (5)支出予定額（一般財源） | AZH1: （６）①支給予定人数計 | AZI1: (6)①第１～３段階（要介護５） | AZJ1: (6)①第４段階（要介護５） | AZK1: (6)①第５段階（要介護５） | AZL1: (6)①第１～３段階（要介護４） | AZM1: (6)①第４段階（要介護４） | AZN1: (6)①第５段階（要介護４） | AZO1: (6)①第１～３段階（要介護３） | AZP1: (6)①第４段階（要介護３） | AZQ1: (6)①第５段階（要介護３） | AZR1: (6)①第１～３段階（要介護１～２） | AZS1: (6)①第４段階（要介護１～２） | AZT1: (6)①第５段階（要介護１～２） | AZU1: (6)①第１～３段階（要支援１～２） | AZV1: (6)①第４段階（要支援１～２） | AZW1: (6)①第５段階（要支援１～２） | AZX1: (6)①第１～３段階（事業対象者） | AZY1: (6)①第４段階（事業対象者） | AZZ1: (6)①第５段階（事業対象者） | BAA1: (6)②一人当たり支給上限額 | BAB1: (6)②詳細 | BAC1: (6)③交付希望額 | BAD1: R6廃止・縮小 | BAE1: R6具体的な取組（縮小） | BAF1: R6廃止後の移行先等 | BAG1: R7廃止・縮小 | BAH1: R7具体的な取組（縮小） | BAI1: R7廃止後の移行先等 | BAJ1: R8廃止・縮小 | BAK1: R8具体的な取組（縮小） | BAL1: R8廃止後の移行先等 | BAM1: （介護用品）任意事業計画書に転記する額 | BAN1: 介護用品上限額 | BAO1: 介護用品やむを得ない場合の上限額 | BAP1: 別紙様式４番号 | BAQ1: 別紙様式２日付 | BAR1: 別紙様式２職氏名
A2: =#REF! -> #REF! | B2: =#REF! -> #REF! | C2: =#REF! -> #REF! | D2: =#REF! -> #REF! | E2: =#REF! -> #REF! | F2: =#REF! -> #REF! | G2: =#REF! -> #REF! | H2: =#REF! -> #REF! | ... VK2: =#REF! -> #REF! | VL2: ='（参考）包括・任意事業の上限額算定の手引き'!$E5 | VM2: ='（参考）包括・任意事業の上限額算定の手引き'!$E6 | VN2: ='（参考）包括・任意事業の上限額算定の手引き'!$E7 -> ①原則の上限額 | VO2: ='（参考）包括・任意事業の上限額算定の手引き'!$E10 -> 24076130 | VP2: ='（参考）包括・任意事業の上限額算定の手引き'!$E11 -> 3464 | VQ2: ='（参考）包括・任意事業の上限額算定の手引き'!$E12 -> 3497 | VR2: ='（参考）包括・任意事業の上限額算定の手引き'!$E13 -> 1.0032 | VS2: ='（参考）包括・任意事業の上限額算定の手引き'!$E14 -> 24153173 | VT2: ='（参考）包括・任意事業の上限額算定の手引き'!$E17 -> 3497 | VU2: ='（参考）包括・任意事業の上限額算定の手引き'!$E18 -> 19427777 | VV2: ='（参考）包括・任意事業の上限額算定の手引き'!$E19 -> 3252210 | VW2: ='（参考）包括・任意事業の上限額算定の手引き'!$E20 -> 22679987 | VX2: ='（参考）包括・任意事業の上限額算定の手引き'!$E25 -> #REF! | VY2: ='（参考）包括・任意事業の上限額算定の手引き'!$E26 -> 3252210 | VZ2: ='（参考）包括・任意事業の上限額算定の手引き'!$E27 -> 0 | WA2: ='（参考）包括・任意事業の上限額算定の手引き'!$E28 -> 0 | WB2: ='（参考）包括・任意事業の上限額算定の手引き'!$E29 -> 3252210 | WC2: ='（参考）包括・任意事業の上限額算定の手引き'!$E30 -> #REF! | WD2: ='（参考）包括・任意事業の上限額算定の手引き'!$G5 | WE2: ='（参考）包括・任意事業の上限額算定の手引き'!$G6 | WF2: ='（参考）包括・任意事業の上限額算定の手引き'!$G7 -> 0 | WG2: ='（参考）包括・任意事業の上限額算定の手引き'!$G10 -> 0 | WH2: ='（参考）包括・任意事業の上限額算定の手引き'!$G11 -> 0 | WI2: ='（参考）包括・任意事業の上限額算定の手引き'!$G12 -> 0 | WJ2: ='（参考）包括・任意事業の上限額算定の手引き'!$G13 | WK2: ='（参考）包括・任意事業の上限額算定の手引き'!$G14 -> 0 | WL2: ='（参考）包括・任意事業の上限額算定の手引き'!$G17 -> 0 | WM2: ='（参考）包括・任意事業の上限額算定の手引き'!$G18 -> 0 | WN2: ='（参考）包括・任意事業の上限額算定の手引き'!$G19 -> 0 | WO2: ='（参考）包括・任意事業の上限額算定の手引き'!$G20 -> 0 | WP2: ='（参考）包括・任意事業の上限額算定の手引き'!$G25 -> 0 | WQ2: ='（参考）包括・任意事業の上限額算定の手引き'!$G26 -> 0 | WR2: ='（参考）包括・任意事業の上限額算定の手引き'!$G27 -> 0 | WS2: ='（参考）包括・任意事業の上限額算定の手引き'!$G28 -> 0 | WT2: ='（参考）包括・任意事業の上限額算定の手引き'!$G29 -> 0 | WU2: ='（参考）包括・任意事業の上限額算定の手引き'!$G30 -> × | WV2: ='（参考）包括・任意事業の上限額算定の手引き'!$I5 | WW2: ='（参考）包括・任意事業の上限額算定の手引き'!$I6 | WX2: ='（参考）包括・任意事業の上限額算定の手引き'!$I7 -> 0 | WY2: ='（参考）包括・任意事業の上限額算定の手引き'!$I10 -> 0 | WZ2: ='（参考）包括・任意事業の上限額算定の手引き'!$I11 -> 0 | XA2: ='（参考）包括・任意事業の上限額算定の手引き'!$I12 -> 0 | XB2: ='（参考）包括・任意事業の上限額算定の手引き'!$I13 | XC2: ='（参考）包括・任意事業の上限額算定の手引き'!$I14 -> 0 | XD2: ='（参考）包括・任意事業の上限額算定の手引き'!$I17 -> 0 | XE2: ='（参考）包括・任意事業の上限額算定の手引き'!$I18 -> 0 | XF2: ='（参考）包括・任意事業の上限額算定の手引き'!$I19 -> 0 | XG2: ='（参考）包括・任意事業の上限額算定の手引き'!$I20 -> 0 | XH2: ='（参考）包括・任意事業の上限額算定の手引き'!$I25 -> 0 | XI2: ='（参考）包括・任意事業の上限額算定の手引き'!$I26 -> 0 | XJ2: ='（参考）包括・任意事業の上限額算定の手引き'!$I27 -> 0 | XK2: ='（参考）包括・任意事業の上限額算定の手引き'!$I28 -> 0 | XL2: ='（参考）包括・任意事業の上限額算定の手引き'!$I29 -> 0 | XM2: ='（参考）包括・任意事業の上限額算定の手引き'!$I30 -> × | XN2: ='（参考）包括・任意事業の上限額算定の手引き'!$K5 | XO2: ='（参考）包括・任意事業の上限額算定の手引き'!$K6 | XP2: ='（参考）包括・任意事業の上限額算定の手引き'!$K7 -> 0 | XQ2: ='（参考）包括・任意事業の上限額算定の手引き'!$K10 -> 0 | XR2: ='（参考）包括・任意事業の上限額算定の手引き'!$K11 -> 0 | XS2: ='（参考）包括・任意事業の上限額算定の手引き'!$K12 -> 0 | XT2: ='（参考）包括・任意事業の上限額算定の手引き'!$K13 | XU2: ='（参考）包括・任意事業の上限額算定の手引き'!$K14 -> 0 | XV2: ='（参考）包括・任意事業の上限額算定の手引き'!$K17 -> 0 | XW2: ='（参考）包括・任意事業の上限額算定の手引き'!$K18 -> 0 | XX2: ='（参考）包括・任意事業の上限額算定の手引き'!$K19 -> 0 | XY2: ='（参考）包括・任意事業の上限額算定の手引き'!$K20 -> 0 | XZ2: ='（参考）包括・任意事業の上限額算定の手引き'!$K25 -> 0 | YA2: ='（参考）包括・任意事業の上限額算定の手引き'!$K26 -> 0 | YB2: ='（参考）包括・任意事業の上限額算定の手引き'!$K27 -> 0 | YC2: ='（参考）包括・任意事業の上限額算定の手引き'!$K28 -> 0 | YD2: ='（参考）包括・任意事業の上限額算定の手引き'!$K29 -> 0 | YE2: ='（参考）包括・任意事業の上限額算定の手引き'!$K30 -> × | YF2: ='（参考）包括・任意事業の上限額算定の手引き'!$M5 | YG2: ='（参考）包括・任意事業の上限額算定の手引き'!$M6 | YH2: ='（参考）包括・任意事業の上限額算定の手引き'!$M7 -> 0 | YI2: ='（参考）包括・任意事業の上限額算定の手引き'!$M10 -> 0 | YJ2: ='（参考）包括・任意事業の上限額算定の手引き'!$M11 -> 0 | YK2: ='（参考）包括・任意事業の上限額算定の手引き'!$M12 -> 0 | YL2: ='（参考）包括・任意事業の上限額算定の手引き'!$M13 | YM2: ='（参考）包括・任意事業の上限額算定の手引き'!$M14 -> 0 | YN2: ='（参考）包括・任意事業の上限額算定の手引き'!$M17 -> 0 | YO2: ='（参考）包括・任意事業の上限額算定の手引き'!$M18 -> 0 | YP2: ='（参考）包括・任意事業の上限額算定の手引き'!$M19 -> 0 | YQ2: ='（参考）包括・任意事業の上限額算定の手引き'!$M20 -> 0 | YR2: ='（参考）包括・任意事業の上限額算定の手引き'!$M25 -> 0 | YS2: ='（参考）包括・任意事業の上限額算定の手引き'!$M26 -> 0 | YT2: ='（参考）包括・任意事業の上限額算定の手引き'!$M27 -> 0 | YU2: ='（参考）包括・任意事業の上限額算定の手引き'!$M28 -> 0 | YV2: ='（参考）包括・任意事業の上限額算定の手引き'!$M29 -> 0 | YW2: ='（参考）包括・任意事業の上限額算定の手引き'!$M30 -> × | YX2: ='（参考）包括・任意事業の上限額算定の手引き'!$O5 | YY2: ='（参考）包括・任意事業の上限額算定の手引き'!$O6 | YZ2: ='（参考）包括・任意事業の上限額算定の手引き'!$O7 -> 0 | ZA2: ='（参考）包括・任意事業の上限額算定の手引き'!$O10 -> 0 | ZB2: ='（参考）包括・任意事業の上限額算定の手引き'!$O11 -> 0 | ZC2: ='（参考）包括・任意事業の上限額算定の手引き'!$O12 -> 0 | ZD2: ='（参考）包括・任意事業の上限額算定の手引き'!$O13 | ZE2: ='（参考）包括・任意事業の上限額算定の手引き'!$O14 -> 0 | ZF2: ='（参考）包括・任意事業の上限額算定の手引き'!$O17 -> 0 | ZG2: ='（参考）包括・任意事業の上限額算定の手引き'!$O18 -> 0 | ZH2: ='（参考）包括・任意事業の上限額算定の手引き'!$O19 -> 0 | ZI2: ='（参考）包括・任意事業の上限額算定の手引き'!$O20 -> 0 | ZJ2: ='（参考）包括・任意事業の上限額算定の手引き'!$O25 -> 0 | ZK2: ='（参考）包括・任意事業の上限額算定の手引き'!$O26 -> 0 | ZL2: ='（参考）包括・任意事業の上限額算定の手引き'!$O27 -> 0 | ZM2: ='（参考）包括・任意事業の上限額算定の手引き'!$O28 -> 0 | ZN2: ='（参考）包括・任意事業の上限額算定の手引き'!$O29 -> 0 | ZO2: ='（参考）包括・任意事業の上限額算定の手引き'!$O30 -> × | ZP2: ='（参考）包括・任意事業の上限額算定の手引き'!$Q5 | ZQ2: ='（参考）包括・任意事業の上限額算定の手引き'!$Q6 | ZR2: ='（参考）包括・任意事業の上限額算定の手引き'!$Q7 -> 0 | ZS2: ='（参考）包括・任意事業の上限額算定の手引き'!$Q10 -> 0 | ZT2: ='（参考）包括・任意事業の上限額算定の手引き'!$Q11 -> 0 | ZU2: ='（参考）包括・任意事業の上限額算定の手引き'!$Q12 -> 0 | ZV2: ='（参考）包括・任意事業の上限額算定の手引き'!$Q13 | ZW2: ='（参考）包括・任意事業の上限額算定の手引き'!$Q14 -> 0 | ZX2: ='（参考）包括・任意事業の上限額算定の手引き'!$Q17 -> 0 | ZY2: ='（参考）包括・任意事業の上限額算定の手引き'!$Q18 -> 0 | ZZ2: ='（参考）包括・任意事業の上限額算定の手引き'!$Q19 -> 0 | AAA2: ='（参考）包括・任意事業の上限額算定の手引き'!$Q20 -> 0 | AAB2: ='（参考）包括・任意事業の上限額算定の手引き'!$Q25 -> 0 | AAC2: ='（参考）包括・任意事業の上限額算定の手引き'!$Q26 -> 0 | AAD2: ='（参考）包括・任意事業の上限額算定の手引き'!$Q27 -> 0 | AAE2: ='（参考）包括・任意事業の上限額算定の手引き'!$Q28 -> 0 | AAF2: ='（参考）包括・任意事業の上限額算定の手引き'!$Q29 -> 0 | AAG2: ='（参考）包括・任意事業の上限額算定の手引き'!$Q30 -> × | AAH2: ='（参考）包括・任意事業の上限額算定の手引き'!$S5 | AAI2: ='（参考）包括・任意事業の上限額算定の手引き'!$S6 | AAJ2: ='（参考）包括・任意事業の上限額算定の手引き'!$S7 -> 0 | AAK2: ='（参考）包括・任意事業の上限額算定の手引き'!$S10 -> 0 | AAL2: ='（参考）包括・任意事業の上限額算定の手引き'!$S11 -> 0 | AAM2: ='（参考）包括・任意事業の上限額算定の手引き'!$S12 -> 0 | AAN2: ='（参考）包括・任意事業の上限額算定の手引き'!$S13 | AAO2: ='（参考）包括・任意事業の上限額算定の手引き'!$S14 -> 0 | AAP2: ='（参考）包括・任意事業の上限額算定の手引き'!$S17 -> 0 | AAQ2: ='（参考）包括・任意事業の上限額算定の手引き'!$S18 -> 0 | AAR2: ='（参考）包括・任意事業の上限額算定の手引き'!$S19 -> 0 | AAS2: ='（参考）包括・任意事業の上限額算定の手引き'!$S20 -> 0 | AAT2: ='（参考）包括・任意事業の上限額算定の手引き'!$S25 -> 0 | AAU2: ='（参考）包括・任意事業の上限額算定の手引き'!$S26 -> 0 | AAV2: ='（参考）包括・任意事業の上限額算定の手引き'!$S27 -> 0 | AAW2: ='（参考）包括・任意事業の上限額算定の手引き'!$S28 -> 0 | AAX2: ='（参考）包括・任意事業の上限額算定の手引き'!$S29 -> 0 | AAY2: ='（参考）包括・任意事業の上限額算定の手引き'!$S30 -> × | AAZ2: ='（参考）包括・任意事業の上限額算定の手引き'!$U5 | ABA2: ='（参考）包括・任意事業の上限額算定の手引き'!$U6 | ABB2: ='（参考）包括・任意事業の上限額算定の手引き'!$U7 -> 0 | ABC2: ='（参考）包括・任意事業の上限額算定の手引き'!$U10 -> 0 | ABD2: ='（参考）包括・任意事業の上限額算定の手引き'!$U11 -> 0 | ABE2: ='（参考）包括・任意事業の上限額算定の手引き'!$U12 -> 0 | ABF2: ='（参考）包括・任意事業の上限額算定の手引き'!$U13 | ABG2: ='（参考）包括・任意事業の上限額算定の手引き'!$U14 -> 0 | ABH2: ='（参考）包括・任意事業の上限額算定の手引き'!$U17 -> 0 | ABI2: ='（参考）包括・任意事業の上限額算定の手引き'!$U18 -> 0 | ABJ2: ='（参考）包括・任意事業の上限額算定の手引き'!$U19 -> 0 | ABK2: ='（参考）包括・任意事業の上限額算定の手引き'!$U20 -> 0 | ABL2: ='（参考）包括・任意事業の上限額算定の手引き'!$U25 -> 0 | ABM2: ='（参考）包括・任意事業の上限額算定の手引き'!$U26 -> 0 | ABN2: ='（参考）包括・任意事業の上限額算定の手引き'!$U27 -> 0 | ABO2: ='（参考）包括・任意事業の上限額算定の手引き'!$U28 -> 0 | ABP2: ='（参考）包括・任意事業の上限額算定の手引き'!$U29 -> 0 | ABQ2: ='（参考）包括・任意事業の上限額算定の手引き'!$U30 -> × | ABR2: ='（参考）包括・任意事業の上限額算定の手引き'!$W5 | ABS2: ='（参考）包括・任意事業の上限額算定の手引き'!$W6 | ABT2: ='（参考）包括・任意事業の上限額算定の手引き'!$W7 -> 0 | ABU2: ='（参考）包括・任意事業の上限額算定の手引き'!$W10 -> 0 | ABV2: ='（参考）包括・任意事業の上限額算定の手引き'!$W11 -> 0 | ABW2: ='（参考）包括・任意事業の上限額算定の手引き'!$W12 -> 0 | ABX2: ='（参考）包括・任意事業の上限額算定の手引き'!$W13 | ABY2: ='（参考）包括・任意事業の上限額算定の手引き'!$W14 -> 0 | ABZ2: ='（参考）包括・任意事業の上限額算定の手引き'!$W17 -> 0 | ACA2: ='（参考）包括・任意事業の上限額算定の手引き'!$W18 -> 0 | ACB2: ='（参考）包括・任意事業の上限額算定の手引き'!$W19 -> 0 | ACC2: ='（参考）包括・任意事業の上限額算定の手引き'!$W20 -> 0 | ACD2: ='（参考）包括・任意事業の上限額算定の手引き'!$W25 -> 0 | ACE2: ='（参考）包括・任意事業の上限額算定の手引き'!$W26 -> 0 | ACF2: ='（参考）包括・任意事業の上限額算定の手引き'!$W27 -> 0 | ACG2: ='（参考）包括・任意事業の上限額算定の手引き'!$W28 -> 0 | ACH2: ='（参考）包括・任意事業の上限額算定の手引き'!$W29 -> 0 | ACI2: ='（参考）包括・任意事業の上限額算定の手引き'!$W30 -> × | ACJ2: ='（参考）包括・任意事業の上限額算定の手引き'!$Y5 | ACK2: ='（参考）包括・任意事業の上限額算定の手引き'!$Y6 | ACL2: ='（参考）包括・任意事業の上限額算定の手引き'!$Y7 -> 0 | ACM2: ='（参考）包括・任意事業の上限額算定の手引き'!$Y10 -> 0 | ACN2: ='（参考）包括・任意事業の上限額算定の手引き'!$Y11 -> 0 | ACO2: ='（参考）包括・任意事業の上限額算定の手引き'!$Y12 -> 0 | ACP2: ='（参考）包括・任意事業の上限額算定の手引き'!$Y13 | ACQ2: ='（参考）包括・任意事業の上限額算定の手引き'!$Y14 -> 0 | ACR2: ='（参考）包括・任意事業の上限額算定の手引き'!$Y17 -> 0 | ACS2: ='（参考）包括・任意事業の上限額算定の手引き'!$Y18 -> 0 | ACT2: ='（参考）包括・任意事業の上限額算定の手引き'!$Y19 -> 0 | ACU2: ='（参考）包括・任意事業の上限額算定の手引き'!$Y20 -> 0 | ACV2: ='（参考）包括・任意事業の上限額算定の手引き'!$Y25 -> 0 | ACW2: ='（参考）包括・任意事業の上限額算定の手引き'!$Y26 -> 0 | ACX2: ='（参考）包括・任意事業の上限額算定の手引き'!$Y27 -> 0 | ACY2: ='（参考）包括・任意事業の上限額算定の手引き'!$Y28 -> 0 | ACZ2: ='（参考）包括・任意事業の上限額算定の手引き'!$Y29 -> 0 | ADA2: ='（参考）包括・任意事業の上限額算定の手引き'!$Y30 -> × | ADB2: ='（参考）包括・任意事業の上限額算定の手引き'!$AA5 | ADC2: ='（参考）包括・任意事業の上限額算定の手引き'!$AA6 | ADD2: ='（参考）包括・任意事業の上限額算定の手引き'!$AA7 -> 0 | ADE2: ='（参考）包括・任意事業の上限額算定の手引き'!$AA10 -> 0 | ADF2: ='（参考）包括・任意事業の上限額算定の手引き'!$AA11 -> 0 | ADG2: ='（参考）包括・任意事業の上限額算定の手引き'!$AA12 -> 0 | ADH2: ='（参考）包括・任意事業の上限額算定の手引き'!$AA13 | ADI2: ='（参考）包括・任意事業の上限額算定の手引き'!$AA14 -> 0 | ADJ2: ='（参考）包括・任意事業の上限額算定の手引き'!$AA17 -> 0 | ADK2: ='（参考）包括・任意事業の上限額算定の手引き'!$AA18 -> 0 | ADL2: ='（参考）包括・任意事業の上限額算定の手引き'!$AA19 -> 0 | ADM2: ='（参考）包括・任意事業の上限額算定の手引き'!$AA20 -> 0 | ADN2: ='（参考）包括・任意事業の上限額算定の手引き'!$AA25 -> 0 | ADO2: ='（参考）包括・任意事業の上限額算定の手引き'!$AA26 -> 0 | ADP2: ='（参考）包括・任意事業の上限額算定の手引き'!$AA27 -> 0 | ADQ2: ='（参考）包括・任意事業の上限額算定の手引き'!$AA28 -> 0 | ADR2: ='（参考）包括・任意事業の上限額算定の手引き'!$AA29 -> 0 | ADS2: ='（参考）包括・任意事業の上限額算定の手引き'!$AA30 -> × | ADT2: ='（参考）包括・任意事業の上限額算定の手引き'!$AC5 | ADU2: ='（参考）包括・任意事業の上限額算定の手引き'!$AC6 | ADV2: ='（参考）包括・任意事業の上限額算定の手引き'!$AC7 -> 0 | ADW2: ='（参考）包括・任意事業の上限額算定の手引き'!$AC10 -> 0 | ADX2: ='（参考）包括・任意事業の上限額算定の手引き'!$AC11 -> 0 | ADY2: ='（参考）包括・任意事業の上限額算定の手引き'!$AC12 -> 0 | ADZ2: ='（参考）包括・任意事業の上限額算定の手引き'!$AC13 | AEA2: ='（参考）包括・任意事業の上限額算定の手引き'!$AC14 -> 0 | AEB2: ='（参考）包括・任意事業の上限額算定の手引き'!$AC17 -> 0 | AEC2: ='（参考）包括・任意事業の上限額算定の手引き'!$AC18 -> 0 | AED2: ='（参考）包括・任意事業の上限額算定の手引き'!$AC19 -> 0 | AEE2: ='（参考）包括・任意事業の上限額算定の手引き'!$AC20 -> 0 | AEF2: ='（参考）包括・任意事業の上限額算定の手引き'!$AC25 -> 0 | AEG2: ='（参考）包括・任意事業の上限額算定の手引き'!$AC26 -> 0 | AEH2: ='（参考）包括・任意事業の上限額算定の手引き'!$AC27 -> 0 | AEI2: ='（参考）包括・任意事業の上限額算定の手引き'!$AC28 -> 0 | AEJ2: ='（参考）包括・任意事業の上限額算定の手引き'!$AC29 -> 0 | AEK2: ='（参考）包括・任意事業の上限額算定の手引き'!$AC30 -> × | AEL2: ='（参考）包括・任意事業の上限額算定の手引き'!$AE5 | AEM2: ='（参考）包括・任意事業の上限額算定の手引き'!$AE6 | AEN2: ='（参考）包括・任意事業の上限額算定の手引き'!$AE7 -> 0 | AEO2: ='（参考）包括・任意事業の上限額算定の手引き'!$AE10 -> 0 | AEP2: ='（参考）包括・任意事業の上限額算定の手引き'!$AE11 -> 0 | AEQ2: ='（参考）包括・任意事業の上限額算定の手引き'!$AE12 -> 0 | AER2: ='（参考）包括・任意事業の上限額算定の手引き'!$AE13 | AES2: ='（参考）包括・任意事業の上限額算定の手引き'!$AE14 -> 0 | AET2: ='（参考）包括・任意事業の上限額算定の手引き'!$AE17 -> 0 | AEU2: ='（参考）包括・任意事業の上限額算定の手引き'!$AE18 -> 0 | AEV2: ='（参考）包括・任意事業の上限額算定の手引き'!$AE19 -> 0 | AEW2: ='（参考）包括・任意事業の上限額算定の手引き'!$AE20 -> 0 | AEX2: ='（参考）包括・任意事業の上限額算定の手引き'!$AE25 -> 0 | AEY2: ='（参考）包括・任意事業の上限額算定の手引き'!$AE26 -> 0 | AEZ2: ='（参考）包括・任意事業の上限額算定の手引き'!$AE27 -> 0 | AFA2: ='（参考）包括・任意事業の上限額算定の手引き'!$AE28 -> 0 | AFB2: ='（参考）包括・任意事業の上限額算定の手引き'!$AE29 -> 0 | AFC2: ='（参考）包括・任意事業の上限額算定の手引き'!$AE30 -> × | AFD2: ='（参考）包括・任意事業の上限額算定の手引き'!$AG5 | AFE2: ='（参考）包括・任意事業の上限額算定の手引き'!$AG6 | AFF2: ='（参考）包括・任意事業の上限額算定の手引き'!$AG7 -> 0 | AFG2: ='（参考）包括・任意事業の上限額算定の手引き'!$AG10 -> 0 | AFH2: ='（参考）包括・任意事業の上限額算定の手引き'!$AG11 -> 0 | AFI2: ='（参考）包括・任意事業の上限額算定の手引き'!$AG12 -> 0 | AFJ2: ='（参考）包括・任意事業の上限額算定の手引き'!$AG13 | AFK2: ='（参考）包括・任意事業の上限額算定の手引き'!$AG14 -> 0 | AFL2: ='（参考）包括・任意事業の上限額算定の手引き'!$AG17 -> 0 | AFM2: ='（参考）包括・任意事業の上限額算定の手引き'!$AG18 -> 0 | AFN2: ='（参考）包括・任意事業の上限額算定の手引き'!$AG19 -> 0 | AFO2: ='（参考）包括・任意事業の上限額算定の手引き'!$AG20 -> 0 | AFP2: ='（参考）包括・任意事業の上限額算定の手引き'!$AG25 -> 0 | AFQ2: ='（参考）包括・任意事業の上限額算定の手引き'!$AG26 -> 0 | AFR2: ='（参考）包括・任意事業の上限額算定の手引き'!$AG27 -> 0 | AFS2: ='（参考）包括・任意事業の上限額算定の手引き'!$AG28 -> 0 | AFT2: ='（参考）包括・任意事業の上限額算定の手引き'!$AG29 -> 0 | AFU2: ='（参考）包括・任意事業の上限額算定の手引き'!$AG30 -> × | AFV2: ='（参考）包括・任意事業の上限額算定の手引き'!$AI5 | AFW2: ='（参考）包括・任意事業の上限額算定の手引き'!$AI6 | AFX2: ='（参考）包括・任意事業の上限額算定の手引き'!$AI7 -> 0 | AFY2: ='（参考）包括・任意事業の上限額算定の手引き'!$AI10 -> 0 | AFZ2: ='（参考）包括・任意事業の上限額算定の手引き'!$AI11 -> 0 | AGA2: ='（参考）包括・任意事業の上限額算定の手引き'!$AI12 -> 0 | AGB2: ='（参考）包括・任意事業の上限額算定の手引き'!$AI13 | AGC2: ='（参考）包括・任意事業の上限額算定の手引き'!$AI14 -> 0 | AGD2: ='（参考）包括・任意事業の上限額算定の手引き'!$AI17 -> 0 | AGE2: ='（参考）包括・任意事業の上限額算定の手引き'!$AI18 -> 0 | AGF2: ='（参考）包括・任意事業の上限額算定の手引き'!$AI19 -> 0 | AGG2: ='（参考）包括・任意事業の上限額算定の手引き'!$AI20 -> 0 | AGH2: ='（参考）包括・任意事業の上限額算定の手引き'!$AI25 -> 0 | AGI2: ='（参考）包括・任意事業の上限額算定の手引き'!$AI26 -> 0 | AGJ2: ='（参考）包括・任意事業の上限額算定の手引き'!$AI27 -> 0 | AGK2: ='（参考）包括・任意事業の上限額算定の手引き'!$AI28 -> 0 | AGL2: ='（参考）包括・任意事業の上限額算定の手引き'!$AI29 -> 0 | AGM2: ='（参考）包括・任意事業の上限額算定の手引き'!$AI30 -> × | AGN2: ='（参考）包括・任意事業の上限額算定の手引き'!$AK5 | AGO2: ='（参考）包括・任意事業の上限額算定の手引き'!$AK6 | AGP2: ='（参考）包括・任意事業の上限額算定の手引き'!$AK7 -> 0 | AGQ2: ='（参考）包括・任意事業の上限額算定の手引き'!$AK10 -> 0 | AGR2: ='（参考）包括・任意事業の上限額算定の手引き'!$AK11 -> 0 | AGS2: ='（参考）包括・任意事業の上限額算定の手引き'!$AK12 -> 0 | AGT2: ='（参考）包括・任意事業の上限額算定の手引き'!$AK13 | AGU2: ='（参考）包括・任意事業の上限額算定の手引き'!$AK14 -> 0 | AGV2: ='（参考）包括・任意事業の上限額算定の手引き'!$AK17 -> 0 | AGW2: ='（参考）包括・任意事業の上限額算定の手引き'!$AK18 -> 0 | AGX2: ='（参考）包括・任意事業の上限額算定の手引き'!$AK19 -> 0 | AGY2: ='（参考）包括・任意事業の上限額算定の手引き'!$AK20 -> 0 | AGZ2: ='（参考）包括・任意事業の上限額算定の手引き'!$AK25 -> 0 | AHA2: ='（参考）包括・任意事業の上限額算定の手引き'!$AK26 -> 0 | AHB2: ='（参考）包括・任意事業の上限額算定の手引き'!$AK27 -> 0 | AHC2: ='（参考）包括・任意事業の上限額算定の手引き'!$AK28 -> 0 | AHD2: ='（参考）包括・任意事業の上限額算定の手引き'!$AK29 -> 0 | AHE2: ='（参考）包括・任意事業の上限額算定の手引き'!$AK30 -> × | AHF2: ='（参考）包括・任意事業の上限額算定の手引き'!$AM5 | AHG2: ='（参考）包括・任意事業の上限額算定の手引き'!$AM6 | AHH2: ='（参考）包括・任意事業の上限額算定の手引き'!$AM7 -> 0 | AHI2: ='（参考）包括・任意事業の上限額算定の手引き'!$AM10 -> 0 | AHJ2: ='（参考）包括・任意事業の上限額算定の手引き'!$AM11 -> 0 | AHK2: ='（参考）包括・任意事業の上限額算定の手引き'!$AM12 -> 0 | AHL2: ='（参考）包括・任意事業の上限額算定の手引き'!$AM13 | AHM2: ='（参考）包括・任意事業の上限額算定の手引き'!$AM14 -> 0 | AHN2: ='（参考）包括・任意事業の上限額算定の手引き'!$AM17 -> 0 | AHO2: ='（参考）包括・任意事業の上限額算定の手引き'!$AM18 -> 0 | AHP2: ='（参考）包括・任意事業の上限額算定の手引き'!$AM19 -> 0 | AHQ2: ='（参考）包括・任意事業の上限額算定の手引き'!$AM20 -> 0 | AHR2: ='（参考）包括・任意事業の上限額算定の手引き'!$AM25 -> 0 | AHS2: ='（参考）包括・任意事業の上限額算定の手引き'!$AM26 -> 0 | AHT2: ='（参考）包括・任意事業の上限額算定の手引き'!$AM27 -> 0 | AHU2: ='（参考）包括・任意事業の上限額算定の手引き'!$AM28 -> 0 | AHV2: ='（参考）包括・任意事業の上限額算定の手引き'!$AM29 -> 0 | AHW2: ='（参考）包括・任意事業の上限額算定の手引き'!$AM30 -> × | AHX2: ='（参考）包括・任意事業の上限額算定の手引き'!$AO5 | AHY2: ='（参考）包括・任意事業の上限額算定の手引き'!$AO6 | AHZ2: ='（参考）包括・任意事業の上限額算定の手引き'!$AO7 -> 0 | AIA2: ='（参考）包括・任意事業の上限額算定の手引き'!$AO10 -> 0 | AIB2: ='（参考）包括・任意事業の上限額算定の手引き'!$AO11 -> 0 | AIC2: ='（参考）包括・任意事業の上限額算定の手引き'!$AO12 -> 0 | AID2: ='（参考）包括・任意事業の上限額算定の手引き'!$AO13 | AIE2: ='（参考）包括・任意事業の上限額算定の手引き'!$AO14 -> 0 | AIF2: ='（参考）包括・任意事業の上限額算定の手引き'!$AO17 -> 0 | AIG2: ='（参考）包括・任意事業の上限額算定の手引き'!$AO18 -> 0 | AIH2: ='（参考）包括・任意事業の上限額算定の手引き'!$AO19 -> 0 | AII2: ='（参考）包括・任意事業の上限額算定の手引き'!$AO20 -> 0 | AIJ2: ='（参考）包括・任意事業の上限額算定の手引き'!$AO25 -> 0 | AIK2: ='（参考）包括・任意事業の上限額算定の手引き'!$AO26 -> 0 | AIL2: ='（参考）包括・任意事業の上限額算定の手引き'!$AO27 -> 0 | AIM2: ='（参考）包括・任意事業の上限額算定の手引き'!$AO28 -> 0 | AIN2: ='（参考）包括・任意事業の上限額算定の手引き'!$AO29 -> 0 | AIO2: ='（参考）包括・任意事業の上限額算定の手引き'!$AO30 -> × | AIP2: ='（参考）包括・任意事業の上限額算定の手引き'!$AQ5 | AIQ2: ='（参考）包括・任意事業の上限額算定の手引き'!$AQ6 | AIR2: ='（参考）包括・任意事業の上限額算定の手引き'!$AQ7 -> 0 | AIS2: ='（参考）包括・任意事業の上限額算定の手引き'!$AQ10 -> 0 | AIT2: ='（参考）包括・任意事業の上限額算定の手引き'!$AQ11 -> 0 | AIU2: ='（参考）包括・任意事業の上限額算定の手引き'!$AQ12 -> 0 | AIV2: ='（参考）包括・任意事業の上限額算定の手引き'!$AQ13 | AIW2: ='（参考）包括・任意事業の上限額算定の手引き'!$AQ14 -> 0 | AIX2: ='（参考）包括・任意事業の上限額算定の手引き'!$AQ17 -> 0 | AIY2: ='（参考）包括・任意事業の上限額算定の手引き'!$AQ18 -> 0 | AIZ2: ='（参考）包括・任意事業の上限額算定の手引き'!$AQ19 -> 0 | AJA2: ='（参考）包括・任意事業の上限額算定の手引き'!$AQ20 -> 0 | AJB2: ='（参考）包括・任意事業の上限額算定の手引き'!$AQ25 -> 0 | AJC2: ='（参考）包括・任意事業の上限額算定の手引き'!$AQ26 -> 0 | AJD2: ='（参考）包括・任意事業の上限額算定の手引き'!$AQ27 -> 0 | AJE2: ='（参考）包括・任意事業の上限額算定の手引き'!$AQ28 -> 0 | AJF2: ='（参考）包括・任意事業の上限額算定の手引き'!$AQ29 -> 0 | AJG2: ='（参考）包括・任意事業の上限額算定の手引き'!$AQ30 -> × | AJH2: ='（参考）包括・任意事業の上限額算定の手引き'!$AS5 | AJI2: ='（参考）包括・任意事業の上限額算定の手引き'!$AS6 | AJJ2: ='（参考）包括・任意事業の上限額算定の手引き'!$AS7 -> 0 | AJK2: ='（参考）包括・任意事業の上限額算定の手引き'!$AS10 -> 0 | AJL2: ='（参考）包括・任意事業の上限額算定の手引き'!$AS11 -> 0 | AJM2: ='（参考）包括・任意事業の上限額算定の手引き'!$AS12 -> 0 | AJN2: ='（参考）包括・任意事業の上限額算定の手引き'!$AS13 | AJO2: ='（参考）包括・任意事業の上限額算定の手引き'!$AS14 -> 0 | AJP2: ='（参考）包括・任意事業の上限額算定の手引き'!$AS17 -> 0 | AJQ2: ='（参考）包括・任意事業の上限額算定の手引き'!$AS18 -> 0 | AJR2: ='（参考）包括・任意事業の上限額算定の手引き'!$AS19 -> 0 | AJS2: ='（参考）包括・任意事業の上限額算定の手引き'!$AS20 -> 0 | AJT2: ='（参考）包括・任意事業の上限額算定の手引き'!$AS25 -> 0 | AJU2: ='（参考）包括・任意事業の上限額算定の手引き'!$AS26 -> 0 | AJV2: ='（参考）包括・任意事業の上限額算定の手引き'!$AS27 -> 0 | AJW2: ='（参考）包括・任意事業の上限額算定の手引き'!$AS28 -> 0 | AJX2: ='（参考）包括・任意事業の上限額算定の手引き'!$AS29 -> 0 | AJY2: ='（参考）包括・任意事業の上限額算定の手引き'!$AS30 -> × | AJZ2: ='（参考）包括・任意事業の上限額算定の手引き'!$AU5 | AKA2: ='（参考）包括・任意事業の上限額算定の手引き'!$AU6 | AKB2: ='（参考）包括・任意事業の上限額算定の手引き'!$AU7 -> 0 | AKC2: ='（参考）包括・任意事業の上限額算定の手引き'!$AU10 -> 0 | AKD2: ='（参考）包括・任意事業の上限額算定の手引き'!$AU11 -> 0 | AKE2: ='（参考）包括・任意事業の上限額算定の手引き'!$AU12 -> 0 | AKF2: ='（参考）包括・任意事業の上限額算定の手引き'!$AU13 | AKG2: ='（参考）包括・任意事業の上限額算定の手引き'!$AU14 -> 0 | AKH2: ='（参考）包括・任意事業の上限額算定の手引き'!$AU17 -> 0 | AKI2: ='（参考）包括・任意事業の上限額算定の手引き'!$AU18 -> 0 | AKJ2: ='（参考）包括・任意事業の上限額算定の手引き'!$AU19 -> 0 | AKK2: ='（参考）包括・任意事業の上限額算定の手引き'!$AU20 -> 0 | AKL2: ='（参考）包括・任意事業の上限額算定の手引き'!$AU25 -> 0 | AKM2: ='（参考）包括・任意事業の上限額算定の手引き'!$AU26 -> 0 | AKN2: ='（参考）包括・任意事業の上限額算定の手引き'!$AU27 -> 0 | AKO2: ='（参考）包括・任意事業の上限額算定の手引き'!$AU28 -> 0 | AKP2: ='（参考）包括・任意事業の上限額算定の手引き'!$AU29 -> 0 | AKQ2: ='（参考）包括・任意事業の上限額算定の手引き'!$AU30 -> × | AKR2: ='（参考）包括・任意事業の上限額算定の手引き'!$AW5 | AKS2: ='（参考）包括・任意事業の上限額算定の手引き'!$AW6 | AKT2: ='（参考）包括・任意事業の上限額算定の手引き'!$AW7 -> 0 | AKU2: ='（参考）包括・任意事業の上限額算定の手引き'!$AW10 -> 0 | AKV2: ='（参考）包括・任意事業の上限額算定の手引き'!$AW11 -> 0 | AKW2: ='（参考）包括・任意事業の上限額算定の手引き'!$AW12 -> 0 | AKX2: ='（参考）包括・任意事業の上限額算定の手引き'!$AW13 | AKY2: ='（参考）包括・任意事業の上限額算定の手引き'!$AW14 -> 0 | AKZ2: ='（参考）包括・任意事業の上限額算定の手引き'!$AW17 -> 0 | ALA2: ='（参考）包括・任意事業の上限額算定の手引き'!$AW18 -> 0 | ALB2: ='（参考）包括・任意事業の上限額算定の手引き'!$AW19 -> 0 | ALC2: ='（参考）包括・任意事業の上限額算定の手引き'!$AW20 -> 0 | ALD2: ='（参考）包括・任意事業の上限額算定の手引き'!$AW25 -> 0 | ALE2: ='（参考）包括・任意事業の上限額算定の手引き'!$AW26 -> 0 | ALF2: ='（参考）包括・任意事業の上限額算定の手引き'!$AW27 -> 0 | ALG2: ='（参考）包括・任意事業の上限額算定の手引き'!$AW28 -> 0 | ALH2: ='（参考）包括・任意事業の上限額算定の手引き'!$AW29 -> 0 | ALI2: ='（参考）包括・任意事業の上限額算定の手引き'!$AW30 -> × | ALJ2: ='（参考）包括・任意事業の上限額算定の手引き'!$AY5 | ALK2: ='（参考）包括・任意事業の上限額算定の手引き'!$AY6 | ALL2: ='（参考）包括・任意事業の上限額算定の手引き'!$AY7 -> 0 | ALM2: ='（参考）包括・任意事業の上限額算定の手引き'!$AY10 -> 0 | ALN2: ='（参考）包括・任意事業の上限額算定の手引き'!$AY11 -> 0 | ALO2: ='（参考）包括・任意事業の上限額算定の手引き'!$AY12 -> 0 | ALP2: ='（参考）包括・任意事業の上限額算定の手引き'!$AY13 | ALQ2: ='（参考）包括・任意事業の上限額算定の手引き'!$AY14 -> 0 | ALR2: ='（参考）包括・任意事業の上限額算定の手引き'!$AY17 -> 0 | ALS2: ='（参考）包括・任意事業の上限額算定の手引き'!$AY18 -> 0 | ALT2: ='（参考）包括・任意事業の上限額算定の手引き'!$AY19 -> 0 | ALU2: ='（参考）包括・任意事業の上限額算定の手引き'!$AY20 -> 0 | ALV2: ='（参考）包括・任意事業の上限額算定の手引き'!$AY25 -> 0 | ALW2: ='（参考）包括・任意事業の上限額算定の手引き'!$AY26 -> 0 | ALX2: ='（参考）包括・任意事業の上限額算定の手引き'!$AY27 -> 0 | ALY2: ='（参考）包括・任意事業の上限額算定の手引き'!$AY28 -> 0 | ALZ2: ='（参考）包括・任意事業の上限額算定の手引き'!$AY29 -> 0 | AMA2: ='（参考）包括・任意事業の上限額算定の手引き'!$AY30 -> × | AMB2: ='（参考）包括・任意事業の上限額算定の手引き'!$BA5 | AMC2: ='（参考）包括・任意事業の上限額算定の手引き'!$BA6 | AMD2: ='（参考）包括・任意事業の上限額算定の手引き'!$BA7 -> 0 | AME2: ='（参考）包括・任意事業の上限額算定の手引き'!$BA10 -> 0 | AMF2: ='（参考）包括・任意事業の上限額算定の手引き'!$BA11 -> 0 | AMG2: ='（参考）包括・任意事業の上限額算定の手引き'!$BA12 -> 0 | AMH2: ='（参考）包括・任意事業の上限額算定の手引き'!$BA13 | AMI2: ='（参考）包括・任意事業の上限額算定の手引き'!$BA14 -> 0 | AMJ2: ='（参考）包括・任意事業の上限額算定の手引き'!$BA17 -> 0 | AMK2: ='（参考）包括・任意事業の上限額算定の手引き'!$BA18 -> 0 | AML2: ='（参考）包括・任意事業の上限額算定の手引き'!$BA19 -> 0 | AMM2: ='（参考）包括・任意事業の上限額算定の手引き'!$BA20 -> 0 | AMN2: ='（参考）包括・任意事業の上限額算定の手引き'!$BA25 -> 0 | AMO2: ='（参考）包括・任意事業の上限額算定の手引き'!$BA26 -> 0 | AMP2: ='（参考）包括・任意事業の上限額算定の手引き'!$BA27 -> 0 | AMQ2: ='（参考）包括・任意事業の上限額算定の手引き'!$BA28 -> 0 | AMR2: ='（参考）包括・任意事業の上限額算定の手引き'!$BA29 -> 0 | AMS2: ='（参考）包括・任意事業の上限額算定の手引き'!$BA30 -> × | AMT2: ='（参考）包括・任意事業の上限額算定の手引き'!$BC5 | AMU2: ='（参考）包括・任意事業の上限額算定の手引き'!$BC6 | AMV2: ='（参考）包括・任意事業の上限額算定の手引き'!$BC7 -> 0 | AMW2: ='（参考）包括・任意事業の上限額算定の手引き'!$BC10 -> 0 | AMX2: ='（参考）包括・任意事業の上限額算定の手引き'!$BC11 -> 0 | AMY2: ='（参考）包括・任意事業の上限額算定の手引き'!$BC12 -> 0 | AMZ2: ='（参考）包括・任意事業の上限額算定の手引き'!$BC13 | ANA2: ='（参考）包括・任意事業の上限額算定の手引き'!$BC14 -> 0 | ANB2: ='（参考）包括・任意事業の上限額算定の手引き'!$BC17 -> 0 | ANC2: ='（参考）包括・任意事業の上限額算定の手引き'!$BC18 -> 0 | AND2: ='（参考）包括・任意事業の上限額算定の手引き'!$BC19 -> 0 | ANE2: ='（参考）包括・任意事業の上限額算定の手引き'!$BC20 -> 0 | ANF2: ='（参考）包括・任意事業の上限額算定の手引き'!$BC25 -> 0 | ANG2: ='（参考）包括・任意事業の上限額算定の手引き'!$BC26 -> 0 | ANH2: ='（参考）包括・任意事業の上限額算定の手引き'!$BC27 -> 0 | ANI2: ='（参考）包括・任意事業の上限額算定の手引き'!$BC28 -> 0 | ANJ2: ='（参考）包括・任意事業の上限額算定の手引き'!$BC29 -> 0 | ANK2: ='（参考）包括・任意事業の上限額算定の手引き'!$BC30 -> × | ANL2: ='（参考）包括・任意事業の上限額算定の手引き'!$BE5 | ANM2: ='（参考）包括・任意事業の上限額算定の手引き'!$BE6 | ANN2: ='（参考）包括・任意事業の上限額算定の手引き'!$BE7 -> 0 | ANO2: ='（参考）包括・任意事業の上限額算定の手引き'!$BE10 -> 0 | ANP2: ='（参考）包括・任意事業の上限額算定の手引き'!$BE11 -> 0 | ANQ2: ='（参考）包括・任意事業の上限額算定の手引き'!$BE12 -> 0 | ANR2: ='（参考）包括・任意事業の上限額算定の手引き'!$BE13 | ANS2: ='（参考）包括・任意事業の上限額算定の手引き'!$BE14 -> 0 | ANT2: ='（参考）包括・任意事業の上限額算定の手引き'!$BE17 -> 0 | ANU2: ='（参考）包括・任意事業の上限額算定の手引き'!$BE18 -> 0 | ANV2: ='（参考）包括・任意事業の上限額算定の手引き'!$BE19 -> 0 | ANW2: ='（参考）包括・任意事業の上限額算定の手引き'!$BE20 -> 0 | ANX2: ='（参考）包括・任意事業の上限額算定の手引き'!$BE25 -> 0 | ANY2: ='（参考）包括・任意事業の上限額算定の手引き'!$BE26 -> 0 | ANZ2: ='（参考）包括・任意事業の上限額算定の手引き'!$BE27 -> 0 | AOA2: ='（参考）包括・任意事業の上限額算定の手引き'!$BE28 -> 0 | AOB2: ='（参考）包括・任意事業の上限額算定の手引き'!$BE29 -> 0 | AOC2: ='（参考）包括・任意事業の上限額算定の手引き'!$BE30 -> × | AOD2: ='（参考）包括・任意事業の上限額算定の手引き'!$BG5 | AOE2: ='（参考）包括・任意事業の上限額算定の手引き'!$BG6 | AOF2: ='（参考）包括・任意事業の上限額算定の手引き'!$BG7 -> 0 | AOG2: ='（参考）包括・任意事業の上限額算定の手引き'!$BG10 -> 0 | AOH2: ='（参考）包括・任意事業の上限額算定の手引き'!$BG11 -> 0 | AOI2: ='（参考）包括・任意事業の上限額算定の手引き'!$BG12 -> 0 | AOJ2: ='（参考）包括・任意事業の上限額算定の手引き'!$BG13 | AOK2: ='（参考）包括・任意事業の上限額算定の手引き'!$BG14 -> 0 | AOL2: ='（参考）包括・任意事業の上限額算定の手引き'!$BG17 -> 0 | AOM2: ='（参考）包括・任意事業の上限額算定の手引き'!$BG18 -> 0 | AON2: ='（参考）包括・任意事業の上限額算定の手引き'!$BG19 -> 0 | AOO2: ='（参考）包括・任意事業の上限額算定の手引き'!$BG20 -> 0 | AOP2: ='（参考）包括・任意事業の上限額算定の手引き'!$BG25 -> 0 | AOQ2: ='（参考）包括・任意事業の上限額算定の手引き'!$BG26 -> 0 | AOR2: ='（参考）包括・任意事業の上限額算定の手引き'!$BG27 -> 0 | AOS2: ='（参考）包括・任意事業の上限額算定の手引き'!$BG28 -> 0 | AOT2: ='（参考）包括・任意事業の上限額算定の手引き'!$BG29 -> 0 | AOU2: ='（参考）包括・任意事業の上限額算定の手引き'!$BG30 -> × | AOV2: ='（参考）包括・任意事業の上限額算定の手引き'!$BI5 | AOW2: ='（参考）包括・任意事業の上限額算定の手引き'!$BI6 | AOX2: ='（参考）包括・任意事業の上限額算定の手引き'!$BI7 -> 0 | AOY2: ='（参考）包括・任意事業の上限額算定の手引き'!$BI10 -> 0 | AOZ2: ='（参考）包括・任意事業の上限額算定の手引き'!$BI11 -> 0 | APA2: ='（参考）包括・任意事業の上限額算定の手引き'!$BI12 -> 0 | APB2: ='（参考）包括・任意事業の上限額算定の手引き'!$BI13 | APC2: ='（参考）包括・任意事業の上限額算定の手引き'!$BI14 -> 0 | APD2: ='（参考）包括・任意事業の上限額算定の手引き'!$BI17 -> 0 | APE2: ='（参考）包括・任意事業の上限額算定の手引き'!$BI18 -> 0 | APF2: ='（参考）包括・任意事業の上限額算定の手引き'!$BI19 -> 0 | APG2: ='（参考）包括・任意事業の上限額算定の手引き'!$BI20 -> 0 | APH2: ='（参考）包括・任意事業の上限額算定の手引き'!$BI25 -> 0 | API2: ='（参考）包括・任意事業の上限額算定の手引き'!$BI26 -> 0 | APJ2: ='（参考）包括・任意事業の上限額算定の手引き'!$BI27 -> 0 | APK2: ='（参考）包括・任意事業の上限額算定の手引き'!$BI28 -> 0 | APL2: ='（参考）包括・任意事業の上限額算定の手引き'!$BI29 -> 0 | APM2: ='（参考）包括・任意事業の上限額算定の手引き'!$BI30 -> × | APN2: ='（参考）包括・任意事業の上限額算定の手引き'!$BK5 | APO2: ='（参考）包括・任意事業の上限額算定の手引き'!$BK6 | APP2: ='（参考）包括・任意事業の上限額算定の手引き'!$BK7 -> 0 | APQ2: ='（参考）包括・任意事業の上限額算定の手引き'!$BK10 -> 0 | APR2: ='（参考）包括・任意事業の上限額算定の手引き'!$BK11 -> 0 | APS2: ='（参考）包括・任意事業の上限額算定の手引き'!$BK12 -> 0 | APT2: ='（参考）包括・任意事業の上限額算定の手引き'!$BK13 | APU2: ='（参考）包括・任意事業の上限額算定の手引き'!$BK14 -> 0 | APV2: ='（参考）包括・任意事業の上限額算定の手引き'!$BK17 -> 0 | APW2: ='（参考）包括・任意事業の上限額算定の手引き'!$BK18 -> 0 | APX2: ='（参考）包括・任意事業の上限額算定の手引き'!$BK19 -> 0 | APY2: ='（参考）包括・任意事業の上限額算定の手引き'!$BK20 -> 0 | APZ2: ='（参考）包括・任意事業の上限額算定の手引き'!$BK25 -> 0 | AQA2: ='（参考）包括・任意事業の上限額算定の手引き'!$BK26 -> 0 | AQB2: ='（参考）包括・任意事業の上限額算定の手引き'!$BK27 -> 0 | AQC2: ='（参考）包括・任意事業の上限額算定の手引き'!$BK28 -> 0 | AQD2: ='（参考）包括・任意事業の上限額算定の手引き'!$BK29 -> 0 | AQE2: ='（参考）包括・任意事業の上限額算定の手引き'!$BK30 -> × | AQF2: ='（参考）包括・任意事業の上限額算定の手引き'!$BM5 | AQG2: ='（参考）包括・任意事業の上限額算定の手引き'!$BM6 | AQH2: ='（参考）包括・任意事業の上限額算定の手引き'!$BM7 -> 0 | AQI2: ='（参考）包括・任意事業の上限額算定の手引き'!$BM10 -> 0 | AQJ2: ='（参考）包括・任意事業の上限額算定の手引き'!$BM11 -> 0 | AQK2: ='（参考）包括・任意事業の上限額算定の手引き'!$BM12 -> 0 | AQL2: ='（参考）包括・任意事業の上限額算定の手引き'!$BM13 | AQM2: ='（参考）包括・任意事業の上限額算定の手引き'!$BM14 -> 0 | AQN2: ='（参考）包括・任意事業の上限額算定の手引き'!$BM17 -> 0 | AQO2: ='（参考）包括・任意事業の上限額算定の手引き'!$BM18 -> 0 | AQP2: ='（参考）包括・任意事業の上限額算定の手引き'!$BM19 -> 0 | AQQ2: ='（参考）包括・任意事業の上限額算定の手引き'!$BM20 -> 0 | AQR2: ='（参考）包括・任意事業の上限額算定の手引き'!$BM25 -> 0 | AQS2: ='（参考）包括・任意事業の上限額算定の手引き'!$BM26 -> 0 | AQT2: ='（参考）包括・任意事業の上限額算定の手引き'!$BM27 -> 0 | AQU2: ='（参考）包括・任意事業の上限額算定の手引き'!$BM28 -> 0 | AQV2: ='（参考）包括・任意事業の上限額算定の手引き'!$BM29 -> 0 | AQW2: ='（参考）包括・任意事業の上限額算定の手引き'!$BM30 -> × | AQX2: ='（参考）包括・任意事業の上限額算定の手引き'!$BO5 | AQY2: ='（参考）包括・任意事業の上限額算定の手引き'!$BO6 | AQZ2: ='（参考）包括・任意事業の上限額算定の手引き'!$BO7 -> 0 | ARA2: ='（参考）包括・任意事業の上限額算定の手引き'!$BO10 -> 0 | ARB2: ='（参考）包括・任意事業の上限額算定の手引き'!$BO11 -> 0 | ARC2: ='（参考）包括・任意事業の上限額算定の手引き'!$BO12 -> 0 | ARD2: ='（参考）包括・任意事業の上限額算定の手引き'!$BO13 | ARE2: ='（参考）包括・任意事業の上限額算定の手引き'!$BO14 -> 0 | ARF2: ='（参考）包括・任意事業の上限額算定の手引き'!$BO17 -> 0 | ARG2: ='（参考）包括・任意事業の上限額算定の手引き'!$BO18 -> 0 | ARH2: ='（参考）包括・任意事業の上限額算定の手引き'!$BO19 -> 0 | ARI2: ='（参考）包括・任意事業の上限額算定の手引き'!$BO20 -> 0 | ARJ2: ='（参考）包括・任意事業の上限額算定の手引き'!$BO25 -> 0 | ARK2: ='（参考）包括・任意事業の上限額算定の手引き'!$BO26 -> 0 | ARL2: ='（参考）包括・任意事業の上限額算定の手引き'!$BO27 -> 0 | ARM2: ='（参考）包括・任意事業の上限額算定の手引き'!$BO28 -> 0 | ARN2: ='（参考）包括・任意事業の上限額算定の手引き'!$BO29 -> 0 | ARO2: ='（参考）包括・任意事業の上限額算定の手引き'!$BO30 -> × | ARP2: ='（参考）包括・任意事業の上限額算定の手引き'!$BQ5 | ARQ2: ='（参考）包括・任意事業の上限額算定の手引き'!$BQ6 | ARR2: ='（参考）包括・任意事業の上限額算定の手引き'!$BQ7 -> 0 | ARS2: ='（参考）包括・任意事業の上限額算定の手引き'!$BQ10 -> 0 | ART2: ='（参考）包括・任意事業の上限額算定の手引き'!$BQ11 -> 0 | ARU2: ='（参考）包括・任意事業の上限額算定の手引き'!$BQ12 -> 0 | ARV2: ='（参考）包括・任意事業の上限額算定の手引き'!$BQ13 | ARW2: ='（参考）包括・任意事業の上限額算定の手引き'!$BQ14 -> 0 | ARX2: ='（参考）包括・任意事業の上限額算定の手引き'!$BQ17 -> 0 | ARY2: ='（参考）包括・任意事業の上限額算定の手引き'!$BQ18 -> 0 | ARZ2: ='（参考）包括・任意事業の上限額算定の手引き'!$BQ19 -> 0 | ASA2: ='（参考）包括・任意事業の上限額算定の手引き'!$BQ20 -> 0 | ASB2: ='（参考）包括・任意事業の上限額算定の手引き'!$BQ25 -> 0 | ASC2: ='（参考）包括・任意事業の上限額算定の手引き'!$BQ26 -> 0 | ASD2: ='（参考）包括・任意事業の上限額算定の手引き'!$BQ27 -> 0 | ASE2: ='（参考）包括・任意事業の上限額算定の手引き'!$BQ28 -> 0 | ASF2: ='（参考）包括・任意事業の上限額算定の手引き'!$BQ29 -> 0 | ASG2: ='（参考）包括・任意事業の上限額算定の手引き'!$BQ30 -> × | ASH2: ='（参考）包括・任意事業の上限額算定の手引き'!$BS5 | ASI2: ='（参考）包括・任意事業の上限額算定の手引き'!$BS6 | ASJ2: ='（参考）包括・任意事業の上限額算定の手引き'!$BS7 -> 0 | ASK2: ='（参考）包括・任意事業の上限額算定の手引き'!$BS10 -> 0 | ASL2: ='（参考）包括・任意事業の上限額算定の手引き'!$BS11 -> 0 | ASM2: ='（参考）包括・任意事業の上限額算定の手引き'!$BS12 -> 0 | ASN2: ='（参考）包括・任意事業の上限額算定の手引き'!$BS13 | ASO2: ='（参考）包括・任意事業の上限額算定の手引き'!$BS14 -> 0 | ASP2: ='（参考）包括・任意事業の上限額算定の手引き'!$BS17 -> 0 | ASQ2: ='（参考）包括・任意事業の上限額算定の手引き'!$BS18 -> 0 | ASR2: ='（参考）包括・任意事業の上限額算定の手引き'!$BS19 -> 0 | ASS2: ='（参考）包括・任意事業の上限額算定の手引き'!$BS20 -> 0 | AST2: ='（参考）包括・任意事業の上限額算定の手引き'!$BS25 -> 0 | ASU2: ='（参考）包括・任意事業の上限額算定の手引き'!$BS26 -> 0 | ASV2: ='（参考）包括・任意事業の上限額算定の手引き'!$BS27 -> 0 | ASW2: ='（参考）包括・任意事業の上限額算定の手引き'!$BS28 -> 0 | ASX2: ='（参考）包括・任意事業の上限額算定の手引き'!$BS29 -> 0 | ASY2: ='（参考）包括・任意事業の上限額算定の手引き'!$BS30 -> × | ASZ2: =#REF! -> #REF! | ATA2: =#REF! -> #REF! | ATB2: =#REF! -> #REF! | ATC2: =#REF! -> #REF! | ATD2: =#REF! -> #REF! | ATE2: =#REF! -> #REF! | ATF2: =#REF! -> #REF! | ATG2: =#REF! -> #REF! | ... AYJ2: =#REF! -> #REF! | AYK2: =IF(SUM(AYL2:AYP2)=0,"","有") -> #REF! | AYL2: =#REF! -> #REF! | AYM2: =#REF! -> #REF! | AYN2: =#REF! -> #REF! | AYO2: =#REF! -> #REF! | AYP2: =#REF! -> #REF! | AYQ2: =#REF! -> #REF! | AYR2: =#REF! -> #REF! | AYS2: =#REF! -> #REF! | ... BAR2: =#REF! -> #REF!
OK5: 令和６年10月１日における85歳以上の人口
OK6: 令和６年度の10月１日における75歳以上80歳未満人口を同日における75歳以上人口で除して得た率・・・X1
OK7: 令和６年度の10月１日における80歳以上85歳未満人口を同日における75歳以上人口で除して得た率・・・Y1
OK8: 令和６年度の10月１日における85歳以上人口を同日における75歳以上人口で除して得た率・・・Z1
OK9: 令和３年10月１日における75歳以上の人口
OK10: 令和３年10月１日における75歳以上80歳未満人口
OK11: 令和３年10月１日における80歳以上85歳未満人口
OK12: 令和３年10月１日における85歳以上の人口
OK13: 令和３年度の10月１日における75歳以上80歳未満人口を同日における75歳以上人口で除して得た率・・・X2
OK14: 令和３年度の10月１日における80歳以上85歳未満人口を同日における75歳以上人口で除して得た率・・・Y2
OK15: 令和３年度の10月１日における85歳以上人口を同日における75歳以上人口で除して得た率・・・Z2
OK16: A×0.9×(X1＋Y1×2＋Z1×3)/(X2＋Y2×2＋Z2×3)＋A×0.1－A・・・イ

Sheet PullDown
A1: 厚生(支)局一覧 | F1: 都道府県一覧 | M1: 地方公共団体一覧 | Z1: 地方公共団体一覧(都道府県別） | BX1: プルダウン一覧
AA4: 北海道 | AB4: 青森県 | AC4: 岩手県 | AD4: 宮城県 | AE4: 秋田県 | AF4: 山形県 | AG4: 福島県 | AH4: 茨城県 | AI4: 栃木県 | AJ4: 群馬県 | AK4: 埼玉県 | AL4: 千葉県 | AM4: 東京都 | AN4: 神奈川県 | AO4: 新潟県 | AP4: 富山県 | AQ4: 石川県 | AR4: 福井県 | AS4: 山梨県 | AT4: 長野県 | AU4: 岐阜県 | AV4: 静岡県 | AW4: 愛知県 | AX4: 三重県 | AY4: 滋賀県 | AZ4: 京都府 | BA4: 大阪府 | BB4: 兵庫県 | BC4: 奈良県 | BD4: 和歌山県 | BE4: 鳥取県 | BF4: 島根県 | BG4: 岡山県 | BH4: 広島県 | BI4: 山口県 | BJ4: 徳島県 | BK4: 香川県 | BL4: 愛媛県 | BM4: 高知県 | BN4: 福岡県 | BO4: 佐賀県 | BP4: 長崎県 | BQ4: 熊本県 | BR4: 大分県 | BS4: 宮崎県 | BT4: 鹿児島県 | BU4: 沖縄県 | BY4: 上限設定状況 | CC4: 実績上限設定状況
B5: 厚生(支)局番号 | C5: 厚生(支)局名 | F5: 地方公共団体コード | G5: 厚生(支)局番号 | H5: 厚生(支)局名 | I5: 都道府県コード | J5: 都道府県名 | N5: 通し番号 | O5: 都道府県番号 | P5: 保険者番号 | Q5: 都道府県コード | R5: 市区町村コード | S5: Ｃ・Ｄ | T5: 団体名 | U5: 厚生(支)局番号 | V5: 厚生(支)局名 | W5: 地方公共団体コード | AA5: 01 | AB5: 02 | AC5: 03 | AD5: 04 | AE5: 05 | AF5: 06 | AG5: 07 | AH5: 08 | AI5: 09 | AJ5: 10 | AK5: 11 | AL5: 12 | AM5: 13 | AN5: 14 | AO5: 15 | AP5: 16 | AQ5: 17 | AR5: 18 | AS5: 19 | AT5: 20 | AU5: 21 | AV5: 22 | AW5: 23 | AX5: 24 | AY5: 25 | AZ5: 26 | BA5: 27 | BB5: 28 | BC5: 29 | BD5: 30 | BE5: 31 | BF5: 32 | BG5: 33 | BH5: 34 | BI5: 35 | BJ5: 36 | BK5: 37 | BL5: 38 | BM5: 39 | BN5: 40 | BO5: 41 | BP5: 42 | BQ5: 43 | BR5: 44 | BS5: 45 | BT5: 46 | BU5: 47 | BY5: ①総合事業上限設定状況 | BZ5: ②センター運営上限設定状況 | CA5: ③社会保障充実上限設定状況 | CC5: ①総合事業実績上限設定状況 | CE5: 移行年度 | CG5: サービス類型 | CJ5: 都道府県名 | CK5: 保険者名 | CM5: 項番
B6: 01 | C6: 北海道厚生局 | F6: 010006 | G6: 01 | H6: 北海道厚生局 | I6: 01 | J6: 北海道 | L6: 0001-1 | M6: 北海道札幌市 | N6: 0001 | O6: 01 | P6: 011007 | Q6: 01 | R6: 100 | S6: 7 | T6: 札幌市 | U6: 01 | V6: 北海道厚生局 | W6: 011002 | X6: 1 | AA6: 札幌市 | AB6: 青森市 | AC6: 盛岡市 | AD6: 仙台市 | AE6: 秋田市 | AF6: 山形市 | AG6: 福島市 | AH6: 水戸市 | AI6: 宇都宮市 | AJ6: 前橋市 | AK6: さいたま市 | AL6: 千葉市 | AM6: 千代田区 | AN6: 横浜市 | AO6: 新潟市 | AP6: 富山市 | AQ6: 金沢市 | AR6: 福井市 | AS6: 甲府市 | AT6: 長野市 | AU6: 岐阜市 | AV6: 静岡市 | AW6: 名古屋市 | AX6: 津市 | AY6: 大津市 | AZ6: 京都市 | BA6: 大阪市 | BB6: 神戸市 | BC6: 奈良市 | BD6: 和歌山市 | BE6: 鳥取市 | BF6: 松江市 | BG6: 岡山市 | BH6: 広島市 | BI6: 下関市 | BJ6: 徳島市 | BK6: 高松市 | BL6: 松山市 | BM6: 高知市 | BN6: 北九州市 | BO6: 唐津市 | BP6: 長崎市 | BQ6: 熊本市 | BR6: 大分市 | BS6: 宮崎市 | BT6: 鹿児島市 | BU6: 那覇市 | BY6: ①基本の上限額 | BZ6: ①原則の上限額 | CA6: ①標準額 | CC6: ①基本の上限額 | CE6: 42095 | CG6: 訪問型サービス・活動A | CI6: 希望する | CJ6: 北海道 | CK6: 札幌市 | CL6: =CJ6&CK6 -> 北海道札幌市 | CM6: 1 | CN6: =VLOOKUP(CL6,$M$6:$N$1784,2,FALSE) -> 0001 | CO6: =CM6&TEXT(CN6,0)&CK6 -> 11札幌市 | CP6: 11札幌市 | CQ6: =CO6=CP6 -> TRUE
B7: 02 | C7: 東北厚生局 | F7: 020001 | G7: 02 | H7: 東北厚生局 | I7: 02 | J7: 青森県 | L7: 0002-1 | M7: 北海道函館市 | N7: 0002 | O7: 01 | P7: 012021 | Q7: 01 | R7: 202 | S7: 1 | T7: 函館市 | U7: 01 | V7: 北海道厚生局 | W7: 012025 | X7: 1 | AA7: 函館市 | AB7: 弘前市 | AC7: 宮古市 | AD7: 石巻市 | AE7: 能代市 | AF7: 米沢市 | AG7: 会津若松市 | AH7: 日立市 | AI7: 足利市 | AJ7: 高崎市 | AK7: 川越市 | AL7: 銚子市 | AM7: 中央区 | AN7: 川崎市 | AO7: 長岡市 | AP7: 高岡市 | AQ7: 七尾市 | AR7: 敦賀市 | AS7: 富士吉田市 | AT7: 松本市 | AU7: 大垣市 | AV7: 浜松市 | AW7: 岡崎市 | AX7: 四日市市 | AY7: 彦根市 | AZ7: 福知山市 | BA7: 堺市 | BB7: 姫路市 | BC7: 大和高田市 | BD7: 海南市 | BE7: 米子市 | BF7: 出雲市 | BG7: 倉敷市 | BH7: 呉市 | BI7: 宇部市 | BJ7: 鳴門市 | BK7: 丸亀市 | BL7: 今治市 | BM7: 室戸市 | BN7: 福岡市 | BO7: 伊万里市 | BP7: 佐世保市 | BQ7: 八代市 | BR7: 別府市 | BS7: 都城市 | BT7: 鹿屋市 | BU7: 宜野湾市 | BY7: ②介護予防給付全体の伸びを考慮する上限額 | BZ7: ②特例の上限額 | CA7: ②個別協議希望 | CC7: ②介護予防給付全体の伸びを考慮する上限額 | CE7: 42461 | CG7: 訪問型サービス・活動B | CI7: 希望しない | CJ7: 北海道 | CK7: 函館市 | CL7: =CJ7&CK7 -> 北海道函館市 | CM7: 2 | CN7: =VLOOKUP(CL7,$M$6:$N$1784,2,FALSE) -> 0002 | CO7: =CM7&TEXT(CN7,0)&CK7 -> 22函館市 | CP7: 22函館市 | CQ7: =CO7=CP7 -> TRUE
