Workbook
Name _: #REF!
Name __: #REF!
Name _1Q_H12国調結果地区別年齢別_5歳毎: #REF!
Name _END1: #REF!
Name _N1: #REF!
Name _PNO1: #REF!
Name _PNO2: #REF!
Name _PNO3: #REF!
Name _PNO4: #REF!
Name _YH1: #REF!
Name _YH2: #REF!
Name \0: #REF!
Name \a: #REF!
Name \b: #REF!
Name \c: #REF!
Name \d: #REF!
Name \e: #REF!
Name \p: #REF!
Name \s: #REF!
Name aa: #REF!
Name BC: #REF!
Name BGH: #REF!
Name BH: #REF!
Name BOR: #REF!
Name CODE: #REF!
Name Data: [2]H17国勢調査!#REF!
Name DataEnd: [2]H17国勢調査!#REF!
Name F: #REF!
Name H6ﾃﾞｰﾀ: #REF!
Name H7ﾃﾞｰﾀ: #REF!
Name HEAD2: #REF!
Name Hyousoku: [2]H17国勢調査!#REF!
Name HyousokuArea: [2]H17国勢調査!#REF!
Name HyousokuEnd: [2]H17国勢調査!#REF!
Name Hyoutou: [2]H17国勢調査!#REF!
Name kei: #REF!
Name KES: #REF!
Name ｎ: #N/A
Name №１: #REF!
Name №１００: #REF!
Name №１５０: #REF!
Name №２００: #REF!
Name №２５０: #REF!
Name №３００: #REF!
Name №３２５: #REF!
Name №348: #REF!
Name №３５０: #REF!
Name №５０: #REF!
Name P: #N/A
Name ppp: '[3]10(000)'!#REF!
Name PRIN1: #REF!
Name PRINT: #REF!
Name Rangai0: [2]H17国勢調査!#REF!
Name RECORD: #REF!
Name RR: #REF!
Name START: #REF!
Name tanjyuu: #REF!
Name Title: [2]H17国勢調査!#REF!
Name TitleEnglish: [2]H17国勢調査!#REF!
Name UNDK_KF010H: #REF!

Sheet 計画改訂スケジュール水道
A5: 年度 | B5: 2025 | C5: 2026 | D5: 2027 | E5: 2028 | F5: 2029 | G5: 2030 | H5: 2031 | I5: 2032 | J5: 2033 | K5: 2034
B6: (令和7) | C6: (令和8) | D6: (令和9) | E6: (令和10) | F6: (令和11) | G6: (令和12) | H6: (令和13) | I6: (令和14) | J6: (令和15) | K6: (令和16)
A7: 瀬戸市汚水適正処理構想 | B7: 【愛知県】 全県域汚水適正処理構想の 見直し・改定までに実施
A10: 瀬戸市公共下水道事業基本計画 | E10: 見直し 改定 | J10: 見直し 改定
A13: 瀬戸市下水道ストックマネジメント計画 【管路施設】 | E13: 見直し 改定 | J13: 見直し 改定
A16: 瀬戸市下水道ストックマネジメント計画 【処理場施設】 | B16: 見直し 改定
A19: 年度 | B19: 令和7 | C19: 令和8 | D19: 令和9 | E19: 令和10 | F19: 令和11 | G19: 令和12 | H19: 令和13 | I19: 令和14 | J19: 令和15 | K19: 令和16 | L19: 令和17
B20: 2025 | C20: 2026 | D20: 2027 | E20: 2028 | F20: 2029 | G20: 2030 | H20: 2031 | I20: 2032 | J20: 2033 | K20: 2034 | L20: 2035
A21: 経営戦略 | B21: 改定 | F21: 検証 見直し | G21: 改定 | K21: 検証 見直し | L21: 改定
A24: 料金 | C24: 改定必要性の検証 | H24: 改定必要性の検証

Sheet 計画改訂スケジュール 下水道
A5: 年度 | B5: 2025 | C5: 2026 | D5: 2027 | E5: 2028 | F5: 2029 | G5: 2030 | H5: 2031 | I5: 2032 | J5: 2033 | K5: 2034
B6: (令和7) | C6: (令和8) | D6: (令和9) | E6: (令和10) | F6: (令和11) | G6: (令和12) | H6: (令和13) | I6: (令和14) | J6: (令和15) | K6: (令和16)
A7: 瀬戸市汚水適正処理構想 | B7: 【愛知県】 全県域汚水適正処理構想の 見直し・改定までに実施
A10: 瀬戸市公共下水道事業基本計画 | E10: 見直し 改定 | J10: 見直し 改定
A13: 瀬戸市下水道ストックマネジメント計画 【管路施設】 | E13: 見直し 改定 | J13: 見直し 改定
A16: 瀬戸市下水道ストックマネジメント計画 【処理場施設】 | B16: 見直し 改定
A19: 年度 | B19: 令和7 | C19: 令和8 | D19: 令和9 | E19: 令和10 | F19: 令和11 | G19: 令和12 | H19: 令和13 | I19: 令和14 | J19: 令和15 | K19: 令和16 | L19: 令和17
B20: 2025 | C20: 2026 | D20: 2027 | E20: 2028 | F20: 2029 | G20: 2030 | H20: 2031 | I20: 2032 | J20: 2033 | K20: 2034 | L20: 2035
A21: 経営戦略 | B21: 改定 | F21: 検証 見直し | G21: 改定 | K21: 検証 見直し | L21: 改定
A24: 使用料 | C24: 改定必要性の検証 | D24: 改定（※） | H24: 改定必要性の検証

Sheet Sheet2
B2: 和暦 | C2: 西暦
B3: S45 | C3: 1970
B4: S46 | C4: 1971
B5: S47 | C5: 1972
B6: S48 | C6: 1973
B7: S49 | C7: 1974
B8: S50 | C8: 1975
B9: S51 | C9: 1976
B10: S52 | C10: 1977
B11: S53 | C11: 1978
B12: S54 | C12: 1979
B13: S55 | C13: 1980
B14: S56 | C14: 1981
... B63: R5 | C63: 2023

Sheet Sheet3
B1: 取得価額 | C1: 資産名称 | D1: 取得価額 | E1: 耐用年数 | F1: 取得年度 | G1: 年度２ | H1: デフレーター | I1: 区分 | J1: 係数 | K1: 限界耐用年数 | L1: 限界年度 | X1: s | Y1: d | Z1: f | AB1: s | AC1: d | AD1: f
B2: 21817 | C2: 非常通報装置 | D2: =ROUND(B2*H2,0) -> 31786 | E2: 9 | F2: H18 | G2: =VLOOKUP(F2,Sheet2!$B$2:$C$70,2,FALSE) -> 2006 | H2: =VLOOKUP(G2,$AB$1:$AD$51,3,FALSE) -> 1.4569536 | I2: 配水・給水設備 | K2: =ROUND(E2*1.5,0) -> 14 | L2: =G2+K2 -> 2020 | N2: 2026 | O2: 2027 | P2: 2028 | Q2: 2029 | R2: 2030 | S2: 2031 | T2: 2032 | U2: 2033 | V2: 2034 | W2: 2035 | X2: 1985 | Y2: 77.7 | Z2: =$Y$32/Y2 -> 1.2870013 | AB2: 1975 | AC2: 77.7 | AD2: =$AC$51/AC2 -> 1.6988417
B3: 863776 | C3: 加圧ポンプ | D3: =ROUND(B3*H3,0) -> 1258482 | E3: 15 | F3: H18 | G3: =VLOOKUP(F3,Sheet2!$B$2:$C$70,2,FALSE) -> 2006 | H3: =VLOOKUP(G3,$AB$1:$AD$51,3,FALSE) -> 1.4569536 | I3: 配水・給水設備 | K3: =ROUND(E3*1.5,0) -> 23 | L3: =G3+K3 -> 2029 | M3: 取水・浄水施設 | N3: =SUMIFS($D$1:$D$203,$L$1:$L$203,N$2,$I$1:$I$203,$M3) -> 0 | O3: =SUMIFS($D$1:$D$203,$L$1:$L$203,O$2,$I$1:$I$203,$M3) -> 0 | P3: =SUMIFS($D$1:$D$203,$L$1:$L$203,P$2,$I$1:$I$203,$M3) -> 0 | Q3: =SUMIFS($D$1:$D$203,$L$1:$L$203,Q$2,$I$1:$I$203,$M3) -> 0 | R3: =SUMIFS($D$1:$D$203,$L$1:$L$203,R$2,$I$1:$I$203,$M3) -> 0 | S3: =SUMIFS($D$1:$D$203,$L$1:$L$203,S$2,$I$1:$I$203,$M3) -> 4143468 | T3: =SUMIFS($D$1:$D$203,$L$1:$L$203,T$2,$I$1:$I$203,$M3) -> 0 | U3: =SUMIFS($D$1:$D$203,$L$1:$L$203,U$2,$I$1:$I$203,$M3) -> 0 | ... W3: =SUMIFS($D$1:$D$203,$L$1:$L$203,W$2,$I$1:$I$203,$M3) -> 0 | X3: 1986 | Y3: 76.8 | Z3: =$Y$32/Y3 -> 1.3020833 | AB3: 1976 | AC3: 77.7 | AD3: =$AC$51/AC3 -> 1.6988417
B4: 755516 | C4: 薬品注入ポンプ（NKW-20VL-CIH） | D4: =ROUND(B4*H4,0) -> 1060937 | E4: 15 | F4: H21 | G4: =VLOOKUP(F4,Sheet2!$B$2:$C$70,2,FALSE) -> 2009 | H4: =VLOOKUP(G4,$AB$1:$AD$51,3,FALSE) -> 1.4042553 | I4: 配水・給水設備 | K4: =ROUND(E4*1.5,0) -> 23 | L4: =G4+K4 -> 2032 | M4: 配水・給水施設 | N4: =SUMIFS($D$1:$D$203,$L$1:$L$203,N$2,$I$1:$I$203,$M4) -> 0 | O4: =SUMIFS($D$1:$D$203,$L$1:$L$203,O$2,$I$1:$I$203,$M4) -> 0 | P4: =SUMIFS($D$1:$D$203,$L$1:$L$203,P$2,$I$1:$I$203,$M4) -> 0 | Q4: =SUMIFS($D$1:$D$203,$L$1:$L$203,Q$2,$I$1:$I$203,$M4) -> 0 | R4: =SUMIFS($D$1:$D$203,$L$1:$L$203,R$2,$I$1:$I$203,$M4) -> 0 | S4: =SUMIFS($D$1:$D$203,$L$1:$L$203,S$2,$I$1:$I$203,$M4) -> 3351730 | T4: =SUMIFS($D$1:$D$203,$L$1:$L$203,T$2,$I$1:$I$203,$M4) -> 0 | U4: =SUMIFS($D$1:$D$203,$L$1:$L$203,U$2,$I$1:$I$203,$M4) -> 0 | ... W4: =SUMIFS($D$1:$D$203,$L$1:$L$203,W$2,$I$1:$I$203,$M4) -> 0 | X4: 1987 | Y4: 77.3 | Z4: =$Y$32/Y4 -> 1.2936611 | AB4: 1977 | AC4: 77.7 | AD4: =$AC$51/AC4 -> 1.6988417
B5: 693900 | C5: 水位計 | D5: =ROUND(B5*H5,0) -> 973377 | E5: 10 | F5: H22 | G5: =VLOOKUP(F5,Sheet2!$B$2:$C$70,2,FALSE) -> 2010 | H5: =VLOOKUP(G5,$AB$1:$AD$51,3,FALSE) -> 1.402763 | I5: 配水・給水設備 | K5: =ROUND(E5*1.5,0) -> 15 | L5: =G5+K5 -> 2025 | M5: 取水・浄水設備 | N5: =SUMIFS($D$1:$D$203,$L$1:$L$203,N$2,$I$1:$I$203,$M5) -> 0 | O5: =SUMIFS($D$1:$D$203,$L$1:$L$203,O$2,$I$1:$I$203,$M5) -> 0 | P5: =SUMIFS($D$1:$D$203,$L$1:$L$203,P$2,$I$1:$I$203,$M5) -> 0 | Q5: =SUMIFS($D$1:$D$203,$L$1:$L$203,Q$2,$I$1:$I$203,$M5) -> 0 | R5: =SUMIFS($D$1:$D$203,$L$1:$L$203,R$2,$I$1:$I$203,$M5) -> 0 | S5: =SUMIFS($D$1:$D$203,$L$1:$L$203,S$2,$I$1:$I$203,$M5) -> 0 | T5: =SUMIFS($D$1:$D$203,$L$1:$L$203,T$2,$I$1:$I$203,$M5) -> 0 | U5: =SUMIFS($D$1:$D$203,$L$1:$L$203,U$2,$I$1:$I$203,$M5) -> 0 | ... W5: =SUMIFS($D$1:$D$203,$L$1:$L$203,W$2,$I$1:$I$203,$M5) -> 0 | X5: 1988 | Y5: 78.7 | Z5: =$Y$32/Y5 -> 1.270648 | AB5: 1978 | AC5: 77.7 | AD5: =$AC$51/AC5 -> 1.6988417
B6: 615009 | C6: 排水設備 | D6: =ROUND(B6*H6,0) -> 862712 | E6: 20 | F6: H22 | G6: =VLOOKUP(F6,Sheet2!$B$2:$C$70,2,FALSE) -> 2010 | H6: =VLOOKUP(G6,$AB$1:$AD$51,3,FALSE) -> 1.402763 | I6: 配水・給水設備 | K6: =ROUND(E6*1.5,0) -> 30 | L6: =G6+K6 -> 2040 | M6: 配水・給水設備 | N6: =SUMIFS($D$1:$D$203,$L$1:$L$203,N$2,$I$1:$I$203,$M6) -> 5213139 | O6: =SUMIFS($D$1:$D$203,$L$1:$L$203,O$2,$I$1:$I$203,$M6) -> 0 | P6: =SUMIFS($D$1:$D$203,$L$1:$L$203,P$2,$I$1:$I$203,$M6) -> 24757302 | Q6: =SUMIFS($D$1:$D$203,$L$1:$L$203,Q$2,$I$1:$I$203,$M6) -> 1258482 | R6: =SUMIFS($D$1:$D$203,$L$1:$L$203,R$2,$I$1:$I$203,$M6) -> 74777679 | S6: =SUMIFS($D$1:$D$203,$L$1:$L$203,S$2,$I$1:$I$203,$M6) -> 6794350 | T6: =SUMIFS($D$1:$D$203,$L$1:$L$203,T$2,$I$1:$I$203,$M6) -> 20517734 | U6: =SUMIFS($D$1:$D$203,$L$1:$L$203,U$2,$I$1:$I$203,$M6) -> 19106249 | ... W6: =SUMIFS($D$1:$D$203,$L$1:$L$203,W$2,$I$1:$I$203,$M6) -> 0 | X6: 1989 | Y6: 82.4 | Z6: =$Y$32/Y6 -> 1.2135922 | AB6: 1979 | AC6: 77.7 | AD6: =$AC$51/AC6 -> 1.6988417
B7: 321730 | C7: 無試薬形遊離塩素計 | D7: =ROUND(B7*H7,0) -> 401402 | E7: 10 | F7: H30 | G7: =VLOOKUP(F7,Sheet2!$B$2:$C$70,2,FALSE) -> 2018 | H7: =VLOOKUP(G7,$AB$1:$AD$51,3,FALSE) -> 1.2476371 | I7: 配水・給水設備 | K7: =ROUND(E7*1.5,0) -> 15 | L7: =G7+K7 -> 2033 | M7: 管路 | N7: =SUMIFS($D$1:$D$203,$L$1:$L$203,N$2,$I$1:$I$203,$M7) -> 0 | O7: =SUMIFS($D$1:$D$203,$L$1:$L$203,O$2,$I$1:$I$203,$M7) -> 0 | P7: =SUMIFS($D$1:$D$203,$L$1:$L$203,P$2,$I$1:$I$203,$M7) -> 0 | Q7: =SUMIFS($D$1:$D$203,$L$1:$L$203,Q$2,$I$1:$I$203,$M7) -> 0 | R7: =SUMIFS($D$1:$D$203,$L$1:$L$203,R$2,$I$1:$I$203,$M7) -> 0 | S7: =SUMIFS($D$1:$D$203,$L$1:$L$203,S$2,$I$1:$I$203,$M7) -> 20864978 | T7: =SUMIFS($D$1:$D$203,$L$1:$L$203,T$2,$I$1:$I$203,$M7) -> 0 | U7: =SUMIFS($D$1:$D$203,$L$1:$L$203,U$2,$I$1:$I$203,$M7) -> 0 | ... W7: =SUMIFS($D$1:$D$203,$L$1:$L$203,W$2,$I$1:$I$203,$M7) -> 0 | X7: 1990 | Y7: 85.3 | Z7: =$Y$32/Y7 -> 1.1723329 | AB7: 1980 | AC7: 77.7 | AD7: =$AC$51/AC7 -> 1.6988417
B8: 6069467 | C8: 増圧ポンプ | D8: =ROUND(B8*H8,0) -> 7572492 | E8: 15 | F8: H30 | G8: =VLOOKUP(F8,Sheet2!$B$2:$C$70,2,FALSE) -> 2018 | H8: =VLOOKUP(G8,$AB$1:$AD$51,3,FALSE) -> 1.2476371 | I8: 配水・給水設備 | K8: =ROUND(E8*1.5,0) -> 23 | L8: =G8+K8 -> 2041 | X8: 1991 | Y8: 87.6 | Z8: =$Y$32/Y8 -> 1.1415525 | AB8: 1981 | AC8: 77.7 | AD8: =$AC$51/AC8 -> 1.6988417
B9: 3339935 | C9: 遠方通報装置 | D9: =ROUND(B9*H9,0) -> 4167027 | E9: 9 | F9: H30 | G9: =VLOOKUP(F9,Sheet2!$B$2:$C$70,2,FALSE) -> 2018 | H9: =VLOOKUP(G9,$AB$1:$AD$51,3,FALSE) -> 1.2476371 | I9: 配水・給水設備 | K9: =ROUND(E9*1.5,0) -> 14 | L9: =G9+K9 -> 2032 | N9: 2026 | O9: 2027 | P9: 2028 | Q9: 2029 | R9: 2030 | S9: 2031 | T9: 2032 | U9: 2033 | V9: 2034 | W9: 2035 | X9: 1992 | Y9: 88.6 | Z9: =$Y$32/Y9 -> 1.1286682 | AB9: 1982 | AC9: 77.7 | AD9: =$AC$51/AC9 -> 1.6988417
B10: 2130648 | C10: 増圧ポンプ | D10: =ROUND(B10*H10,0) -> 2582604 | E10: 15 | F10: R2 | G10: =VLOOKUP(F10,Sheet2!$B$2:$C$70,2,FALSE) -> 2020 | H10: =VLOOKUP(G10,$AB$1:$AD$51,3,FALSE) -> 1.2121212 | I10: 配水・給水設備 | K10: =ROUND(E10*1.5,0) -> 23 | L10: =G10+K10 -> 2043 | M10: 取水・浄水施設 | N10: =ROUND(N3/1000,0) -> 0 | O10: =ROUND(O3/1000,0) -> 0 | P10: =ROUND(P3/1000,0) -> 0 | Q10: =ROUND(Q3/1000,0) -> 0 | R10: =ROUND(R3/1000,0) -> 0 | S10: =ROUND(S3/1000,0) -> 4143 | T10: =ROUND(T3/1000,0) -> 0 | U10: =ROUND(U3/1000,0) -> 0 | ... W10: =ROUND(W3/1000,0) -> 0 | X10: 1993 | Y10: 88.4 | Z10: =$Y$32/Y10 -> 1.1312217 | AB10: 1983 | AC10: 77.7 | AD10: =$AC$51/AC10 -> 1.6988417
B11: 3685445 | C11: 配水管 | D11: =ROUND(B11*H11,0) -> 4467206 | E11: 40 | F11: R2 | G11: =VLOOKUP(F11,Sheet2!$B$2:$C$70,2,FALSE) -> 2020 | H11: =VLOOKUP(G11,$AB$1:$AD$51,3,FALSE) -> 1.2121212 | I11: 管路 | K11: =ROUND(E11*1.5,0) -> 60 | L11: =G11+K11 -> 2080 | M11: 配水・給水施設 | N11: =ROUND(N4/1000,0) -> 0 | O11: =ROUND(O4/1000,0) -> 0 | P11: =ROUND(P4/1000,0) -> 0 | Q11: =ROUND(Q4/1000,0) -> 0 | R11: =ROUND(R4/1000,0) -> 0 | S11: =ROUND(S4/1000,0) -> 3352 | T11: =ROUND(T4/1000,0) -> 0 | U11: =ROUND(U4/1000,0) -> 0 | ... W11: =ROUND(W4/1000,0) -> 0 | X11: 1994 | Y11: 88.6 | Z11: =$Y$32/Y11 -> 1.1286682 | AB11: 1984 | AC11: 77.7 | AD11: =$AC$51/AC11 -> 1.6988417
B12: 2303403 | C12: フェンス | D12: =ROUND(B12*H12,0) -> 3190443 | E12: 60 | F12: H23 | G12: =VLOOKUP(F12,Sheet2!$B$2:$C$70,2,FALSE) -> 2011 | H12: =VLOOKUP(G12,$AB$1:$AD$51,3,FALSE) -> 1.3850997 | I12: 配水・給水設備 | K12: =ROUND(E12*1.5,0) -> 90 | L12: =G12+K12 -> 2101 | M12: 取水・浄水設備 | N12: =ROUND(N5/1000,0) -> 0 | O12: =ROUND(O5/1000,0) -> 0 | P12: =ROUND(P5/1000,0) -> 0 | Q12: =ROUND(Q5/1000,0) -> 0 | R12: =ROUND(R5/1000,0) -> 0 | S12: =ROUND(S5/1000,0) -> 0 | T12: =ROUND(T5/1000,0) -> 0 | U12: =ROUND(U5/1000,0) -> 0 | ... W12: =ROUND(W5/1000,0) -> 0 | X12: 1995 | Y12: 88.8 | Z12: =$Y$32/Y12 -> 1.1261261 | AB12: 1985 | AC12: 77.7 | AD12: =$AC$51/AC12 -> 1.6988417
B13: 3800615 | C13: 管路一式 | D13: =ROUND(B13*H13,0) -> 5042022 | E13: 40 | F13: H26 | G13: =VLOOKUP(F13,Sheet2!$B$2:$C$70,2,FALSE) -> 2014 | H13: =VLOOKUP(G13,$AB$1:$AD$51,3,FALSE) -> 1.3266332 | I13: 管路 | K13: =ROUND(E13*1.5,0) -> 60 | L13: =G13+K13 -> 2074 | M13: 配水・給水設備 | N13: =ROUND(N6/1000,0) -> 5213 | O13: =ROUND(O6/1000,0) -> 0 | P13: =ROUND(P6/1000,0) -> 24757 | Q13: =ROUND(Q6/1000,0) -> 1258 | R13: =ROUND(R6/1000,0) -> 74778 | S13: =ROUND(S6/1000,0) -> 6794 | T13: =ROUND(T6/1000,0) -> 20518 | U13: =ROUND(U6/1000,0) -> 19106 | ... W13: =ROUND(W6/1000,0) -> 0 | X13: 1996 | Y13: 88.5 | Z13: =$Y$32/Y13 -> 1.1299435 | AB13: 1986 | AC13: 76.8 | AD13: =$AC$51/AC13 -> 1.71875
B14: 1071082 | C14: 次亜塩注入器 | D14: =ROUND(B14*H14,0) -> 1298281 | E14: 10 | F14: R1 | G14: =VLOOKUP(F14,Sheet2!$B$2:$C$70,2,FALSE) -> 2019 | H14: =VLOOKUP(G14,$AB$1:$AD$51,3,FALSE) -> 1.2121212 | I14: 配水・給水設備 | K14: =ROUND(E14*1.5,0) -> 15 | L14: =G14+K14 -> 2034 | M14: 管路 | N14: =ROUND(N7/1000,0) -> 0 | O14: =ROUND(O7/1000,0) -> 0 | P14: =ROUND(P7/1000,0) -> 0 | Q14: =ROUND(Q7/1000,0) -> 0 | R14: =ROUND(R7/1000,0) -> 0 | S14: =ROUND(S7/1000,0) -> 20865 | T14: =ROUND(T7/1000,0) -> 0 | U14: =ROUND(U7/1000,0) -> 0 | ... W14: =ROUND(W7/1000,0) -> 0 | X14: 1997 | Y14: 89.4 | Z14: =$Y$32/Y14 -> 1.1185682 | AB14: 1987 | AC14: 77.3 | AD14: =$AC$51/AC14 -> 1.7076326
B15: 345510 | C15: 配水管 | D15: =ROUND(B15*H15,0) -> 586967 | E15: 40 | F15: S59 | G15: =VLOOKUP(F15,Sheet2!$B$2:$C$70,2,FALSE) -> 1984 | H15: =VLOOKUP(G15,$AB$1:$AD$51,3,FALSE) -> 1.6988417 | I15: 管路 | K15: =ROUND(E15*1.5,0) -> 60 | L15: =G15+K15 -> 2044 | X15: 1998 | Y15: 88 | Z15: =$Y$32/Y15 -> 1.1363636 | AB15: 1988 | AC15: 78.7 | AD15: =$AC$51/AC15 -> 1.6772554
B16: 1900308 | C16: 湧水井戸 | D16: =ROUND(B16*H16,0) -> 3228322 | E16: 40 | F16: S60 | G16: =VLOOKUP(F16,Sheet2!$B$2:$C$70,2,FALSE) -> 1985 | H16: =VLOOKUP(G16,$AB$1:$AD$51,3,FALSE) -> 1.6988417 | I16: 取水・浄水施設 | K16: =ROUND(E16*1.5,0) -> 60 | L16: =G16+K16 -> 2045 | X16: 1999 | Y16: 87 | Z16: =$Y$32/Y16 -> 1.1494253 | AB16: 1989 | AC16: 82.4 | AD16: =$AC$51/AC16 -> 1.6019417
B17: 493504 | C17: 砕石 | D17: =ROUND(B17*H17,0) -> 748765 | E17: 40 | F17: H11 | G17: =VLOOKUP(F17,Sheet2!$B$2:$C$70,2,FALSE) -> 1999 | H17: =VLOOKUP(G17,$AB$1:$AD$51,3,FALSE) -> 1.5172414 | I17: 取水・浄水施設 | K17: =ROUND(E17*1.5,0) -> 60 | L17: =G17+K17 -> 2059 | X17: 2000 | Y17: 87.2 | Z17: =$Y$32/Y17 -> 1.146789 | AB17: 1990 | AC17: 85.3 | AD17: =$AC$51/AC17 -> 1.5474795
B18: 341988 | C18: 水源地施設 | D18: =ROUND(B18*H18,0) -> 517688 | E18: 40 | F18: H12 | G18: =VLOOKUP(F18,Sheet2!$B$2:$C$70,2,FALSE) -> 2000 | H18: =VLOOKUP(G18,$AB$1:$AD$51,3,FALSE) -> 1.5137615 | I18: 取水・浄水施設 | K18: =ROUND(E18*1.5,0) -> 60 | L18: =G18+K18 -> 2060 | X18: 2001 | Y18: 85.6 | Z18: =$Y$32/Y18 -> 1.1682243 | AB18: 1991 | AC18: 87.6 | AD18: =$AC$51/AC18 -> 1.5068493
B19: 1471331 | C19: 管路一式 | D19: =ROUND(B19*H19,0) -> 2227244 | E19: 40 | F19: H12 | G19: =VLOOKUP(F19,Sheet2!$B$2:$C$70,2,FALSE) -> 2000 | H19: =VLOOKUP(G19,$AB$1:$AD$51,3,FALSE) -> 1.5137615 | I19: 管路 | K19: =ROUND(E19*1.5,0) -> 60 | L19: =G19+K19 -> 2060 | X19: 2002 | Y19: 85 | Z19: =$Y$32/Y19 -> 1.1764706 | AB19: 1992 | AC19: 88.6 | AD19: =$AC$51/AC19 -> 1.489842
B20: 13431685 | C20: 建屋 | D20: =ROUND(B20*H20,0) -> 20332367 | E20: 50 | F20: H12 | G20: =VLOOKUP(F20,Sheet2!$B$2:$C$70,2,FALSE) -> 2000 | H20: =VLOOKUP(G20,$AB$1:$AD$51,3,FALSE) -> 1.5137615 | I20: 取水・浄水施設 | K20: =ROUND(E20*1.5,0) -> 75 | L20: =G20+K20 -> 2075 | X20: 2003 | Y20: 86 | Z20: =$Y$32/Y20 -> 1.1627907 | AB20: 1993 | AC20: 88.4 | AD20: =$AC$51/AC20 -> 1.4932127
B21: 5752823 | C21: 浄水施設 配水池 | D21: =ROUND(B21*H21,0) -> 8708402 | E21: 60 | F21: H12 | G21: =VLOOKUP(F21,Sheet2!$B$2:$C$70,2,FALSE) -> 2000 | H21: =VLOOKUP(G21,$AB$1:$AD$51,3,FALSE) -> 1.5137615 | I21: 取水・浄水施設 | K21: =ROUND(E21*1.5,0) -> 90 | L21: =G21+K21 -> 2090 | X21: 2004 | Y21: 87.5 | Z21: =$Y$32/Y21 -> 1.1428571 | AB21: 1994 | AC21: 88.6 | AD21: =$AC$51/AC21 -> 1.489842
B22: 35619073 | C22: 機械設備 | D22: =ROUND(B22*H22,0) -> 53918780 | E22: 20 | F22: H12 | G22: =VLOOKUP(F22,Sheet2!$B$2:$C$70,2,FALSE) -> 2000 | H22: =VLOOKUP(G22,$AB$1:$AD$51,3,FALSE) -> 1.5137615 | I22: 配水・給水設備 | K22: =ROUND(E22*1.5,0) -> 30 | L22: =G22+K22 -> 2030 | X22: 2005 | Y22: 89 | Z22: =$Y$32/Y22 -> 1.1235955 | AB22: 1995 | AC22: 88.8 | AD22: =$AC$51/AC22 -> 1.4864865
B23: 20711870 | C23: 電気計装設備 | D23: =ROUND(B23*H23,0) -> 31352831 | E23: 10 | F23: H12 | G23: =VLOOKUP(F23,Sheet2!$B$2:$C$70,2,FALSE) -> 2000 | H23: =VLOOKUP(G23,$AB$1:$AD$51,3,FALSE) -> 1.5137615 | I23: 配水・給水設備 | K23: =ROUND(E23*1.5,0) -> 15 | L23: =G23+K23 -> 2015 | X23: 2006 | Y23: 90.6 | Z23: =$Y$32/Y23 -> 1.1037528 | AB23: 1996 | AC23: 88.5 | AD23: =$AC$51/AC23 -> 1.4915254
B24: 529783 | C24: 緊急警報装置 | D24: =ROUND(B24*H24,0) -> 738451 | E24: 9 | F24: H24 | G24: =VLOOKUP(F24,Sheet2!$B$2:$C$70,2,FALSE) -> 2012 | H24: =VLOOKUP(G24,$AB$1:$AD$51,3,FALSE) -> 1.3938754 | I24: 配水・給水設備 | K24: =ROUND(E24*1.5,0) -> 14 | L24: =G24+K24 -> 2026 | X24: 2007 | Y24: 93.5 | Z24: =$Y$32/Y24 -> 1.0695187 | AB24: 1997 | AC24: 89.4 | AD24: =$AC$51/AC24 -> 1.4765101
B25: 5308193 | C25: 制水弁設置工事 | D25: =ROUND(B25*H25,0) -> 7253431 | E25: 20 | F25: H25 | G25: =VLOOKUP(F25,Sheet2!$B$2:$C$70,2,FALSE) -> 2013 | H25: =VLOOKUP(G25,$AB$1:$AD$51,3,FALSE) -> 1.3664596 | I25: 配水・給水設備 | K25: =ROUND(E25*1.5,0) -> 30 | L25: =G25+K25 -> 2043 | X25: 2008 | Y25: 98.8 | Z25: =$Y$32/Y25 -> 1.0121457 | AB25: 1998 | AC25: 88 | AD25: =$AC$51/AC25 -> 1.5
B26: 3535724 | C26: 減圧弁 | D26: =ROUND(B26*H26,0) -> 4575643 | E26: 20 | F26: H29 | G26: =VLOOKUP(F26,Sheet2!$B$2:$C$70,2,FALSE) -> 2017 | H26: =VLOOKUP(G26,$AB$1:$AD$51,3,FALSE) -> 1.2941176 | I26: 配水・給水設備 | K26: =ROUND(E26*1.5,0) -> 30 | L26: =G26+K26 -> 2047 | X26: 2009 | Y26: 94 | Z26: =$Y$32/Y26 -> 1.0638298 | AB26: 1999 | AC26: 87 | AD26: =$AC$51/AC26 -> 1.5172414
... B29: 2084580 | C29: 浄水UF膜 | D29: =ROUND(B29*H29,0) -> 2420093 | E29: 20 | F29: R3 | G29: =VLOOKUP(F29,Sheet2!$B$2:$C$70,2,FALSE) -> 2021 | H29: =VLOOKUP(G29,$AB$1:$AD$51,3,FALSE) -> 1.1609499 | I29: 配水・給水設備 | K29: =ROUND(E29*1.5,0) -> 30 | L29: =G29+K29 -> 2051 | X29: 2012 | Y29: 94.7 | Z29: =$Y$32/Y29 -> 1.0559662 | AB29: 2002 | AC29: 85 | AD29: =$AC$51/AC29 -> 1.5529412
B30: 915296 | C30: 水源施設 第1取水 | D30: =ROUND(B30*H30,0) -> 1554943 | E30: 40 | F30: S46 | G30: =VLOOKUP(F30,Sheet2!$B$2:$C$70,2,FALSE) -> 1971 | H30: 1.6988417 | I30: 取水・浄水施設 | K30: =ROUND(E30*1.5,0) -> 60 | L30: =G30+K30 -> 2031 | X30: 2013 | Y30: 96.6 | Z30: =$Y$32/Y30 -> 1.0351967 | AB30: 2003 | AC30: 86 | AD30: =$AC$51/AC30 -> 1.5348837
B31: 1523700 | C31: 水源施設 第2取水 | D31: =ROUND(B31*H31,0) -> 2588525 | E31: 40 | F31: S46 | G31: =VLOOKUP(F31,Sheet2!$B$2:$C$70,2,FALSE) -> 1971 | H31: 1.6988417 | I31: 取水・浄水施設 | K31: =ROUND(E31*1.5,0) -> 60 | L31: =G31+K31 -> 2031 | X31: 2014 | Y31: 99.5 | Z31: =$Y$32/Y31 -> 1.0050251 | AB31: 2004 | AC31: 87.5 | AD31: =$AC$51/AC31 -> 1.5085714
B32: 12183990 | C32: 管路一式 | D32: =ROUND(B32*H32,0) -> 20698670 | E32: 40 | F32: S46 | G32: =VLOOKUP(F32,Sheet2!$B$2:$C$70,2,FALSE) -> 1971 | H32: 1.6988417 | I32: 管路 | K32: =ROUND(E32*1.5,0) -> 60 | L32: =G32+K32 -> 2031 | X32: 2015 | Y32: 100 | Z32: =$Y$32/Y32 -> 1 | AB32: 2005 | AC32: 89 | AD32: =$AC$51/AC32 -> 1.4831461
B33: 508511 | C33: 送水施設 減圧槽 | D33: =ROUND(B33*H33,0) -> 863880 | E33: 60 | F33: S46 | G33: =VLOOKUP(F33,Sheet2!$B$2:$C$70,2,FALSE) -> 1971 | H33: 1.6988417 | I33: 配水・給水施設 | K33: =ROUND(E33*1.5,0) -> 90 | L33: =G33+K33 -> 2061 | X33: 2016 | Y33: 100.1 | Z33: =$Y$32/Y33 -> 0.999001 | AB33: 2006 | AC33: 90.6 | AD33: =$AC$51/AC33 -> 1.4569536
B34: 970654 | C34: 浄水施設 滅菌設備棟 | D34: =ROUND(B34*H34,0) -> 1648987 | E34: 50 | F34: S46 | G34: =VLOOKUP(F34,Sheet2!$B$2:$C$70,2,FALSE) -> 1971 | H34: 1.6988417 | I34: 取水・浄水施設 | K34: =ROUND(E34*1.5,0) -> 75 | L34: =G34+K34 -> 2046 | X34: 2017 | Y34: 102 | Z34: =$Y$32/Y34 -> 0.98039216 | AB34: 2007 | AC34: 93.5 | AD34: =$AC$51/AC34 -> 1.4117647
B35: 731578 | C35: 浄水施設 着水井 | D35: =ROUND(B35*H35,0) -> 1242835 | E35: 60 | F35: S46 | G35: =VLOOKUP(F35,Sheet2!$B$2:$C$70,2,FALSE) -> 1971 | H35: 1.6988417 | I35: 取水・浄水施設 | K35: =ROUND(E35*1.5,0) -> 90 | L35: =G35+K35 -> 2061 | X35: 2018 | Y35: 105.8 | Z35: =$Y$32/Y35 -> 0.94517958 | AB35: 2008 | AC35: 98.8 | AD35: =$AC$51/AC35 -> 1.3360324
B36: 687236 | C36: 浄水施設 滅菌設備 | D36: =ROUND(B36*H36,0) -> 1167505 | E36: 10 | F36: S46 | G36: =VLOOKUP(F36,Sheet2!$B$2:$C$70,2,FALSE) -> 1971 | H36: 1.6988417 | I36: 取水・浄水施設 | K36: =ROUND(E36*1.5,0) -> 15 | L36: =G36+K36 -> 1986 | X36: 2019 | Y36: 108.9 | Z36: =$Y$32/Y36 -> 0.91827365 | AB36: 2009 | AC36: 94 | AD36: =$AC$51/AC36 -> 1.4042553
B37: 2849736 | C37: 配水施設 配水池 | D37: =ROUND(B37*H37,0) -> 4841250 | E37: 60 | F37: S46 | G37: =VLOOKUP(F37,Sheet2!$B$2:$C$70,2,FALSE) -> 1971 | H37: 1.6988417 | I37: 配水・給水施設 | K37: =ROUND(E37*1.5,0) -> 90 | L37: =G37+K37 -> 2061 | X37: 2020 | Y37: 108.9 | Z37: =$Y$32/Y37 -> 0.91827365 | AB37: 2010 | AC37: 94.1 | AD37: =$AC$51/AC37 -> 1.402763
B38: 539105 | C38: 配水施設 減圧槽 | D38: =ROUND(B38*H38,0) -> 915854 | E38: 60 | F38: S46 | G38: =VLOOKUP(F38,Sheet2!$B$2:$C$70,2,FALSE) -> 1971 | H38: 1.6988417 | I38: 配水・給水施設 | K38: =ROUND(E38*1.5,0) -> 90 | L38: =G38+K38 -> 2061 | X38: 2021 | Y38: 113.7 | Z38: =$Y$32/Y38 -> 0.87950748 | AB38: 2011 | AC38: 95.3 | AD38: =$AC$51/AC38 -> 1.3850997
B39: 279129 | C39: 水深及浄水場内柵 | D39: =ROUND(B39*H39,0) -> 474196 | E39: 60 | F39: S46 | G39: =VLOOKUP(F39,Sheet2!$B$2:$C$70,2,FALSE) -> 1971 | H39: 1.6988417 | I39: 配水・給水施設 | K39: =ROUND(E39*1.5,0) -> 90 | L39: =G39+K39 -> 2061 | X39: 2022 | Y39: 122.8 | Z39: =$Y$32/Y39 -> 0.81433225 | AB39: 2012 | AC39: 94.7 | AD39: =$AC$51/AC39 -> 1.3938754
B40: 647538 | C40: 量水器ボックス | D40: =ROUND(B40*H40,0) -> 1100065 | E40: 60 | F40: S46 | G40: =VLOOKUP(F40,Sheet2!$B$2:$C$70,2,FALSE) -> 1971 | H40: 1.6988417 | I40: 配水・給水施設 | K40: =ROUND(E40*1.5,0) -> 90 | L40: =G40+K40 -> 2061 | X40: 2023 | Y40: 127.1 | Z40: =$Y$32/Y40 -> 0.78678206 | AB40: 2013 | AC40: 96.6 | AD40: =$AC$51/AC40 -> 1.3664596 | AG40: 100 | AH40: 132 | AI40: =AG40*AJ40/AH40 -> 75.757576 | AJ40: 100
B41: 97895 | C41: 配水池排泥管 | D41: =ROUND(B41*H41,0) -> 166308 | E41: 40 | F41: S46 | G41: =VLOOKUP(F41,Sheet2!$B$2:$C$70,2,FALSE) -> 1971 | H41: 1.6988417 | I41: 管路 | K41: =ROUND(E41*1.5,0) -> 60 | L41: =G41+K41 -> 2031 | X41: 2024 | Y41: 132 | Z41: =$Y$32/Y41 -> 0.75757576 | AB41: 2014 | AC41: 99.5 | AD41: =$AC$51/AC41 -> 1.3266332
B42: 1972950 | C42: 給水装置 | D42: =ROUND(B42*H42,0) -> 3351730 | E42: 40 | F42: S46 | G42: =VLOOKUP(F42,Sheet2!$B$2:$C$70,2,FALSE) -> 1971 | H42: 1.6988417 | I42: 配水・給水施設 | K42: =ROUND(E42*1.5,0) -> 60 | L42: =G42+K42 -> 2031 | AB42: 2015 | AC42: 100 | AD42: =$AC$51/AC42 -> 1.32
...

Sheet Sheet1
C1: 資産名称 | D1: 取得価額 | E1: 耐用年数 | F1: 取得年度 | H1: コード | I1: 区分 | J1: 係数 | K1: 限界耐用年数 | L1: 限界年度
C2: 流入ポンプ棟_土木躯体 | D2: 95930106 | E2: 50 | F2: H17 | G2: =VLOOKUP(F2,Sheet2!$B$2:$C$90,2,FALSE) -> 2005 | H2: 610104001000 | I2: 建物 | J2: 1.5 | K2: =ROUND(E2*J2,0) -> 75 | L2: =G2+K2 -> 2080 | N2: 2026 | O2: 2027 | P2: 2028 | Q2: 2029 | R2: 2030 | S2: 2031 | T2: 2032 | U2: 2033 | V2: 2034 | W2: 2035
C3: オキシデーションディッチ_土木躯体 | D3: 127211158 | E3: 50 | F3: H17 | G3: =VLOOKUP(F3,Sheet2!$B$2:$C$90,2,FALSE) -> 2005 | H3: 610104001000 | I3: 建物 | J3: 1.5 | K3: =ROUND(E3*J3,0) -> 75 | L3: =G3+K3 -> 2080 | M3: 建物 | N3: =SUMIFS($D$1:$D$203,$L$1:$L$203,N$2,$I$1:$I$203,$M3) -> 0 | O3: =SUMIFS($D$1:$D$203,$L$1:$L$203,O$2,$I$1:$I$203,$M3) -> 0 | P3: =SUMIFS($D$1:$D$203,$L$1:$L$203,P$2,$I$1:$I$203,$M3) -> 0 | Q3: =SUMIFS($D$1:$D$203,$L$1:$L$203,Q$2,$I$1:$I$203,$M3) -> 0 | R3: =SUMIFS($D$1:$D$203,$L$1:$L$203,R$2,$I$1:$I$203,$M3) -> 0 | S3: =SUMIFS($D$1:$D$203,$L$1:$L$203,S$2,$I$1:$I$203,$M3) -> 0 | T3: =SUMIFS($D$1:$D$203,$L$1:$L$203,T$2,$I$1:$I$203,$M3) -> 0 | U3: =SUMIFS($D$1:$D$203,$L$1:$L$203,U$2,$I$1:$I$203,$M3) -> 0 | ... W3: =SUMIFS($D$1:$D$203,$L$1:$L$203,W$2,$I$1:$I$203,$M3) -> 0
C4: 最終沈殿池_土木躯体 | D4: 63704898 | E4: 50 | F4: H17 | G4: =VLOOKUP(F4,Sheet2!$B$2:$C$90,2,FALSE) -> 2005 | H4: 610104001000 | I4: 建物 | J4: 1.5 | K4: =ROUND(E4*J4,0) -> 75 | L4: =G4+K4 -> 2080 | M4: 処理場設備 | N4: =SUMIFS($D$1:$D$203,$L$1:$L$203,N$2,$I$1:$I$203,$M4) -> 0 | O4: =SUMIFS($D$1:$D$203,$L$1:$L$203,O$2,$I$1:$I$203,$M4) -> 0 | P4: =SUMIFS($D$1:$D$203,$L$1:$L$203,P$2,$I$1:$I$203,$M4) -> 154940800 | Q4: =SUMIFS($D$1:$D$203,$L$1:$L$203,Q$2,$I$1:$I$203,$M4) -> 0 | R4: =SUMIFS($D$1:$D$203,$L$1:$L$203,R$2,$I$1:$I$203,$M4) -> 0 | S4: =SUMIFS($D$1:$D$203,$L$1:$L$203,S$2,$I$1:$I$203,$M4) -> 0 | T4: =SUMIFS($D$1:$D$203,$L$1:$L$203,T$2,$I$1:$I$203,$M4) -> 0 | U4: =SUMIFS($D$1:$D$203,$L$1:$L$203,U$2,$I$1:$I$203,$M4) -> 0 | ... W4: =SUMIFS($D$1:$D$203,$L$1:$L$203,W$2,$I$1:$I$203,$M4) -> 0
C5: 滅菌池_土木躯体 | D5: 21113153 | E5: 50 | F5: H17 | G5: =VLOOKUP(F5,Sheet2!$B$2:$C$90,2,FALSE) -> 2005 | H5: 610104001000 | I5: 建物 | J5: 1.5 | K5: =ROUND(E5*J5,0) -> 75 | L5: =G5+K5 -> 2080 | M5: 処理場機械 | N5: =SUMIFS($D$1:$D$203,$L$1:$L$203,N$2,$I$1:$I$203,$M5) -> 0 | O5: =SUMIFS($D$1:$D$203,$L$1:$L$203,O$2,$I$1:$I$203,$M5) -> 0 | P5: =SUMIFS($D$1:$D$203,$L$1:$L$203,P$2,$I$1:$I$203,$M5) -> 0 | Q5: =SUMIFS($D$1:$D$203,$L$1:$L$203,Q$2,$I$1:$I$203,$M5) -> 0 | R5: =SUMIFS($D$1:$D$203,$L$1:$L$203,R$2,$I$1:$I$203,$M5) -> 0 | S5: =SUMIFS($D$1:$D$203,$L$1:$L$203,S$2,$I$1:$I$203,$M5) -> 0 | T5: =SUMIFS($D$1:$D$203,$L$1:$L$203,T$2,$I$1:$I$203,$M5) -> 0 | U5: =SUMIFS($D$1:$D$203,$L$1:$L$203,U$2,$I$1:$I$203,$M5) -> 0 | ... W5: =SUMIFS($D$1:$D$203,$L$1:$L$203,W$2,$I$1:$I$203,$M5) -> 0
C6: ブロワ室・汚泥ポンプ_土木躯体 | D6: 2552415 | E6: 50 | F6: H17 | G6: =VLOOKUP(F6,Sheet2!$B$2:$C$90,2,FALSE) -> 2005 | H6: 610104001000 | I6: 建物 | J6: 1.5 | K6: =ROUND(E6*J6,0) -> 75 | L6: =G6+K6 -> 2080 | M6: 管渠 | N6: =SUMIFS($D$1:$D$203,$L$1:$L$203,N$2,$I$1:$I$203,$M6) -> 0 | O6: =SUMIFS($D$1:$D$203,$L$1:$L$203,O$2,$I$1:$I$203,$M6) -> 0 | P6: =SUMIFS($D$1:$D$203,$L$1:$L$203,P$2,$I$1:$I$203,$M6) -> 0 | Q6: =SUMIFS($D$1:$D$203,$L$1:$L$203,Q$2,$I$1:$I$203,$M6) -> 0 | R6: =SUMIFS($D$1:$D$203,$L$1:$L$203,R$2,$I$1:$I$203,$M6) -> 0 | S6: =SUMIFS($D$1:$D$203,$L$1:$L$203,S$2,$I$1:$I$203,$M6) -> 0 | T6: =SUMIFS($D$1:$D$203,$L$1:$L$203,T$2,$I$1:$I$203,$M6) -> 0 | U6: =SUMIFS($D$1:$D$203,$L$1:$L$203,U$2,$I$1:$I$203,$M6) -> 0 | ... W6: =SUMIFS($D$1:$D$203,$L$1:$L$203,W$2,$I$1:$I$203,$M6) -> 0
B7: 管理棟 | C7: 管理汚泥棟_土木躯体 | D7: 17729272 | E7: 50 | F7: H17 | G7: =VLOOKUP(F7,Sheet2!$B$2:$C$90,2,FALSE) -> 2005 | H7: 610104001000 | I7: 建物 | J7: 1.5 | K7: =ROUND(E7*J7,0) -> 75 | L7: =G7+K7 -> 2080 | M7: MP | N7: =SUMIFS($D$1:$D$203,$L$1:$L$203,N$2,$I$1:$I$203,$M7) -> 0 | O7: =SUMIFS($D$1:$D$203,$L$1:$L$203,O$2,$I$1:$I$203,$M7) -> 0 | P7: =SUMIFS($D$1:$D$203,$L$1:$L$203,P$2,$I$1:$I$203,$M7) -> 196139904 | Q7: =SUMIFS($D$1:$D$203,$L$1:$L$203,Q$2,$I$1:$I$203,$M7) -> 19468200 | R7: =SUMIFS($D$1:$D$203,$L$1:$L$203,R$2,$I$1:$I$203,$M7) -> 9383952 | S7: =SUMIFS($D$1:$D$203,$L$1:$L$203,S$2,$I$1:$I$203,$M7) -> 12591303 | T7: =SUMIFS($D$1:$D$203,$L$1:$L$203,T$2,$I$1:$I$203,$M7) -> 0 | U7: =SUMIFS($D$1:$D$203,$L$1:$L$203,U$2,$I$1:$I$203,$M7) -> 0 | ... W7: =SUMIFS($D$1:$D$203,$L$1:$L$203,W$2,$I$1:$I$203,$M7) -> 18434564
B8: 管理棟 | C8: 管理汚泥棟_建築躯体 | D8: 281475173 | E8: 50 | F8: H17 | G8: =VLOOKUP(F8,Sheet2!$B$2:$C$90,2,FALSE) -> 2005 | H8: 610102001000 | I8: 建物 | J8: 1.5 | K8: =ROUND(E8*J8,0) -> 75 | L8: =G8+K8 -> 2080
B9: 管理棟 | C9: 管理汚泥等_照明設備 | D9: 21251387 | E9: 15 | F9: H17 | G9: =VLOOKUP(F9,Sheet2!$B$2:$C$90,2,FALSE) -> 2005 | H9: 610102001000 | I9: 処理場設備 | J9: 1.5 | K9: =ROUND(E9*J9,0) -> 23 | L9: =G9+K9 -> 2028 | N9: 2026 | O9: 2027 | P9: 2028 | Q9: 2029 | R9: 2030 | S9: 2031 | T9: 2032 | U9: 2033 | V9: 2034 | W9: 2035
B10: 管理棟 | C10: 管理汚泥等_コンセント設備 | D10: 4368779 | E10: 15 | F10: H17 | G10: =VLOOKUP(F10,Sheet2!$B$2:$C$90,2,FALSE) -> 2005 | H10: 610102001000 | I10: 処理場設備 | J10: 1.5 | K10: =ROUND(E10*J10,0) -> 23 | L10: =G10+K10 -> 2028 | M10: 建物 | N10: =ROUND(N3/1000,0) -> 0 | O10: =ROUND(O3/1000,0) -> 0 | P10: =ROUND(P3/1000,0) -> 0 | Q10: =ROUND(Q3/1000,0) -> 0 | R10: =ROUND(R3/1000,0) -> 0 | S10: =ROUND(S3/1000,0) -> 0 | T10: =ROUND(T3/1000,0) -> 0 | U10: =ROUND(U3/1000,0) -> 0 | ... W10: =ROUND(W3/1000,0) -> 0
B11: 管理棟 | C11: 管理汚泥等_動力設備 | D11: 17233413 | E11: 15 | F11: H17 | G11: =VLOOKUP(F11,Sheet2!$B$2:$C$90,2,FALSE) -> 2005 | H11: 610102001000 | I11: 処理場設備 | J11: 1.5 | K11: =ROUND(E11*J11,0) -> 23 | L11: =G11+K11 -> 2028 | M11: 処理場設備 | N11: =ROUND(N4/1000,0) -> 0 | O11: =ROUND(O4/1000,0) -> 0 | P11: =ROUND(P4/1000,0) -> 154941 | Q11: =ROUND(Q4/1000,0) -> 0 | R11: =ROUND(R4/1000,0) -> 0 | S11: =ROUND(S4/1000,0) -> 0 | T11: =ROUND(T4/1000,0) -> 0 | U11: =ROUND(U4/1000,0) -> 0 | ... W11: =ROUND(W4/1000,0) -> 0
B12: 管理棟 | C12: 管理汚泥等_電話設備 | D12: 1887014 | E12: 15 | F12: H17 | G12: =VLOOKUP(F12,Sheet2!$B$2:$C$90,2,FALSE) -> 2005 | H12: 610102001000 | I12: 処理場設備 | J12: 1.5 | K12: =ROUND(E12*J12,0) -> 23 | L12: =G12+K12 -> 2028 | M12: 処理場機械 | N12: =ROUND(N5/1000,0) -> 0 | O12: =ROUND(O5/1000,0) -> 0 | P12: =ROUND(P5/1000,0) -> 0 | Q12: =ROUND(Q5/1000,0) -> 0 | R12: =ROUND(R5/1000,0) -> 0 | S12: =ROUND(S5/1000,0) -> 0 | T12: =ROUND(T5/1000,0) -> 0 | U12: =ROUND(U5/1000,0) -> 0 | ... W12: =ROUND(W5/1000,0) -> 0
B13: 管理棟 | C13: 管理汚泥等_インターホン設備 | D13: 49953 | E13: 15 | F13: H17 | G13: =VLOOKUP(F13,Sheet2!$B$2:$C$90,2,FALSE) -> 2005 | H13: 610102001000 | I13: 処理場設備 | J13: 1.5 | K13: =ROUND(E13*J13,0) -> 23 | L13: =G13+K13 -> 2028 | M13: 管渠 | N13: =ROUND(N6/1000,0) -> 0 | O13: =ROUND(O6/1000,0) -> 0 | P13: =ROUND(P6/1000,0) -> 0 | Q13: =ROUND(Q6/1000,0) -> 0 | R13: =ROUND(R6/1000,0) -> 0 | S13: =ROUND(S6/1000,0) -> 0 | T13: =ROUND(T6/1000,0) -> 0 | U13: =ROUND(U6/1000,0) -> 0 | ... W13: =ROUND(W6/1000,0) -> 0
B14: 管理棟 | C14: 管理汚泥等_呼出設備 | D14: 345234 | E14: 15 | F14: H17 | G14: =VLOOKUP(F14,Sheet2!$B$2:$C$90,2,FALSE) -> 2005 | H14: 610102001000 | I14: 処理場設備 | J14: 1.5 | K14: =ROUND(E14*J14,0) -> 23 | L14: =G14+K14 -> 2028 | M14: MP | N14: =ROUND(N7/1000,0) -> 0 | O14: =ROUND(O7/1000,0) -> 0 | P14: =ROUND(P7/1000,0) -> 196140 | Q14: =ROUND(Q7/1000,0) -> 19468 | R14: =ROUND(R7/1000,0) -> 9384 | S14: =ROUND(S7/1000,0) -> 12591 | T14: =ROUND(T7/1000,0) -> 0 | U14: =ROUND(U7/1000,0) -> 0 | ... W14: =ROUND(W7/1000,0) -> 18435
B15: 管理棟 | C15: 管理汚泥等_テレビ共同受信設備 | D15: 288940 | E15: 15 | F15: H17 | G15: =VLOOKUP(F15,Sheet2!$B$2:$C$90,2,FALSE) -> 2005 | H15: 610102001000 | I15: 処理場設備 | J15: 1.5 | K15: =ROUND(E15*J15,0) -> 23 | L15: =G15+K15 -> 2028
B16: 管理棟 | C16: 管理汚泥等_防犯設備 | D16: 387964 | E16: 15 | F16: H17 | G16: =VLOOKUP(F16,Sheet2!$B$2:$C$90,2,FALSE) -> 2005 | H16: 610102001000 | I16: 処理場設備 | J16: 1.5 | K16: =ROUND(E16*J16,0) -> 23 | L16: =G16+K16 -> 2028
B17: 管理棟 | C17: 管理汚泥等_火災報知設備 | D17: 8836787 | E17: 15 | F17: H17 | G17: =VLOOKUP(F17,Sheet2!$B$2:$C$90,2,FALSE) -> 2005 | H17: 610102001000 | I17: 処理場設備 | J17: 1.5 | K17: =ROUND(E17*J17,0) -> 23 | L17: =G17+K17 -> 2028
B18: 管理棟 | C18: 管理汚泥等_空調機器設備 | D18: 10724570 | E18: 15 | F18: H17 | G18: =VLOOKUP(F18,Sheet2!$B$2:$C$90,2,FALSE) -> 2005 | H18: 610102001000 | I18: 処理場設備 | J18: 1.5 | K18: =ROUND(E18*J18,0) -> 23 | L18: =G18+K18 -> 2028
B19: 管理棟 | C19: 管理汚泥等_冷媒配管設備 | D19: 551161 | E19: 15 | F19: H17 | G19: =VLOOKUP(F19,Sheet2!$B$2:$C$90,2,FALSE) -> 2005 | H19: 610102001000 | I19: 処理場設備 | J19: 1.5 | K19: =ROUND(E19*J19,0) -> 23 | L19: =G19+K19 -> 2028
B20: 管理棟 | C20: 管理汚泥等_ドレン配管設備 | D20: 598578 | E20: 15 | F20: H17 | G20: =VLOOKUP(F20,Sheet2!$B$2:$C$90,2,FALSE) -> 2005 | H20: 610102001000 | I20: 処理場設備 | J20: 1.5 | K20: =ROUND(E20*J20,0) -> 23 | L20: =G20+K20 -> 2028
B21: 管理棟 | C21: 管理汚泥等_換気機器設備 | D21: 9305431 | E21: 15 | F21: H17 | G21: =VLOOKUP(F21,Sheet2!$B$2:$C$90,2,FALSE) -> 2005 | H21: 610102001000 | I21: 処理場設備 | J21: 1.5 | K21: =ROUND(E21*J21,0) -> 23 | L21: =G21+K21 -> 2028
B22: 管理棟 | C22: 管理汚泥等_換気ダクト設備 | D22: 20457729 | E22: 15 | F22: H17 | G22: =VLOOKUP(F22,Sheet2!$B$2:$C$90,2,FALSE) -> 2005 | H22: 610102001000 | I22: 処理場設備 | J22: 1.5 | K22: =ROUND(E22*J22,0) -> 23 | L22: =G22+K22 -> 2028
B23: 管理棟 | C23: 管理汚泥等_衛生器具設備 | D23: 3125315 | E23: 15 | F23: H17 | G23: =VLOOKUP(F23,Sheet2!$B$2:$C$90,2,FALSE) -> 2005 | H23: 610102001000 | I23: 処理場設備 | J23: 1.5 | K23: =ROUND(E23*J23,0) -> 23 | L23: =G23+K23 -> 2028
B24: 管理棟 | C24: 管理汚泥等_給水設備 | D24: 3008244 | E24: 15 | F24: H17 | G24: =VLOOKUP(F24,Sheet2!$B$2:$C$90,2,FALSE) -> 2005 | H24: 610102001000 | I24: 処理場設備 | J24: 1.5 | K24: =ROUND(E24*J24,0) -> 23 | L24: =G24+K24 -> 2028
B25: 管理棟 | C25: 管理汚泥等_排水設備 | D25: 2494220 | E25: 15 | F25: H17 | G25: =VLOOKUP(F25,Sheet2!$B$2:$C$90,2,FALSE) -> 2005 | H25: 610102001000 | I25: 処理場設備 | J25: 1.5 | K25: =ROUND(E25*J25,0) -> 23 | L25: =G25+K25 -> 2028
B26: 管理棟 | C26: 管理汚泥等_給湯設備 | D26: 1785863 | E26: 15 | F26: H17 | G26: =VLOOKUP(F26,Sheet2!$B$2:$C$90,2,FALSE) -> 2005 | H26: 610102001000 | I26: 処理場設備 | J26: 1.5 | K26: =ROUND(E26*J26,0) -> 23 | L26: =G26+K26 -> 2028
... B68: その他 | C68: 排水設備 | D68: 1795689 | E68: 15 | F68: H17 | G68: =VLOOKUP(F68,Sheet2!$B$2:$C$90,2,FALSE) -> 2005 | H68: 610102001000 | I68: 処理場設備 | J68: 1.5 | K68: =ROUND(E68*J68,0) -> 23 | L68: =G68+K68 -> 2028
C69: 汚水ポンプ | D69: 21647911 | E69: 20 | F69: H17 | G69: =VLOOKUP(F69,Sheet2!$B$2:$C$90,2,FALSE) -> 2005 | H69: 610106002000 | I69: 処理場機械 | J69: 1 | K69: =ROUND(E69*J69,0) -> 20 | L69: =G69+K69 -> 2025
C70: 汚水ポンプ吊上機 | D70: 457414 | E70: 20 | F70: H17 | G70: =VLOOKUP(F70,Sheet2!$B$2:$C$90,2,FALSE) -> 2005 | H70: 610106007000 | I70: 処理場機械 | J70: 1 | K70: =ROUND(E70*J70,0) -> 20 | L70: =G70+K70 -> 2025
C71: スクリーンユニット | D71: 67253448 | E71: 20 | F71: H17 | G71: =VLOOKUP(F71,Sheet2!$B$2:$C$90,2,FALSE) -> 2005 | H71: 610106007000 | I71: 処理場機械 | J71: 1 | K71: =ROUND(E71*J71,0) -> 20 | L71: =G71+K71 -> 2025
C72: 汚水切り替え弁（Φ400） | D72: 2581445 | E72: 20 | F72: H17 | G72: =VLOOKUP(F72,Sheet2!$B$2:$C$90,2,FALSE) -> 2005 | H72: 610106007000 | I72: 処理場機械 | J72: 1 | K72: =ROUND(E72*J72,0) -> 20 | L72: =G72+K72 -> 2025
C73: 分配可動堰 | D73: 4325054 | E73: 20 | F73: H17 | G73: =VLOOKUP(F73,Sheet2!$B$2:$C$90,2,FALSE) -> 2005 | H73: 610106007000 | I73: 処理場機械 | J73: 1 | K73: =ROUND(E73*J73,0) -> 20 | L73: =G73+K73 -> 2025
C74: 汚水切替弁（Φ250） | D74: 1050693 | E74: 20 | F74: H17 | G74: =VLOOKUP(F74,Sheet2!$B$2:$C$90,2,FALSE) -> 2005 | H74: 610106007000 | I74: 処理場機械 | J74: 1 | K74: =ROUND(E74*J74,0) -> 20 | L74: =G74+K74 -> 2025
C75: ディッチ曝気装置 | D75: 126807848 | E75: 20 | F75: H17 | G75: =VLOOKUP(F75,Sheet2!$B$2:$C$90,2,FALSE) -> 2005 | H75: 610106007000 | I75: 処理場機械 | J75: 1 | K75: =ROUND(E75*J75,0) -> 20 | L75: =G75+K75 -> 2025
C76: 送風機吊上機 | D76: 523082 | E76: 20 | F76: H17 | G76: =VLOOKUP(F76,Sheet2!$B$2:$C$90,2,FALSE) -> 2005 | H76: 610106007000 | I76: 処理場機械 | J76: 1 | K76: =ROUND(E76*J76,0) -> 20 | L76: =G76+K76 -> 2025
C77: ディッチ流出可動堰 | D77: 4098611 | E77: 20 | F77: H17 | G77: =VLOOKUP(F77,Sheet2!$B$2:$C$90,2,FALSE) -> 2005 | H77: 610106007000 | I77: 処理場機械 | J77: 1 | K77: =ROUND(E77*J77,0) -> 20 | L77: =G77+K77 -> 2025
C78: ディッチ流出ゲート | D78: 2694666 | E78: 20 | F78: H17 | G78: =VLOOKUP(F78,Sheet2!$B$2:$C$90,2,FALSE) -> 2005 | H78: 610106007000 | I78: 処理場機械 | J78: 1 | K78: =ROUND(E78*J78,0) -> 20 | L78: =G78+K78 -> 2025
C79: ディッチ連絡ゲート | D79: 2694666 | E79: 20 | F79: H17 | G79: =VLOOKUP(F79,Sheet2!$B$2:$C$90,2,FALSE) -> 2005 | H79: 610106007000 | I79: 処理場機械 | J79: 1 | K79: =ROUND(E79*J79,0) -> 20 | L79: =G79+K79 -> 2025
C80: 終沈汚泥掻寄機 | D80: 57742860 | E80: 20 | F80: H17 | G80: =VLOOKUP(F80,Sheet2!$B$2:$C$90,2,FALSE) -> 2005 | H80: 610106007000 | I80: 処理場機械 | J80: 1 | K80: =ROUND(E80*J80,0) -> 20 | L80: =G80+K80 -> 2025
... C203: 管渠一式 | D203: 3120514 | E203: 50 | F203: R3 | G203: =VLOOKUP(F203,Sheet2!$B$2:$C$90,2,FALSE) -> 2021 | H203: 610104002000 | I203: 管渠 | J203: 1.5 | K203: =ROUND(E203*J203,0) -> 75 | L203: =G203+K203 -> 2096
...

Sheet 予測
A1: コード | B1: 市などの別 | C1: 都道府県 | D1: 市区町村 | E1: 総人口（人） | L1: 令和2（2020）年の総人口を100としたときの総人口の指数
E2: 2020年 | F2: 2025年 | G2: 2030年 | H2: 2035年 | I2: 2040年 | J2: 2045年 | K2: 2050年 | L2: 2020年 | M2: 2025年 | N2: 2030年 | O2: 2035年 | P2: 2040年 | Q2: 2045年 | R2: 2050年
A3: 2441 | B3: 3 | C3: 青森県 | D3: 三戸町 | E3: 9082 | F3: 8122 | G3: 7226 | H3: 6371 | I3: 5563 | J3: 4824 | K3: 4143 | L3: 100 | M3: 89.429641 | N3: 79.563973 | O3: 70.149747 | P3: 61.253028 | Q3: 53.116054 | R3: 45.617705
G4: =G3/F3 -> 0.88968234 | H4: =H3/G3 -> 0.88167728
F6: 2025
F7: 8598
F9: 1 | G9: =F9-G4 -> 0.11031766 | H9: =G9/5 -> 0.022063531
F10: 1 | G10: =F10-H4 -> 0.11832272 | H10: =G10/5 -> 0.023664545
F11: 令和7 （2025） | G11: 令和8 （2026） | H11: 令和9 （2027） | I11: 令和10 （2028） | J11: 令和11 （2029） | K11: 令和12 （2030） | L11: 令和13 （2031） | M11: 令和14 （2032） | N11: 令和15 （2033） | O11: 令和16 （2034） | P11: 令和17 （2035）
E12: 総人口(人） | F12: 3846 | G12: 3835 | H12: 3825 | I12: 3814 | J12: 3803 | K12: 3771 | L12: 3757 | M12: 3742 | N12: 3728 | O12: 3713 | P12: 3670
E13: 処理区域人口(人） | F13: 2727 | G13: 2719 | H13: 2712 | I13: 2704 | J13: 2696 | K13: 2674 | L13: 2664 | M13: 2653 | N13: 2643 | O13: 2633 | P13: 2602
E14: 水洗化人口(人） | F14: =ROUND(F13*98.5%,0) -> 2686 | G14: =ROUND(G13*98.5%,0) -> 2678 | H14: =ROUND(H13*98.5%,0) -> 2671 | I14: =ROUND(I13*98.5%,0) -> 2663 | J14: =ROUND(J13*98.5%,0) -> 2656 | K14: =ROUND(K13*98.5%,0) -> 2634 | L14: =ROUND(L13*98.5%,0) -> 2624 | M14: =ROUND(M13*98.5%,0) -> 2613 | ... P14: =ROUND(P13*98.5%,0) -> 2563
F18: 令和7 （2025） | G18: 令和8 （2026） | H18: 令和9 （2027） | I18: 令和10 （2028） | J18: 令和11 （2029） | K18: 令和12 （2030） | L18: 令和13 （2031） | M18: 令和14 （2032） | N18: 令和15 （2033） | O18: 令和16 （2034） | P18: 令和17 （2035）
E19: 一般家庭等 | F19: =ROUND(F14*91.1,0) -> 244695 | G19: =ROUND(G14*91.1,0) -> 243966 | H19: =ROUND(H14*91.1,0) -> 243328 | I19: =ROUND(I14*91.1,0) -> 242599 | J19: =ROUND(J14*91.1,0) -> 241962 | K19: =ROUND(K14*91.1,0) -> 239957 | L19: =ROUND(L14*91.1,0) -> 239046 | M19: =ROUND(M14*91.1,0) -> 238044 | ... P19: =ROUND(P14*91.1,0) -> 233489
E20: 工場排水 | F20: 117600 | G20: 117600 | H20: 117600 | I20: 117600 | J20: 117600 | K20: 117600 | L20: 117600 | M20: 117600 | N20: 117600 | O20: 117600 | P20: 117600
E21: 有収水量（㎥） | F21: =SUM(F19:F20) -> 362295 | G21: =SUM(G19:G20) -> 361566 | H21: =SUM(H19:H20) -> 360928 | I21: =SUM(I19:I20) -> 360199 | J21: =SUM(J19:J20) -> 359562 | K21: =SUM(K19:K20) -> 357557 | L21: =SUM(L19:L20) -> 356646 | M21: =SUM(M19:M20) -> 355644 | ... P21: =SUM(P19:P20) -> 351089
F22: 令和7 （2025） | G22: 令和8 （2026） | H22: 令和9 （2027） | I22: 令和10 （2028） | J22: 令和11 （2029） | K22: 令和12 （2030） | L22: 令和13 （2031） | M22: 令和14 （2032） | N22: 令和15 （2033） | O22: 令和16 （2034） | P22: 令和17 （2035）
E23: 一般家庭等 | F23: =ROUND(F19*170.5/1000,0) -> 41720 | G23: =ROUND(G19*170.5/1000,0) -> 41596 | H23: =ROUND(H19*170.5/1000,0) -> 41487 | I23: =ROUND(I19*170.5/1000,0) -> 41363 | J23: =ROUND(J19*170.5/1000,0) -> 41255 | K23: =ROUND(K19*170.5/1000,0) -> 40913 | L23: =ROUND(L19*170.5/1000,0) -> 40757 | M23: =ROUND(M19*170.5/1000,0) -> 40587 | ... P23: =ROUND(P19*170.5/1000,0) -> 39810
E24: 工場利用 | F24: =ROUND(F20*170.5/1000,0) -> 20051 | G24: =ROUND(G20*170.5/1000,0) -> 20051 | H24: =ROUND(H20*170.5/1000,0) -> 20051 | I24: =ROUND(I20*170.5/1000,0) -> 20051 | J24: =ROUND(J20*170.5/1000,0) -> 20051 | K24: =ROUND(K20*170.5/1000,0) -> 20051 | L24: =ROUND(L20*170.5/1000,0) -> 20051 | M24: =ROUND(M20*170.5/1000,0) -> 20051 | ... P24: =ROUND(P20*170.5/1000,0) -> 20051
E25: 料金収入 | F25: =SUM(F23:F24) -> 61771 | G25: =SUM(G23:G24) -> 61647 | H25: =SUM(H23:H24) -> 61538 | I25: =SUM(I23:I24) -> 61414 | J25: =SUM(J23:J24) -> 61306 | K25: =SUM(K23:K24) -> 60964 | L25: =SUM(L23:L24) -> 60808 | M25: =SUM(M23:M24) -> 60638 | ... P25: =SUM(P23:P24) -> 59861
F29: 令和7 （2025） | G29: 令和8 （2026） | H29: 令和9 （2027） | I29: 令和10 （2028） | J29: 令和11 （2029） | K29: 令和12 （2030） | L29: 令和13 （2031） | M29: 令和14 （2032） | N29: 令和15 （2033） | O29: 令和16 （2034） | P29: 令和17 （2035）
E30: 総人口(人） | F30: =F12 -> 3846 | G30: =G12 -> 3835 | H30: =H12 -> 3825 | I30: =I12 -> 3814 | J30: =J12 -> 3803 | K30: =K12 -> 3771 | L30: =L12 -> 3757 | M30: =M12 -> 3742 | ... O30: =O12 -> 3713
E31: 給水人口（人） | F31: 3803 | G31: 3798 | H31: 3794 | I31: 3790 | J31: 3786 | K31: 3783 | L31: 3779 | M31: 3776 | N31: 3773 | O31: 3771
F35: 令和7 （2025） | G35: 令和8 （2026） | H35: 令和9 （2027） | I35: 令和10 （2028） | J35: 令和11 （2029） | K35: 令和12 （2030） | L35: 令和13 （2031） | M35: 令和14 （2032） | N35: 令和15 （2033） | O35: 令和16 （2034） | P35: 令和17 （2035）
E36: 有収水量（㎥） | F36: =F45*1000 -> 741320 | G36: =G45*1000 -> 740950 | H36: =H45*1000 -> 742610 | I36: =I45*1000 -> 740590 | J36: =J45*1000 -> 740220 | K36: =K45*1000 -> 740220 | L36: =L45*1000 -> 741880 | M36: =M45*1000 -> 739490 | ... O36: =O45*1000 -> 739490
G37: =F36-G36 -> 370 | H37: =G36-H36 -> -1660 | I37: =H36-I36 -> 2020 | J37: =I36-J36 -> 370 | K37: =J36-K36 -> 0 | L37: =K36-L36 -> -1660 | M37: =L36-M36 -> 2390 | N37: =M36-N36 -> 0 | O37: =N36-O36 -> 0
F40: 令和7 （2025） | G40: 令和8 （2026） | H40: 令和9 （2027） | I40: 令和10 （2028） | J40: 令和11 （2029） | K40: 令和12 （2030） | L40: 令和13 （2031） | M40: 令和14 （2032） | N40: 令和15 （2033） | O40: 令和16 （2034） | P40: 令和17 （2035）
E41: 料金収入（千円） | F41: 83606 | G41: 83564 | H41: 83752 | I41: 83524 | J41: 83482 | K41: 83482 | L41: 83669 | M41: 83400 | N41: 83400 | O41: 83400
F45: 741.32 | G45: 740.95 | H45: 742.61 | I45: 740.59 | J45: 740.22 | K45: 740.22 | L45: 741.88 | M45: 739.49 | N45: 739.49 | O45: 739.49

Sheet 下水過去
B2: 平成26年度 (2014) | C2: 平成27年度 (2015) | D2: 平成28年度 (2016) | E2: 平成29年度 (2017) | F2: 平成30年度 (2018) | G2: 令和元年度 （2019） | H2: 令和2年度 （2020） | I2: 令和3年度 （2021） | J2: 令和4年度 （2022） | K2: 令和5年度 （2023） | L2: 令和6年度 （2024） | M2: R7 | N2: R8 | O2: R9 | P2: R10 | Q2: R11 | R2: R12 | S2: R13 | T2: R14 | U2: R15 | V2: R16 | W2: R17 | X2: R18 | Y2: R19
A3: 行政区域内人口 | B3: 11023 | C3: 10763 | D3: 10517 | E3: 10236 | F3: 10027 | G3: 9814 | H3: 9596 | I3: 9353 | J3: 9114 | K3: 8954 | L3: 8699
A4: 処理区域内人口 | B4: 2487 | C4: 2540 | D4: 2601 | E4: 2573 | F4: 2619 | G4: 2581 | H4: 2557 | I4: 2512 | J4: 2453 | K4: 2428 | L4: 2375
A5: 水洗便所設置人口（水洗化人口） | B5: 908 | C5: 949 | D5: 1010 | E5: 1046 | F5: 1128 | G5: 1180 | H5: 1196 | I5: 1201 | J5: 1230 | K5: 1218 | L5: 1236
A6: 年間総処理水量 | B6: 92397 | C6: 92397 | D6: 115147 | E6: 126057 | F6: 123822 | G6: 132480 | H6: 141455 | I6: 139716 | J6: 133569 | K6: 136601 | L6: 143484
A7: 有収水量 | B7: 92397 | C7: 92397 | D7: 109901 | E7: 116363 | F7: 121416 | G7: 129752 | H7: 134144 | I7: 140013 | J7: 131918 | K7: 137673 | L7: 141103
A8: 使用料収入 | B8: 16335000 | C8: 18571000 | D8: 19404000 | E8: 20438000 | F8: 21301000 | G8: 23039000 | H8: 24134000 | I8: 25187000 | J8: 23963000 | K8: 24015000 | L8: 23660000
A9: 有収水量 | B9: 92397 | C9: 92397 | D9: 109901 | E9: 116363 | F9: 121416 | G9: 129752 | H9: 134144 | I9: 140013 | J9: 131918 | K9: 137673 | L9: 141103
A10: 汚水処理費 | B10: 105578000 | C10: 114501000 | D10: 123604000 | E10: 98219000 | F10: 84617000 | G10: 94520000 | H10: 92010000 | I10: 91414000 | J10: 103443000 | K10: 98181000 | L10: 64460000
G12: =G4/G3 -> 0.26299164 | H12: =H4/H3 -> 0.26646519 | I12: =I4/I3 -> 0.26857693 | J12: =J4/J3 -> 0.26914637 | K12: =K4/K3 -> 0.27116373 | L12: =L4/L3 -> 0.27301989 | M12: =L12+$L$14 -> 0.27450087 | N12: =M12+$L$14 -> 0.27598186 | O12: =N12+$L$14 -> 0.27746285 | P12: =O12+$L$14 -> 0.27894383 | Q12: =P12+$L$14 -> 0.28042482 | R12: =Q12+$L$14 -> 0.28190581 | S12: =R12+$L$14 -> 0.28338679 | T12: =S12+$L$14 -> 0.28486778 | ... Z12: =Y12+$L$14 -> 0.2937537
H13: =H5/H4 -> 0.46773563 | I13: =I12-H12 -> 0.0021117334 | J13: =J12-I12 -> 0.00056944104 | K13: =K12-J12 -> 0.0020173575 | L13: =L12-K12 -> 0.0018561616
L14: =AVERAGE(J13:L13) -> 0.0014809867
G16: =G5/G4 -> 0.45718714 | H16: =H5/H4 -> 0.46773563 | I16: =I5/I4 -> 0.4781051 | J16: =J5/J4 -> 0.50142682 | K16: =K5/K4 -> 0.50164745 | L16: =L5/L4 -> 0.52042105 | M16: =L16+$L$18 -> 0.53452637 | N16: =M16+$L$18 -> 0.54863169 | O16: =N16+$L$18 -> 0.56273701 | P16: =O16+$L$18 -> 0.57684233 | Q16: =P16+$L$18 -> 0.59094765 | R16: =Q16+$L$18 -> 0.60505297 | S16: =R16+$L$18 -> 0.61915829 | T16: =S16+$L$18 -> 0.6332636 | ... Y16: =X16+$L$18 -> 0.7037902
H17: =H9/H8 -> 0.0055582995 | I17: =I16-H16 -> 0.010369468 | J17: =J16-I16 -> 0.023321729 | K17: =K16-J16 -> 0.00022062216 | L17: =L16-K16 -> 0.018773606
L18: =AVERAGE(J17:L17) -> 0.014105319
G20: =G7/G5 -> 109.95932 | H20: =H7/H5 -> 112.16054 | I20: =I7/I5 -> 116.58035 | J20: =J7/J5 -> 107.25041 | K20: =K7/K5 -> 113.03202 | L20: =L7/L5 -> 114.161
L21: =AVERAGE(K20:L20) -> 113.59651
L23: =L8/L7 -> 167.67893

Sheet 簡水過去
B1: 平成26年度 (2014) | C1: 平成27年度 (2015) | D1: 平成28年度 (2016) | E1: 平成29年度 (2017) | F1: 平成30年度 (2018) | G1: 令和元年度 （2019） | H1: 令和2年度 （2020） | I1: 令和3年度 （2021） | J1: 令和4年度 （2022） | K1: 令和5年度 （2023） | L1: 令和6年度 （2024）
A2: 行政区域内人口 | B2: 11023 | C2: 10763 | D2: 10517 | E2: 10235 | F2: 10027 | G2: 9814 | H2: 9596 | I2: 9353 | J2: 9114 | K2: 8954 | L2: 8699
A3: 給水人口(人） | B3: 1214 | C3: 1111 | D3: 1101 | E3: 1068 | F3: 1064 | G3: 983 | H3: 1018 | I3: 954 | J3: 959 | K3: 954 | L3: 867
A4: 給水戸数(戸） | G4: 386 | H4: 388 | I4: 384 | J4: 384 | K4: 382 | L4: 380
A5: 年間総配水量 | B5: 101297 | C5: 81334 | D5: 73493 | E5: 76114 | F5: 71592 | G5: 76669 | H5: 74134 | I5: 76664 | J5: 83492 | K5: 66584 | L5: 52420
A6: 有収水量（㎥） | B6: 61696 | C6: 63548 | D6: 57682 | E6: 56577 | F6: 56676 | G6: 58604 | H6: 56491 | I6: 56936 | J6: 54363 | K6: 54695 | L6: 51540
A7: 料金収入 | B7: 13986000 | C7: 14450000 | D7: 13728000 | E7: 13054000 | F7: 13668000 | G7: 14030000 | H7: 14568000 | I7: 13861000 | J7: 13202000 | K7: 12705000 | L7: 11841000
B8: =B3/B2 -> 0.11013336 | C8: =C3/C2 -> 0.10322401 | D8: =D3/D2 -> 0.10468765 | E8: =E3/E2 -> 0.10434783 | F8: =F3/F2 -> 0.10611349 | G8: =G3/G2 -> 0.10016303 | H8: =H3/H2 -> 0.10608587 | I8: =I3/I2 -> 0.10199936 | ... L8: =L3/L2 -> 0.099666628
C12: =B3-C3 -> 103 | D12: =C3-D3 -> 10 | E12: =D3-E3 -> 33 | F12: =E3-F3 -> 4 | G12: =F3-G3 -> 81 | H12: =G3-H3 -> -35 | I12: =H3-I3 -> 64 | J12: =I3-J3 -> -5 | ... L12: =K3-L3 -> 87
C14: =C6*1000/C3 -> 57198.92 | D14: =D6*1000/D3 -> 52390.554 | E14: =E6*1000/E3 -> 52974.719 | F14: =F6*1000/F3 -> 53266.917 | G14: =G6*1000/G3 -> 59617.497 | H14: =H6*1000/H3 -> 55492.141 | I14: =I6*1000/I3 -> 59681.342 | J14: =J6*1000/J3 -> 56687.174 | ... L14: =L6*1000/L3 -> 59446.367 | N14: 51.54 | O14: =N14*1000 -> 51540
L15: =AVERAGE(J14:L14) -> 57821.942
L17: =L7/L6 -> 229.74389

Sheet 【下水道】建設改良費の年度別事業費 (2)
N2: （単位：千円）
E3: 計画年次❶ | F3: ❷ | G3: ❸ | H3: ❹ | I3: ❺ | J3: ❻ | K3: ❼ | L3: ❽ | M3: ❾ | N3: ➓
A4: 内容 年度 | C4: 2023 (令和5) | D4: 2024 (令和6) | E4: 令和7 (2025) | F4: 令和8 (2026) | G4: 令和9 (2027) | H4: 令和10 (2028) | I4: 令和11 (2029) | J4: 令和12 (2030) | K4: 令和13 (2031) | L4: 令和14 (2032) | M4: 令和15 (2033) | N4: 令和16 (2034) | O4: 令和17 (2035) | S4: 令和8 (2026) | T4: 令和9 (2027) | U4: 令和10 (2028) | V4: 令和11 (2029) | W4: 令和12 (2030) | X4: 令和13 (2031) | Y4: 令和14 (2032) | Z4: 令和15 (2033) | AA4: 令和16 (2034) | AB4: 令和17 (2035)
A5: ❶管渠更新 | R5: 事業計画 | T5: 10000
A6: 金額 | E6: 12500 | F6: 0 | G6: 0 | H6: 0 | I6: 11000 | J6: 0 | K6: 0 | L6: 0 | M6: 0 | N6: 11000 | R6: ストマネ計画策て | T6: 16000
A7: ❷マンホールポンプ更新 | R7: 事業計画 | T7: 10000
C8: 18000 | D8: 18000 | R8: ストマネ計画策て | T8: 16000
A9: ❸管路施設・設備長寿命化
A10: 金額
A11: ❷処理場設備等更新
A12: 金額 | C12: 18000 | D12: 18000 | E12: 80600 | F12: 146000 | G12: 749000 | H12: 50000 | I12: 88426 | J12: 50000 | K12: 50000 | L12: 50000 | M12: 50000 | N12: 58426
A13: 内容 年度 | C13: 2023 (令和5) | D13: 2024 (令和6) | E13: 令和7 (2025) | F13: 令和8 (2026) | G13: 令和9 (2027) | H13: 令和10 (2028) | I13: 令和11 (2029) | J13: 令和12 (2030) | K13: 令和13 (2031) | L13: 令和14 (2032) | M13: 令和15 (2033) | N13: 令和16 (2034)
A14: 事業費合計 | C14: =#REF!+#REF!+C12+#REF!+#REF!+#REF!+#REF!+C10+#REF!+C8+C6 -> #REF! | D14: =#REF!+#REF!+D12+#REF!+#REF!+#REF!+#REF!+D10+#REF!+D8+D6 -> #REF! | E14: =E6+E8+E10+E12 -> 93100 | F14: =F6+F8+F10+F12 -> 146000 | G14: =G6+G8+G10+G12 -> 749000 | H14: =H6+H8+H10+H12 -> 50000 | I14: =I6+I8+I10+I12 -> 99426 | J14: =J6+J8+J10+J12 -> 50000 | K14: =K6+K8+K10+K12 -> 50000 | L14: =L6+L8+L10+L12 -> 50000 | ... N14: =N6+N8+N10+N12 -> 69426
A15: 財源内訳
A16: ①国庫補助金
A17: 金額 | E17: =ROUND((E14-E6)*50%,0) -> 40300 | F17: =ROUND((F14-F6)*50%,0) -> 73000 | G17: =ROUND((G14-G6)*50%,0) -> 374500 | H17: =ROUND((H14-H6)*50%,0) -> 25000 | I17: =ROUND((I14-I6)*50%,0) -> 44213 | J17: =ROUND((J14-J6)*50%,0) -> 25000 | K17: =ROUND((K14-K6)*50%,0) -> 25000 | L17: =ROUND((L14-L6)*50%,0) -> 25000 | ... N17: =ROUND((N14-N6)*50%,0) -> 29213
A18: ②受益者負担金
A19: 金額
A20: ②企業債
A21: 金額 | E21: 46550 | F21: 73000 | G21: 374500 | H21: 25000 | I21: 49713 | J21: 25000 | K21: 25000 | L21: 25000 | M21: 25000 | N21: 34713
A22: ③自己財源
A23: 金額 | E23: =E14-E17-E19-E21 -> 6250 | F23: =F14-F17-F19-F21 -> 0 | G23: =G14-G17-G19-G21 -> 0 | H23: =H14-H17-H19-H21 -> 0 | I23: =I14-I17-I19-I21 -> 5500 | J23: =J14-J17-J19-J21 -> 0 | K23: =K14-K17-K19-K21 -> 0 | L23: =L14-L17-L19-L21 -> 0 | ... N23: =N14-N17-N19-N21 -> 5500
A25: 差額 | E25: =E14-E17-E19-E21-E23 -> 0 | F25: =F14-F17-F19-F21-F23 -> 0 | G25: =G14-G17-G19-G21-G23 -> 0 | H25: =H14-H17-H19-H21-H23 -> 0 | I25: =I14-I17-I19-I21-I23 -> 0 | J25: =J14-J17-J19-J21-J23 -> 0 | K25: =K14-K17-K19-K21-K23 -> 0 | L25: =L14-L17-L19-L21-L23 -> 0 | ... N25: =N14-N17-N19-N21-N23 -> 0
A26: [注]
C29: =SUM(C17:C23) -> 0 | D29: =SUM(D17:D23) -> 0 | E29: =SUM(E17:E23) -> 93100 | F29: =SUM(F17:F23) -> 146000 | G29: =SUM(G17:G23) -> 749000 | H29: =SUM(H17:H23) -> 50000 | I29: =SUM(I17:I23) -> 99426 | J29: =SUM(J17:J23) -> 50000 | ... N29: =SUM(N17:N23) -> 69426
C31: =C14-C29 -> #REF! | D31: =D14-D29 -> #REF! | E31: =E14-E29 -> 0 | F31: =F14-F29 -> 0 | G31: =G14-G29 -> 0 | H31: =H14-H29 -> 0 | I31: =I14-I29 -> 0 | J31: =J14-J29 -> 0 | ... N31: =N14-N29 -> 0
C33: =SUM(C17,C19,C23) -> 0 | D33: =SUM(D17,D19,D23) -> 0 | E33: =SUM(E17,E19,E23) -> 46550 | F33: =SUM(F17,F19,F23) -> 73000 | G33: =SUM(G17,G19,G23) -> 374500 | H33: =SUM(H17,H19,H23) -> 25000 | I33: =SUM(I17,I19,I23) -> 49713 | J33: =SUM(J17,J19,J23) -> 25000 | ... N33: =SUM(N17,N19,N23) -> 34713
E37: =#REF!+#REF! -> #REF! | F37: =#REF!+#REF! -> #REF! | G37: =#REF!+#REF! -> #REF! | H37: =#REF!+#REF! -> #REF! | I37: =#REF!+#REF! -> #REF! | J37: =#REF!+#REF! -> #REF! | K37: =#REF!+#REF! -> #REF! | L37: =#REF!+#REF! -> #REF! | ... N37: =#REF!+#REF! -> #REF!
E38: =E14-E37 -> #REF! | F38: =F14-F37 -> #REF! | G38: =G14-G37 -> #REF! | H38: =H14-H37 -> #REF! | I38: =I14-I37 -> #REF! | J38: =J14-J37 -> #REF! | K38: =K14-K37 -> #REF! | L38: =L14-L37 -> #REF! | ... N38: =N14-N37 -> #REF!
F39: 200 | G39: 0.4 | H39: =F39/G39 -> 500
G40: 0.6 | H40: =F39/G40 -> 333.33333
E42: 投資３億円で調整
E46: =ROUND((E6+E8+E10+#REF!+#REF!)*45%,0) -> #REF! | F46: =ROUND((F6+F8+F10+#REF!+#REF!)*45%,0) -> #REF! | G46: =ROUND((G6+G8+G10+#REF!+#REF!)*45%,0) -> #REF! | H46: =ROUND((H6+H8+H10+#REF!+#REF!)*45%,0) -> #REF! | I46: =ROUND((I6+I8+I10+#REF!+#REF!)*45%,0) -> #REF! | J46: =ROUND((J6+J8+J10+#REF!+#REF!)*45%,0) -> #REF! | K46: =ROUND((K6+K8+K10+#REF!+#REF!)*45%,0) -> #REF! | L46: =ROUND((L6+L8+L10+#REF!+#REF!)*45%,0) -> #REF! | ... N46: =ROUND((N6+N8+N10+#REF!+#REF!)*45%,0) -> #REF!

Sheet 下水道現況予測
A1: 3事業合算 | P1: 令和7年度 | Q1: 令和8年度 | R1: 令和9年度 | S1: 令和10年度 | T1: 令和11年度 | U1: 令和12年度 | V1: 令和13年度 | W1: 令和14年度 | X1: 令和15年度 | Y1: 令和16年度 | Z1: 令和17年度 | AA1: 令和18年度 | AB1: 令和19年度 | AC1: 令和20年度 | AD1: 令和21年度 | AE1: 令和22年度 | AF1: 令和23年度 | AG1: 令和24年度 | AH1: 令和25年度 | AI1: 令和26年度 | AJ1: 令和27年度 | AK1: 令和28年度 | AL1: 令和29年度 | AM1: 令和30年度 | AN1: 令和31年度 | AO1: 令和32年度 | AP1: 令和33年度 | AQ1: 令和34年度 | AR1: 令和35年度
P2: 2025 | Q2: 2026 | R2: 2027 | S2: 2028 | T2: 2029 | U2: 2030 | V2: 2031 | W2: 2032 | X2: 2033 | Y2: 2034 | Z2: 2035 | AA2: 2036 | AB2: 2037 | AC2: 2038 | AD2: 2039 | AE2: 2040 | AF2: 2041 | AG2: 2042 | AH2: 2043 | AI2: 2044 | AJ2: 2045 | AK2: 2046 | AL2: 2047 | AM2: 2048 | AN2: 2049 | AO2: 2050 | AP2: 2051 | AQ2: 2052 | AR2: 2053 | AS2: 2055
D3: 普及率 | J3: 10(000)_行政区域内人口 | AT3: =[12]公共下水道事業!AY3 -> 75263
D4: 水洗化率 | J4: 10(000)_処理区域内人口
D5: 有収水量 | J5: 10(000)_水洗化人口
J6: 10(000)_現在処理区域面積
J7: 10(000)_年間総処理水量
J8: 10(000)_年間有収水量
J10: 人口一人当たりの有収水量
J11: 人口一人当たりの使用料（使用料収入÷水洗化人口）
J12: 20㎥あたりの使用料（使用料収入÷年間有収水量×20）
J13: 普及率 | P13: =P5/P3 -> #DIV/0! | Q13: =Q5/Q3 -> #DIV/0! | R13: =R5/R3 -> #DIV/0! | S13: =S5/S3 -> #DIV/0! | T13: =T5/T3 -> #DIV/0! | U13: =U5/U3 -> #DIV/0! | V13: =V5/V3 -> #DIV/0! | W13: =W5/W3 -> #DIV/0! | ... AR13: =AR5/AR3 -> #DIV/0!
J14: 水洗化率 | P14: =AVERAGE($K$14:$M$14) -> #DIV/0! | Q14: =AVERAGE($K$14:$M$14) -> #DIV/0! | R14: =AVERAGE($K$14:$M$14) -> #DIV/0! | S14: =AVERAGE($K$14:$M$14) -> #DIV/0! | T14: =AVERAGE($K$14:$M$14) -> #DIV/0! | U14: =AVERAGE($K$14:$M$14) -> #DIV/0! | V14: =AVERAGE($K$14:$M$14) -> #DIV/0! | W14: =AVERAGE($K$14:$M$14) -> #DIV/0! | ... AR14: =AVERAGE($K$14:$M$14) -> #DIV/0!
J16: 汚水処理費（A） | P16: =ROUND(P53*$AT$21,0) -> 109223 | Q16: =ROUND(Q53*$AT$21,0) -> 109886 | R16: =ROUND(R53*$AT$21,0) -> 111329 | S16: =ROUND(S53*$AT$21,0)-15000 -> 117988 | T16: =ROUND(T53*$AT$21,0)-16000 -> 117748 | U16: =ROUND(U53*$AT$21,0)-17000 -> 118784 | V16: =ROUND(V53*$AT$21,0)-18000 -> 119166 | W16: =ROUND(W53*$AT$21,0)-19000 -> 119595 | X16: =ROUND(X53*$AT$21,0)-20000 -> 119785 | Y16: =ROUND(Y53*$AT$21,0)-21000 -> 118804 | Z16: =[12]公共下水道事業!AE16+#REF!+[12]農業集落排水事業!AE16 -> #REF! | AA16: =[12]公共下水道事業!AF16+#REF!+[12]農業集落排水事業!AF16 -> #REF! | AB16: =[12]公共下水道事業!AG16+#REF!+[12]農業集落排水事業!AG16 -> #REF! | AC16: =[12]公共下水道事業!AH16+#REF!+[12]農業集落排水事業!AH16 -> #REF! | AD16: =[12]公共下水道事業!AI16+#REF!+[12]農業集落排水事業!AI16 -> #REF! | AE16: =[12]公共下水道事業!AJ16+#REF!+[12]農業集落排水事業!AJ16 -> #REF! | AF16: =[12]公共下水道事業!AK16+#REF!+[12]農業集落排水事業!AK16 -> #REF! | AG16: =[12]公共下水道事業!AL16+#REF!+[12]農業集落排水事業!AL16 -> #REF! | ... AR16: =[12]公共下水道事業!AW16+#REF!+[12]農業集落排水事業!AW16 -> #REF!
J17: 使用料収入（B） | P17: =P28 -> 61771 | Q17: =Q28 -> 61647 | R17: =R28 -> 61538 | S17: =S28 -> 61414 | T17: =T28 -> 61306 | U17: =U28 -> 60964 | V17: =V28 -> 60808 | W17: =W28 -> 60638 | ... Y17: =Y28 -> 60342 | Z17: =[12]公共下水道事業!AE19+#REF!+[12]農業集落排水事業!AE19 -> #REF! | AA17: =[12]公共下水道事業!AF19+#REF!+[12]農業集落排水事業!AF19 -> #REF! | AB17: =[12]公共下水道事業!AG19+#REF!+[12]農業集落排水事業!AG19 -> #REF! | AC17: =[12]公共下水道事業!AH19+#REF!+[12]農業集落排水事業!AH19 -> #REF! | AD17: =[12]公共下水道事業!AI19+#REF!+[12]農業集落排水事業!AI19 -> #REF! | AE17: =[12]公共下水道事業!AJ19+#REF!+[12]農業集落排水事業!AJ19 -> #REF! | AF17: =[12]公共下水道事業!AK19+#REF!+[12]農業集落排水事業!AK19 -> #REF! | AG17: =[12]公共下水道事業!AL19+#REF!+[12]農業集落排水事業!AL19 -> #REF! | ... AR17: =[12]公共下水道事業!AW19+#REF!+[12]農業集落排水事業!AW19 -> #REF!
J18: 経費回収率（B÷A） | P18: =P17/P16 -> 0.56554938 | Q18: =Q17/Q16 -> 0.56100868 | R18: =R17/R16 -> 0.55275804 | S18: =S17/S16 -> 0.52051056 | T18: =T17/T16 -> 0.52065428 | U18: =U17/U16 -> 0.51323411 | V18: =V17/V16 -> 0.51027978 | W18: =W17/W16 -> 0.50702789 | ... AR18: =AR17/AR16 -> #REF!
J19: 有収水量（C） | P19: =予測!F21 -> 362295 | Q19: =予測!G21 -> 361566 | R19: =予測!H21 -> 360928 | S19: =予測!I21 -> 360199 | T19: =予測!J21 -> 359562 | U19: =予測!K21 -> 357557 | V19: =予測!L21 -> 356646 | W19: =予測!M21 -> 355644 | ... Y19: =予測!O21 -> 353913 | Z19: =Z8 -> 0 | AA19: =AA8 -> 0 | AB19: =AB8 -> 0 | AC19: =AC8 -> 0 | AD19: =AD8 -> 0 | AE19: =AE8 -> 0 | AF19: =AF8 -> 0 | AG19: =AG8 -> 0 | ... AR19: =AR8 -> 0 | AT19: 109686
J20: 汚水処理原価（A÷C） | P20: =P16/P19*1000 -> 301.47532 | Q20: =Q16/Q19*1000 -> 303.91685 | R20: =R16/R19*1000 -> 308.4521 | S20: =S16/S19*1000 -> 327.56337 | T20: =T16/T19*1000 -> 327.47621 | U20: =U16/U19*1000 -> 332.20997 | V20: =V16/V19*1000 -> 334.12964 | W20: =W16/W19*1000 -> 336.27729 | ... AR20: =AR16/AR19*1000 -> #REF! | AT20: 175739
J21: 経常収支比率 | P21: =P37/P53 -> 1.0950931 | Q21: =Q37/Q53 -> 1.0762415 | R21: =R37/R53 -> 1.0577672 | S21: =S37/S53 -> 1.0340306 | T21: =T37/T53 -> 1.0200102 | U21: =U37/U53 -> 1.0053412 | V21: =V37/V53 -> 0.99220542 | W21: =W37/W53 -> 0.97954579 | ... AR21: =AR37/AR53 -> #REF! | AT21: =AT19/AT20 -> 0.62414148
P23: =P49-P35+P51 -> 47112 | Q23: =Q49-Q35+Q51 -> 44631 | R23: =R49-R35+R51 -> 41592 | S23: =S49-S35+S51 -> 60280 | T23: =T49-T35+T51 -> 58152 | U23: =U49-U35+U51 -> 59445 | V23: =V49-V35+V51 -> 60068 | W23: =W49-W35+W51 -> 60745 | ... Y23: =Y49-Y35+Y51 -> 60864
J24: 3条
I25: 年 度 | P25: 令和7年度 | Q25: 令和8年度 | R25: 令和9年度 | S25: 令和10年度 | T25: 令和11年度 | U25: 令和12年度 | V25: 令和13年度 | W25: 令和14年度 | X25: 令和15年度 | Y25: 令和16年度 | Z25: 令和17年度 | AA25: 令和18年度 | AB25: 令和19年度 | AC25: 令和20年度 | AD25: 令和21年度 | AE25: 令和22年度 | AF25: 令和23年度 | AG25: 令和24年度 | AH25: 令和25年度 | AI25: 令和26年度 | AJ25: 令和27年度 | AK25: 令和28年度 | AL25: 令和29年度 | AM25: 令和30年度 | AN25: 令和31年度 | AO25: 令和32年度 | AP25: 令和33年度 | AQ25: 令和34年度 | AR25: 令和35年度
C26: 区 分 | P26: 2025 | Q26: 2026 | R26: 2027 | S26: 2028 | T26: 2029 | U26: 2030 | V26: 2031 | W26: 2032 | X26: 2033 | Y26: 2034 | Z26: 2035 | AA26: 2036 | AB26: 2037 | AC26: 2038 | AD26: 2039 | AE26: 2040 | AF26: 2041 | AG26: 2042 | AH26: 2043 | AI26: 2044 | AJ26: 2045 | AK26: 2046 | AL26: 2047 | AM26: 2048 | AN26: 2049 | AO26: 2050 | AP26: 2051 | AQ26: 2052 | AR26: 2053
B27: 収益的収支 | C27: 収益的収入 | D27: １． | E27: 営業収益 | J27: (A) | P27: =SUM(P28:P30) -> 61841 | Q27: =SUM(Q28:Q30) -> 61717 | R27: =SUM(R28:R30) -> 61608 | S27: =SUM(S28:S30) -> 61484 | T27: =SUM(T28:T30) -> 61376 | U27: =SUM(U28:U30) -> 61034 | V27: =SUM(V28:V30) -> 60878 | W27: =SUM(W28:W30) -> 60708 | ... AR27: =SUM(AR28:AR30) -> #REF!
D28: (1) | F28: 使用料収入 | P28: =予測!F25 -> 61771 | Q28: =予測!G25 -> 61647 | R28: =予測!H25 -> 61538 | S28: =予測!I25 -> 61414 | T28: =予測!J25 -> 61306 | U28: =予測!K25 -> 60964 | V28: =予測!L25 -> 60808 | W28: =予測!M25 -> 60638 | ... Y28: =予測!O25 -> 60342 | Z28: =[12]公共下水道事業!AE30+#REF!+[12]農業集落排水事業!AE30 -> #REF! | AA28: =[12]公共下水道事業!AF30+#REF!+[12]農業集落排水事業!AF30 -> #REF! | AB28: =[12]公共下水道事業!AG30+#REF!+[12]農業集落排水事業!AG30 -> #REF! | AC28: =[12]公共下水道事業!AH30+#REF!+[12]農業集落排水事業!AH30 -> #REF! | AD28: =[12]公共下水道事業!AI30+#REF!+[12]農業集落排水事業!AI30 -> #REF! | AE28: =[12]公共下水道事業!AJ30+#REF!+[12]農業集落排水事業!AJ30 -> #REF! | AF28: =[12]公共下水道事業!AK30+#REF!+[12]農業集落排水事業!AK30 -> #REF! | AG28: =[12]公共下水道事業!AL30+#REF!+[12]農業集落排水事業!AL30 -> #REF! | ... AR28: =[12]公共下水道事業!AW30+#REF!+[12]農業集落排水事業!AW30 -> #REF!
D29: (2) | F29: 雨水処理負担金 | P29: 0 | Q29: 0 | R29: 0 | S29: 0 | T29: 0 | U29: 0 | V29: 0 | W29: 0 | X29: 0 | Y29: 0 | Z29: =[12]公共下水道事業!AE31+#REF!+[12]農業集落排水事業!AE31 -> #REF! | AA29: =[12]公共下水道事業!AF31+#REF!+[12]農業集落排水事業!AF31 -> #REF! | AB29: =[12]公共下水道事業!AG31+#REF!+[12]農業集落排水事業!AG31 -> #REF! | AC29: =[12]公共下水道事業!AH31+#REF!+[12]農業集落排水事業!AH31 -> #REF! | AD29: =[12]公共下水道事業!AI31+#REF!+[12]農業集落排水事業!AI31 -> #REF! | AE29: =[12]公共下水道事業!AJ31+#REF!+[12]農業集落排水事業!AJ31 -> #REF! | AF29: =[12]公共下水道事業!AK31+#REF!+[12]農業集落排水事業!AK31 -> #REF! | AG29: =[12]公共下水道事業!AL31+#REF!+[12]農業集落排水事業!AL31 -> #REF! | ... AR29: =[12]公共下水道事業!AW31+#REF!+[12]農業集落排水事業!AW31 -> #REF!
D30: (3) | F30: その他 | P30: 70 | Q30: =P30 -> 70 | R30: =Q30 -> 70 | S30: =R30 -> 70 | T30: =S30 -> 70 | U30: =T30 -> 70 | V30: =U30 -> 70 | W30: =V30 -> 70 | X30: =W30 -> 70 | Y30: =X30 -> 70 | Z30: =[12]公共下水道事業!AE32+#REF!+[12]農業集落排水事業!AE32 -> #REF! | AA30: =[12]公共下水道事業!AF32+#REF!+[12]農業集落排水事業!AF32 -> #REF! | AB30: =[12]公共下水道事業!AG32+#REF!+[12]農業集落排水事業!AG32 -> #REF! | AC30: =[12]公共下水道事業!AH32+#REF!+[12]農業集落排水事業!AH32 -> #REF! | AD30: =[12]公共下水道事業!AI32+#REF!+[12]農業集落排水事業!AI32 -> #REF! | AE30: =[12]公共下水道事業!AJ32+#REF!+[12]農業集落排水事業!AJ32 -> #REF! | AF30: =[12]公共下水道事業!AK32+#REF!+[12]農業集落排水事業!AK32 -> #REF! | AG30: =[12]公共下水道事業!AL32+#REF!+[12]農業集落排水事業!AL32 -> #REF! | ... AR30: =[12]公共下水道事業!AW32+#REF!+[12]農業集落排水事業!AW32 -> #REF!
D31: ２． | E31: 営業外収益 | P31: =P32+P35+P36 -> 129797 | Q31: =Q32+Q35+Q36 -> 127765 | R31: =R32+R35+R36 -> 127067 | S31: =S32+S35+S36 -> 158840 | T31: =T32+T35+T36 -> 157203 | U31: =U32+U35+U36 -> 157681 | V31: =V32+V35+V36 -> 157177 | W31: =W32+W35+W36 -> 156807 | ... Y31: =Y32+Y35+Y36 -> 153591 | Z31: =[12]公共下水道事業!AE33+#REF!+[12]農業集落排水事業!AE33 -> #REF! | AA31: =[12]公共下水道事業!AF33+#REF!+[12]農業集落排水事業!AF33 -> #REF! | AB31: =[12]公共下水道事業!AG33+#REF!+[12]農業集落排水事業!AG33 -> #REF! | AC31: =[12]公共下水道事業!AH33+#REF!+[12]農業集落排水事業!AH33 -> #REF! | AD31: =[12]公共下水道事業!AI33+#REF!+[12]農業集落排水事業!AI33 -> #REF! | AE31: =[12]公共下水道事業!AJ33+#REF!+[12]農業集落排水事業!AJ33 -> #REF! | AF31: =[12]公共下水道事業!AK33+#REF!+[12]農業集落排水事業!AK33 -> #REF! | AG31: =[12]公共下水道事業!AL33+#REF!+[12]農業集落排水事業!AL33 -> #REF! | ... AR31: =[12]公共下水道事業!AW33+#REF!+[12]農業集落排水事業!AW33 -> #REF!
D32: (1) | F32: 補助金 | P32: =P33+P34 -> 88514 | Q32: =Q33+Q34 -> 83963 | R32: =R33+R34 -> 78957 | S32: =S33+S34 -> 95777 | T32: =T33+T34 -> 91874 | U32: =U33+U34 -> 91481 | V32: =V33+V34 -> 90502 | W32: =W33+W34 -> 89657 | ... Y32: =Y33+Y34 -> 86957 | Z32: =[12]公共下水道事業!AE34+#REF!+[12]農業集落排水事業!AE34 -> #REF! | AA32: =[12]公共下水道事業!AF34+#REF!+[12]農業集落排水事業!AF34 -> #REF! | AB32: =[12]公共下水道事業!AG34+#REF!+[12]農業集落排水事業!AG34 -> #REF! | AC32: =[12]公共下水道事業!AH34+#REF!+[12]農業集落排水事業!AH34 -> #REF! | AD32: =[12]公共下水道事業!AI34+#REF!+[12]農業集落排水事業!AI34 -> #REF! | AE32: =[12]公共下水道事業!AJ34+#REF!+[12]農業集落排水事業!AJ34 -> #REF! | AF32: =[12]公共下水道事業!AK34+#REF!+[12]農業集落排水事業!AK34 -> #REF! | AG32: =[12]公共下水道事業!AL34+#REF!+[12]農業集落排水事業!AL34 -> #REF! | ... AR32: =[12]公共下水道事業!AW34+#REF!+[12]農業集落排水事業!AW34 -> #REF!
