Workbook
Name グラフ選択: #REF!
Name グラフ選択: #REF!
Name サービス: #REF!
Name サービス: #REF!
Name サービス選択: #REF!
Name サービス選択: #REF!
Name サービス名: #REF!
Name サービス名: #REF!
Name 在宅サービス: #REF!
Name 在宅サービス: #REF!
Name 施設・居住系サービス: #REF!
Name 施設・居住系サービス: #REF!
Name 推計パターン名: '1_推計値サマリ'!$S$5
Name 選択肢: #REF!
Name 選択肢: #REF!
Name 年度選択: #REF!
Name 年度選択: #REF!
Name 年度選択: #REF!
Name 保険者番号: '1_推計値サマリ'!$S$4
Name 保険者名: '1_推計値サマリ'!$S$3

Sheet 1_推計値サマリ
A1: 第10期介護保険事業（支援）計画策定に向けたワークシート 【総括表】
S2: 出力日： | T2: 2026/10/19
Q3: 保険者名 | S3: 川崎町
Q4: 保険者番号 | S4: 04324
Q5: 推計パターン名 | S5: 0911
A6: （１）推計値サマリ
A8: １．被保険者数（年度別） | T8: 単位：人
D9: 第9期 | G9: 第10期 | K9: 第11期 | M9: 第12期 | O9: 第14期 | Q9: 第16期 | S9: 第17期
D10: 令和6年度 | E10: 令和7年度 | F10: 令和8年度 | G10: 令和9年度 | H10: 令和10年度 | I10: 令和11年度 | J10: 伸び率① ※１ | K10: 令和12年度 | L10: 伸び率① ※２ | M10: 令和17年度 | N10: 伸び率① ※２ | O10: 令和22年度 | P10: 伸び率① ※２ | Q10: 令和27年度 | R10: 伸び率① ※２ | S10: 令和32年度 | T10: 伸び率① ※２
A11: 総数 | D11: =SUM(D12:D13) -> 5774 | E11: =SUM(E12:E13) -> 5740 | F11: =SUM(F12:F13) -> 5672 | G11: =SUM(G12:G13) -> 5605 | H11: =SUM(H12:H13) -> 5536 | I11: =SUM(I12:I13) -> 5469 | J11: =IFERROR((SUM(G11:I11)/3)/F11,"－") -> 0.9761401 | K11: =SUM(K12:K13) -> 5401 | L11: =IFERROR(K11/F11,"－") -> 0.95222144 | M11: =SUM(M12:M13) -> 5009 | N11: =IFERROR(M11/F11,"－") -> 0.88311001 | O11: =SUM(O12:O13) -> 4640 | P11: =IFERROR(O11/F11,"－") -> 0.8180536 | Q11: =SUM(Q12:Q13) -> 4192 | R11: =IFERROR(Q11/F11,"－") -> 0.73906911 | S11: =SUM(S12:S13) -> 3748 | T11: =IFERROR(S11/F11,"－") -> 0.66078984
B12: 第1号被保険者数 | D12: 3270 | E12: 3285 | F12: 3257 | G12: 3231 | H12: 3203 | I12: 3177 | J12: =IFERROR((SUM(G12:I12)/3)/F12,"－") -> 0.98362501 | K12: 3149 | L12: =IFERROR(K12/F12,"－") -> 0.96684065 | M12: 2967 | N12: =IFERROR(M12/F12,"－") -> 0.91096101 | O12: 2835 | P12: =IFERROR(O12/F12,"－") -> 0.87043291 | Q12: 2639 | R12: =IFERROR(Q12/F12,"－") -> 0.81025484 | S12: 2494 | T12: =IFERROR(S12/F12,"－") -> 0.76573534
B13: 第2号被保険者数 | D13: 2504 | E13: 2455 | F13: 2415 | G13: 2374 | H13: 2333 | I13: 2292 | J13: =IFERROR((SUM(G13:I13)/3)/F13,"－") -> 0.96604555 | K13: 2252 | L13: =IFERROR(K13/F13,"－") -> 0.93250518 | M13: 2042 | N13: =IFERROR(M13/F13,"－") -> 0.84554865 | O13: 1805 | P13: =IFERROR(O13/F13,"－") -> 0.74741201 | Q13: 1553 | R13: =IFERROR(Q13/F13,"－") -> 0.64306418 | S13: 1254 | T13: =IFERROR(S13/F13,"－") -> 0.51925466
G14: ※１：第10期平均値/令和8年度の値*100 | K14: ※２：令和12（17,22,27,32）年度の値/令和8年度の値*100
A16: ２．要介護（支援）認定者数 | T16: 単位：人
D17: 第9期 | G17: 第10期 | K17: 第11期 | M17: 第12期 | O17: 第14期 | Q17: 第16期 | S17: 第17期
D18: 令和6年度 | E18: 令和7年度 | F18: 令和8年度 | G18: 令和9年度 | H18: 令和10年度 | I18: 令和11年度 | J18: 伸び率① ※１ | K18: 令和12年度 | L18: 伸び率① ※２ | M18: 令和17年度 | N18: 伸び率① ※２ | O18: 令和22年度 | P18: 伸び率① ※２ | Q18: 令和27年度 | R18: 伸び率① ※２ | S18: 令和32年度 | T18: 伸び率① ※２
A19: 総数 | D19: =SUM(D20:D26) -> 562 | E19: =SUM(E20:E26) -> 568 | F19: =SUM(F20:F26) -> 567 | G19: =SUM(G20:G26) -> 580 | H19: =SUM(H20:H26) -> 584 | I19: =SUM(I20:I26) -> 589 | J19: =IFERROR((SUM(G19:I19)/3)/F19,"－") -> 1.0305703 | K19: =SUM(K20:K26) -> 590 | L19: =IFERROR(K19/F19,"－") -> 1.0405644 | M19: =SUM(M20:M26) -> 641 | N19: =IFERROR(M19/F19,"－") -> 1.1305115 | O19: =SUM(O20:O26) -> 694 | P19: =IFERROR(O19/F19,"－") -> 1.2239859 | Q19: =SUM(Q20:Q26) -> 673 | R19: =IFERROR(Q19/F19,"－") -> 1.1869489 | S19: =SUM(S20:S26) -> 593 | T19: =IFERROR(S19/F19,"－") -> 1.0458554
C20: 要支援1 | D20: 27 | E20: 33 | F20: 33 | G20: 34 | H20: 34 | I20: 34 | J20: =IFERROR((SUM(G20:I20)/3)/F20,"－") -> 1.030303 | K20: 33 | L20: =IFERROR(K20/F20,"－") -> 1 | M20: 37 | N20: =IFERROR(M20/F20,"－") -> 1.1212121 | O20: 40 | P20: =IFERROR(O20/F20,"－") -> 1.2121212 | Q20: 37 | R20: =IFERROR(Q20/F20,"－") -> 1.1212121 | S20: 32 | T20: =IFERROR(S20/F20,"－") -> 0.96969697
C21: 要支援2 | D21: 73 | E21: 85 | F21: 92 | G21: 97 | H21: 98 | I21: 100 | J21: =IFERROR((SUM(G21:I21)/3)/F21,"－") -> 1.0688406 | K21: 100 | L21: =IFERROR(K21/F21,"－") -> 1.0869565 | M21: 106 | N21: =IFERROR(M21/F21,"－") -> 1.1521739 | O21: 112 | P21: =IFERROR(O21/F21,"－") -> 1.2173913 | Q21: 106 | R21: =IFERROR(Q21/F21,"－") -> 1.1521739 | S21: 95 | T21: =IFERROR(S21/F21,"－") -> 1.0326087
C22: 要介護1 | D22: 69 | E22: 70 | F22: 65 | G22: 64 | H22: 65 | I22: 66 | J22: =IFERROR((SUM(G22:I22)/3)/F22,"－") -> 1 | K22: 69 | L22: =IFERROR(K22/F22,"－") -> 1.0615385 | M22: 73 | N22: =IFERROR(M22/F22,"－") -> 1.1230769 | O22: 77 | P22: =IFERROR(O22/F22,"－") -> 1.1846154 | Q22: 70 | R22: =IFERROR(Q22/F22,"－") -> 1.0769231 | S22: 60 | T22: =IFERROR(S22/F22,"－") -> 0.92307692
C23: 要介護2 | D23: 126 | E23: 116 | F23: 97 | G23: 98 | H23: 100 | I23: 100 | J23: =IFERROR((SUM(G23:I23)/3)/F23,"－") -> 1.024055 | K23: 101 | L23: =IFERROR(K23/F23,"－") -> 1.0412371 | M23: 116 | N23: =IFERROR(M23/F23,"－") -> 1.1958763 | O23: 120 | P23: =IFERROR(O23/F23,"－") -> 1.2371134 | Q23: 114 | R23: =IFERROR(Q23/F23,"－") -> 1.1752577 | S23: 99 | T23: =IFERROR(S23/F23,"－") -> 1.0206186
C24: 要介護3 | D24: 126 | E24: 131 | F24: 133 | G24: 138 | H24: 138 | I24: 140 | J24: =IFERROR((SUM(G24:I24)/3)/F24,"－") -> 1.0426065 | K24: 138 | L24: =IFERROR(K24/F24,"－") -> 1.037594 | M24: 152 | N24: =IFERROR(M24/F24,"－") -> 1.1428571 | O24: 169 | P24: =IFERROR(O24/F24,"－") -> 1.2706767 | Q24: 170 | R24: =IFERROR(Q24/F24,"－") -> 1.2781955 | S24: 150 | T24: =IFERROR(S24/F24,"－") -> 1.1278195
C25: 要介護4 | D25: 89 | E25: 84 | F25: 98 | G25: 99 | H25: 99 | I25: 98 | J25: =IFERROR((SUM(G25:I25)/3)/F25,"－") -> 1.0068027 | K25: 99 | L25: =IFERROR(K25/F25,"－") -> 1.0102041 | M25: 105 | N25: =IFERROR(M25/F25,"－") -> 1.0714286 | O25: 115 | P25: =IFERROR(O25/F25,"－") -> 1.1734694 | Q25: 112 | R25: =IFERROR(Q25/F25,"－") -> 1.1428571 | S25: 100 | T25: =IFERROR(S25/F25,"－") -> 1.0204082
C26: 要介護5 | D26: 52 | E26: 49 | F26: 49 | G26: 50 | H26: 50 | I26: 51 | J26: =IFERROR((SUM(G26:I26)/3)/F26,"－") -> 1.0272109 | K26: 50 | L26: =IFERROR(K26/F26,"－") -> 1.0204082 | M26: 52 | N26: =IFERROR(M26/F26,"－") -> 1.0612245 | O26: 61 | P26: =IFERROR(O26/F26,"－") -> 1.244898 | Q26: 64 | R26: =IFERROR(Q26/F26,"－") -> 1.3061224 | S26: 57 | T26: =IFERROR(S26/F26,"－") -> 1.1632653
B27: うち第1号被保険者数 | D27: =SUM(D28:D34) -> 554 | E27: =SUM(E28:E34) -> 560 | F27: =SUM(F28:F34) -> 562 | G27: =SUM(G28:G34) -> 575 | H27: =SUM(H28:H34) -> 579 | I27: =SUM(I28:I34) -> 584 | J27: =IFERROR((SUM(G27:I27)/3)/F27,"－") -> 1.0308422 | K27: =SUM(K28:K34) -> 585 | L27: =IFERROR(K27/F27,"－") -> 1.0409253 | M27: =SUM(M28:M34) -> 636 | N27: =IFERROR(M27/F27,"－") -> 1.1316726 | O27: =SUM(O28:O34) -> 689 | P27: =IFERROR(O27/F27,"－") -> 1.2259786 | Q27: =SUM(Q28:Q34) -> 669 | R27: =IFERROR(Q27/F27,"－") -> 1.1903915 | S27: =SUM(S28:S34) -> 590 | T27: =IFERROR(S27/F27,"－") -> 1.0498221
C28: 要支援1 | D28: 27 | E28: 33 | F28: 33 | G28: 34 | H28: 34 | I28: 34 | J28: =IFERROR((SUM(G28:I28)/3)/F28,"－") -> 1.030303 | K28: 33 | L28: =IFERROR(K28/F28,"－") -> 1 | M28: 37 | N28: =IFERROR(M28/F28,"－") -> 1.1212121 | O28: 40 | P28: =IFERROR(O28/F28,"－") -> 1.2121212 | Q28: 37 | R28: =IFERROR(Q28/F28,"－") -> 1.1212121 | S28: 32 | T28: =IFERROR(S28/F28,"－") -> 0.96969697
C29: 要支援2 | D29: 72 | E29: 84 | F29: 91 | G29: 96 | H29: 97 | I29: 99 | J29: =IFERROR((SUM(G29:I29)/3)/F29,"－") -> 1.0695971 | K29: 99 | L29: =IFERROR(K29/F29,"－") -> 1.0879121 | M29: 105 | N29: =IFERROR(M29/F29,"－") -> 1.1538462 | O29: 111 | P29: =IFERROR(O29/F29,"－") -> 1.2197802 | Q29: 105 | R29: =IFERROR(Q29/F29,"－") -> 1.1538462 | S29: 95 | T29: =IFERROR(S29/F29,"－") -> 1.043956
C30: 要介護1 | D30: 68 | E30: 69 | F30: 65 | G30: 64 | H30: 65 | I30: 66 | J30: =IFERROR((SUM(G30:I30)/3)/F30,"－") -> 1 | K30: 69 | L30: =IFERROR(K30/F30,"－") -> 1.0615385 | M30: 73 | N30: =IFERROR(M30/F30,"－") -> 1.1230769 | O30: 77 | P30: =IFERROR(O30/F30,"－") -> 1.1846154 | Q30: 70 | R30: =IFERROR(Q30/F30,"－") -> 1.0769231 | S30: 60 | T30: =IFERROR(S30/F30,"－") -> 0.92307692
C31: 要介護2 | D31: 124 | E31: 115 | F31: 97 | G31: 98 | H31: 100 | I31: 100 | J31: =IFERROR((SUM(G31:I31)/3)/F31,"－") -> 1.024055 | K31: 101 | L31: =IFERROR(K31/F31,"－") -> 1.0412371 | M31: 116 | N31: =IFERROR(M31/F31,"－") -> 1.1958763 | O31: 120 | P31: =IFERROR(O31/F31,"－") -> 1.2371134 | Q31: 114 | R31: =IFERROR(Q31/F31,"－") -> 1.1752577 | S31: 99 | T31: =IFERROR(S31/F31,"－") -> 1.0206186
C32: 要介護3 | D32: 125 | E32: 128 | F32: 131 | G32: 136 | H32: 136 | I32: 138 | J32: =IFERROR((SUM(G32:I32)/3)/F32,"－") -> 1.043257 | K32: 136 | L32: =IFERROR(K32/F32,"－") -> 1.0381679 | M32: 150 | N32: =IFERROR(M32/F32,"－") -> 1.1450382 | O32: 167 | P32: =IFERROR(O32/F32,"－") -> 1.2748092 | Q32: 168 | R32: =IFERROR(Q32/F32,"－") -> 1.2824427 | S32: 148 | T32: =IFERROR(S32/F32,"－") -> 1.129771
C33: 要介護4 | D33: 87 | E33: 83 | F33: 98 | G33: 99 | H33: 99 | I33: 98 | J33: =IFERROR((SUM(G33:I33)/3)/F33,"－") -> 1.0068027 | K33: 99 | L33: =IFERROR(K33/F33,"－") -> 1.0102041 | M33: 105 | N33: =IFERROR(M33/F33,"－") -> 1.0714286 | O33: 115 | P33: =IFERROR(O33/F33,"－") -> 1.1734694 | Q33: 112 | R33: =IFERROR(Q33/F33,"－") -> 1.1428571 | S33: 100 | T33: =IFERROR(S33/F33,"－") -> 1.0204082
C34: 要介護5 | D34: 51 | E34: 48 | F34: 47 | G34: 48 | H34: 48 | I34: 49 | J34: =IFERROR((SUM(G34:I34)/3)/F34,"－") -> 1.0283688 | K34: 48 | L34: =IFERROR(K34/F34,"－") -> 1.0212766 | M34: 50 | N34: =IFERROR(M34/F34,"－") -> 1.0638298 | O34: 59 | P34: =IFERROR(O34/F34,"－") -> 1.2553191 | Q34: 63 | R34: =IFERROR(Q34/F34,"－") -> 1.3404255 | S34: 56 | T34: =IFERROR(S34/F34,"－") -> 1.1914894
G35: ※１：第10期平均値/令和8年度の値*100 | K35: ※２：令和12（17,22,27,32）年度の値/令和8年度の値*100
A37: ３．介護予防サービス見込量 | T37: 単位：千円
D38: 第9期 | G38: 第10期 | K38: 第11期 | M38: 第12期 | O38: 第14期 | Q38: 第16期 | S38: 第17期
D39: 令和6年度 | E39: 令和7年度 | F39: 令和8年度 | G39: 令和9年度 | H39: 令和10年度 | I39: 令和11年度 | J39: 伸び率① ※１ | K39: 令和12年度 | L39: 伸び率① ※２ | M39: 令和17年度 | N39: 伸び率① ※２ | O39: 令和22年度 | P39: 伸び率① ※２ | Q39: 令和27年度 | R39: 伸び率① ※２ | S39: 令和32年度 | T39: 伸び率① ※２
A40: （１）在宅サービス | D40: =('2_サービス別給付費'!D12+'2_サービス別給付費'!D14+'2_サービス別給付費'!D17+'2_サービス別給付費'!D20+'2_サービス別給付費'!D23+'2_サービス別給付費'!D25+'2_サービス別給付費'!D27+'2_サービス別給付費'!D29+'2_サービス別給付費'!D32+'2_サービス別給付費'!D35+'2_サービス別給付費'!D38+'2_サービス別給付費'!D41+'2_サービス別給付費'!D43+'2_サービス別給付費'!D45+'2_サービス別給付費'!D50+'2_サービス別給付費'!D53+'2_サービス別給付費'!D57) -> 27005.507 | E40: =('2_サービス別給付費'!E12+'2_サービス別給付費'!E14+'2_サービス別給付費'!E17+'2_サービス別給付費'!E20+'2_サービス別給付費'!E23+'2_サービス別給付費'!E25+'2_サービス別給付費'!E27+'2_サービス別給付費'!E29+'2_サービス別給付費'!E32+'2_サービス別給付費'!E35+'2_サービス別給付費'!E38+'2_サービス別給付費'!E41+'2_サービス別給付費'!E43+'2_サービス別給付費'!E45+'2_サービス別給付費'!E50+'2_サービス別給付費'!E53+'2_サービス別給付費'!E57) -> 27938.341 | F40: =('2_サービス別給付費'!F12+'2_サービス別給付費'!F14+'2_サービス別給付費'!F17+'2_サービス別給付費'!F20+'2_サービス別給付費'!F23+'2_サービス別給付費'!F25+'2_サービス別給付費'!F27+'2_サービス別給付費'!F29+'2_サービス別給付費'!F32+'2_サービス別給付費'!F35+'2_サービス別給付費'!F38+'2_サービス別給付費'!F41+'2_サービス別給付費'!F43+'2_サービス別給付費'!F45+'2_サービス別給付費'!F50+'2_サービス別給付費'!F53+'2_サービス別給付費'!F57) -> 34325.975 | G40: =('2_サービス別給付費'!G12+'2_サービス別給付費'!G14+'2_サービス別給付費'!G17+'2_サービス別給付費'!G20+'2_サービス別給付費'!G23+'2_サービス別給付費'!G25+'2_サービス別給付費'!G27+'2_サービス別給付費'!G29+'2_サービス別給付費'!G32+'2_サービス別給付費'!G35+'2_サービス別給付費'!G38+'2_サービス別給付費'!G41+'2_サービス別給付費'!G43+'2_サービス別給付費'!G45+'2_サービス別給付費'!G50+'2_サービス別給付費'!G53+'2_サービス別給付費'!G57) -> 33168 | H40: =('2_サービス別給付費'!H12+'2_サービス別給付費'!H14+'2_サービス別給付費'!H17+'2_サービス別給付費'!H20+'2_サービス別給付費'!H23+'2_サービス別給付費'!H25+'2_サービス別給付費'!H27+'2_サービス別給付費'!H29+'2_サービス別給付費'!H32+'2_サービス別給付費'!H35+'2_サービス別給付費'!H38+'2_サービス別給付費'!H41+'2_サービス別給付費'!H43+'2_サービス別給付費'!H45+'2_サービス別給付費'!H50+'2_サービス別給付費'!H53+'2_サービス別給付費'!H57+'2_サービス別給付費'!H59) -> 33965 | I40: =('2_サービス別給付費'!I12+'2_サービス別給付費'!I14+'2_サービス別給付費'!I17+'2_サービス別給付費'!I20+'2_サービス別給付費'!I23+'2_サービス別給付費'!I25+'2_サービス別給付費'!I27+'2_サービス別給付費'!I29+'2_サービス別給付費'!I32+'2_サービス別給付費'!I35+'2_サービス別給付費'!I38+'2_サービス別給付費'!I41+'2_サービス別給付費'!I43+'2_サービス別給付費'!I45+'2_サービス別給付費'!I50+'2_サービス別給付費'!I53+'2_サービス別給付費'!I57+'2_サービス別給付費'!I59) -> 34358 | J40: =IFERROR((SUM(G40:I40)/3)/F40,"－") -> 0.98556075 | K40: =('2_サービス別給付費'!K12+'2_サービス別給付費'!K14+'2_サービス別給付費'!K17+'2_サービス別給付費'!K20+'2_サービス別給付費'!K23+'2_サービス別給付費'!K25+'2_サービス別給付費'!K27+'2_サービス別給付費'!K29+'2_サービス別給付費'!K32+'2_サービス別給付費'!K35+'2_サービス別給付費'!K38+'2_サービス別給付費'!K41+'2_サービス別給付費'!K43+'2_サービス別給付費'!K45+'2_サービス別給付費'!K50+'2_サービス別給付費'!K53+'2_サービス別給付費'!K57+'2_サービス別給付費'!K59) -> 33959 | L40: =IFERROR(K40/F40,"－") -> 0.98930912 | M40: =('2_サービス別給付費'!M12+'2_サービス別給付費'!M14+'2_サービス別給付費'!M17+'2_サービス別給付費'!M20+'2_サービス別給付費'!M23+'2_サービス別給付費'!M25+'2_サービス別給付費'!M27+'2_サービス別給付費'!M29+'2_サービス別給付費'!M32+'2_サービス別給付費'!M35+'2_サービス別給付費'!M38+'2_サービス別給付費'!M41+'2_サービス別給付費'!M43+'2_サービス別給付費'!M45+'2_サービス別給付費'!M50+'2_サービス別給付費'!M53+'2_サービス別給付費'!M57+'2_サービス別給付費'!M59) -> 36228 | N40: =IFERROR(M40/F40,"－") -> 1.0554107 | O40: =('2_サービス別給付費'!O12+'2_サービス別給付費'!O14+'2_サービス別給付費'!O17+'2_サービス別給付費'!O20+'2_サービス別給付費'!O23+'2_サービス別給付費'!O25+'2_サービス別給付費'!O27+'2_サービス別給付費'!O29+'2_サービス別給付費'!O32+'2_サービス別給付費'!O35+'2_サービス別給付費'!O38+'2_サービス別給付費'!O41+'2_サービス別給付費'!O43+'2_サービス別給付費'!O45+'2_サービス別給付費'!O50+'2_サービス別給付費'!O53+'2_サービス別給付費'!O57+'2_サービス別給付費'!O59) -> 38436 | P40: =IFERROR(O40/F40,"－") -> 1.1197351 | Q40: =('2_サービス別給付費'!Q12+'2_サービス別給付費'!Q14+'2_サービス別給付費'!Q17+'2_サービス別給付費'!Q20+'2_サービス別給付費'!Q23+'2_サービス別給付費'!Q25+'2_サービス別給付費'!Q27+'2_サービス別給付費'!Q29+'2_サービス別給付費'!Q32+'2_サービス別給付費'!Q35+'2_サービス別給付費'!Q38+'2_サービス別給付費'!Q41+'2_サービス別給付費'!Q43+'2_サービス別給付費'!Q45+'2_サービス別給付費'!Q50+'2_サービス別給付費'!Q53+'2_サービス別給付費'!Q57+'2_サービス別給付費'!Q59) -> 36228 | R40: =IFERROR(Q40/F40,"－") -> 1.0554107 | S40: =('2_サービス別給付費'!S12+'2_サービス別給付費'!S14+'2_サービス別給付費'!S17+'2_サービス別給付費'!S20+'2_サービス別給付費'!S23+'2_サービス別給付費'!S25+'2_サービス別給付費'!S27+'2_サービス別給付費'!S29+'2_サービス別給付費'!S32+'2_サービス別給付費'!S35+'2_サービス別給付費'!S38+'2_サービス別給付費'!S41+'2_サービス別給付費'!S43+'2_サービス別給付費'!S45+'2_サービス別給付費'!S50+'2_サービス別給付費'!S53+'2_サービス別給付費'!S57+'2_サービス別給付費'!S59) -> 32680 | T40: =IFERROR(S40/F40,"－") -> 0.95204871
A41: （２）居住系サービス | D41: =('2_サービス別給付費'!D47+'2_サービス別給付費'!D55) -> 0 | E41: =('2_サービス別給付費'!E47+'2_サービス別給付費'!E55) -> 4349.297 | F41: =('2_サービス別給付費'!F47+'2_サービス別給付費'!F55) -> 0 | G41: =('2_サービス別給付費'!G47+'2_サービス別給付費'!G55) -> 0 | H41: =('2_サービス別給付費'!H47+'2_サービス別給付費'!H55) -> 0 | I41: =('2_サービス別給付費'!I47+'2_サービス別給付費'!I55) -> 0 | J41: =IFERROR((SUM(G41:I41)/3)/F41,"－") -> － | K41: =('2_サービス別給付費'!K47+'2_サービス別給付費'!K55) -> 0 | L41: =IFERROR(K41/F41,"－") -> － | M41: =('2_サービス別給付費'!M47+'2_サービス別給付費'!M55) -> 0 | N41: =IFERROR(M41/F41,"－") -> － | O41: =('2_サービス別給付費'!O47+'2_サービス別給付費'!O55) -> 0 | P41: =IFERROR(O41/F41,"－") -> － | Q41: =('2_サービス別給付費'!Q47+'2_サービス別給付費'!Q55) -> 0 | R41: =IFERROR(Q41/F41,"－") -> － | S41: =('2_サービス別給付費'!S47+'2_サービス別給付費'!S55) -> 0 | T41: =IFERROR(S41/F41,"－") -> －
A42: 合計 | D42: =SUM(D40:D41) -> 27005.507 | E42: =SUM(E40:E41) -> 32287.638 | F42: =SUM(F40:F41) -> 34325.975 | G42: =SUM(G40:G41) -> 33168 | H42: =SUM(H40:H41) -> 33965 | I42: =SUM(I40:I41) -> 34358 | J42: =IFERROR((SUM(G42:I42)/3)/F42,"－") -> 0.98556075 | K42: =SUM(K40:K41) -> 33959 | L42: =IFERROR(K42/F42,"－") -> 0.98930912 | M42: =SUM(M40:M41) -> 36228 | N42: =IFERROR(M42/F42,"－") -> 1.0554107 | O42: =SUM(O40:O41) -> 38436 | P42: =IFERROR(O42/F42,"－") -> 1.1197351 | Q42: =SUM(Q40:Q41) -> 36228 | R42: =IFERROR(Q42/F42,"－") -> 1.0554107 | S42: =SUM(S40:S41) -> 32680 | T42: =IFERROR(S42/F42,"－") -> 0.95204871
G43: ※１：第10期平均値/令和8年度の値*100 | K43: ※２：令和12（17,22,27,32）年度の値/令和8年度の値*100
...

Sheet 2_サービス別給付費
A1: （２）サービス別給付費
S2: 出力日： | T2: ='1_推計値サマリ'!T2 -> 2026/10/19
Q3: 保険者名 | S3: =保険者名 -> 川崎町
Q4: 保険者番号 | S4: =保険者番号 -> 04324
Q5: 推計パターン名 | S5: =推計パターン名 -> 0911
A8: １．介護予防サービス見込量 | T8: 単位：各項目の（）内
D9: 第9期 | G9: 第10期 | K9: 第11期 | M9: 第12期 | O9: 第14期 | Q9: 第16期 | S9: 第17期
D10: 令和6年度 | E10: 令和7年度 | F10: 令和8年度 | G10: 令和9年度 | H10: 令和10年度 | I10: 令和11年度 | J10: 伸び率① ※１ | K10: 令和12年度 | L10: 伸び率① ※２ | M10: 令和17年度 | N10: 伸び率① ※２ | O10: 令和22年度 | P10: 伸び率① ※２ | Q10: 令和27年度 | R10: 伸び率① ※２ | S10: 令和32年度 | T10: 伸び率① ※２
A11: （１）介護予防サービス
B12: 未使用 | C12: 給付費（千円）
C13: 人数（人）
B14: 介護予防訪問入浴介護 | C14: 給付費（千円） | D14: 52.542 | E14: 168.56 | F14: 0 | G14: 0 | H14: 0 | I14: 0 | J14: =IFERROR(SUM(G14:I14)/3/F14,"－") -> － | K14: 0 | L14: =IFERROR(K14/F14,"－") -> － | M14: 0 | N14: =IFERROR(M14/F14,"－") -> － | O14: 0 | P14: =IFERROR(O14/F14,"－") -> － | Q14: 0 | R14: =IFERROR(Q14/F14,"－") -> － | S14: 0 | T14: =IFERROR(S14/F14,"－") -> －
C15: 回数（回） | D15: 0.5 | E15: 1.6666667 | F15: 0 | G15: 0 | H15: 0 | I15: 0 | J15: =IFERROR(SUM(G15:I15)/3/F15,"－") -> － | K15: 0 | L15: =IFERROR(K15/F15,"－") -> － | M15: 0 | N15: =IFERROR(M15/F15,"－") -> － | O15: 0 | P15: =IFERROR(O15/F15,"－") -> － | Q15: 0 | R15: =IFERROR(Q15/F15,"－") -> － | S15: 0 | T15: =IFERROR(S15/F15,"－") -> －
C16: 人数（人） | D16: 0.16666667 | E16: 0.41666667 | F16: 0 | G16: 0 | H16: 0 | I16: 0 | J16: =IFERROR(SUM(G16:I16)/3/F16,"－") -> － | K16: 0 | L16: =IFERROR(K16/F16,"－") -> － | M16: 0 | N16: =IFERROR(M16/F16,"－") -> － | O16: 0 | P16: =IFERROR(O16/F16,"－") -> － | Q16: 0 | R16: =IFERROR(Q16/F16,"－") -> － | S16: 0 | T16: =IFERROR(S16/F16,"－") -> －
B17: 介護予防訪問看護 | C17: 給付費（千円） | D17: 153.405 | E17: 118.694 | F17: 289.8504 | G17: 261 | H17: 261 | I17: 261 | J17: =IFERROR(SUM(G17:I17)/3/F17,"－") -> 0.90046452 | K17: 261 | L17: =IFERROR(K17/F17,"－") -> 0.90046452 | M17: 261 | N17: =IFERROR(M17/F17,"－") -> 0.90046452 | O17: 261 | P17: =IFERROR(O17/F17,"－") -> 0.90046452 | Q17: 261 | R17: =IFERROR(Q17/F17,"－") -> 0.90046452 | S17: 261 | T17: =IFERROR(S17/F17,"－") -> 0.90046452
C18: 回数（回） | D18: 3.75 | E18: 2.8333333 | F18: 7.1 | G18: 6.4 | H18: 6.4 | I18: 6.4 | J18: =IFERROR(SUM(G18:I18)/3/F18,"－") -> 0.90140845 | K18: 6.4 | L18: =IFERROR(K18/F18,"－") -> 0.90140845 | M18: 6.4 | N18: =IFERROR(M18/F18,"－") -> 0.90140845 | O18: 6.4 | P18: =IFERROR(O18/F18,"－") -> 0.90140845 | Q18: 6.4 | R18: =IFERROR(Q18/F18,"－") -> 0.90140845 | S18: 6.4 | T18: =IFERROR(S18/F18,"－") -> 0.90140845
C19: 人数（人） | D19: 0.91666667 | E19: 1 | F19: 1 | G19: 1 | H19: 1 | I19: 1 | J19: =IFERROR(SUM(G19:I19)/3/F19,"－") -> 1 | K19: 1 | L19: =IFERROR(K19/F19,"－") -> 1 | M19: 1 | N19: =IFERROR(M19/F19,"－") -> 1 | O19: 1 | P19: =IFERROR(O19/F19,"－") -> 1 | Q19: 1 | R19: =IFERROR(Q19/F19,"－") -> 1 | S19: 1 | T19: =IFERROR(S19/F19,"－") -> 1
B20: 介護予防訪問リハビリテーション | C20: 給付費（千円） | D20: 2263.051 | E20: 2212.932 | F20: 3748.4604 | G20: 3517 | H20: 3469 | I20: 3457 | J20: =IFERROR(SUM(G20:I20)/3/F20,"－") -> 0.92864793 | K20: 3457 | L20: =IFERROR(K20/F20,"－") -> 0.9222453 | M20: 3457 | N20: =IFERROR(M20/F20,"－") -> 0.9222453 | O20: 3457 | P20: =IFERROR(O20/F20,"－") -> 0.9222453 | Q20: 3457 | R20: =IFERROR(Q20/F20,"－") -> 0.9222453 | S20: 3457 | T20: =IFERROR(S20/F20,"－") -> 0.9222453
C21: 回数（回） | D21: 60.083333 | E21: 57.666667 | F21: 91.2 | G21: 85.8 | H21: 84.6 | I21: 84.3 | J21: =IFERROR(SUM(G21:I21)/3/F21,"－") -> 0.93092105 | K21: 84.3 | L21: =IFERROR(K21/F21,"－") -> 0.92434211 | M21: 84.3 | N21: =IFERROR(M21/F21,"－") -> 0.92434211 | O21: 84.3 | P21: =IFERROR(O21/F21,"－") -> 0.92434211 | Q21: 84.3 | R21: =IFERROR(Q21/F21,"－") -> 0.92434211 | S21: 84.3 | T21: =IFERROR(S21/F21,"－") -> 0.92434211
C22: 人数（人） | D22: 5 | E22: 5.25 | F22: 6 | G22: 6 | H22: 6 | I22: 6 | J22: =IFERROR(SUM(G22:I22)/3/F22,"－") -> 1 | K22: 6 | L22: =IFERROR(K22/F22,"－") -> 1 | M22: 6 | N22: =IFERROR(M22/F22,"－") -> 1 | O22: 6 | P22: =IFERROR(O22/F22,"－") -> 1 | Q22: 6 | R22: =IFERROR(Q22/F22,"－") -> 1 | S22: 6 | T22: =IFERROR(S22/F22,"－") -> 1
B23: 介護予防居宅療養管理指導 | C23: 給付費（千円） | D23: 0 | E23: 0 | F23: 0 | G23: 0 | H23: 0 | I23: 0 | J23: =IFERROR(SUM(G23:I23)/3/F23,"－") -> － | K23: 0 | L23: =IFERROR(K23/F23,"－") -> － | M23: 0 | N23: =IFERROR(M23/F23,"－") -> － | O23: 0 | P23: =IFERROR(O23/F23,"－") -> － | Q23: 0 | R23: =IFERROR(Q23/F23,"－") -> － | S23: 0 | T23: =IFERROR(S23/F23,"－") -> －
C24: 人数（人） | D24: 0 | E24: 0 | F24: 0 | G24: 0 | H24: 0 | I24: 0 | J24: =IFERROR(SUM(G24:I24)/3/F24,"－") -> － | K24: 0 | L24: =IFERROR(K24/F24,"－") -> － | M24: 0 | N24: =IFERROR(M24/F24,"－") -> － | O24: 0 | P24: =IFERROR(O24/F24,"－") -> － | Q24: 0 | R24: =IFERROR(Q24/F24,"－") -> － | S24: 0 | T24: =IFERROR(S24/F24,"－") -> －
B25: 未使用 | C25: 給付費（千円） | N25: =IFERROR(M25/F25,"－") -> － | P25: =IFERROR(O25/F25,"－") -> － | R25: =IFERROR(Q25/F25,"－") -> － | T25: =IFERROR(S25/F25,"－") -> －
C26: 人数（人） | N26: =IFERROR(M26/F26,"－") -> － | P26: =IFERROR(O26/F26,"－") -> － | R26: =IFERROR(Q26/F26,"－") -> － | T26: =IFERROR(S26/F26,"－") -> －
B27: 介護予防通所リハビリテーション | C27: 給付費（千円） | D27: 18826.216 | E27: 17070.292 | F27: 21512.58 | G27: 20748 | H27: 21573 | I27: 21868 | J27: =IFERROR(SUM(G27:I27)/3/F27,"－") -> 0.99459634 | K27: 21573 | L27: =IFERROR(K27/F27,"－") -> 1.0028086 | M27: 23224 | N27: =IFERROR(M27/F27,"－") -> 1.0795544 | O27: 24874 | P27: =IFERROR(O27/F27,"－") -> 1.1562537 | Q27: 23224 | R27: =IFERROR(Q27/F27,"－") -> 1.0795544 | S27: 20748 | T27: =IFERROR(S27/F27,"－") -> 0.96445894
C28: 人数（人） | D28: 37.5 | E28: 34.666667 | F28: 49 | G28: 48 | H28: 50 | I28: 51 | J28: =IFERROR(SUM(G28:I28)/3/F28,"－") -> 1.0136054 | K28: 50 | L28: =IFERROR(K28/F28,"－") -> 1.0204082 | M28: 54 | N28: =IFERROR(M28/F28,"－") -> 1.1020408 | O28: 58 | P28: =IFERROR(O28/F28,"－") -> 1.1836735 | Q28: 54 | R28: =IFERROR(Q28/F28,"－") -> 1.1020408 | S28: 48 | T28: =IFERROR(S28/F28,"－") -> 0.97959184
B29: 介護予防短期入所生活介護 | C29: 給付費（千円） | D29: 57.912 | E29: 37.6 | F29: 0 | G29: 0 | H29: 0 | I29: 0 | J29: =IFERROR(SUM(G29:I29)/3/F29,"－") -> － | K29: 0 | L29: =IFERROR(K29/F29,"－") -> － | M29: 0 | N29: =IFERROR(M29/F29,"－") -> － | O29: 0 | P29: =IFERROR(O29/F29,"－") -> － | Q29: 0 | R29: =IFERROR(Q29/F29,"－") -> － | S29: 0 | T29: =IFERROR(S29/F29,"－") -> －
C30: 日数（日） | D30: 0.75 | E30: 0.41666667 | F30: 0 | G30: 0 | H30: 0 | I30: 0 | J30: =IFERROR(SUM(G30:I30)/3/F30,"－") -> － | K30: 0 | L30: =IFERROR(K30/F30,"－") -> － | M30: 0 | N30: =IFERROR(M30/F30,"－") -> － | O30: 0 | P30: =IFERROR(O30/F30,"－") -> － | Q30: 0 | R30: =IFERROR(Q30/F30,"－") -> － | S30: 0 | T30: =IFERROR(S30/F30,"－") -> －
C31: 人数（人） | D31: 0.16666667 | E31: 0.083333333 | F31: 0 | G31: 0 | H31: 0 | I31: 0 | J31: =IFERROR(SUM(G31:I31)/3/F31,"－") -> － | K31: 0 | L31: =IFERROR(K31/F31,"－") -> － | M31: 0 | N31: =IFERROR(M31/F31,"－") -> － | O31: 0 | P31: =IFERROR(O31/F31,"－") -> － | Q31: 0 | R31: =IFERROR(Q31/F31,"－") -> － | S31: 0 | T31: =IFERROR(S31/F31,"－") -> －
B32: 介護予防短期入所療養介護（老健） | C32: 給付費（千円） | D32: 260.084 | E32: 44.84 | F32: 0 | G32: 0 | H32: 0 | I32: 0 | J32: =IFERROR(SUM(G32:I32)/3/F32,"－") -> － | K32: 0 | L32: =IFERROR(K32/F32,"－") -> － | M32: 0 | N32: =IFERROR(M32/F32,"－") -> － | O32: 0 | P32: =IFERROR(O32/F32,"－") -> － | Q32: 0 | R32: =IFERROR(Q32/F32,"－") -> － | S32: 0 | T32: =IFERROR(S32/F32,"－") -> －
C33: 日数（日） | D33: 1.9166667 | E33: 0.33333333 | F33: 0 | G33: 0 | H33: 0 | I33: 0 | J33: =IFERROR(SUM(G33:I33)/3/F33,"－") -> － | K33: 0 | L33: =IFERROR(K33/F33,"－") -> － | M33: 0 | N33: =IFERROR(M33/F33,"－") -> － | O33: 0 | P33: =IFERROR(O33/F33,"－") -> － | Q33: 0 | R33: =IFERROR(Q33/F33,"－") -> － | S33: 0 | T33: =IFERROR(S33/F33,"－") -> －
C34: 人数（人） | D34: 0.5 | E34: 0.083333333 | F34: 0 | G34: 0 | H34: 0 | I34: 0 | J34: =IFERROR(SUM(G34:I34)/3/F34,"－") -> － | K34: 0 | L34: =IFERROR(K34/F34,"－") -> － | M34: 0 | N34: =IFERROR(M34/F34,"－") -> － | O34: 0 | P34: =IFERROR(O34/F34,"－") -> － | Q34: 0 | R34: =IFERROR(Q34/F34,"－") -> － | S34: 0 | T34: =IFERROR(S34/F34,"－") -> －
B35: 介護予防短期入所療養介護（病院等） | C35: 給付費（千円） | D35: 0 | E35: 0 | F35: 0 | G35: 0 | H35: 0 | I35: 0 | J35: =IFERROR(SUM(G35:I35)/3/F35,"－") -> － | K35: 0 | L35: =IFERROR(K35/F35,"－") -> － | M35: 0 | N35: =IFERROR(M35/F35,"－") -> － | O35: 0 | P35: =IFERROR(O35/F35,"－") -> － | Q35: 0 | R35: =IFERROR(Q35/F35,"－") -> － | S35: 0 | T35: =IFERROR(S35/F35,"－") -> －
C36: 日数（日） | D36: 0 | E36: 0 | F36: 0 | G36: 0 | H36: 0 | I36: 0 | J36: =IFERROR(SUM(G36:I36)/3/F36,"－") -> － | K36: 0 | L36: =IFERROR(K36/F36,"－") -> － | M36: 0 | N36: =IFERROR(M36/F36,"－") -> － | O36: 0 | P36: =IFERROR(O36/F36,"－") -> － | Q36: 0 | R36: =IFERROR(Q36/F36,"－") -> － | S36: 0 | T36: =IFERROR(S36/F36,"－") -> －
C37: 人数（人） | D37: 0 | E37: 0 | F37: 0 | G37: 0 | H37: 0 | I37: 0 | J37: =IFERROR(SUM(G37:I37)/3/F37,"－") -> － | K37: 0 | L37: =IFERROR(K37/F37,"－") -> － | M37: 0 | N37: =IFERROR(M37/F37,"－") -> － | O37: 0 | P37: =IFERROR(O37/F37,"－") -> － | Q37: 0 | R37: =IFERROR(Q37/F37,"－") -> － | S37: 0 | T37: =IFERROR(S37/F37,"－") -> －
B38: 介護予防短期入所療養介護(介護医療院) | C38: 給付費（千円） | D38: 0 | E38: 0 | F38: 0 | G38: 0 | H38: 0 | I38: 0 | J38: =IFERROR(SUM(G38:I38)/3/F38,"－") -> － | K38: 0 | L38: =IFERROR(K38/F38,"－") -> － | M38: 0 | N38: =IFERROR(M38/F38,"－") -> － | O38: 0 | P38: =IFERROR(O38/F38,"－") -> － | Q38: 0 | R38: =IFERROR(Q38/F38,"－") -> － | S38: 0 | T38: =IFERROR(S38/F38,"－") -> －
C39: 日数（日） | D39: 0 | E39: 0 | F39: 0 | G39: 0 | H39: 0 | I39: 0 | J39: =IFERROR(SUM(G39:I39)/3/F39,"－") -> － | K39: 0 | L39: =IFERROR(K39/F39,"－") -> － | M39: 0 | N39: =IFERROR(M39/F39,"－") -> － | O39: 0 | P39: =IFERROR(O39/F39,"－") -> － | Q39: 0 | R39: =IFERROR(Q39/F39,"－") -> － | S39: 0 | T39: =IFERROR(S39/F39,"－") -> －
C40: 人数（人） | D40: 0 | E40: 0 | F40: 0 | G40: 0 | H40: 0 | I40: 0 | J40: =IFERROR(SUM(G40:I40)/3/F40,"－") -> － | K40: 0 | L40: =IFERROR(K40/F40,"－") -> － | M40: 0 | N40: =IFERROR(M40/F40,"－") -> － | O40: 0 | P40: =IFERROR(O40/F40,"－") -> － | Q40: 0 | R40: =IFERROR(Q40/F40,"－") -> － | S40: 0 | T40: =IFERROR(S40/F40,"－") -> －
B41: 介護予防福祉用具貸与 | C41: 給付費（千円） | D41: 2636.495 | E41: 3245.792 | F41: 3974.172 | G41: 3974 | H41: 3872 | I41: 3918 | J41: =IFERROR(SUM(G41:I41)/3/F41,"－") -> 0.98670448 | K41: 3872 | L41: =IFERROR(K41/F41,"－") -> 0.974291 | M41: 4122 | N41: =IFERROR(M41/F41,"－") -> 1.0371972 | O41: 4371 | P41: =IFERROR(O41/F41,"－") -> 1.0998517 | Q41: 4122 | R41: =IFERROR(Q41/F41,"－") -> 1.0371972 | S41: 3669 | T41: =IFERROR(S41/F41,"－") -> 0.92321117
C42: 人数（人） | D42: 33.166667 | E42: 36.666667 | F42: 44 | G42: 44 | H42: 43 | I42: 44 | J42: =IFERROR(SUM(G42:I42)/3/F42,"－") -> 0.99242424 | K42: 43 | L42: =IFERROR(K42/F42,"－") -> 0.97727273 | M42: 46 | N42: =IFERROR(M42/F42,"－") -> 1.0454545 | O42: 49 | P42: =IFERROR(O42/F42,"－") -> 1.1136364 | Q42: 46 | R42: =IFERROR(Q42/F42,"－") -> 1.0454545 | S42: 41 | T42: =IFERROR(S42/F42,"－") -> 0.93181818
...

Sheet 3_地域支援事業費
A1: （３）地域支援事業費
K3: 保険者名 | L3: =保険者名 -> 川崎町
K4: 保険者番号 | L4: =保険者番号 -> 04324
K5: 推計パターン名 | L5: =推計パターン名 -> 0911
L6: 単位：円(括弧書きの数値を除く)
A7: １．介護予防・日常生活支援総合事業 | B7: 第9期 | E7: 第10期 | H7: 第11期 | I7: 第12期 | J7: 第14期 | K7: 第16期 | L7: 第17期
A8: サービス種別・項目 | B8: 令和6年度 | C8: 令和7年度 | D8: 令和8年度 | E8: 令和9年度 | F8: 令和10年度 | G8: 令和11年度 | H8: 令和12年度 | I8: 令和17年度 | J8: 令和22年度 | K8: 令和27年度 | L8: 令和32年度
A9: 訪問介護相当サービス | B9: 1395761 | C9: 2668301 | D9: 2400000 | E9: 2100000 | F9: 2100000 | G9: 2100000 | H9: 1953000 | I9: 1806000 | J9: 1659000 | K9: 1449000 | L9: 1302000
A10: (利用者数：人) | B10: 417 | C10: 398 | D10: 400 | E10: 395 | F10: 395 | G10: 395 | H10: 381 | I10: 353 | J10: 327 | K10: 296 | L10: 264
A11: 訪問型サービスA | B11: 0 | C11: 0 | D11: 0 | E11: 0 | F11: 0 | G11: 0 | H11: 0 | I11: 0 | J11: 0 | K11: 0 | L11: 0
A12: (利用者数：人) | B12: 0 | C12: 0 | D12: 0 | E12: 0 | F12: 0 | G12: 0 | H12: 0 | I12: 0 | J12: 0 | K12: 0 | L12: 0
A13: 訪問型サービスB | B13: 340500 | C13: 314100 | D13: 600000 | E13: 400000 | F13: 400000 | G13: 400000 | H13: 464000 | I13: 488000 | J13: 460000 | K13: 404000 | L13: 368000
A14: 訪問型サービスC | B14: 0 | C14: 0 | D14: 0 | E14: 0 | F14: 0 | G14: 0 | H14: 0 | I14: 0 | J14: 0 | K14: 0 | L14: 0
A15: 訪問型サービスD | B15: 0 | C15: 0 | D15: 0 | E15: 0 | F15: 0 | G15: 0 | H15: 0 | I15: 0 | J15: 0 | K15: 0 | L15: 0
A16: 訪問型サービス(その他) | B16: 0 | C16: 0 | D16: 0 | E16: 0 | F16: 0 | G16: 0 | H16: 0 | I16: 0 | J16: 0 | K16: 0 | L16: 0
A17: 通所介護相当サービス | B17: 4544841 | C17: 2646409 | D17: 5187000 | E17: 4200000 | F17: 4200000 | G17: 4200000 | H17: 3906000 | I17: 3612000 | J17: 3318000 | K17: 2898000 | L17: 2604000
A18: (利用者数：人) | B18: 706 | C18: 638 | D18: 640 | E18: 635 | F18: 635 | G18: 635 | H18: 609 | I18: 565 | J18: 524 | K18: 473 | L18: 423
A19: 通所型サービスA | B19: 0 | C19: 0 | D19: 0 | E19: 0 | F19: 0 | G19: 0 | H19: 0 | I19: 0 | J19: 0 | K19: 0 | L19: 0
A20: (利用者数：人) | B20: 0 | C20: 0 | D20: 0 | E20: 0 | F20: 0 | G20: 0 | H20: 0 | I20: 0 | J20: 0 | K20: 0 | L20: 0
... A34: 地域リハビリテーション活動支援事業 | B34: 0 | C34: 0 | D34: 0 | E34: 0 | F34: 0 | G34: 0 | H34: 0 | I34: 0 | J34: 0 | K34: 0 | L34: 0
A35: 介護予防・地域ささえあいサポート拠点事業 | E35: 0 | F35: 0 | G35: 0 | H35: 0 | I35: 0 | J35: 0 | K35: 0 | L35: 0
L36: 単位：円
A37: ２．包括的支援事業（地域包括支援センターの運営）及び任意事業 | B37: 第9期 | E37: 第10期 | H37: 第11期 | I37: 第12期 | J37: 第14期 | K37: 第16期 | L37: 第17期
A38: サービス種別・項目 | B38: 令和6年度 | C38: 令和7年度 | D38: 令和8年度 | E38: 令和9年度 | F38: 令和10年度 | G38: 令和11年度 | H38: 令和12年度 | I38: 令和17年度 | J38: 令和22年度 | K38: 令和27年度 | L38: 令和32年度
A39: 包括的支援事業(地域包括支援センターの運営) | B39: 11031753 | C39: 8308039 | D39: 8791803 | E39: 9300000 | F39: 9300000 | G39: 9300000 | H39: 8500273 | I39: 8008990 | J39: 7652675 | K39: 7123601 | L39: 6732194
A40: 任意事業 | B40: 4519729 | C40: 3612985 | D40: 7485000 | E40: 5200000 | F40: 5200000 | G40: 5200000 | H40: 7236802 | I40: 6818543 | J40: 6515190 | K40: 6064757 | L40: 5731529
L41: 単位：円
A42: ３．包括的支援事業（社会保障充実分） | B42: 第9期 | E42: 第10期 | H42: 第11期 | I42: 第12期 | J42: 第14期 | K42: 第16期 | L42: 第17期
A43: サービス種別・項目 | B43: 令和6年度 | C43: 令和7年度 | D43: 令和8年度 | E43: 令和9年度 | F43: 令和10年度 | G43: 令和11年度 | H43: 令和12年度 | I43: 令和17年度 | J43: 令和22年度 | K43: 令和27年度 | L43: 令和32年度
A44: 在宅医療・介護連携推進事業 | B44: 2242541 | C44: 2646068 | D44: 2616855 | E44: 2500000 | F44: 2500000 | G44: 2500000 | H44: 2616855 | I44: 2616855 | J44: 2616855 | K44: 2616855 | L44: 2616855
A45: 生活支援体制整備事業 | B45: 2254541 | C45: 2615701 | D45: 2593855 | E45: 2480000 | F45: 2480000 | G45: 2480000 | H45: 2593855 | I45: 2593855 | J45: 2593855 | K45: 2593855 | L45: 2593855
A46: 認知症初期集中支援推進事業 | B46: 1451594 | C46: 1703079 | D46: 2362928 | E46: 1839000 | F46: 1839000 | G46: 1839000 | H46: 2362928 | I46: 2362928 | J46: 2362928 | K46: 2362928 | L46: 2362928
A47: 認知症地域支援・ケア向上事業 | B47: 2110977 | C47: 2337705 | D47: 1941926 | E47: 2130000 | F47: 2130000 | G47: 2130000 | H47: 1941926 | I47: 1941926 | J47: 1941926 | K47: 1941926 | L47: 1941926
A48: 認知症サポーター活動促進・地域づくり推進事業 | B48: 0 | C48: 0 | D48: 0 | E48: 0 | F48: 0 | G48: 0 | H48: 0 | I48: 0 | J48: 0 | K48: 0 | L48: 0
A49: 地域ケア会議推進事業 | B49: 1081600 | C49: 1187860 | D49: 1405951 | E49: 1220000 | F49: 1220000 | G49: 1220000 | H49: 1405951 | I49: 1405951 | J49: 1405951 | K49: 1405951 | L49: 1405951
L50: 単位：円
A51: ４．特定地域居宅サービス等事業 | B51: 第9期 | E51: 第10期 | H51: 第11期 | I51: 第12期 | J51: 第14期 | K51: 第16期 | L51: 第17期
A52: サービス種別・項目 | B52: 令和6年度 | C52: 令和7年度 | D52: 令和8年度 | E52: 令和9年度 | F52: 令和10年度 | G52: 令和11年度 | H52: 令和12年度 | I52: 令和17年度 | J52: 令和22年度 | K52: 令和27年度 | L52: 令和32年度
A53: 特定地域居宅サービス等事業 | E53: 0 | F53: 0 | G53: 0 | H53: 0 | I53: 0 | J53: 0 | K53: 0 | L53: 0
L54: 単位：円
...

Sheet 4_施策反映の解説
A1: （４）施策反映の内容
K2: 出力日： | L2: ='1_推計値サマリ'!T2 -> 2026/10/19
I3: 保険者名 | K3: =保険者名 -> 川崎町
I4: 保険者番号 | K4: =保険者番号 -> 04324
I5: 推計パターン名 | K5: =推計パターン名 -> 0911
A7: 施策反映の全体方針
A8: 出力後に入力
A9: １．自然体推計手法
A10: 認定者数の自然体推計手法 | B10: 性別／年齢５歳階級別／要介護度別に推計する ※初期値
A11: 介護サービス利用者数の自然体推計手法 | B11: サービス別／要介護度別に推計する ※初期値
A12: ２．要介護(支援)認定者数
A13: 推計に用いた認定率の伸び | B13: 当該市町村における令和６年度→令和７年度の伸び
B14: 認定者数の設定内容
A15: 認定者数
B17: 施策反映内容
A18: 認定者数
A19: ３．施設・居住系サービス利用者数
A20: 推計に用いた利用率の伸び | B20: 当該市町村における令和６年度→令和７年度の伸び
A21: 推計に用いた1人1月あたりの給付費の実績値 | B21: 令和8年度
B22: 給付費の設定内容
A23: 1人1月あたり給付費
B24: 利用者数の設定内容
A25: 施設・居住系サービス利用者数
B26: 施策反映内容
A27: （１）居宅サービス
A28: （２）地域密着型サービス
A29: （３）施設サービス
A30: ４．在宅サービス利用者数
A31: 推計に用いた利用率の伸び | B31: 当該市町村における令和６年度→令和７年度の伸び
A32: 推計に用いた1人1月あたり利用回（日）数の伸び | B32: 当該市町村における令和６年度→令和７年度の伸び
A33: 推計に用いた1人1月あたりの給付費の実績値 | B33: 令和8年度
B34: 利用者数の設定内容
A35: 在宅サービス利用者数
B36: 利用回(日)数の設定内容
A37: 在宅サービス利用回(日)数
B38: 給付費の設定内容
A39: 1人1月あたり給付費
B40: 施策反映内容
A41: 在宅サービス利用者数(利用率)
A42: 在宅サービス利用回(日)数
...

Sheet 5_保険料推計
A1: （５）第１号被保険者の保険料推計
P3: 保険者名 | Q3: =保険者名 -> 川崎町
P4: 保険者番号 | Q4: =保険者番号 -> 04324
P5: 推計パターン名 | Q5: =推計パターン名 -> 0911
A7: １．９期保険料基準額
A8: 第９期保険料の基準額（月額） | F8: 6508.3306
A10: ２．保険料基準額の指標 | F10: 第10期 | G10: 第11期 | H10: 第12期 | I10: 第14期 | J10: 第16期 | K10: 第17期
G11: 令和12年度 | H11: 令和17年度 | I11: 令和22年度 | J11: 令和27年度 | K11: 令和32年度
A12: 保険料基準額（月額） | F12: =F105/F106/F254/12 -> 7146.9002 | G12: =J105/J106/J254/12 -> 8262.7727 | H12: =K105/K106/K254/12 -> 8925.3795 | I12: =L105/L106/L254/12 -> 9207.0871 | J12: =M105/M106/M254/12 -> 9635.8792 | K12: =N105/N106/N254/12 -> 10180.306
A13: 準備基金取崩額の影響額 | F13: =(F105+F15)/F106/F254/12-F12 -> 0 | G13: =(J105+G15)/J106/J254/12-G12 -> 0 | H13: =(K105+H15)/K106/K254/12-H12 -> 0 | I13: =(L105+I15)/L106/L254/12-I12 -> 0 | J13: =(M105+J15)/M106/M254/12-J12 -> 0 | K13: =(N105+K15)/N106/N254/12-K12 -> 0
B14: 準備基金の残高（前年度末の見込額） | F14: 152500000 | G14: 0 | H14: 0 | I14: 0 | J14: 0 | K14: 0
B15: 準備基金取崩額 | F15: 0 | G15: 0 | H15: 0 | I15: 0 | J15: 0 | K15: 0
B16: 準備基金取崩割合 | F16: =IF(F14=0,0, F15/F14) -> 0 | G16: =IF(G14=0,0,G15/G14) -> 0 | H16: =IF(H14=0,0,H15/H14) -> 0 | I16: =IF(I14=0,0,I15/I14) -> 0 | J16: =IF(J14=0,0,J15/J14) -> 0 | K16: =IF(K14=0,0,K15/K14) -> 0
A17: 財政安定化基金拠出金見込額の影響額 | F17: =F12-(F105-F18)/F106/F254/12 -> 0 | G17: =G12-(J105-G18)/J106/J254/12 -> 0 | H17: =H12-(K105-H18)/K106/K254/12 -> 0 | I17: =I12-(L105-I18)/L106/L254/12 -> 0 | J17: =J12-(M105-J18)/M106/M254/12 -> 0 | K17: =K12-(N105-K18)/N106/N254/12 -> 0
B18: 財政安定化基金拠出金見込額 | F18: =(F68+F86)*F19 -> 0 | G18: =(J68+J86)*G19 -> 0 | H18: =(K68+K86)*H19 -> 0 | I18: =(L68+L86)*I19 -> 0 | J18: =(M68+M86)*J19 -> 0 | K18: =(N68+N86)*K19 -> 0
B19: 財政安定化基金拠出率 | F19: 0 | G19: 0 | H19: 0 | I19: 0 | J19: 0 | K19: 0
A20: 財政安定化基金償還金の影響額 | F20: =F12-(F105-F21)/F106/F254/12 -> 0 | G20: =G12-(J105-G21)/J106/J254/12 -> 0 | H20: =H12-(K105-H21)/K106/K254/12 -> 0 | I20: =I12-(L105-I21)/L106/L254/12 -> 0 | J20: =J12-(M105-J21)/M106/M254/12 -> 0 | K20: =K12-(N105-K21)/N106/N254/12 -> 0
B21: 財政安定化基金償還金 | F21: 0 | G21: 0 | H21: 0 | I21: 0 | J21: 0 | K21: 0
A22: 保険料基準額の伸び率（％） （対９期保険料） | F22: =F12/$F$8-1 -> 0.098115726 | G22: =G12/ROUND($F$8,0)-1 -> 0.26963317 | H22: =H12/ROUND($F$8,0)-1 -> 0.37144738 | I22: =I12/ROUND($F$8,0)-1 -> 0.41473373 | J22: =J12/ROUND($F$8,0)-1 -> 0.48062065 | K22: =K12/ROUND($F$8,0)-1 -> 0.56427572
A24: ３．保険料設定を弾力化した場合の保険料額の指標 | F24: 第10期 | G24: 第11期 | H24: 第12期 | I24: 第14期 | J24: 第16期 | K24: 第17期
G25: 令和12年度 | H25: 令和17年度 | I25: 令和22年度 | J25: 令和27年度 | K25: 令和32年度
A26: 保険料基準額（月額） | F26: =IFERROR(F105/F106/F255/12,"－") -> － | G26: =IFERROR(J105/J106/J255/12,"－") -> － | H26: =IFERROR(K105/K106/K255/12,"－") -> － | I26: =IFERROR(L105/L106/L255/12,"－") -> － | J26: =IFERROR(M105/M106/M255/12,"－") -> － | K26: =IFERROR(N105/N106/N255/12,"－") -> －
A27: 準備基金取崩額の影響額 | F27: =IFERROR((F105+F29)/F106/F255/12-F26,"－") -> － | G27: =IFERROR((J105+G29)/J106/J255/12-G26,"－") -> － | H27: =IFERROR((K105+H29)/K106/K255/12-H26,"－") -> － | I27: =IFERROR((L105+I29)/L106/L255/12-I26,"－") -> － | J27: =IFERROR((M105+J29)/M106/M255/12-J26,"－") -> － | K27: =IFERROR((N105+K29)/N106/N255/12-K26,"－") -> －
B28: 準備基金の残高（前年度末の見込額） | F28: =IF(F26="－","－",F14) -> － | G28: =IF(G26="－","－",G14) -> － | H28: =IF(H26="－","－",H14) -> － | I28: =IF(I26="－","－",I14) -> － | J28: =IF(J26="－","－",J14) -> － | K28: =IF(K26="－","－",K14) -> －
B29: 準備基金取崩額 | F29: =IF(F26="－","－",F15) -> － | G29: =IF(G26="－","－",G15) -> － | H29: =IF(H26="－","－",H15) -> － | I29: =IF(I26="－","－",I15) -> － | J29: =IF(J26="－","－",J15) -> － | K29: =IF(K26="－","－",K15) -> －
B30: 準備基金取崩割合 | F30: =IFERROR(F29/F28,"－") -> － | G30: =IFERROR(G29/G28,"－") -> － | H30: =IFERROR(H29/H28,"－") -> － | I30: =IFERROR(I29/I28,"－") -> － | J30: =IFERROR(J29/J28,"－") -> － | K30: =IFERROR(K29/K28,"－") -> －
A31: 財政安定化基金拠出金見込額の影響額 | F31: =IFERROR(F26-(F105-F32)/F106/F255/12,"－") -> － | G31: =IFERROR(G26-(J105-G32)/J106/J255/12,"－") -> － | H31: =IFERROR(H26-(K105-H32)/K106/K255/12,"－") -> － | I31: =IFERROR(I26-(L105-I32)/L106/L255/12,"－") -> － | J31: =IFERROR(J26-(M105-J32)/M106/M255/12,"－") -> － | K31: =IFERROR(K26-(N105-K32)/N106/N255/12,"－") -> －
B32: 財政安定化基金拠出金見込額 | F32: =IF(F26="－","－",(F68+F86)*F33) -> － | G32: =IF(G26="－","－",(J68+J86)*G33) -> － | H32: =IF(H26="－","－",(K68+K86)*H33) -> － | I32: =IF(I26="－","－",(L68+L86)*I33) -> － | J32: =IF(J26="－","－",(M68+M86)*J33) -> － | K32: =IF(K26="－","－",(N68+N86)*K33) -> －
B33: 財政安定化基金拠出率 | F33: =IF(F26="－","－",F19) -> － | G33: =IF(G26="－","－",G19) -> － | H33: =IF(H26="－","－",H19) -> － | I33: =IF(I26="－","－",I19) -> － | J33: =IF(J26="－","－",J19) -> － | K33: =IF(K26="－","－",K19) -> －
A34: 財政安定化基金償還金の影響額 | F34: =IFERROR(F26-(F105-F35)/F106/F255/12,"－") -> － | G34: =IFERROR(G26-(J105-G35)/J106/J255/12,"－") -> － | H34: =IFERROR(H26-(K105-H35)/K106/K255/12,"－") -> － | I34: =IFERROR(I26-(L105-I35)/L106/L255/12,"－") -> － | J34: =IFERROR(J26-(M105-J35)/M106/M255/12,"－") -> － | K34: =IFERROR(K26-(N105-K35)/N106/N255/12,"－") -> －
B35: 財政安定化基金償還金 | F35: =IF(F26="－","－",F21) -> － | G35: =IF(G26="－","－",G21) -> － | H35: =IF(H26="－","－",H21) -> － | I35: =IF(I26="－","－",I21) -> － | J35: =IF(J26="－","－",J21) -> － | K35: =IF(K26="－","－",K21) -> －
A36: 保険料基準額の伸び率（％） （対９期保険料） | F36: =IFERROR(F26/$F$8-1,"－") -> － | G36: =IFERROR(G26/ROUND($F$8,0)-1,"－") -> － | H36: =IFERROR(H26/ROUND($F$8,0)-1,"－") -> － | I36: =IFERROR(I26/ROUND($F$8,0)-1,"－") -> － | J36: =IFERROR(J26/ROUND($F$8,0)-1,"－") -> － | K36: =IFERROR(K26/ROUND($F$8,0)-1,"－") -> －
A38: ４ 介護保険料基準額（月額）の内訳 | F38: 金額 | L38: 構成比
F39: 第10期 | G39: 第11期 | H39: 第12期 | I39: 第14期 | J39: 第16期 | K39: 第17期 | L39: 第10期 | M39: 第11期 | N39: 第12期 | O39: 第14期 | P39: 第16期 | Q39: 第17期
G40: 令和12年度 | H40: 令和17年度 | I40: 令和22年度 | J40: 令和27年度 | K40: 令和32年度 | M40: 令和12年度 | N40: 令和17年度 | O40: 令和22年度 | P40: 令和27年度 | Q40: 令和32年度
A41: 総給付費 | F41: =(F69*'(参考)保険料の推計に要する係数'!D5+(F93-F94))/(F254*F106*12) -> 6448.1366 | G41: =(J69*'(参考)保険料の推計に要する係数'!E5+(J93-J94))/(J254*J106*12) -> 7450.7586 | H41: =(K69*'(参考)保険料の推計に要する係数'!F5+(K93-K94))/(K254*K106*12) -> 7978.11 | I41: =(L69*'(参考)保険料の推計に要する係数'!G5+(L93-L94))/(L254*L106*12) -> 8117.647 | J41: =(M69*'(参考)保険料の推計に要する係数'!H5+(M93-M94))/(M254*M106*12) -> 8462.9561 | K41: =(N69*'(参考)保険料の推計に要する係数'!I5+(N93-N94))/(N254*N106*12) -> 9013.8084 | L41: =F41/$F$49 -> 0.90222845 | M41: =G41/$G$49 -> 0.9017262 | N41: =H41/$H$49 -> 0.89386787 | O41: =I41/$I$49 -> 0.88167375 | P41: =J41/$J$49 -> 0.87827545 | Q41: =K41/$K$49 -> 0.88541622
B42: 在宅サービス | F42: =$F$41*SUM('2_サービス別給付費'!G151:I151)/SUM('2_サービス別給付費'!$G$150:$I$150) -> 1994.2502 | G42: =$G$41*SUM('2_サービス別給付費'!J151)/SUM('2_サービス別給付費'!$J$150) -> 2121.5169 | H42: =$H$41*SUM('2_サービス別給付費'!K151)/SUM('2_サービス別給付費'!$K$150) -> 2292.2384 | I42: =$I$41*SUM('2_サービス別給付費'!L151)/SUM('2_サービス別給付費'!$L$150) -> 2315.2524 | J42: =$J$41*SUM('2_サービス別給付費'!M151)/SUM('2_サービス別給付費'!$M$150) -> 2336.4491 | K42: =$K$41*SUM('2_サービス別給付費'!N151)/SUM('2_サービス別給付費'!$N$150) -> 2527.8305 | L42: =F42/$F$49 -> 0.27903709 | M42: =G42/$G$49 -> 0.25675605 | N42: =H42/$H$49 -> 0.25682252 | O42: =I42/$I$49 -> 0.25146415 | P42: =J42/$J$49 -> 0.24247389 | Q42: =K42/$K$49 -> 0.24830593
B43: 居住系サービス | F43: =$F$41*SUM('2_サービス別給付費'!G152:I152)/SUM('2_サービス別給付費'!$G$150:$I$150) -> 431.59814 | G43: =$G$41*SUM('2_サービス別給付費'!J152)/SUM('2_サービス別給付費'!$J$150) -> 484.78542 | H43: =$H$41*SUM('2_サービス別給付費'!K152)/SUM('2_サービス別給付費'!$K$150) -> 556.62182 | I43: =$I$41*SUM('2_サービス別給付費'!L152)/SUM('2_サービス別給付費'!$L$150) -> 537.44365 | J43: =$J$41*SUM('2_サービス別給付費'!M152)/SUM('2_サービス別給付費'!$M$150) -> 562.53711 | K43: =$K$41*SUM('2_サービス別給付費'!N152)/SUM('2_サービス別給付費'!$N$150) -> 558.38459 | L43: =F43/$F$49 -> 0.060389558 | M43: =G43/$G$49 -> 0.058671034 | N43: =H43/$H$49 -> 0.062363939 | O43: =I43/$I$49 -> 0.058372821 | P43: =J43/$J$49 -> 0.058379427 | Q43: =K43/$K$49 -> 0.054849488
B44: 施設サービス | F44: =$F$41*SUM('2_サービス別給付費'!G153:I153)/SUM('2_サービス別給付費'!$G$150:$I$150) -> 4022.2882 | G44: =$G$41*SUM('2_サービス別給付費'!J153)/SUM('2_サービス別給付費'!$J$150) -> 4844.4563 | H44: =$H$41*SUM('2_サービス別給付費'!K153)/SUM('2_サービス別給付費'!$K$150) -> 5129.2497 | I44: =$I$41*SUM('2_サービス別給付費'!L153)/SUM('2_サービス別給付費'!$L$150) -> 5264.951 | J44: =$J$41*SUM('2_サービス別給付費'!M153)/SUM('2_サービス別給付費'!$M$150) -> 5563.9699 | K44: =$K$41*SUM('2_サービス別給付費'!N153)/SUM('2_サービス別給付費'!$N$150) -> 5927.5933 | L44: =F44/$F$49 -> 0.5628018 | M44: =G44/$G$49 -> 0.58629912 | N44: =H44/$H$49 -> 0.57468142 | O44: =I44/$I$49 -> 0.57183678 | P44: =J44/$J$49 -> 0.57742213 | Q44: =K44/$K$49 -> 0.5822608
A45: その他給付費 | F45: =((F75+F78+F81+F82)*'(参考)保険料の推計に要する係数'!D5+F85)/(F254*F106*12) -> 520.25708 | G45: =((J75+J78+J81+J82)*'(参考)保険料の推計に要する係数'!E5+J85)/(J254*J106*12) -> 587.02295 | H45: =((K75+K78+K81+K82)*'(参考)保険料の推計に要する係数'!F5+K85)/(K254*K106*12) -> 703.09357 | I45: =((L75+L78+L81+L82)*'(参考)保険料の推計に要する係数'!G5+L85)/(L254*L106*12) -> 833.1596 | J45: =((M75+M78+M81+M82)*'(参考)保険料の推計に要する係数'!H5+M85)/(M254*M106*12) -> 904.98007 | K45: =((N75+N78+N81+N82)*'(参考)保険料の推計に要する係数'!I5+N85)/(N254*N106*12) -> 883.82016 | L45: =F45/$F$49 -> 0.072794787 | M45: =G45/$G$49 -> 0.071044306 | N45: =H45/$H$49 -> 0.078774642 | O45: =I45/$I$49 -> 0.090491118 | P45: =J45/$J$49 -> 0.093917748 | Q45: =K45/$K$49 -> 0.086816656
...

Sheet (参考)保険料の推計に要する係数
B1: (参考)保険料の推計に要する係数
D3: 第10期 | E3: 第11期 | F3: 第12期 | G3: 第14期 | H3: 第16期 | I3: 第17期
D4: 令和9～11年度 | E4: 令和12年度 | F4: 令和17年度 | G4: 令和22年度 | H4: 令和27年度 | I4: 令和32年度
C5: 第１号被保険者負担割合（%） | D5: 0.23 | E5: 0.24 | F5: 0.25 | G5: 0.26 | H5: 0.27 | I5: 0.28
B7: 後期高齢者加入割合補正係数の算出に係る係数（全国値） （仮置値） | D7: 第10期 | G7: 第11期 | H7: 第12期 | I7: 第14期 | J7: 第16期 | K7: 第17期
D8: 令和9年度 | E8: 令和10年度 | F8: 令和11年度 | G8: 令和12年度 | H8: 令和17年度 | I8: 令和22年度 | J8: 令和27年度 | K8: 令和32年度
C9: 前期高齢者加入割合 | D9: 0.4312 | E9: 0.4166 | F9: 0.4076 | G9: 0.3946 | H9: 0.4156 | I9: 0.4449 | J9: 0.4377 | K9: 0.4062
C10: 85歳未満後期高齢者加入割合 | D10: 0.3825 | E10: 0.3924 | F10: 0.3951 | G10: 0.3898 | H10: 0.333 | I10: 0.3103 | J10: 0.3328 | K10: 0.3669
C11: 85歳以上後期高齢者加入割合 | D11: 0.1863 | E11: 0.191 | F11: 0.1973 | G11: 0.2157 | H11: 0.2513 | I11: 0.2448 | J11: 0.2295 | K11: 0.227
C12: 前期高齢者の1人あたり給付費 | D12: 4296 | E12: 4296 | F12: 4296 | G12: 4296 | H12: 4296 | I12: 4296 | J12: 4296 | K12: 4296
C13: 85歳未満後期高齢者の1人あたり給付費 | D13: 17647 | E13: 17647 | F13: 17647 | G13: 17647 | H13: 17647 | I13: 17647 | J13: 17647 | K13: 17647
C14: 85歳以上後期高齢者の1人あたり給付費 | D14: 80362 | E14: 80362 | F14: 80362 | G14: 80362 | H14: 80362 | I14: 80362 | J14: 80362 | K14: 80362
B16: 所得段階別加入割合補正係数の算出に係る係数（全国値）（％） （仮置値）
C17: 第1段階 | D17: 0.1749
C18: 第2段階 | D18: 0.0967
C19: 第3段階 | D19: 0.0864
C20: 第4段階 | D20: 0.1074
C21: 第5段階 | D21: 0.1405
C22: 第6段階 | D22: 0.1333
C23: 第7段階 | D23: 0.1361
C24: 第8段階 | D24: 0.061
C25: 第9段階 | D25: 0.0241
C26: 第10段階 | D26: 0.0115
C27: 第11段階 | D27: 0.0061
C28: 第12段階 | D28: 0.0039
C29: 第13段階 | D29: 0.0181
B43: 費用負担の見直しに伴う調整に係る係数（参考値）（未定）
C44: 利用者負担の見直し等に伴う財政影響補正係数 | D44: 1
C45: 特定入所者介護サービス費等に係る制度改正に伴う財政影響補正係数 | D45: 1
C48: 国庫負担金等の算定の基準となる算定対象審査支払手数料単価（上限）（円） | D48: 95
