Workbook

Sheet 表紙・使い方
A1: 小野町 第8期障がい福祉計画・第4期障がい児福祉計画 見込量・目標値設定シート
A4: 計画期間：令和9年度～令和11年度
A7: 作成方針 | B7: 小野町ワークシートに入力された人口・R5～R8実績を基礎に、R9～R11の必要見込量と成果目標を設定します。
A8: 見込量の考え方 | B8: 小規模自治体では0→1人等で伸び率が過大になりやすいため、単純CAGRではなく「横ばい・直近平均・線形トレンド・人口比率・政策調整」を使い分けています。
A9: R8実績の扱い | B9: 元ワークシートにR8実績が入力されているため、阿蘇市フォーマットを拡張し、R8を最新実績として算定に反映しています。
A10: 黄色セル | B10: 不足している基準値・実績値や政策調整値の入力欄です。
A11: 緑色セル | B11: 小野町の政策的な初期設定値です。必要に応じて上書きしてください。
A12: 重要 | B12: 成果目標は令和8年3月31日告示の国基本指針を基準に設定しています。厚生労働省は令和8年10月の基本指針改正を予定しているため、計画確定前に最新版を再確認してください。
A14: シート | B14: 用途
A15: 人口基礎データ | B15: 人口・年齢3区分・障害者手帳所持者数の実績／推計
A16: 見込量算定(障害福祉)・(障害児) | B16: R5～R8実績からR9～R11見込量を算定。算定方法・政策値は変更可能
A17: 成果目標算定・確認事項 | B17: 国基本指針の成果目標と、小野町で追加確認が必要な事項
A19: 参考URL | B19: 内容
A20: https://www.mhlw.go.jp/stf/newpage_72187.html | B20: 厚生労働省「第8期障害福祉計画について」
A21: https://www.mhlw.go.jp/web/t_doc?dataId=83ac0954&dataType=0&pageNo=1 | B21: 令和8年3月31日 基本指針（こども家庭庁・厚生労働省告示第4号）

Sheet 人口基礎データ
A1: 小野町 人口基礎データ（R5～R11）
A2: ※R5～R8はワークシート入力値、R9～R11はワークシートの人口推計値を採用。障害児サービスの人口比率型では、入手可能な年少人口「0～14歳」を算定基礎として使用します。
A5: 区分 | B5: 単位 | C5: R5 | D5: R6 | E5: R7 | F5: R8 | G5: R9 | H5: R10 | I5: R11 | J5: R7→R11増減 | K5: 増減率 | L5: 備考
A6: 総人口 | B6: 人 | C6: 9372 | D6: 9116 | E6: 8740 | F6: 8520 | G6: 8287 | H6: 8076 | I6: 7830 | J6: =I6-E6 -> -910 | K6: =IFERROR(I6/E6-1,0) -> -0.10411899 | L6: 小野町ワークシート人口推計
A7: 0～14歳人口 | B7: 人 | C7: 884 | D7: 809 | E7: 732 | F7: 679 | G7: 624 | H7: 584 | I7: 517 | J7: =I7-E7 -> -215 | K7: =IFERROR(I7/E7-1,0) -> -0.29371585 | L7: 障害児サービスの人口比率型に使用
A8: 15～64歳人口 | B8: 人 | C8: 4986 | D8: 4814 | E8: 4525 | F8: 4382 | G8: 4203 | H8: 4040 | I8: 3891 | J8: =I8-E8 -> -634 | K8: =IFERROR(I8/E8-1,0) -> -0.1401105
A9: 65歳以上人口 | B9: 人 | C9: 3502 | D9: 3493 | E9: 3483 | F9: 3459 | G9: 3460 | H9: 3452 | I9: 3422 | J9: =I9-E9 -> -61 | K9: =IFERROR(I9/E9-1,0) -> -0.017513638
A10: 身体障害者手帳所持者数 | B10: 人 | C10: 412 | D10: 406 | E10: 372 | F10: 363 | G10: 353 | H10: 344 | I10: 333 | J10: =I10-E10 -> -39 | K10: =IFERROR(I10/E10-1,0) -> -0.10483871
A11: 療育手帳所持者数 | B11: 人 | C11: 82 | D11: 77 | E11: 74 | F11: 72 | G11: 70 | H11: 68 | I11: 66 | J11: =I11-E11 -> -8 | K11: =IFERROR(I11/E11-1,0) -> -0.10810811
A12: 精神障害者保健福祉手帳所持者数 | B12: 人 | C12: 45 | D12: 47 | E12: 62 | F12: 60 | G12: 59 | H12: 57 | I12: 56 | J12: =I12-E12 -> -6 | K12: =IFERROR(I12/E12-1,0) -> -0.096774194
A13: 障害者手帳所持者数計 | B13: 人 | C13: 539 | D13: 530 | E13: 508 | F13: 495 | G13: 482 | H13: 469 | I13: 455 | J13: =I13-E13 -> -53 | K13: =IFERROR(I13/E13-1,0) -> -0.10433071 | L13: 3手帳の合計

Sheet 見込量算定(障害福祉)
A1: 見込量算定（障害福祉サービス）－小野町
A2: ※R5～R8実績は小野町ワークシートから反映。R9～R11見込は選択した算定方法で自動計算します。緑色の政策値は小野町向け初期設定で、必要に応じて変更してください。
D4: 利用者数（実績・算定方法・政策値・見込） | O4: サービス量（実績・算定方法・政策値・見込）
A5: 分類 | B5: サービス名 | C5: 単位（量） | D5: R5実績 | E5: R6実績 | F5: R7実績 | G5: R8実績 | H5: 算定方法（者） | I5: 政策R9 | J5: 政策R10 | K5: 政策R11 | L5: R9見込 | M5: R10見込 | N5: R11見込 | O5: R5実績量 | P5: R6実績量 | Q5: R7実績量 | R5: R8実績量 | S5: 算定方法（量） | T5: 政策R9量 | U5: 政策R10量 | V5: 政策R11量 | W5: R9見込量 | X5: R10見込量 | Y5: R11見込量 | Z5: 備考
A6: 訪問系 | B6: 居宅介護 | C6: 時間/月 | D6: 4 | E6: 4 | F6: 5 | G6: 6 | H6: 線形トレンド | L6: =IF($H6="直近実績横ばい",$G6,IF($H6="直近2年平均",ROUND(AVERAGE($F6:$G6),0),IF($H6="直近3年平均",ROUND(AVERAGE($E6:$G6),0),IF($H6="線形トレンド",MAX(0,ROUND($G6+1*($G6-$D6)/3,0)),IF($H6="人口比率型",IFERROR(ROUND($G6/人口基礎データ!$F$13*人口基礎データ!$G$13,0),$G6),IF($H6="政策調整",IF($I6="",$G6,$I6),$G6)))))) -> 7 | M6: =IF($H6="直近実績横ばい",$G6,IF($H6="直近2年平均",ROUND(AVERAGE($F6:$G6),0),IF($H6="直近3年平均",ROUND(AVERAGE($E6:$G6),0),IF($H6="線形トレンド",MAX(0,ROUND($G6+2*($G6-$D6)/3,0)),IF($H6="人口比率型",IFERROR(ROUND($G6/人口基礎データ!$F$13*人口基礎データ!$H$13,0),$G6),IF($H6="政策調整",IF($J6="",$G6,$J6),$G6)))))) -> 7 | N6: =IF($H6="直近実績横ばい",$G6,IF($H6="直近2年平均",ROUND(AVERAGE($F6:$G6),0),IF($H6="直近3年平均",ROUND(AVERAGE($E6:$G6),0),IF($H6="線形トレンド",MAX(0,ROUND($G6+3*($G6-$D6)/3,0)),IF($H6="人口比率型",IFERROR(ROUND($G6/人口基礎データ!$F$13*人口基礎データ!$I$13,0),$G6),IF($H6="政策調整",IF($K6="",$G6,$K6),$G6)))))) -> 8 | O6: 26 | P6: 29 | Q6: 113 | R6: 38 | S6: 利用者数連動 | W6: =IF($S6="-","-",IF($S6="直近実績横ばい",$R6,IF($S6="直近2年平均",ROUND(AVERAGE($Q6:$R6),0),IF($S6="利用者数連動",IFERROR(ROUND($L6*(($Q6+$R6)/($F6+$G6)),0),0),IF($S6="政策調整",IF($T6="","",$T6),""))))) -> 96 | X6: =IF($S6="-","-",IF($S6="直近実績横ばい",$R6,IF($S6="直近2年平均",ROUND(AVERAGE($Q6:$R6),0),IF($S6="利用者数連動",IFERROR(ROUND($M6*(($Q6+$R6)/($F6+$G6)),0),0),IF($S6="政策調整",IF($U6="","",$U6),""))))) -> 96 | Y6: =IF($S6="-","-",IF($S6="直近実績横ばい",$R6,IF($S6="直近2年平均",ROUND(AVERAGE($Q6:$R6),0),IF($S6="利用者数連動",IFERROR(ROUND($N6*(($Q6+$R6)/($F6+$G6)),0),0),IF($S6="政策調整",IF($V6="","",$V6),""))))) -> 110 | Z6: R7の利用時間が突出しているため、利用量はR7・R8の1人当たり利用量平均で連動。
A7: 訪問系 | B7: 重度訪問介護 | C7: 時間/月 | D7: 0 | E7: 0 | F7: 0 | G7: 1 | H7: 直近実績横ばい | L7: =IF($H7="直近実績横ばい",$G7,IF($H7="直近2年平均",ROUND(AVERAGE($F7:$G7),0),IF($H7="直近3年平均",ROUND(AVERAGE($E7:$G7),0),IF($H7="線形トレンド",MAX(0,ROUND($G7+1*($G7-$D7)/3,0)),IF($H7="人口比率型",IFERROR(ROUND($G7/人口基礎データ!$F$13*人口基礎データ!$G$13,0),$G7),IF($H7="政策調整",IF($I7="",$G7,$I7),$G7)))))) -> 1 | M7: =IF($H7="直近実績横ばい",$G7,IF($H7="直近2年平均",ROUND(AVERAGE($F7:$G7),0),IF($H7="直近3年平均",ROUND(AVERAGE($E7:$G7),0),IF($H7="線形トレンド",MAX(0,ROUND($G7+2*($G7-$D7)/3,0)),IF($H7="人口比率型",IFERROR(ROUND($G7/人口基礎データ!$F$13*人口基礎データ!$H$13,0),$G7),IF($H7="政策調整",IF($J7="",$G7,$J7),$G7)))))) -> 1 | N7: =IF($H7="直近実績横ばい",$G7,IF($H7="直近2年平均",ROUND(AVERAGE($F7:$G7),0),IF($H7="直近3年平均",ROUND(AVERAGE($E7:$G7),0),IF($H7="線形トレンド",MAX(0,ROUND($G7+3*($G7-$D7)/3,0)),IF($H7="人口比率型",IFERROR(ROUND($G7/人口基礎データ!$F$13*人口基礎データ!$I$13,0),$G7),IF($H7="政策調整",IF($K7="",$G7,$K7),$G7)))))) -> 1 | O7: 0 | P7: 0 | Q7: 4 | R7: 16 | S7: 利用者数連動 | W7: =IF($S7="-","-",IF($S7="直近実績横ばい",$R7,IF($S7="直近2年平均",ROUND(AVERAGE($Q7:$R7),0),IF($S7="利用者数連動",IFERROR(ROUND($L7*(($Q7+$R7)/($F7+$G7)),0),0),IF($S7="政策調整",IF($T7="","",$T7),""))))) -> 20 | X7: =IF($S7="-","-",IF($S7="直近実績横ばい",$R7,IF($S7="直近2年平均",ROUND(AVERAGE($Q7:$R7),0),IF($S7="利用者数連動",IFERROR(ROUND($M7*(($Q7+$R7)/($F7+$G7)),0),0),IF($S7="政策調整",IF($U7="","",$U7),""))))) -> 20 | Y7: =IF($S7="-","-",IF($S7="直近実績横ばい",$R7,IF($S7="直近2年平均",ROUND(AVERAGE($Q7:$R7),0),IF($S7="利用者数連動",IFERROR(ROUND($N7*(($Q7+$R7)/($F7+$G7)),0),0),IF($S7="政策調整",IF($V7="","",$V7),""))))) -> 20 | Z7: 少人数のため伸び率推計を避け、R8実績を基準。
A8: 訪問系 | B8: 同行援護 | C8: 時間/月 | D8: 0 | E8: 0 | F8: 0 | G8: 0 | H8: 直近実績横ばい | L8: =IF($H8="直近実績横ばい",$G8,IF($H8="直近2年平均",ROUND(AVERAGE($F8:$G8),0),IF($H8="直近3年平均",ROUND(AVERAGE($E8:$G8),0),IF($H8="線形トレンド",MAX(0,ROUND($G8+1*($G8-$D8)/3,0)),IF($H8="人口比率型",IFERROR(ROUND($G8/人口基礎データ!$F$13*人口基礎データ!$G$13,0),$G8),IF($H8="政策調整",IF($I8="",$G8,$I8),$G8)))))) -> 0 | M8: =IF($H8="直近実績横ばい",$G8,IF($H8="直近2年平均",ROUND(AVERAGE($F8:$G8),0),IF($H8="直近3年平均",ROUND(AVERAGE($E8:$G8),0),IF($H8="線形トレンド",MAX(0,ROUND($G8+2*($G8-$D8)/3,0)),IF($H8="人口比率型",IFERROR(ROUND($G8/人口基礎データ!$F$13*人口基礎データ!$H$13,0),$G8),IF($H8="政策調整",IF($J8="",$G8,$J8),$G8)))))) -> 0 | N8: =IF($H8="直近実績横ばい",$G8,IF($H8="直近2年平均",ROUND(AVERAGE($F8:$G8),0),IF($H8="直近3年平均",ROUND(AVERAGE($E8:$G8),0),IF($H8="線形トレンド",MAX(0,ROUND($G8+3*($G8-$D8)/3,0)),IF($H8="人口比率型",IFERROR(ROUND($G8/人口基礎データ!$F$13*人口基礎データ!$I$13,0),$G8),IF($H8="政策調整",IF($K8="",$G8,$K8),$G8)))))) -> 0 | O8: 0 | P8: 0 | Q8: 0 | R8: 0 | S8: 直近実績横ばい | W8: =IF($S8="-","-",IF($S8="直近実績横ばい",$R8,IF($S8="直近2年平均",ROUND(AVERAGE($Q8:$R8),0),IF($S8="利用者数連動",IFERROR(ROUND($L8*(($Q8+$R8)/($F8+$G8)),0),0),IF($S8="政策調整",IF($T8="","",$T8),""))))) -> 0 | X8: =IF($S8="-","-",IF($S8="直近実績横ばい",$R8,IF($S8="直近2年平均",ROUND(AVERAGE($Q8:$R8),0),IF($S8="利用者数連動",IFERROR(ROUND($M8*(($Q8+$R8)/($F8+$G8)),0),0),IF($S8="政策調整",IF($U8="","",$U8),""))))) -> 0 | Y8: =IF($S8="-","-",IF($S8="直近実績横ばい",$R8,IF($S8="直近2年平均",ROUND(AVERAGE($Q8:$R8),0),IF($S8="利用者数連動",IFERROR(ROUND($N8*(($Q8+$R8)/($F8+$G8)),0),0),IF($S8="政策調整",IF($V8="","",$V8),""))))) -> 0 | Z8: 4年間実績0。ニーズ発生時の圏域内提供体制は別途確保。
A9: 訪問系 | B9: 行動援護 | C9: 時間/月 | D9: 0 | E9: 0 | F9: 0 | G9: 0 | H9: 直近実績横ばい | L9: =IF($H9="直近実績横ばい",$G9,IF($H9="直近2年平均",ROUND(AVERAGE($F9:$G9),0),IF($H9="直近3年平均",ROUND(AVERAGE($E9:$G9),0),IF($H9="線形トレンド",MAX(0,ROUND($G9+1*($G9-$D9)/3,0)),IF($H9="人口比率型",IFERROR(ROUND($G9/人口基礎データ!$F$13*人口基礎データ!$G$13,0),$G9),IF($H9="政策調整",IF($I9="",$G9,$I9),$G9)))))) -> 0 | M9: =IF($H9="直近実績横ばい",$G9,IF($H9="直近2年平均",ROUND(AVERAGE($F9:$G9),0),IF($H9="直近3年平均",ROUND(AVERAGE($E9:$G9),0),IF($H9="線形トレンド",MAX(0,ROUND($G9+2*($G9-$D9)/3,0)),IF($H9="人口比率型",IFERROR(ROUND($G9/人口基礎データ!$F$13*人口基礎データ!$H$13,0),$G9),IF($H9="政策調整",IF($J9="",$G9,$J9),$G9)))))) -> 0 | N9: =IF($H9="直近実績横ばい",$G9,IF($H9="直近2年平均",ROUND(AVERAGE($F9:$G9),0),IF($H9="直近3年平均",ROUND(AVERAGE($E9:$G9),0),IF($H9="線形トレンド",MAX(0,ROUND($G9+3*($G9-$D9)/3,0)),IF($H9="人口比率型",IFERROR(ROUND($G9/人口基礎データ!$F$13*人口基礎データ!$I$13,0),$G9),IF($H9="政策調整",IF($K9="",$G9,$K9),$G9)))))) -> 0 | O9: 0 | P9: 0 | Q9: 0 | R9: 0 | S9: 直近実績横ばい | W9: =IF($S9="-","-",IF($S9="直近実績横ばい",$R9,IF($S9="直近2年平均",ROUND(AVERAGE($Q9:$R9),0),IF($S9="利用者数連動",IFERROR(ROUND($L9*(($Q9+$R9)/($F9+$G9)),0),0),IF($S9="政策調整",IF($T9="","",$T9),""))))) -> 0 | X9: =IF($S9="-","-",IF($S9="直近実績横ばい",$R9,IF($S9="直近2年平均",ROUND(AVERAGE($Q9:$R9),0),IF($S9="利用者数連動",IFERROR(ROUND($M9*(($Q9+$R9)/($F9+$G9)),0),0),IF($S9="政策調整",IF($U9="","",$U9),""))))) -> 0 | Y9: =IF($S9="-","-",IF($S9="直近実績横ばい",$R9,IF($S9="直近2年平均",ROUND(AVERAGE($Q9:$R9),0),IF($S9="利用者数連動",IFERROR(ROUND($N9*(($Q9+$R9)/($F9+$G9)),0),0),IF($S9="政策調整",IF($V9="","",$V9),""))))) -> 0 | Z9: 4年間実績0。強度行動障がい者のニーズ把握とあわせて毎年度見直し。
A10: 訪問系 | B10: 重度障害者等包括支援 | C10: 時間/月 | D10: 0 | E10: 0 | F10: 0 | G10: 0 | H10: 直近実績横ばい | L10: =IF($H10="直近実績横ばい",$G10,IF($H10="直近2年平均",ROUND(AVERAGE($F10:$G10),0),IF($H10="直近3年平均",ROUND(AVERAGE($E10:$G10),0),IF($H10="線形トレンド",MAX(0,ROUND($G10+1*($G10-$D10)/3,0)),IF($H10="人口比率型",IFERROR(ROUND($G10/人口基礎データ!$F$13*人口基礎データ!$G$13,0),$G10),IF($H10="政策調整",IF($I10="",$G10,$I10),$G10)))))) -> 0 | M10: =IF($H10="直近実績横ばい",$G10,IF($H10="直近2年平均",ROUND(AVERAGE($F10:$G10),0),IF($H10="直近3年平均",ROUND(AVERAGE($E10:$G10),0),IF($H10="線形トレンド",MAX(0,ROUND($G10+2*($G10-$D10)/3,0)),IF($H10="人口比率型",IFERROR(ROUND($G10/人口基礎データ!$F$13*人口基礎データ!$H$13,0),$G10),IF($H10="政策調整",IF($J10="",$G10,$J10),$G10)))))) -> 0 | N10: =IF($H10="直近実績横ばい",$G10,IF($H10="直近2年平均",ROUND(AVERAGE($F10:$G10),0),IF($H10="直近3年平均",ROUND(AVERAGE($E10:$G10),0),IF($H10="線形トレンド",MAX(0,ROUND($G10+3*($G10-$D10)/3,0)),IF($H10="人口比率型",IFERROR(ROUND($G10/人口基礎データ!$F$13*人口基礎データ!$I$13,0),$G10),IF($H10="政策調整",IF($K10="",$G10,$K10),$G10)))))) -> 0 | O10: 0 | P10: 0 | Q10: 0 | R10: 0 | S10: 直近実績横ばい | W10: =IF($S10="-","-",IF($S10="直近実績横ばい",$R10,IF($S10="直近2年平均",ROUND(AVERAGE($Q10:$R10),0),IF($S10="利用者数連動",IFERROR(ROUND($L10*(($Q10+$R10)/($F10+$G10)),0),0),IF($S10="政策調整",IF($T10="","",$T10),""))))) -> 0 | X10: =IF($S10="-","-",IF($S10="直近実績横ばい",$R10,IF($S10="直近2年平均",ROUND(AVERAGE($Q10:$R10),0),IF($S10="利用者数連動",IFERROR(ROUND($M10*(($Q10+$R10)/($F10+$G10)),0),0),IF($S10="政策調整",IF($U10="","",$U10),""))))) -> 0 | Y10: =IF($S10="-","-",IF($S10="直近実績横ばい",$R10,IF($S10="直近2年平均",ROUND(AVERAGE($Q10:$R10),0),IF($S10="利用者数連動",IFERROR(ROUND($N10*(($Q10+$R10)/($F10+$G10)),0),0),IF($S10="政策調整",IF($V10="","",$V10),""))))) -> 0 | Z10: 4年間実績0。個別ニーズ発生時に見直し。
A11: 日中活動系 | B11: 生活介護 | C11: 人日/月 | D11: 31 | E11: 30 | F11: 32 | G11: 30 | H11: 直近3年平均 | L11: =IF($H11="直近実績横ばい",$G11,IF($H11="直近2年平均",ROUND(AVERAGE($F11:$G11),0),IF($H11="直近3年平均",ROUND(AVERAGE($E11:$G11),0),IF($H11="線形トレンド",MAX(0,ROUND($G11+1*($G11-$D11)/3,0)),IF($H11="人口比率型",IFERROR(ROUND($G11/人口基礎データ!$F$13*人口基礎データ!$G$13,0),$G11),IF($H11="政策調整",IF($I11="",$G11,$I11),$G11)))))) -> 31 | M11: =IF($H11="直近実績横ばい",$G11,IF($H11="直近2年平均",ROUND(AVERAGE($F11:$G11),0),IF($H11="直近3年平均",ROUND(AVERAGE($E11:$G11),0),IF($H11="線形トレンド",MAX(0,ROUND($G11+2*($G11-$D11)/3,0)),IF($H11="人口比率型",IFERROR(ROUND($G11/人口基礎データ!$F$13*人口基礎データ!$H$13,0),$G11),IF($H11="政策調整",IF($J11="",$G11,$J11),$G11)))))) -> 31 | N11: =IF($H11="直近実績横ばい",$G11,IF($H11="直近2年平均",ROUND(AVERAGE($F11:$G11),0),IF($H11="直近3年平均",ROUND(AVERAGE($E11:$G11),0),IF($H11="線形トレンド",MAX(0,ROUND($G11+3*($G11-$D11)/3,0)),IF($H11="人口比率型",IFERROR(ROUND($G11/人口基礎データ!$F$13*人口基礎データ!$I$13,0),$G11),IF($H11="政策調整",IF($K11="",$G11,$K11),$G11)))))) -> 31 | O11: 589 | P11: 688 | Q11: 689 | R11: 568 | S11: 利用者数連動 | W11: =IF($S11="-","-",IF($S11="直近実績横ばい",$R11,IF($S11="直近2年平均",ROUND(AVERAGE($Q11:$R11),0),IF($S11="利用者数連動",IFERROR(ROUND($L11*(($Q11+$R11)/($F11+$G11)),0),0),IF($S11="政策調整",IF($T11="","",$T11),""))))) -> 629 | X11: =IF($S11="-","-",IF($S11="直近実績横ばい",$R11,IF($S11="直近2年平均",ROUND(AVERAGE($Q11:$R11),0),IF($S11="利用者数連動",IFERROR(ROUND($M11*(($Q11+$R11)/($F11+$G11)),0),0),IF($S11="政策調整",IF($U11="","",$U11),""))))) -> 629 | Y11: =IF($S11="-","-",IF($S11="直近実績横ばい",$R11,IF($S11="直近2年平均",ROUND(AVERAGE($Q11:$R11),0),IF($S11="利用者数連動",IFERROR(ROUND($N11*(($Q11+$R11)/($F11+$G11)),0),0),IF($S11="政策調整",IF($V11="","",$V11),""))))) -> 629 | Z11: 利用者数は概ね横ばい。人口減少下でも重度化・高齢化を考慮して直近平均を採用。
A12: 日中活動系 | B12: 自立訓練（機能訓練） | C12: 人日/月 | D12: 0 | E12: 0 | F12: 0 | G12: 0 | H12: 直近実績横ばい | L12: =IF($H12="直近実績横ばい",$G12,IF($H12="直近2年平均",ROUND(AVERAGE($F12:$G12),0),IF($H12="直近3年平均",ROUND(AVERAGE($E12:$G12),0),IF($H12="線形トレンド",MAX(0,ROUND($G12+1*($G12-$D12)/3,0)),IF($H12="人口比率型",IFERROR(ROUND($G12/人口基礎データ!$F$13*人口基礎データ!$G$13,0),$G12),IF($H12="政策調整",IF($I12="",$G12,$I12),$G12)))))) -> 0 | M12: =IF($H12="直近実績横ばい",$G12,IF($H12="直近2年平均",ROUND(AVERAGE($F12:$G12),0),IF($H12="直近3年平均",ROUND(AVERAGE($E12:$G12),0),IF($H12="線形トレンド",MAX(0,ROUND($G12+2*($G12-$D12)/3,0)),IF($H12="人口比率型",IFERROR(ROUND($G12/人口基礎データ!$F$13*人口基礎データ!$H$13,0),$G12),IF($H12="政策調整",IF($J12="",$G12,$J12),$G12)))))) -> 0 | N12: =IF($H12="直近実績横ばい",$G12,IF($H12="直近2年平均",ROUND(AVERAGE($F12:$G12),0),IF($H12="直近3年平均",ROUND(AVERAGE($E12:$G12),0),IF($H12="線形トレンド",MAX(0,ROUND($G12+3*($G12-$D12)/3,0)),IF($H12="人口比率型",IFERROR(ROUND($G12/人口基礎データ!$F$13*人口基礎データ!$I$13,0),$G12),IF($H12="政策調整",IF($K12="",$G12,$K12),$G12)))))) -> 0 | O12: 0 | P12: 0 | Q12: 0 | R12: 0 | S12: 直近実績横ばい | W12: =IF($S12="-","-",IF($S12="直近実績横ばい",$R12,IF($S12="直近2年平均",ROUND(AVERAGE($Q12:$R12),0),IF($S12="利用者数連動",IFERROR(ROUND($L12*(($Q12+$R12)/($F12+$G12)),0),0),IF($S12="政策調整",IF($T12="","",$T12),""))))) -> 0 | X12: =IF($S12="-","-",IF($S12="直近実績横ばい",$R12,IF($S12="直近2年平均",ROUND(AVERAGE($Q12:$R12),0),IF($S12="利用者数連動",IFERROR(ROUND($M12*(($Q12+$R12)/($F12+$G12)),0),0),IF($S12="政策調整",IF($U12="","",$U12),""))))) -> 0 | Y12: =IF($S12="-","-",IF($S12="直近実績横ばい",$R12,IF($S12="直近2年平均",ROUND(AVERAGE($Q12:$R12),0),IF($S12="利用者数連動",IFERROR(ROUND($N12*(($Q12+$R12)/($F12+$G12)),0),0),IF($S12="政策調整",IF($V12="","",$V12),""))))) -> 0 | Z12: 実績0。必要時に圏域での利用確保を検討。
A13: 日中活動系 | B13: 自立訓練（生活訓練） | C13: 人日/月 | D13: 1 | E13: 5 | F13: 4 | G13: 2 | H13: 直近2年平均 | L13: =IF($H13="直近実績横ばい",$G13,IF($H13="直近2年平均",ROUND(AVERAGE($F13:$G13),0),IF($H13="直近3年平均",ROUND(AVERAGE($E13:$G13),0),IF($H13="線形トレンド",MAX(0,ROUND($G13+1*($G13-$D13)/3,0)),IF($H13="人口比率型",IFERROR(ROUND($G13/人口基礎データ!$F$13*人口基礎データ!$G$13,0),$G13),IF($H13="政策調整",IF($I13="",$G13,$I13),$G13)))))) -> 3 | M13: =IF($H13="直近実績横ばい",$G13,IF($H13="直近2年平均",ROUND(AVERAGE($F13:$G13),0),IF($H13="直近3年平均",ROUND(AVERAGE($E13:$G13),0),IF($H13="線形トレンド",MAX(0,ROUND($G13+2*($G13-$D13)/3,0)),IF($H13="人口比率型",IFERROR(ROUND($G13/人口基礎データ!$F$13*人口基礎データ!$H$13,0),$G13),IF($H13="政策調整",IF($J13="",$G13,$J13),$G13)))))) -> 3 | N13: =IF($H13="直近実績横ばい",$G13,IF($H13="直近2年平均",ROUND(AVERAGE($F13:$G13),0),IF($H13="直近3年平均",ROUND(AVERAGE($E13:$G13),0),IF($H13="線形トレンド",MAX(0,ROUND($G13+3*($G13-$D13)/3,0)),IF($H13="人口比率型",IFERROR(ROUND($G13/人口基礎データ!$F$13*人口基礎データ!$I$13,0),$G13),IF($H13="政策調整",IF($K13="",$G13,$K13),$G13)))))) -> 3 | O13: 30 | P13: 97 | Q13: 70 | R13: 39 | S13: 利用者数連動 | W13: =IF($S13="-","-",IF($S13="直近実績横ばい",$R13,IF($S13="直近2年平均",ROUND(AVERAGE($Q13:$R13),0),IF($S13="利用者数連動",IFERROR(ROUND($L13*(($Q13+$R13)/($F13+$G13)),0),0),IF($S13="政策調整",IF($T13="","",$T13),""))))) -> 55 | X13: =IF($S13="-","-",IF($S13="直近実績横ばい",$R13,IF($S13="直近2年平均",ROUND(AVERAGE($Q13:$R13),0),IF($S13="利用者数連動",IFERROR(ROUND($M13*(($Q13+$R13)/($F13+$G13)),0),0),IF($S13="政策調整",IF($U13="","",$U13),""))))) -> 55 | Y13: =IF($S13="-","-",IF($S13="直近実績横ばい",$R13,IF($S13="直近2年平均",ROUND(AVERAGE($Q13:$R13),0),IF($S13="利用者数連動",IFERROR(ROUND($N13*(($Q13+$R13)/($F13+$G13)),0),0),IF($S13="政策調整",IF($V13="","",$V13),""))))) -> 55 | Z13: 変動が大きいため直近2年平均を採用。
A14: 日中活動系 | B14: 就労選択支援 | C14: - | D14: - | E14: - | F14: 0 | G14: 0 | H14: 政策調整 | I14: 1 | J14: 1 | K14: 1 | L14: =IF($H14="直近実績横ばい",$G14,IF($H14="直近2年平均",ROUND(AVERAGE($F14:$G14),0),IF($H14="直近3年平均",ROUND(AVERAGE($E14:$G14),0),IF($H14="線形トレンド",MAX(0,ROUND($G14+1*($G14-$D14)/3,0)),IF($H14="人口比率型",IFERROR(ROUND($G14/人口基礎データ!$F$13*人口基礎データ!$G$13,0),$G14),IF($H14="政策調整",IF($I14="",$G14,$I14),$G14)))))) -> 1 | M14: =IF($H14="直近実績横ばい",$G14,IF($H14="直近2年平均",ROUND(AVERAGE($F14:$G14),0),IF($H14="直近3年平均",ROUND(AVERAGE($E14:$G14),0),IF($H14="線形トレンド",MAX(0,ROUND($G14+2*($G14-$D14)/3,0)),IF($H14="人口比率型",IFERROR(ROUND($G14/人口基礎データ!$F$13*人口基礎データ!$H$13,0),$G14),IF($H14="政策調整",IF($J14="",$G14,$J14),$G14)))))) -> 1 | N14: =IF($H14="直近実績横ばい",$G14,IF($H14="直近2年平均",ROUND(AVERAGE($F14:$G14),0),IF($H14="直近3年平均",ROUND(AVERAGE($E14:$G14),0),IF($H14="線形トレンド",MAX(0,ROUND($G14+3*($G14-$D14)/3,0)),IF($H14="人口比率型",IFERROR(ROUND($G14/人口基礎データ!$F$13*人口基礎データ!$I$13,0),$G14),IF($H14="政策調整",IF($K14="",$G14,$K14),$G14)))))) -> 1 | O14: - | P14: - | Q14: 0 | R14: 0 | S14: - | W14: =IF($S14="-","-",IF($S14="直近実績横ばい",$R14,IF($S14="直近2年平均",ROUND(AVERAGE($Q14:$R14),0),IF($S14="利用者数連動",IFERROR(ROUND($L14*(($Q14+$R14)/($F14+$G14)),0),0),IF($S14="政策調整",IF($T14="","",$T14),""))))) -> - | X14: =IF($S14="-","-",IF($S14="直近実績横ばい",$R14,IF($S14="直近2年平均",ROUND(AVERAGE($Q14:$R14),0),IF($S14="利用者数連動",IFERROR(ROUND($M14*(($Q14+$R14)/($F14+$G14)),0),0),IF($S14="政策調整",IF($U14="","",$U14),""))))) -> - | Y14: =IF($S14="-","-",IF($S14="直近実績横ばい",$R14,IF($S14="直近2年平均",ROUND(AVERAGE($Q14:$R14),0),IF($S14="利用者数連動",IFERROR(ROUND($N14*(($Q14+$R14)/($F14+$G14)),0),0),IF($S14="政策調整",IF($V14="","",$V14),""))))) -> - | Z14: 新設サービス。協議会圏域で提供体制を確保し、小野町では月1人程度の利用を初期設定。
A15: 日中活動系 | B15: 就労移行支援 | C15: 人日/月 | D15: 3 | E15: 1 | F15: 2 | G15: 0 | H15: 政策調整 | I15: 1 | J15: 1 | K15: 1 | L15: =IF($H15="直近実績横ばい",$G15,IF($H15="直近2年平均",ROUND(AVERAGE($F15:$G15),0),IF($H15="直近3年平均",ROUND(AVERAGE($E15:$G15),0),IF($H15="線形トレンド",MAX(0,ROUND($G15+1*($G15-$D15)/3,0)),IF($H15="人口比率型",IFERROR(ROUND($G15/人口基礎データ!$F$13*人口基礎データ!$G$13,0),$G15),IF($H15="政策調整",IF($I15="",$G15,$I15),$G15)))))) -> 1 | M15: =IF($H15="直近実績横ばい",$G15,IF($H15="直近2年平均",ROUND(AVERAGE($F15:$G15),0),IF($H15="直近3年平均",ROUND(AVERAGE($E15:$G15),0),IF($H15="線形トレンド",MAX(0,ROUND($G15+2*($G15-$D15)/3,0)),IF($H15="人口比率型",IFERROR(ROUND($G15/人口基礎データ!$F$13*人口基礎データ!$H$13,0),$G15),IF($H15="政策調整",IF($J15="",$G15,$J15),$G15)))))) -> 1 | N15: =IF($H15="直近実績横ばい",$G15,IF($H15="直近2年平均",ROUND(AVERAGE($F15:$G15),0),IF($H15="直近3年平均",ROUND(AVERAGE($E15:$G15),0),IF($H15="線形トレンド",MAX(0,ROUND($G15+3*($G15-$D15)/3,0)),IF($H15="人口比率型",IFERROR(ROUND($G15/人口基礎データ!$F$13*人口基礎データ!$I$13,0),$G15),IF($H15="政策調整",IF($K15="",$G15,$K15),$G15)))))) -> 1 | O15: 48 | P15: 21 | Q15: 29 | R15: 0 | S15: 政策調整 | T15: 15 | U15: 15 | V15: 15 | W15: =IF($S15="-","-",IF($S15="直近実績横ばい",$R15,IF($S15="直近2年平均",ROUND(AVERAGE($Q15:$R15),0),IF($S15="利用者数連動",IFERROR(ROUND($L15*(($Q15+$R15)/($F15+$G15)),0),0),IF($S15="政策調整",IF($T15="","",$T15),""))))) -> 15 | X15: =IF($S15="-","-",IF($S15="直近実績横ばい",$R15,IF($S15="直近2年平均",ROUND(AVERAGE($Q15:$R15),0),IF($S15="利用者数連動",IFERROR(ROUND($M15*(($Q15+$R15)/($F15+$G15)),0),0),IF($S15="政策調整",IF($U15="","",$U15),""))))) -> 15 | Y15: =IF($S15="-","-",IF($S15="直近実績横ばい",$R15,IF($S15="直近2年平均",ROUND(AVERAGE($Q15:$R15),0),IF($S15="利用者数連動",IFERROR(ROUND($N15*(($Q15+$R15)/($F15+$G15)),0),0),IF($S15="政策調整",IF($V15="","",$V15),""))))) -> 15 | Z15: R8実績0だが一般就労移行目標との整合から利用機会を確保。利用量はR7以前の実績水準から15人日/月を仮置き。
A16: 日中活動系 | B16: 就労継続支援A型 | C16: 人日/月 | D16: 5 | E16: 8 | F16: 9 | G16: 11 | H16: 線形トレンド | L16: =IF($H16="直近実績横ばい",$G16,IF($H16="直近2年平均",ROUND(AVERAGE($F16:$G16),0),IF($H16="直近3年平均",ROUND(AVERAGE($E16:$G16),0),IF($H16="線形トレンド",MAX(0,ROUND($G16+1*($G16-$D16)/3,0)),IF($H16="人口比率型",IFERROR(ROUND($G16/人口基礎データ!$F$13*人口基礎データ!$G$13,0),$G16),IF($H16="政策調整",IF($I16="",$G16,$I16),$G16)))))) -> 13 | M16: =IF($H16="直近実績横ばい",$G16,IF($H16="直近2年平均",ROUND(AVERAGE($F16:$G16),0),IF($H16="直近3年平均",ROUND(AVERAGE($E16:$G16),0),IF($H16="線形トレンド",MAX(0,ROUND($G16+2*($G16-$D16)/3,0)),IF($H16="人口比率型",IFERROR(ROUND($G16/人口基礎データ!$F$13*人口基礎データ!$H$13,0),$G16),IF($H16="政策調整",IF($J16="",$G16,$J16),$G16)))))) -> 15 | N16: =IF($H16="直近実績横ばい",$G16,IF($H16="直近2年平均",ROUND(AVERAGE($F16:$G16),0),IF($H16="直近3年平均",ROUND(AVERAGE($E16:$G16),0),IF($H16="線形トレンド",MAX(0,ROUND($G16+3*($G16-$D16)/3,0)),IF($H16="人口比率型",IFERROR(ROUND($G16/人口基礎データ!$F$13*人口基礎データ!$I$13,0),$G16),IF($H16="政策調整",IF($K16="",$G16,$K16),$G16)))))) -> 17 | O16: 105 | P16: 163 | Q16: 188 | R16: 238 | S16: 利用者数連動 | W16: =IF($S16="-","-",IF($S16="直近実績横ばい",$R16,IF($S16="直近2年平均",ROUND(AVERAGE($Q16:$R16),0),IF($S16="利用者数連動",IFERROR(ROUND($L16*(($Q16+$R16)/($F16+$G16)),0),0),IF($S16="政策調整",IF($T16="","",$T16),""))))) -> 277 | X16: =IF($S16="-","-",IF($S16="直近実績横ばい",$R16,IF($S16="直近2年平均",ROUND(AVERAGE($Q16:$R16),0),IF($S16="利用者数連動",IFERROR(ROUND($M16*(($Q16+$R16)/($F16+$G16)),0),0),IF($S16="政策調整",IF($U16="","",$U16),""))))) -> 320 | Y16: =IF($S16="-","-",IF($S16="直近実績横ばい",$R16,IF($S16="直近2年平均",ROUND(AVERAGE($Q16:$R16),0),IF($S16="利用者数連動",IFERROR(ROUND($N16*(($Q16+$R16)/($F16+$G16)),0),0),IF($S16="政策調整",IF($V16="","",$V16),""))))) -> 362 | Z16: 4年間増加傾向が明確なため線形トレンドを採用。
A17: 日中活動系 | B17: 就労継続支援B型 | C17: 人日/月 | D17: 36 | E17: 33 | F17: 35 | G17: 36 | H17: 直近2年平均 | L17: =IF($H17="直近実績横ばい",$G17,IF($H17="直近2年平均",ROUND(AVERAGE($F17:$G17),0),IF($H17="直近3年平均",ROUND(AVERAGE($E17:$G17),0),IF($H17="線形トレンド",MAX(0,ROUND($G17+1*($G17-$D17)/3,0)),IF($H17="人口比率型",IFERROR(ROUND($G17/人口基礎データ!$F$13*人口基礎データ!$G$13,0),$G17),IF($H17="政策調整",IF($I17="",$G17,$I17),$G17)))))) -> 36 | M17: =IF($H17="直近実績横ばい",$G17,IF($H17="直近2年平均",ROUND(AVERAGE($F17:$G17),0),IF($H17="直近3年平均",ROUND(AVERAGE($E17:$G17),0),IF($H17="線形トレンド",MAX(0,ROUND($G17+2*($G17-$D17)/3,0)),IF($H17="人口比率型",IFERROR(ROUND($G17/人口基礎データ!$F$13*人口基礎データ!$H$13,0),$G17),IF($H17="政策調整",IF($J17="",$G17,$J17),$G17)))))) -> 36 | N17: =IF($H17="直近実績横ばい",$G17,IF($H17="直近2年平均",ROUND(AVERAGE($F17:$G17),0),IF($H17="直近3年平均",ROUND(AVERAGE($E17:$G17),0),IF($H17="線形トレンド",MAX(0,ROUND($G17+3*($G17-$D17)/3,0)),IF($H17="人口比率型",IFERROR(ROUND($G17/人口基礎データ!$F$13*人口基礎データ!$I$13,0),$G17),IF($H17="政策調整",IF($K17="",$G17,$K17),$G17)))))) -> 36 | O17: 653 | P17: 593 | Q17: 626 | R17: 664 | S17: 利用者数連動 | W17: =IF($S17="-","-",IF($S17="直近実績横ばい",$R17,IF($S17="直近2年平均",ROUND(AVERAGE($Q17:$R17),0),IF($S17="利用者数連動",IFERROR(ROUND($L17*(($Q17+$R17)/($F17+$G17)),0),0),IF($S17="政策調整",IF($T17="","",$T17),""))))) -> 654 | X17: =IF($S17="-","-",IF($S17="直近実績横ばい",$R17,IF($S17="直近2年平均",ROUND(AVERAGE($Q17:$R17),0),IF($S17="利用者数連動",IFERROR(ROUND($M17*(($Q17+$R17)/($F17+$G17)),0),0),IF($S17="政策調整",IF($U17="","",$U17),""))))) -> 654 | Y17: =IF($S17="-","-",IF($S17="直近実績横ばい",$R17,IF($S17="直近2年平均",ROUND(AVERAGE($Q17:$R17),0),IF($S17="利用者数連動",IFERROR(ROUND($N17*(($Q17+$R17)/($F17+$G17)),0),0),IF($S17="政策調整",IF($V17="","",$V17),""))))) -> 654 | Z17: 利用者数は概ね横ばい。
A18: 日中活動系 | B18: 就労定着支援 | C18: - | D18: 0 | E18: 1 | F18: 0 | G18: 0 | H18: 政策調整 | I18: 1 | J18: 1 | K18: 2 | L18: =IF($H18="直近実績横ばい",$G18,IF($H18="直近2年平均",ROUND(AVERAGE($F18:$G18),0),IF($H18="直近3年平均",ROUND(AVERAGE($E18:$G18),0),IF($H18="線形トレンド",MAX(0,ROUND($G18+1*($G18-$D18)/3,0)),IF($H18="人口比率型",IFERROR(ROUND($G18/人口基礎データ!$F$13*人口基礎データ!$G$13,0),$G18),IF($H18="政策調整",IF($I18="",$G18,$I18),$G18)))))) -> 1 | M18: =IF($H18="直近実績横ばい",$G18,IF($H18="直近2年平均",ROUND(AVERAGE($F18:$G18),0),IF($H18="直近3年平均",ROUND(AVERAGE($E18:$G18),0),IF($H18="線形トレンド",MAX(0,ROUND($G18+2*($G18-$D18)/3,0)),IF($H18="人口比率型",IFERROR(ROUND($G18/人口基礎データ!$F$13*人口基礎データ!$H$13,0),$G18),IF($H18="政策調整",IF($J18="",$G18,$J18),$G18)))))) -> 1 | N18: =IF($H18="直近実績横ばい",$G18,IF($H18="直近2年平均",ROUND(AVERAGE($F18:$G18),0),IF($H18="直近3年平均",ROUND(AVERAGE($E18:$G18),0),IF($H18="線形トレンド",MAX(0,ROUND($G18+3*($G18-$D18)/3,0)),IF($H18="人口比率型",IFERROR(ROUND($G18/人口基礎データ!$F$13*人口基礎データ!$I$13,0),$G18),IF($H18="政策調整",IF($K18="",$G18,$K18),$G18)))))) -> 2 | O18: - | P18: - | Q18: - | R18: - | S18: - | W18: =IF($S18="-","-",IF($S18="直近実績横ばい",$R18,IF($S18="直近2年平均",ROUND(AVERAGE($Q18:$R18),0),IF($S18="利用者数連動",IFERROR(ROUND($L18*(($Q18+$R18)/($F18+$G18)),0),0),IF($S18="政策調整",IF($T18="","",$T18),""))))) -> - | X18: =IF($S18="-","-",IF($S18="直近実績横ばい",$R18,IF($S18="直近2年平均",ROUND(AVERAGE($Q18:$R18),0),IF($S18="利用者数連動",IFERROR(ROUND($M18*(($Q18+$R18)/($F18+$G18)),0),0),IF($S18="政策調整",IF($U18="","",$U18),""))))) -> - | Y18: =IF($S18="-","-",IF($S18="直近実績横ばい",$R18,IF($S18="直近2年平均",ROUND(AVERAGE($Q18:$R18),0),IF($S18="利用者数連動",IFERROR(ROUND($N18*(($Q18+$R18)/($F18+$G18)),0),0),IF($S18="政策調整",IF($V18="","",$V18),""))))) -> - | Z18: 国目標（R6実績の1.47倍以上）からR11は2人以上を設定。
A19: 日中活動系 | B19: 療養介護 | C19: - | D19: 3 | E19: 3 | F19: 3 | G19: 3 | H19: 直近実績横ばい | L19: =IF($H19="直近実績横ばい",$G19,IF($H19="直近2年平均",ROUND(AVERAGE($F19:$G19),0),IF($H19="直近3年平均",ROUND(AVERAGE($E19:$G19),0),IF($H19="線形トレンド",MAX(0,ROUND($G19+1*($G19-$D19)/3,0)),IF($H19="人口比率型",IFERROR(ROUND($G19/人口基礎データ!$F$13*人口基礎データ!$G$13,0),$G19),IF($H19="政策調整",IF($I19="",$G19,$I19),$G19)))))) -> 3 | M19: =IF($H19="直近実績横ばい",$G19,IF($H19="直近2年平均",ROUND(AVERAGE($F19:$G19),0),IF($H19="直近3年平均",ROUND(AVERAGE($E19:$G19),0),IF($H19="線形トレンド",MAX(0,ROUND($G19+2*($G19-$D19)/3,0)),IF($H19="人口比率型",IFERROR(ROUND($G19/人口基礎データ!$F$13*人口基礎データ!$H$13,0),$G19),IF($H19="政策調整",IF($J19="",$G19,$J19),$G19)))))) -> 3 | N19: =IF($H19="直近実績横ばい",$G19,IF($H19="直近2年平均",ROUND(AVERAGE($F19:$G19),0),IF($H19="直近3年平均",ROUND(AVERAGE($E19:$G19),0),IF($H19="線形トレンド",MAX(0,ROUND($G19+3*($G19-$D19)/3,0)),IF($H19="人口比率型",IFERROR(ROUND($G19/人口基礎データ!$F$13*人口基礎データ!$I$13,0),$G19),IF($H19="政策調整",IF($K19="",$G19,$K19),$G19)))))) -> 3 | O19: - | P19: - | Q19: - | R19: - | S19: - | W19: =IF($S19="-","-",IF($S19="直近実績横ばい",$R19,IF($S19="直近2年平均",ROUND(AVERAGE($Q19:$R19),0),IF($S19="利用者数連動",IFERROR(ROUND($L19*(($Q19+$R19)/($F19+$G19)),0),0),IF($S19="政策調整",IF($T19="","",$T19),""))))) -> - | X19: =IF($S19="-","-",IF($S19="直近実績横ばい",$R19,IF($S19="直近2年平均",ROUND(AVERAGE($Q19:$R19),0),IF($S19="利用者数連動",IFERROR(ROUND($M19*(($Q19+$R19)/($F19+$G19)),0),0),IF($S19="政策調整",IF($U19="","",$U19),""))))) -> - | Y19: =IF($S19="-","-",IF($S19="直近実績横ばい",$R19,IF($S19="直近2年平均",ROUND(AVERAGE($Q19:$R19),0),IF($S19="利用者数連動",IFERROR(ROUND($N19*(($Q19+$R19)/($F19+$G19)),0),0),IF($S19="政策調整",IF($V19="","",$V19),""))))) -> - | Z19: 4年間3人で安定。
A20: 日中活動系 | B20: 短期入所（福祉型） | C20: 人日/月 | D20: 0 | E20: 0 | F20: 0 | G20: 0 | H20: 直近実績横ばい | L20: =IF($H20="直近実績横ばい",$G20,IF($H20="直近2年平均",ROUND(AVERAGE($F20:$G20),0),IF($H20="直近3年平均",ROUND(AVERAGE($E20:$G20),0),IF($H20="線形トレンド",MAX(0,ROUND($G20+1*($G20-$D20)/3,0)),IF($H20="人口比率型",IFERROR(ROUND($G20/人口基礎データ!$F$13*人口基礎データ!$G$13,0),$G20),IF($H20="政策調整",IF($I20="",$G20,$I20),$G20)))))) -> 0 | M20: =IF($H20="直近実績横ばい",$G20,IF($H20="直近2年平均",ROUND(AVERAGE($F20:$G20),0),IF($H20="直近3年平均",ROUND(AVERAGE($E20:$G20),0),IF($H20="線形トレンド",MAX(0,ROUND($G20+2*($G20-$D20)/3,0)),IF($H20="人口比率型",IFERROR(ROUND($G20/人口基礎データ!$F$13*人口基礎データ!$H$13,0),$G20),IF($H20="政策調整",IF($J20="",$G20,$J20),$G20)))))) -> 0 | N20: =IF($H20="直近実績横ばい",$G20,IF($H20="直近2年平均",ROUND(AVERAGE($F20:$G20),0),IF($H20="直近3年平均",ROUND(AVERAGE($E20:$G20),0),IF($H20="線形トレンド",MAX(0,ROUND($G20+3*($G20-$D20)/3,0)),IF($H20="人口比率型",IFERROR(ROUND($G20/人口基礎データ!$F$13*人口基礎データ!$I$13,0),$G20),IF($H20="政策調整",IF($K20="",$G20,$K20),$G20)))))) -> 0 | O20: 0 | P20: 0 | Q20: 0 | R20: 0 | S20: 直近実績横ばい | W20: =IF($S20="-","-",IF($S20="直近実績横ばい",$R20,IF($S20="直近2年平均",ROUND(AVERAGE($Q20:$R20),0),IF($S20="利用者数連動",IFERROR(ROUND($L20*(($Q20+$R20)/($F20+$G20)),0),0),IF($S20="政策調整",IF($T20="","",$T20),""))))) -> 0 | X20: =IF($S20="-","-",IF($S20="直近実績横ばい",$R20,IF($S20="直近2年平均",ROUND(AVERAGE($Q20:$R20),0),IF($S20="利用者数連動",IFERROR(ROUND($M20*(($Q20+$R20)/($F20+$G20)),0),0),IF($S20="政策調整",IF($U20="","",$U20),""))))) -> 0 | Y20: =IF($S20="-","-",IF($S20="直近実績横ばい",$R20,IF($S20="直近2年平均",ROUND(AVERAGE($Q20:$R20),0),IF($S20="利用者数連動",IFERROR(ROUND($N20*(($Q20+$R20)/($F20+$G20)),0),0),IF($S20="政策調整",IF($V20="","",$V20),""))))) -> 0 | Z20: 実績0。ただし緊急時・レスパイト需要に備え提供体制確保を計画本文に記載。
A21: 日中活動系 | B21: 短期入所（医療型） | C21: 人日/月 | D21: 0 | E21: 0 | F21: 0 | G21: 0 | H21: 直近実績横ばい | L21: =IF($H21="直近実績横ばい",$G21,IF($H21="直近2年平均",ROUND(AVERAGE($F21:$G21),0),IF($H21="直近3年平均",ROUND(AVERAGE($E21:$G21),0),IF($H21="線形トレンド",MAX(0,ROUND($G21+1*($G21-$D21)/3,0)),IF($H21="人口比率型",IFERROR(ROUND($G21/人口基礎データ!$F$13*人口基礎データ!$G$13,0),$G21),IF($H21="政策調整",IF($I21="",$G21,$I21),$G21)))))) -> 0 | M21: =IF($H21="直近実績横ばい",$G21,IF($H21="直近2年平均",ROUND(AVERAGE($F21:$G21),0),IF($H21="直近3年平均",ROUND(AVERAGE($E21:$G21),0),IF($H21="線形トレンド",MAX(0,ROUND($G21+2*($G21-$D21)/3,0)),IF($H21="人口比率型",IFERROR(ROUND($G21/人口基礎データ!$F$13*人口基礎データ!$H$13,0),$G21),IF($H21="政策調整",IF($J21="",$G21,$J21),$G21)))))) -> 0 | N21: =IF($H21="直近実績横ばい",$G21,IF($H21="直近2年平均",ROUND(AVERAGE($F21:$G21),0),IF($H21="直近3年平均",ROUND(AVERAGE($E21:$G21),0),IF($H21="線形トレンド",MAX(0,ROUND($G21+3*($G21-$D21)/3,0)),IF($H21="人口比率型",IFERROR(ROUND($G21/人口基礎データ!$F$13*人口基礎データ!$I$13,0),$G21),IF($H21="政策調整",IF($K21="",$G21,$K21),$G21)))))) -> 0 | O21: 0 | P21: 0 | Q21: 0 | R21: 0 | S21: 直近実績横ばい | W21: =IF($S21="-","-",IF($S21="直近実績横ばい",$R21,IF($S21="直近2年平均",ROUND(AVERAGE($Q21:$R21),0),IF($S21="利用者数連動",IFERROR(ROUND($L21*(($Q21+$R21)/($F21+$G21)),0),0),IF($S21="政策調整",IF($T21="","",$T21),""))))) -> 0 | X21: =IF($S21="-","-",IF($S21="直近実績横ばい",$R21,IF($S21="直近2年平均",ROUND(AVERAGE($Q21:$R21),0),IF($S21="利用者数連動",IFERROR(ROUND($M21*(($Q21+$R21)/($F21+$G21)),0),0),IF($S21="政策調整",IF($U21="","",$U21),""))))) -> 0 | Y21: =IF($S21="-","-",IF($S21="直近実績横ばい",$R21,IF($S21="直近2年平均",ROUND(AVERAGE($Q21:$R21),0),IF($S21="利用者数連動",IFERROR(ROUND($N21*(($Q21+$R21)/($F21+$G21)),0),0),IF($S21="政策調整",IF($V21="","",$V21),""))))) -> 0 | Z21: 実績0。医療的ケア等の個別ニーズ発生時に見直し。
A22: 居住系 | B22: 自立生活援助 | C22: - | D22: 0 | E22: 0 | F22: 0 | G22: 0 | H22: 直近実績横ばい | L22: =IF($H22="直近実績横ばい",$G22,IF($H22="直近2年平均",ROUND(AVERAGE($F22:$G22),0),IF($H22="直近3年平均",ROUND(AVERAGE($E22:$G22),0),IF($H22="線形トレンド",MAX(0,ROUND($G22+1*($G22-$D22)/3,0)),IF($H22="人口比率型",IFERROR(ROUND($G22/人口基礎データ!$F$13*人口基礎データ!$G$13,0),$G22),IF($H22="政策調整",IF($I22="",$G22,$I22),$G22)))))) -> 0 | M22: =IF($H22="直近実績横ばい",$G22,IF($H22="直近2年平均",ROUND(AVERAGE($F22:$G22),0),IF($H22="直近3年平均",ROUND(AVERAGE($E22:$G22),0),IF($H22="線形トレンド",MAX(0,ROUND($G22+2*($G22-$D22)/3,0)),IF($H22="人口比率型",IFERROR(ROUND($G22/人口基礎データ!$F$13*人口基礎データ!$H$13,0),$G22),IF($H22="政策調整",IF($J22="",$G22,$J22),$G22)))))) -> 0 | N22: =IF($H22="直近実績横ばい",$G22,IF($H22="直近2年平均",ROUND(AVERAGE($F22:$G22),0),IF($H22="直近3年平均",ROUND(AVERAGE($E22:$G22),0),IF($H22="線形トレンド",MAX(0,ROUND($G22+3*($G22-$D22)/3,0)),IF($H22="人口比率型",IFERROR(ROUND($G22/人口基礎データ!$F$13*人口基礎データ!$I$13,0),$G22),IF($H22="政策調整",IF($K22="",$G22,$K22),$G22)))))) -> 0 | O22: - | P22: - | Q22: - | R22: - | S22: - | W22: =IF($S22="-","-",IF($S22="直近実績横ばい",$R22,IF($S22="直近2年平均",ROUND(AVERAGE($Q22:$R22),0),IF($S22="利用者数連動",IFERROR(ROUND($L22*(($Q22+$R22)/($F22+$G22)),0),0),IF($S22="政策調整",IF($T22="","",$T22),""))))) -> - | X22: =IF($S22="-","-",IF($S22="直近実績横ばい",$R22,IF($S22="直近2年平均",ROUND(AVERAGE($Q22:$R22),0),IF($S22="利用者数連動",IFERROR(ROUND($M22*(($Q22+$R22)/($F22+$G22)),0),0),IF($S22="政策調整",IF($U22="","",$U22),""))))) -> - | Y22: =IF($S22="-","-",IF($S22="直近実績横ばい",$R22,IF($S22="直近2年平均",ROUND(AVERAGE($Q22:$R22),0),IF($S22="利用者数連動",IFERROR(ROUND($N22*(($Q22+$R22)/($F22+$G22)),0),0),IF($S22="政策調整",IF($V22="","",$V22),""))))) -> - | Z22: 実績0。地域移行意向の把握結果に応じ見直し。
A23: 居住系 | B23: 共同生活援助（グループホーム） | C23: - | D23: 14 | E23: 15 | F23: 16 | G23: 18 | H23: 線形トレンド | L23: =IF($H23="直近実績横ばい",$G23,IF($H23="直近2年平均",ROUND(AVERAGE($F23:$G23),0),IF($H23="直近3年平均",ROUND(AVERAGE($E23:$G23),0),IF($H23="線形トレンド",MAX(0,ROUND($G23+1*($G23-$D23)/3,0)),IF($H23="人口比率型",IFERROR(ROUND($G23/人口基礎データ!$F$13*人口基礎データ!$G$13,0),$G23),IF($H23="政策調整",IF($I23="",$G23,$I23),$G23)))))) -> 19 | M23: =IF($H23="直近実績横ばい",$G23,IF($H23="直近2年平均",ROUND(AVERAGE($F23:$G23),0),IF($H23="直近3年平均",ROUND(AVERAGE($E23:$G23),0),IF($H23="線形トレンド",MAX(0,ROUND($G23+2*($G23-$D23)/3,0)),IF($H23="人口比率型",IFERROR(ROUND($G23/人口基礎データ!$F$13*人口基礎データ!$H$13,0),$G23),IF($H23="政策調整",IF($J23="",$G23,$J23),$G23)))))) -> 21 | N23: =IF($H23="直近実績横ばい",$G23,IF($H23="直近2年平均",ROUND(AVERAGE($F23:$G23),0),IF($H23="直近3年平均",ROUND(AVERAGE($E23:$G23),0),IF($H23="線形トレンド",MAX(0,ROUND($G23+3*($G23-$D23)/3,0)),IF($H23="人口比率型",IFERROR(ROUND($G23/人口基礎データ!$F$13*人口基礎データ!$I$13,0),$G23),IF($H23="政策調整",IF($K23="",$G23,$K23),$G23)))))) -> 22 | O23: - | P23: - | Q23: - | R23: - | S23: - | W23: =IF($S23="-","-",IF($S23="直近実績横ばい",$R23,IF($S23="直近2年平均",ROUND(AVERAGE($Q23:$R23),0),IF($S23="利用者数連動",IFERROR(ROUND($L23*(($Q23+$R23)/($F23+$G23)),0),0),IF($S23="政策調整",IF($T23="","",$T23),""))))) -> - | X23: =IF($S23="-","-",IF($S23="直近実績横ばい",$R23,IF($S23="直近2年平均",ROUND(AVERAGE($Q23:$R23),0),IF($S23="利用者数連動",IFERROR(ROUND($M23*(($Q23+$R23)/($F23+$G23)),0),0),IF($S23="政策調整",IF($U23="","",$U23),""))))) -> - | Y23: =IF($S23="-","-",IF($S23="直近実績横ばい",$R23,IF($S23="直近2年平均",ROUND(AVERAGE($Q23:$R23),0),IF($S23="利用者数連動",IFERROR(ROUND($N23*(($Q23+$R23)/($F23+$G23)),0),0),IF($S23="政策調整",IF($V23="","",$V23),""))))) -> - | Z23: 増加傾向。施設・在宅からの地域生活移行先として需要増を見込む。
A24: 居住系 | B24: 施設入所支援 | C24: - | D24: 16 | E24: 16 | F24: 19 | G24: 18 | H24: 政策調整 | I24: 18 | J24: 18 | K24: 18 | L24: =IF($H24="直近実績横ばい",$G24,IF($H24="直近2年平均",ROUND(AVERAGE($F24:$G24),0),IF($H24="直近3年平均",ROUND(AVERAGE($E24:$G24),0),IF($H24="線形トレンド",MAX(0,ROUND($G24+1*($G24-$D24)/3,0)),IF($H24="人口比率型",IFERROR(ROUND($G24/人口基礎データ!$F$13*人口基礎データ!$G$13,0),$G24),IF($H24="政策調整",IF($I24="",$G24,$I24),$G24)))))) -> 18 | M24: =IF($H24="直近実績横ばい",$G24,IF($H24="直近2年平均",ROUND(AVERAGE($F24:$G24),0),IF($H24="直近3年平均",ROUND(AVERAGE($E24:$G24),0),IF($H24="線形トレンド",MAX(0,ROUND($G24+2*($G24-$D24)/3,0)),IF($H24="人口比率型",IFERROR(ROUND($G24/人口基礎データ!$F$13*人口基礎データ!$H$13,0),$G24),IF($H24="政策調整",IF($J24="",$G24,$J24),$G24)))))) -> 18 | N24: =IF($H24="直近実績横ばい",$G24,IF($H24="直近2年平均",ROUND(AVERAGE($F24:$G24),0),IF($H24="直近3年平均",ROUND(AVERAGE($E24:$G24),0),IF($H24="線形トレンド",MAX(0,ROUND($G24+3*($G24-$D24)/3,0)),IF($H24="人口比率型",IFERROR(ROUND($G24/人口基礎データ!$F$13*人口基礎データ!$I$13,0),$G24),IF($H24="政策調整",IF($K24="",$G24,$K24),$G24)))))) -> 18 | O24: - | P24: - | Q24: - | R24: - | S24: - | W24: =IF($S24="-","-",IF($S24="直近実績横ばい",$R24,IF($S24="直近2年平均",ROUND(AVERAGE($Q24:$R24),0),IF($S24="利用者数連動",IFERROR(ROUND($L24*(($Q24+$R24)/($F24+$G24)),0),0),IF($S24="政策調整",IF($T24="","",$T24),""))))) -> - | X24: =IF($S24="-","-",IF($S24="直近実績横ばい",$R24,IF($S24="直近2年平均",ROUND(AVERAGE($Q24:$R24),0),IF($S24="利用者数連動",IFERROR(ROUND($M24*(($Q24+$R24)/($F24+$G24)),0),0),IF($S24="政策調整",IF($U24="","",$U24),""))))) -> - | Y24: =IF($S24="-","-",IF($S24="直近実績横ばい",$R24,IF($S24="直近2年平均",ROUND(AVERAGE($Q24:$R24),0),IF($S24="利用者数連動",IFERROR(ROUND($N24*(($Q24+$R24)/($F24+$G24)),0),0),IF($S24="政策調整",IF($V24="","",$V24),""))))) -> - | Z24: R7基準19人。国の5％以上削減目標からR11は18人以下。R8で18人となっており水準を維持。
A25: 相談支援 | B25: 計画相談支援 | C25: - | D25: 12 | E25: 14 | F25: 13 | G25: 15 | H25: 線形トレンド | L25: =IF($H25="直近実績横ばい",$G25,IF($H25="直近2年平均",ROUND(AVERAGE($F25:$G25),0),IF($H25="直近3年平均",ROUND(AVERAGE($E25:$G25),0),IF($H25="線形トレンド",MAX(0,ROUND($G25+1*($G25-$D25)/3,0)),IF($H25="人口比率型",IFERROR(ROUND($G25/人口基礎データ!$F$13*人口基礎データ!$G$13,0),$G25),IF($H25="政策調整",IF($I25="",$G25,$I25),$G25)))))) -> 16 | M25: =IF($H25="直近実績横ばい",$G25,IF($H25="直近2年平均",ROUND(AVERAGE($F25:$G25),0),IF($H25="直近3年平均",ROUND(AVERAGE($E25:$G25),0),IF($H25="線形トレンド",MAX(0,ROUND($G25+2*($G25-$D25)/3,0)),IF($H25="人口比率型",IFERROR(ROUND($G25/人口基礎データ!$F$13*人口基礎データ!$H$13,0),$G25),IF($H25="政策調整",IF($J25="",$G25,$J25),$G25)))))) -> 17 | N25: =IF($H25="直近実績横ばい",$G25,IF($H25="直近2年平均",ROUND(AVERAGE($F25:$G25),0),IF($H25="直近3年平均",ROUND(AVERAGE($E25:$G25),0),IF($H25="線形トレンド",MAX(0,ROUND($G25+3*($G25-$D25)/3,0)),IF($H25="人口比率型",IFERROR(ROUND($G25/人口基礎データ!$F$13*人口基礎データ!$I$13,0),$G25),IF($H25="政策調整",IF($K25="",$G25,$K25),$G25)))))) -> 18 | O25: - | P25: - | Q25: - | R25: - | S25: - | W25: =IF($S25="-","-",IF($S25="直近実績横ばい",$R25,IF($S25="直近2年平均",ROUND(AVERAGE($Q25:$R25),0),IF($S25="利用者数連動",IFERROR(ROUND($L25*(($Q25+$R25)/($F25+$G25)),0),0),IF($S25="政策調整",IF($T25="","",$T25),""))))) -> - | X25: =IF($S25="-","-",IF($S25="直近実績横ばい",$R25,IF($S25="直近2年平均",ROUND(AVERAGE($Q25:$R25),0),IF($S25="利用者数連動",IFERROR(ROUND($M25*(($Q25+$R25)/($F25+$G25)),0),0),IF($S25="政策調整",IF($U25="","",$U25),""))))) -> - | Y25: =IF($S25="-","-",IF($S25="直近実績横ばい",$R25,IF($S25="直近2年平均",ROUND(AVERAGE($Q25:$R25),0),IF($S25="利用者数連動",IFERROR(ROUND($N25*(($Q25+$R25)/($F25+$G25)),0),0),IF($S25="政策調整",IF($V25="","",$V25),""))))) -> - | Z25: 相談支援体制充実・のぞまないセルフプラン解消を踏まえ増加を見込む。
A26: 相談支援 | B26: 地域移行支援 | C26: - | D26: 0 | E26: 0 | F26: 0 | G26: 0 | H26: 政策調整 | I26: 1 | J26: 1 | K26: 1 | L26: =IF($H26="直近実績横ばい",$G26,IF($H26="直近2年平均",ROUND(AVERAGE($F26:$G26),0),IF($H26="直近3年平均",ROUND(AVERAGE($E26:$G26),0),IF($H26="線形トレンド",MAX(0,ROUND($G26+1*($G26-$D26)/3,0)),IF($H26="人口比率型",IFERROR(ROUND($G26/人口基礎データ!$F$13*人口基礎データ!$G$13,0),$G26),IF($H26="政策調整",IF($I26="",$G26,$I26),$G26)))))) -> 1 | M26: =IF($H26="直近実績横ばい",$G26,IF($H26="直近2年平均",ROUND(AVERAGE($F26:$G26),0),IF($H26="直近3年平均",ROUND(AVERAGE($E26:$G26),0),IF($H26="線形トレンド",MAX(0,ROUND($G26+2*($G26-$D26)/3,0)),IF($H26="人口比率型",IFERROR(ROUND($G26/人口基礎データ!$F$13*人口基礎データ!$H$13,0),$G26),IF($H26="政策調整",IF($J26="",$G26,$J26),$G26)))))) -> 1 | N26: =IF($H26="直近実績横ばい",$G26,IF($H26="直近2年平均",ROUND(AVERAGE($F26:$G26),0),IF($H26="直近3年平均",ROUND(AVERAGE($E26:$G26),0),IF($H26="線形トレンド",MAX(0,ROUND($G26+3*($G26-$D26)/3,0)),IF($H26="人口比率型",IFERROR(ROUND($G26/人口基礎データ!$F$13*人口基礎データ!$I$13,0),$G26),IF($H26="政策調整",IF($K26="",$G26,$K26),$G26)))))) -> 1 | O26: - | P26: - | Q26: - | R26: - | S26: - | W26: =IF($S26="-","-",IF($S26="直近実績横ばい",$R26,IF($S26="直近2年平均",ROUND(AVERAGE($Q26:$R26),0),IF($S26="利用者数連動",IFERROR(ROUND($L26*(($Q26+$R26)/($F26+$G26)),0),0),IF($S26="政策調整",IF($T26="","",$T26),""))))) -> - | X26: =IF($S26="-","-",IF($S26="直近実績横ばい",$R26,IF($S26="直近2年平均",ROUND(AVERAGE($Q26:$R26),0),IF($S26="利用者数連動",IFERROR(ROUND($M26*(($Q26+$R26)/($F26+$G26)),0),0),IF($S26="政策調整",IF($U26="","",$U26),""))))) -> - | Y26: =IF($S26="-","-",IF($S26="直近実績横ばい",$R26,IF($S26="直近2年平均",ROUND(AVERAGE($Q26:$R26),0),IF($S26="利用者数連動",IFERROR(ROUND($N26*(($Q26+$R26)/($F26+$G26)),0),0),IF($S26="政策調整",IF($V26="","",$V26),""))))) -> - | Z26: 施設入所者の地域移行目標（R11までに2人以上）を支えるため利用枠を設定。
A27: 相談支援 | B27: 地域定着支援 | C27: - | D27: 0 | E27: 0 | F27: 0 | G27: 0 | H27: 政策調整 | I27: 1 | J27: 1 | K27: 2 | L27: =IF($H27="直近実績横ばい",$G27,IF($H27="直近2年平均",ROUND(AVERAGE($F27:$G27),0),IF($H27="直近3年平均",ROUND(AVERAGE($E27:$G27),0),IF($H27="線形トレンド",MAX(0,ROUND($G27+1*($G27-$D27)/3,0)),IF($H27="人口比率型",IFERROR(ROUND($G27/人口基礎データ!$F$13*人口基礎データ!$G$13,0),$G27),IF($H27="政策調整",IF($I27="",$G27,$I27),$G27)))))) -> 1 | M27: =IF($H27="直近実績横ばい",$G27,IF($H27="直近2年平均",ROUND(AVERAGE($F27:$G27),0),IF($H27="直近3年平均",ROUND(AVERAGE($E27:$G27),0),IF($H27="線形トレンド",MAX(0,ROUND($G27+2*($G27-$D27)/3,0)),IF($H27="人口比率型",IFERROR(ROUND($G27/人口基礎データ!$F$13*人口基礎データ!$H$13,0),$G27),IF($H27="政策調整",IF($J27="",$G27,$J27),$G27)))))) -> 1 | N27: =IF($H27="直近実績横ばい",$G27,IF($H27="直近2年平均",ROUND(AVERAGE($F27:$G27),0),IF($H27="直近3年平均",ROUND(AVERAGE($E27:$G27),0),IF($H27="線形トレンド",MAX(0,ROUND($G27+3*($G27-$D27)/3,0)),IF($H27="人口比率型",IFERROR(ROUND($G27/人口基礎データ!$F$13*人口基礎データ!$I$13,0),$G27),IF($H27="政策調整",IF($K27="",$G27,$K27),$G27)))))) -> 2 | O27: - | P27: - | Q27: - | R27: - | S27: - | W27: =IF($S27="-","-",IF($S27="直近実績横ばい",$R27,IF($S27="直近2年平均",ROUND(AVERAGE($Q27:$R27),0),IF($S27="利用者数連動",IFERROR(ROUND($L27*(($Q27+$R27)/($F27+$G27)),0),0),IF($S27="政策調整",IF($T27="","",$T27),""))))) -> - | X27: =IF($S27="-","-",IF($S27="直近実績横ばい",$R27,IF($S27="直近2年平均",ROUND(AVERAGE($Q27:$R27),0),IF($S27="利用者数連動",IFERROR(ROUND($M27*(($Q27+$R27)/($F27+$G27)),0),0),IF($S27="政策調整",IF($U27="","",$U27),""))))) -> - | Y27: =IF($S27="-","-",IF($S27="直近実績横ばい",$R27,IF($S27="直近2年平均",ROUND(AVERAGE($Q27:$R27),0),IF($S27="利用者数連動",IFERROR(ROUND($N27*(($Q27+$R27)/($F27+$G27)),0),0),IF($S27="政策調整",IF($V27="","",$V27),""))))) -> - | Z27: 地域移行後の定着支援を見込み段階的に設定。

Sheet 見込量算定(障害児)
A1: 見込量算定（障害児支援）－小野町
A2: ※障害児サービスの人口比率型は、ワークシートで将来推計がある0～14歳人口を基礎にしています。R8実績0の障害児相談支援は要確認です。
D4: 利用者数（実績・算定方法・政策値・見込） | O4: サービス量（実績・算定方法・政策値・見込）
A5: 分類 | B5: サービス名 | C5: 単位（量） | D5: R5実績 | E5: R6実績 | F5: R7実績 | G5: R8実績 | H5: 算定方法（者） | I5: 政策R9 | J5: 政策R10 | K5: 政策R11 | L5: R9見込 | M5: R10見込 | N5: R11見込 | O5: R5実績量 | P5: R6実績量 | Q5: R7実績量 | R5: R8実績量 | S5: 算定方法（量） | T5: 政策R9量 | U5: 政策R10量 | V5: 政策R11量 | W5: R9見込量 | X5: R10見込量 | Y5: R11見込量 | Z5: 備考
A6: 障害児通所 | B6: 児童発達支援 | C6: 人日/月 | D6: 6 | E6: 7 | F6: 5 | G6: 6 | H6: 人口比率型 | L6: =IF($H6="直近実績横ばい",$G6,IF($H6="直近2年平均",ROUND(AVERAGE($F6:$G6),0),IF($H6="直近3年平均",ROUND(AVERAGE($E6:$G6),0),IF($H6="線形トレンド",MAX(0,ROUND($G6+1*($G6-$D6)/3,0)),IF($H6="人口比率型",IFERROR(ROUND($G6/人口基礎データ!$F$7*人口基礎データ!$G$7,0),$G6),IF($H6="政策調整",IF($I6="",$G6,$I6),$G6)))))) -> 6 | M6: =IF($H6="直近実績横ばい",$G6,IF($H6="直近2年平均",ROUND(AVERAGE($F6:$G6),0),IF($H6="直近3年平均",ROUND(AVERAGE($E6:$G6),0),IF($H6="線形トレンド",MAX(0,ROUND($G6+2*($G6-$D6)/3,0)),IF($H6="人口比率型",IFERROR(ROUND($G6/人口基礎データ!$F$7*人口基礎データ!$H$7,0),$G6),IF($H6="政策調整",IF($J6="",$G6,$J6),$G6)))))) -> 5 | N6: =IF($H6="直近実績横ばい",$G6,IF($H6="直近2年平均",ROUND(AVERAGE($F6:$G6),0),IF($H6="直近3年平均",ROUND(AVERAGE($E6:$G6),0),IF($H6="線形トレンド",MAX(0,ROUND($G6+3*($G6-$D6)/3,0)),IF($H6="人口比率型",IFERROR(ROUND($G6/人口基礎データ!$F$7*人口基礎データ!$I$7,0),$G6),IF($H6="政策調整",IF($K6="",$G6,$K6),$G6)))))) -> 5 | O6: 26 | P6: 24 | Q6: 15 | R6: 25 | S6: 利用者数連動 | W6: =IF($S6="-","-",IF($S6="直近実績横ばい",$R6,IF($S6="直近2年平均",ROUND(AVERAGE($Q6:$R6),0),IF($S6="利用者数連動",IFERROR(ROUND($L6*(($Q6+$R6)/($F6+$G6)),0),0),IF($S6="政策調整",IF($T6="","",$T6),""))))) -> 22 | X6: =IF($S6="-","-",IF($S6="直近実績横ばい",$R6,IF($S6="直近2年平均",ROUND(AVERAGE($Q6:$R6),0),IF($S6="利用者数連動",IFERROR(ROUND($M6*(($Q6+$R6)/($F6+$G6)),0),0),IF($S6="政策調整",IF($U6="","",$U6),""))))) -> 18 | Y6: =IF($S6="-","-",IF($S6="直近実績横ばい",$R6,IF($S6="直近2年平均",ROUND(AVERAGE($Q6:$R6),0),IF($S6="利用者数連動",IFERROR(ROUND($N6*(($Q6+$R6)/($F6+$G6)),0),0),IF($S6="政策調整",IF($V6="","",$V6),""))))) -> 18 | Z6: 0～14歳人口の減少を基礎に推計。
A7: 障害児通所 | B7: 放課後等デイサービス | C7: 人日/月 | D7: 31 | E7: 30 | F7: 24 | G7: 19 | H7: 人口比率型 | L7: =IF($H7="直近実績横ばい",$G7,IF($H7="直近2年平均",ROUND(AVERAGE($F7:$G7),0),IF($H7="直近3年平均",ROUND(AVERAGE($E7:$G7),0),IF($H7="線形トレンド",MAX(0,ROUND($G7+1*($G7-$D7)/3,0)),IF($H7="人口比率型",IFERROR(ROUND($G7/人口基礎データ!$F$7*人口基礎データ!$G$7,0),$G7),IF($H7="政策調整",IF($I7="",$G7,$I7),$G7)))))) -> 17 | M7: =IF($H7="直近実績横ばい",$G7,IF($H7="直近2年平均",ROUND(AVERAGE($F7:$G7),0),IF($H7="直近3年平均",ROUND(AVERAGE($E7:$G7),0),IF($H7="線形トレンド",MAX(0,ROUND($G7+2*($G7-$D7)/3,0)),IF($H7="人口比率型",IFERROR(ROUND($G7/人口基礎データ!$F$7*人口基礎データ!$H$7,0),$G7),IF($H7="政策調整",IF($J7="",$G7,$J7),$G7)))))) -> 16 | N7: =IF($H7="直近実績横ばい",$G7,IF($H7="直近2年平均",ROUND(AVERAGE($F7:$G7),0),IF($H7="直近3年平均",ROUND(AVERAGE($E7:$G7),0),IF($H7="線形トレンド",MAX(0,ROUND($G7+3*($G7-$D7)/3,0)),IF($H7="人口比率型",IFERROR(ROUND($G7/人口基礎データ!$F$7*人口基礎データ!$I$7,0),$G7),IF($H7="政策調整",IF($K7="",$G7,$K7),$G7)))))) -> 14 | O7: 100 | P7: 93 | Q7: 73 | R7: 65 | S7: 利用者数連動 | W7: =IF($S7="-","-",IF($S7="直近実績横ばい",$R7,IF($S7="直近2年平均",ROUND(AVERAGE($Q7:$R7),0),IF($S7="利用者数連動",IFERROR(ROUND($L7*(($Q7+$R7)/($F7+$G7)),0),0),IF($S7="政策調整",IF($T7="","",$T7),""))))) -> 55 | X7: =IF($S7="-","-",IF($S7="直近実績横ばい",$R7,IF($S7="直近2年平均",ROUND(AVERAGE($Q7:$R7),0),IF($S7="利用者数連動",IFERROR(ROUND($M7*(($Q7+$R7)/($F7+$G7)),0),0),IF($S7="政策調整",IF($U7="","",$U7),""))))) -> 51 | Y7: =IF($S7="-","-",IF($S7="直近実績横ばい",$R7,IF($S7="直近2年平均",ROUND(AVERAGE($Q7:$R7),0),IF($S7="利用者数連動",IFERROR(ROUND($N7*(($Q7+$R7)/($F7+$G7)),0),0),IF($S7="政策調整",IF($V7="","",$V7),""))))) -> 45 | Z7: 利用実績と年少人口がともに減少。R8利用率を年少人口推計に連動。
A8: 障害児通所 | B8: 保育所等訪問支援 | C8: 人日/月 | D8: 0 | E8: 0 | F8: 0 | G8: 0 | H8: 政策調整 | I8: 1 | J8: 1 | K8: 1 | L8: =IF($H8="直近実績横ばい",$G8,IF($H8="直近2年平均",ROUND(AVERAGE($F8:$G8),0),IF($H8="直近3年平均",ROUND(AVERAGE($E8:$G8),0),IF($H8="線形トレンド",MAX(0,ROUND($G8+1*($G8-$D8)/3,0)),IF($H8="人口比率型",IFERROR(ROUND($G8/人口基礎データ!$F$7*人口基礎データ!$G$7,0),$G8),IF($H8="政策調整",IF($I8="",$G8,$I8),$G8)))))) -> 1 | M8: =IF($H8="直近実績横ばい",$G8,IF($H8="直近2年平均",ROUND(AVERAGE($F8:$G8),0),IF($H8="直近3年平均",ROUND(AVERAGE($E8:$G8),0),IF($H8="線形トレンド",MAX(0,ROUND($G8+2*($G8-$D8)/3,0)),IF($H8="人口比率型",IFERROR(ROUND($G8/人口基礎データ!$F$7*人口基礎データ!$H$7,0),$G8),IF($H8="政策調整",IF($J8="",$G8,$J8),$G8)))))) -> 1 | N8: =IF($H8="直近実績横ばい",$G8,IF($H8="直近2年平均",ROUND(AVERAGE($F8:$G8),0),IF($H8="直近3年平均",ROUND(AVERAGE($E8:$G8),0),IF($H8="線形トレンド",MAX(0,ROUND($G8+3*($G8-$D8)/3,0)),IF($H8="人口比率型",IFERROR(ROUND($G8/人口基礎データ!$F$7*人口基礎データ!$I$7,0),$G8),IF($H8="政策調整",IF($K8="",$G8,$K8),$G8)))))) -> 1 | O8: 0 | P8: 0 | Q8: 0 | R8: 0 | S8: 政策調整 | T8: 1 | U8: 1 | V8: 1 | W8: =IF($S8="-","-",IF($S8="直近実績横ばい",$R8,IF($S8="直近2年平均",ROUND(AVERAGE($Q8:$R8),0),IF($S8="利用者数連動",IFERROR(ROUND($L8*(($Q8+$R8)/($F8+$G8)),0),0),IF($S8="政策調整",IF($T8="","",$T8),""))))) -> 1 | X8: =IF($S8="-","-",IF($S8="直近実績横ばい",$R8,IF($S8="直近2年平均",ROUND(AVERAGE($Q8:$R8),0),IF($S8="利用者数連動",IFERROR(ROUND($M8*(($Q8+$R8)/($F8+$G8)),0),0),IF($S8="政策調整",IF($U8="","",$U8),""))))) -> 1 | Y8: =IF($S8="-","-",IF($S8="直近実績横ばい",$R8,IF($S8="直近2年平均",ROUND(AVERAGE($Q8:$R8),0),IF($S8="利用者数連動",IFERROR(ROUND($N8*(($Q8+$R8)/($F8+$G8)),0),0),IF($S8="政策調整",IF($V8="","",$V8),""))))) -> 1 | Z8: インクルージョン推進の観点から利用実績0でも活用可能な体制を前提に月1人を初期設定。
A9: 障害児通所 | B9: 居宅訪問型児童発達支援 | C9: 人日/月 | D9: 0 | E9: 0 | F9: 0 | G9: 0 | H9: 直近実績横ばい | L9: =IF($H9="直近実績横ばい",$G9,IF($H9="直近2年平均",ROUND(AVERAGE($F9:$G9),0),IF($H9="直近3年平均",ROUND(AVERAGE($E9:$G9),0),IF($H9="線形トレンド",MAX(0,ROUND($G9+1*($G9-$D9)/3,0)),IF($H9="人口比率型",IFERROR(ROUND($G9/人口基礎データ!$F$7*人口基礎データ!$G$7,0),$G9),IF($H9="政策調整",IF($I9="",$G9,$I9),$G9)))))) -> 0 | M9: =IF($H9="直近実績横ばい",$G9,IF($H9="直近2年平均",ROUND(AVERAGE($F9:$G9),0),IF($H9="直近3年平均",ROUND(AVERAGE($E9:$G9),0),IF($H9="線形トレンド",MAX(0,ROUND($G9+2*($G9-$D9)/3,0)),IF($H9="人口比率型",IFERROR(ROUND($G9/人口基礎データ!$F$7*人口基礎データ!$H$7,0),$G9),IF($H9="政策調整",IF($J9="",$G9,$J9),$G9)))))) -> 0 | N9: =IF($H9="直近実績横ばい",$G9,IF($H9="直近2年平均",ROUND(AVERAGE($F9:$G9),0),IF($H9="直近3年平均",ROUND(AVERAGE($E9:$G9),0),IF($H9="線形トレンド",MAX(0,ROUND($G9+3*($G9-$D9)/3,0)),IF($H9="人口比率型",IFERROR(ROUND($G9/人口基礎データ!$F$7*人口基礎データ!$I$7,0),$G9),IF($H9="政策調整",IF($K9="",$G9,$K9),$G9)))))) -> 0 | O9: 0 | P9: 0 | Q9: 0 | R9: 0 | S9: 直近実績横ばい | W9: =IF($S9="-","-",IF($S9="直近実績横ばい",$R9,IF($S9="直近2年平均",ROUND(AVERAGE($Q9:$R9),0),IF($S9="利用者数連動",IFERROR(ROUND($L9*(($Q9+$R9)/($F9+$G9)),0),0),IF($S9="政策調整",IF($T9="","",$T9),""))))) -> 0 | X9: =IF($S9="-","-",IF($S9="直近実績横ばい",$R9,IF($S9="直近2年平均",ROUND(AVERAGE($Q9:$R9),0),IF($S9="利用者数連動",IFERROR(ROUND($M9*(($Q9+$R9)/($F9+$G9)),0),0),IF($S9="政策調整",IF($U9="","",$U9),""))))) -> 0 | Y9: =IF($S9="-","-",IF($S9="直近実績横ばい",$R9,IF($S9="直近2年平均",ROUND(AVERAGE($Q9:$R9),0),IF($S9="利用者数連動",IFERROR(ROUND($N9*(($Q9+$R9)/($F9+$G9)),0),0),IF($S9="政策調整",IF($V9="","",$V9),""))))) -> 0 | Z9: 4年間実績0。対象児の発生時に見直し。
A10: 障害児相談 | B10: 障害児相談支援 | C10: - | D10: 3 | E10: 4 | F10: 4 | G10: 0 | H10: 政策調整 | I10: 4 | J10: 5 | K10: 5 | L10: =IF($H10="直近実績横ばい",$G10,IF($H10="直近2年平均",ROUND(AVERAGE($F10:$G10),0),IF($H10="直近3年平均",ROUND(AVERAGE($E10:$G10),0),IF($H10="線形トレンド",MAX(0,ROUND($G10+1*($G10-$D10)/3,0)),IF($H10="人口比率型",IFERROR(ROUND($G10/人口基礎データ!$F$7*人口基礎データ!$G$7,0),$G10),IF($H10="政策調整",IF($I10="",$G10,$I10),$G10)))))) -> 4 | M10: =IF($H10="直近実績横ばい",$G10,IF($H10="直近2年平均",ROUND(AVERAGE($F10:$G10),0),IF($H10="直近3年平均",ROUND(AVERAGE($E10:$G10),0),IF($H10="線形トレンド",MAX(0,ROUND($G10+2*($G10-$D10)/3,0)),IF($H10="人口比率型",IFERROR(ROUND($G10/人口基礎データ!$F$7*人口基礎データ!$H$7,0),$G10),IF($H10="政策調整",IF($J10="",$G10,$J10),$G10)))))) -> 5 | N10: =IF($H10="直近実績横ばい",$G10,IF($H10="直近2年平均",ROUND(AVERAGE($F10:$G10),0),IF($H10="直近3年平均",ROUND(AVERAGE($E10:$G10),0),IF($H10="線形トレンド",MAX(0,ROUND($G10+3*($G10-$D10)/3,0)),IF($H10="人口比率型",IFERROR(ROUND($G10/人口基礎データ!$F$7*人口基礎データ!$I$7,0),$G10),IF($H10="政策調整",IF($K10="",$G10,$K10),$G10)))))) -> 5 | O10: - | P10: - | Q10: - | R10: - | S10: - | W10: =IF($S10="-","-",IF($S10="直近実績横ばい",$R10,IF($S10="直近2年平均",ROUND(AVERAGE($Q10:$R10),0),IF($S10="利用者数連動",IFERROR(ROUND($L10*(($Q10+$R10)/($F10+$G10)),0),0),IF($S10="政策調整",IF($T10="","",$T10),""))))) -> - | X10: =IF($S10="-","-",IF($S10="直近実績横ばい",$R10,IF($S10="直近2年平均",ROUND(AVERAGE($Q10:$R10),0),IF($S10="利用者数連動",IFERROR(ROUND($M10*(($Q10+$R10)/($F10+$G10)),0),0),IF($S10="政策調整",IF($U10="","",$U10),""))))) -> - | Y10: =IF($S10="-","-",IF($S10="直近実績横ばい",$R10,IF($S10="直近2年平均",ROUND(AVERAGE($Q10:$R10),0),IF($S10="利用者数連動",IFERROR(ROUND($N10*(($Q10+$R10)/($F10+$G10)),0),0),IF($S10="政策調整",IF($V10="","",$V10),""))))) -> - | Z10: R8実績0は要確認。伴走的相談支援・セルフプラン解消を踏まえ、R9以降は回復・拡充を見込む。

Sheet 地域生活支援事業
A1: 地域生活支援事業・相談支援体制 見込量／確認表
A2: ※元ワークシートでR6～R8実績が未入力の項目が多いため、実績が揃っている項目のみ初期見込を設定し、不足項目は「要確認」としています。
A5: 区分 | B5: 項目 | C5: 単位 | D5: R5実績 | E5: R6実績 | F5: R7実績 | G5: R8実績 | H5: 設定方法 | I5: 政策R9 | J5: 政策R10 | K5: 政策R11 | L5: R9採用 | M5: R10採用 | N5: R11採用 | O5: 確認事項・備考
A6: 必須 | B6: 理解促進研修・啓発事業（利用者数） | C6: 人/月 | D6: 0 | E6: 2 | F6: 2 | G6: 2 | H6: 直近実績横ばい | L6: =IF($H6="政策調整",$I6,IF($H6="直近実績横ばい",$G6,IF($H6="直近2年平均",ROUND(AVERAGE($F6:$G6),0),""))) -> 2 | M6: =IF($H6="政策調整",$J6,IF($H6="直近実績横ばい",$G6,IF($H6="直近2年平均",ROUND(AVERAGE($F6:$G6),0),""))) -> 2 | N6: =IF($H6="政策調整",$K6,IF($H6="直近実績横ばい",$G6,IF($H6="直近2年平均",ROUND(AVERAGE($F6:$G6),0),""))) -> 2 | O6: R8実績を維持。
A7: 必須 | B7: 理解促進研修・啓発事業（サービス量） | C7: 人日/月 | E7: 16 | F7: 16 | G7: 16 | H7: 直近実績横ばい | L7: =IF($H7="政策調整",$I7,IF($H7="直近実績横ばい",$G7,IF($H7="直近2年平均",ROUND(AVERAGE($F7:$G7),0),""))) -> 16 | M7: =IF($H7="政策調整",$J7,IF($H7="直近実績横ばい",$G7,IF($H7="直近2年平均",ROUND(AVERAGE($F7:$G7),0),""))) -> 16 | N7: =IF($H7="政策調整",$K7,IF($H7="直近実績横ばい",$G7,IF($H7="直近2年平均",ROUND(AVERAGE($F7:$G7),0),""))) -> 16 | O7: R6～R8は16で安定。
A8: 必須 | B8: 自発的活動支援事業（利用者数） | C8: 人/月 | D8: 0 | E8: 2 | F8: 2 | G8: 2 | H8: 直近実績横ばい | L8: =IF($H8="政策調整",$I8,IF($H8="直近実績横ばい",$G8,IF($H8="直近2年平均",ROUND(AVERAGE($F8:$G8),0),""))) -> 2 | M8: =IF($H8="政策調整",$J8,IF($H8="直近実績横ばい",$G8,IF($H8="直近2年平均",ROUND(AVERAGE($F8:$G8),0),""))) -> 2 | N8: =IF($H8="政策調整",$K8,IF($H8="直近実績横ばい",$G8,IF($H8="直近2年平均",ROUND(AVERAGE($F8:$G8),0),""))) -> 2 | O8: R8実績を維持。
A9: 必須 | B9: 自発的活動支援事業（サービス量） | C9: 人日/月 | E9: 16 | F9: 16 | G9: 16 | H9: 直近実績横ばい | L9: =IF($H9="政策調整",$I9,IF($H9="直近実績横ばい",$G9,IF($H9="直近2年平均",ROUND(AVERAGE($F9:$G9),0),""))) -> 16 | M9: =IF($H9="政策調整",$J9,IF($H9="直近実績横ばい",$G9,IF($H9="直近2年平均",ROUND(AVERAGE($F9:$G9),0),""))) -> 16 | N9: =IF($H9="政策調整",$K9,IF($H9="直近実績横ばい",$G9,IF($H9="直近2年平均",ROUND(AVERAGE($F9:$G9),0),""))) -> 16 | O9: R6～R8は16で安定。
A10: 相談支援 | B10: 委託相談支援 | C10: 事業所数 | E10: 2 | F10: 2 | G10: 2 | H10: 直近実績横ばい | L10: =IF($H10="政策調整",$I10,IF($H10="直近実績横ばい",$G10,IF($H10="直近2年平均",ROUND(AVERAGE($F10:$G10),0),""))) -> 2 | M10: =IF($H10="政策調整",$J10,IF($H10="直近実績横ばい",$G10,IF($H10="直近2年平均",ROUND(AVERAGE($F10:$G10),0),""))) -> 2 | N10: =IF($H10="政策調整",$K10,IF($H10="直近実績横ばい",$G10,IF($H10="直近2年平均",ROUND(AVERAGE($F10:$G10),0),""))) -> 2 | O10: R6～R8は2事業所。
A11: 相談支援 | B11: 基幹相談支援センター | C11: 設置の有無 | E11: 〇 | F11: 〇 | G11: 〇 | H11: 政策調整 | I11: 〇 | J11: 〇 | K11: 〇 | L11: =IF($H11="政策調整",$I11,IF($H11="直近実績横ばい",$G11,IF($H11="直近2年平均",ROUND(AVERAGE($F11:$G11),0),""))) -> 〇 | M11: =IF($H11="政策調整",$J11,IF($H11="直近実績横ばい",$G11,IF($H11="直近2年平均",ROUND(AVERAGE($F11:$G11),0),""))) -> 〇 | N11: =IF($H11="政策調整",$K11,IF($H11="直近実績横ばい",$G11,IF($H11="直近2年平均",ROUND(AVERAGE($F11:$G11),0),""))) -> 〇 | O11: 現行ワークシートではR6～R8「〇」。機能強化・協議会等との連携状況を確認。
A12: 権利擁護 | B12: 障がい者虐待防止センター | C12: 実施の有無 | E12: 〇 | F12: 〇 | G12: 〇 | H12: 政策調整 | I12: 〇 | J12: 〇 | K12: 〇 | L12: =IF($H12="政策調整",$I12,IF($H12="直近実績横ばい",$G12,IF($H12="直近2年平均",ROUND(AVERAGE($F12:$G12),0),""))) -> 〇 | M12: =IF($H12="政策調整",$J12,IF($H12="直近実績横ばい",$G12,IF($H12="直近2年平均",ROUND(AVERAGE($F12:$G12),0),""))) -> 〇 | N12: =IF($H12="政策調整",$K12,IF($H12="直近実績横ばい",$G12,IF($H12="直近2年平均",ROUND(AVERAGE($F12:$G12),0),""))) -> 〇 | O12: 継続実施。
A13: 地域共生 | B13: 共生推進委員会 | C13: 実施の有無 | E13: 〇 | F13: 〇 | G13: 〇 | H13: 政策調整 | I13: 〇 | J13: 〇 | K13: 〇 | L13: =IF($H13="政策調整",$I13,IF($H13="直近実績横ばい",$G13,IF($H13="直近2年平均",ROUND(AVERAGE($F13:$G13),0),""))) -> 〇 | M13: =IF($H13="政策調整",$J13,IF($H13="直近実績横ばい",$G13,IF($H13="直近2年平均",ROUND(AVERAGE($F13:$G13),0),""))) -> 〇 | N13: =IF($H13="政策調整",$K13,IF($H13="直近実績横ばい",$G13,IF($H13="直近2年平均",ROUND(AVERAGE($F13:$G13),0),""))) -> 〇 | O13: 継続実施。
A14: 権利擁護 | B14: 成年後見制度利用支援事業 | C14: 人/年 | D14: 0 | H14: 要確認 | L14: =IF($H14="政策調整",$I14,IF($H14="直近実績横ばい",$G14,IF($H14="直近2年平均",ROUND(AVERAGE($F14:$G14),0),""))) | M14: =IF($H14="政策調整",$J14,IF($H14="直近実績横ばい",$G14,IF($H14="直近2年平均",ROUND(AVERAGE($F14:$G14),0),""))) | N14: =IF($H14="政策調整",$K14,IF($H14="直近実績横ばい",$G14,IF($H14="直近2年平均",ROUND(AVERAGE($F14:$G14),0),""))) | O14: R6～R8実績が未入力。地域福祉計画との整合を確認。
A15: 意思疎通 | B15: 手話通訳者派遣事業 | C15: 件/年 | D15: 0 | H15: 要確認 | L15: =IF($H15="政策調整",$I15,IF($H15="直近実績横ばい",$G15,IF($H15="直近2年平均",ROUND(AVERAGE($F15:$G15),0),""))) | M15: =IF($H15="政策調整",$J15,IF($H15="直近実績横ばい",$G15,IF($H15="直近2年平均",ROUND(AVERAGE($F15:$G15),0),""))) | N15: =IF($H15="政策調整",$K15,IF($H15="直近実績横ばい",$G15,IF($H15="直近2年平均",ROUND(AVERAGE($F15:$G15),0),""))) | O15: R6～R8実績未入力。
A16: 意思疎通 | B16: 要約筆記者派遣事業 | C16: 件/年 | D16: 0 | H16: 要確認 | L16: =IF($H16="政策調整",$I16,IF($H16="直近実績横ばい",$G16,IF($H16="直近2年平均",ROUND(AVERAGE($F16:$G16),0),""))) | M16: =IF($H16="政策調整",$J16,IF($H16="直近実績横ばい",$G16,IF($H16="直近2年平均",ROUND(AVERAGE($F16:$G16),0),""))) | N16: =IF($H16="政策調整",$K16,IF($H16="直近実績横ばい",$G16,IF($H16="直近2年平均",ROUND(AVERAGE($F16:$G16),0),""))) | O16: R6～R8実績未入力。
A17: 意思疎通 | B17: 手話通訳者設置事業 | C17: 件/年 | D17: 0 | H17: 要確認 | L17: =IF($H17="政策調整",$I17,IF($H17="直近実績横ばい",$G17,IF($H17="直近2年平均",ROUND(AVERAGE($F17:$G17),0),""))) | M17: =IF($H17="政策調整",$J17,IF($H17="直近実績横ばい",$G17,IF($H17="直近2年平均",ROUND(AVERAGE($F17:$G17),0),""))) | N17: =IF($H17="政策調整",$K17,IF($H17="直近実績横ばい",$G17,IF($H17="直近2年平均",ROUND(AVERAGE($F17:$G17),0),""))) | O17: R6～R8実績未入力。
A18: 日常生活用具 | B18: 排泄管理支援用具 | C18: 件/年 | D18: 277 | H18: 要確認 | L18: =IF($H18="政策調整",$I18,IF($H18="直近実績横ばい",$G18,IF($H18="直近2年平均",ROUND(AVERAGE($F18:$G18),0),""))) | M18: =IF($H18="政策調整",$J18,IF($H18="直近実績横ばい",$G18,IF($H18="直近2年平均",ROUND(AVERAGE($F18:$G18),0),""))) | N18: =IF($H18="政策調整",$K18,IF($H18="直近実績横ばい",$G18,IF($H18="直近2年平均",ROUND(AVERAGE($F18:$G18),0),""))) | O18: R6～R8実績未入力。R5実績277件。
A19: 人材養成 | B19: 手話奉仕員養成研修事業 | C19: 人/年 | D19: 0 | E19: 20 | F19: 20 | G19: 20 | H19: 直近実績横ばい | L19: =IF($H19="政策調整",$I19,IF($H19="直近実績横ばい",$G19,IF($H19="直近2年平均",ROUND(AVERAGE($F19:$G19),0),""))) -> 20 | M19: =IF($H19="政策調整",$J19,IF($H19="直近実績横ばい",$G19,IF($H19="直近2年平均",ROUND(AVERAGE($F19:$G19),0),""))) -> 20 | N19: =IF($H19="政策調整",$K19,IF($H19="直近実績横ばい",$G19,IF($H19="直近2年平均",ROUND(AVERAGE($F19:$G19),0),""))) -> 20 | O19: R6～R8は20人で安定。
A20: 移動支援 | B20: 移動支援事業（利用者数） | C20: 人/月 | D20: 0 | H20: 要確認 | L20: =IF($H20="政策調整",$I20,IF($H20="直近実績横ばい",$G20,IF($H20="直近2年平均",ROUND(AVERAGE($F20:$G20),0),""))) | M20: =IF($H20="政策調整",$J20,IF($H20="直近実績横ばい",$G20,IF($H20="直近2年平均",ROUND(AVERAGE($F20:$G20),0),""))) | N20: =IF($H20="政策調整",$K20,IF($H20="直近実績横ばい",$G20,IF($H20="直近2年平均",ROUND(AVERAGE($F20:$G20),0),""))) | O20: R6～R8実績未入力。
A21: 移動支援 | B21: 移動支援事業（時間数） | C21: 時間/月 | D21: 0 | H21: 要確認 | L21: =IF($H21="政策調整",$I21,IF($H21="直近実績横ばい",$G21,IF($H21="直近2年平均",ROUND(AVERAGE($F21:$G21),0),""))) | M21: =IF($H21="政策調整",$J21,IF($H21="直近実績横ばい",$G21,IF($H21="直近2年平均",ROUND(AVERAGE($F21:$G21),0),""))) | N21: =IF($H21="政策調整",$K21,IF($H21="直近実績横ばい",$G21,IF($H21="直近2年平均",ROUND(AVERAGE($F21:$G21),0),""))) | O21: R6～R8実績未入力。
A22: 地域活動 | B22: 地域活動支援センター（箇所数） | C22: 箇所 | H22: 要確認 | L22: =IF($H22="政策調整",$I22,IF($H22="直近実績横ばい",$G22,IF($H22="直近2年平均",ROUND(AVERAGE($F22:$G22),0),""))) | M22: =IF($H22="政策調整",$J22,IF($H22="直近実績横ばい",$G22,IF($H22="直近2年平均",ROUND(AVERAGE($F22:$G22),0),""))) | N22: =IF($H22="政策調整",$K22,IF($H22="直近実績横ばい",$G22,IF($H22="直近2年平均",ROUND(AVERAGE($F22:$G22),0),""))) | O22: 実績未入力。
A23: 地域活動 | B23: 地域活動支援センター（利用者数） | C23: 人/年 | D23: 0 | H23: 要確認 | L23: =IF($H23="政策調整",$I23,IF($H23="直近実績横ばい",$G23,IF($H23="直近2年平均",ROUND(AVERAGE($F23:$G23),0),""))) | M23: =IF($H23="政策調整",$J23,IF($H23="直近実績横ばい",$G23,IF($H23="直近2年平均",ROUND(AVERAGE($F23:$G23),0),""))) | N23: =IF($H23="政策調整",$K23,IF($H23="直近実績横ばい",$G23,IF($H23="直近2年平均",ROUND(AVERAGE($F23:$G23),0),""))) | O23: R6～R8実績未入力。
A24: 任意 | B24: 訪問入浴サービス事業（利用者数） | C24: 人/月 | D24: 1 | H24: 要確認 | L24: =IF($H24="政策調整",$I24,IF($H24="直近実績横ばい",$G24,IF($H24="直近2年平均",ROUND(AVERAGE($F24:$G24),0),""))) | M24: =IF($H24="政策調整",$J24,IF($H24="直近実績横ばい",$G24,IF($H24="直近2年平均",ROUND(AVERAGE($F24:$G24),0),""))) | N24: =IF($H24="政策調整",$K24,IF($H24="直近実績横ばい",$G24,IF($H24="直近2年平均",ROUND(AVERAGE($F24:$G24),0),""))) | O24: R6～R8実績未入力。
A25: 任意 | B25: 日中一時支援事業（利用者数） | C25: 人/年 | D25: 24 | H25: 要確認 | L25: =IF($H25="政策調整",$I25,IF($H25="直近実績横ばい",$G25,IF($H25="直近2年平均",ROUND(AVERAGE($F25:$G25),0),""))) | M25: =IF($H25="政策調整",$J25,IF($H25="直近実績横ばい",$G25,IF($H25="直近2年平均",ROUND(AVERAGE($F25:$G25),0),""))) | N25: =IF($H25="政策調整",$K25,IF($H25="直近実績横ばい",$G25,IF($H25="直近2年平均",ROUND(AVERAGE($F25:$G25),0),""))) | O25: R6～R8実績未入力。
A26: 任意 | B26: 自動車運転免許取得・自動車改造助成事業 | C26: 件/年 | D26: 0 | H26: 要確認 | L26: =IF($H26="政策調整",$I26,IF($H26="直近実績横ばい",$G26,IF($H26="直近2年平均",ROUND(AVERAGE($F26:$G26),0),""))) | M26: =IF($H26="政策調整",$J26,IF($H26="直近実績横ばい",$G26,IF($H26="直近2年平均",ROUND(AVERAGE($F26:$G26),0),""))) | N26: =IF($H26="政策調整",$K26,IF($H26="直近実績横ばい",$G26,IF($H26="直近2年平均",ROUND(AVERAGE($F26:$G26),0),""))) | O26: R6～R8実績未入力。

Sheet 成果目標算定
A1: 成果目標・体制整備目標（令和11年度末）－小野町
A2: ※令和8年3月31日告示の国基本指針に基づく初期設定。令和8年10月改正予定のため、最終確定前に最新告示・福島県方針を再確認してください。
A5: 区分 | B5: 指標 | C5: 基準年度 | D5: 基準値 | E5: 国の基準 | F5: 率・倍率 | G5: R11目標値 | H5: 単位 | I5: 小野町の設定・状況 | J5: 確認 | K5: 所管 | L5: 出典・備考
A6: 地域生活移行 | B6: 地域生活移行者数 | C6: R7年度末 | D6: ='見込量算定(障害福祉)'!F24 -> 19 | E6: 施設入所者の6％以上 | F6: 0.06 | G6: =ROUNDUP(D6*F6,0) -> 2 | H6: 人 | I6: 2人以上 | K6: 町 | L6: 国基本指針 第二・一
A7: 地域生活移行 | B7: 施設入所者削減数 | C7: R7年度末 | D7: =D6 -> 19 | E7: 施設入所者の5％以上削減 | F7: 0.05 | G7: =ROUNDUP(D7*F7,0) -> 1 | H7: 人 | I7: 1人以上 | K7: 町 | L7: 国基本指針 第二・一
A8: 地域生活移行 | B8: R11年度末施設入所者数 | C8: R7年度末 | D8: =D6 -> 19 | E8: 基準値－削減数 | F8: - | G8: =D8-G7 -> 18 | H8: 人 | I8: 18人以下 | K8: 町 | L8: 上記から算定
A9: 一般就労 | B9: 一般就労移行者数（就労移行支援事業等計） | C9: R6年度 | E9: R6実績の1.31倍以上 | F9: 1.31 | G9: =IF(D9="","",ROUNDUP(D9*F9,0)) | H9: 人 | J9: 要入力 | K9: 町 | L9: 国基本指針 第二・三
A10: 一般就労 | B10: 就労移行支援から一般就労へ移行 | C10: R6年度 | E10: R6実績の1.14倍以上 | F10: 1.14 | G10: =IF(D10="","",ROUNDUP(D10*F10,0)) | H10: 人 | J10: 要入力 | K10: 町 | L10: 国基本指針 第二・三
A11: 一般就労 | B11: 就労継続支援A型から一般就労へ移行 | C11: R6年度 | E11: R6実績のおおむね1.52倍以上 | F11: 1.52 | G11: =IF(D11="","",ROUNDUP(D11*F11,0)) | H11: 人 | J11: 要入力 | K11: 町 | L11: 国基本指針 第二・三
A12: 一般就労 | B12: 就労継続支援B型から一般就労へ移行 | C12: R6年度 | E12: R6実績のおおむね1.67倍以上 | F12: 1.67 | G12: =IF(D12="","",ROUNDUP(D12*F12,0)) | H12: 人 | J12: 要入力 | K12: 町 | L12: 国基本指針 第二・三
A13: 一般就労 | B13: 就労定着支援利用者数 | C13: R6年度 | D13: ='見込量算定(障害福祉)'!E18 -> 1 | E13: R6実績の1.47倍以上 | F13: 1.47 | G13: =ROUNDUP(D13*F13,0) -> 2 | H13: 人 | I13: 2人以上 | K13: 町 | L13: 国基本指針 第二・三
A14: 一般就労 | B14: 一般就労移行率5割以上の就労移行支援事業所割合 | C14: R11年度 | D14: - | E14: 50％以上 | F14: 0.5 | G14: 0.5 | H14: % | I14: 50％以上 | J14: 圏域事業所状況確認 | K14: 町/県 | L14: 国基本指針 第二・三
A15: 一般就労 | B15: 就労定着率7割以上の就労定着支援事業所割合 | C15: R11年度 | D15: - | E15: 25％以上 | F15: 0.25 | G15: 0.25 | H15: % | I15: 25％以上 | J15: 圏域事業所状況確認 | K15: 町/県 | L15: 国基本指針 第二・三
A16: 一般就労 | B16: 就労選択支援事業所 | C16: R11年度 | D16: - | E16: 協議会圏域ごと1事業所以上 | F16: - | G16: 1 | H16: 事業所以上 | I16: 圏域で1か所以上 | J16: 圏域確認 | K16: 町/県 | L16: 国基本指針 第二・三
A17: 障害児支援 | B17: 児童発達支援センター等の4つの中核機能 | C17: R11年度 | D17: - | E17: 各市町村で機能確保（圏域可） | F17: - | G17: 確保 | H17: - | I17: 町又は圏域で確保 | J17: 要確認 | K17: 町 | L17: 国基本指針 第二・四
A18: 障害児支援 | B18: インクルージョン推進のための協議の場 | C18: R11年度 | D18: - | E18: 各市町村で設置（圏域可） | F18: - | G18: 設置 | H18: - | I18: 設置 | J18: 要確認 | K18: 町 | L18: 国基本指針 第二・四
A19: 障害児支援 | B19: 主に重症心身障がい児を支援する児童発達支援・放デイ事業所 | C19: R11年度 | D19: - | E19: 各市町村に1か所以上（圏域可） | F19: - | G19: 1 | H19: か所以上 | I19: 町又は圏域で1か所以上 | J19: 要確認 | K19: 町 | L19: 国基本指針 第二・四
