Workbook

Sheet 00_使い方
A1: 小野町 第10期介護保険事業計画 サービス見込量・保険料 算定シート
A2: 作成日：2026-09-09
A4: ■ 本シートの位置づけ
A5: 委託仕様書4(2)が定める「サービス見込量の推計」及び「想定されるケースごとの保険料の算定」を行うための算定シートです。
A6: 算式は実装済みです。令和8年9月8日に介護保険事業状況報告（年報）令和3〜7年度を受領したため、人口・認定者数・所得段階別被保険者数・収納率は実績を投入済みです（11_実績（年報）参照）。
A7: 残る入力欄は、サービス別の見込量（05・06）、地域支援事業費（07）、調整交付金見込額・基金取崩額（09）です。
A9: ■ セルの色
A10: 黄色 | B10: 入力欄。町からの受領データ、見える化システムの出力、政策判断による設定値を入れます
A11: 水色 | B11: 算式。触らないでください
A12: 赤色 | B12: 算定結果（保険料基準額など）
A14: ■ 算定の流れ
A15: 1 | B15: 02_人口・被保険者 | C15: 見える化システムの人口推計から、令和9〜11年度の被保険者数を入力
A16: 2 | B16: 03_認定者推計 | C16: 認定率を入力すると、要介護度別の認定者数が算出されます
A17: 3 | B17: 04_受給率 | C17: 認定者に対する受給者の比率を入力
A18: 4 | B18: 05_見込量_介護 | C18: サービス別の利用者数・回数・単価を入力すると給付費が算出されます
A19: 5 | B19: 06_見込量_予防 | C19: 同上（予防給付）
A20: 6 | B20: 07_地域支援事業 | C20: 介護予防・日常生活支援総合事業、包括的支援事業、任意事業の事業費を入力
A21: 7 | B21: 08_標準給付費 | C21: 05〜07が集計され、標準給付費見込額が算出されます
A22: 8 | B22: 09_保険料算定 | C22: 負担割合・調整交付金・基金取崩・収納率・所得段階別人数を入力すると保険料基準額が出ます
A23: 9 | B23: 10_ケース比較 | C23: 01で定義した各ケースの結果を並べます
A25: ■ ケースの考え方（仕様書4(2)）
A26: 仕様書は「新たに介護施設を整備する場合や制度改正により条件が変わる場合等」を例示しています。
A27: 引継ぎ時点のテンプレートは基金の取扱いによる3ケースのみで、仕様書の例示に対応していませんでした。
A28: 本シートでは、政策要因（施設整備・制度改正・基金）に加え、本町固有の事情として「認定者数の前提」を軸に加えています。
A29: 令和8年3月末の認定者数は20期の系列で唯一の大幅減（▲152人）であり、確認中です。
A30: 確定値が792人か900人台かで給付費は2割近く動くため、前提を1つに固定して算定すると、確認結果しだいで全面やり直しになります。
A32: ■ 受領済みのデータ（令和8年9月8日）
B33: 令和8年3月末の認定者数 792人 **年報 様式1の5で確定**
B34: 令和3〜7年度 サービス別給付費・受給者数 年報 様式2・様式1の6
B35: 所得段階別第1号被保険者数と保険料率 年報 様式1 所得段階別
B36: 保険料収納率 99.35％ 年報 様式3
B37: 第10期将来推計用推計人口（男女別・5歳階級別）
A39: ■ 残る未受領のデータ
B40: 地域支援事業費の実績と事業別内訳（年報 様式4は令和7年度が未入力）
B41: 令和7年度の介護保険特別会計決算（様式4が全て0）
B42: 介護給付費準備基金の取崩方針（保有額は12,000千円だが第9期は35,000千円の取崩を見込んでいた）
B43: 令和7年8〜9月の認定者数の計上方法の変更の有無
A45: ■ 第9期の算定根拠（参考・第9期計画本文より）
A46: 標準給付費見込額（3年計） | B46: 3,566,486千円
A47: 準備基金取崩額 | B47: 35,000千円
...

Sheet 01_ケース定義
A1: ケース | B1: 名称 | C1: 認定者数の前提 | D1: 施設整備 | E1: 制度改正 | F1: 基金取崩 | G1: 設定の趣旨 | H1: 仕様書との対応
A2: C1 | B2: 標準（低位） | C2: 令和8年3月末792人を実勢とみる。以後は人口推計に認定率を乗じる | D2: 新規整備なし（第9期方針を継承） | E2: 織り込まない | F2: 第9期と同水準 | G2: 見える化システムの出力をそのまま前提とする、最も機械的なケース。確認の結果792人が正しければこれが基準になる | H2: 仕様書4(2)の基本ケース
A3: C2 | B3: 標準（高位） | C3: 令和7年7月末953人の水準を実勢とみる。792人は一時的な減少とみて補正する | D3: 新規整備なし | E3: 織り込まない | F3: 第9期と同水準 | G3: **認定者数の減少が更新認定の運用等による一時的なものであった場合。**20期の系列では令和2年度以外に減少年がなく、こちらが趨勢に沿う | H3: 同上（本町固有のリスクへの対応）
A4: C3 | B4: 施設整備あり | C4: C1と同じ | D4: **計画期間中に施設又は居住系サービスを整備する** | E4: 織り込まない | F4: 第9期と同水準 | G4: 仕様書が明示的に例示するケース。整備の内容・定員・開設時期を入力すると、在宅から施設への移行と給付費の増を反映する | H4: **仕様書4(2)「新たに介護施設を整備する場合」**
A5: C4 | B5: 制度改正の影響 | C5: C1と同じ | D5: 新規整備なし | E5: **利用者負担、報酬改定、支給限度額、第2号被保険者の負担率等の改正を織り込む** | F5: 第9期と同水準 | G5: 仕様書が明示的に例示するケース。国の制度改正の内容が示された時点でパラメータを入れる。示されるまでは感度分析として幅で持つ | H5: **仕様書4(2)「制度改正により条件が変わる場合」**
A6: C5 | B6: 基金活用 | C6: C1と同じ | D6: 新規整備なし | E6: 織り込まない | F6: **準備基金を取り崩し、保険料の上昇を抑制する** | G6: 繰越金182.0百万円・基金純増88.1百万円という財政余剰の還元。取崩額を変えて保険料への影響を示す | H6: 仕様書4(2)（引継ぎテンプレートの3ケースはこの軸のみ）
A7: C6 | B7: 保険料抑制（据置） | C7: C1と同じ | D7: 新規整備なし | E7: 織り込まない | F7: **保険料基準額を第9期（6,600円）に据え置くために必要な取崩額を逆算** | G7: 保険料を先に決め、必要な基金取崩額を求める逆算ケース。協議会に「据え置くとしたら基金がいくら必要か」を示すために使う | H7: 同上
A9: ※ C1とC2は認定者数の前提が異なるだけで、他の条件は同じです。**この2ケースの差が、認定者数の確認が済むまでの不確実性の幅を表します。**
A10: ※ C3〜C6はC1を基準にした差分です。C2を基準にした組合せも必要に応じて算定します。
A11: ※ 第10期の第1号被保険者負担割合・調整交付金の考え方は国の基本指針で示されます。示されるまでは第9期の値（23％）を仮置きします。

Sheet 02_人口・被保険者
A1: 区分 | B1: 令和7年度（実績） | C1: 令和8年度（見込） | D1: 令和9年度（推計） | E1: 令和10年度（推計） | F1: 令和11年度（推計） | G1: 出典・備考
A2: 総人口 | C2: 8771 | D2: 8591 | E2: 8411 | F2: 8232 | G2: 第10期将来推計用推計人口（各年10月1日）
A3: 第1号被保険者数（65歳以上） | B3: 3443 | C3: 3449 | D3: 3438 | E3: 3428 | F3: 3418 | G3: 令和7年度は年報 様式1（年度末現在）。令和8年度以降は推計（10月1日）
A4: 前期高齢者（65〜74歳） | B4: 1634 | C4: 1613 | D4: 1583 | E4: 1554 | F4: 1524 | G4: 同上
A5: 後期高齢者（75〜84歳） | B5: 1090 | C5: 1117 | D5: 1150 | E5: 1183 | F5: 1217 | G5: **計画期間中に1,150人→1,217人へ増える。第1号全体は横ばいでも構成が変わる**
A6: 85歳以上 | B6: 719 | C6: 719 | D6: 705 | E6: 691 | F6: 677 | G6: **705人→677人へ減る。認定者の約2/3を占める層が縮む**
A7: 第2号被保険者数（40〜64歳） | C7: 2295 | D7: 2251 | E7: 2207 | F7: 2163 | G7: 推計人口の40〜64歳
A8: 高齢化率（％） | B8: =IF(B2=0,"",B3/B2*100) | C8: =IF(C2=0,"",C3/C2*100) | D8: =IF(D2=0,"",D3/D2*100) | E8: =IF(E2=0,"",E3/E2*100) | F8: =IF(F2=0,"",F3/F2*100) | G8: 第1号÷総人口（算式）
A10: ※ 第1号被保険者数は前期（65〜74歳）＋後期（75〜84歳）＋85歳以上と一致すること。
A11: ※ **令和7年度は年報の実績（年度末現在）、令和8年度以降は第10期将来推計用推計人口（各年10月1日時点）。基準日が異なるため、そのまま接続すると段差が出る。**計画本文では基準日をそろえて記載する
A12: ※ 障がい福祉計画の設定シートが用いている人口（令和9年8,287人）とは300人以上異なる。2計画で出典を統一すること

Sheet 03_認定者推計
A1: 要介護度 | B1: 令和8年3月末（実績） | C1: 構成比 | D1: 令和9年度 | E1: 令和10年度 | F1: 令和11年度 | G1: 備考
A2: 要支援1 | B2: 70 | C2: =IF($B$9=0,"",B2/$B$9) | G2: 令和8年3月末の実績（年報 様式1の5）
A3: 要支援2 | B3: 129 | C3: =IF($B$9=0,"",B3/$B$9) | G3: 令和8年3月末の実績（年報 様式1の5）
A4: 要介護1 | B4: 143 | C4: =IF($B$9=0,"",B4/$B$9) | G4: 令和8年3月末の実績（年報 様式1の5）
A5: 要介護2 | B5: 125 | C5: =IF($B$9=0,"",B5/$B$9) | G5: 令和8年3月末の実績（年報 様式1の5）
A6: 要介護3 | B6: 145 | C6: =IF($B$9=0,"",B6/$B$9) | G6: 令和8年3月末の実績（年報 様式1の5）
A7: 要介護4 | B7: 108 | C7: =IF($B$9=0,"",B7/$B$9) | G7: 令和8年3月末の実績（年報 様式1の5）
A8: 要介護5 | B8: 72 | C8: =IF($B$9=0,"",B8/$B$9) | G8: 令和8年3月末の実績（年報 様式1の5）
A9: 合計 | B9: =SUM(B2:B8) | C9: =IF($B$9=0,"",SUM(C2:C8)) | D9: =SUM(D2:D8) | E9: =SUM(E2:E8) | F9: =SUM(F2:F8)
A11: 【推計の前提】
A12: 認定率の設定方法 | G12: 見える化システムの認定率（第1号被保険者に対する割合）を年齢階層別に設定し、02の被保険者数に乗じる
A13: 65〜74歳の認定率（％） | B13: 3.92 | G13: 令和7年度実績（認定64人÷人口1,634人）
A14: 75〜84歳の認定率（％） | B14: 18.72 | G14: 令和7年度実績（認定204人÷人口1,090人）
A15: 85歳以上の認定率（％） | B15: 71.63 | G15: 令和7年度実績（認定515人÷人口719人）。**令和6年度は82.8％で、11.2ポイント下がっている**
A16: 第2号被保険者の認定者数 | B16: 9 | G16: 令和8年3月末の実績9人（年報 様式1の5）
A18: ※ 認定者数の推計は、年齢階層別の認定率に被保険者数を乗じる方法（自然体推計）を基本とします。
A19: ※ **令和8年3月末の認定者数792人は、介護保険事業状況報告（年報）様式1の5で裏付けられました。**第1号783人＋第2号9人。見える化システムの値と一致します。
A20: ※ ただし国保連月報によると、減少は令和7年9月審査分の1か月に集中しており（961人→862人）、**同じ月に給付件数は減っていません（1,303件→1,365件）。**計上方法の変更の可能性があり、町への確認が続いています。
A21: ※ 令和7年度は認定者が▲16.1％である一方、受給者延は▲4.6％、給付費は▲7.4％。**認定者数ベースで給付費を推計すると過小になります。**見込量は受給者数と給付費の実績を基礎に置いてください。
A22: ※ 介護予防・日常生活支援総合事業の対象者（事業対象者）は、認定者とは別に07で扱います。

Sheet 04_受給率
A1: 区分 | B1: 令和7年度（実績） | C1: 令和9年度 | D1: 令和10年度 | E1: 令和11年度 | F1: 設定の考え方
A2: 認定者に対する受給者の比率（全体） | F2: 見える化 D17系。**本町は認定率が高い一方で受給率が低く、在宅の認定者の42.1％が未利用（令和7年度調査）**
A3: 居宅サービス受給率 | F3: 認定者のうち居宅サービスを利用する割合
A4: 地域密着型サービス受給率 | F4: 同上
A5: 施設サービス受給率 | F5: 同上
A6: サービス未利用の割合 | F6: **令和7年度調査で在宅の認定者の42.1％。利用に移行した場合の給付費増がリスク**
A8: ※ 未利用者が利用に移行すると給付費が急増します。**未利用の理由は需要側が92.9％（状態ではない46.8％、本人希望なし29.2％、家族が介護16.9％）、供給制約は0.6％**であり、供給を増やしても利用は増えない構造です。
A9: ※ したがって受給率は実績の延長を基本とし、施策により押し上げる分はレスパイト・利用意向への働きかけの効果として別に見込みます。

Sheet 05_見込量_介護
A1: 区分 | B1: サービス | C1: 単位 | D1: 令和7年度 件数 | E1: 令和7年度 給付費(千円) | F1: 単価(円/件) | G1: 令和9年度 件数 | H1: 令和9年度 人/月 | I1: 令和9年度 量 | J1: 令和9年度 給付費(千円) | K1: 令和10年度 件数 | L1: 令和10年度 人/月 | M1: 令和10年度 量 | N1: 令和10年度 給付費(千円) | O1: 令和11年度 件数 | P1: 令和11年度 人/月 | Q1: 令和11年度 量 | R1: 令和11年度 給付費(千円) | S1: 備考
A2: 居宅 | B2: 訪問介護 | C2: 回 | D2: 628 | E2: 29747.388 | F2: 47368.452 | G2: 799.90995 | H2: 66.659163 | J2: 32659.96 | K2: 797.58328 | L2: 66.465273 | N2: 32564.963 | O2: 795.25661 | P2: 66.271384 | R2: 32469.966
A3: 居宅 | B3: 訪問入浴介護 | C3: 回 | D3: 68 | E3: 3170.413 | F3: 46623.721 | G3: 78.408156 | H3: 6.534013 | J3: 3624.0633 | K3: 78.180092 | L3: 6.5150077 | N3: 3613.5221 | O3: 77.952029 | P3: 6.4960024 | R3: 3602.9809
A4: 居宅 | B4: 訪問看護 | C4: 回 | D4: 519 | E4: 20186.841 | F4: 38895.647 | G4: 476.55524 | H4: 39.712936 | J4: 19409.676 | K4: 475.16909 | L4: 39.597425 | N4: 19353.22 | O4: 473.78295 | P4: 39.481913 | R4: 19296.763
A5: 居宅 | B5: 訪問リハビリテーション | C5: 回 | D5: 0 | E5: 0 | F5: 0 | G5: 0 | H5: 0 | J5: 0 | K5: 0 | L5: 0 | N5: 0 | O5: 0 | P5: 0 | R5: 0 | S5: 5年間を通じて実績なし。町内・近隣に事業所がないか確認します
A6: 居宅 | B6: 居宅療養管理指導 | C6: 人 | D6: 195 | E6: 866.483 | F6: 4443.5026 | G6: 204.99779 | H6: 17.083149 | J6: 923.37206 | K6: 204.40152 | L6: 17.03346 | N6: 920.68628 | O6: 203.80525 | P6: 16.983771 | R6: 918.0005
A7: 居宅 | B7: 通所介護 | C7: 回 | D7: 2053 | E7: 152490.58 | F7: 74276.949 | G7: 2129.8652 | H7: 177.48876 | J7: 156967.34 | K7: 2123.6701 | L7: 176.97251 | N7: 156510.78 | O7: 2117.475 | P7: 176.45625 | R7: 156054.21
A8: 居宅 | B8: 通所リハビリテーション | C8: 回 | D8: 311 | E8: 15575.466 | F8: 50081.884 | G8: 298.39846 | H8: 24.866538 | J8: 14217.821 | K8: 297.53051 | L8: 24.794209 | N8: 14176.466 | O8: 296.66257 | P8: 24.721881 | R8: 14135.111
A9: 居宅 | B9: 短期入所生活介護 | C9: 日 | D9: 357 | E9: 27393.691 | F9: 76733.028 | G9: 369.15584 | H9: 30.762987 | J9: 28650.358 | K9: 368.08209 | L9: 30.673508 | N9: 28567.024 | O9: 367.00834 | P9: 30.584028 | R9: 28483.689
A10: 居宅 | B10: 短期入所療養介護 | C10: 日 | D10: 27 | E10: 2327.634 | F10: 86208.667 | G10: 24.734998 | H10: 2.0612498 | J10: 1857.4447 | K10: 24.663052 | L10: 2.0552543 | N10: 1852.042 | O10: 24.591106 | P10: 2.0492588 | R10: 1846.6393
A11: 居宅 | B11: 福祉用具貸与 | C11: 人 | D11: 2387 | E11: 31304.782 | F11: 13114.697 | G11: 2371.2864 | H11: 197.6072 | J11: 30291.408 | K11: 2364.3892 | L11: 197.03243 | N11: 30203.3 | O11: 2357.4919 | P11: 196.45766 | R11: 30115.192
A12: 居宅 | B12: 特定福祉用具販売 | C12: 人 | D12: 45 | E12: 1722.55 | F12: 38278.889 | G12: 41.168155 | H12: 3.4306796 | J12: 1522.3466 | K12: 41.048411 | L12: 3.4207009 | N12: 1517.9186 | O12: 40.928666 | P12: 3.4107222 | R12: 1513.4906
A13: 居宅 | B13: 住宅改修 | C13: 人 | D13: 22 | E13: 1812.993 | F13: 82408.773 | G13: 25.747839 | H13: 2.1456532 | J13: 2009.6024 | K13: 25.672947 | L13: 2.1394122 | N13: 2003.7571 | O13: 25.598055 | P13: 2.1331713 | R13: 1997.9118
A14: 居宅 | B14: 特定施設入居者生活介護 | C14: 人 | D14: 45 | E14: 9718.948 | F14: 215976.62 | G14: 42.20925 | H14: 3.5174375 | J14: 8441.5009 | K14: 42.086477 | L14: 3.5072065 | N14: 8416.9474 | O14: 41.963705 | P14: 3.4969754 | R14: 8392.3939
A15: 居宅 | B15: 居宅介護支援 | C15: 人 | D15: 3036 | E15: 48080.693 | F15: 15836.855 | G15: 3118.8029 | H15: 259.90024 | J15: 49497.31 | K15: 3109.7313 | L15: 259.14428 | N15: 49353.338 | O15: 3100.6598 | P15: 258.38831 | R15: 49209.367
A16: 地域密着型 | B16: 定期巡回・随時対応型訪問介護看護 | C16: 人 | D16: 0 | E16: 0 | F16: 0 | G16: 0 | H16: 0 | J16: 0 | K16: 0 | L16: 0 | N16: 0 | O16: 0 | P16: 0 | R16: 0 | S16: 5年間を通じて実績なし。町内・近隣に事業所がないか確認します
A17: 地域密着型 | B17: 夜間対応型訪問介護 | C17: 人 | D17: 0 | E17: 0 | F17: 0 | G17: 0 | H17: 0 | J17: 0 | K17: 0 | L17: 0 | N17: 0 | O17: 0 | P17: 0 | R17: 0 | S17: 5年間を通じて実績なし。町内・近隣に事業所がないか確認します
A18: 地域密着型 | B18: 地域密着型通所介護 | C18: 回 | D18: 0 | E18: 0 | F18: 0 | G18: 0 | H18: 0 | J18: 0 | K18: 0 | L18: 0 | N18: 0 | O18: 0 | P18: 0 | R18: 0 | S18: 5年間を通じて実績なし。町内・近隣に事業所がないか確認します
A19: 地域密着型 | B19: 認知症対応型通所介護 | C19: 回 | D19: 115 | E19: 12237.804 | F19: 106415.69 | G19: 100.94185 | H19: 8.4118209 | J19: 11374.4 | K19: 100.64824 | L19: 8.3873537 | N19: 11341.315 | O19: 100.35464 | P19: 8.3628865 | R19: 11308.231
A20: 地域密着型 | B20: 小規模多機能型居宅介護 | C20: 人 | D20: 270 | E20: 49578.822 | F20: 183625.27 | G20: 296.89077 | H20: 24.740898 | J20: 51809.107 | K20: 296.02721 | L20: 24.668935 | N20: 51658.412 | O20: 295.16366 | P20: 24.596972 | R20: 51507.717
A21: 地域密着型 | B21: 認知症対応型共同生活介護 | C21: 人 | D21: 537 | E21: 134380.04 | F21: 250242.15 | G21: 579.00344 | H21: 48.250286 | J21: 147523.78 | K21: 577.31931 | L21: 48.109942 | N21: 147094.68 | O21: 575.63518 | P21: 47.969598 | R21: 146665.58
A22: 地域密着型 | B22: 地域密着型特定施設入居者生活介護 | C22: 人 | D22: 0 | E22: 0 | F22: 0 | G22: 0 | H22: 0 | J22: 0 | K22: 0 | L22: 0 | N22: 0 | O22: 0 | P22: 0 | R22: 0 | S22: 5年間を通じて実績なし。町内・近隣に事業所がないか確認します
A23: 地域密着型 | B23: 地域密着型介護老人福祉施設入所者生活介護 | C23: 人 | D23: 496 | E23: 126349.62 | F23: 254737.13 | G23: 521.06518 | H23: 43.422098 | J23: 129903.69 | K23: 519.54957 | L23: 43.295798 | N23: 129525.85 | O23: 518.03397 | P23: 43.169497 | R23: 129148
A24: 地域密着型 | B24: 看護小規模多機能型居宅介護 | C24: 人 | D24: 0 | E24: 0 | F24: 0 | G24: 0 | H24: 0 | J24: 0 | K24: 0 | L24: 0 | N24: 0 | O24: 0 | P24: 0 | R24: 0 | S24: 5年間を通じて実績なし。町内・近隣に事業所がないか確認します
A25: 施設 | B25: 介護老人福祉施設 | C25: 人 | D25: 827 | E25: 204849.64 | F25: 247702.1 | G25: 815.62191 | H25: 67.968492 | J25: 204435.01 | K25: 813.24953 | L25: 67.770794 | N25: 203840.37 | O25: 810.87716 | P25: 67.573097 | R25: 203245.74
A26: 施設 | B26: 介護老人保健施設 | C26: 人 | D26: 343 | E26: 92523.077 | F26: 269746.58 | G26: 354.9815 | H26: 29.581791 | J26: 97062.815 | K26: 353.94897 | L26: 29.495748 | N26: 96780.492 | O26: 352.91645 | P26: 29.409704 | R26: 96498.168
A27: 施設 | B27: 介護医療院 | C27: 人 | D27: 14 | E27: 4309.632 | F27: 307830.86 | G27: 13.979669 | H27: 1.1649724 | J27: 4303.3735 | K27: 13.939007 | L27: 1.1615839 | N27: 4290.8564 | O27: 13.898344 | P27: 1.1581954 | R27: 4278.3393
A28: 合計 | D28: =SUM(D2:D27) | E28: =SUM(E2:E27) | G28: =SUM(G2:G27) | H28: =SUM(H2:H27) | J28: =SUM(J2:J27) | K28: =SUM(K2:K27) | L28: =SUM(L2:L27) | N28: =SUM(N2:N27) | O28: =SUM(O2:O27) | P28: =SUM(P2:P27) | R28: =SUM(R2:R27)
A30: ※ 介護給付（要介護1〜5）。件数・給付費は年報（様式2）の実績から算出したもので、「小野町_第10期_サービス別単価・見込量試算」の04・05と同じ値です。
A31: ※ 件数は請求件数（＝月あたり受給者数の年間累計）。「人/月」は件数÷12です。
A32: ※ 見込件数は「基準期間の件数÷第1号被保険者数」に将来の第1号被保険者数を乗じたもの。給付費は同じ方法で給付費そのものを延ばしています。
A33: **※ 「量」（回・日）の列だけが空欄です。年報には回数・日数が入っていないため、国保連の給付実績を受領した時点で入れます。**
A34: ※ 報酬改定率は0.0％（据置）で置いています。改定率が決まったら試算ブックの06_感度分析で置き換えます。

Sheet 06_見込量_予防
A1: 区分 | B1: サービス | C1: 単位 | D1: 令和7年度 件数 | E1: 令和7年度 給付費(千円) | F1: 単価(円/件) | G1: 令和9年度 件数 | H1: 令和9年度 人/月 | I1: 令和9年度 量 | J1: 令和9年度 給付費(千円) | K1: 令和10年度 件数 | L1: 令和10年度 人/月 | M1: 令和10年度 量 | N1: 令和10年度 給付費(千円) | O1: 令和11年度 件数 | P1: 令和11年度 人/月 | Q1: 令和11年度 量 | R1: 令和11年度 給付費(千円) | S1: 備考
A2: 介護予防 | B2: 介護予防訪問入浴介護 | C2: 回 | D2: 0 | E2: 0 | F2: 0 | G2: 0 | H2: 0 | J2: 0 | K2: 0 | L2: 0 | N2: 0 | O2: 0 | P2: 0 | R2: 0 | S2: 5年間を通じて実績なし。町内・近隣に事業所がないか確認します
A3: 介護予防 | B3: 介護予防訪問看護 | C3: 回 | D3: 88 | E3: 2213.819 | F3: 25157.034 | G3: 66.692395 | H3: 5.5576996 | J3: 1845.4217 | K3: 66.498409 | L3: 5.5415341 | N3: 1840.0539 | O3: 66.304423 | P3: 5.5253686 | R3: 1834.6862
A4: 介護予防 | B4: 介護予防訪問リハビリテーション | C4: 回 | D4: 0 | E4: 0 | F4: 0 | G4: 0 | H4: 0 | J4: 0 | K4: 0 | L4: 0 | N4: 0 | O4: 0 | P4: 0 | R4: 0 | S4: 5年間を通じて実績なし。町内・近隣に事業所がないか確認します
A5: 介護予防 | B5: 介護予防居宅療養管理指導 | C5: 人 | D5: 25 | E5: 132.372 | F5: 5294.88 | G5: 24.069299 | H5: 2.0057749 | J5: 128.87201 | K5: 23.999289 | L5: 1.9999408 | N5: 128.49716 | O5: 23.92928 | P5: 1.9941067 | R5: 128.12231
A6: 介護予防 | B6: 介護予防通所リハビリテーション | C6: 人 | D6: 329 | E6: 11689.154 | F6: 35529.343 | G6: 292.57869 | H6: 24.381558 | J6: 11009.924 | K6: 291.72768 | L6: 24.31064 | N6: 10977.9 | O6: 290.87666 | P6: 24.239722 | R6: 10945.875
A7: 介護予防 | B7: 介護予防短期入所生活介護 | C7: 日 | D7: 9 | E7: 292.959 | F7: 32551 | G7: 5.2922365 | H7: 0.44101971 | J7: 147.9153 | K7: 5.2768432 | L7: 0.43973693 | N7: 147.48506 | O7: 5.2614498 | P7: 0.43845415 | R7: 147.05482 | S7: **月あたり1人に満たない見込みです。計画書の見込量表に載せるかどうかの判断を要します**
A8: 介護予防 | B8: 介護予防短期入所療養介護 | C8: 日 | D8: 1 | E8: 50.004 | F8: 50004 | G8: 0.98901874 | H8: 0.082418228 | J8: 57.817836 | K8: 0.98614201 | L8: 0.082178501 | N8: 57.649663 | O8: 0.98326529 | P8: 0.081938774 | R8: 57.48149 | S8: **月あたり1人に満たない見込みです。計画書の見込量表に載せるかどうかの判断を要します**
A9: 介護予防 | B9: 介護予防福祉用具貸与 | C9: 人 | D9: 688 | E9: 6000.387 | F9: 8721.4927 | G9: 626.639 | H9: 52.219916 | J9: 5204.3768 | K9: 624.81631 | L9: 52.068026 | N9: 5189.239 | O9: 622.99363 | P9: 51.916136 | R9: 5174.1012
A10: 介護予防 | B10: 特定介護予防福祉用具販売 | C10: 人 | D10: 17 | E10: 484.06 | F10: 28474.118 | G10: 14.393181 | H10: 1.1994318 | J10: 406.30734 | K10: 14.351316 | L10: 1.195943 | N10: 405.12553 | O10: 14.309451 | P10: 1.1924543 | R10: 403.94371
A11: 介護予防 | B11: 介護予防住宅改修 | C11: 人 | D11: 11 | E11: 876.749 | F11: 79704.455 | G11: 11.889665 | H11: 0.99080544 | J11: 1161.4743 | K11: 11.855082 | L11: 0.98792351 | N11: 1158.0959 | O11: 11.820499 | P11: 0.98504159 | R11: 1154.7176 | S11: **月あたり1人に満たない見込みです。計画書の見込量表に載せるかどうかの判断を要します**
A12: 介護予防 | B12: 介護予防特定施設入居者生活介護 | C12: 人 | D12: 0 | E12: 0 | F12: 0 | G12: 0 | H12: 0 | J12: 0 | K12: 0 | L12: 0 | N12: 0 | O12: 0 | P12: 0 | R12: 0 | S12: 5年間を通じて実績なし。町内・近隣に事業所がないか確認します
A13: 介護予防 | B13: 介護予防支援 | C13: 人 | D13: 919 | E13: 4145.98 | F13: 4511.4037 | G13: 833.77682 | H13: 69.481401 | J13: 3760.9501 | K13: 831.35164 | L13: 69.279303 | N13: 3750.0107 | O13: 828.92646 | P13: 69.077205 | R13: 3739.0714
A14: 地域密着型予防 | B14: 介護予防認知症対応型通所介護 | C14: 回 | D14: 0 | E14: 0 | F14: 0 | G14: 0 | H14: 0 | J14: 0 | K14: 0 | L14: 0 | N14: 0 | O14: 0 | P14: 0 | R14: 0 | S14: 5年間を通じて実績なし。町内・近隣に事業所がないか確認します
A15: 地域密着型予防 | B15: 介護予防小規模多機能型居宅介護 | C15: 人 | D15: 92 | E15: 7288.119 | F15: 79218.685 | G15: 80.491012 | H15: 6.7075844 | J15: 6320.0482 | K15: 80.256891 | L15: 6.6880742 | N15: 6301.6653 | O15: 80.022769 | P15: 6.6685641 | R15: 6283.2824
A16: 地域密着型予防 | B16: 介護予防認知症対応型共同生活介護 | C16: 人 | D16: 14 | E16: 3343.374 | F16: 238812.43 | G16: 26.969652 | H16: 2.247471 | J16: 6270.9044 | K16: 26.891206 | L16: 2.2409339 | N16: 6252.6644 | O16: 26.81276 | P16: 2.2343967 | R16: 6234.4245
A17: 合計 | D17: =SUM(D2:D16) | E17: =SUM(E2:E16) | G17: =SUM(G2:G16) | H17: =SUM(H2:H16) | J17: =SUM(J2:J16) | K17: =SUM(K2:K16) | L17: =SUM(L2:L16) | N17: =SUM(N2:N16) | O17: =SUM(O2:O16) | P17: =SUM(P2:P16) | R17: =SUM(R2:R16)
A19: ※ 予防給付（要支援1・2）。件数・給付費は年報（様式2）の実績から算出したもので、「小野町_第10期_サービス別単価・見込量試算」の04・05と同じ値です。
A20: ※ 件数は請求件数（＝月あたり受給者数の年間累計）。「人/月」は件数÷12です。
A21: ※ 見込件数は「基準期間の件数÷第1号被保険者数」に将来の第1号被保険者数を乗じたもの。給付費は同じ方法で給付費そのものを延ばしています。
A22: **※ 「量」（回・日）の列だけが空欄です。年報には回数・日数が入っていないため、国保連の給付実績を受領した時点で入れます。**
A23: ※ 報酬改定率は0.0％（据置）で置いています。改定率が決まったら試算ブックの06_感度分析で置き換えます。

Sheet 07_地域支援事業
A1: 区分 | B1: 事業 | C1: 令和7年度（実績） | D1: 令和9年度 | E1: 令和10年度 | F1: 令和11年度 | G1: 備考
A2: 総合事業 | B2: 介護予防・生活支援サービス事業（訪問型）
A3: 総合事業 | B3: 介護予防・生活支援サービス事業（通所型）
A4: 総合事業 | B4: その他の生活支援サービス
A5: 総合事業 | B5: 介護予防ケアマネジメント
A6: 総合事業 | B6: 一般介護予防事業 | G6: **令和5年度で1.0百万円と低水準。通いの場を第10期の最重点とするため増額を見込む**
A7: 包括的支援事業 | B7: 地域包括支援センターの運営
A8: 包括的支援事業 | B8: 在宅医療・介護連携推進事業
A9: 包括的支援事業 | B9: 生活支援体制整備事業
A10: 包括的支援事業 | B10: 認知症総合支援事業
A11: 包括的支援事業 | B11: 地域ケア会議推進事業
A12: 任意事業 | B12: 介護給付等費用適正化事業
A13: 任意事業 | B13: 家族介護支援事業
A14: 任意事業 | B14: その他の任意事業
A15: 合計 | C15: =SUM(C2:C14) | D15: =SUM(D2:D14) | E15: =SUM(E2:E14) | F15: =SUM(F2:F14)
A17: ※ 単位：千円。
A18: ※ 総合事業には上限額（前年度実績×高齢者人口の伸び率）が設定されます。上限を超える場合は町と協議します。
A19: ※ **見える化システムには令和3年度以降の総合事業の値がありません。**町の事業実績が必要です。

Sheet 08_標準給付費
A1: 項目 | B1: 令和9年度 | C1: 令和10年度 | D1: 令和11年度 | E1: 3年計 | F1: 算式・備考
A2: 介護給付費（05_見込量_介護の合計） | B2: ='05_見込量_介護'!J28 | C2: ='05_見込量_介護'!N28 | D2: ='05_見込量_介護'!R28 | E2: =SUM(B2:D2) | F2: 05_見込量_介護 の合計行
A3: 予防給付費（06_見込量_予防の合計） | B3: ='06_見込量_予防'!J17 | C3: ='06_見込量_予防'!N17 | D3: ='06_見込量_予防'!R17 | E3: =SUM(B3:D3) | F3: 06_見込量_予防 の合計行
A4: 総給付費 | B4: =B2+B3 | C4: =C2+C3 | D4: =D2+D3 | E4: =SUM(B4:D4) | F4: 介護給付費＋予防給付費
A5: 特定入所者介護サービス費等給付額 | B5: =B4*0.049932 | C5: =C4*0.049932 | D5: =D4*0.049932 | E5: =SUM(B5:D5) | F5: 補足給付。総給付費×4.993％（令和5〜7年度の対総給付費比の平均）
A6: 高額介護サービス費等給付額 | B6: =B4*0.024606 | C6: =C4*0.024606 | D6: =D4*0.024606 | E6: =SUM(B6:D6) | F6: 総給付費×2.461％（同）
A7: 高額医療合算介護サービス費等給付額 | B7: =B4*0.002657 | C7: =C4*0.002657 | D7: =D4*0.002657 | E7: =SUM(B7:D7) | F7: 総給付費×0.266％（同）
A8: 算定対象審査支払手数料 | B8: =('05_見込量_介護'!G28+'06_見込量_予防'!G17)*60/1000 | C8: =('05_見込量_介護'!K28+'06_見込量_予防'!K17)*60/1000 | D8: =('05_見込量_介護'!O28+'06_見込量_予防'!O17)*60/1000 | E8: =SUM(B8:D8) | F8: 国保連への手数料。05・06の件数合計×60円。**年報に計上欄がないため仮置き。決算での確認を要します**
A9: 標準給付費見込額 | B9: =B4+B5+B6+B7+B8 | C9: =C4+C5+C6+C7+C8 | D9: =D4+D5+D6+D7+D8 | E9: =SUM(B9:D9) | F9: 総給付費＋補足給付＋高額＋高額合算＋手数料
A10: 地域支援事業費（07の合計） | B10: ='07_地域支援事業'!D15 | C10: ='07_地域支援事業'!E15 | D10: ='07_地域支援事業'!F15 | E10: =SUM(B10:D10) | F10: 07_地域支援事業 の合計行
A11: 総費用額 | B11: =B9+B10 | C11: =C9+C10 | D11: =D9+D10 | E11: =SUM(B11:D11) | F11: 標準給付費見込額＋地域支援事業費
A13: ※ 単位：千円。
A14: ※ 第9期の標準給付費見込額（3年計）は3,566,486千円でした。第10期はこれを基礎に、認定者数の推計と実績の伸びで算定します。

Sheet 09_保険料算定
A1: # | B1: 項目 | C1: 値 | D1: 単位 | E1: 算式・出典
A2: 1 | B2: 標準給付費見込額（3年計） | C2: ='08_標準給付費'!E9 | D2: 千円 | E2: 08_標準給付費 より
A3: 2 | B3: 地域支援事業費（3年計） | C3: ='08_標準給付費'!E10 | D3: 千円 | E3: 08_標準給付費 より
A4: 3 | B4: 総費用額（3年計） | C4: =C2+C3 | D4: 千円 | E4: ①＋②
A5: 4 | B5: 第1号被保険者負担割合 | D5: ％ | E5: 国の基本指針による。第9期は23％。**第10期の割合は国の決定後に確定**
A6: 5 | B6: 第1号被保険者負担分相当額 | C6: =C4*C5/100 | D6: 千円 | E6: ③×④
A7: 6 | B7: 調整交付金相当額 | C7: =C4*C8/100 | D7: 千円 | E7: ③×⑦
A8: 7 | B8: 調整交付金相当割合 | D8: ％ | E8: 国の基本指針による。標準は5％
A9: 8 | B9: 調整交付金見込額 | D9: 千円 | E9: **後期高齢者加入割合・所得段階別加入割合により算定。見える化システムで確認**
A10: 9 | B10: 財政安定化基金拠出金見込額 | D10: 千円 | E10: 県の設定による。第9期は0円
A11: 10 | B11: 財政安定化基金償還金 | D11: 千円 | E11: 借入がある場合。第9期は0円
A12: 11 | B12: 準備基金取崩額 | D12: 千円 | E12: **政策判断。第9期は35,000千円を見込んだが、介護給付費準備基金の保有額は令和5・6年度末とも12,000千円しかない（年報 様式4）。**取崩の原資が足りるかを確認したうえで設定する。ケースC5・C6で変える
A13: 12 | B13: 市町村特別給付費等 | D13: 千円 | E13: 町単独事業を保険料で賄う場合
A14: 13 | B14: 保険料収納必要額 | C14: =C6+C7-C9+C10+C11-C12+C13 | D14: 千円 | E14: ⑤＋⑥－⑧＋⑨＋⑩－⑪＋⑫
A15: 14 | B15: 予定保険料収納率 | C15: 99.35 | D15: ％ | E15: **令和7年度実績＝収納264,162,900円÷調定265,881,800円＝99.35％（年報 様式3）。**直近3年の実績を踏まえて設定する
A16: 15 | B16: 保険料賦課総額 | C16: =IF(C15=0,"",C14/C15*100) | D16: 千円 | E16: ⑬÷⑭
A17: 16 | B17: 所得段階別加入割合補正後被保険者数（3年計） | C17: =E37 | D17: 人 | E17: 下表の合計。**所得段階別第1号被保険者数が必要**
A18: 17 | B18: 保険料基準額（年額） | C18: =IF(C17=0,"",C16*1000/C17) | D18: 円 | E18: ⑮÷⑯
A19: 18 | B19: 保険料基準額（月額） | C19: =IF(C18="","",C18/12) | D19: 円 | E19: ⑰÷12
A20: 19 | B20: 第9期の保険料基準額（月額） | C20: 6600 | D20: 円 | E20: 第9期計画本文
A21: 20 | B21: 第9期との差 | C21: =IF(C19="","",C19-C20) | D21: 円 | E21: ⑱－⑲
A22: 【所得段階別 加入割合補正後被保険者数】
A23: 段階 | B23: 対象 | C23: 保険料率 | D23: 被保険者数（3年計） | E23: 補正後人数
A24: 第1段階 | B24: 生活保護受給者、老齢福祉年金受給者、住民税非課税世帯かつ年金収入等80万円以下 | C24: 0.285 | D24: 1575 | E24: =IF(D24="","",C24*D24)
A25: 第2段階 | B25: 住民税非課税世帯かつ年金収入等80万円超120万円以下 | C25: 0.486 | D25: 891 | E25: =IF(D25="","",C25*D25)
A26: 第3段階 | B26: 住民税非課税世帯かつ年金収入等120万円超 | C26: 0.685 | D26: 816 | E26: =IF(D26="","",C26*D26)
A27: 第4段階 | B27: 本人非課税かつ世帯課税、年金収入等80万円以下 | C27: 0.9 | D27: 1302 | E27: =IF(D27="","",C27*D27)
A28: 第5段階 | B28: 本人非課税かつ世帯課税、年金収入等80万円超 | C28: 1 | D28: 1830 | E28: =IF(D28="","",C28*D28)
A29: 第6段階 | B29: 本人課税、合計所得金額120万円未満 | C29: 1.2 | D29: 1473 | E29: =IF(D29="","",C29*D29)
A30: 第7段階 | B30: 本人課税、合計所得金額120万円以上210万円未満 | C30: 1.3 | D30: 1254 | E30: =IF(D30="","",C30*D30)
A31: 第8段階 | B31: 本人課税、合計所得金額210万円以上320万円未満 | C31: 1.5 | D31: 693 | E31: =IF(D31="","",C31*D31)
A32: 第9段階 | B32: 本人課税、合計所得金額320万円以上420万円未満 | C32: 1.7 | D32: 231 | E32: =IF(D32="","",C32*D32)
A33: 第10段階 | B33: 本人課税、合計所得金額420万円以上520万円未満 | C33: 1.9 | D33: 108 | E33: =IF(D33="","",C33*D33)
A34: 第11段階 | B34: 本人課税、合計所得金額520万円以上620万円未満 | C34: 2.1 | D34: 42 | E34: =IF(D34="","",C34*D34)
A35: 第12段階 | B35: 本人課税、合計所得金額620万円以上720万円未満 | C35: 2.3 | D35: 21 | E35: =IF(D35="","",C35*D35)
A36: 第13段階 | B36: 本人課税、合計所得金額720万円以上 | C36: 2.4 | D36: 93 | E36: =IF(D36="","",C36*D36)
A37: 合計 | D37: =SUM(D24:D36) | E37: =SUM(E24:E36)
A39: ※ **保険料率は小野町が第9期で定めた割合（年報 様式1 所得段階別）。**第1〜3段階は国の標準（0.455／0.685／0.69）より低い0.285／0.486／0.685で、公費による低所得者軽減を反映した率です。第10期の段階設定は国の基本指針を受けて確定します。
A40: ※ **被保険者数は令和7年度末の実績（年報 様式1 所得段階別）を3倍して3年計としています。**計画期間の被保険者数の推移（02_人口・被保険者）に応じて置き換えてください。
A41: ※ 補正後人数＝保険料率×被保険者数。

Sheet 10_ケース比較
A1: ケース | B1: 認定者数の前提 | C1: 標準給付費（3年計・千円） | D1: 地域支援事業費（千円） | E1: 総費用額（千円） | F1: 基金取崩額（千円） | G1: 保険料基準額（月額・円） | H1: 第9期との差（円） | I1: 備考
A2: C1 標準（低位）
A3: C2 標準（高位）
A4: C3 施設整備あり
A5: C4 制度改正の影響
A6: C5 基金活用
A7: C6 保険料据置（逆算）
A9: ※ 各ケースは09_保険料算定の入力値を変えて算定し、結果を本表に転記します。**ブックを複製してケースごとに保存する運用とします。**
A10: ※ **C1とC2の差が、認定者数の確認が済むまでの不確実性の幅です。**この幅を協議会に示したうえで、確認結果を待って1本に絞ります。
A11: ※ 協議会に諮る際は、保険料の水準だけでなく、繰越金182.0百万円・基金純増88.1百万円という財政余剰の還元方針を併せて示します。

Sheet 11_実績（年報）
A1: 区分 | B1: 項目 | C1: 令和7年度 実績 | D1: 単位 | E1: 出典・備考
A2: 認定者 | B2: 要支援・要介護認定者数（令和8年3月末） | C2: 792 | D2: 人 | E2: **年報 様式1の5。第1号783＋第2号9。見える化システムの値と一致**
A3: 認定者 | B3: 要支援1 | C3: 70 | D3: 人 | E3: 年報 様式1の5
A4: 認定者 | B4: 要支援2 | C4: 129 | D4: 人 | E4: 年報 様式1の5
A5: 認定者 | B5: 要介護1 | C5: 143 | D5: 人 | E5: 年報 様式1の5
A6: 認定者 | B6: 要介護2 | C6: 125 | D6: 人 | E6: 年報 様式1の5
A7: 認定者 | B7: 要介護3 | C7: 145 | D7: 人 | E7: 年報 様式1の5
A8: 認定者 | B8: 要介護4 | C8: 108 | D8: 人 | E8: 年報 様式1の5
A9: 認定者 | B9: 要介護5 | C9: 72 | D9: 人 | E9: 年報 様式1の5
A10: 認定者 | B10: （年齢別）65〜74歳 | C10: 64 | D10: 人 | E10: 年報 様式1の5（第1号）
A11: 認定者 | B11: （年齢別）75〜84歳 | C11: 204 | D11: 人 | E11: 年報 様式1の5（第1号）
A12: 認定者 | B12: （年齢別）85歳以上 | C12: 515 | D12: 人 | E12: 年報 様式1の5（第1号）
A13: 被保険者 | B13: 第1号被保険者数（年度末） | C13: 3443 | D13: 人 | E13: 年報 様式1
... A32: 財政 | B32: 第9期 第1号保険料 基準額（月額） | C32: 6600 | D32: 円 | E32: 年報 経理状況シート
A34: ※ 令和8年9月8日受領の介護保険事業状況報告（年報）令和3〜7年度から抽出。5年分の系列は 18_年報・国保連データ/小野町_年報・国保連データ整理 を参照。
A35: ※ **令和7年度は認定者が▲16.1％である一方、受給者延は▲4.6％、給付費は▲7.4％。**認定者数ベースの推計は給付費を過小推計するため、見込量は受給者数と給付費の実績を基礎に置くこと。
A36: ※ 令和7年度の様式4（経理状況）は全て0で未入力。決算確定後の再受領が必要。
