Workbook

Sheet 目次
B1: 小野町 障がい福祉に関するアンケート調査 分析報告書 図表データ集（編集用）
B3: ・このブックは、分析報告書に掲載した図表を、Excelで編集できる形式で収録したものです。図表番号は報告書と対応しています。
B4: ・グラフはすべてExcelのグラフ機能で作成しています。色・フォント・ラベル・サイズ等を通常どおり編集でき、そのままWordに貼り付けて使用できます。
B5: ・青字のセルが入力値（件数・回答者数）、黒字のセルは計算式です。「集計_障がい者」「集計_障がい児」シートの件数を修正すると、各章シートの表とグラフに自動で反映されます。
B6: ・第4章のクロス集計は、各表の【件数】欄（青字）が入力値で、【割合】欄は計算式です。
B7: ・第3章の【障がい別】の図表は、「集計_障がい別」シート（手帳の所持により身体・知的・精神に区分、重複所持は各区分に計上）の件数（青字）を参照しています。
B8: ・割合は、各設問の回答者数（無回答を含む）を基数として算出し、表示上、小数点第2位を四捨五入しています。全ての設問に「無回答」を設けています。グラフの項目の並び順は、報告書作成時点の件数順で固定しています。
B9: ・出典：小野町_障がい者__アンケート2026_統合.xlsx、小野町_障がい児_アンケート_2026_統合.xlsx（いずれもデータシート）。第6章・第7章は分析報告書（第1稿）の内容を引き継いでいます。
B11: 図表番号 | C11: タイトル | D11: 収録シート | E11: 移動
B12: 表1-1 | C12: 調査の概要 | D12: 1-2章_概要・要点 | E12: → 表示
B13: 表1-2 | C13: 調査項目の構成 | D13: 1-2章_概要・要点 | E13: → 表示
B14: 表2-1 | C14: 障がい者調査の主要指標 | D14: 1-2章_概要・要点 | E14: → 表示
B15: 図3-1 | C15: 調査票の回答者（問1） | D15: 3章_1属性 | E15: → 表示
B16: 図3-2 | C16: 性別（問2） | D16: 3章_1属性 | E16: → 表示
B17: 図3-3 | C17: 性別【障がい別】（問2） | D17: 3章_1属性 | E17: → 表示
B18: 図3-4 | C18: 年齢（問3） | D18: 3章_1属性 | E18: → 表示
B19: 図3-5 | C19: 年齢【障がい別】（問3） | D19: 3章_1属性 | E19: → 表示
B20: 図3-6 | C20: 現在の暮らしの場（問4） | D20: 3章_1属性 | E20: → 表示
B21: 図3-7 | C21: 現在の暮らしの場【障がい別】（問4） | D21: 3章_1属性 | E21: → 表示
B22: 図3-8 | C22: 同居している家族（問4） | D22: 3章_1属性 | E22: → 表示
... B179: 入力データ | C179: 障がい者調査 障がい別集計（入力用） | D179: 集計_障がい別 | E179: → 表示

Sheet 1-2章_概要・要点
B2: 表1-1 調査の概要
B3: 項目 | C3: 障がい者調査 | G3: 障がい児調査
B4: 調査対象 | C4: 主に18歳以上の障がいのある方 | G4: 主に18歳未満の障がいのある児童・保護者
B5: 調査方法 | C5: 郵送配布、郵送回収及び役場配布、役場回収 | G5: 郵送配布、郵送回収及び役場配布、役場回収
B6: 調査期間 | C6: 令和8年8月14日～9月25日 | G6: 令和8年8月14日～9月25日
B7: 配布数
B8: 有効回答数 | C8: =集計_障がい者!$F$5 -> 259 | G8: =集計_障がい児!$F$5 -> 25
B9: 有効回答率 | C9: =IF(C7="","",C8/C7) | G9: =IF(G7="","",G8/G7)
B10: ※黄色の網掛け部分は、実施記録に基づき記入してください。（参考）前回調査（令和５年10月実施）は、障がい者調査が配布520件・有効回答280件（53.8％）、障がい児調査が配布36件・有効回答22件（61.1％）でした。
B12: 表1-2 調査項目の構成
B13: 分野 | C13: 障がい者調査 | F13: 障がい児調査
B14: 回答者の属性・生活状況 | C14: 問1～問7 | F14: 問1～問7
B15: 障がい・医療 | C15: 問8～問16 | F15: 問8～問16
B16: 将来の暮らし・外出 | C16: 問17～問22 | F16: 問23～問27
B17: 日中活動・就労・進路 | C17: 問23～問27 | F17: 問17～問22
B18: 福祉サービス | C18: 問28～問32 | F18: 問28～問29
B19: 相談・情報 | C19: 問33～問34 | F19: 問30～問31
B20: 差別解消・権利擁護 | C20: 問35～問40 | F20: 問32～問37
B21: 災害時の対応 | C21: 問41～問45 | F21: 問38～問42
B22: 自由意見 | C22: 問46 | F22: 問43
B24: 表2-1 障がい者調査の主要指標
B25: 分野 | C25: 指標 | H25: 結果 | I25: 設問
B26: 回答者 | C26: 65歳以上の割合 | H26: =IF(集計_障がい者!$F$21=0,0,SUM(集計_障がい者!$D$21)/集計_障がい者!$F$21) -> 0.68339768 | I26: 問3
B27: 暮らし | C27: 自宅で家族等と一緒に住んでいる | H27: =IF(集計_障がい者!$F$24=0,0,SUM(集計_障がい者!$D$24)/集計_障がい者!$F$24) -> 0.65250965 | I27: 問4-1
B28: 介助者 | C28: 主介助者が60歳以上 | H28: =IF(集計_障がい者!$F$85=0,0,SUM(集計_障がい者!$D$85,集計_障がい者!$D$86)/集計_障がい者!$F$85) -> 0.26254826 | I28: 問7-1
B29: 将来の暮らし | C29: 「家族と一緒に生活したい」 | H29: =IF(集計_障がい者!$F$153=0,0,SUM(集計_障がい者!$D$153)/集計_障がい者!$F$153) -> 0.61003861 | I29: 問17
B30: 地域生活 | C30: 必要な支援「経済的な負担の軽減」（第1位） | H30: =IF(集計_障がい者!$F$163=0,0,SUM(集計_障がい者!$D$163)/集計_障がい者!$F$163) -> 0.48262548 | I30: 問18
B31: 外出 | C31: 外出時に困ること「外出にお金がかかる」（第1位） | H31: =IF(集計_障がい者!$F$200=0,0,SUM(集計_障がい者!$D$200)/集計_障がい者!$F$200) -> 0.25096525 | I31: 問22
B32: 日中活動 | C32: 「自宅で過ごしている」 | H32: =IF(集計_障がい者!$F$213=0,0,SUM(集計_障がい者!$D$213)/集計_障がい者!$F$213) -> 0.44015444 | I32: 問23
B33: 就労 | C33: 就労支援として必要なこと「職場の上司や同僚に障がいの理解があること」（第1位） | H33: =IF(集計_障がい者!$F$236=0,0,SUM(集計_障がい者!$D$236)/集計_障がい者!$F$236) -> 0.35907336 | I33: 問27
B34: サービス | C34: 介護保険サービスを利用している | H34: =IF(集計_障がい者!$F$251=0,0,SUM(集計_障がい者!$D$251)/集計_障がい者!$F$251) -> 0.2972973 | I34: 問29
B35: 相談 | C35: 相談相手「家族や親せき」 | H35: =IF(集計_障がい者!$F$352=0,0,SUM(集計_障がい者!$D$352)/集計_障がい者!$F$352) -> 0.73745174 | I35: 問33
B36: 情報 | C36: 情報の入手先「本や新聞、雑誌の記事、テレビやラジオのニュース」（第1位） | H36: =IF(集計_障がい者!$F$368=0,0,SUM(集計_障がい者!$D$368)/集計_障がい者!$F$368) -> 0.37837838 | I36: 問34
B37: 権利擁護 | C37: 差別や嫌な思いをしたことが「ある」「少しある」 | H37: =IF(集計_障がい者!$F$384=0,0,SUM(集計_障がい者!$D$384,集計_障がい者!$D$385)/集計_障がい者!$F$384) -> 0.25868726 | I37: 問35
B38: 権利擁護 | C38: 成年後見制度を「名前も内容も知らない」 | H38: =IF(集計_障がい者!$F$399=0,0,SUM(集計_障がい者!$D$399)/集計_障がい者!$F$399) -> 0.36679537 | I38: 問37
B39: 災害 | C39: 一人で避難「できない」「わからない」 | H39: =IF(集計_障がい者!$F$416=0,0,SUM(集計_障がい者!$D$416,集計_障がい者!$D$417)/集計_障がい者!$F$416) -> 0.55598456 | I39: 問41
B40: 災害 | C40: 近所に助けてくれる人が「いない」 | H40: =IF(集計_障がい者!$F$420=0,0,SUM(集計_障がい者!$D$420)/集計_障がい者!$F$420) -> 0.23166023 | I40: 問42
B41: 災害 | C41: 個別避難計画の作成を「希望する」 | H41: =IF(集計_障がい者!$F$438=0,0,SUM(集計_障がい者!$D$438)/集計_障がい者!$F$438) -> 0.25482625 | I41: 問45
B42: ※結果は回答者数（無回答を含む）に対する割合です。条件付き設問も回答者数を基数としています。

Sheet 3章_1属性
B2: 図3-1 調査票の回答者（問1）
B3: ="n="&集計_障がい者!$F$5&"（単一回答）" -> n=259（単一回答）
B4: 選択肢 | C4: 件数 | D4: 割合
B5: ご本人が自分で記入 | C5: =集計_障がい者!$D$5 -> 144 | D5: =集計_障がい者!$E$5 -> 0.55598456
B6: ご本人が回答し、家族の方が記入 | C6: =集計_障がい者!$D$6 -> 37 | D6: =集計_障がい者!$E$6 -> 0.14285714
B7: 家族の方が代理で回答・記入 | C7: =集計_障がい者!$D$7 -> 48 | D7: =集計_障がい者!$E$7 -> 0.18532819
B8: ご本人が回答し、施設職員が記入 | C8: =集計_障がい者!$D$8 -> 9 | D8: =集計_障がい者!$E$8 -> 0.034749035
B9: 施設職員が代理で回答・記入 | C9: =集計_障がい者!$D$9 -> 10 | D9: =集計_障がい者!$E$9 -> 0.038610039
B10: その他 | C10: =集計_障がい者!$D$10 -> 3 | D10: =集計_障がい者!$E$10 -> 0.011583012
B11: 無回答 | C11: =集計_障がい者!$D$11 -> 8 | D11: =集計_障がい者!$E$11 -> 0.030888031
B15: 図3-2 性別（問2）
B16: ="n="&集計_障がい者!$F$12&"（単一回答）" -> n=259（単一回答）
B17: 選択肢 | C17: 件数 | D17: 割合
B18: 男性 | C18: =集計_障がい者!$D$12 -> 144 | D18: =集計_障がい者!$E$12 -> 0.55598456
B19: 女性 | C19: =集計_障がい者!$D$13 -> 109 | D19: =集計_障がい者!$E$13 -> 0.42084942
B20: わからない | C20: =集計_障がい者!$D$14 -> 0 | D20: =集計_障がい者!$E$14 -> 0
B21: 答えたくない | C21: =集計_障がい者!$D$15 -> 0 | D21: =集計_障がい者!$E$15 -> 0
B22: 無回答 | C22: =集計_障がい者!$D$16 -> 6 | D22: =集計_障がい者!$E$16 -> 0.023166023
B26: 図3-3 性別【障がい別】（問2）
B28: 区分 | C28: 男性 | D28: 女性 | E28: わからない | F28: 答えたくない | G28: 無回答
B29: 全体 | C29: =集計_障がい者!$E$12 -> 0.55598456 | D29: =集計_障がい者!$E$13 -> 0.42084942 | E29: =集計_障がい者!$E$14 -> 0 | F29: =集計_障がい者!$E$15 -> 0 | G29: =集計_障がい者!$E$16 -> 0.023166023
B30: 身体障がい（n=193） | C30: =集計_障がい別!$G$13 -> 0.56994819 | D30: =集計_障がい別!$G$14 -> 0.40414508 | E30: =集計_障がい別!$G$15 -> 0 | F30: =集計_障がい別!$G$16 -> 0 | G30: =集計_障がい別!$G$17 -> 0.025906736
B31: 知的障がい（n=33） | C31: =集計_障がい別!$H$13 -> 0.60606061 | D31: =集計_障がい別!$H$14 -> 0.36363636 | E31: =集計_障がい別!$H$15 -> 0 | F31: =集計_障がい別!$H$16 -> 0 | G31: =集計_障がい別!$H$17 -> 0.03030303
B32: 精神障がい（n=44） | C32: =集計_障がい別!$I$13 -> 0.54545455 | D32: =集計_障がい別!$I$14 -> 0.40909091 | E32: =集計_障がい別!$I$15 -> 0 | F32: =集計_障がい別!$I$16 -> 0 | G32: =集計_障がい別!$I$17 -> 0.045454545
B40: 図3-4 年齢（問3）
B41: ="n="&集計_障がい者!$F$17&"（単一回答）" -> n=259（単一回答）
B42: 選択肢 | C42: 件数 | D42: 割合
B43: 18～29歳 | C43: =集計_障がい者!$D$17 -> 12 | D43: =集計_障がい者!$E$17 -> 0.046332046
B44: 30～39歳 | C44: =集計_障がい者!$D$18 -> 12 | D44: =集計_障がい者!$E$18 -> 0.046332046
B45: 40～49歳 | C45: =集計_障がい者!$D$19 -> 16 | D45: =集計_障がい者!$E$19 -> 0.061776062
B46: 50～64歳 | C46: =集計_障がい者!$D$20 -> 32 | D46: =集計_障がい者!$E$20 -> 0.12355212
B47: 65歳以上 | C47: =集計_障がい者!$D$21 -> 177 | D47: =集計_障がい者!$E$21 -> 0.68339768
B48: 無回答 | C48: =集計_障がい者!$D$22 -> 10 | D48: =集計_障がい者!$E$22 -> 0.038610039
B51: 図3-5 年齢【障がい別】（問3）
B53: 区分 | C53: 18～29歳 | D53: 30～39歳 | E53: 40～49歳 | F53: 50～64歳 | G53: 65歳以上 | H53: 無回答
B54: 全体 | C54: =集計_障がい者!$E$17 -> 0.046332046 | D54: =集計_障がい者!$E$18 -> 0.046332046 | E54: =集計_障がい者!$E$19 -> 0.061776062 | F54: =集計_障がい者!$E$20 -> 0.12355212 | G54: =集計_障がい者!$E$21 -> 0.68339768 | H54: =集計_障がい者!$E$22 -> 0.038610039
B55: 身体障がい（n=193） | C55: =集計_障がい別!$G$18 -> 0.0051813472 | D55: =集計_障がい別!$G$19 -> 0.015544041 | E55: =集計_障がい別!$G$20 -> 0.025906736 | F55: =集計_障がい別!$G$21 -> 0.093264249 | G55: =集計_障がい別!$G$22 -> 0.8238342 | H55: =集計_障がい別!$G$23 -> 0.03626943
B56: 知的障がい（n=33） | C56: =集計_障がい別!$H$18 -> 0.21212121 | D56: =集計_障がい別!$H$19 -> 0.12121212 | E56: =集計_障がい別!$H$20 -> 0.060606061 | F56: =集計_障がい別!$H$21 -> 0.3030303 | G56: =集計_障がい別!$H$22 -> 0.27272727 | H56: =集計_障がい別!$H$23 -> 0.03030303
B57: 精神障がい（n=44） | C57: =集計_障がい別!$I$18 -> 0.13636364 | D57: =集計_障がい別!$I$19 -> 0.13636364 | E57: =集計_障がい別!$I$20 -> 0.20454545 | F57: =集計_障がい別!$I$21 -> 0.22727273 | G57: =集計_障がい別!$I$22 -> 0.25 | H57: =集計_障がい別!$I$23 -> 0.045454545
B66: 図3-6 現在の暮らしの場（問4）
...

Sheet 3章_2障がい・医療
B2: 図3-20 身体障害者手帳の所持状況（問8）
B3: ="n="&集計_障がい者!$F$95&"（単一回答）" -> n=259（単一回答）
B4: 選択肢 | C4: 件数 | D4: 割合
B5: １級 | C5: =集計_障がい者!$D$95 -> 72 | D5: =集計_障がい者!$E$95 -> 0.27799228
B6: ２級 | C6: =集計_障がい者!$D$96 -> 34 | D6: =集計_障がい者!$E$96 -> 0.13127413
B7: ３級 | C7: =集計_障がい者!$D$97 -> 28 | D7: =集計_障がい者!$E$97 -> 0.10810811
B8: ４級 | C8: =集計_障がい者!$D$98 -> 33 | D8: =集計_障がい者!$E$98 -> 0.12741313
B9: ５級 | C9: =集計_障がい者!$D$99 -> 16 | D9: =集計_障がい者!$E$99 -> 0.061776062
B10: ６級 | C10: =集計_障がい者!$D$100 -> 10 | D10: =集計_障がい者!$E$100 -> 0.038610039
B11: 持っていない | C11: =集計_障がい者!$D$101 -> 49 | D11: =集計_障がい者!$E$101 -> 0.18918919
B12: 無回答 | C12: =集計_障がい者!$D$102 -> 17 | D12: =集計_障がい者!$E$102 -> 0.065637066
B16: 図3-21 身体障害者手帳所持者の主な障がい（問9）
B17: ="n="&集計_障がい者!$F$103&"（単一回答）" -> n=259（単一回答）
B18: 選択肢 | C18: 件数 | D18: 割合
B19: 視覚障がい | C19: =集計_障がい者!$D$103 -> 14 | D19: =集計_障がい者!$E$103 -> 0.054054054
B20: 聴覚・平衡機能障がい | C20: =集計_障がい者!$D$104 -> 18 | D20: =集計_障がい者!$E$104 -> 0.069498069
B21: 音声・言語・そしゃく機能障がい | C21: =集計_障がい者!$D$105 -> 4 | D21: =集計_障がい者!$E$105 -> 0.015444015
B22: 肢体不自由（上肢） | C22: =集計_障がい者!$D$106 -> 12 | D22: =集計_障がい者!$E$106 -> 0.046332046
B23: 肢体不自由（下肢） | C23: =集計_障がい者!$D$107 -> 39 | D23: =集計_障がい者!$E$107 -> 0.15057915
B24: 肢体不自由（体幹） | C24: =集計_障がい者!$D$108 -> 11 | D24: =集計_障がい者!$E$108 -> 0.042471042
B25: 内部障がい（１～６以外） | C25: =集計_障がい者!$D$109 -> 81 | D25: =集計_障がい者!$E$109 -> 0.31274131
B26: 無回答 | C26: =集計_障がい者!$D$110 -> 80 | D26: =集計_障がい者!$E$110 -> 0.30888031
B30: 図3-22 療育手帳の所持状況（問10）
B31: ="n="&集計_障がい者!$F$111&"（単一回答）" -> n=259（単一回答）
B32: 選択肢 | C32: 件数 | D32: 割合
B33: Ａ判定 | C33: =集計_障がい者!$D$111 -> 10 | D33: =集計_障がい者!$E$111 -> 0.038610039
B34: Ｂ判定 | C34: =集計_障がい者!$D$112 -> 23 | D34: =集計_障がい者!$E$112 -> 0.088803089
B35: 持っていない | C35: =集計_障がい者!$D$113 -> 199 | D35: =集計_障がい者!$E$113 -> 0.76833977
B36: 無回答 | C36: =集計_障がい者!$D$114 -> 27 | D36: =集計_障がい者!$E$114 -> 0.1042471
B41: 図3-23 精神障害者保健福祉手帳の所持状況（問11）
B42: ="n="&集計_障がい者!$F$115&"（単一回答）" -> n=259（単一回答）
B43: 選択肢 | C43: 件数 | D43: 割合
B44: １級 | C44: =集計_障がい者!$D$115 -> 13 | D44: =集計_障がい者!$E$115 -> 0.05019305
B45: ２級 | C45: =集計_障がい者!$D$116 -> 23 | D45: =集計_障がい者!$E$116 -> 0.088803089
B46: ３級 | C46: =集計_障がい者!$D$117 -> 8 | D46: =集計_障がい者!$E$117 -> 0.030888031
B47: 持っていない | C47: =集計_障がい者!$D$118 -> 196 | D47: =集計_障がい者!$E$118 -> 0.75675676
B48: 無回答 | C48: =集計_障がい者!$D$119 -> 19 | D48: =集計_障がい者!$E$119 -> 0.073359073
B52: 図3-24 特別児童扶養手当の受給状況（問12）
B53: ="n="&集計_障がい者!$F$120&"（単一回答）" -> n=259（単一回答）
B54: 選択肢 | C54: 件数 | D54: 割合
...

Sheet 3章_3暮らし・外出
B2: 図3-36 将来の暮らし方（問17）
B3: ="n="&集計_障がい者!$F$153&"（単一回答）" -> n=259（単一回答）
B4: 選択肢 | C4: 件数 | D4: 割合
B5: 家族と一緒に生活したい | C5: =集計_障がい者!$D$153 -> 158 | D5: =集計_障がい者!$E$153 -> 0.61003861
B6: 一般の住宅でひとり暮らしをしたい | C6: =集計_障がい者!$D$154 -> 23 | D6: =集計_障がい者!$E$154 -> 0.088803089
B7: グループホームなどを利用したい | C7: =集計_障がい者!$D$155 -> 17 | D7: =集計_障がい者!$E$155 -> 0.065637066
B8: 福祉施設で暮らしたい | C8: =集計_障がい者!$D$156 -> 37 | D8: =集計_障がい者!$E$156 -> 0.14285714
B9: その他 | C9: =集計_障がい者!$D$157 -> 9 | D9: =集計_障がい者!$E$157 -> 0.034749035
B10: 無回答 | C10: =集計_障がい者!$D$158 -> 15 | D10: =集計_障がい者!$E$158 -> 0.057915058
B14: 図3-37 将来の暮らし方【障がい別】（問17）
B16: 区分 | C16: 家族と一緒に生活したい | D16: 一般の住宅でひとり暮らしをしたい | E16: グループホームなどを利用したい | F16: 福祉施設で暮らしたい | G16: その他 | H16: 無回答
B17: 全体 | C17: =集計_障がい者!$E$153 -> 0.61003861 | D17: =集計_障がい者!$E$154 -> 0.088803089 | E17: =集計_障がい者!$E$155 -> 0.065637066 | F17: =集計_障がい者!$E$156 -> 0.14285714 | G17: =集計_障がい者!$E$157 -> 0.034749035 | H17: =集計_障がい者!$E$158 -> 0.057915058
B18: 身体障がい（n=193） | C18: =集計_障がい別!$G$154 -> 0.65803109 | D18: =集計_障がい別!$G$155 -> 0.062176166 | E18: =集計_障がい別!$G$156 -> 0.062176166 | F18: =集計_障がい別!$G$157 -> 0.13989637 | G18: =集計_障がい別!$G$158 -> 0.025906736 | H18: =集計_障がい別!$G$159 -> 0.051813472
B19: 知的障がい（n=33） | C19: =集計_障がい別!$H$154 -> 0.33333333 | D19: =集計_障がい別!$H$155 -> 0.18181818 | E19: =集計_障がい別!$H$156 -> 0.15151515 | F19: =集計_障がい別!$H$157 -> 0.21212121 | G19: =集計_障がい別!$H$158 -> 0.060606061 | H19: =集計_障がい別!$H$159 -> 0.060606061
B20: 精神障がい（n=44） | C20: =集計_障がい別!$I$154 -> 0.52272727 | D20: =集計_障がい別!$I$155 -> 0.18181818 | E20: =集計_障がい別!$I$156 -> 0.045454545 | F20: =集計_障がい別!$I$157 -> 0.11363636 | G20: =集計_障がい別!$I$158 -> 0.11363636 | H20: =集計_障がい別!$I$159 -> 0.022727273
B26: 図3-38 地域で生活するために必要な支援（問18）
B27: ="n="&集計_障がい者!$F$163&"（複数回答）" -> n=259（複数回答）
B28: 選択肢 | C28: 件数 | D28: 割合
B29: 経済的な負担の軽減 | C29: =集計_障がい者!$D$163 -> 125 | D29: =集計_障がい者!$E$163 -> 0.48262548
B30: 必要な在宅サービスが適切に利用できること | C30: =集計_障がい者!$D$161 -> 117 | D30: =集計_障がい者!$E$161 -> 0.45173745
B31: 在宅で医療ケアなどが適切に得られること | C31: =集計_障がい者!$D$159 -> 113 | D31: =集計_障がい者!$E$159 -> 0.43629344
B32: 障がい者に適した住居の確保 | C32: =集計_障がい者!$D$160 -> 75 | D32: =集計_障がい者!$E$160 -> 0.28957529
B33: 町外サービス利用時の送迎支援 | C33: =集計_障がい者!$D$169 -> 63 | D33: =集計_障がい者!$E$169 -> 0.24324324
B34: 相談対応等の充実 | C34: =集計_障がい者!$D$164 -> 57 | D34: =集計_障がい者!$E$164 -> 0.22007722
B35: 地域住民等の理解 | C35: =集計_障がい者!$D$165 -> 38 | D35: =集計_障がい者!$E$165 -> 0.14671815
B36: コミュニケーションについての支援 | C36: =集計_障がい者!$D$166 -> 33 | D36: =集計_障がい者!$E$166 -> 0.12741313
B37: 生活訓練等の充実 | C37: =集計_障がい者!$D$162 -> 30 | D37: =集計_障がい者!$E$162 -> 0.11583012
B38: 地域移行に向けた具体的な相談や体験利用ができること | C38: =集計_障がい者!$D$168 -> 25 | D38: =集計_障がい者!$E$168 -> 0.096525097
B39: 意思決定への支援 | C39: =集計_障がい者!$D$167 -> 22 | D39: =集計_障がい者!$E$167 -> 0.084942085
B40: その他 | C40: =集計_障がい者!$D$170 -> 10 | D40: =集計_障がい者!$E$170 -> 0.038610039
B41: 無回答 | C41: =集計_障がい者!$D$171 -> 35 | D41: =集計_障がい者!$E$171 -> 0.13513514
B45: 図3-39 地域で生活するために必要な支援【障がい別】（問18）
B47: 選択肢 | C47: 身体障がい（n=193） | D47: 知的障がい（n=33） | E47: 精神障がい（n=44）
B48: 経済的な負担の軽減 | C48: =集計_障がい別!$G$164 -> 0.45595855 | D48: =集計_障がい別!$H$164 -> 0.33333333 | E48: =集計_障がい別!$I$164 -> 0.56818182
B49: 必要な在宅サービスが適切に利用できること | C49: =集計_障がい別!$G$162 -> 0.47150259 | D49: =集計_障がい別!$H$162 -> 0.24242424 | E49: =集計_障がい別!$I$162 -> 0.34090909
B50: 在宅で医療ケアなどが適切に得られること | C50: =集計_障がい別!$G$160 -> 0.46632124 | D50: =集計_障がい別!$H$160 -> 0.15151515 | E50: =集計_障がい別!$I$160 -> 0.27272727
B51: 障がい者に適した住居の確保 | C51: =集計_障がい別!$G$161 -> 0.27979275 | D51: =集計_障がい別!$H$161 -> 0.45454545 | E51: =集計_障がい別!$I$161 -> 0.40909091
B52: 町外サービス利用時の送迎支援 | C52: =集計_障がい別!$G$170 -> 0.23834197 | D52: =集計_障がい別!$H$170 -> 0.27272727 | E52: =集計_障がい別!$I$170 -> 0.20454545
B53: 相談対応等の充実 | C53: =集計_障がい別!$G$165 -> 0.1761658 | D53: =集計_障がい別!$H$165 -> 0.27272727 | E53: =集計_障がい別!$I$165 -> 0.43181818
B54: 地域住民等の理解 | C54: =集計_障がい別!$G$166 -> 0.11917098 | D54: =集計_障がい別!$H$166 -> 0.3030303 | E54: =集計_障がい別!$I$166 -> 0.34090909
...

Sheet 3章_4日中・就労
B2: 図3-48 平日の日中の過ごし方（問23）
B3: ="n="&集計_障がい者!$F$207&"（単一回答）" -> n=259（単一回答）
B4: 選択肢 | C4: 件数 | D4: 割合
B5: 会社勤めや、自営業、家業などで収入を得て仕事している | C5: =集計_障がい者!$D$207 -> 41 | D5: =集計_障がい者!$E$207 -> 0.15830116
B6: ボランティアなど、収入を得ない仕事をしている | C6: =集計_障がい者!$D$208 -> 2 | D6: =集計_障がい者!$E$208 -> 0.0077220077
B7: 専業主婦（主夫）をしている | C7: =集計_障がい者!$D$209 -> 8 | D7: =集計_障がい者!$E$209 -> 0.030888031
B8: 福祉施設、作業所等に通っている（就労継続支援Ａ型も含む） | C8: =集計_障がい者!$D$210 -> 26 | D8: =集計_障がい者!$E$210 -> 0.1003861
B9: 病院などのデイケアに通っている | C9: =集計_障がい者!$D$211 -> 3 | D9: =集計_障がい者!$E$211 -> 0.011583012
B10: リハビリテーションを受けている | C10: =集計_障がい者!$D$212 -> 3 | D10: =集計_障がい者!$E$212 -> 0.011583012
B11: 自宅で過ごしている | C11: =集計_障がい者!$D$213 -> 114 | D11: =集計_障がい者!$E$213 -> 0.44015444
B12: 入所している施設や病院等で過ごしている | C12: =集計_障がい者!$D$214 -> 24 | D12: =集計_障がい者!$E$214 -> 0.092664093
B13: 大学、専門学校、職業訓練校などに通っている | C13: =集計_障がい者!$D$215 -> 3 | D13: =集計_障がい者!$E$215 -> 0.011583012
B14: その他 | C14: =集計_障がい者!$D$216 -> 7 | D14: =集計_障がい者!$E$216 -> 0.027027027
B15: 無回答 | C15: =集計_障がい者!$D$217 -> 28 | D15: =集計_障がい者!$E$217 -> 0.10810811
B19: 図3-49 平日の日中の過ごし方【障がい別】（問23）
B21: 選択肢 | C21: 身体障がい（n=193） | D21: 知的障がい（n=33） | E21: 精神障がい（n=44）
B22: 会社勤めや、自営業、家業などで収入を得て仕事している | C22: =集計_障がい別!$G$208 -> 0.15025907 | D22: =集計_障がい別!$H$208 -> 0.15151515 | E22: =集計_障がい別!$I$208 -> 0.18181818
B23: ボランティアなど、収入を得ない仕事をしている | C23: =集計_障がい別!$G$209 -> 0.010362694 | D23: =集計_障がい別!$H$209 -> 0 | E23: =集計_障がい別!$I$209 -> 0
B24: 専業主婦（主夫）をしている | C24: =集計_障がい別!$G$210 -> 0.041450777 | D24: =集計_障がい別!$H$210 -> 0 | E24: =集計_障がい別!$I$210 -> 0
B25: 福祉施設、作業所等に通っている（就労継続支援Ａ型も含む） | C25: =集計_障がい別!$G$211 -> 0.03626943 | D25: =集計_障がい別!$H$211 -> 0.42424242 | E25: =集計_障がい別!$I$211 -> 0.29545455
B26: 病院などのデイケアに通っている | C26: =集計_障がい別!$G$212 -> 0.015544041 | D26: =集計_障がい別!$H$212 -> 0 | E26: =集計_障がい別!$I$212 -> 0.022727273
B27: リハビリテーションを受けている | C27: =集計_障がい別!$G$213 -> 0.010362694 | D27: =集計_障がい別!$H$213 -> 0 | E27: =集計_障がい別!$I$213 -> 0.022727273
B28: 自宅で過ごしている | C28: =集計_障がい別!$G$214 -> 0.49740933 | D28: =集計_障がい別!$H$214 -> 0.18181818 | E28: =集計_障がい別!$I$214 -> 0.36363636
B29: 入所している施設や病院等で過ごしている | C29: =集計_障がい別!$G$215 -> 0.088082902 | D29: =集計_障がい別!$H$215 -> 0.15151515 | E29: =集計_障がい別!$I$215 -> 0.045454545
B30: 大学、専門学校、職業訓練校などに通っている | C30: =集計_障がい別!$G$216 -> 0.0051813472 | D30: =集計_障がい別!$H$216 -> 0.03030303 | E30: =集計_障がい別!$I$216 -> 0.022727273
B31: その他 | C31: =集計_障がい別!$G$217 -> 0.031088083 | D31: =集計_障がい別!$H$217 -> 0.03030303 | E31: =集計_障がい別!$I$217 -> 0.022727273
B32: 無回答 | C32: =集計_障がい別!$G$218 -> 0.11398964 | D32: =集計_障がい別!$H$218 -> 0.03030303 | E32: =集計_障がい別!$I$218 -> 0.022727273
B53: 図3-50 業務形態（問24）
B54: ="n="&集計_障がい者!$F$218&"（単一回答）" -> n=259（単一回答）
B55: 選択肢 | C55: 件数 | D55: 割合
B56: 正職員で他の職員と勤務条件等に違いはない | C56: =集計_障がい者!$D$218 -> 10 | D56: =集計_障がい者!$E$218 -> 0.038610039
B57: 正職員で短時間勤務などの障がい者配慮がある | C57: =集計_障がい者!$D$219 -> 8 | D57: =集計_障がい者!$E$219 -> 0.030888031
B58: パート・アルバイト等の非常勤職員、派遣職員 | C58: =集計_障がい者!$D$220 -> 14 | D58: =集計_障がい者!$E$220 -> 0.054054054
B59: 自営業、農業、林業、水産業など | C59: =集計_障がい者!$D$221 -> 7 | D59: =集計_障がい者!$E$221 -> 0.027027027
B60: その他 | C60: =集計_障がい者!$D$222 -> 2 | D60: =集計_障がい者!$E$222 -> 0.0077220077
B61: 無回答 | C61: =集計_障がい者!$D$223 -> 218 | D61: =集計_障がい者!$E$223 -> 0.84169884
B66: 図3-51 業務形態【障がい別】（問24）
B68: 区分 | C68: 正職員で他の職員と勤務条件等に違いはない | D68: 正職員で短時間勤務などの障がい者配慮がある | E68: パート・アルバイト等の非常勤職員、派遣職員 | F68: 自営業、農業、林業、水産業など | G68: その他 | H68: 無回答
B69: 全体 | C69: =集計_障がい者!$E$218 -> 0.038610039 | D69: =集計_障がい者!$E$219 -> 0.030888031 | E69: =集計_障がい者!$E$220 -> 0.054054054 | F69: =集計_障がい者!$E$221 -> 0.027027027 | G69: =集計_障がい者!$E$222 -> 0.0077220077 | H69: =集計_障がい者!$E$223 -> 0.84169884
B70: 身体障がい（n=193） | C70: =集計_障がい別!$G$219 -> 0.041450777 | D70: =集計_障がい別!$G$220 -> 0.020725389 | E70: =集計_障がい別!$G$221 -> 0.046632124 | F70: =集計_障がい別!$G$222 -> 0.03626943 | G70: =集計_障がい別!$G$223 -> 0.0051813472 | H70: =集計_障がい別!$G$224 -> 0.84974093
...

Sheet 3章_5サービス
B2: 図3-58 障がい支援区分の認定状況（問28）
B3: ="n="&集計_障がい者!$F$243&"（単一回答）" -> n=259（単一回答）
B4: 選択肢 | C4: 件数 | D4: 割合
B5: 区分１ | C5: =集計_障がい者!$D$243 -> 8 | D5: =集計_障がい者!$E$243 -> 0.030888031
B6: 区分２ | C6: =集計_障がい者!$D$244 -> 8 | D6: =集計_障がい者!$E$244 -> 0.030888031
B7: 区分３ | C7: =集計_障がい者!$D$245 -> 5 | D7: =集計_障がい者!$E$245 -> 0.019305019
B8: 区分４ | C8: =集計_障がい者!$D$246 -> 4 | D8: =集計_障がい者!$E$246 -> 0.015444015
B9: 区分５ | C9: =集計_障がい者!$D$247 -> 5 | D9: =集計_障がい者!$E$247 -> 0.019305019
B10: 区分６ | C10: =集計_障がい者!$D$248 -> 3 | D10: =集計_障がい者!$E$248 -> 0.011583012
B11: 受けていない | C11: =集計_障がい者!$D$249 -> 149 | D11: =集計_障がい者!$E$249 -> 0.57528958
B12: 無回答 | C12: =集計_障がい者!$D$250 -> 77 | D12: =集計_障がい者!$E$250 -> 0.2972973
B16: 図3-59 障がい支援区分の認定状況【障がい別】（問28）
B18: 区分 | C18: 区分１ | D18: 区分２ | E18: 区分３ | F18: 区分４ | G18: 区分５ | H18: 区分６ | I18: 受けていない | J18: 無回答
B19: 全体 | C19: =集計_障がい者!$E$243 -> 0.030888031 | D19: =集計_障がい者!$E$244 -> 0.030888031 | E19: =集計_障がい者!$E$245 -> 0.019305019 | F19: =集計_障がい者!$E$246 -> 0.015444015 | G19: =集計_障がい者!$E$247 -> 0.019305019 | H19: =集計_障がい者!$E$248 -> 0.011583012 | I19: =集計_障がい者!$E$249 -> 0.57528958 | J19: =集計_障がい者!$E$250 -> 0.2972973
B20: 身体障がい（n=193） | C20: =集計_障がい別!$G$244 -> 0.03626943 | D20: =集計_障がい別!$G$245 -> 0.025906736 | E20: =集計_障がい別!$G$246 -> 0.0051813472 | F20: =集計_障がい別!$G$247 -> 0.0051813472 | G20: =集計_障がい別!$G$248 -> 0.010362694 | H20: =集計_障がい別!$G$249 -> 0.010362694 | I20: =集計_障がい別!$G$250 -> 0.60103627 | J20: =集計_障がい別!$G$251 -> 0.30569948
B21: 知的障がい（n=33） | C21: =集計_障がい別!$H$244 -> 0.060606061 | D21: =集計_障がい別!$H$245 -> 0.060606061 | E21: =集計_障がい別!$H$246 -> 0.12121212 | F21: =集計_障がい別!$H$247 -> 0.03030303 | G21: =集計_障がい別!$H$248 -> 0.060606061 | H21: =集計_障がい別!$H$249 -> 0.060606061 | I21: =集計_障がい別!$H$250 -> 0.45454545 | J21: =集計_障がい別!$H$251 -> 0.15151515
B22: 精神障がい（n=44） | C22: =集計_障がい別!$I$244 -> 0.068181818 | D22: =集計_障がい別!$I$245 -> 0.068181818 | E22: =集計_障がい別!$I$246 -> 0.068181818 | F22: =集計_障がい別!$I$247 -> 0 | G22: =集計_障がい別!$I$248 -> 0.045454545 | H22: =集計_障がい別!$I$249 -> 0.022727273 | I22: =集計_障がい別!$I$250 -> 0.47727273 | J22: =集計_障がい別!$I$251 -> 0.25
B30: 図3-60 介護保険サービスの利用状況（問29）
B31: ="n="&集計_障がい者!$F$251&"（単一回答）" -> n=259（単一回答）
B32: 選択肢 | C32: 件数 | D32: 割合
B33: 利用している | C33: =集計_障がい者!$D$251 -> 77 | D33: =集計_障がい者!$E$251 -> 0.2972973
B34: 利用していない | C34: =集計_障がい者!$D$252 -> 161 | D34: =集計_障がい者!$E$252 -> 0.62162162
B35: 無回答 | C35: =集計_障がい者!$D$253 -> 21 | D35: =集計_障がい者!$E$253 -> 0.081081081
B42: 図3-61 介護保険サービスの利用状況【障がい別】（問29）
B44: 区分 | C44: 利用している | D44: 利用していない | E44: 無回答
B45: 全体 | C45: =集計_障がい者!$E$251 -> 0.2972973 | D45: =集計_障がい者!$E$252 -> 0.62162162 | E45: =集計_障がい者!$E$253 -> 0.081081081
B46: 身体障がい（n=193） | C46: =集計_障がい別!$G$252 -> 0.33678756 | D46: =集計_障がい別!$G$253 -> 0.59585492 | E46: =集計_障がい別!$G$254 -> 0.067357513
B47: 知的障がい（n=33） | C47: =集計_障がい別!$H$252 -> 0.12121212 | D47: =集計_障がい別!$H$253 -> 0.72727273 | E47: =集計_障がい別!$H$254 -> 0.15151515
B48: 精神障がい（n=44） | C48: =集計_障がい別!$I$252 -> 0.15909091 | D48: =集計_障がい別!$I$253 -> 0.70454545 | E48: =集計_障がい別!$I$254 -> 0.13636364
B56: 図3-62 要介護度（問30）
B57: ="n="&集計_障がい者!$F$254&"（単一回答）" -> n=259（単一回答）
B58: 選択肢 | C58: 件数 | D58: 割合
B59: 要支援１ | C59: =集計_障がい者!$D$254 -> 6 | D59: =集計_障がい者!$E$254 -> 0.023166023
B60: 要支援２ | C60: =集計_障がい者!$D$255 -> 15 | D60: =集計_障がい者!$E$255 -> 0.057915058
B61: 要介護１ | C61: =集計_障がい者!$D$256 -> 5 | D61: =集計_障がい者!$E$256 -> 0.019305019
B62: 要介護２ | C62: =集計_障がい者!$D$257 -> 20 | D62: =集計_障がい者!$E$257 -> 0.077220077
B63: 要介護３ | C63: =集計_障がい者!$D$258 -> 8 | D63: =集計_障がい者!$E$258 -> 0.030888031
B64: 要介護４ | C64: =集計_障がい者!$D$259 -> 13 | D64: =集計_障がい者!$E$259 -> 0.05019305
B65: 要介護５ | C65: =集計_障がい者!$D$260 -> 8 | D65: =集計_障がい者!$E$260 -> 0.030888031
B66: 無回答 | C66: =集計_障がい者!$D$261 -> 184 | D66: =集計_障がい者!$E$261 -> 0.71042471
...

Sheet 3章_6相談・権利
B2: 図3-66 悩みや困ったことの相談相手（問33）
B3: ="n="&集計_障がい者!$F$352&"（複数回答）" -> n=259（複数回答）
B4: 選択肢 | C4: 件数 | D4: 割合
B5: 家族や親せき | C5: =集計_障がい者!$D$352 -> 191 | D5: =集計_障がい者!$E$352 -> 0.73745174
B6: かかりつけの医師や看護師 | C6: =集計_障がい者!$D$359 -> 64 | D6: =集計_障がい者!$E$359 -> 0.24710425
B7: 友人・知人 | C7: =集計_障がい者!$D$353 -> 62 | D7: =集計_障がい者!$E$353 -> 0.23938224
B8: 施設の指導員など | C8: =集計_障がい者!$D$356 -> 37 | D8: =集計_障がい者!$E$356 -> 0.14285714
B9: 病院のケースワーカーや介護保険のケアマネージャー | C9: =集計_障がい者!$D$360 -> 29 | D9: =集計_障がい者!$E$360 -> 0.11196911
B10: 相談支援事業所などの民間の相談窓口 | C10: =集計_障がい者!$D$363 -> 22 | D10: =集計_障がい者!$E$363 -> 0.084942085
B11: 行政機関の相談窓口 | C11: =集計_障がい者!$D$364 -> 22 | D11: =集計_障がい者!$E$364 -> 0.084942085
B12: 近所の人 | C12: =集計_障がい者!$D$354 -> 21 | D12: =集計_障がい者!$E$354 -> 0.081081081
B13: ホームヘルパーなどサービス事業所の人 | C13: =集計_障がい者!$D$357 -> 18 | D13: =集計_障がい者!$E$357 -> 0.069498069
B14: 職場の上司や同僚 | C14: =集計_障がい者!$D$355 -> 14 | D14: =集計_障がい者!$E$355 -> 0.054054054
B15: 相談する相手がいない | C15: =集計_障がい者!$D$366 -> 12 | D15: =集計_障がい者!$E$366 -> 0.046332046
B16: 民生委員・児童委員 | C16: =集計_障がい者!$D$361 -> 5 | D16: =集計_障がい者!$E$361 -> 0.019305019
B17: 学校の先生 | C17: =集計_障がい者!$D$362 -> 3 | D17: =集計_障がい者!$E$362 -> 0.011583012
B18: 障がい者団体や家族会 | C18: =集計_障がい者!$D$358 -> 1 | D18: =集計_障がい者!$E$358 -> 0.0038610039
B19: その他 | C19: =集計_障がい者!$D$365 -> 7 | D19: =集計_障がい者!$E$365 -> 0.027027027
B20: 無回答 | C20: =集計_障がい者!$D$367 -> 11 | D20: =集計_障がい者!$E$367 -> 0.042471042
B24: 図3-67 悩みや困ったことの相談相手【障がい別】（問33）
B26: 選択肢 | C26: 身体障がい（n=193） | D26: 知的障がい（n=33） | E26: 精神障がい（n=44）
B27: 家族や親せき | C27: =集計_障がい別!$G$353 -> 0.76683938 | D27: =集計_障がい別!$H$353 -> 0.51515152 | E27: =集計_障がい別!$I$353 -> 0.70454545
B28: かかりつけの医師や看護師 | C28: =集計_障がい別!$G$360 -> 0.23316062 | D28: =集計_障がい別!$H$360 -> 0.12121212 | E28: =集計_障がい別!$I$360 -> 0.36363636
B29: 友人・知人 | C29: =集計_障がい別!$G$354 -> 0.2642487 | D29: =集計_障がい別!$H$354 -> 0.15151515 | E29: =集計_障がい別!$I$354 -> 0.22727273
B30: 施設の指導員など | C30: =集計_障がい別!$G$357 -> 0.098445596 | D30: =集計_障がい別!$H$357 -> 0.36363636 | E30: =集計_障がい別!$I$357 -> 0.20454545
B31: 病院のケースワーカーや介護保険のケアマネージャー | C31: =集計_障がい別!$G$361 -> 0.12953368 | D31: =集計_障がい別!$H$361 -> 0.060606061 | E31: =集計_障がい別!$I$361 -> 0.13636364
B32: 相談支援事業所などの民間の相談窓口 | C32: =集計_障がい別!$G$364 -> 0.056994819 | D32: =集計_障がい別!$H$364 -> 0.15151515 | E32: =集計_障がい別!$I$364 -> 0.15909091
B33: 行政機関の相談窓口 | C33: =集計_障がい別!$G$365 -> 0.093264249 | D33: =集計_障がい別!$H$365 -> 0.03030303 | E33: =集計_障がい別!$I$365 -> 0.11363636
B34: 近所の人 | C34: =集計_障がい別!$G$355 -> 0.10362694 | D34: =集計_障がい別!$H$355 -> 0 | E34: =集計_障がい別!$I$355 -> 0
B35: ホームヘルパーなどサービス事業所の人 | C35: =集計_障がい別!$G$358 -> 0.056994819 | D35: =集計_障がい別!$H$358 -> 0.15151515 | E35: =集計_障がい別!$I$358 -> 0.11363636
B36: 職場の上司や同僚 | C36: =集計_障がい別!$G$356 -> 0.03626943 | D36: =集計_障がい別!$H$356 -> 0.15151515 | E36: =集計_障がい別!$I$356 -> 0.090909091
B37: 相談する相手がいない | C37: =集計_障がい別!$G$367 -> 0.046632124 | D37: =集計_障がい別!$H$367 -> 0.03030303 | E37: =集計_障がい別!$I$367 -> 0.045454545
B38: 民生委員・児童委員 | C38: =集計_障がい別!$G$362 -> 0.020725389 | D38: =集計_障がい別!$H$362 -> 0 | E38: =集計_障がい別!$I$362 -> 0.022727273
B39: 学校の先生 | C39: =集計_障がい別!$G$363 -> 0 | D39: =集計_障がい別!$H$363 -> 0.03030303 | E39: =集計_障がい別!$I$363 -> 0.068181818
B40: 障がい者団体や家族会 | C40: =集計_障がい別!$G$359 -> 0 | D40: =集計_障がい別!$H$359 -> 0 | E40: =集計_障がい別!$I$359 -> 0.022727273
B41: その他 | C41: =集計_障がい別!$G$366 -> 0.020725389 | D41: =集計_障がい別!$H$366 -> 0.03030303 | E41: =集計_障がい別!$I$366 -> 0.045454545
B42: 無回答 | C42: =集計_障がい別!$G$368 -> 0.041450777 | D42: =集計_障がい別!$H$368 -> 0.090909091 | E42: =集計_障がい別!$I$368 -> 0.090909091
B73: 図3-68 障がいや福祉サービスに関する情報の入手先（問34）
B74: ="n="&集計_障がい者!$F$368&"（複数回答）" -> n=259（複数回答）
B75: 選択肢 | C75: 件数 | D75: 割合
...

Sheet 3章_7災害・意見
B2: 図3-82 災害時に一人で避難できるか（問41）
B3: ="n="&集計_障がい者!$F$415&"（単一回答）" -> n=259（単一回答）
B4: 選択肢 | C4: 件数 | D4: 割合
B5: できる | C5: =集計_障がい者!$D$415 -> 100 | D5: =集計_障がい者!$E$415 -> 0.38610039
B6: できない | C6: =集計_障がい者!$D$416 -> 92 | D6: =集計_障がい者!$E$416 -> 0.35521236
B7: わからない | C7: =集計_障がい者!$D$417 -> 52 | D7: =集計_障がい者!$E$417 -> 0.2007722
B8: 無回答 | C8: =集計_障がい者!$D$418 -> 15 | D8: =集計_障がい者!$E$418 -> 0.057915058
B13: 図3-83 災害時に一人で避難できるか【障がい別】（問41）
B15: 区分 | C15: できる | D15: できない | E15: わからない | F15: 無回答
B16: 全体 | C16: =集計_障がい者!$E$415 -> 0.38610039 | D16: =集計_障がい者!$E$416 -> 0.35521236 | E16: =集計_障がい者!$E$417 -> 0.2007722 | F16: =集計_障がい者!$E$418 -> 0.057915058
B17: 身体障がい（n=193） | C17: =集計_障がい別!$G$416 -> 0.40932642 | D17: =集計_障がい別!$G$417 -> 0.35233161 | E17: =集計_障がい別!$G$418 -> 0.17098446 | F17: =集計_障がい別!$G$419 -> 0.067357513
B18: 知的障がい（n=33） | C18: =集計_障がい別!$H$416 -> 0.33333333 | D18: =集計_障がい別!$H$417 -> 0.36363636 | E18: =集計_障がい別!$H$418 -> 0.24242424 | F18: =集計_障がい別!$H$419 -> 0.060606061
B19: 精神障がい（n=44） | C19: =集計_障がい別!$I$416 -> 0.29545455 | D19: =集計_障がい別!$I$417 -> 0.18181818 | E19: =集計_障がい別!$I$418 -> 0.40909091 | F19: =集計_障がい別!$I$419 -> 0.11363636
B28: 図3-84 近所で助けてくれる人の有無（問42）
B29: ="n="&集計_障がい者!$F$419&"（単一回答）" -> n=259（単一回答）
B30: 選択肢 | C30: 件数 | D30: 割合
B31: いる | C31: =集計_障がい者!$D$419 -> 82 | D31: =集計_障がい者!$E$419 -> 0.31660232
B32: いない | C32: =集計_障がい者!$D$420 -> 60 | D32: =集計_障がい者!$E$420 -> 0.23166023
B33: わからない | C33: =集計_障がい者!$D$421 -> 94 | D33: =集計_障がい者!$E$421 -> 0.36293436
B34: 無回答 | C34: =集計_障がい者!$D$422 -> 23 | D34: =集計_障がい者!$E$422 -> 0.088803089
B39: 図3-85 近所で助けてくれる人の有無【障がい別】（問42）
B41: 区分 | C41: いる | D41: いない | E41: わからない | F41: 無回答
B42: 全体 | C42: =集計_障がい者!$E$419 -> 0.31660232 | D42: =集計_障がい者!$E$420 -> 0.23166023 | E42: =集計_障がい者!$E$421 -> 0.36293436 | F42: =集計_障がい者!$E$422 -> 0.088803089
B43: 身体障がい（n=193） | C43: =集計_障がい別!$G$420 -> 0.37305699 | D43: =集計_障がい別!$G$421 -> 0.19170984 | E43: =集計_障がい別!$G$422 -> 0.34715026 | F43: =集計_障がい別!$G$423 -> 0.088082902
B44: 知的障がい（n=33） | C44: =集計_障がい別!$H$420 -> 0.18181818 | D44: =集計_障がい別!$H$421 -> 0.27272727 | E44: =集計_障がい別!$H$422 -> 0.36363636 | F44: =集計_障がい別!$H$423 -> 0.18181818
B45: 精神障がい（n=44） | C45: =集計_障がい別!$I$420 -> 0.13636364 | D45: =集計_障がい別!$I$421 -> 0.25 | E45: =集計_障がい別!$I$422 -> 0.45454545 | F45: =集計_障がい別!$I$423 -> 0.15909091
B54: 図3-86 災害時に困ること（問43）
B55: ="n="&集計_障がい者!$F$423&"（複数回答）" -> n=259（複数回答）
B56: 選択肢 | C56: 件数 | D56: 割合
B57: 投薬や治療が受けられない | C57: =集計_障がい者!$D$423 -> 134 | D57: =集計_障がい者!$E$423 -> 0.51737452
B58: 避難場所の設備（トイレ等）や生活環境が不安 | C58: =集計_障がい者!$D$430 -> 121 | D58: =集計_障がい者!$E$430 -> 0.46718147
B59: 安全なところまで、迅速に避難することができない | C59: =集計_障がい者!$D$427 -> 97 | D59: =集計_障がい者!$E$427 -> 0.37451737
B60: 救助を求めることができない | C60: =集計_障がい者!$D$426 -> 52 | D60: =集計_障がい者!$E$426 -> 0.2007722
B61: 周囲とのコミュニケーションがとれない | C61: =集計_障がい者!$D$429 -> 43 | D61: =集計_障がい者!$E$429 -> 0.16602317
B62: 被害状況、避難場所などの情報が入手できない | C62: =集計_障がい者!$D$428 -> 41 | D62: =集計_障がい者!$E$428 -> 0.15830116
B63: 医療機器の電源確保 | C63: =集計_障がい者!$D$431 -> 40 | D63: =集計_障がい者!$E$431 -> 0.15444015
B64: 補装具や日常生活用具の入手ができなくなる | C64: =集計_障がい者!$D$425 -> 31 | D64: =集計_障がい者!$E$425 -> 0.11969112
B65: 補装具の使用が困難になる | C65: =集計_障がい者!$D$424 -> 25 | D65: =集計_障がい者!$E$424 -> 0.096525097
B66: その他 | C66: =集計_障がい者!$D$432 -> 5 | D66: =集計_障がい者!$E$432 -> 0.019305019
B67: 特にない | C67: =集計_障がい者!$D$433 -> 34 | D67: =集計_障がい者!$E$433 -> 0.13127413
...

Sheet 4章_クロス集計
B2: 表4-1 年齢×将来の暮らし方（問3×問17）
B3: 【件数】青字のセルが入力値です
B4: 区分 | C4: 18～29歳 | D4: 30～39歳 | E4: 40～49歳 | F4: 50～64歳 | G4: 65歳以上
B5: 回答者数（n） | C5: 12 | D5: 12 | E5: 16 | F5: 32 | G5: 177
B6: 家族と一緒に生活したい | C6: 8 | D6: 6 | E6: 10 | F6: 16 | G6: 109
B7: 一般の住宅でひとり暮らしをしたい | C7: 2 | D7: 4 | E7: 1 | F7: 3 | G7: 13
B8: グループホームなどを利用したい | C8: 2 | D8: 2 | E8: 1 | F8: 3 | G8: 9
B9: 福祉施設で暮らしたい | C9: 0 | D9: 0 | E9: 2 | F9: 2 | G9: 32
B10: その他 | C10: 0 | D10: 0 | E10: 2 | F10: 3 | G10: 4
B11: 無回答 | C11: 0 | D11: 0 | E11: 0 | F11: 5 | G11: 10
B13: 【割合】各区分の回答者数（n）に占める割合（計算式）
B14: 区分 | C14: 18～29歳 | D14: 30～39歳 | E14: 40～49歳 | F14: 50～64歳 | G14: 65歳以上
B15: 家族と一緒に生活したい | C15: =IF($C$5=0,0,$C$6/$C$5) -> 0.66666667 | D15: =IF($D$5=0,0,$D$6/$D$5) -> 0.5 | E15: =IF($E$5=0,0,$E$6/$E$5) -> 0.625 | F15: =IF($F$5=0,0,$F$6/$F$5) -> 0.5 | G15: =IF($G$5=0,0,$G$6/$G$5) -> 0.61581921
B16: 一般の住宅でひとり暮らしをしたい | C16: =IF($C$5=0,0,$C$7/$C$5) -> 0.16666667 | D16: =IF($D$5=0,0,$D$7/$D$5) -> 0.33333333 | E16: =IF($E$5=0,0,$E$7/$E$5) -> 0.0625 | F16: =IF($F$5=0,0,$F$7/$F$5) -> 0.09375 | G16: =IF($G$5=0,0,$G$7/$G$5) -> 0.073446328
B17: グループホームなどを利用したい | C17: =IF($C$5=0,0,$C$8/$C$5) -> 0.16666667 | D17: =IF($D$5=0,0,$D$8/$D$5) -> 0.16666667 | E17: =IF($E$5=0,0,$E$8/$E$5) -> 0.0625 | F17: =IF($F$5=0,0,$F$8/$F$5) -> 0.09375 | G17: =IF($G$5=0,0,$G$8/$G$5) -> 0.050847458
B18: 福祉施設で暮らしたい | C18: =IF($C$5=0,0,$C$9/$C$5) -> 0 | D18: =IF($D$5=0,0,$D$9/$D$5) -> 0 | E18: =IF($E$5=0,0,$E$9/$E$5) -> 0.125 | F18: =IF($F$5=0,0,$F$9/$F$5) -> 0.0625 | G18: =IF($G$5=0,0,$G$9/$G$5) -> 0.18079096
B19: その他 | C19: =IF($C$5=0,0,$C$10/$C$5) -> 0 | D19: =IF($D$5=0,0,$D$10/$D$5) -> 0 | E19: =IF($E$5=0,0,$E$10/$E$5) -> 0.125 | F19: =IF($F$5=0,0,$F$10/$F$5) -> 0.09375 | G19: =IF($G$5=0,0,$G$10/$G$5) -> 0.02259887
B20: 無回答 | C20: =IF($C$5=0,0,$C$11/$C$5) -> 0 | D20: =IF($D$5=0,0,$D$11/$D$5) -> 0 | E20: =IF($E$5=0,0,$E$11/$E$5) -> 0 | F20: =IF($F$5=0,0,$F$11/$F$5) -> 0.15625 | G20: =IF($G$5=0,0,$G$11/$G$5) -> 0.056497175
B21: ※色が濃いほど割合が高く、太字は各区分で最も割合が高い項目です（条件付き書式）。
B23: 図4-1 年齢×将来の暮らし方（問3×問17）
B25: 区分 | C25: 家族と一緒に生活したい | D25: 一般の住宅でひとり暮らしをしたい | E25: グループホームなどを利用したい | F25: 福祉施設で暮らしたい | G25: その他 | H25: 無回答
B26: 18～29歳 | C26: =$C$15 -> 0.66666667 | D26: =$C$16 -> 0.16666667 | E26: =$C$17 -> 0.16666667 | F26: =$C$18 -> 0 | G26: =$C$19 -> 0 | H26: =$C$20 -> 0
B27: 30～39歳 | C27: =$D$15 -> 0.5 | D27: =$D$16 -> 0.33333333 | E27: =$D$17 -> 0.16666667 | F27: =$D$18 -> 0 | G27: =$D$19 -> 0 | H27: =$D$20 -> 0
B28: 40～49歳 | C28: =$E$15 -> 0.625 | D28: =$E$16 -> 0.0625 | E28: =$E$17 -> 0.0625 | F28: =$E$18 -> 0.125 | G28: =$E$19 -> 0.125 | H28: =$E$20 -> 0
B29: 50～64歳 | C29: =$F$15 -> 0.5 | D29: =$F$16 -> 0.09375 | E29: =$F$17 -> 0.09375 | F29: =$F$18 -> 0.0625 | G29: =$F$19 -> 0.09375 | H29: =$F$20 -> 0.15625
B30: 65歳以上 | C30: =$G$15 -> 0.61581921 | D30: =$G$16 -> 0.073446328 | E30: =$G$17 -> 0.050847458 | F30: =$G$18 -> 0.18079096 | G30: =$G$19 -> 0.02259887 | H30: =$G$20 -> 0.056497175
B38: 表4-2 現在の暮らしの場×将来の暮らし方（問4×問17）
B39: 【件数】青字のセルが入力値です
B40: 区分 | C40: 自宅（アパート・町営住宅等も含む）でひとり暮らし | D40: 自宅（アパート・町営住宅等も含む）で家族等と一緒に住んでいる | E40: グループホームで暮らしている | F40: 福祉施設（障がい者支援施設、高齢者支援施設）で暮らしている | G40: 病院に入院している | H40: その他
B41: 回答者数（n） | C41: 41 | D41: 169 | E41: 11 | F41: 24 | G41: 6 | H41: 1
B42: 家族と一緒に生活したい | C42: 12 | D42: 132 | E42: 2 | F42: 3 | G42: 3 | H42: 1
B43: 一般の住宅でひとり暮らしをしたい | C43: 10 | D43: 11 | E43: 1 | F43: 1 | G43: 0 | H43: 0
B44: グループホームなどを利用したい | C44: 5 | D44: 5 | E44: 5 | F44: 1 | G44: 1 | H44: 0
B45: 福祉施設で暮らしたい | C45: 8 | D45: 9 | E45: 1 | F45: 16 | G45: 2 | H45: 0
B46: その他 | C46: 3 | D46: 5 | E46: 0 | F46: 1 | G46: 0 | H46: 0
B47: 無回答 | C47: 3 | D47: 7 | E47: 2 | F47: 2 | G47: 0 | H47: 0
B49: 【割合】各区分の回答者数（n）に占める割合（計算式）
B50: 区分 | C50: 自宅（アパート・町営住宅等も含む）でひとり暮らし | D50: 自宅（アパート・町営住宅等も含む）で家族等と一緒に住んでいる | E50: グループホームで暮らしている | F50: 福祉施設（障がい者支援施設、高齢者支援施設）で暮らしている | G50: 病院に入院している | H50: その他
B51: 家族と一緒に生活したい | C51: =IF($C$41=0,0,$C$42/$C$41) -> 0.29268293 | D51: =IF($D$41=0,0,$D$42/$D$41) -> 0.78106509 | E51: =IF($E$41=0,0,$E$42/$E$41) -> 0.18181818 | F51: =IF($F$41=0,0,$F$42/$F$41) -> 0.125 | G51: =IF($G$41=0,0,$G$42/$G$41) -> 0.5 | H51: =IF($H$41=0,0,$H$42/$H$41) -> 1
B52: 一般の住宅でひとり暮らしをしたい | C52: =IF($C$41=0,0,$C$43/$C$41) -> 0.24390244 | D52: =IF($D$41=0,0,$D$43/$D$41) -> 0.065088757 | E52: =IF($E$41=0,0,$E$43/$E$41) -> 0.090909091 | F52: =IF($F$41=0,0,$F$43/$F$41) -> 0.041666667 | G52: =IF($G$41=0,0,$G$43/$G$41) -> 0 | H52: =IF($H$41=0,0,$H$43/$H$41) -> 0
...

Sheet 5章_障がい児
B2: 図5-1 調査票の回答者（問1）
B3: ="n="&集計_障がい児!$F$5&"（単一回答）" -> n=25（単一回答）
B4: 選択肢 | C4: 件数 | D4: 割合
B5: ご本人が自分で記入 | C5: =集計_障がい児!$D$5 -> 5 | D5: =集計_障がい児!$E$5 -> 0.2
B6: ご本人が回答し、家族の方が記入 | C6: =集計_障がい児!$D$6 -> 8 | D6: =集計_障がい児!$E$6 -> 0.32
B7: 家族の方が代理で回答・記入 | C7: =集計_障がい児!$D$7 -> 4 | D7: =集計_障がい児!$E$7 -> 0.16
B8: ご本人が回答し、施設職員が記入 | C8: =集計_障がい児!$D$8 -> 1 | D8: =集計_障がい児!$E$8 -> 0.04
B9: 施設職員が代理で回答・記入 | C9: =集計_障がい児!$D$9 -> 5 | D9: =集計_障がい児!$E$9 -> 0.2
B10: その他 | C10: =集計_障がい児!$D$10 -> 1 | D10: =集計_障がい児!$E$10 -> 0.04
B11: 無回答 | C11: =集計_障がい児!$D$11 -> 1 | D11: =集計_障がい児!$E$11 -> 0.04
B15: 図5-2 性別（問2）
B16: ="n="&集計_障がい児!$F$12&"（単一回答）" -> n=25（単一回答）
B17: 選択肢 | C17: 件数 | D17: 割合
B18: 男性 | C18: =集計_障がい児!$D$12 -> 13 | D18: =集計_障がい児!$E$12 -> 0.52
B19: 女性 | C19: =集計_障がい児!$D$13 -> 10 | D19: =集計_障がい児!$E$13 -> 0.4
B20: わからない | C20: =集計_障がい児!$D$14 -> 0 | D20: =集計_障がい児!$E$14 -> 0
B21: 答えたくない | C21: =集計_障がい児!$D$15 -> 1 | D21: =集計_障がい児!$E$15 -> 0.04
B22: 無回答 | C22: =集計_障がい児!$D$16 -> 1 | D22: =集計_障がい児!$E$16 -> 0.04
B26: 図5-3 年齢（問3）
B27: ="n="&集計_障がい児!$F$17&"（単一回答）" -> n=25（単一回答）
B28: 選択肢 | C28: 件数 | D28: 割合
B29: 0～5歳 | C29: =集計_障がい児!$D$17 -> 3 | D29: =集計_障がい児!$E$17 -> 0.12
B30: 6～11歳 | C30: =集計_障がい児!$D$18 -> 6 | D30: =集計_障がい児!$E$18 -> 0.24
B31: 12～14歳 | C31: =集計_障がい児!$D$19 -> 5 | D31: =集計_障がい児!$E$19 -> 0.2
B32: 15～17歳 | C32: =集計_障がい児!$D$20 -> 4 | D32: =集計_障がい児!$E$20 -> 0.16
B33: 18歳以上 | C33: =集計_障がい児!$D$21 -> 5 | D33: =集計_障がい児!$E$21 -> 0.2
B34: 無回答 | C34: =集計_障がい児!$D$22 -> 2 | D34: =集計_障がい児!$E$22 -> 0.08
B37: 図5-4 現在の暮らしの場（問4）
B38: ="n="&集計_障がい児!$F$23&"（単一回答）" -> n=25（単一回答）
B39: 選択肢 | C39: 件数 | D39: 割合
B40: 家族と暮らしている | C40: =集計_障がい児!$D$23 -> 25 | D40: =集計_障がい児!$E$23 -> 1
B41: 支援学校の寄宿舎で暮らしている | C41: =集計_障がい児!$D$24 -> 0 | D41: =集計_障がい児!$E$24 -> 0
B42: 施設（障がい児入所施設）で暮らしている | C42: =集計_障がい児!$D$25 -> 0 | D42: =集計_障がい児!$E$25 -> 0
B43: 病院に入院している | C43: =集計_障がい児!$D$26 -> 0 | D43: =集計_障がい児!$E$26 -> 0
B44: その他 | C44: =集計_障がい児!$D$27 -> 0 | D44: =集計_障がい児!$E$27 -> 0
B45: 無回答 | C45: =集計_障がい児!$D$28 -> 0 | D45: =集計_障がい児!$E$28 -> 0
B49: 図5-5 同居している家族（問4）
B50: ="n="&集計_障がい児!$F$29&"（複数回答）" -> n=25（複数回答）
B51: 選択肢 | C51: 件数 | D51: 割合
B52: 父母 | C52: =集計_障がい児!$D$29 -> 25 | D52: =集計_障がい児!$E$29 -> 1
...

Sheet 6章_課題
B2: 表6-1 課題と計画上の取組の関係
B3: 課題 | C3: 計画上の主な対応方向 | F3: 障がい者の主な根拠 | I3: 障がい児の主な根拠
B4: 相談支援・情報提供 | C4: 相談支援体制、分かりやすい情報提供、関係機関の連携 | F4: 問33・問34・問46 | I4: 問30・問31・問43
B5: 地域生活・住まい | C5: 在宅サービス、住まい、地域生活支援拠点、家族支援 | F5: 問17・問18・問31 | I5: 問23・問24・問28
B6: 移動・外出 | C6: 移動支援、通院・買い物支援、町外サービス利用時の送迎 | F6: 問19～問22 | I6: 問25～問27
B7: 就労 | C7: 就労移行・継続・選択支援、企業理解、通勤・勤務配慮 | F7: 問23～問27・問31 | I7: 問19～問22・問28
B8: 権利擁護 | C8: 差別解消、合理的配慮、成年後見、虐待防止 | F8: 問35～問40 | I8: 問32～問37
B9: 災害時支援 | C9: 避難行動要支援者、個別避難計画、福祉避難所、医療継続 | F9: 問41～問45 | I9: 問38～問42
B10: 障がい児・移行支援 | C10: 教育・療育・福祉連携、進路・成人期への移行支援 | F10: ― | I10: 問17～問24・問28
B11: 障がい特性に応じた支援 | C11: 身体・知的・精神の障がい別の傾向を踏まえた情報提供、相談支援及びサービス提供体制の整備 | F11: 第３章【障がい別】の図表（問23、問27、問33） | I11: 療育手帳所持者（16人）の結果（第５章）

Sheet 7章_追加分析
B2: 表7-1 サービス利用の需給ギャップ（n=259）
B3: サービス | C3: 現在利用 | E3: 今後利用意向 | G3: 差
B4: 居宅介護 | C4: 19件（7.3%） | E4: 83件（32.0%） | G4: +64件（+24.7pt）
B5: 短期入所 | C5: 9件（3.5%） | E5: 67件（25.9%） | G5: +58件（+22.4pt）
B6: 生活介護 | C6: 25件（9.7%） | E6: 73件（28.2%） | G6: +48件（+18.5pt）
B7: 相談支援 | C7: 37件（14.3%） | E7: 84件（32.4%） | G7: +47件（+18.1pt）
B8: 共同生活援助 | C8: 8件（3.1%） | E8: 49件（18.9%） | G8: +41件（+15.8pt）
B9: 施設入所 | C9: 18件（6.9%） | E9: 54件（20.8%） | G9: +36件（+13.9pt）
B10: 重度訪問介護 | C10: 6件（2.3%） | E10: 41件（15.8%） | G10: +35件（+13.5pt）
B11: 重度包括 | C11: 5件（1.9%） | E11: 38件（14.7%） | G11: +33件（+12.7pt）
B13: 表7-2 障がい特性別のサービス利用意向（n=259）
B14: 障がい特性 | C14: n | D14: 今後利用意向の上位3サービス
B15: 身体障がい（身体障害者手帳所持） | C15: 193 | D15: 居宅介護 66件（34.2%）、相談支援 57件（29.5%）、生活介護 57件（29.5%）
B16: 知的障がい（療育手帳所持） | C16: 33 | D16: 相談支援 12件（36.4%）、共同生活援助 11件（33.3%）、生活介護 9件（27.3%）
B17: 精神障がい（精神障害者保健福祉手帳所持） | C17: 44 | D17: 就労選択 15件（34.1%）、就労継続 13件（29.5%）、相談支援 12件（27.3%）
B18: 発達障がい（診断あり） | C18: 31 | D18: 就労選択 11件（35.5%）、相談支援 9件（29.0%）、就労移行 9件（29.0%）
B19: 難病（認定あり） | C19: 17 | D19: 居宅介護 7件（41.2%）、相談支援 4件（23.5%）、施設入所 4件（23.5%）
B20: 高次脳機能障がい（診断あり） | C20: 8 | D20: 居宅介護 3件（37.5%）、短期入所 2件（25.0%）、相談支援 2件（25.0%）
B22: 表7-3 介助者の高齢化と将来の暮らし（n=105）
B23: 主介助者年齢 | C23: n | D23: 本人が家族との生活を希望 | G23: 介助者の健康状態「よくない」
B24: 64歳以下 | C24: 51 | D24: 38件（74.5%） | G24: 3件（5.9%）
B25: 65～74歳 | C25: 35 | D25: 30件（85.7%） | G25: 6件（17.1%）
B26: 75歳以上 | C26: 19 | D26: 14件（73.7%） | G26: 6件（31.6%）
B28: 表7-4 ADL介助必要度とサービスニーズ（n=259）
B29: ADL介助区分 | C29: n | D29: 生活介護 | F29: 短期入所 | H29: 施設入所 | J29: 相談支援
B30: 介助なし | C30: 127 | D30: 28件（22.0%） | F30: 29件（22.8%） | H30: 20件（15.7%） | J30: 37件（29.1%）
B31: 1～2項目で介助 | C31: 48 | D31: 12件（25.0%） | F31: 14件（29.2%） | H31: 11件（22.9%） | J31: 19件（39.6%）
B32: 3～5項目で介助 | C32: 35 | D32: 11件（31.4%） | F32: 10件（28.6%） | H32: 6件（17.1%） | J32: 13件（37.1%）
B33: 6項目以上で介助 | C33: 49 | D33: 22件（44.9%） | F33: 14件（28.6%） | H33: 17件（34.7%） | J33: 15件（30.6%）
B35: 表7-5 災害時の避難支援（n=259）
B36: 一人避難 | C36: n | D36: 要支援者登録を希望 | G36: 個別避難計画を希望
B37: できる | C37: 100 | D37: 14件（14.0%） | G37: 18件（18.0%）
B38: できない | C38: 92 | D38: 38件（41.3%） | G38: 30件（32.6%）
B39: わからない | C39: 52 | D39: 18件（34.6%） | G39: 15件（28.8%）
B40: 無回答 | C40: 15 | D40: 2件（13.3%） | G40: 3件（20.0%）
B42: 表7-6 地域生活移行・居住支援（n=41）
B43: 現在の暮らし | C43: n | D43: 家族・一般住宅・GHを希望 | G43: 将来「福祉施設」を希望
B44: グループホーム | C44: 11 | D44: 8件（72.7%） | G44: 1件（9.1%）
B45: 福祉施設 | C45: 24 | D45: 5件（20.8%） | G45: 16件（66.7%）
B46: 病院 | C46: 6 | D46: 4件（66.7%） | G46: 2件（33.3%）
...

Sheet 集計_障がい者
A1: 障がい者調査（18歳以上） 単純集計（入力データ）
A2: 青字のセル（件数・回答者数）が入力値です。割合は計算式で、各章シートの表・グラフに自動で反映されます。回答者数（n）は無回答を含む人数で、各設問の先頭行に入力し、2行目以降は先頭行を参照しています。「無回答」は各設問の最終行です。
A4: 設問番号 | B4: 設問 | C4: 選択肢 | D4: 件数 | E4: 割合 | F4: 回答者数（n） | G4: 回答形式
A5: 問1 | B5: この調査票にご回答いただく方はどなたですか。（○は１つだけ） | C5: ご本人が自分で記入 | D5: 144 | E5: =IF($F5=0,0,D5/$F5) -> 0.55598456 | F5: 259 | G5: 単一回答
A6: 問1 | B6: この調査票にご回答いただく方はどなたですか。（○は１つだけ） | C6: ご本人が回答し、家族の方が記入 | D6: 37 | E6: =IF($F6=0,0,D6/$F6) -> 0.14285714 | F6: =$F$5 -> 259 | G6: 単一回答
A7: 問1 | B7: この調査票にご回答いただく方はどなたですか。（○は１つだけ） | C7: 家族の方が代理で回答・記入 | D7: 48 | E7: =IF($F7=0,0,D7/$F7) -> 0.18532819 | F7: =$F$5 -> 259 | G7: 単一回答
A8: 問1 | B8: この調査票にご回答いただく方はどなたですか。（○は１つだけ） | C8: ご本人が回答し、施設職員が記入 | D8: 9 | E8: =IF($F8=0,0,D8/$F8) -> 0.034749035 | F8: =$F$5 -> 259 | G8: 単一回答
A9: 問1 | B9: この調査票にご回答いただく方はどなたですか。（○は１つだけ） | C9: 施設職員が代理で回答・記入 | D9: 10 | E9: =IF($F9=0,0,D9/$F9) -> 0.038610039 | F9: =$F$5 -> 259 | G9: 単一回答
A10: 問1 | B10: この調査票にご回答いただく方はどなたですか。（○は１つだけ） | C10: その他 | D10: 3 | E10: =IF($F10=0,0,D10/$F10) -> 0.011583012 | F10: =$F$5 -> 259 | G10: 単一回答
A11: 問1 | B11: この調査票にご回答いただく方はどなたですか。（○は１つだけ） | C11: 無回答 | D11: 8 | E11: =IF($F11=0,0,D11/$F11) -> 0.030888031 | F11: =$F$5 -> 259 | G11: 単一回答
A12: 問2 | B12: あなた（対象者）の性別をお答えください。（○は１つだけ） | C12: 男性 | D12: 144 | E12: =IF($F12=0,0,D12/$F12) -> 0.55598456 | F12: 259 | G12: 単一回答
A13: 問2 | B13: あなた（対象者）の性別をお答えください。（○は１つだけ） | C13: 女性 | D13: 109 | E13: =IF($F13=0,0,D13/$F13) -> 0.42084942 | F13: =$F$12 -> 259 | G13: 単一回答
A14: 問2 | B14: あなた（対象者）の性別をお答えください。（○は１つだけ） | C14: わからない | D14: 0 | E14: =IF($F14=0,0,D14/$F14) -> 0 | F14: =$F$12 -> 259 | G14: 単一回答
A15: 問2 | B15: あなた（対象者）の性別をお答えください。（○は１つだけ） | C15: 答えたくない | D15: 0 | E15: =IF($F15=0,0,D15/$F15) -> 0 | F15: =$F$12 -> 259 | G15: 単一回答
A16: 問2 | B16: あなた（対象者）の性別をお答えください。（○は１つだけ） | C16: 無回答 | D16: 6 | E16: =IF($F16=0,0,D16/$F16) -> 0.023166023 | F16: =$F$12 -> 259 | G16: 単一回答
A17: 問3 | B17: 令和８年8月１日現在のあなた（対象者）の年齢をお答えください。 | C17: 18～29歳 | D17: 12 | E17: =IF($F17=0,0,D17/$F17) -> 0.046332046 | F17: 259 | G17: 単一回答
A18: 問3 | B18: 令和８年8月１日現在のあなた（対象者）の年齢をお答えください。 | C18: 30～39歳 | D18: 12 | E18: =IF($F18=0,0,D18/$F18) -> 0.046332046 | F18: =$F$17 -> 259 | G18: 単一回答
A19: 問3 | B19: 令和８年8月１日現在のあなた（対象者）の年齢をお答えください。 | C19: 40～49歳 | D19: 16 | E19: =IF($F19=0,0,D19/$F19) -> 0.061776062 | F19: =$F$17 -> 259 | G19: 単一回答
A20: 問3 | B20: 令和８年8月１日現在のあなた（対象者）の年齢をお答えください。 | C20: 50～64歳 | D20: 32 | E20: =IF($F20=0,0,D20/$F20) -> 0.12355212 | F20: =$F$17 -> 259 | G20: 単一回答
A21: 問3 | B21: 令和８年8月１日現在のあなた（対象者）の年齢をお答えください。 | C21: 65歳以上 | D21: 177 | E21: =IF($F21=0,0,D21/$F21) -> 0.68339768 | F21: =$F$17 -> 259 | G21: 単一回答
A22: 問3 | B22: 令和８年8月１日現在のあなた（対象者）の年齢をお答えください。 | C22: 無回答 | D22: 10 | E22: =IF($F22=0,0,D22/$F22) -> 0.038610039 | F22: =$F$17 -> 259 | G22: 単一回答
A23: 問4-1 | B23: あなたが現在暮らしている場所はどこですか。（○は１つだけ） | C23: 自宅（アパート・町営住宅等も含む）でひとり暮らし | D23: 41 | E23: =IF($F23=0,0,D23/$F23) -> 0.15830116 | F23: 259 | G23: 単一回答
A24: 問4-1 | B24: あなたが現在暮らしている場所はどこですか。（○は１つだけ） | C24: 自宅（アパート・町営住宅等も含む）で家族等と一緒に住んでいる | D24: 169 | E24: =IF($F24=0,0,D24/$F24) -> 0.65250965 | F24: =$F$23 -> 259 | G24: 単一回答
A25: 問4-1 | B25: あなたが現在暮らしている場所はどこですか。（○は１つだけ） | C25: グループホームで暮らしている | D25: 11 | E25: =IF($F25=0,0,D25/$F25) -> 0.042471042 | F25: =$F$23 -> 259 | G25: 単一回答
A26: 問4-1 | B26: あなたが現在暮らしている場所はどこですか。（○は１つだけ） | C26: 福祉施設（障がい者支援施設、高齢者支援施設）で暮らしている | D26: 24 | E26: =IF($F26=0,0,D26/$F26) -> 0.092664093 | F26: =$F$23 -> 259 | G26: 単一回答
A27: 問4-1 | B27: あなたが現在暮らしている場所はどこですか。（○は１つだけ） | C27: 病院に入院している | D27: 6 | E27: =IF($F27=0,0,D27/$F27) -> 0.023166023 | F27: =$F$23 -> 259 | G27: 単一回答
A28: 問4-1 | B28: あなたが現在暮らしている場所はどこですか。（○は１つだけ） | C28: その他 | D28: 1 | E28: =IF($F28=0,0,D28/$F28) -> 0.0038610039 | F28: =$F$23 -> 259 | G28: 単一回答
A29: 問4-1 | B29: あなたが現在暮らしている場所はどこですか。（○は１つだけ） | C29: 無回答 | D29: 7 | E29: =IF($F29=0,0,D29/$F29) -> 0.027027027 | F29: =$F$23 -> 259 | G29: 単一回答
A30: 問4-2 | B30: 同居しているご家族をお答えください。（あてはまるものすべてに○） | C30: 父母 | D30: 46 | E30: =IF($F30=0,0,D30/$F30) -> 0.17760618 | F30: 259 | G30: 複数回答
A31: 問4-2 | B31: 同居しているご家族をお答えください。（あてはまるものすべてに○） | C31: 祖父母 | D31: 7 | E31: =IF($F31=0,0,D31/$F31) -> 0.027027027 | F31: =$F$30 -> 259 | G31: 複数回答
A32: 問4-2 | B32: 同居しているご家族をお答えください。（あてはまるものすべてに○） | C32: 兄弟姉妹 | D32: 24 | E32: =IF($F32=0,0,D32/$F32) -> 0.092664093 | F32: =$F$30 -> 259 | G32: 複数回答
A33: 問4-2 | B33: 同居しているご家族をお答えください。（あてはまるものすべてに○） | C33: 配偶者 | D33: 95 | E33: =IF($F33=0,0,D33/$F33) -> 0.36679537 | F33: =$F$30 -> 259 | G33: 複数回答
A34: 問4-2 | B34: 同居しているご家族をお答えください。（あてはまるものすべてに○） | C34: その他 | D34: 64 | E34: =IF($F34=0,0,D34/$F34) -> 0.24710425 | F34: =$F$30 -> 259 | G34: 複数回答
A35: 問4-2 | B35: 同居しているご家族をお答えください。（あてはまるものすべてに○） | C35: 無回答 | D35: 90 | E35: =IF($F35=0,0,D35/$F35) -> 0.34749035 | F35: =$F$30 -> 259 | G35: 複数回答
A36: 問5 | B36: 食事 | C36: ひとりでできる | D36: 212 | E36: =IF($F36=0,0,D36/$F36) -> 0.81853282 | F36: 259 | G36: 単一回答（項目別）
A37: 問5 | B37: 食事 | C37: 一部介助が必要 | D37: 24 | E37: =IF($F37=0,0,D37/$F37) -> 0.092664093 | F37: =$F$36 -> 259 | G37: 単一回答（項目別）
A38: 問5 | B38: 食事 | C38: 全部介助が必要 | D38: 12 | E38: =IF($F38=0,0,D38/$F38) -> 0.046332046 | F38: =$F$36 -> 259 | G38: 単一回答（項目別）
A39: 問5 | B39: 食事 | C39: 無回答 | D39: 11 | E39: =IF($F39=0,0,D39/$F39) -> 0.042471042 | F39: =$F$36 -> 259 | G39: 単一回答（項目別）
A40: 問5 | B40: トイレ | C40: ひとりでできる | D40: 206 | E40: =IF($F40=0,0,D40/$F40) -> 0.7953668 | F40: 259 | G40: 単一回答（項目別）
A41: 問5 | B41: トイレ | C41: 一部介助が必要 | D41: 24 | E41: =IF($F41=0,0,D41/$F41) -> 0.092664093 | F41: =$F$40 -> 259 | G41: 単一回答（項目別）
...

Sheet 集計_障がい児
A1: 障がい児調査（18歳未満） 単純集計（入力データ）
A2: 青字のセル（件数・回答者数）が入力値です。割合は計算式で、各章シートの表・グラフに自動で反映されます。回答者数（n）は無回答を含む人数で、各設問の先頭行に入力し、2行目以降は先頭行を参照しています。「無回答」は各設問の最終行です。
A4: 設問番号 | B4: 設問 | C4: 選択肢 | D4: 件数 | E4: 割合 | F4: 回答者数（n） | G4: 回答形式
A5: 問1 | B5: この調査票にご回答いただく方はどなたですか。（○は１つだけ） | C5: ご本人が自分で記入 | D5: 5 | E5: =IF($F5=0,0,D5/$F5) -> 0.2 | F5: 25 | G5: 単一回答
A6: 問1 | B6: この調査票にご回答いただく方はどなたですか。（○は１つだけ） | C6: ご本人が回答し、家族の方が記入 | D6: 8 | E6: =IF($F6=0,0,D6/$F6) -> 0.32 | F6: =$F$5 -> 25 | G6: 単一回答
A7: 問1 | B7: この調査票にご回答いただく方はどなたですか。（○は１つだけ） | C7: 家族の方が代理で回答・記入 | D7: 4 | E7: =IF($F7=0,0,D7/$F7) -> 0.16 | F7: =$F$5 -> 25 | G7: 単一回答
A8: 問1 | B8: この調査票にご回答いただく方はどなたですか。（○は１つだけ） | C8: ご本人が回答し、施設職員が記入 | D8: 1 | E8: =IF($F8=0,0,D8/$F8) -> 0.04 | F8: =$F$5 -> 25 | G8: 単一回答
A9: 問1 | B9: この調査票にご回答いただく方はどなたですか。（○は１つだけ） | C9: 施設職員が代理で回答・記入 | D9: 5 | E9: =IF($F9=0,0,D9/$F9) -> 0.2 | F9: =$F$5 -> 25 | G9: 単一回答
A10: 問1 | B10: この調査票にご回答いただく方はどなたですか。（○は１つだけ） | C10: その他 | D10: 1 | E10: =IF($F10=0,0,D10/$F10) -> 0.04 | F10: =$F$5 -> 25 | G10: 単一回答
A11: 問1 | B11: この調査票にご回答いただく方はどなたですか。（○は１つだけ） | C11: 無回答 | D11: 1 | E11: =IF($F11=0,0,D11/$F11) -> 0.04 | F11: =$F$5 -> 25 | G11: 単一回答
A12: 問2 | B12: あなた（対象者）の性別をお答えください。（○は１つだけ） | C12: 男性 | D12: 13 | E12: =IF($F12=0,0,D12/$F12) -> 0.52 | F12: 25 | G12: 単一回答
A13: 問2 | B13: あなた（対象者）の性別をお答えください。（○は１つだけ） | C13: 女性 | D13: 10 | E13: =IF($F13=0,0,D13/$F13) -> 0.4 | F13: =$F$12 -> 25 | G13: 単一回答
A14: 問2 | B14: あなた（対象者）の性別をお答えください。（○は１つだけ） | C14: わからない | D14: 0 | E14: =IF($F14=0,0,D14/$F14) -> 0 | F14: =$F$12 -> 25 | G14: 単一回答
A15: 問2 | B15: あなた（対象者）の性別をお答えください。（○は１つだけ） | C15: 答えたくない | D15: 1 | E15: =IF($F15=0,0,D15/$F15) -> 0.04 | F15: =$F$12 -> 25 | G15: 単一回答
A16: 問2 | B16: あなた（対象者）の性別をお答えください。（○は１つだけ） | C16: 無回答 | D16: 1 | E16: =IF($F16=0,0,D16/$F16) -> 0.04 | F16: =$F$12 -> 25 | G16: 単一回答
A17: 問3 | B17: 令和８年8月１日現在のあなた（対象者）の年齢をお答えください。 | C17: 0～5歳 | D17: 3 | E17: =IF($F17=0,0,D17/$F17) -> 0.12 | F17: 25 | G17: 単一回答
A18: 問3 | B18: 令和８年8月１日現在のあなた（対象者）の年齢をお答えください。 | C18: 6～11歳 | D18: 6 | E18: =IF($F18=0,0,D18/$F18) -> 0.24 | F18: =$F$17 -> 25 | G18: 単一回答
A19: 問3 | B19: 令和８年8月１日現在のあなた（対象者）の年齢をお答えください。 | C19: 12～14歳 | D19: 5 | E19: =IF($F19=0,0,D19/$F19) -> 0.2 | F19: =$F$17 -> 25 | G19: 単一回答
A20: 問3 | B20: 令和８年8月１日現在のあなた（対象者）の年齢をお答えください。 | C20: 15～17歳 | D20: 4 | E20: =IF($F20=0,0,D20/$F20) -> 0.16 | F20: =$F$17 -> 25 | G20: 単一回答
A21: 問3 | B21: 令和８年8月１日現在のあなた（対象者）の年齢をお答えください。 | C21: 18歳以上 | D21: 5 | E21: =IF($F21=0,0,D21/$F21) -> 0.2 | F21: =$F$17 -> 25 | G21: 単一回答
A22: 問3 | B22: 令和８年8月１日現在のあなた（対象者）の年齢をお答えください。 | C22: 無回答 | D22: 2 | E22: =IF($F22=0,0,D22/$F22) -> 0.08 | F22: =$F$17 -> 25 | G22: 単一回答
A23: 問4-1 | B23: あなたが現在暮らしている場所はどこですか。（○は１つだけ） | C23: 家族と暮らしている | D23: 25 | E23: =IF($F23=0,0,D23/$F23) -> 1 | F23: 25 | G23: 単一回答
A24: 問4-1 | B24: あなたが現在暮らしている場所はどこですか。（○は１つだけ） | C24: 支援学校の寄宿舎で暮らしている | D24: 0 | E24: =IF($F24=0,0,D24/$F24) -> 0 | F24: =$F$23 -> 25 | G24: 単一回答
A25: 問4-1 | B25: あなたが現在暮らしている場所はどこですか。（○は１つだけ） | C25: 施設（障がい児入所施設）で暮らしている | D25: 0 | E25: =IF($F25=0,0,D25/$F25) -> 0 | F25: =$F$23 -> 25 | G25: 単一回答
A26: 問4-1 | B26: あなたが現在暮らしている場所はどこですか。（○は１つだけ） | C26: 病院に入院している | D26: 0 | E26: =IF($F26=0,0,D26/$F26) -> 0 | F26: =$F$23 -> 25 | G26: 単一回答
A27: 問4-1 | B27: あなたが現在暮らしている場所はどこですか。（○は１つだけ） | C27: その他 | D27: 0 | E27: =IF($F27=0,0,D27/$F27) -> 0 | F27: =$F$23 -> 25 | G27: 単一回答
A28: 問4-1 | B28: あなたが現在暮らしている場所はどこですか。（○は１つだけ） | C28: 無回答 | D28: 0 | E28: =IF($F28=0,0,D28/$F28) -> 0 | F28: =$F$23 -> 25 | G28: 単一回答
A29: 問4-2 | B29: 同居しているご家族をお答えください。（あてはまるものすべてに○） | C29: 父母 | D29: 25 | E29: =IF($F29=0,0,D29/$F29) -> 1 | F29: 25 | G29: 複数回答
A30: 問4-2 | B30: 同居しているご家族をお答えください。（あてはまるものすべてに○） | C30: 祖父母 | D30: 11 | E30: =IF($F30=0,0,D30/$F30) -> 0.44 | F30: =$F$29 -> 25 | G30: 複数回答
A31: 問4-2 | B31: 同居しているご家族をお答えください。（あてはまるものすべてに○） | C31: 兄弟姉妹 | D31: 20 | E31: =IF($F31=0,0,D31/$F31) -> 0.8 | F31: =$F$29 -> 25 | G31: 複数回答
A32: 問4-2 | B32: 同居しているご家族をお答えください。（あてはまるものすべてに○） | C32: その他 | D32: 0 | E32: =IF($F32=0,0,D32/$F32) -> 0 | F32: =$F$29 -> 25 | G32: 複数回答
A33: 問4-2 | B33: 同居しているご家族をお答えください。（あてはまるものすべてに○） | C33: 無回答 | D33: 0 | E33: =IF($F33=0,0,D33/$F33) -> 0 | F33: =$F$29 -> 25 | G33: 複数回答
A34: 問5 | B34: 食事 | C34: ひとりでできる | D34: 24 | E34: =IF($F34=0,0,D34/$F34) -> 0.96 | F34: 25 | G34: 単一回答（項目別）
A35: 問5 | B35: 食事 | C35: 一部介助が必要 | D35: 1 | E35: =IF($F35=0,0,D35/$F35) -> 0.04 | F35: =$F$34 -> 25 | G35: 単一回答（項目別）
A36: 問5 | B36: 食事 | C36: 全部介助が必要 | D36: 0 | E36: =IF($F36=0,0,D36/$F36) -> 0 | F36: =$F$34 -> 25 | G36: 単一回答（項目別）
A37: 問5 | B37: 食事 | C37: 無回答 | D37: 0 | E37: =IF($F37=0,0,D37/$F37) -> 0 | F37: =$F$34 -> 25 | G37: 単一回答（項目別）
A38: 問5 | B38: トイレ | C38: ひとりでできる | D38: 24 | E38: =IF($F38=0,0,D38/$F38) -> 0.96 | F38: 25 | G38: 単一回答（項目別）
A39: 問5 | B39: トイレ | C39: 一部介助が必要 | D39: 0 | E39: =IF($F39=0,0,D39/$F39) -> 0 | F39: =$F$38 -> 25 | G39: 単一回答（項目別）
A40: 問5 | B40: トイレ | C40: 全部介助が必要 | D40: 1 | E40: =IF($F40=0,0,D40/$F40) -> 0.04 | F40: =$F$38 -> 25 | G40: 単一回答（項目別）
A41: 問5 | B41: トイレ | C41: 無回答 | D41: 0 | E41: =IF($F41=0,0,D41/$F41) -> 0 | F41: =$F$38 -> 25 | G41: 単一回答（項目別）
...

Sheet 集計_障がい別
A1: 障がい者調査 障がい別集計（入力データ）
A2: 障がい別は、所持している手帳により区分しています（身体障害者手帳（問8で１～６級）＝身体障がい、療育手帳（問10でＡ判定・Ｂ判定）＝知的障がい、精神障害者保健福祉手帳（問11で１～３級）＝精神障がい）。複数の手帳を所持している方は各区分に計上。青字が入力値（件数・回答者数）、割合は各区分の回答者数を基数とする計算式です。
A4: 設問番号 | B4: 設問・項目 | C4: 選択肢 | D4: 身体障がい （件数） | E4: 知的障がい （件数） | F4: 精神障がい （件数） | G4: 身体障がい （割合） | H4: 知的障がい （割合） | I4: 精神障がい （割合）
C5: 回答者数（n） | D5: 193 | E5: 33 | F5: 44
A6: 問1 | B6: この調査票にご回答いただく方はどなたですか。（○は１つだけ） | C6: ご本人が自分で記入 | D6: 109 | E6: 10 | F6: 29 | G6: =IF(D$5=0,0,D6/D$5) -> 0.56476684 | H6: =IF(E$5=0,0,E6/E$5) -> 0.3030303 | I6: =IF(F$5=0,0,F6/F$5) -> 0.65909091
A7: 問1 | C7: ご本人が回答し、家族の方が記入 | D7: 27 | E7: 5 | F7: 5 | G7: =IF(D$5=0,0,D7/D$5) -> 0.13989637 | H7: =IF(E$5=0,0,E7/E$5) -> 0.15151515 | I7: =IF(F$5=0,0,F7/F$5) -> 0.11363636
A8: 問1 | C8: 家族の方が代理で回答・記入 | D8: 39 | E8: 5 | F8: 3 | G8: =IF(D$5=0,0,D8/D$5) -> 0.20207254 | H8: =IF(E$5=0,0,E8/E$5) -> 0.15151515 | I8: =IF(F$5=0,0,F8/F$5) -> 0.068181818
A9: 問1 | C9: ご本人が回答し、施設職員が記入 | D9: 8 | E9: 3 | F9: 2 | G9: =IF(D$5=0,0,D9/D$5) -> 0.041450777 | H9: =IF(E$5=0,0,E9/E$5) -> 0.090909091 | I9: =IF(F$5=0,0,F9/F$5) -> 0.045454545
A10: 問1 | C10: 施設職員が代理で回答・記入 | D10: 3 | E10: 5 | F10: 2 | G10: =IF(D$5=0,0,D10/D$5) -> 0.015544041 | H10: =IF(E$5=0,0,E10/E$5) -> 0.15151515 | I10: =IF(F$5=0,0,F10/F$5) -> 0.045454545
A11: 問1 | C11: その他 | D11: 2 | E11: 2 | F11: 1 | G11: =IF(D$5=0,0,D11/D$5) -> 0.010362694 | H11: =IF(E$5=0,0,E11/E$5) -> 0.060606061 | I11: =IF(F$5=0,0,F11/F$5) -> 0.022727273
A12: 問1 | C12: 無回答 | D12: 5 | E12: 3 | F12: 2 | G12: =IF(D$5=0,0,D12/D$5) -> 0.025906736 | H12: =IF(E$5=0,0,E12/E$5) -> 0.090909091 | I12: =IF(F$5=0,0,F12/F$5) -> 0.045454545
A13: 問2 | B13: あなた（対象者）の性別をお答えください。（○は１つだけ） | C13: 男性 | D13: 110 | E13: 20 | F13: 24 | G13: =IF(D$5=0,0,D13/D$5) -> 0.56994819 | H13: =IF(E$5=0,0,E13/E$5) -> 0.60606061 | I13: =IF(F$5=0,0,F13/F$5) -> 0.54545455
A14: 問2 | C14: 女性 | D14: 78 | E14: 12 | F14: 18 | G14: =IF(D$5=0,0,D14/D$5) -> 0.40414508 | H14: =IF(E$5=0,0,E14/E$5) -> 0.36363636 | I14: =IF(F$5=0,0,F14/F$5) -> 0.40909091
A15: 問2 | C15: わからない | D15: 0 | E15: 0 | F15: 0 | G15: =IF(D$5=0,0,D15/D$5) -> 0 | H15: =IF(E$5=0,0,E15/E$5) -> 0 | I15: =IF(F$5=0,0,F15/F$5) -> 0
A16: 問2 | C16: 答えたくない | D16: 0 | E16: 0 | F16: 0 | G16: =IF(D$5=0,0,D16/D$5) -> 0 | H16: =IF(E$5=0,0,E16/E$5) -> 0 | I16: =IF(F$5=0,0,F16/F$5) -> 0
A17: 問2 | C17: 無回答 | D17: 5 | E17: 1 | F17: 2 | G17: =IF(D$5=0,0,D17/D$5) -> 0.025906736 | H17: =IF(E$5=0,0,E17/E$5) -> 0.03030303 | I17: =IF(F$5=0,0,F17/F$5) -> 0.045454545
A18: 問3 | B18: 令和８年8月１日現在のあなた（対象者）の年齢をお答えください。 | C18: 18～29歳 | D18: 1 | E18: 7 | F18: 6 | G18: =IF(D$5=0,0,D18/D$5) -> 0.0051813472 | H18: =IF(E$5=0,0,E18/E$5) -> 0.21212121 | I18: =IF(F$5=0,0,F18/F$5) -> 0.13636364
A19: 問3 | C19: 30～39歳 | D19: 3 | E19: 4 | F19: 6 | G19: =IF(D$5=0,0,D19/D$5) -> 0.015544041 | H19: =IF(E$5=0,0,E19/E$5) -> 0.12121212 | I19: =IF(F$5=0,0,F19/F$5) -> 0.13636364
A20: 問3 | C20: 40～49歳 | D20: 5 | E20: 2 | F20: 9 | G20: =IF(D$5=0,0,D20/D$5) -> 0.025906736 | H20: =IF(E$5=0,0,E20/E$5) -> 0.060606061 | I20: =IF(F$5=0,0,F20/F$5) -> 0.20454545
A21: 問3 | C21: 50～64歳 | D21: 18 | E21: 10 | F21: 10 | G21: =IF(D$5=0,0,D21/D$5) -> 0.093264249 | H21: =IF(E$5=0,0,E21/E$5) -> 0.3030303 | I21: =IF(F$5=0,0,F21/F$5) -> 0.22727273
A22: 問3 | C22: 65歳以上 | D22: 159 | E22: 9 | F22: 11 | G22: =IF(D$5=0,0,D22/D$5) -> 0.8238342 | H22: =IF(E$5=0,0,E22/E$5) -> 0.27272727 | I22: =IF(F$5=0,0,F22/F$5) -> 0.25
A23: 問3 | C23: 無回答 | D23: 7 | E23: 1 | F23: 2 | G23: =IF(D$5=0,0,D23/D$5) -> 0.03626943 | H23: =IF(E$5=0,0,E23/E$5) -> 0.03030303 | I23: =IF(F$5=0,0,F23/F$5) -> 0.045454545
A24: 問4-1 | B24: あなたが現在暮らしている場所はどこですか。（○は１つだけ） | C24: 自宅（アパート・町営住宅等も含む）でひとり暮らし | D24: 35 | E24: 4 | F24: 8 | G24: =IF(D$5=0,0,D24/D$5) -> 0.18134715 | H24: =IF(E$5=0,0,E24/E$5) -> 0.12121212 | I24: =IF(F$5=0,0,F24/F$5) -> 0.18181818
A25: 問4-1 | C25: 自宅（アパート・町営住宅等も含む）で家族等と一緒に住んでいる | D25: 123 | E25: 17 | F25: 27 | G25: =IF(D$5=0,0,D25/D$5) -> 0.6373057 | H25: =IF(E$5=0,0,E25/E$5) -> 0.51515152 | I25: =IF(F$5=0,0,F25/F$5) -> 0.61363636
A26: 問4-1 | C26: グループホームで暮らしている | D26: 7 | E26: 3 | F26: 2 | G26: =IF(D$5=0,0,D26/D$5) -> 0.03626943 | H26: =IF(E$5=0,0,E26/E$5) -> 0.090909091 | I26: =IF(F$5=0,0,F26/F$5) -> 0.045454545
A27: 問4-1 | C27: 福祉施設（障がい者支援施設、高齢者支援施設）で暮らしている | D27: 16 | E27: 8 | F27: 5 | G27: =IF(D$5=0,0,D27/D$5) -> 0.082901554 | H27: =IF(E$5=0,0,E27/E$5) -> 0.24242424 | I27: =IF(F$5=0,0,F27/F$5) -> 0.11363636
A28: 問4-1 | C28: 病院に入院している | D28: 5 | E28: 0 | F28: 0 | G28: =IF(D$5=0,0,D28/D$5) -> 0.025906736 | H28: =IF(E$5=0,0,E28/E$5) -> 0 | I28: =IF(F$5=0,0,F28/F$5) -> 0
A29: 問4-1 | C29: その他 | D29: 1 | E29: 0 | F29: 0 | G29: =IF(D$5=0,0,D29/D$5) -> 0.0051813472 | H29: =IF(E$5=0,0,E29/E$5) -> 0 | I29: =IF(F$5=0,0,F29/F$5) -> 0
A30: 問4-1 | C30: 無回答 | D30: 6 | E30: 1 | F30: 2 | G30: =IF(D$5=0,0,D30/D$5) -> 0.031088083 | H30: =IF(E$5=0,0,E30/E$5) -> 0.03030303 | I30: =IF(F$5=0,0,F30/F$5) -> 0.045454545
A31: 問4-2 | B31: 同居しているご家族をお答えください。（あてはまるものすべてに○） | C31: 父母 | D31: 16 | E31: 12 | F31: 22 | G31: =IF(D$5=0,0,D31/D$5) -> 0.082901554 | H31: =IF(E$5=0,0,E31/E$5) -> 0.36363636 | I31: =IF(F$5=0,0,F31/F$5) -> 0.5
A32: 問4-2 | C32: 祖父母 | D32: 3 | E32: 4 | F32: 2 | G32: =IF(D$5=0,0,D32/D$5) -> 0.015544041 | H32: =IF(E$5=0,0,E32/E$5) -> 0.12121212 | I32: =IF(F$5=0,0,F32/F$5) -> 0.045454545
A33: 問4-2 | C33: 兄弟姉妹 | D33: 8 | E33: 6 | F33: 13 | G33: =IF(D$5=0,0,D33/D$5) -> 0.041450777 | H33: =IF(E$5=0,0,E33/E$5) -> 0.18181818 | I33: =IF(F$5=0,0,F33/F$5) -> 0.29545455
A34: 問4-2 | C34: 配偶者 | D34: 82 | E34: 2 | F34: 5 | G34: =IF(D$5=0,0,D34/D$5) -> 0.42487047 | H34: =IF(E$5=0,0,E34/E$5) -> 0.060606061 | I34: =IF(F$5=0,0,F34/F$5) -> 0.11363636
A35: 問4-2 | C35: その他 | D35: 52 | E35: 4 | F35: 4 | G35: =IF(D$5=0,0,D35/D$5) -> 0.26943005 | H35: =IF(E$5=0,0,E35/E$5) -> 0.12121212 | I35: =IF(F$5=0,0,F35/F$5) -> 0.090909091
A36: 問4-2 | C36: 無回答 | D36: 70 | E36: 16 | F36: 17 | G36: =IF(D$5=0,0,D36/D$5) -> 0.3626943 | H36: =IF(E$5=0,0,E36/E$5) -> 0.48484848 | I36: =IF(F$5=0,0,F36/F$5) -> 0.38636364
A37: 問5 | B37: 食事 | C37: ひとりでできる | D37: 158 | E37: 28 | F37: 36 | G37: =IF(D$5=0,0,D37/D$5) -> 0.81865285 | H37: =IF(E$5=0,0,E37/E$5) -> 0.84848485 | I37: =IF(F$5=0,0,F37/F$5) -> 0.81818182
A38: 問5 | C38: 一部介助が必要 | D38: 17 | E38: 1 | F38: 4 | G38: =IF(D$5=0,0,D38/D$5) -> 0.088082902 | H38: =IF(E$5=0,0,E38/E$5) -> 0.03030303 | I38: =IF(F$5=0,0,F38/F$5) -> 0.090909091
A39: 問5 | C39: 全部介助が必要 | D39: 9 | E39: 2 | F39: 1 | G39: =IF(D$5=0,0,D39/D$5) -> 0.046632124 | H39: =IF(E$5=0,0,E39/E$5) -> 0.060606061 | I39: =IF(F$5=0,0,F39/F$5) -> 0.022727273
A40: 問5 | C40: 無回答 | D40: 9 | E40: 2 | F40: 3 | G40: =IF(D$5=0,0,D40/D$5) -> 0.046632124 | H40: =IF(E$5=0,0,E40/E$5) -> 0.060606061 | I40: =IF(F$5=0,0,F40/F$5) -> 0.068181818
A41: 問5 | B41: トイレ | C41: ひとりでできる | D41: 153 | E41: 26 | F41: 39 | G41: =IF(D$5=0,0,D41/D$5) -> 0.79274611 | H41: =IF(E$5=0,0,E41/E$5) -> 0.78787879 | I41: =IF(F$5=0,0,F41/F$5) -> 0.88636364
...
