Workbook
Name グラフ選択: '[1]施策反映(在宅サービス)'!$R$3:$R$7
Name グラフ選択: '[1]施策反映(在宅サービス)'!$R$3:$R$7
Name サービス: #REF!
Name サービス選択: #REF!
Name サービス名: '[1]施策反映(在宅サービス) (利用者数)'!$R$3:$R$21
Name サービス名: '[1]施策反映(在宅サービス) (利用者数)'!$R$3:$R$21
Name 在宅サービス: #REF!
Name 施設・居住系サービス: #REF!
Name 推計パターン名: '[2]1_推計値サマリ'!$S$5
Name 選択肢: #REF!
Name 年度選択: #REF!
Name 保険者番号: '[2]1_推計値サマリ'!$S$4
Name 保険者名: '[2]1_推計値サマリ'!$S$3

Sheet グラフ
B2: 貴保険者における要介護認定率の伸びのパターンの比較
B4: ●説明
B5: 目的
B6: 本シートは、各保険者が次期計画期間における認定者数の見込量を定める際に、認定率の推移を確認し、その中で生じた状況や実施した施策等、当該実績に寄与したと考えられる状況を振り返ることで、
B7: 一定の仮説に基づく伸びの選択に資することを目的としています。
B9: 本シートの操作方法
B10: 1．「選択」の「性別」、「年齢階級別」及び「要介護度別」から選択してください。選択した値により「当該市町村における認定率の伸び」の表とグラフが自動的に変更されます。
B11: 2．下部のグラフを確認してください。
B12: 3．地域包括ケア「見える化」システム「将来推計」の「推計方法の設定」画面から、認定率の伸びを選択してください。
B14: 伸びを選択する際の考え方
B15: 貴保険者において、下記のポイントを踏まえ、次期計画期間における認定率の伸びを選択してください。
C16: ・第９期介護保険事業計画時に設定した認定率に基づく計画値と令和８年度までの実績値を比較し、その乖離状況を考慮して、次期計画期間における認定率の伸びを選択してください。
C17: ・また、過年度に自然災害等の特殊な要因による高齢者の人口動態やサービスの利用形態に変化を生じた等、認定率に大きな影響を与えたと考えられる状況がある場合には、このような状況を生じた年度を含まない期間の伸びを選択する等、
C18: 各地域における状況を勘案して、適切な認定率の伸びを選択してください。
B20: ●当該市町村における要介護認定率の伸び | T20: ●選択
H21: 令和3年度 | I21: 令和4年度 | J21: 令和5年度 | K21: 令和6年度 | L21: 令和7年度 | M21: 令和8年度 | N21: 令和9年度 | O21: 令和10年度 | P21: 令和11年度 | R21: 伸び | T21: 性別 | U21: 年齢階級別 | V21: 要介護度別
B22: 実績値 | H22: {=IFERROR(INDEX(データ!$E$4:$L$30,(MATCH($T$22,リスト!$A$3:$A$5,0)-1)*9+MATCH($U$22,リスト!$B$3:$B$11,0),MATCH($V$22,データ!$E$3:$L$3,0)),"")*100} -> 9.6532971 | I22: {=IFERROR(INDEX(データ!$E$34:$L$60,(MATCH($T$22,リスト!$A$3:$A$5,0)-1)*9+MATCH($U$22,リスト!$B$3:$B$11,0),MATCH($V$22,データ!$E$33:$L$33,0)),"")*100} -> 9.8357852 | J22: {=IFERROR(INDEX(データ!$E$64:$L$90,(MATCH($T$22,リスト!$A$3:$A$5,0)-1)*9+MATCH($U$22,リスト!$B$3:$B$11,0),MATCH($V$22,データ!$E$63:$L$63,0)),"")*100} -> 9.9105299 | K22: {=IFERROR(INDEX(データ!$E$94:$L$120,(MATCH($T$22,リスト!$A$3:$A$5,0)-1)*9+MATCH($U$22,リスト!$B$3:$B$11,0),MATCH($V$22,データ!$E$93:$L$93,0)),"")*100} -> 9.7332871 | L22: {=IFERROR(INDEX(データ!$E$124:$L$150,(MATCH($T$22,リスト!$A$3:$A$5,0)-1)*9+MATCH($U$22,リスト!$B$3:$B$11,0),MATCH($V$22,データ!$E$123:$L$123,0)),"")*100} -> 9.8954704 | M22: {=IFERROR(INDEX(データ!$E$154:$L$180,(MATCH($T$22,リスト!$A$3:$A$5,0)-1)*9+MATCH($U$22,リスト!$B$3:$B$11,0),MATCH($V$22,データ!$E$153:$L$153,0)),"")*100} -> 9.9964739 | T22: 合計 | U22: 総数 | V22: 全体
B23: ①当該市町村における令和３年度→令和８年度の伸び | M23: =$M$22 -> 9.9964739 | N23: =IFERROR(M23+$R23,"") -> 10.065109 | O23: =IFERROR(N23+$R23,"") -> 10.133745 | P23: =IFERROR(O23+$R23,"") -> 10.20238 | R23: {=IFERROR(INDEX(データ!$B$185:$L$211,(MATCH($T$22,リスト!$A$3:$A$5,0)-1)*9+MATCH($U$22,リスト!$B$3:$B$11,0),MATCH($V$22,データ!$B$184:$L$184,0)),"")*100} -> 0.068635366
B24: ②当該市町村における令和７年度→令和８年度の伸び | M24: =$M$22 -> 9.9964739 | N24: =IFERROR(M24+$R24,"") -> 10.097477 | O24: =IFERROR(N24+$R24,"") -> 10.198481 | P24: =IFERROR(O24+$R24,"") -> 10.299484 | R24: {=IFERROR(INDEX(データ!$B$215:$L$241,(MATCH($T$22,リスト!$A$3:$A$5,0)-1)*9+MATCH($U$22,リスト!$B$3:$B$11,0),MATCH($V$22,データ!$B$214:$L$214,0)),"")*100} -> 0.10100352
B25: ③当該市町村における令和６年度→令和８年度の伸び | M25: =$M$22 -> 9.9964739 | N25: =IFERROR(M25+$R25,"") -> 10.128067 | O25: =IFERROR(N25+$R25,"") -> 10.259661 | P25: =IFERROR(O25+$R25,"") -> 10.391254 | R25: {=IFERROR(INDEX(データ!$B$245:$L$271,(MATCH($T$22,リスト!$A$3:$A$5,0)-1)*9+MATCH($U$22,リスト!$B$3:$B$11,0),MATCH($V$22,データ!$B$244:$L$244,0)),"")*100} -> 0.13159338
B26: ④当該市町村における令和６年度→令和７年度の伸び | M26: =$M$22 -> 9.9964739 | N26: =IFERROR(M26+$R26,"") -> 10.158657 | O26: =IFERROR(N26+$R26,"") -> 10.32084 | P26: =IFERROR(O26+$R26,"") -> 10.483024 | R26: {=IFERROR(INDEX(データ!$B$275:$L$301,(MATCH($T$22,リスト!$A$3:$A$5,0)-1)*9+MATCH($U$22,リスト!$B$3:$B$11,0),MATCH($V$22,データ!$B$274:$L$274,0)),"")*100} -> 0.16218323
B27: ⑤全国における令和６年度→令和７年度の伸び | M27: =$M$22 -> 9.9964739 | N27: =IFERROR(M27+$R27,"") -> 10.187568 | O27: =IFERROR(N27+$R27,"") -> 10.378662 | P27: =IFERROR(O27+$R27,"") -> 10.569756 | R27: {=IFERROR(INDEX(データ!$B305:$L$331,(MATCH($T$22,リスト!$A$3:$A$5,0)-1)*9+MATCH($U$22,リスト!$B$3:$B$11,0),MATCH($V$22,データ!$B$304:$L$304,0)),"")*100} -> 0.19109399
B59: 各伸びの定義
B60: 認定者数の自然体推計では、第９期の認定率の「伸び（変化の傾き）」が第10期以降も続くという仮定に基づいて推計を行います。
B61: 将来の認定者数の推計は、将来の被保険者数の推計をもとに、認定率の実績と貴保険者が設定した現状の推移から予測される年間の認定率の変化（ただし、令和12年度以降は、令和11年度の認定率が継続と仮定）により算出します。
B62: 認定率の１年間の伸びについて、「当該市町村における認定率の伸び」の①～⑤から１つを選択します。（「⑤全国における令和６年度→令和７年度の伸び」は認定率のみ）
B64: ＜①～⑤の計算式＞
C65: ①当該市町村における令和３年度→令和８年度の伸び
D66: ＝（令和８年度の認定率－令和３年度の認定率）÷５ ※単年度の伸びを算出
C67: ②当該市町村における令和７年度→令和８年度の伸び
D68: ＝令和８年度の認定率－令和７年度の認定率
C69: ③当該市町村における令和６年度→令和８年度の伸び
D70: ＝（令和８年度の認定率－令和６年度の認定率）÷２ ※単年度の伸びを算出
C71: ④当該市町村における令和６年度→令和７年度の伸び
D72: ＝令和７年度の認定率－令和６年度の認定率
C73: ⑤全国における令和６年度→令和７年度の伸び
D74: ＝令和７年度の認定率－令和６年度の認定率
B76: <「当該市町村における認定率の伸び」の推計式>
C77: 各年度の認定率＝令和８年度の認定率+（認定率の伸び×年数）

Sheet データ
B1: 認定率(実績値)
B2: 令和3年度 | L2: 単位：%
E3: 全体 | F3: 要支援１ | G3: 要支援２ | H3: 要介護１ | I3: 要介護２ | J3: 要介護３ | K3: 要介護４ | L3: 要介護５
B4: 男 | C4: 第1号被保険者 | E4: 0.11590296 | F4: 0.0026954178 | G4: 0.019541779 | H4: 0.0080862534 | I4: 0.030997305 | J4: 0.029649596 | K4: 0.016172507 | L4: 0.0087601078
D5: 65～69歳 | E5: 0.020930233 | F5: 0.0023255814 | G5: 0.0046511628 | H5: 0 | I5: 0.0046511628 | J5: 0.0046511628 | K5: 0.0046511628 | L5: 0
D6: 70～74歳 | E6: 0.069047619 | F6: 0.0023809524 | G6: 0.014285714 | H6: 0.0023809524 | I6: 0.021428571 | J6: 0.016666667 | K6: 0.0095238095 | L6: 0.0023809524
D7: 75～79歳 | E7: 0.073076923 | F7: 0.0076923077 | G7: 0.0076923077 | H7: 0 | I7: 0.019230769 | J7: 0.023076923 | K7: 0.0076923077 | L7: 0.0076923077
D8: 80～84歳 | E8: 0.19047619 | F8: 0 | G8: 0.047619048 | H8: 0.021164021 | I8: 0.042328042 | J8: 0.042328042 | K8: 0.031746032 | L8: 0.0052910053
D9: 85～89歳 | E9: 0.4 | F9: 0 | G9: 0.069565217 | H9: 0.043478261 | I9: 0.11304348 | J9: 0.07826087 | K9: 0.060869565 | L9: 0.034782609
D10: 90歳以上 | E10: 0.47142857 | F10: 0 | G10: 0.028571429 | H10: 0.028571429 | I10: 0.12857143 | J10: 0.17142857 | K10: 0.042857143 | L10: 0.071428571
C11: 第2号被保険者 | E11: 0.0036337209 | F11: 0 | G11: 0.0014534884 | H11: 0 | I11: 0 | J11: 0.00072674419 | K11: 0.00072674419 | L11: 0.00072674419
C12: 総数 | E12: 0.061888112 | F12: 0.0013986014 | G12: 0.010839161 | H12: 0.0041958042 | I12: 0.016083916 | J12: 0.015734266 | K12: 0.0087412587 | L12: 0.0048951049
B13: 女 | C13: 第1号被保険者 | E13: 0.22228571 | F13: 0.0085714286 | G13: 0.035428571 | H13: 0.017714286 | I13: 0.055428571 | J13: 0.047428571 | K13: 0.032571429 | L13: 0.025142857
D14: 65～69歳 | E14: 0.019704433 | F14: 0 | G14: 0.0049261084 | H14: 0.0024630542 | I14: 0.0049261084 | J14: 0.0024630542 | K14: 0.0024630542 | L14: 0.0024630542
D15: 70～74歳 | E15: 0.074270557 | F15: 0.0053050398 | G15: 0.021220159 | H15: 0.0079575597 | I15: 0.013262599 | J15: 0.0053050398 | K15: 0.01061008 | L15: 0.01061008
D16: 75～79歳 | E16: 0.086142322 | F16: 0.0037453184 | G16: 0.02247191 | H16: 0.0037453184 | I16: 0.018726592 | J16: 0.014981273 | K16: 0.011235955 | L16: 0.011235955
D17: 80～84歳 | E17: 0.23396226 | F17: 0.018867925 | G17: 0.056603774 | H17: 0.011320755 | I17: 0.052830189 | J17: 0.041509434 | K17: 0.026415094 | L17: 0.026415094
D18: 85～89歳 | E18: 0.48017621 | F18: 0.026431718 | G18: 0.061674009 | H18: 0.057268722 | I18: 0.15418502 | J18: 0.092511013 | K18: 0.052863436 | L18: 0.035242291
D19: 90歳以上 | E19: 0.76442308 | F19: 0.0048076923 | G19: 0.081730769 | H19: 0.048076923 | I19: 0.17307692 | J19: 0.21153846 | K19: 0.14423077 | L19: 0.10096154
C20: 第2号被保険者 | E20: 0.0015698587 | F20: 0 | G20: 0 | H20: 0 | I20: 0.0015698587 | J20: 0 | K20: 0 | L20: 0
C21: 総数 | E21: 0.12929894 | F21: 0.0049603175 | G21: 0.020502646 | H21: 0.010251323 | I21: 0.032738095 | J21: 0.02744709 | K21: 0.018849206 | L21: 0.014550265
B22: 計 | C22: 第1号被保険者 | E22: 0.17346939 | F22: 0.0058750773 | G22: 0.028138528 | H22: 0.013296228 | I22: 0.044217687 | J22: 0.039270254 | K22: 0.025046382 | L22: 0.017625232
D23: 65～69歳 | E23: 0.020334928 | F23: 0.0011961722 | G23: 0.004784689 | H23: 0.0011961722 | I23: 0.004784689 | J23: 0.0035885167 | K23: 0.0035885167 | L23: 0.0011961722
D24: 70～74歳 | E24: 0.071518193 | F24: 0.0037641154 | G24: 0.017565872 | H24: 0.0050188206 | I24: 0.017565872 | J24: 0.011292346 | K24: 0.010037641 | L24: 0.0062735257
D25: 75～79歳 | E25: 0.079696395 | F25: 0.0056925996 | G25: 0.015180266 | H25: 0.0018975332 | I25: 0.018975332 | J25: 0.018975332 | K25: 0.009487666 | L25: 0.009487666
D26: 80～84歳 | E26: 0.21585903 | F26: 0.011013216 | G26: 0.052863436 | H26: 0.015418502 | I26: 0.04845815 | J26: 0.04185022 | K26: 0.028634361 | L26: 0.017621145
D27: 85～89歳 | E27: 0.45321637 | F27: 0.01754386 | G27: 0.064327485 | H27: 0.052631579 | I27: 0.14035088 | J27: 0.087719298 | K27: 0.055555556 | L27: 0.035087719
D28: 90歳以上 | E28: 0.69064748 | F28: 0.0035971223 | G28: 0.068345324 | H28: 0.043165468 | I28: 0.1618705 | J28: 0.20143885 | K28: 0.11870504 | L28: 0.09352518
C29: 第2号被保険者 | E29: 0.0026415094 | F29: 0 | G29: 0.00075471698 | H29: 0 | I29: 0.00075471698 | J29: 0.00037735849 | K29: 0.00037735849 | L29: 0.00037735849
C30: 総数 | E30: 0.096532971 | F30: 0.0032290959 | G30: 0.015805574 | H30: 0.0073079538 | I30: 0.0246431 | J30: 0.021753909 | K30: 0.013936098 | L30: 0.00985724
B32: 令和4年度 | L32: 単位：%
E33: 全体 | F33: 要支援１ | G33: 要支援２ | H33: 要介護１ | I33: 要介護２ | J33: 要介護３ | K33: 要介護４ | L33: 要介護５
B34: 男 | C34: 第1号被保険者 | E34: 0.11721366 | F34: 0.0053583389 | G34: 0.018754186 | H34: 0.012056263 | I34: 0.031480241 | J34: 0.021433356 | K34: 0.016075017 | L34: 0.012056263
D35: 65～69歳 | E35: 0.024449878 | F35: 0 | G35: 0.0073349633 | H35: 0 | I35: 0.0097799511 | J35: 0.0024449878 | K35: 0.0024449878 | L35: 0.0024449878
D36: 70～74歳 | E36: 0.071770335 | F36: 0.004784689 | G36: 0.014354067 | H36: 0.004784689 | I36: 0.016746411 | J36: 0.016746411 | K36: 0.009569378 | L36: 0.004784689
D37: 75～79歳 | E37: 0.0625 | F37: 0.0069444444 | G37: 0.010416667 | H37: 0.0069444444 | I37: 0.013888889 | J37: 0.017361111 | K37: 0.0034722222 | L37: 0.0034722222
D38: 80～84歳 | E38: 0.19047619 | F38: 0.010582011 | G38: 0.037037037 | H38: 0.021164021 | I38: 0.037037037 | J38: 0.037037037 | K38: 0.026455026 | L38: 0.021164021
D39: 85～89歳 | E39: 0.34453782 | F39: 0.0084033613 | G39: 0.058823529 | H39: 0.042016807 | I39: 0.12605042 | J39: 0.042016807 | K39: 0.042016807 | L39: 0.025210084
D40: 90歳以上 | E40: 0.57142857 | F40: 0.014285714 | G40: 0.028571429 | H40: 0.071428571 | I40: 0.14285714 | J40: 0.1 | K40: 0.11428571 | L40: 0.1
C41: 第2号被保険者 | E41: 0.0036845984 | F41: 0.00073691968 | G41: 0.0014738394 | H41: 0 | I41: 0 | J41: 0 | K41: 0 | L41: 0.0014738394
...

Sheet リスト
A1: ●選択肢
A2: 性別 | B2: 年齢階級別 | C2: 要介護度別
A3: 男 | B3: 第1号被保険者 | C3: 要支援１
A4: 女 | B4: 65～69歳 | C4: 要支援２
A5: 合計 | B5: 70～74歳 | C5: 要介護１
B6: 75～79歳 | C6: 要介護２
B7: 80～84歳 | C7: 要介護３
B8: 85～89歳 | C8: 要介護４
B9: 90歳以上 | C9: 要介護５
B10: 第2号被保険者 | C10: 全体
B11: 総数
