Workbook
Name グラフ選択: '[1]施策反映(在宅サービス)'!$R$3:$R$7
Name グラフ選択: '[1]施策反映(在宅サービス)'!$R$3:$R$7
Name サービス: #REF!
Name サービス選択: #REF!
Name サービス名: '[1]施策反映(在宅サービス) (利用者数)'!$R$3:$R$21
Name サービス名: '[1]施策反映(在宅サービス) (利用者数)'!$R$3:$R$21
Name 在宅サービス: #REF!
Name 施設・居住系サービス: #REF!
Name 推計パターン名: '[2]1_推計値サマリ'!$S$5
Name 選択肢: #REF!
Name 年度選択: #REF!
Name 保険者番号: '[2]1_推計値サマリ'!$S$4
Name 保険者名: '[2]1_推計値サマリ'!$S$3

Sheet グラフ
B2: 貴保険者における在宅サービス利用率の伸びのパターンの比較
B4: ●説明
B5: 目的
B6: 本シートは、各保険者が次期計画期間における在宅サービスの見込量を定める際に、サービス別の利用実績（利用者数や伸び等）の推移を確認し、その中で生じた状況や実施した施策等、当該実績に寄与したと考えられる状況を振り返ることで、
B7: 一定の仮説に基づく伸びの選択に資することを目的としています。
B9: 本シートの操作方法
B10: 1．「選択」の「サービス別」及び「要介護度別」から選択してください。選択した値により「当該市町村における在宅サービス利用率の伸び」の表とグラフが自動的に変更されます。
B11: 2．下部のグラフを確認してください。
B12: 3．地域包括ケア「見える化」システム「将来推計」の「推計方法の設定」画面から、在宅サービス利用率の伸びを選択してください。
B14: 伸びを選択する際の考え方
B15: 貴保険者において、下記のポイントを踏まえ、次期計画期間における在宅サービス利用率の伸びを選択してください。
C16: ・第９期介護保険事業計画時に設定した在宅サービスの利用率に基づく計画値と令和８年度までの利用実績を比較し、その乖離状況を考慮して、次期計画期間における在宅サービス利用率の伸びを選択してください。
C17: ・また、過年度に自然災害等の特殊な要因による高齢者の人口動態やサービスの利用形態に変化を生じた等、各サービスの利用率に大きな影響を与えたと考えられる状況がある場合には、このような状況を生じた年度を含まない期間の伸びを選択する等、
C18: 各地域における状況を勘案して、適切な在宅サービスの利用率の伸びを選択してください。
B20: ●当該市町村における在宅サービス利用率の伸び | T20: ●選択
H21: 令和3年度 | I21: 令和4年度 | J21: 令和5年度 | K21: 令和6年度 | L21: 令和7年度 | M21: 令和8年度 | N21: 令和9年度 | O21: 令和10年度 | P21: 令和11年度 | R21: 伸び | T21: サービス別 | U21: 要介護度別
B22: 実績値 | H22: =IFERROR(INDEX(データ!$C$4:$J$27,(MATCH($T$22,データ!$B$4:$B$27,0)),MATCH($U$22,データ!$C$3:$J$3,0)),"")*100 -> 9.6286973 | I22: =IFERROR(INDEX(データ!$C$31:$J$54,(MATCH($T$22,データ!$B$31:$B$54,0)),MATCH($U$22,データ!$C$30:$J$30,0)),"")*100 -> 9.0491118 | J22: =IFERROR(INDEX(データ!$C$58:$J$81,(MATCH($T$22,データ!$B$58:$B$81,0)),MATCH($U$22,データ!$C$57:$J$57,0)),"")*100 -> 7.9965972 | K22: =IFERROR(INDEX(データ!$C$85:$J$108,(MATCH($T$22,データ!$B$85:$B$108,0)),MATCH($U$22,データ!$C$84:$J$84,0)),"")*100 -> 9.2461197 | L22: =IFERROR(INDEX(データ!$C$112:$J$135,(MATCH($T$22,データ!$B$112:$B$135,0)),MATCH($U$22,データ!$C$111:$J$111,0)),"")*100 -> 8.7645893 | M22: =IFERROR(INDEX(データ!$C$139:$J$162,(MATCH($T$22,データ!$B$139:$B$162,0)),MATCH($U$22,データ!$C$138:$J$138,0)),"")*100 -> 7.3170732 | T22: 訪問介護 | U22: 全体
B23: ①当該市町村における令和３年度→令和８年度の伸び | M23: =$M$22 -> 7.3170732 | N23: =IFERROR(M23+$R23,"") -> 6.8547483 | O23: =IFERROR(N23+$R23,"") -> 6.3924235 | P23: =IFERROR(O23+$R23,"") -> 5.9300987 | R23: =IFERROR(INDEX(データ!$C$167:$J$190,(MATCH($T$22,データ!$B$167:$B$190,0)),MATCH($U$22,データ!$C$166:$J$166,0)),"")*100 -> -0.46232482
B24: ②当該市町村における令和７年度→令和８年度の伸び | M24: =$M$22 -> 7.3170732 | N24: =IFERROR(M24+$R24,"") -> 5.869557 | O24: =IFERROR(N24+$R24,"") -> 4.4220409 | P24: =IFERROR(O24+$R24,"") -> 2.9745248 | R24: =IFERROR(INDEX(データ!$C$194:$J$217,(MATCH($T$22,データ!$B$194:$B$217,0)),MATCH($U$22,データ!$C$193:$J$193,0)),"")*100 -> -1.4475161
B25: ③当該市町村における令和６年度→令和８年度の伸び | M25: =$M$22 -> 7.3170732 | N25: =IFERROR(M25+$R25,"") -> 6.3525499 | O25: =IFERROR(N25+$R25,"") -> 5.3880266 | P25: =IFERROR(O25+$R25,"") -> 4.4235033 | R25: =IFERROR(INDEX(データ!$C$221:$J$244,(MATCH($T$22,データ!$B$221:$B$244,0)),MATCH($U$22,データ!$C$220:$J$220,0)),"")*100 -> -0.96452328
B26: ④当該市町村における令和６年度→令和７年度の伸び | M26: =$M$22 -> 7.3170732 | N26: =IFERROR(M26+$R26,"") -> 6.8355427 | O26: =IFERROR(N26+$R26,"") -> 6.3540123 | P26: =IFERROR(O26+$R26,"") -> 5.8724819 | R26: =IFERROR(INDEX(データ!$C$248:$J$271,(MATCH($T$22,データ!$B$248:$B$271,0)),MATCH($U$22,データ!$C$247:$J$247,0)),"")*100 -> -0.48153044
B58: 各伸びの定義
B59: 各在宅サービスの利用者数の自然体推計では、第９期の各サービスの利用率の「伸び（変化の傾き）」が第10期以降も続くという仮定に基づいて推計を行います。
B60: 将来の在宅サービス利用者数の推計は、将来の在宅サービス対象者数の推計をもとに、サービス利用率の実績と貴保険者が設定した現状の推移から予測される年間のサービス利用率の変化（ただし、令和12年度以降は、令和11年度の在宅サービス利用率が継続と仮定）により算出します。
B61: 在宅サービス利用率の１年間の伸びについて、「当該市町村における在宅サービス利用率の伸び」の①～④から１つを選択します。
B63: ＜①～④の計算式＞
C64: ①当該市町村における令和３年度→令和８年度の伸び
D65: ＝（令和８年度の在宅サービス利用率－令和３年度の在宅サービス利用率）÷５ ※単年度の伸びを算出
C66: ②当該市町村における令和７年度→令和８年度の伸び
D67: ＝令和８年度の在宅サービス利用率－令和７年度の在宅サービス利用率
C68: ③当該市町村における令和６年度→令和８年度の伸び
D69: ＝（令和８年度の在宅サービス利用率－令和６年度の在宅サービス利用率）÷２ ※単年度の伸びを算出
C70: ④当該市町村における令和６年度→令和７年度の伸び
D71: ＝令和７年度の在宅サービス利用率－令和６年度の在宅サービス利用率
B73: <「当該市町村における在宅サービス利用率の伸び」の推計式>
C74: 各年度の在宅サービス利用率＝令和８年度の在宅サービス利用率+（在宅サービス利用率の伸び×年数）

Sheet データ
B1: 在宅サービス利用率
B2: 令和3年度 | J2: 単位：%
C3: 全体 | D3: 要支援１ | E3: 要支援２ | F3: 要介護１ | G3: 要介護２ | H3: 要介護３ | I3: 要介護４ | J3: 要介護５
B4: （１）居宅サービス
B5: 訪問介護 | C5: 0.096286973 | F5: 0.10672854 | G5: 0.12584118 | H5: 0.11418685 | I5: 0.15420561 | J5: 0.28909953
B6: 訪問入浴介護 | C6: 0.015942941 | D6: 0 | E6: 0 | F6: 0 | G6: 0.011440108 | H6: 0.0046136101 | I6: 0.086448598 | J6: 0.085308057
B7: 訪問看護 | C7: 0.015942941 | D7: 0 | E7: 0 | F7: 0.027842227 | G7: 0.010094213 | H7: 0.023068051 | I7: 0.021028037 | J7: 0.09478673
B8: 訪問リハビリテーション | C8: 0.048038599 | D8: 0.035087719 | E8: 0.048387097 | F8: 0.055684455 | G8: 0.074024226 | H8: 0.035755479 | I8: 0.0046728972 | J8: 0
B9: 居宅療養管理指導 | C9: 0.013215859 | D9: 0 | E9: 0 | F9: 0 | G9: 0 | H9: 0.023068051 | I9: 0.030373832 | J9: 0.14218009
B10: 通所介護 | C10: 0.14789176 | F10: 0.19721578 | G10: 0.24697174 | H10: 0.16839677 | I10: 0.1682243 | J10: 0.16587678
B11: 通所リハビリテーション | C11: 0.33585064 | D11: 0.070175439 | E11: 0.34498208 | F11: 0.27610209 | G11: 0.32907133 | H11: 0.37831603 | I11: 0.44392523 | J11: 0.3507109
B12: 短期入所生活介護 | C12: 0.047828823 | D12: 0 | E12: 0.0080645161 | F12: 0.011600928 | G12: 0.024899058 | H12: 0.1372549 | I12: 0.095794393 | J12: 0.08056872
B13: 短期入所療養介護（老健） | C13: 0.026851269 | D13: 0.0087719298 | E13: 0.00089605735 | F13: 0.0069605568 | G13: 0.035666218 | H13: 0.050749712 | I13: 0.028037383 | J13: 0.061611374
B14: 短期入所療養介護（病院等） | C14: 0 | D14: 0 | E14: 0 | F14: 0 | G14: 0 | H14: 0 | I14: 0 | J14: 0
B15: 短期入所療養介護（介護医療院） | C15: 0 | D15: 0 | E15: 0 | F15: 0 | G15: 0 | H15: 0 | I15: 0 | J15: 0
B16: 福祉用具貸与 | C16: 0.45122719 | D16: 0.17105263 | E16: 0.36469534 | F16: 0.22737819 | G16: 0.50403769 | H16: 0.46943483 | I16: 0.71495327 | J16: 0.68720379
B17: 特定福祉用具購入費 | C17: 0.005034613 | D17: 0.0043859649 | E17: 0.0053763441 | F17: 0.0069605568 | G17: 0.0047106326 | H17: 0.0046136101 | I17: 0.0070093458 | J17: 0
B18: 住宅改修費 | C18: 0.0035661842 | D18: 0.0043859649 | E18: 0.0053763441 | F18: 0.0023201856 | G18: 0.0020188425 | H18: 0.0034602076 | I18: 0.0046728972 | J18: 0.0047393365
B19: 介護予防支援・居宅介護支援 | C19: 0.69960143 | D19: 0.26754386 | E19: 0.58781362 | F19: 0.66357309 | G19: 0.77725437 | H19: 0.75201845 | I19: 0.86915888 | J19: 0.72511848
B20: 登録施設介護支援 | C20: 0 | D20: 0 | E20: 0 | F20: 0 | G20: 0 | H20: 0 | I20: 0 | J20: 0
B21: （２）地域密着型サービス
B22: 定期巡回・随時対応型訪問介護看護 | C22: 0 | F22: 0 | G22: 0 | H22: 0 | I22: 0 | J22: 0
B23: 夜間対応型訪問介護 | C23: 0 | F23: 0 | G23: 0 | H23: 0 | I23: 0 | J23: 0
B24: 地域密着型通所介護 | C24: 0 | F24: 0 | G24: 0 | H24: 0 | I24: 0 | J24: 0
B25: 認知症対応型通所介護 | C25: 0 | D25: 0 | E25: 0 | F25: 0 | G25: 0 | H25: 0 | I25: 0 | J25: 0
B26: 小規模多機能型居宅介護 | C26: 0 | D26: 0 | E26: 0 | F26: 0 | G26: 0 | H26: 0 | I26: 0 | J26: 0
B27: 看護小規模多機能型居宅介護 | C27: 0 | F27: 0 | G27: 0 | H27: 0 | I27: 0 | J27: 0
B29: 令和4年度 | J29: 単位：%
C30: 全体 | D30: 要支援１ | E30: 要支援２ | F30: 要介護１ | G30: 要介護２ | H30: 要介護３ | I30: 要介護４ | J30: 要介護５
B31: （１）居宅サービス
B32: 訪問介護 | C32: 0.090491118 | F32: 0.10990712 | G32: 0.11134904 | H32: 0.13198758 | I32: 0.14253898 | J32: 0.22529644
B33: 訪問入浴介護 | C33: 0.01630094 | D33: 0 | E33: 0 | F33: 0 | G33: 0.01213419 | H33: 0.01242236 | I33: 0.069042316 | J33: 0.086956522
B34: 訪問看護 | C34: 0.017345873 | D34: 0 | E34: 0.0092592593 | F34: 0.0015479876 | G34: 0.0071377587 | H34: 0.031055901 | I34: 0.042316258 | J34: 0.090909091
B35: 訪問リハビリテーション | C35: 0.048275862 | D35: 0.051282051 | E35: 0.051851852 | F35: 0.047987616 | G35: 0.053533191 | H35: 0.065217391 | I35: 0.022271715 | J35: 0.0039525692
B36: 居宅療養管理指導 | C36: 0.012957158 | D36: 0 | E36: 0 | F36: 0.0077399381 | G36: 0.0021413276 | H36: 0.027950311 | I36: 0.008908686 | J36: 0.12648221
B37: 通所介護 | C37: 0.14357367 | F37: 0.14551084 | G37: 0.25838687 | H37: 0.21583851 | I37: 0.12917595 | J37: 0.13438735
B38: 通所リハビリテーション | C38: 0.32936259 | D38: 0.14102564 | E38: 0.38240741 | F38: 0.30650155 | G38: 0.31263383 | H38: 0.37888199 | I38: 0.39420935 | J38: 0.24505929
B39: 短期入所生活介護 | C39: 0.035527691 | D39: 0 | E39: 0.0018518519 | F39: 0.021671827 | G39: 0.0206995 | H39: 0.11801242 | I39: 0.06013363 | J39: 0.086956522
B40: 短期入所療養介護（老健） | C40: 0.023615465 | D40: 0 | E40: 0 | F40: 0.0092879257 | G40: 0.032119914 | H40: 0.038819876 | I40: 0.053452116 | J40: 0.051383399
B41: 短期入所療養介護（病院等） | C41: 0 | D41: 0 | E41: 0 | F41: 0 | G41: 0 | H41: 0 | I41: 0 | J41: 0
...

Sheet リスト
A1: ●選択肢
A2: サービス別 | B2: 要介護度別
A3: 訪問介護 | B3: 要支援１
A4: 訪問入浴介護 | B4: 要支援２
A5: 訪問看護 | B5: 要介護１
A6: 訪問リハビリテーション | B6: 要介護２
A7: 居宅療養管理指導 | B7: 要介護３
A8: 通所介護 | B8: 要介護４
A9: 通所リハビリテーション | B9: 要介護５
A10: 短期入所生活介護 | B10: 全体
A11: 短期入所療養介護（老健）
A12: 短期入所療養介護（病院等）
A13: 短期入所療養介護（介護医療院）
A14: 福祉用具貸与
A15: 特定福祉用具購入費
A16: 住宅改修費
A17: 介護予防支援・居宅介護支援
A18: 登録施設介護支援
A19: 定期巡回・随時対応型訪問介護看護
A20: 夜間対応型訪問介護
A21: 地域密着型通所介護
A22: 認知症対応型通所介護
... A24: 看護小規模多機能型居宅介護
