Workbook
Name グラフ選択: #REF!
Name グラフ選択: #REF!
Name サービス: #REF!
Name サービス: #REF!
Name サービス選択: #REF!
Name サービス選択: #REF!
Name サービス名: #REF!
Name サービス名: #REF!
Name 在宅サービス: #REF!
Name 在宅サービス: #REF!
Name 施設・居住系サービス: #REF!
Name 施設・居住系サービス: #REF!
Name 推計パターン名: '1_推計値サマリ'!$S$5
Name 選択肢: #REF!
Name 選択肢: #REF!
Name 年度選択: #REF!
Name 年度選択: #REF!
Name 年度選択: #REF!
Name 保険者番号: '1_推計値サマリ'!$S$4
Name 保険者名: '1_推計値サマリ'!$S$3

Sheet 1_推計値サマリ
A1: 第10期介護保険事業（支援）計画策定に向けたワークシート 【総括表】
S2: 出力日： | T2: 2026/09/11
Q3: 保険者名 | S3: 川崎町
Q4: 保険者番号 | S4: 04324
Q5: 推計パターン名 | S5: R8
A6: （１）推計値サマリ
A8: １．被保険者数（年度別）
T9: 単位：人
D10: 令和6年度 | E10: 令和7年度 | F10: 令和8年度 | G10: 令和9年度 | H10: 令和10年度 | I10: 令和11年度 | J10: 伸び率① ※１ | K10: 令和12年度 | L10: 伸び率① ※２ | M10: 令和17年度 | N10: 伸び率① ※２ | O10: 令和22年度 | P10: 伸び率① ※２ | Q10: 令和27年度 | R10: 伸び率① ※２ | S10: 令和32年度 | T10: 伸び率① ※２
A11: 総数 | D11: =SUM(D12:D13) -> 5774 | E11: =SUM(E12:E13) -> 5740 | F11: =SUM(F12:F13) -> 5672 | G11: =SUM(G12:G13) -> 5605 | H11: =SUM(H12:H13) -> 5536 | I11: =SUM(I12:I13) -> 5469 | J11: =IFERROR((SUM(G11:I11)/3)/F11,"－") -> 0.9761401 | K11: =SUM(K12:K13) -> 5401 | L11: =IFERROR(K11/F11,"－") -> 0.95222144 | M11: =SUM(M12:M13) -> 5009 | N11: =IFERROR(M11/F11,"－") -> 0.88311001 | O11: =SUM(O12:O13) -> 4640 | P11: =IFERROR(O11/F11,"－") -> 0.8180536 | Q11: =SUM(Q12:Q13) -> 4192 | R11: =IFERROR(Q11/F11,"－") -> 0.73906911 | S11: =SUM(S12:S13) -> 3748 | T11: =IFERROR(S11/F11,"－") -> 0.66078984
B12: 第1号被保険者数 | D12: 3270 | E12: 3285 | F12: 3257 | G12: 3231 | H12: 3203 | I12: 3177 | J12: =IFERROR((SUM(G12:I12)/3)/F12,"－") -> 0.98362501 | K12: 3149 | L12: =IFERROR(K12/F12,"－") -> 0.96684065 | M12: 2967 | N12: =IFERROR(M12/F12,"－") -> 0.91096101 | O12: 2835 | P12: =IFERROR(O12/F12,"－") -> 0.87043291 | Q12: 2639 | R12: =IFERROR(Q12/F12,"－") -> 0.81025484 | S12: 2494 | T12: =IFERROR(S12/F12,"－") -> 0.76573534
B13: 第2号被保険者数 | D13: 2504 | E13: 2455 | F13: 2415 | G13: 2374 | H13: 2333 | I13: 2292 | J13: =IFERROR((SUM(G13:I13)/3)/F13,"－") -> 0.96604555 | K13: 2252 | L13: =IFERROR(K13/F13,"－") -> 0.93250518 | M13: 2042 | N13: =IFERROR(M13/F13,"－") -> 0.84554865 | O13: 1805 | P13: =IFERROR(O13/F13,"－") -> 0.74741201 | Q13: 1553 | R13: =IFERROR(Q13/F13,"－") -> 0.64306418 | S13: 1254 | T13: =IFERROR(S13/F13,"－") -> 0.51925466
G14: ※１：第10期平均値/令和8年度の値*100 | K14: ※２：令和12（17,22,27,32）年度の値/令和8年度の値*100
A16: ２．要介護（支援）認定者数
T17: 単位：人
D18: 令和6年度 | E18: 令和7年度 | F18: 令和8年度 | G18: 令和9年度 | H18: 令和10年度 | I18: 令和11年度 | J18: 伸び率① ※１ | K18: 令和12年度 | L18: 伸び率① ※２ | M18: 令和17年度 | N18: 伸び率① ※２ | O18: 令和22年度 | P18: 伸び率① ※２ | Q18: 令和27年度 | R18: 伸び率① ※２ | S18: 令和32年度 | T18: 伸び率① ※２
A19: 総数 | D19: =SUM(D20:D26) -> 562 | E19: =SUM(E20:E26) -> 568 | F19: =SUM(F20:F26) -> 567 | G19: =SUM(G20:G26) -> 580 | H19: =SUM(H20:H26) -> 576 | I19: =SUM(I20:I26) -> 581 | J19: =IFERROR((SUM(G19:I19)/3)/F19,"－") -> 1.021164 | K19: =SUM(K20:K26) -> 585 | L19: =IFERROR(K19/F19,"－") -> 1.031746 | M19: =SUM(M20:M26) -> 639 | N19: =IFERROR(M19/F19,"－") -> 1.1269841 | O19: =SUM(O20:O26) -> 688 | P19: =IFERROR(O19/F19,"－") -> 1.2134039 | Q19: =SUM(Q20:Q26) -> 666 | R19: =IFERROR(Q19/F19,"－") -> 1.1746032 | S19: =SUM(S20:S26) -> 586 | T19: =IFERROR(S19/F19,"－") -> 1.0335097
C20: 要支援1 | D20: 27 | E20: 33 | F20: 33 | G20: 34 | H20: 33 | I20: 33 | J20: =IFERROR((SUM(G20:I20)/3)/F20,"－") -> 1.010101 | K20: 34 | L20: =IFERROR(K20/F20,"－") -> 1.030303 | M20: 40 | N20: =IFERROR(M20/F20,"－") -> 1.2121212 | O20: 41 | P20: =IFERROR(O20/F20,"－") -> 1.2424242 | Q20: 37 | R20: =IFERROR(Q20/F20,"－") -> 1.1212121 | S20: 31 | T20: =IFERROR(S20/F20,"－") -> 0.93939394
C21: 要支援2 | D21: 73 | E21: 85 | F21: 92 | G21: 97 | H21: 93 | I21: 96 | J21: =IFERROR((SUM(G21:I21)/3)/F21,"－") -> 1.0362319 | K21: 95 | L21: =IFERROR(K21/F21,"－") -> 1.0326087 | M21: 102 | N21: =IFERROR(M21/F21,"－") -> 1.1086957 | O21: 107 | P21: =IFERROR(O21/F21,"－") -> 1.1630435 | Q21: 103 | R21: =IFERROR(Q21/F21,"－") -> 1.1195652 | S21: 92 | T21: =IFERROR(S21/F21,"－") -> 1
C22: 要介護1 | D22: 69 | E22: 70 | F22: 65 | G22: 64 | H22: 72 | I22: 73 | J22: =IFERROR((SUM(G22:I22)/3)/F22,"－") -> 1.0717949 | K22: 75 | L22: =IFERROR(K22/F22,"－") -> 1.1538462 | M22: 82 | N22: =IFERROR(M22/F22,"－") -> 1.2615385 | O22: 85 | P22: =IFERROR(O22/F22,"－") -> 1.3076923 | Q22: 78 | R22: =IFERROR(Q22/F22,"－") -> 1.2 | S22: 67 | T22: =IFERROR(S22/F22,"－") -> 1.0307692
C23: 要介護2 | D23: 126 | E23: 116 | F23: 97 | G23: 98 | H23: 91 | I23: 93 | J23: =IFERROR((SUM(G23:I23)/3)/F23,"－") -> 0.96907216 | K23: 94 | L23: =IFERROR(K23/F23,"－") -> 0.96907216 | M23: 104 | N23: =IFERROR(M23/F23,"－") -> 1.0721649 | O23: 108 | P23: =IFERROR(O23/F23,"－") -> 1.1134021 | Q23: 102 | R23: =IFERROR(Q23/F23,"－") -> 1.0515464 | S23: 89 | T23: =IFERROR(S23/F23,"－") -> 0.91752577
C24: 要介護3 | D24: 126 | E24: 131 | F24: 133 | G24: 138 | H24: 134 | I24: 134 | J24: =IFERROR((SUM(G24:I24)/3)/F24,"－") -> 1.0175439 | K24: 133 | L24: =IFERROR(K24/F24,"－") -> 1 | M24: 149 | N24: =IFERROR(M24/F24,"－") -> 1.1203008 | O24: 164 | P24: =IFERROR(O24/F24,"－") -> 1.2330827 | Q24: 164 | R24: =IFERROR(Q24/F24,"－") -> 1.2330827 | S24: 143 | T24: =IFERROR(S24/F24,"－") -> 1.075188
C25: 要介護4 | D25: 89 | E25: 84 | F25: 98 | G25: 99 | H25: 103 | I25: 102 | J25: =IFERROR((SUM(G25:I25)/3)/F25,"－") -> 1.0340136 | K25: 103 | L25: =IFERROR(K25/F25,"－") -> 1.0510204 | M25: 110 | N25: =IFERROR(M25/F25,"－") -> 1.122449 | O25: 122 | P25: =IFERROR(O25/F25,"－") -> 1.244898 | Q25: 119 | R25: =IFERROR(Q25/F25,"－") -> 1.2142857 | S25: 107 | T25: =IFERROR(S25/F25,"－") -> 1.0918367
C26: 要介護5 | D26: 52 | E26: 49 | F26: 49 | G26: 50 | H26: 50 | I26: 50 | J26: =IFERROR((SUM(G26:I26)/3)/F26,"－") -> 1.0204082 | K26: 51 | L26: =IFERROR(K26/F26,"－") -> 1.0408163 | M26: 52 | N26: =IFERROR(M26/F26,"－") -> 1.0612245 | O26: 61 | P26: =IFERROR(O26/F26,"－") -> 1.244898 | Q26: 63 | R26: =IFERROR(Q26/F26,"－") -> 1.2857143 | S26: 57 | T26: =IFERROR(S26/F26,"－") -> 1.1632653
B27: うち第1号被保険者数 | D27: =SUM(D28:D34) -> 554 | E27: =SUM(E28:E34) -> 560 | F27: =SUM(F28:F34) -> 562 | G27: =SUM(G28:G34) -> 575 | H27: =SUM(H28:H34) -> 571 | I27: =SUM(I28:I34) -> 576 | J27: =IFERROR((SUM(G27:I27)/3)/F27,"－") -> 1.0213523 | K27: =SUM(K28:K34) -> 580 | L27: =IFERROR(K27/F27,"－") -> 1.0320285 | M27: =SUM(M28:M34) -> 634 | N27: =IFERROR(M27/F27,"－") -> 1.1281139 | O27: =SUM(O28:O34) -> 683 | P27: =IFERROR(O27/F27,"－") -> 1.2153025 | Q27: =SUM(Q28:Q34) -> 662 | R27: =IFERROR(Q27/F27,"－") -> 1.1779359 | S27: =SUM(S28:S34) -> 584 | T27: =IFERROR(S27/F27,"－") -> 1.0391459
C28: 要支援1 | D28: 27 | E28: 33 | F28: 33 | G28: 34 | H28: 33 | I28: 33 | J28: =IFERROR((SUM(G28:I28)/3)/F28,"－") -> 1.010101 | K28: 34 | L28: =IFERROR(K28/F28,"－") -> 1.030303 | M28: 40 | N28: =IFERROR(M28/F28,"－") -> 1.2121212 | O28: 41 | P28: =IFERROR(O28/F28,"－") -> 1.2424242 | Q28: 37 | R28: =IFERROR(Q28/F28,"－") -> 1.1212121 | S28: 31 | T28: =IFERROR(S28/F28,"－") -> 0.93939394
C29: 要支援2 | D29: 72 | E29: 84 | F29: 91 | G29: 96 | H29: 92 | I29: 95 | J29: =IFERROR((SUM(G29:I29)/3)/F29,"－") -> 1.03663 | K29: 94 | L29: =IFERROR(K29/F29,"－") -> 1.032967 | M29: 101 | N29: =IFERROR(M29/F29,"－") -> 1.1098901 | O29: 106 | P29: =IFERROR(O29/F29,"－") -> 1.1648352 | Q29: 102 | R29: =IFERROR(Q29/F29,"－") -> 1.1208791 | S29: 92 | T29: =IFERROR(S29/F29,"－") -> 1.010989
C30: 要介護1 | D30: 68 | E30: 69 | F30: 65 | G30: 64 | H30: 72 | I30: 73 | J30: =IFERROR((SUM(G30:I30)/3)/F30,"－") -> 1.0717949 | K30: 75 | L30: =IFERROR(K30/F30,"－") -> 1.1538462 | M30: 82 | N30: =IFERROR(M30/F30,"－") -> 1.2615385 | O30: 85 | P30: =IFERROR(O30/F30,"－") -> 1.3076923 | Q30: 78 | R30: =IFERROR(Q30/F30,"－") -> 1.2 | S30: 67 | T30: =IFERROR(S30/F30,"－") -> 1.0307692
C31: 要介護2 | D31: 124 | E31: 115 | F31: 97 | G31: 98 | H31: 91 | I31: 93 | J31: =IFERROR((SUM(G31:I31)/3)/F31,"－") -> 0.96907216 | K31: 94 | L31: =IFERROR(K31/F31,"－") -> 0.96907216 | M31: 104 | N31: =IFERROR(M31/F31,"－") -> 1.0721649 | O31: 108 | P31: =IFERROR(O31/F31,"－") -> 1.1134021 | Q31: 102 | R31: =IFERROR(Q31/F31,"－") -> 1.0515464 | S31: 89 | T31: =IFERROR(S31/F31,"－") -> 0.91752577
C32: 要介護3 | D32: 125 | E32: 128 | F32: 131 | G32: 136 | H32: 132 | I32: 132 | J32: =IFERROR((SUM(G32:I32)/3)/F32,"－") -> 1.0178117 | K32: 131 | L32: =IFERROR(K32/F32,"－") -> 1 | M32: 147 | N32: =IFERROR(M32/F32,"－") -> 1.1221374 | O32: 162 | P32: =IFERROR(O32/F32,"－") -> 1.2366412 | Q32: 162 | R32: =IFERROR(Q32/F32,"－") -> 1.2366412 | S32: 142 | T32: =IFERROR(S32/F32,"－") -> 1.0839695
C33: 要介護4 | D33: 87 | E33: 83 | F33: 98 | G33: 99 | H33: 103 | I33: 102 | J33: =IFERROR((SUM(G33:I33)/3)/F33,"－") -> 1.0340136 | K33: 103 | L33: =IFERROR(K33/F33,"－") -> 1.0510204 | M33: 110 | N33: =IFERROR(M33/F33,"－") -> 1.122449 | O33: 122 | P33: =IFERROR(O33/F33,"－") -> 1.244898 | Q33: 119 | R33: =IFERROR(Q33/F33,"－") -> 1.2142857 | S33: 107 | T33: =IFERROR(S33/F33,"－") -> 1.0918367
C34: 要介護5 | D34: 51 | E34: 48 | F34: 47 | G34: 48 | H34: 48 | I34: 48 | J34: =IFERROR((SUM(G34:I34)/3)/F34,"－") -> 1.0212766 | K34: 49 | L34: =IFERROR(K34/F34,"－") -> 1.0425532 | M34: 50 | N34: =IFERROR(M34/F34,"－") -> 1.0638298 | O34: 59 | P34: =IFERROR(O34/F34,"－") -> 1.2553191 | Q34: 62 | R34: =IFERROR(Q34/F34,"－") -> 1.3191489 | S34: 56 | T34: =IFERROR(S34/F34,"－") -> 1.1914894
G35: ※１：第10期平均値/令和8年度の値*100 | K35: ※２：令和12（17,22,27,32）年度の値/令和8年度の値*100
A37: ３．介護予防サービス見込量
T38: 単位：千円
D39: 令和6年度 | E39: 令和7年度 | F39: 令和8年度 | G39: 令和9年度 | H39: 令和10年度 | I39: 令和11年度 | J39: 伸び率① ※１ | K39: 令和12年度 | L39: 伸び率① ※２ | M39: 令和17年度 | N39: 伸び率① ※２ | O39: 令和22年度 | P39: 伸び率① ※２ | Q39: 令和27年度 | R39: 伸び率① ※２ | S39: 令和32年度 | T39: 伸び率① ※２
A40: （１）在宅サービス | D40: =('2_サービス別給付費'!D12+'2_サービス別給付費'!D14+'2_サービス別給付費'!D17+'2_サービス別給付費'!D20+'2_サービス別給付費'!D23+'2_サービス別給付費'!D25+'2_サービス別給付費'!D27+'2_サービス別給付費'!D29+'2_サービス別給付費'!D32+'2_サービス別給付費'!D35+'2_サービス別給付費'!D38+'2_サービス別給付費'!D41+'2_サービス別給付費'!D43+'2_サービス別給付費'!D45+'2_サービス別給付費'!D50+'2_サービス別給付費'!D53+'2_サービス別給付費'!D57) -> 27005.507 | E40: =('2_サービス別給付費'!E12+'2_サービス別給付費'!E14+'2_サービス別給付費'!E17+'2_サービス別給付費'!E20+'2_サービス別給付費'!E23+'2_サービス別給付費'!E25+'2_サービス別給付費'!E27+'2_サービス別給付費'!E29+'2_サービス別給付費'!E32+'2_サービス別給付費'!E35+'2_サービス別給付費'!E38+'2_サービス別給付費'!E41+'2_サービス別給付費'!E43+'2_サービス別給付費'!E45+'2_サービス別給付費'!E50+'2_サービス別給付費'!E53+'2_サービス別給付費'!E57) -> 27938.341 | F40: =('2_サービス別給付費'!F12+'2_サービス別給付費'!F14+'2_サービス別給付費'!F17+'2_サービス別給付費'!F20+'2_サービス別給付費'!F23+'2_サービス別給付費'!F25+'2_サービス別給付費'!F27+'2_サービス別給付費'!F29+'2_サービス別給付費'!F32+'2_サービス別給付費'!F35+'2_サービス別給付費'!F38+'2_サービス別給付費'!F41+'2_サービス別給付費'!F43+'2_サービス別給付費'!F45+'2_サービス別給付費'!F50+'2_サービス別給付費'!F53+'2_サービス別給付費'!F57) -> 26302.52 | G40: =('2_サービス別給付費'!G12+'2_サービス別給付費'!G14+'2_サービス別給付費'!G17+'2_サービス別給付費'!G20+'2_サービス別給付費'!G23+'2_サービス別給付費'!G25+'2_サービス別給付費'!G27+'2_サービス別給付費'!G29+'2_サービス別給付費'!G32+'2_サービス別給付費'!G35+'2_サービス別給付費'!G38+'2_サービス別給付費'!G41+'2_サービス別給付費'!G43+'2_サービス別給付費'!G45+'2_サービス別給付費'!G50+'2_サービス別給付費'!G53+'2_サービス別給付費'!G57) -> 28331 | H40: =('2_サービス別給付費'!H12+'2_サービス別給付費'!H14+'2_サービス別給付費'!H17+'2_サービス別給付費'!H20+'2_サービス別給付費'!H23+'2_サービス別給付費'!H25+'2_サービス別給付費'!H27+'2_サービス別給付費'!H29+'2_サービス別給付費'!H32+'2_サービス別給付費'!H35+'2_サービス別給付費'!H38+'2_サービス別給付費'!H41+'2_サービス別給付費'!H43+'2_サービス別給付費'!H45+'2_サービス別給付費'!H50+'2_サービス別給付費'!H53+'2_サービス別給付費'!H57+'2_サービス別給付費'!H59) -> 27269 | I40: =('2_サービス別給付費'!I12+'2_サービス別給付費'!I14+'2_サービス別給付費'!I17+'2_サービス別給付費'!I20+'2_サービス別給付費'!I23+'2_サービス別給付費'!I25+'2_サービス別給付費'!I27+'2_サービス別給付費'!I29+'2_サービス別給付費'!I32+'2_サービス別給付費'!I35+'2_サービス別給付費'!I38+'2_サービス別給付費'!I41+'2_サービス別給付費'!I43+'2_サービス別給付費'!I45+'2_サービス別給付費'!I50+'2_サービス別給付費'!I53+'2_サービス別給付費'!I57+'2_サービス別給付費'!I59) -> 27965 | J40: =IFERROR((SUM(G40:I40)/3)/F40,"－") -> 1.059024 | K40: =('2_サービス別給付費'!K12+'2_サービス別給付費'!K14+'2_サービス別給付費'!K17+'2_サービス別給付費'!K20+'2_サービス別給付費'!K23+'2_サービス別給付費'!K25+'2_サービス別給付費'!K27+'2_サービス別給付費'!K29+'2_サービス別給付費'!K32+'2_サービス別給付費'!K35+'2_サービス別給付費'!K38+'2_サービス別給付費'!K41+'2_サービス別給付費'!K43+'2_サービス別給付費'!K45+'2_サービス別給付費'!K50+'2_サービス別給付費'!K53+'2_サービス別給付費'!K57+'2_サービス別給付費'!K59) -> 28024 | L40: =IFERROR(K40/F40,"－") -> 1.0654492 | M40: =('2_サービス別給付費'!M12+'2_サービス別給付費'!M14+'2_サービス別給付費'!M17+'2_サービス別給付費'!M20+'2_サービス別給付費'!M23+'2_サービス別給付費'!M25+'2_サービス別給付費'!M27+'2_サービス別給付費'!M29+'2_サービス別給付費'!M32+'2_サービス別給付費'!M35+'2_サービス別給付費'!M38+'2_サービス別給付費'!M41+'2_サービス別給付費'!M43+'2_サービス別給付費'!M45+'2_サービス別給付費'!M50+'2_サービス別給付費'!M53+'2_サービス別給付費'!M57+'2_サービス別給付費'!M59) -> 30145 | N40: =IFERROR(M40/F40,"－") -> 1.1460879 | O40: =('2_サービス別給付費'!O12+'2_サービス別給付費'!O14+'2_サービス別給付費'!O17+'2_サービス別給付費'!O20+'2_サービス別給付費'!O23+'2_サービス別給付費'!O25+'2_サービス別給付費'!O27+'2_サービス別給付費'!O29+'2_サービス別給付費'!O32+'2_サービス別給付費'!O35+'2_サービス別給付費'!O38+'2_サービス別給付費'!O41+'2_サービス別給付費'!O43+'2_サービス別給付費'!O45+'2_サービス別給付費'!O50+'2_サービス別給付費'!O53+'2_サービス別給付費'!O57+'2_サービス別給付費'!O59) -> 31301 | P40: =IFERROR(O40/F40,"－") -> 1.190038 | Q40: =('2_サービス別給付費'!Q12+'2_サービス別給付費'!Q14+'2_サービス別給付費'!Q17+'2_サービス別給付費'!Q20+'2_サービス別給付費'!Q23+'2_サービス別給付費'!Q25+'2_サービス別給付費'!Q27+'2_サービス別給付費'!Q29+'2_サービス別給付費'!Q32+'2_サービス別給付費'!Q35+'2_サービス別給付費'!Q38+'2_サービス別給付費'!Q41+'2_サービス別給付費'!Q43+'2_サービス別給付費'!Q45+'2_サービス別給付費'!Q50+'2_サービス別給付費'!Q53+'2_サービス別給付費'!Q57+'2_サービス別給付費'!Q59) -> 29982 | R40: =IFERROR(Q40/F40,"－") -> 1.1398908 | S40: =('2_サービス別給付費'!S12+'2_サービス別給付費'!S14+'2_サービス別給付費'!S17+'2_サービス別給付費'!S20+'2_サービス別給付費'!S23+'2_サービス別給付費'!S25+'2_サービス別給付費'!S27+'2_サービス別給付費'!S29+'2_サービス別給付費'!S32+'2_サービス別給付費'!S35+'2_サービス別給付費'!S38+'2_サービス別給付費'!S41+'2_サービス別給付費'!S43+'2_サービス別給付費'!S45+'2_サービス別給付費'!S50+'2_サービス別給付費'!S53+'2_サービス別給付費'!S57+'2_サービス別給付費'!S59) -> 26805 | T40: =IFERROR(S40/F40,"－") -> 1.0191039
A41: （２）居住系サービス | D41: =('2_サービス別給付費'!D47+'2_サービス別給付費'!D55) -> 0 | E41: =('2_サービス別給付費'!E47+'2_サービス別給付費'!E55) -> 4349.297 | F41: =('2_サービス別給付費'!F47+'2_サービス別給付費'!F55) -> 3086.664 | G41: =('2_サービス別給付費'!G47+'2_サービス別給付費'!G55) -> 3070 | H41: =('2_サービス別給付費'!H47+'2_サービス別給付費'!H55) -> 3070 | I41: =('2_サービス別給付費'!I47+'2_サービス別給付費'!I55) -> 3070 | J41: =IFERROR((SUM(G41:I41)/3)/F41,"－") -> 0.99460129 | K41: =('2_サービス別給付費'!K47+'2_サービス別給付費'!K55) -> 3070 | L41: =IFERROR(K41/F41,"－") -> 0.99460129 | M41: =('2_サービス別給付費'!M47+'2_サービス別給付費'!M55) -> 3070 | N41: =IFERROR(M41/F41,"－") -> 0.99460129 | O41: =('2_サービス別給付費'!O47+'2_サービス別給付費'!O55) -> 3070 | P41: =IFERROR(O41/F41,"－") -> 0.99460129 | Q41: =('2_サービス別給付費'!Q47+'2_サービス別給付費'!Q55) -> 3070 | R41: =IFERROR(Q41/F41,"－") -> 0.99460129 | S41: =('2_サービス別給付費'!S47+'2_サービス別給付費'!S55) -> 3070 | T41: =IFERROR(S41/F41,"－") -> 0.99460129
A42: 合計 | D42: =SUM(D40:D41) -> 27005.507 | E42: =SUM(E40:E41) -> 32287.638 | F42: =SUM(F40:F41) -> 29389.184 | G42: =SUM(G40:G41) -> 31401 | H42: =SUM(H40:H41) -> 30339 | I42: =SUM(I40:I41) -> 31035 | J42: =IFERROR((SUM(G42:I42)/3)/F42,"－") -> 1.0522579 | K42: =SUM(K40:K41) -> 31094 | L42: =IFERROR(K42/F42,"－") -> 1.0580083 | M42: =SUM(M40:M41) -> 33215 | N42: =IFERROR(M42/F42,"－") -> 1.1301777 | O42: =SUM(O40:O41) -> 34371 | P42: =IFERROR(O42/F42,"－") -> 1.1695119 | Q42: =SUM(Q40:Q41) -> 33052 | R42: =IFERROR(Q42/F42,"－") -> 1.1246314 | S42: =SUM(S40:S41) -> 29875 | T42: =IFERROR(S42/F42,"－") -> 1.0165304
G43: ※１：第10期平均値/令和8年度の値*100 | K43: ※２：令和12（17,22,27,32）年度の値/令和8年度の値*100
...

Sheet 2_サービス別給付費
A1: （２）サービス別給付費
S2: 出力日： | T2: ='1_推計値サマリ'!T2 -> 2026/09/11
Q3: 保険者名 | S3: =保険者名 -> 川崎町
Q4: 保険者番号 | S4: =保険者番号 -> 04324
Q5: 推計パターン名 | S5: =推計パターン名 -> R8
A8: １．介護予防サービス見込量
T9: 単位：各項目の（）内
D10: 令和6年度 | E10: 令和7年度 | F10: 令和8年度 | G10: 令和9年度 | H10: 令和10年度 | I10: 令和11年度 | J10: 伸び率① ※１ | K10: 令和12年度 | L10: 伸び率① ※２ | M10: 令和17年度 | N10: 伸び率① ※２ | O10: 令和22年度 | P10: 伸び率① ※２ | Q10: 令和27年度 | R10: 伸び率① ※２ | S10: 令和32年度 | T10: 伸び率① ※２
A11: （１）介護予防サービス
B12: 未使用 | C12: 給付費（千円）
C13: 人数（人）
B14: 介護予防訪問入浴介護 | C14: 給付費（千円） | D14: 52.542 | E14: 168.56 | F14: 0 | G14: 0 | H14: 0 | I14: 0 | J14: =IFERROR(SUM(G14:I14)/3/F14,"－") -> － | K14: 0 | L14: =IFERROR(K14/F14,"－") -> － | M14: 0 | N14: =IFERROR(M14/F14,"－") -> － | O14: 0 | P14: =IFERROR(O14/F14,"－") -> － | Q14: 0 | R14: =IFERROR(Q14/F14,"－") -> － | S14: 0 | T14: =IFERROR(S14/F14,"－") -> －
C15: 回数（回） | D15: 0.5 | E15: 1.6666667 | F15: 0 | G15: 0 | H15: 0 | I15: 0 | J15: =IFERROR(SUM(G15:I15)/3/F15,"－") -> － | K15: 0 | L15: =IFERROR(K15/F15,"－") -> － | M15: 0 | N15: =IFERROR(M15/F15,"－") -> － | O15: 0 | P15: =IFERROR(O15/F15,"－") -> － | Q15: 0 | R15: =IFERROR(Q15/F15,"－") -> － | S15: 0 | T15: =IFERROR(S15/F15,"－") -> －
C16: 人数（人） | D16: 0.16666667 | E16: 0.41666667 | F16: 0 | G16: 0 | H16: 0 | I16: 0 | J16: =IFERROR(SUM(G16:I16)/3/F16,"－") -> － | K16: 0 | L16: =IFERROR(K16/F16,"－") -> － | M16: 0 | N16: =IFERROR(M16/F16,"－") -> － | O16: 0 | P16: =IFERROR(O16/F16,"－") -> － | Q16: 0 | R16: =IFERROR(Q16/F16,"－") -> － | S16: 0 | T16: =IFERROR(S16/F16,"－") -> －
B17: 介護予防訪問看護 | C17: 給付費（千円） | D17: 153.405 | E17: 118.694 | F17: 114.3072 | G17: 318 | H17: 318 | I17: 318 | J17: =IFERROR(SUM(G17:I17)/3/F17,"－") -> 2.781977 | K17: 318 | L17: =IFERROR(K17/F17,"－") -> 2.781977 | M17: 318 | N17: =IFERROR(M17/F17,"－") -> 2.781977 | O17: 318 | P17: =IFERROR(O17/F17,"－") -> 2.781977 | Q17: 318 | R17: =IFERROR(Q17/F17,"－") -> 2.781977 | S17: 318 | T17: =IFERROR(S17/F17,"－") -> 2.781977
C18: 回数（回） | D18: 3.75 | E18: 2.8333333 | F18: 2.8 | G18: 7.8 | H18: 7.8 | I18: 7.8 | J18: =IFERROR(SUM(G18:I18)/3/F18,"－") -> 2.7857143 | K18: 7.8 | L18: =IFERROR(K18/F18,"－") -> 2.7857143 | M18: 7.8 | N18: =IFERROR(M18/F18,"－") -> 2.7857143 | O18: 7.8 | P18: =IFERROR(O18/F18,"－") -> 2.7857143 | Q18: 7.8 | R18: =IFERROR(Q18/F18,"－") -> 2.7857143 | S18: 7.8 | T18: =IFERROR(S18/F18,"－") -> 2.7857143
C19: 人数（人） | D19: 0.91666667 | E19: 1 | F19: 1 | G19: 1 | H19: 1 | I19: 1 | J19: =IFERROR(SUM(G19:I19)/3/F19,"－") -> 1 | K19: 1 | L19: =IFERROR(K19/F19,"－") -> 1 | M19: 1 | N19: =IFERROR(M19/F19,"－") -> 1 | O19: 1 | P19: =IFERROR(O19/F19,"－") -> 1 | Q19: 1 | R19: =IFERROR(Q19/F19,"－") -> 1 | S19: 1 | T19: =IFERROR(S19/F19,"－") -> 1
B20: 介護予防訪問リハビリテーション | C20: 給付費（千円） | D20: 2263.051 | E20: 2212.932 | F20: 2246.6412 | G20: 3526 | H20: 3652 | I20: 3652 | J20: =IFERROR(SUM(G20:I20)/3/F20,"－") -> 1.6068431 | K20: 3652 | L20: =IFERROR(K20/F20,"－") -> 1.6255377 | M20: 3652 | N20: =IFERROR(M20/F20,"－") -> 1.6255377 | O20: 3652 | P20: =IFERROR(O20/F20,"－") -> 1.6255377 | Q20: 3652 | R20: =IFERROR(Q20/F20,"－") -> 1.6255377 | S20: 3652 | T20: =IFERROR(S20/F20,"－") -> 1.6255377
C21: 回数（回） | D21: 60.083333 | E21: 57.666667 | F21: 54.9 | G21: 84.8 | H21: 87.8 | I21: 87.8 | J21: =IFERROR(SUM(G21:I21)/3/F21,"－") -> 1.5810565 | K21: 87.8 | L21: =IFERROR(K21/F21,"－") -> 1.5992714 | M21: 87.8 | N21: =IFERROR(M21/F21,"－") -> 1.5992714 | O21: 87.8 | P21: =IFERROR(O21/F21,"－") -> 1.5992714 | Q21: 87.8 | R21: =IFERROR(Q21/F21,"－") -> 1.5992714 | S21: 87.8 | T21: =IFERROR(S21/F21,"－") -> 1.5992714
C22: 人数（人） | D22: 5 | E22: 5.25 | F22: 5 | G22: 5 | H22: 5 | I22: 5 | J22: =IFERROR(SUM(G22:I22)/3/F22,"－") -> 1 | K22: 5 | L22: =IFERROR(K22/F22,"－") -> 1 | M22: 5 | N22: =IFERROR(M22/F22,"－") -> 1 | O22: 5 | P22: =IFERROR(O22/F22,"－") -> 1 | Q22: 5 | R22: =IFERROR(Q22/F22,"－") -> 1 | S22: 5 | T22: =IFERROR(S22/F22,"－") -> 1
B23: 介護予防居宅療養管理指導 | C23: 給付費（千円） | D23: 0 | E23: 0 | F23: 0 | G23: 0 | H23: 0 | I23: 0 | J23: =IFERROR(SUM(G23:I23)/3/F23,"－") -> － | K23: 0 | L23: =IFERROR(K23/F23,"－") -> － | M23: 0 | N23: =IFERROR(M23/F23,"－") -> － | O23: 0 | P23: =IFERROR(O23/F23,"－") -> － | Q23: 0 | R23: =IFERROR(Q23/F23,"－") -> － | S23: 0 | T23: =IFERROR(S23/F23,"－") -> －
C24: 人数（人） | D24: 0 | E24: 0 | F24: 0 | G24: 0 | H24: 0 | I24: 0 | J24: =IFERROR(SUM(G24:I24)/3/F24,"－") -> － | K24: 0 | L24: =IFERROR(K24/F24,"－") -> － | M24: 0 | N24: =IFERROR(M24/F24,"－") -> － | O24: 0 | P24: =IFERROR(O24/F24,"－") -> － | Q24: 0 | R24: =IFERROR(Q24/F24,"－") -> － | S24: 0 | T24: =IFERROR(S24/F24,"－") -> －
B25: 未使用 | C25: 給付費（千円） | N25: =IFERROR(M25/F25,"－") -> － | P25: =IFERROR(O25/F25,"－") -> － | R25: =IFERROR(Q25/F25,"－") -> － | T25: =IFERROR(S25/F25,"－") -> －
C26: 人数（人） | N26: =IFERROR(M26/F26,"－") -> － | P26: =IFERROR(O26/F26,"－") -> － | R26: =IFERROR(Q26/F26,"－") -> － | T26: =IFERROR(S26/F26,"－") -> －
B27: 介護予防通所リハビリテーション | C27: 給付費（千円） | D27: 18826.216 | E27: 17070.292 | F27: 16909.284 | G27: 16674 | H27: 15614 | I27: 16144 | J27: =IFERROR(SUM(G27:I27)/3/F27,"－") -> 0.95474179 | K27: 16144 | L27: =IFERROR(K27/F27,"－") -> 0.95474179 | M27: 17500 | N27: =IFERROR(M27/F27,"－") -> 1.0349344 | O27: 18325 | P27: =IFERROR(O27/F27,"－") -> 1.0837242 | Q27: 17500 | R27: =IFERROR(Q27/F27,"－") -> 1.0349344 | S27: 15319 | T27: =IFERROR(S27/F27,"－") -> 0.90595202
C28: 人数（人） | D28: 37.5 | E28: 34.666667 | F28: 35 | G28: 35 | H28: 33 | I28: 34 | J28: =IFERROR(SUM(G28:I28)/3/F28,"－") -> 0.97142857 | K28: 34 | L28: =IFERROR(K28/F28,"－") -> 0.97142857 | M28: 37 | N28: =IFERROR(M28/F28,"－") -> 1.0571429 | O28: 39 | P28: =IFERROR(O28/F28,"－") -> 1.1142857 | Q28: 37 | R28: =IFERROR(Q28/F28,"－") -> 1.0571429 | S28: 32 | T28: =IFERROR(S28/F28,"－") -> 0.91428571
B29: 介護予防短期入所生活介護 | C29: 給付費（千円） | D29: 57.912 | E29: 37.6 | F29: 0 | G29: 0 | H29: 0 | I29: 0 | J29: =IFERROR(SUM(G29:I29)/3/F29,"－") -> － | K29: 0 | L29: =IFERROR(K29/F29,"－") -> － | M29: 0 | N29: =IFERROR(M29/F29,"－") -> － | O29: 0 | P29: =IFERROR(O29/F29,"－") -> － | Q29: 0 | R29: =IFERROR(Q29/F29,"－") -> － | S29: 0 | T29: =IFERROR(S29/F29,"－") -> －
C30: 日数（日） | D30: 0.75 | E30: 0.41666667 | F30: 0 | G30: 0 | H30: 0 | I30: 0 | J30: =IFERROR(SUM(G30:I30)/3/F30,"－") -> － | K30: 0 | L30: =IFERROR(K30/F30,"－") -> － | M30: 0 | N30: =IFERROR(M30/F30,"－") -> － | O30: 0 | P30: =IFERROR(O30/F30,"－") -> － | Q30: 0 | R30: =IFERROR(Q30/F30,"－") -> － | S30: 0 | T30: =IFERROR(S30/F30,"－") -> －
C31: 人数（人） | D31: 0.16666667 | E31: 0.083333333 | F31: 0 | G31: 0 | H31: 0 | I31: 0 | J31: =IFERROR(SUM(G31:I31)/3/F31,"－") -> － | K31: 0 | L31: =IFERROR(K31/F31,"－") -> － | M31: 0 | N31: =IFERROR(M31/F31,"－") -> － | O31: 0 | P31: =IFERROR(O31/F31,"－") -> － | Q31: 0 | R31: =IFERROR(Q31/F31,"－") -> － | S31: 0 | T31: =IFERROR(S31/F31,"－") -> －
B32: 介護予防短期入所療養介護（老健） | C32: 給付費（千円） | D32: 260.084 | E32: 44.84 | F32: 0 | G32: 0 | H32: 0 | I32: 0 | J32: =IFERROR(SUM(G32:I32)/3/F32,"－") -> － | K32: 0 | L32: =IFERROR(K32/F32,"－") -> － | M32: 0 | N32: =IFERROR(M32/F32,"－") -> － | O32: 0 | P32: =IFERROR(O32/F32,"－") -> － | Q32: 0 | R32: =IFERROR(Q32/F32,"－") -> － | S32: 0 | T32: =IFERROR(S32/F32,"－") -> －
C33: 日数（日） | D33: 1.9166667 | E33: 0.33333333 | F33: 0 | G33: 0 | H33: 0 | I33: 0 | J33: =IFERROR(SUM(G33:I33)/3/F33,"－") -> － | K33: 0 | L33: =IFERROR(K33/F33,"－") -> － | M33: 0 | N33: =IFERROR(M33/F33,"－") -> － | O33: 0 | P33: =IFERROR(O33/F33,"－") -> － | Q33: 0 | R33: =IFERROR(Q33/F33,"－") -> － | S33: 0 | T33: =IFERROR(S33/F33,"－") -> －
C34: 人数（人） | D34: 0.5 | E34: 0.083333333 | F34: 0 | G34: 0 | H34: 0 | I34: 0 | J34: =IFERROR(SUM(G34:I34)/3/F34,"－") -> － | K34: 0 | L34: =IFERROR(K34/F34,"－") -> － | M34: 0 | N34: =IFERROR(M34/F34,"－") -> － | O34: 0 | P34: =IFERROR(O34/F34,"－") -> － | Q34: 0 | R34: =IFERROR(Q34/F34,"－") -> － | S34: 0 | T34: =IFERROR(S34/F34,"－") -> －
B35: 介護予防短期入所療養介護（病院等） | C35: 給付費（千円） | D35: 0 | E35: 0 | F35: 0 | G35: 0 | H35: 0 | I35: 0 | J35: =IFERROR(SUM(G35:I35)/3/F35,"－") -> － | K35: 0 | L35: =IFERROR(K35/F35,"－") -> － | M35: 0 | N35: =IFERROR(M35/F35,"－") -> － | O35: 0 | P35: =IFERROR(O35/F35,"－") -> － | Q35: 0 | R35: =IFERROR(Q35/F35,"－") -> － | S35: 0 | T35: =IFERROR(S35/F35,"－") -> －
C36: 日数（日） | D36: 0 | E36: 0 | F36: 0 | G36: 0 | H36: 0 | I36: 0 | J36: =IFERROR(SUM(G36:I36)/3/F36,"－") -> － | K36: 0 | L36: =IFERROR(K36/F36,"－") -> － | M36: 0 | N36: =IFERROR(M36/F36,"－") -> － | O36: 0 | P36: =IFERROR(O36/F36,"－") -> － | Q36: 0 | R36: =IFERROR(Q36/F36,"－") -> － | S36: 0 | T36: =IFERROR(S36/F36,"－") -> －
C37: 人数（人） | D37: 0 | E37: 0 | F37: 0 | G37: 0 | H37: 0 | I37: 0 | J37: =IFERROR(SUM(G37:I37)/3/F37,"－") -> － | K37: 0 | L37: =IFERROR(K37/F37,"－") -> － | M37: 0 | N37: =IFERROR(M37/F37,"－") -> － | O37: 0 | P37: =IFERROR(O37/F37,"－") -> － | Q37: 0 | R37: =IFERROR(Q37/F37,"－") -> － | S37: 0 | T37: =IFERROR(S37/F37,"－") -> －
B38: 介護予防短期入所療養介護(介護医療院) | C38: 給付費（千円） | D38: 0 | E38: 0 | F38: 0 | G38: 0 | H38: 0 | I38: 0 | J38: =IFERROR(SUM(G38:I38)/3/F38,"－") -> － | K38: 0 | L38: =IFERROR(K38/F38,"－") -> － | M38: 0 | N38: =IFERROR(M38/F38,"－") -> － | O38: 0 | P38: =IFERROR(O38/F38,"－") -> － | Q38: 0 | R38: =IFERROR(Q38/F38,"－") -> － | S38: 0 | T38: =IFERROR(S38/F38,"－") -> －
C39: 日数（日） | D39: 0 | E39: 0 | F39: 0 | G39: 0 | H39: 0 | I39: 0 | J39: =IFERROR(SUM(G39:I39)/3/F39,"－") -> － | K39: 0 | L39: =IFERROR(K39/F39,"－") -> － | M39: 0 | N39: =IFERROR(M39/F39,"－") -> － | O39: 0 | P39: =IFERROR(O39/F39,"－") -> － | Q39: 0 | R39: =IFERROR(Q39/F39,"－") -> － | S39: 0 | T39: =IFERROR(S39/F39,"－") -> －
C40: 人数（人） | D40: 0 | E40: 0 | F40: 0 | G40: 0 | H40: 0 | I40: 0 | J40: =IFERROR(SUM(G40:I40)/3/F40,"－") -> － | K40: 0 | L40: =IFERROR(K40/F40,"－") -> － | M40: 0 | N40: =IFERROR(M40/F40,"－") -> － | O40: 0 | P40: =IFERROR(O40/F40,"－") -> － | Q40: 0 | R40: =IFERROR(Q40/F40,"－") -> － | S40: 0 | T40: =IFERROR(S40/F40,"－") -> －
B41: 介護予防福祉用具貸与 | C41: 給付費（千円） | D41: 2636.495 | E41: 3245.792 | F41: 3271.908 | G41: 4122 | H41: 4122 | I41: 4224 | J41: =IFERROR(SUM(G41:I41)/3/F41,"－") -> 1.2702069 | K41: 4224 | L41: =IFERROR(K41/F41,"－") -> 1.2909898 | M41: 4621 | N41: =IFERROR(M41/F41,"－") -> 1.4123258 | O41: 4824 | P41: =IFERROR(O41/F41,"－") -> 1.4743691 | Q41: 4575 | R41: =IFERROR(Q41/F41,"－") -> 1.3982667 | S41: 4076 | T41: =IFERROR(S41/F41,"－") -> 1.2457563
C42: 人数（人） | D42: 33.166667 | E42: 36.666667 | F42: 36 | G42: 46 | H42: 46 | I42: 47 | J42: =IFERROR(SUM(G42:I42)/3/F42,"－") -> 1.287037 | K42: 47 | L42: =IFERROR(K42/F42,"－") -> 1.3055556 | M42: 52 | N42: =IFERROR(M42/F42,"－") -> 1.4444444 | O42: 54 | P42: =IFERROR(O42/F42,"－") -> 1.5 | Q42: 51 | R42: =IFERROR(Q42/F42,"－") -> 1.4166667 | S42: 45 | T42: =IFERROR(S42/F42,"－") -> 1.25
...

Sheet 3_地域支援事業費
A1: （３）地域支援事業費
K3: 保険者名 | L3: =保険者名 -> 川崎町
K4: 保険者番号 | L4: =保険者番号 -> 04324
K5: 推計パターン名 | L5: =推計パターン名 -> R8
A7: １．介護予防・日常生活支援総合事業 | L7: 単位：円(括弧書きの数値を除く)
A8: サービス種別・項目 | B8: R6 | C8: R7 | D8: R8 | E8: R9 | F8: R10 | G8: R11 | H8: R12 | I8: R17 | J8: R22 | K8: R27 | L8: R32
A9: 訪問介護相当サービス | B9: 1010214 | C9: 1206361 | D9: 994930 | E9: 1045953 | F9: 1071464 | G9: 1096975 | H9: 947394 | I9: 878633 | J9: 813906 | K9: 735322 | L9: 657440
A10: (利用者数：人) | B10: 40 | C10: 45 | D10: 42 | E10: 44 | F10: 46 | G10: 47 | H10: 40 | I10: 37 | J10: 34 | K10: 31 | L10: 28
A11: 訪問型サービスA | B11: 0 | C11: 0 | D11: 0 | E11: 0 | F11: 0 | G11: 0 | H11: 0 | I11: 0 | J11: 0 | K11: 0 | L11: 0
A12: (利用者数：人) | B12: 0 | C12: 0 | D12: 0 | E12: 0 | F12: 0 | G12: 0 | H12: 0 | I12: 0 | J12: 0 | K12: 0 | L12: 0
A13: 訪問型サービスB | B13: 0 | C13: 0 | D13: 0 | E13: 0 | F13: 0 | G13: 0 | H13: 0 | I13: 0 | J13: 0 | K13: 0 | L13: 0
A14: 訪問型サービスC | B14: 0 | C14: 0 | D14: 0 | E14: 0 | F14: 0 | G14: 0 | H14: 0 | I14: 0 | J14: 0 | K14: 0 | L14: 0
A15: 訪問型サービスD | B15: 0 | C15: 0 | D15: 0 | E15: 0 | F15: 0 | G15: 0 | H15: 0 | I15: 0 | J15: 0 | K15: 0 | L15: 0
A16: 訪問型サービス(その他) | B16: 0 | C16: 0 | D16: 0 | E16: 0 | F16: 0 | G16: 0 | H16: 0 | I16: 0 | J16: 0 | K16: 0 | L16: 0
A17: 通所介護相当サービス | B17: 1650786 | C17: 1461639 | D17: 1405070 | E17: 1267702 | F17: 1199019 | G17: 1130335 | H17: 1337938 | I17: 1240831 | J17: 1149423 | K17: 1038444 | L17: 928456
A18: (利用者数：人) | B18: 66 | C18: 54 | D18: 60 | E18: 54 | F18: 51 | G18: 48 | H18: 57 | I18: 53 | J18: 49 | K18: 44 | L18: 40
A19: 通所型サービスA | B19: 0 | C19: 0 | D19: 0 | E19: 0 | F19: 0 | G19: 0 | H19: 0 | I19: 0 | J19: 0 | K19: 0 | L19: 0
A20: (利用者数：人) | B20: 0 | C20: 0 | D20: 0 | E20: 0 | F20: 0 | G20: 0 | H20: 0 | I20: 0 | J20: 0 | K20: 0 | L20: 0
... A34: 地域リハビリテーション活動支援事業 | B34: 0 | C34: 0 | D34: 0 | E34: 0 | F34: 0 | G34: 0 | H34: 0 | I34: 0 | J34: 0 | K34: 0 | L34: 0
A35: 介護予防・地域ささえあいサポート拠点事業 | E35: 0 | F35: 0 | G35: 0 | H35: 0 | I35: 0 | J35: 0 | K35: 0 | L35: 0
A37: ２．包括的支援事業（地域包括支援センターの運営）及び任意事業 | L37: 単位：円
A38: サービス種別・項目 | B38: R6 | C38: R7 | D38: R8 | E38: R9 | F38: R10 | G38: R11 | H38: R12 | I38: R17 | J38: R22 | K38: R27 | L38: R32
A39: 包括的支援事業(地域包括支援センターの運営) | B39: 24606798 | C39: 22439736 | D39: 28981000 | E39: 29716713 | F39: 31903814 | G39: 34090915 | H39: 28020009 | I39: 26400561 | J39: 25226016 | K39: 23481995 | L39: 22191776
A40: 任意事業 | B40: 4519729 | C40: 5886816 | D40: 7486000 | E40: 8930453 | F40: 10413588 | G40: 11896724 | H40: 7237769 | I40: 6819454 | J40: 6516061 | K40: 6065568 | L40: 5732295
A42: ３．包括的支援事業（社会保障充実分） | L42: 単位：円
A43: サービス種別・項目 | B43: R6 | C43: R7 | D43: R8 | E43: R9 | F43: R10 | G43: R11 | H43: R12 | I43: R17 | J43: R22 | K43: R27 | L43: R32
A44: 在宅医療・介護連携推進事業 | B44: 0 | C44: 195543 | D44: 192000 | E44: 321181 | F44: 417181 | G44: 513181 | H44: 192000 | I44: 192000 | J44: 192000 | K44: 192000 | L44: 192000
A45: 生活支援体制整備事業 | B45: 14640 | C45: 188970 | D45: 169000 | E45: 278563 | F45: 355743 | G45: 432923 | H45: 169000 | I45: 169000 | J45: 169000 | K45: 169000 | L45: 169000
A46: 認知症初期集中支援推進事業 | B46: 0 | C46: 0 | D46: 0 | E46: 0 | F46: 0 | G46: 0 | H46: 0 | I46: 0 | J46: 0 | K46: 0 | L46: 0
A47: 認知症地域支援・ケア向上事業 | B47: 0 | C47: 0 | D47: 0 | E47: 0 | F47: 0 | G47: 0 | H47: 0 | I47: 0 | J47: 0 | K47: 0 | L47: 0
A48: 認知症サポーター活動促進・地域づくり推進事業 | B48: 0 | C48: 0 | D48: 0 | E48: 0 | F48: 0 | G48: 0 | H48: 0 | I48: 0 | J48: 0 | K48: 0 | L48: 0
A49: 地域ケア会議推進事業 | B49: 0 | C49: 0 | D49: 0 | E49: 0 | F49: 0 | G49: 0 | H49: 0 | I49: 0 | J49: 0 | K49: 0 | L49: 0
A51: ４．特定地域居宅サービス等事業 | L51: 単位：円
A52: サービス種別・項目 | B52: R6 | C52: R7 | D52: R8 | E52: R9 | F52: R10 | G52: R11 | H52: R12 | I52: R17 | J52: R22 | K52: R27 | L52: R32
A53: 特定地域居宅サービス等事業 | E53: 0 | F53: 0 | G53: 0 | H53: 0 | I53: 0 | J53: 0 | K53: 0 | L53: 0
A55: ５．介護情報利活用事業 | L55: 単位：円
A56: サービス種別・項目 | B56: R6 | C56: R7 | D56: R8 | E56: R9 | F56: R10 | G56: R11 | H56: R12 | I56: R17 | J56: R22 | K56: R27 | L56: R32
A57: 介護情報利活用事業 | E57: 0 | F57: 0 | G57: 0 | H57: 0 | I57: 0 | J57: 0 | K57: 0 | L57: 0
A59: ６．地域支援事業費計 | L59: 単位：円
B60: R6 | C60: R7 | D60: R8 | E60: R9 | F60: R10 | G60: R11 | H60: R12 | I60: R17 | J60: R22 | K60: R27 | L60: R32
...

Sheet 4_施策反映の解説
A1: （４）施策反映の内容
K2: 出力日： | L2: ='1_推計値サマリ'!T2 -> 2026/09/11
I3: 保険者名 | K3: =保険者名 -> 川崎町
I4: 保険者番号 | K4: =保険者番号 -> 04324
I5: 推計パターン名 | K5: =推計パターン名 -> R8
A7: 施策反映の全体方針
A8: 出力後に入力
A9: １．自然体推計手法
A10: 認定者数の自然体推計手法 | B10: 性別／年齢５歳階級別／要介護度別に推計する ※初期値
A11: 介護サービス利用者数の自然体推計手法 | B11: サービス別／要介護度別に推計する ※初期値
A12: ２．要介護(支援)認定者数
A13: 推計に用いた認定率の伸び | B13: 当該市町村における令和６年度→令和７年度の伸び
B14: 認定者数の設定内容
A15: 認定者数
B17: 施策反映内容
A18: 認定者数
A19: ３．施設・居住系サービス利用者数
A20: 推計に用いた利用率の伸び | B20: 当該市町村における令和６年度→令和７年度の伸び
A21: 推計に用いた1人1月あたりの給付費の実績値 | B21: 令和7年度
B22: 給付費の設定内容
A23: 1人1月あたり給付費
B24: 利用者数の設定内容
A25: 施設・居住系サービス利用者数 | B25: 令和8年度実績が少ない為
B26: 施策反映内容
A27: （１）居宅サービス
A28: （２）地域密着型サービス
A29: （３）施設サービス
A30: ４．在宅サービス利用者数
A31: 推計に用いた利用率の伸び | B31: 当該市町村における令和６年度→令和７年度の伸び
A32: 推計に用いた1人1月あたり利用回（日）数の伸び | B32: 当該市町村における令和６年度→令和７年度の伸び
A33: 推計に用いた1人1月あたりの給付費の実績値 | B33: 令和8年度
B34: 利用者数の設定内容
A35: 在宅サービス利用者数 | B35: 令和8年度実績が少ない為
B36: 利用回(日)数の設定内容
A37: 在宅サービス利用回(日)数 | B37: 令和8年度実績が少ない為
B38: 給付費の設定内容
A39: 1人1月あたり給付費
B40: 施策反映内容
A41: 在宅サービス利用者数(利用率)
A42: 在宅サービス利用回(日)数
...

Sheet 5_保険料推計
A1: （５）第１号被保険者の保険料推計
P3: 保険者名 | Q3: =保険者名 -> 川崎町
P4: 保険者番号 | Q4: =保険者番号 -> 04324
P5: 推計パターン名 | Q5: =推計パターン名 -> R8
A7: １．９期保険料基準額
A8: 第９期保険料の基準額（月額） | F8: 6508.3306
A10: ２．保険料基準額の指標
F11: 第10期 | G11: 令和12年度 | H11: 令和17年度 | I11: 令和22年度 | J11: 令和27年度 | K11: 令和32年度
A12: 保険料基準額（月額） | F12: =F105/F106/F214/12 -> 7194.5697 | G12: =J105/J106/J214/12 -> 8273.0673 | H12: =K105/K106/K214/12 -> 8901.4153 | I12: =L105/L106/L214/12 -> 9184.5348 | J12: =M105/M106/M214/12 -> 9531.725 | K12: =N105/N106/N214/12 -> 10011.426
A13: 準備基金取崩額の影響額 | F13: =(F105+F15)/F106/F214/12-F12 -> 0 | G13: =(J105+G15)/J106/J214/12-G12 -> 0 | H13: =(K105+H15)/K106/K214/12-H12 -> 0 | I13: =(L105+I15)/L106/L214/12-I12 -> 0 | J13: =(M105+J15)/M106/M214/12-J12 -> 0 | K13: =(N105+K15)/N106/N214/12-K12 -> 0
B14: 準備基金の残高（前年度末の見込額） | F14: 0 | G14: 0 | H14: 0 | I14: 0 | J14: 0 | K14: 0
B15: 準備基金取崩額 | F15: 0 | G15: 0 | H15: 0 | I15: 0 | J15: 0 | K15: 0
B16: 準備基金取崩割合 | F16: =IF(F14=0,0, F15/F14) -> 0 | G16: =IF(G14=0,0,G15/G14) -> 0 | H16: =IF(H14=0,0,H15/H14) -> 0 | I16: =IF(I14=0,0,I15/I14) -> 0 | J16: =IF(J14=0,0,J15/J14) -> 0 | K16: =IF(K14=0,0,K15/K14) -> 0
A17: 財政安定化基金拠出金見込額の影響額 | F17: =F12-(F105-F18)/F106/F214/12 -> 0 | G17: =G12-(J105-G18)/J106/J214/12 -> 0 | H17: =H12-(K105-H18)/K106/K214/12 -> 0 | I17: =I12-(L105-I18)/L106/L214/12 -> 0 | J17: =J12-(M105-J18)/M106/M214/12 -> 0 | K17: =K12-(N105-K18)/N106/N214/12 -> 0
B18: 財政安定化基金拠出金見込額 | F18: =(F68+F86)*F19 -> 0 | G18: =(J68+J86)*G19 -> 0 | H18: =(K68+K86)*H19 -> 0 | I18: =(L68+L86)*I19 -> 0 | J18: =(M68+M86)*J19 -> 0 | K18: =(N68+N86)*K19 -> 0
B19: 財政安定化基金拠出率 | F19: 0 | G19: 0 | H19: 0 | I19: 0 | J19: 0 | K19: 0
A20: 財政安定化基金償還金の影響額 | F20: =F12-(F105-F21)/F106/F214/12 -> 0 | G20: =G12-(J105-G21)/J106/J214/12 -> 0 | H20: =H12-(K105-H21)/K106/K214/12 -> 0 | I20: =I12-(L105-I21)/L106/L214/12 -> 0 | J20: =J12-(M105-J21)/M106/M214/12 -> 0 | K20: =K12-(N105-K21)/N106/N214/12 -> 0
B21: 財政安定化基金償還金 | F21: 0 | G21: 0 | H21: 0 | I21: 0 | J21: 0 | K21: 0
A22: 保険料基準額の伸び率（％） （対９期保険料） | F22: =F12/$F$8-1 -> 0.10544012 | G22: =G12/ROUND($F$8,0)-1 -> 0.27121502 | H22: =H12/ROUND($F$8,0)-1 -> 0.3677651 | I22: =I12/ROUND($F$8,0)-1 -> 0.41126841 | J22: =J12/ROUND($F$8,0)-1 -> 0.46461662 | K22: =K12/ROUND($F$8,0)-1 -> 0.53832601
A24: ３．保険料設定を弾力化した場合の保険料額の指標
F25: 第10期 | G25: 令和12年度 | H25: 令和17年度 | I25: 令和22年度 | J25: 令和27年度 | K25: 令和32年度
A26: 保険料基準額（月額） | F26: =IFERROR(F105/F106/F215/12,"－") -> － | G26: =IFERROR(J105/J106/J215/12,"－") -> － | H26: =IFERROR(K105/K106/K215/12,"－") -> － | I26: =IFERROR(L105/L106/L215/12,"－") -> － | J26: =IFERROR(M105/M106/M215/12,"－") -> － | K26: =IFERROR(N105/N106/N215/12,"－") -> －
A27: 準備基金取崩額の影響額 | F27: =IFERROR((F105+F29)/F106/F215/12-F26,"－") -> － | G27: =IFERROR((J105+G29)/J106/J215/12-G26,"－") -> － | H27: =IFERROR((K105+H29)/K106/K215/12-H26,"－") -> － | I27: =IFERROR((L105+I29)/L106/L215/12-I26,"－") -> － | J27: =IFERROR((M105+J29)/M106/M215/12-J26,"－") -> － | K27: =IFERROR((N105+K29)/N106/N215/12-K26,"－") -> －
B28: 準備基金の残高（前年度末の見込額） | F28: =IF(F26="－","－",F14) -> － | G28: =IF(G26="－","－",G14) -> － | H28: =IF(H26="－","－",H14) -> － | I28: =IF(I26="－","－",I14) -> － | J28: =IF(J26="－","－",J14) -> － | K28: =IF(K26="－","－",K14) -> －
B29: 準備基金取崩額 | F29: =IF(F26="－","－",F15) -> － | G29: =IF(G26="－","－",G15) -> － | H29: =IF(H26="－","－",H15) -> － | I29: =IF(I26="－","－",I15) -> － | J29: =IF(J26="－","－",J15) -> － | K29: =IF(K26="－","－",K15) -> －
B30: 準備基金取崩割合 | F30: =IFERROR(F29/F28,"－") -> － | G30: =IFERROR(G29/G28,"－") -> － | H30: =IFERROR(H29/H28,"－") -> － | I30: =IFERROR(I29/I28,"－") -> － | J30: =IFERROR(J29/J28,"－") -> － | K30: =IFERROR(K29/K28,"－") -> －
A31: 財政安定化基金拠出金見込額の影響額 | F31: =IFERROR(F26-(F105-F32)/F106/F215/12,"－") -> － | G31: =IFERROR(G26-(J105-G32)/J106/J215/12,"－") -> － | H31: =IFERROR(H26-(K105-H32)/K106/K215/12,"－") -> － | I31: =IFERROR(I26-(L105-I32)/L106/L215/12,"－") -> － | J31: =IFERROR(J26-(M105-J32)/M106/M215/12,"－") -> － | K31: =IFERROR(K26-(N105-K32)/N106/N215/12,"－") -> －
B32: 財政安定化基金拠出金見込額 | F32: =IF(F26="－","－",(F68+F86)*F33) -> － | G32: =IF(G26="－","－",(J68+J86)*G33) -> － | H32: =IF(H26="－","－",(K68+K86)*H33) -> － | I32: =IF(I26="－","－",(L68+L86)*I33) -> － | J32: =IF(J26="－","－",(M68+M86)*J33) -> － | K32: =IF(K26="－","－",(N68+N86)*K33) -> －
B33: 財政安定化基金拠出率 | F33: =IF(F26="－","－",F19) -> － | G33: =IF(G26="－","－",G19) -> － | H33: =IF(H26="－","－",H19) -> － | I33: =IF(I26="－","－",I19) -> － | J33: =IF(J26="－","－",J19) -> － | K33: =IF(K26="－","－",K19) -> －
A34: 財政安定化基金償還金の影響額 | F34: =IFERROR(F26-(F105-F35)/F106/F215/12,"－") -> － | G34: =IFERROR(G26-(J105-G35)/J106/J215/12,"－") -> － | H34: =IFERROR(H26-(K105-H35)/K106/K215/12,"－") -> － | I34: =IFERROR(I26-(L105-I35)/L106/L215/12,"－") -> － | J34: =IFERROR(J26-(M105-J35)/M106/M215/12,"－") -> － | K34: =IFERROR(K26-(N105-K35)/N106/N215/12,"－") -> －
B35: 財政安定化基金償還金 | F35: =IF(F26="－","－",F21) -> － | G35: =IF(G26="－","－",G21) -> － | H35: =IF(H26="－","－",H21) -> － | I35: =IF(I26="－","－",I21) -> － | J35: =IF(J26="－","－",J21) -> － | K35: =IF(K26="－","－",K21) -> －
A36: 保険料基準額の伸び率（％） （対９期保険料） | F36: =IFERROR(F26/$F$8-1,"－") -> － | G36: =IFERROR(G26/ROUND($F$8,0)-1,"－") -> － | H36: =IFERROR(H26/ROUND($F$8,0)-1,"－") -> － | I36: =IFERROR(I26/ROUND($F$8,0)-1,"－") -> － | J36: =IFERROR(J26/ROUND($F$8,0)-1,"－") -> － | K36: =IFERROR(K26/ROUND($F$8,0)-1,"－") -> －
A38: ４ 介護保険料基準額（月額）の内訳
F39: 金額 | L39: 構成比
F40: 第10期 | G40: 令和12年度 | H40: 令和17年度 | I40: 令和22年度 | J40: 令和27年度 | K40: 令和32年度 | L40: 第10期 | M40: 令和12年度 | N40: 令和17年度 | O40: 令和22年度 | P40: 令和27年度 | Q40: 令和32年度
A41: 総給付費 | F41: =(F69*'(参考)保険料の推計に要する係数'!D5+(F93-F94))/(F214*F106*12) -> 6328.7322 | G41: =(J69*'(参考)保険料の推計に要する係数'!E5+(J93-J94))/(J214*J106*12) -> 7380.3768 | H41: =(K69*'(参考)保険料の推計に要する係数'!F5+(K93-K94))/(K214*K106*12) -> 7862.602 | I41: =(L69*'(参考)保険料の推計に要する係数'!G5+(L93-L94))/(L214*L106*12) -> 8001.6855 | J41: =(M69*'(参考)保険料の推計に要する係数'!H5+(M93-M94))/(M214*M106*12) -> 8262.8728 | K41: =(N69*'(参考)保険料の推計に要する係数'!I5+(N93-N94))/(N214*N106*12) -> 8762.9251 | L41: =F41/$F$49 -> 0.87965402 | M41: =G41/$G$49 -> 0.89209678 | N41: =H41/$H$49 -> 0.88329796 | O41: =I41/$I$49 -> 0.87121293 | P41: =J41/$J$49 -> 0.86688116 | Q41: =K41/$K$49 -> 0.87529242
B42: 在宅サービス | F42: =$F$41*SUM('2_サービス別給付費'!G151:I151)/SUM('2_サービス別給付費'!$G$150:$I$150) -> 2107.1912 | G42: =$G$41*SUM('2_サービス別給付費'!J151)/SUM('2_サービス別給付費'!$J$150) -> 2269.4172 | H42: =$H$41*SUM('2_サービス別給付費'!K151)/SUM('2_サービス別給付費'!$K$150) -> 2484.1202 | I42: =$I$41*SUM('2_サービス別給付費'!L151)/SUM('2_サービス別給付費'!$L$150) -> 2451.3129 | J42: =$J$41*SUM('2_サービス別給付費'!M151)/SUM('2_サービス別給付費'!$M$150) -> 2498.9454 | K42: =$K$41*SUM('2_サービス別給付費'!N151)/SUM('2_サービス別給付費'!$N$150) -> 2649.7646 | L42: =F42/$F$49 -> 0.29288633 | M42: =G42/$G$49 -> 0.27431388 | N42: =H42/$H$49 -> 0.27907025 | O42: =I42/$I$49 -> 0.26689571 | P42: =J42/$J$49 -> 0.26217137 | Q42: =K42/$K$49 -> 0.26467405
B43: 居住系サービス | F43: =$F$41*SUM('2_サービス別給付費'!G152:I152)/SUM('2_サービス別給付費'!$G$150:$I$150) -> 579.85888 | G43: =$G$41*SUM('2_サービス別給付費'!J152)/SUM('2_サービス別給付費'!$J$150) -> 667.24418 | H43: =$H$41*SUM('2_サービス別給付費'!K152)/SUM('2_サービス別給付費'!$K$150) -> 725.38139 | I43: =$I$41*SUM('2_サービス別給付費'!L152)/SUM('2_サービス別給付費'!$L$150) -> 696.59959 | J43: =$J$41*SUM('2_サービス別給付費'!M152)/SUM('2_サービス別給付費'!$M$150) -> 706.4479 | K43: =$K$41*SUM('2_サービス別給付費'!N152)/SUM('2_サービス別給付費'!$N$150) -> 714.8283 | L43: =F43/$F$49 -> 0.080596742 | M43: =G43/$G$49 -> 0.080652575 | N43: =H43/$H$49 -> 0.081490568 | O43: =I43/$I$49 -> 0.075844842 | P43: =J43/$J$49 -> 0.07411543 | Q43: =K43/$K$49 -> 0.071401249
B44: 施設サービス | F44: =$F$41*SUM('2_サービス別給付費'!G153:I153)/SUM('2_サービス別給付費'!$G$150:$I$150) -> 3641.6821 | G44: =$G$41*SUM('2_サービス別給付費'!J153)/SUM('2_サービス別給付費'!$J$150) -> 4443.7154 | H44: =$H$41*SUM('2_サービス別給付費'!K153)/SUM('2_サービス別給付費'!$K$150) -> 4653.1004 | I44: =$I$41*SUM('2_サービス別給付費'!L153)/SUM('2_サービス別給付費'!$L$150) -> 4853.773 | J44: =$J$41*SUM('2_サービス別給付費'!M153)/SUM('2_サービス別給付費'!$M$150) -> 5057.4795 | K44: =$K$41*SUM('2_サービス別給付費'!N153)/SUM('2_サービス別給付費'!$N$150) -> 5398.3322 | L44: =F44/$F$49 -> 0.50617094 | M44: =G44/$G$49 -> 0.53713033 | N44: =H44/$H$49 -> 0.52273714 | O44: =I44/$I$49 -> 0.52847238 | P44: =J44/$J$49 -> 0.53059436 | Q44: =K44/$K$49 -> 0.53921713
A45: その他給付費 | F45: =((F75+F78+F81+F82)*'(参考)保険料の推計に要する係数'!D5+F85)/(F214*F106*12) -> 554.06722 | G45: =((J75+J78+J81+J82)*'(参考)保険料の推計に要する係数'!E5+J85)/(J214*J106*12) -> 597.70882 | H45: =((K75+K78+K81+K82)*'(参考)保険料の推計に要する係数'!F5+K85)/(K214*K106*12) -> 726.44815 | I45: =((L75+L78+L81+L82)*'(参考)保険料の推計に要する係数'!G5+L85)/(L214*L106*12) -> 857.05442 | J45: =((M75+M78+M81+M82)*'(参考)保険料の推計に要する係数'!H5+M85)/(M214*M106*12) -> 930.47814 | K45: =((N75+N78+N81+N82)*'(参考)保険料の推計に要する係数'!I5+N85)/(N214*N106*12) -> 898.86365 | L45: =F45/$F$49 -> 0.077011863 | M45: =G45/$G$49 -> 0.072247547 | N45: =H45/$H$49 -> 0.08161041 | O45: =I45/$I$49 -> 0.093314951 | P45: =J45/$J$49 -> 0.097619072 | Q45: =K45/$K$49 -> 0.089783781
...

Sheet (参考)保険料の推計に要する係数
B1: (参考)保険料の推計に要する係数
D4: R9～R11 | E4: R12 | F4: R17 | G4: R22 | H4: R27 | I4: R32
C5: 第１号被保険者負担割合（%） | D5: 0.23 | E5: 0.24 | F5: 0.25 | G5: 0.26 | H5: 0.27 | I5: 0.28
B7: 後期高齢者加入割合補正係数の算出に係る係数（全国値） （仮置値）
D8: R9 | E8: R10 | F8: R11 | G8: R12 | H8: R17 | I8: R22 | J8: R27 | K8: R32
C9: 前期高齢者加入割合 | D9: 0.4312 | E9: 0.4166 | F9: 0.4076 | G9: 0.3946 | H9: 0.4156 | I9: 0.4449 | J9: 0.4377 | K9: 0.4062
C10: 85歳未満後期高齢者加入割合 | D10: 0.3825 | E10: 0.3924 | F10: 0.3951 | G10: 0.3898 | H10: 0.333 | I10: 0.3103 | J10: 0.3328 | K10: 0.3669
C11: 85歳以上後期高齢者加入割合 | D11: 0.1863 | E11: 0.191 | F11: 0.1973 | G11: 0.2157 | H11: 0.2513 | I11: 0.2448 | J11: 0.2295 | K11: 0.227
C12: 前期高齢者の1人あたり給付費 | D12: 4296 | E12: 4296 | F12: 4296 | G12: 4296 | H12: 4296 | I12: 4296 | J12: 4296 | K12: 4296
C13: 85歳未満後期高齢者の1人あたり給付費 | D13: 17647 | E13: 17647 | F13: 17647 | G13: 17647 | H13: 17647 | I13: 17647 | J13: 17647 | K13: 17647
C14: 85歳以上後期高齢者の1人あたり給付費 | D14: 80362 | E14: 80362 | F14: 80362 | G14: 80362 | H14: 80362 | I14: 80362 | J14: 80362 | K14: 80362
B16: 所得段階別加入割合補正係数の算出に係る係数（全国値）（％） （仮置値）
C17: 第1段階 | D17: 0.1749
C18: 第2段階 | D18: 0.0967
C19: 第3段階 | D19: 0.0864
C20: 第4段階 | D20: 0.1074
C21: 第5段階 | D21: 0.1405
C22: 第6段階 | D22: 0.1333
C23: 第7段階 | D23: 0.1361
C24: 第8段階 | D24: 0.061
C25: 第9段階 | D25: 0.0241
C26: 第10段階 | D26: 0.0115
C27: 第11段階 | D27: 0.0061
C28: 第12段階 | D28: 0.0039
C29: 第13段階 | D29: 0.0181
B33: 費用負担の見直しに伴う調整に係る係数（参考値）（未定）
C34: 利用者負担の見直し等に伴う財政影響補正係数 | D34: 1
C35: 特定入所者介護サービス費等に係る制度改正に伴う財政影響補正係数 | D35: 1
C38: 国庫負担金等の算定の基準となる算定対象審査支払手数料単価（上限）（円） | D38: 95
