Workbook

Sheet 00_前提・検証
A1: 項目 | B1: 値 | C1: 単位 | D1: 内容 | F1: Red Team検証 | G1: 結果 | H1: 対象範囲 | I1: 判定式 | J1: 備考
A2: 資産維持費対象資産 | B2: 16455364 | C2: 千円 | D2: R7末償却対象資産相当。資産維持費=対象資産×率。 | F2: 資産維持費込料金回収率の大小 | G2: 03_SIM比較!I4:I11 | H2: 全SIM | I2: 資産維持費込 <= 通常 | J2: 全てOKであればロジック整合
A3: 料金改定開始年度 | B3: 令和11年度 | D3: SIMではR11以降に料金改定率を適用。
A4: 算定期間開始 | B4: 令和11年度 | D4: 料金改定率はR11〜R15の5か年で総括原価を回収する水準。
A5: 算定期間終了 | B5: 令和15年度 | D5: 総括原価=営業費用+営業外費用-長期前受金戻入-その他営業収益-繰入金・負担金等+資産維持費。
A6: R7末現預金（推計開始残高） | B6: 242588 | C6: 千円 | D6: R7末現金預金を推計開始残高として使用。
A7: 最低現金目安 | B7: 300000 | C7: 千円 | D7: 便宜的な資金安全ライン。
A8: 検証ルール | B8: 資産維持費込料金回収率 <= 料金回収率 | D8: 同一分子で分母に資産維持費を加算するため。
A9: 主な修正点 | B9: 資産維持費込料金回収率の分母修正 | D9: 分子は改定後給水収益、分母は通常給水原価対象費用＋資産維持費。
A10: R8予算反映 | B10: R8収入・資本的収入はR8当初予算書を採用。投資は将来年次計画の調整後事業費計を採用。
A11: Red Team確認 | B11: 資産維持費込料金回収率が通常料金回収率を上回らないこと、R8予算値が04シートと一致することを確認。
A12: 営業費用の修正 | B12: 修繕・動力・薬品・委託・資産減耗・その他営業費用は物件費の内数（993作成資料）。従来SIMは約512百万円/年を二重計上しており、必要改定率が約44ポイント過大だった。本版で解消。
A13: 追加精緻化項目 | B13: 値 | C13: 単位 | D13: 内容
A14: 建設仮勘定対象事業合計 | B14: =05_建設仮勘定・企業債!B27 -> 465568277 | C14: 円 | D14: 05_建設仮勘定・企業債で算定
A15: 長期前受金等合計 | B15: =05_建設仮勘定・企業債!B28 -> 346184893 | C15: 円 | D15: 工事負担金・県補償金等
A16: 令和10年度以降 年額減価償却費 | B16: =05_建設仮勘定・企業債!E40 -> 11639 | C16: 千円 | D16: 40年定額、千円丸め
A17: 令和10年度以降 年額長期前受金戻入 | B17: =05_建設仮勘定・企業債!E41 -> 8655 | C17: 千円 | D17: 40年定額、千円丸め
A18: 追加企業債対象額 | B18: =05_建設仮勘定・企業債!B29 -> 119383384 | C18: 円 | D18: 国費・負担金等控除後の純額
A19: 利率の扱い | B19: 区分別入力 | D19: 一律3%固定ではなく、05シートG27:G28で区分別に置換可能
A20: 企業債充当率100% | B20: R8〜R16企業債＝建設改良費−国庫補助金−工事負担金。R9に過年度建設仮勘定純額12,066千円を追加借入。利率3%・40年元金均等・翌年度償還開始（Δモデル、02シート55〜59行）。
A21: 補填財源残高 | B21: R7末183,463千円（0708修正版補てん財源経過表）を起点にSIM72行目で簡便推計。現預金残高（59行）と区分表示。
A22: 建設仮勘定統合 | B22: R10以降の減価償却費+11,639千円・長期前受金戻入+8,655千円を02シート本体へ統合。総括原価・必要改定率へ反映済み。

Sheet 01_ビジョン原計画
A1: ビジョン上の投資財政計画（R7〜R16）
A2: 収益・費用・4条収入は見直後財政計画を基礎。建設改良費はビジョン/既存計画の額を使用。単位：千円。 【修正】修繕費・動力費・薬品費・委託料・資産減耗費・その他営業費用は993作成資料上「物件費」の内数のため、営業費用の合計から除外（従来は二重計上）。R8予算年度のみ資産減耗費12,000を別掲加算。
A3: 区分 | B3: 令和7年度 | C3: 令和8年度 | D3: 令和9年度 | E3: 令和10年度 | F3: 令和11年度 | G3: 令和12年度 | H3: 令和13年度 | I3: 令和14年度 | J3: 令和15年度 | K3: 令和16年度
A4: 【収益的収入】
A5: 水道事業収益 | B5: =SUM(B6,B9,B14) -> 1619060 | C5: =SUM(C6,C9,C14) -> 1604473 | D5: =SUM(D6,D9,D14) -> 1586060 | E5: =SUM(E6,E9,E14) -> 1568503 | F5: =SUM(F6,F9,F14) -> 1550232 | G5: =SUM(G6,G9,G14) -> 1544775 | H5: =SUM(H6,H9,H14) -> 1532660 | I5: =SUM(I6,I9,I14) -> 1511152 | ... K5: =SUM(K6,K9,K14) -> 1463657
A6: 営業収益 | B6: =SUM(B7:B8) -> 1261575 | C6: =SUM(C7:C8) -> 1249336 | D6: =SUM(D7:D8) -> 1237293 | E6: =SUM(E7:E8) -> 1225373 | F6: =SUM(F7:F8) -> 1213574 | G6: =SUM(G7:G8) -> 1201896 | H6: =SUM(H7:H8) -> 1190336 | I6: =SUM(I7:I8) -> 1178894 | ... K6: =SUM(K7:K8) -> 1156360
A7: 給水収益 | B7: 1231181 | C7: 1218869 | D7: 1206680 | E7: 1194613 | F7: 1182666 | G7: 1170839 | H7: 1159130 | I7: 1147538 | J7: 1136062 | K7: 1124701
A8: その他営業収益 | B8: 30394 | C8: 30467 | D8: 30613 | E8: 30760 | F8: 30908 | G8: 31057 | H8: 31206 | I8: 31356 | J8: 31507 | K8: 31659
A9: 営業外収益 | B9: =SUM(B10:B13) -> 354909 | C9: =SUM(C10:C13) -> 355137 | D9: =SUM(D10:D13) -> 348767 | E9: =SUM(E10:E13) -> 343130 | F9: =SUM(F10:F13) -> 336658 | G9: =SUM(G10:G13) -> 342879 | H9: =SUM(H10:H13) -> 342324 | I9: =SUM(I10:I13) -> 332258 | ... K9: =SUM(K10:K13) -> 307297
A10: 受取利息 | B10: 1 | C10: 1 | D10: 0 | E10: 0 | F10: 0 | G10: 0 | H10: 0 | I10: 0 | J10: 0 | K10: 0
A11: 繰入金・負担金等 | B11: 73283 | C11: 71157 | D11: 68955 | E11: 66740 | F11: 64490 | G11: 62175 | H11: 59946 | I11: 57892 | J11: 56062 | K11: 54385
A12: 長期前受金戻入 | B12: 281625 | C12: 283979 | D12: 279812 | E12: 276390 | F12: 272168 | G12: 272926 | H12: 274600 | I12: 266588 | J12: 250287 | K12: 245134
A13: その他営業外収益 | B13: 0 | C13: 0 | D13: 0 | E13: 0 | F13: 0 | G13: 7778 | H13: 7778 | I13: 7778 | J13: 7778 | K13: 7778
A14: 特別利益 | B14: 2576 | C14: 0 | D14: 0 | E14: 0 | F14: 0 | G14: 0 | H14: 0 | I14: 0 | J14: 0 | K14: 0
A16: 【収益的支出】
A17: 水道事業費用 | B17: =SUM(B18,B28,B31) -> 1608275 | C17: =SUM(C18,C28,C31) -> 1597336 | D17: =SUM(D18,D28,D31) -> 1591913 | E17: =SUM(E18,E28,E31) -> 1586945 | F17: =SUM(F18,F28,F31) -> 1585772 | G17: =SUM(G18,G28,G31) -> 1588017 | H17: =SUM(H18,H28,H31) -> 1595258 | I17: =SUM(I18,I28,I31) -> 1591786 | ... K17: =SUM(K18,K28,K31) -> 1575072
A18: 営業費用 | B18: =SUM(B19,B20,B25,B26,B27) -> 1479507 | C18: =SUM(C19,C20,C25,C26,C27) -> 1476545 | D18: =SUM(D19,D20,D25,D26,D27) -> 1474501 | E18: =SUM(E19,E20,E25,E26,E27) -> 1471288 | F18: =SUM(F19,F20,F25,F26,F27) -> 1471712 | G18: =SUM(G19,G20,G25,G26,G27) -> 1476923 | H18: =SUM(H19,H20,H25,H26,H27) -> 1486420 | I18: =SUM(I19,I20,I25,I26,I27) -> 1484101 | ... K18: =SUM(K19,K20,K25,K26,K27) -> 1469682
A19: 人件費 | B19: 176462 | C19: 176462 | D19: 176462 | E19: 176462 | F19: 176462 | G19: 176462 | H19: 176462 | I19: 176462 | J19: 176462 | K19: 176462
A20: 物件費 | B20: 547263 | C20: 545340 | D20: 545648 | E20: 545957 | F20: 546267 | G20: 546577 | H20: 546888 | I20: 547200 | J20: 547513 | K20: 547827
A21: 修繕費（物件費の内数・参考） | B21: 65247 | C21: 65000 | D21: 65000 | E21: 65000 | F21: 65000 | G21: 65000 | H21: 65000 | I21: 65000 | J21: 65000 | K21: 65000
A22: 動力費（物件費の内数・参考） | B22: 102261 | C22: 102568 | D22: 102876 | E22: 103185 | F22: 103495 | G22: 103805 | H22: 104116 | I22: 104428 | J22: 104741 | K22: 105055
A23: 薬品費（物件費の内数・参考） | B23: 15316 | C23: 15000 | D23: 15000 | E23: 15000 | F23: 15000 | G23: 15000 | H23: 15000 | I23: 15000 | J23: 15000 | K23: 15000
A24: 委託料（物件費の内数・参考） | B24: 304419 | C24: 304000 | D24: 304000 | E24: 304000 | F24: 304000 | G24: 304000 | H24: 304000 | I24: 304000 | J24: 304000 | K24: 304000
A25: 減価償却費 | B25: 755782 | C25: 754743 | D25: 752391 | E25: 748869 | F25: 748983 | G25: 753884 | H25: 763070 | I25: 760439 | J25: 744482 | K25: 745393
A26: 資産減耗・除却費（R8予算のみ別掲、他年度は物件費内数のため0） | B26: 0 | C26: 0 | D26: 0 | E26: 0 | F26: 0 | G26: 0 | H26: 0 | I26: 0 | J26: 0 | K26: 0
A27: その他営業費用（物件費内数のため0） | B27: 0 | C27: 0 | D27: 0 | E27: 0 | F27: 0 | G27: 0 | H27: 0 | I27: 0 | J27: 0 | K27: 0
A28: 営業外費用 | B28: =SUM(B29:B30) -> 128495 | C28: =SUM(C29:C30) -> 120518 | D28: =SUM(D29:D30) -> 117139 | E28: =SUM(E29:E30) -> 115384 | F28: =SUM(F29:F30) -> 113787 | G28: =SUM(G29:G30) -> 110821 | H28: =SUM(H29:H30) -> 108565 | I28: =SUM(I29:I30) -> 107412 | ... K28: =SUM(K29:K30) -> 105117
A29: 支払利息 | B29: 118910 | C29: 111872 | D29: 108458 | E29: 106668 | F29: 105071 | G29: 102070 | H29: 99779 | I29: 98626 | J29: 98322 | K29: 96331
A30: 雑支出 | B30: 9585 | C30: 8646 | D30: 8681 | E30: 8716 | F30: 8716 | G30: 8751 | H30: 8786 | I30: 8786 | J30: 8786 | K30: 8786
A31: 特別損失 | B31: 273 | C31: 273 | D31: 273 | E31: 273 | F31: 273 | G31: 273 | H31: 273 | I31: 273 | J31: 273 | K31: 273
A33: 【資本的収入】
A34: 資本的収入 | B34: 698941 | C34: 664331 | D34: 636408 | E34: 715698 | F34: 627649 | G34: 570213 | H34: 571338 | I34: 536592 | J34: 406734 | K34: 365000
A35: 企業債 | B35: 329000 | C35: 435000 | D35: 399000 | E35: 400000 | F35: 232000 | G35: 283000 | H35: 286000 | I35: 368000 | J35: 251000 | K35: 230000
A36: 一般会計負担金 | B36: 169041 | C36: 164831 | D36: 162408 | E36: 167998 | F36: 173649 | G36: 182213 | H36: 180338 | I36: 168592 | J36: 155734 | K36: 135000
A37: 一般会計出資金 | B37: 0 | C37: 0 | D37: 0 | E37: 0 | F37: 0 | G37: 0 | H37: 0 | I37: 0 | J37: 0 | K37: 0
A38: 国庫補助金 | B38: 0 | C38: 64500 | D38: 75000 | E38: 147700 | F38: 222000 | G38: 105000 | H38: 105000 | I38: 0 | J38: 0 | K38: 0
A39: 固定資産売却代金 | B39: 0 | C39: 0 | D39: 0 | E39: 0 | F39: 0 | G39: 0 | H39: 0 | I39: 0 | J39: 0 | K39: 0
A40: 工事負担金 | B40: 200900 | C40: 0 | D40: 0 | E40: 0 | F40: 0 | G40: 0 | H40: 0 | I40: 0 | J40: 0 | K40: 0
A41: その他・調整 | B41: =B34-SUM(B35:B40) -> 0 | C41: =C34-SUM(C35:C40) -> 0 | D41: =D34-SUM(D35:D40) -> 0 | E41: =E34-SUM(E35:E40) -> 0 | F41: =F34-SUM(F35:F40) -> 0 | G41: =G34-SUM(G35:G40) -> 0 | H41: =H34-SUM(H35:H40) -> 0 | I41: =I34-SUM(I35:I40) -> 0 | ... K41: =K34-SUM(K35:K40) -> 0
A43: 【資本的支出】
...

Sheet 02_将来年次投資置換
A1: 将来年次計画の投資に置換した投資財政計画（R7〜R16）
A2: 収益・費用・4条収入は見直後財政計画を基礎。建設改良費のみ将来年次計画2025.12.2（2026.3.1シート）の調整後事業費へ置換。単位：千円。 【修正】修繕費・動力費・薬品費・委託料・資産減耗費・その他営業費用は993作成資料上「物件費」の内数のため、営業費用の合計から除外（従来は二重計上）。R8予算年度のみ資産減耗費12,000を別掲加算。
A3: 区分 | B3: 令和7年度 | C3: 令和8年度 | D3: 令和9年度 | E3: 令和10年度 | F3: 令和11年度 | G3: 令和12年度 | H3: 令和13年度 | I3: 令和14年度 | J3: 令和15年度 | K3: 令和16年度
A4: 【収益的収入】
A5: 水道事業収益 | B5: =SUM(B6,B9,B14) -> 1619060 | C5: =SUM(C6,C9,C14) -> 1604473 | D5: =SUM(D6,D9,D14) -> 1586060 | E5: =SUM(E6,E9,E14) -> 1568503 | F5: =SUM(F6,F9,F14) -> 1550232 | G5: =SUM(G6,G9,G14) -> 1544775 | H5: =SUM(H6,H9,H14) -> 1532660 | I5: =SUM(I6,I9,I14) -> 1511152 | ... K5: =SUM(K6,K9,K14) -> 1463657
A6: 営業収益 | B6: =SUM(B7:B8) -> 1261575 | C6: =SUM(C7:C8) -> 1249336 | D6: =SUM(D7:D8) -> 1237293 | E6: =SUM(E7:E8) -> 1225373 | F6: =SUM(F7:F8) -> 1213574 | G6: =SUM(G7:G8) -> 1201896 | H6: =SUM(H7:H8) -> 1190336 | I6: =SUM(I7:I8) -> 1178894 | ... K6: =SUM(K7:K8) -> 1156360
A7: 給水収益 | B7: 1231181 | C7: 1218869 | D7: 1206680 | E7: 1194613 | F7: 1182666 | G7: 1170839 | H7: 1159130 | I7: 1147538 | J7: 1136062 | K7: 1124701
A8: その他営業収益 | B8: 30394 | C8: 30467 | D8: 30613 | E8: 30760 | F8: 30908 | G8: 31057 | H8: 31206 | I8: 31356 | J8: 31507 | K8: 31659
A9: 営業外収益 | B9: =SUM(B10:B13) -> 354909 | C9: =SUM(C10:C13) -> 355137 | D9: =SUM(D10:D13) -> 348767 | E9: =SUM(E10:E13) -> 343130 | F9: =SUM(F10:F13) -> 336658 | G9: =SUM(G10:G13) -> 342879 | H9: =SUM(H10:H13) -> 342324 | I9: =SUM(I10:I13) -> 332258 | ... K9: =SUM(K10:K13) -> 307297
A10: 受取利息 | B10: 1 | C10: 1 | D10: 0 | E10: 0 | F10: 0 | G10: 0 | H10: 0 | I10: 0 | J10: 0 | K10: 0
A11: 繰入金・負担金等 | B11: 73283 | C11: 71157 | D11: 68955 | E11: 66740 | F11: 64490 | G11: 62175 | H11: 59946 | I11: 57892 | J11: 56062 | K11: 54385
A12: 長期前受金戻入 | B12: 281625 | C12: 283979 | D12: 279812 | E12: 276390 | F12: 272168 | G12: 272926 | H12: 274600 | I12: 266588 | J12: 250287 | K12: 245134
A13: その他営業外収益 | B13: 0 | C13: 0 | D13: 0 | E13: 0 | F13: 0 | G13: 7778 | H13: 7778 | I13: 7778 | J13: 7778 | K13: 7778
A14: 特別利益 | B14: 2576 | C14: 0 | D14: 0 | E14: 0 | F14: 0 | G14: 0 | H14: 0 | I14: 0 | J14: 0 | K14: 0
A16: 【収益的支出】
A17: 水道事業費用 | B17: =SUM(B18,B28,B31) -> 1608275 | C17: =SUM(C18,C28,C31) -> 1597336 | D17: =SUM(D18,D28,D31) -> 1591913 | E17: =SUM(E18,E28,E31) -> 1586945 | F17: =SUM(F18,F28,F31) -> 1585772 | G17: =SUM(G18,G28,G31) -> 1588017 | H17: =SUM(H18,H28,H31) -> 1595258 | I17: =SUM(I18,I28,I31) -> 1591786 | ... K17: =SUM(K18,K28,K31) -> 1575072
A18: 営業費用 | B18: =SUM(B19,B20,B25,B26,B27) -> 1479507 | C18: =SUM(C19,C20,C25,C26,C27) -> 1476545 | D18: =SUM(D19,D20,D25,D26,D27) -> 1474501 | E18: =SUM(E19,E20,E25,E26,E27) -> 1471288 | F18: =SUM(F19,F20,F25,F26,F27) -> 1471712 | G18: =SUM(G19,G20,G25,G26,G27) -> 1476923 | H18: =SUM(H19,H20,H25,H26,H27) -> 1486420 | I18: =SUM(I19,I20,I25,I26,I27) -> 1484101 | ... K18: =SUM(K19,K20,K25,K26,K27) -> 1469682
A19: 人件費 | B19: 176462 | C19: 176462 | D19: 176462 | E19: 176462 | F19: 176462 | G19: 176462 | H19: 176462 | I19: 176462 | J19: 176462 | K19: 176462
A20: 物件費 | B20: 547263 | C20: 545340 | D20: 545648 | E20: 545957 | F20: 546267 | G20: 546577 | H20: 546888 | I20: 547200 | J20: 547513 | K20: 547827
A21: 修繕費（物件費の内数・参考） | B21: 65247 | C21: 65000 | D21: 65000 | E21: 65000 | F21: 65000 | G21: 65000 | H21: 65000 | I21: 65000 | J21: 65000 | K21: 65000
A22: 動力費（物件費の内数・参考） | B22: 102261 | C22: 102568 | D22: 102876 | E22: 103185 | F22: 103495 | G22: 103805 | H22: 104116 | I22: 104428 | J22: 104741 | K22: 105055
A23: 薬品費（物件費の内数・参考） | B23: 15316 | C23: 15000 | D23: 15000 | E23: 15000 | F23: 15000 | G23: 15000 | H23: 15000 | I23: 15000 | J23: 15000 | K23: 15000
A24: 委託料（物件費の内数・参考） | B24: 304419 | C24: 304000 | D24: 304000 | E24: 304000 | F24: 304000 | G24: 304000 | H24: 304000 | I24: 304000 | J24: 304000 | K24: 304000
A25: 減価償却費 | B25: 755782 | C25: 754743 | D25: 752391 | E25: 748869 | F25: 748983 | G25: 753884 | H25: 763070 | I25: 760439 | J25: 744482 | K25: 745393
A26: 資産減耗・除却費（R8予算のみ別掲、他年度は物件費内数のため0） | B26: 0 | C26: 0 | D26: 0 | E26: 0 | F26: 0 | G26: 0 | H26: 0 | I26: 0 | J26: 0 | K26: 0
A27: その他営業費用（物件費内数のため0） | B27: 0 | C27: 0 | D27: 0 | E27: 0 | F27: 0 | G27: 0 | H27: 0 | I27: 0 | J27: 0 | K27: 0
A28: 営業外費用 | B28: =SUM(B29:B30) -> 128495 | C28: =SUM(C29:C30) -> 120518 | D28: =SUM(D29:D30) -> 117139 | E28: =SUM(E29:E30) -> 115384 | F28: =SUM(F29:F30) -> 113787 | G28: =SUM(G29:G30) -> 110821 | H28: =SUM(H29:H30) -> 108565 | I28: =SUM(I29:I30) -> 107412 | ... K28: =SUM(K29:K30) -> 105117
A29: 支払利息 | B29: 118910 | C29: 111872 | D29: 108458 | E29: 106668 | F29: 105071 | G29: 102070 | H29: 99779 | I29: 98626 | J29: 98322 | K29: 96331
A30: 雑支出 | B30: 9585 | C30: 8646 | D30: 8681 | E30: 8716 | F30: 8716 | G30: 8751 | H30: 8786 | I30: 8786 | J30: 8786 | K30: 8786
A31: 特別損失 | B31: 273 | C31: 273 | D31: 273 | E31: 273 | F31: 273 | G31: 273 | H31: 273 | I31: 273 | J31: 273 | K31: 273
A33: 【資本的収入】
A34: 資本的収入 | B34: 698941 | C34: 664331 | D34: 636408 | E34: 715698 | F34: 627649 | G34: 570213 | H34: 571338 | I34: 536592 | J34: 406734 | K34: 365000
A35: 企業債 | B35: 329000 | C35: 435000 | D35: 399000 | E35: 400000 | F35: 232000 | G35: 283000 | H35: 286000 | I35: 368000 | J35: 251000 | K35: 230000
A36: 一般会計負担金 | B36: 169041 | C36: 164831 | D36: 162408 | E36: 167998 | F36: 173649 | G36: 182213 | H36: 180338 | I36: 168592 | J36: 155734 | K36: 135000
A37: 一般会計出資金 | B37: 0 | C37: 0 | D37: 0 | E37: 0 | F37: 0 | G37: 0 | H37: 0 | I37: 0 | J37: 0 | K37: 0
A38: 国庫補助金 | B38: 0 | C38: 64500 | D38: 75000 | E38: 147700 | F38: 222000 | G38: 105000 | H38: 105000 | I38: 0 | J38: 0 | K38: 0
A39: 固定資産売却代金 | B39: 0 | C39: 0 | D39: 0 | E39: 0 | F39: 0 | G39: 0 | H39: 0 | I39: 0 | J39: 0 | K39: 0
A40: 工事負担金 | B40: 200900 | C40: 0 | D40: 0 | E40: 0 | F40: 0 | G40: 0 | H40: 0 | I40: 0 | J40: 0 | K40: 0
A41: その他・調整 | B41: =B34-SUM(B35:B40) -> 0 | C41: =C34-SUM(C35:C40) -> 0 | D41: =D34-SUM(D35:D40) -> 0 | E41: =E34-SUM(E35:E40) -> 0 | F41: =F34-SUM(F35:F40) -> 0 | G41: =G34-SUM(G35:G40) -> 0 | H41: =H34-SUM(H35:H40) -> 0 | I41: =I34-SUM(I35:I40) -> 0 | ... K41: =K34-SUM(K35:K40) -> 0
A43: 【資本的支出】
...

Sheet 03_SIM比較_R8予算反映
A1: SIM比較（R8予算収入・将来年次投資置換／資産維持費0〜3%）
A2: R8は予算ベース、建設改良費は将来年次計画へ置換。資産維持費込料金回収率は「給水収益÷（通常給水原価対象費用＋資産維持費）」で検証。
A3: 計画区分 | B3: 資産維持費率 | C3: 必要改定率 | D3: R11経常収支比率 | E3: R11料金回収率 | F3: R11資産維持費込料金回収率 | G3: R16年度末現預金 | H3: R7-R16累計4条不足額 | I3: 検証 | J3: R16現預金（精緻化後） | K3: 精緻化後最低現金差額
A4: R8予算・年次投資置換 | B4: ='SIM_R8予算置換_0%'!$B$4 -> 0 | C4: ='SIM_R8予算置換_0%'!$B$6 -> 0.072639394 | D4: ='SIM_R8予算置換_0%'!F31 -> 107.67319 | E4: ='SIM_R8予算置換_0%'!F32 -> 95.630009 | F4: ='SIM_R8予算置換_0%'!F33 -> 95.630009 | G4: ='SIM_R8予算置換_0%'!K59 -> 941905.2 | H4: =SUM('SIM_R8予算置換_0%'!B54:K54) -> -4594154 | I4: =IF(F4<=E4,"OK","要確認") -> OK | J4: ='SIM_R8予算置換_0%'!K70 -> 941905.2 | K4: =J4-00_前提・検証!$B$7 -> 641905.2
A5: R8予算・年次投資置換 | B5: ='SIM_R8予算置換_1%'!$B$4 -> 0.01 | C5: ='SIM_R8予算置換_1%'!$B$6 -> 0.21458812 | D5: ='SIM_R8予算置換_1%'!F31 -> 128.56175 | E5: ='SIM_R8予算置換_1%'!F32 -> 108.28529 | F5: ='SIM_R8予算置換_1%'!F33 -> 96.335212 | G5: ='SIM_R8予算置換_1%'!K59 -> 2906741.4 | H5: =SUM('SIM_R8予算置換_1%'!B54:K54) -> -4594154 | I5: =IF(F5<=E5,"OK","要確認") -> OK | J5: ='SIM_R8予算置換_1%'!K70 -> 2906741.4 | K5: =J5-00_前提・検証!$B$7 -> 2606741.4
A6: R8予算・年次投資置換 | B6: ='SIM_R8予算置換_2%'!$B$4 -> 0.02 | C6: ='SIM_R8予算置換_2%'!$B$6 -> 0.35653686 | D6: ='SIM_R8予算置換_2%'!F31 -> 149.45031 | E6: ='SIM_R8予算置換_2%'!F32 -> 120.94058 | F6: ='SIM_R8予算置換_2%'!F33 -> 96.900237 | G6: ='SIM_R8予算置換_2%'!K59 -> 4871577.5 | H6: =SUM('SIM_R8予算置換_2%'!B54:K54) -> -4594154 | I6: =IF(F6<=E6,"OK","要確認") -> OK | J6: ='SIM_R8予算置換_2%'!K70 -> 4871577.5 | K6: =J6-00_前提・検証!$B$7 -> 4571577.5
A7: R8予算・年次投資置換 | B7: ='SIM_R8予算置換_3%'!$B$4 -> 0.03 | C7: ='SIM_R8予算置換_3%'!$B$6 -> 0.49848559 | D7: ='SIM_R8予算置換_3%'!F31 -> 170.33888 | E7: ='SIM_R8予算置換_3%'!F32 -> 133.59587 | F7: ='SIM_R8予算置換_3%'!F33 -> 97.363101 | G7: ='SIM_R8予算置換_3%'!K59 -> 6836413.7 | H7: =SUM('SIM_R8予算置換_3%'!B54:K54) -> -4594154 | I7: =IF(F7<=E7,"OK","要確認") -> OK | J7: ='SIM_R8予算置換_3%'!K70 -> 6836413.7 | K7: =J7-00_前提・検証!$B$7 -> 6536413.7

Sheet 03_SIM比較
A1: SIM比較（ビジョン原計画・将来年次投資置換／資産維持費0〜3%）
A2: 資産維持費込料金回収率は、同一の改定後給水収益を分子とし、給水原価対象費用＋資産維持費を分母にするため、通常料金回収率以下になるよう修正。
A3: 計画区分 | B3: 資産維持費率 | C3: 必要改定率 | D3: R11経常収支比率 | E3: R11料金回収率 | F3: R11資産維持費込料金回収率 | G3: R16年度末現預金 | H3: R7-R16累計4条不足額 | I3: 検証
A4: ビジョン原計画 | B4: ='SIM_ビジョン_0%'!$B$4 -> 0 | C4: ='SIM_ビジョン_0%'!$B$6 -> 0.059677187 | D4: ='SIM_ビジョン_0%'!F31 -> 106.67861 | E4: ='SIM_ビジョン_0%'!F32 -> 95.424853 | F4: ='SIM_ビジョン_0%'!F33 -> 95.424853 | G4: ='SIM_ビジョン_0%'!K59 -> 613660.98 | H4: =SUM('SIM_ビジョン_0%'!B54:K54) -> -5074593 | I4: =IF(F4<=E4,"OK","要確認") -> OK
A5: ビジョン原計画 | B5: ='SIM_ビジョン_1%'!$B$4 -> 0.01 | C5: ='SIM_ビジョン_1%'!$B$6 -> 0.20162592 | D5: ='SIM_ビジョン_1%'!F31 -> 127.85528 | E5: ='SIM_ビジョン_1%'!F32 -> 108.20746 | F5: ='SIM_ビジョン_1%'!F33 -> 96.159205 | G5: ='SIM_ビジョン_1%'!K59 -> 2578497.1 | H5: =SUM('SIM_ビジョン_1%'!B54:K54) -> -5074593 | I5: =IF(F5<=E5,"OK","要確認") -> OK
A6: ビジョン原計画 | B6: ='SIM_ビジョン_2%'!$B$4 -> 0.02 | C6: ='SIM_ビジョン_2%'!$B$6 -> 0.34357465 | D6: ='SIM_ビジョン_2%'!F31 -> 149.03195 | E6: ='SIM_ビジョン_2%'!F32 -> 120.99007 | F6: ='SIM_ビジョン_2%'!F33 -> 96.746409 | G6: ='SIM_ビジョン_2%'!K59 -> 4543333.3 | H6: =SUM('SIM_ビジョン_2%'!B54:K54) -> -5074593 | I6: =IF(F6<=E6,"OK","要確認") -> OK
A7: ビジョン原計画 | B7: ='SIM_ビジョン_3%'!$B$4 -> 0.03 | C7: ='SIM_ビジョン_3%'!$B$6 -> 0.48552338 | D7: ='SIM_ビジョン_3%'!F31 -> 170.20862 | E7: ='SIM_ビジョン_3%'!F32 -> 133.77267 | F7: ='SIM_ビジョン_3%'!F33 -> 97.226666 | G7: ='SIM_ビジョン_3%'!K59 -> 6508169.5 | H7: =SUM('SIM_ビジョン_3%'!B54:K54) -> -5074593 | I7: =IF(F7<=E7,"OK","要確認") -> OK
A8: 将来年次投資置換 | B8: ='SIM_置換後_0%'!$B$4 -> 0 | C8: ='SIM_置換後_0%'!$B$6 -> 0.059677187 | D8: ='SIM_置換後_0%'!F31 -> 106.67861 | E8: ='SIM_置換後_0%'!F32 -> 95.424853 | F8: ='SIM_置換後_0%'!F33 -> 95.424853 | G8: ='SIM_置換後_0%'!K59 -> 219199.98 | H8: =SUM('SIM_置換後_0%'!B54:K54) -> -5179902 | I8: =IF(F8<=E8,"OK","要確認") -> OK
A9: 将来年次投資置換 | B9: ='SIM_置換後_1%'!$B$4 -> 0.01 | C9: ='SIM_置換後_1%'!$B$6 -> 0.20162592 | D9: ='SIM_置換後_1%'!F31 -> 127.85528 | E9: ='SIM_置換後_1%'!F32 -> 108.20746 | F9: ='SIM_置換後_1%'!F33 -> 96.159205 | G9: ='SIM_置換後_1%'!K59 -> 2184036.1 | H9: =SUM('SIM_置換後_1%'!B54:K54) -> -5179902 | I9: =IF(F9<=E9,"OK","要確認") -> OK
A10: 将来年次投資置換 | B10: ='SIM_置換後_2%'!$B$4 -> 0.02 | C10: ='SIM_置換後_2%'!$B$6 -> 0.34357465 | D10: ='SIM_置換後_2%'!F31 -> 149.03195 | E10: ='SIM_置換後_2%'!F32 -> 120.99007 | F10: ='SIM_置換後_2%'!F33 -> 96.746409 | G10: ='SIM_置換後_2%'!K59 -> 4148872.3 | H10: =SUM('SIM_置換後_2%'!B54:K54) -> -5179902 | I10: =IF(F10<=E10,"OK","要確認") -> OK
A11: 将来年次投資置換 | B11: ='SIM_置換後_3%'!$B$4 -> 0.03 | C11: ='SIM_置換後_3%'!$B$6 -> 0.48552338 | D11: ='SIM_置換後_3%'!F31 -> 170.20862 | E11: ='SIM_置換後_3%'!F32 -> 133.77267 | F11: ='SIM_置換後_3%'!F33 -> 97.226666 | G11: ='SIM_置換後_3%'!K59 -> 6113708.5 | H11: =SUM('SIM_置換後_3%'!B54:K54) -> -5179902 | I11: =IF(F11<=E11,"OK","要確認") -> OK

Sheet 04_R8予算・投資確認
A1: 項目 | B1: R8当初予算 | C1: 中間改定/作成資料ベース | D1: 将来年次計画 | E1: 採用値 | F1: 確認結果・備考 | G1: 差額（採用-予算）
A2: 収益的収入：水道事業収益 | B2: 1747782 | C2: =02_将来年次投資置換!C5 -> 1604473 | E2: =02_R8予算_年次計画置換!C5 -> 1747782 | F2: R8は予算ベースへ修正 | G2: =E2-B2 -> 0
A3: 収益的収入：給水収益 | B3: 1331944 | C3: =02_将来年次投資置換!C7 -> 1218869 | E3: =02_R8予算_年次計画置換!C7 -> 1331944 | F3: R8は予算ベースへ修正 | G3: =E3-B3 -> 0
A4: 収益的支出：水道事業費用 | B4: 1710280 | C4: =02_将来年次投資置換!C17 -> 1597336 | E4: =02_R8予算_年次計画置換!C17 -> 1710280 | F4: R8は予算ベースへ修正 | G4: =E4-B4 -> 0
A5: 資本的収入：合計 | B5: 861283 | C5: =02_将来年次投資置換!C34 -> 664331 | E5: =02_R8予算_年次計画置換!C34 -> 1055380 | F5: R8は予算ベースへ修正 | G5: =E5-B5 -> 194097
A6: 資本的収入：企業債 | B6: 519900 | C6: =02_将来年次投資置換!C35 -> 435000 | E6: =02_R8予算_年次計画置換!C35 -> 713997 | F6: R8は予算ベースへ修正 | G6: =E6-B6 -> 194097
A7: 資本的収入：一般会計負担金 | B7: 166838 | C7: =02_将来年次投資置換!C36 -> 164831 | E7: =02_R8予算_年次計画置換!C36 -> 166838 | F7: R8は予算ベースへ修正 | G7: =E7-B7 -> 0
A8: 資本的収入：国庫補助金 | B8: 2000 | C8: =02_将来年次投資置換!C38 -> 64500 | E8: =02_R8予算_年次計画置換!C38 -> 2000 | F8: R8は予算ベースへ修正 | G8: =E8-B8 -> 0
A9: 資本的収入：工事負担金 | B9: 172545 | C9: =02_将来年次投資置換!C40 -> 0 | E9: =02_R8予算_年次計画置換!C40 -> 172545 | F9: R8は予算ベースへ修正 | G9: =E9-B9 -> 0
A10: 建設改良費 | B10: 714032 | C10: =01_ビジョン原計画!C45 -> 525014 | D10: 888542 | E10: =02_R8予算_年次計画置換!C45 -> 888542 | F10: 投資は将来年次計画へ置換（予算との差額を確認） | G10: =E10-B10 -> 174510
A11: 企業債償還金 | B11: 795933 | C11: =02_将来年次投資置換!C46 -> 795941 | E11: =02_R8予算_年次計画置換!C46 -> 795933 | F11: R8は予算ベースへ修正 | G11: =E11-B11 -> 0

Sheet SIM_ビジョン_0%
A1: SIM_ビジョン_0%
A2: 単位：千円、比率は％。料金改定率はR11〜R15の総括原価回収を基礎に算定し、R11以降の給水収益へ反映。
A3: 区分 | B3: 令和7年度 | C3: 令和8年度 | D3: 令和9年度 | E3: 令和10年度 | F3: 令和11年度 | G3: 令和12年度 | H3: 令和13年度 | I3: 令和14年度 | J3: 令和15年度 | K3: 令和16年度
A4: 資産維持費率 | B4: 0
A5: 年額資産維持費（千円） | B5: =00_前提・検証!$B$2*$B$4 -> 0
A6: 料金改定率（R11以降・試算） | B6: =MAX(0,(SUMPRODUCT((01_ビジョン原計画!F18:J18+01_ビジョン原計画!F28:J28-01_ビジョン原計画!F12:J12-01_ビジョン原計画!F8:J8-01_ビジョン原計画!F11:J11+$B$5)-01_ビジョン原計画!F7:J7)/SUM(01_ビジョン原計画!F7:J7))) -> 0.059677187
A8: 【収益的収入】
A9: 営業収益 | B9: =SUM(B10:B12) -> 1261575 | C9: =SUM(C10:C12) -> 1249336 | D9: =SUM(D10:D12) -> 1237293 | E9: =SUM(E10:E12) -> 1225373 | F9: =SUM(F10:F12) -> 1354730.4 | G9: =SUM(G10:G12) -> 1341640.8 | H9: =SUM(H10:H12) -> 1328683.2 | I9: =SUM(I10:I12) -> 1315857.7 | ... K9: =SUM(K10:K12) -> 1290598
A10: 給水収益（改定反映後） | B10: =01_ビジョン原計画!B7*IF(7>=11,1+$B$6,1) -> 1231181 | C10: =01_ビジョン原計画!C7*IF(8>=11,1+$B$6,1) -> 1218869 | D10: =01_ビジョン原計画!D7*IF(9>=11,1+$B$6,1) -> 1206680 | E10: =01_ビジョン原計画!E7*IF(10>=11,1+$B$6,1) -> 1194613 | F10: =01_ビジョン原計画!F7*IF(11>=11,1+$B$6,1) -> 1253244.2 | G10: =01_ビジョン原計画!G7*IF(12>=11,1+$B$6,1) -> 1240711.4 | H10: =01_ビジョン原計画!H7*IF(13>=11,1+$B$6,1) -> 1228303.6 | I10: =01_ビジョン原計画!I7*IF(14>=11,1+$B$6,1) -> 1216019.8 | J10: =01_ビジョン原計画!J7*IF(15>=11,1+$B$6,1) -> 1203859 | K10: =01_ビジョン原計画!K7*IF(16>=11,1+$B$6,1) -> 1191820
A11: うち料金改定増収 | B11: =B10-01_ビジョン原計画!B7 -> 0 | C11: =C10-01_ビジョン原計画!C7 -> 0 | D11: =D10-01_ビジョン原計画!D7 -> 0 | E11: =E10-01_ビジョン原計画!E7 -> 0 | F11: =F10-01_ビジョン原計画!F7 -> 70578.18 | G11: =G10-01_ビジョン原計画!G7 -> 69872.378 | H11: =H10-01_ビジョン原計画!H7 -> 69173.618 | I11: =I10-01_ビジョン原計画!I7 -> 68481.84 | ... K11: =K10-01_ビジョン原計画!K7 -> 67118.992
A12: その他営業収益 | B12: =01_ビジョン原計画!B8 -> 30394 | C12: =01_ビジョン原計画!C8 -> 30467 | D12: =01_ビジョン原計画!D8 -> 30613 | E12: =01_ビジョン原計画!E8 -> 30760 | F12: =01_ビジョン原計画!F8 -> 30908 | G12: =01_ビジョン原計画!G8 -> 31057 | H12: =01_ビジョン原計画!H8 -> 31206 | I12: =01_ビジョン原計画!I8 -> 31356 | ... K12: =01_ビジョン原計画!K8 -> 31659
A13: 営業外収益 | B13: =01_ビジョン原計画!B9 -> 354909 | C13: =01_ビジョン原計画!C9 -> 355137 | D13: =01_ビジョン原計画!D9 -> 348767 | E13: =01_ビジョン原計画!E9 -> 343130 | F13: =01_ビジョン原計画!F9 -> 336658 | G13: =01_ビジョン原計画!G9 -> 342879 | H13: =01_ビジョン原計画!H9 -> 342324 | I13: =01_ビジョン原計画!I9 -> 332258 | ... K13: =01_ビジョン原計画!K9 -> 307297
A14: 長期前受金戻入 | B14: =01_ビジョン原計画!B12 -> 281625 | C14: =01_ビジョン原計画!C12 -> 283979 | D14: =01_ビジョン原計画!D12 -> 279812 | E14: =01_ビジョン原計画!E12 -> 276390 | F14: =01_ビジョン原計画!F12 -> 272168 | G14: =01_ビジョン原計画!G12 -> 272926 | H14: =01_ビジョン原計画!H12 -> 274600 | I14: =01_ビジョン原計画!I12 -> 266588 | ... K14: =01_ビジョン原計画!K12 -> 245134
A15: 繰入金・負担金等 | B15: =01_ビジョン原計画!B11 -> 73283 | C15: =01_ビジョン原計画!C11 -> 71157 | D15: =01_ビジョン原計画!D11 -> 68955 | E15: =01_ビジョン原計画!E11 -> 66740 | F15: =01_ビジョン原計画!F11 -> 64490 | G15: =01_ビジョン原計画!G11 -> 62175 | H15: =01_ビジョン原計画!H11 -> 59946 | I15: =01_ビジョン原計画!I11 -> 57892 | ... K15: =01_ビジョン原計画!K11 -> 54385
A16: 特別利益 | B16: =01_ビジョン原計画!B14 -> 2576 | C16: =01_ビジョン原計画!C14 -> 0 | D16: =01_ビジョン原計画!D14 -> 0 | E16: =01_ビジョン原計画!E14 -> 0 | F16: =01_ビジョン原計画!F14 -> 0 | G16: =01_ビジョン原計画!G14 -> 0 | H16: =01_ビジョン原計画!H14 -> 0 | I16: =01_ビジョン原計画!I14 -> 0 | ... K16: =01_ビジョン原計画!K14 -> 0
A17: 収益的収入合計 | B17: =SUM(B9,B13,B16) -> 1619060 | C17: =SUM(C9,C13,C16) -> 1604473 | D17: =SUM(D9,D13,D16) -> 1586060 | E17: =SUM(E9,E13,E16) -> 1568503 | F17: =SUM(F9,F13,F16) -> 1691388.4 | G17: =SUM(G9,G13,G16) -> 1684519.8 | H17: =SUM(H9,H13,H16) -> 1671007.2 | I17: =SUM(I9,I13,I16) -> 1648115.7 | ... K17: =SUM(K9,K13,K16) -> 1597895
A19: 【収益的支出】
A20: 営業費用 | B20: =01_ビジョン原計画!B18 -> 1479507 | C20: =01_ビジョン原計画!C18 -> 1476545 | D20: =01_ビジョン原計画!D18 -> 1474501 | E20: =01_ビジョン原計画!E18 -> 1471288 | F20: =01_ビジョン原計画!F18 -> 1471712 | G20: =01_ビジョン原計画!G18 -> 1476923 | H20: =01_ビジョン原計画!H18 -> 1486420 | I20: =01_ビジョン原計画!I18 -> 1484101 | ... K20: =01_ビジョン原計画!K18 -> 1469682
A21: 減価償却費 | B21: =01_ビジョン原計画!B25 -> 755782 | C21: =01_ビジョン原計画!C25 -> 754743 | D21: =01_ビジョン原計画!D25 -> 752391 | E21: =01_ビジョン原計画!E25 -> 748869 | F21: =01_ビジョン原計画!F25 -> 748983 | G21: =01_ビジョン原計画!G25 -> 753884 | H21: =01_ビジョン原計画!H25 -> 763070 | I21: =01_ビジョン原計画!I25 -> 760439 | ... K21: =01_ビジョン原計画!K25 -> 745393
A22: 資産減耗・除却費 | B22: =01_ビジョン原計画!B26 -> 0 | C22: =01_ビジョン原計画!C26 -> 0 | D22: =01_ビジョン原計画!D26 -> 0 | E22: =01_ビジョン原計画!E26 -> 0 | F22: =01_ビジョン原計画!F26 -> 0 | G22: =01_ビジョン原計画!G26 -> 0 | H22: =01_ビジョン原計画!H26 -> 0 | I22: =01_ビジョン原計画!I26 -> 0 | ... K22: =01_ビジョン原計画!K26 -> 0
A23: 営業外費用 | B23: =01_ビジョン原計画!B28 -> 128495 | C23: =01_ビジョン原計画!C28 -> 120518 | D23: =01_ビジョン原計画!D28 -> 117139 | E23: =01_ビジョン原計画!E28 -> 115384 | F23: =01_ビジョン原計画!F28 -> 113787 | G23: =01_ビジョン原計画!G28 -> 110821 | H23: =01_ビジョン原計画!H28 -> 108565 | I23: =01_ビジョン原計画!I28 -> 107412 | ... K23: =01_ビジョン原計画!K28 -> 105117
A24: 支払利息 | B24: =01_ビジョン原計画!B29 -> 118910 | C24: =01_ビジョン原計画!C29 -> 111872 | D24: =01_ビジョン原計画!D29 -> 108458 | E24: =01_ビジョン原計画!E29 -> 106668 | F24: =01_ビジョン原計画!F29 -> 105071 | G24: =01_ビジョン原計画!G29 -> 102070 | H24: =01_ビジョン原計画!H29 -> 99779 | I24: =01_ビジョン原計画!I29 -> 98626 | ... K24: =01_ビジョン原計画!K29 -> 96331
A25: 特別損失 | B25: =01_ビジョン原計画!B31 -> 273 | C25: =01_ビジョン原計画!C31 -> 273 | D25: =01_ビジョン原計画!D31 -> 273 | E25: =01_ビジョン原計画!E31 -> 273 | F25: =01_ビジョン原計画!F31 -> 273 | G25: =01_ビジョン原計画!G31 -> 273 | H25: =01_ビジョン原計画!H31 -> 273 | I25: =01_ビジョン原計画!I31 -> 273 | ... K25: =01_ビジョン原計画!K31 -> 273
A26: 収益的支出合計 | B26: =SUM(B20,B23,B25) -> 1608275 | C26: =SUM(C20,C23,C25) -> 1597336 | D26: =SUM(D20,D23,D25) -> 1591913 | E26: =SUM(E20,E23,E25) -> 1586945 | F26: =SUM(F20,F23,F25) -> 1585772 | G26: =SUM(G20,G23,G25) -> 1588017 | H26: =SUM(H20,H23,H25) -> 1595258 | I26: =SUM(I20,I23,I25) -> 1591786 | ... K26: =SUM(K20,K23,K25) -> 1575072
A27: 経常損益 | B27: =SUM(B9,B13)-SUM(B20,B23) -> 8482 | C27: =SUM(C9,C13)-SUM(C20,C23) -> 7410 | D27: =SUM(D9,D13)-SUM(D20,D23) -> -5580 | E27: =SUM(E9,E13)-SUM(E20,E23) -> -18169 | F27: =SUM(F9,F13)-SUM(F20,F23) -> 105889.36 | G27: =SUM(G9,G13)-SUM(G20,G23) -> 96775.756 | H27: =SUM(H9,H13)-SUM(H20,H23) -> 76022.236 | I27: =SUM(I9,I13)-SUM(I20,I23) -> 56602.68 | ... K27: =SUM(K9,K13)-SUM(K20,K23) -> 23095.984
A28: 純損益 | B28: =B27+B16-B25 -> 10785 | C28: =C27+C16-C25 -> 7137 | D28: =D27+D16-D25 -> -5853 | E28: =E27+E16-E25 -> -18442 | F28: =F27+F16-F25 -> 105616.36 | G28: =G27+G16-G25 -> 96502.756 | H28: =H27+H16-H25 -> 75749.236 | I28: =I27+I16-I25 -> 56329.68 | ... K28: =K27+K16-K25 -> 22822.984
A30: 【経営指標】
A31: 経常収支比率 | B31: =IFERROR((SUM(B9,B13)/SUM(B20,B23))*100,0) -> 100.52749 | C31: =IFERROR((SUM(C9,C13)/SUM(C20,C23))*100,0) -> 100.46398 | D31: =IFERROR((SUM(D9,D13)/SUM(D20,D23))*100,0) -> 99.649418 | E31: =IFERROR((SUM(E9,E13)/SUM(E20,E23))*100,0) -> 98.854899 | F31: =IFERROR((SUM(F9,F13)/SUM(F20,F23))*100,0) -> 106.67861 | G31: =IFERROR((SUM(G9,G13)/SUM(G20,G23))*100,0) -> 106.09517 | H31: =IFERROR((SUM(H9,H13)/SUM(H20,H23))*100,0) -> 104.76633 | I31: =IFERROR((SUM(I9,I13)/SUM(I20,I23))*100,0) -> 103.55653 | ... K31: =IFERROR((SUM(K9,K13)/SUM(K20,K23))*100,0) -> 101.4666
A32: 料金回収率（通常） | B32: =IFERROR(B10/B34*100,0) -> 92.822855 | C32: =IFERROR(C10/C34*100,0) -> 92.824907 | D32: =IFERROR(D10/D34*100,0) -> 91.98462 | E32: =IFERROR(E10/E34*100,0) -> 91.172206 | F32: =IFERROR(F10/F34*100,0) -> 95.424853 | G32: =IFERROR(G10/G34*100,0) -> 94.363735 | H32: =IFERROR(H10/H34*100,0) -> 93.026172 | I32: =IFERROR(I10/I34*100,0) -> 91.780277 | ... K32: =IFERROR(K10/K34*100,0) -> 89.633102
A33: 資産維持費込料金回収率 | B33: =IFERROR(B10/B35*100,0) -> 92.822855 | C33: =IFERROR(C10/C35*100,0) -> 92.824907 | D33: =IFERROR(D10/D35*100,0) -> 91.98462 | E33: =IFERROR(E10/E35*100,0) -> 91.172206 | F33: =IFERROR(F10/F35*100,0) -> 95.424853 | G33: =IFERROR(G10/G35*100,0) -> 94.363735 | H33: =IFERROR(H10/H35*100,0) -> 93.026172 | I33: =IFERROR(I10/I35*100,0) -> 91.780277 | ... K33: =IFERROR(K10/K35*100,0) -> 89.633102
A34: 給水原価対象費用 | B34: =SUM(B20,B23)-B14 -> 1326377 | C34: =SUM(C20,C23)-C14 -> 1313084 | D34: =SUM(D20,D23)-D14 -> 1311828 | E34: =SUM(E20,E23)-E14 -> 1310282 | F34: =SUM(F20,F23)-F14 -> 1313331 | G34: =SUM(G20,G23)-G14 -> 1314818 | H34: =SUM(H20,H23)-H14 -> 1320385 | I34: =SUM(I20,I23)-I14 -> 1324925 | ... K34: =SUM(K20,K23)-K14 -> 1329665
A35: 給水原価対象費用＋資産維持費 | B35: =B34+$B$5 -> 1326377 | C35: =C34+$B$5 -> 1313084 | D35: =D34+$B$5 -> 1311828 | E35: =E34+$B$5 -> 1310282 | F35: =F34+$B$5 -> 1313331 | G35: =G34+$B$5 -> 1314818 | H35: =H34+$B$5 -> 1320385 | I35: =I34+$B$5 -> 1324925 | ... K35: =K34+$B$5 -> 1329665
A36: 総括原価回収率（参考） | B36: =IFERROR(B10/(B20+B23-B14-B12-B15+$B$5)*100,0) -> 100.69363 | C36: =IFERROR(C10/(C20+C23-C14-C12-C15+$B$5)*100,0) -> 100.61158 | D36: =IFERROR(D10/(D20+D23-D14-D12-D15+$B$5)*100,0) -> 99.539703 | E36: =IFERROR(E10/(E20+E23-E14-E12-E15+$B$5)*100,0) -> 98.501874 | F36: =IFERROR(F10/(F20+F23-F14-F12-F15+$B$5)*100,0) -> 102.89927 | G36: =IFERROR(G10/(G20+G23-G14-G12-G15+$B$5)*100,0) -> 101.56562 | H36: =IFERROR(H10/(H20+H23-H14-H12-H15+$B$5)*100,0) -> 99.924393 | I36: =IFERROR(I10/(I20+I23-I14-I12-I15+$B$5)*100,0) -> 98.409199 | ... K36: =IFERROR(K10/(K20+K23-K14-K12-K15+$B$5)*100,0) -> 95.834663
A37: 検証：資産維持費込<=通常 | B37: =IF(B33<=B32,"OK","要確認") -> OK | C37: =IF(C33<=C32,"OK","要確認") -> OK | D37: =IF(D33<=D32,"OK","要確認") -> OK | E37: =IF(E33<=E32,"OK","要確認") -> OK | F37: =IF(F33<=F32,"OK","要確認") -> OK | G37: =IF(G33<=G32,"OK","要確認") -> OK | H37: =IF(H33<=H32,"OK","要確認") -> OK | I37: =IF(I33<=I32,"OK","要確認") -> OK | ... K37: =IF(K33<=K32,"OK","要確認") -> OK
A39: 【資本的収入】
A40: 資本的収入 | B40: =01_ビジョン原計画!B34 -> 698941 | C40: =01_ビジョン原計画!C34 -> 664331 | D40: =01_ビジョン原計画!D34 -> 636408 | E40: =01_ビジョン原計画!E34 -> 715698 | F40: =01_ビジョン原計画!F34 -> 627649 | G40: =01_ビジョン原計画!G34 -> 570213 | H40: =01_ビジョン原計画!H34 -> 571338 | I40: =01_ビジョン原計画!I34 -> 536592 | ... K40: =01_ビジョン原計画!K34 -> 365000
A41: 企業債 | B41: =01_ビジョン原計画!B35 -> 329000 | C41: =01_ビジョン原計画!C35 -> 435000 | D41: =01_ビジョン原計画!D35 -> 399000 | E41: =01_ビジョン原計画!E35 -> 400000 | F41: =01_ビジョン原計画!F35 -> 232000 | G41: =01_ビジョン原計画!G35 -> 283000 | H41: =01_ビジョン原計画!H35 -> 286000 | I41: =01_ビジョン原計画!I35 -> 368000 | ... K41: =01_ビジョン原計画!K35 -> 230000
A42: 一般会計負担金 | B42: =01_ビジョン原計画!B36 -> 169041 | C42: =01_ビジョン原計画!C36 -> 164831 | D42: =01_ビジョン原計画!D36 -> 162408 | E42: =01_ビジョン原計画!E36 -> 167998 | F42: =01_ビジョン原計画!F36 -> 173649 | G42: =01_ビジョン原計画!G36 -> 182213 | H42: =01_ビジョン原計画!H36 -> 180338 | I42: =01_ビジョン原計画!I36 -> 168592 | ... K42: =01_ビジョン原計画!K36 -> 135000
A43: 一般会計出資金 | B43: =01_ビジョン原計画!B37 -> 0 | C43: =01_ビジョン原計画!C37 -> 0 | D43: =01_ビジョン原計画!D37 -> 0 | E43: =01_ビジョン原計画!E37 -> 0 | F43: =01_ビジョン原計画!F37 -> 0 | G43: =01_ビジョン原計画!G37 -> 0 | H43: =01_ビジョン原計画!H37 -> 0 | I43: =01_ビジョン原計画!I37 -> 0 | ... K43: =01_ビジョン原計画!K37 -> 0
A44: 国庫補助金 | B44: =01_ビジョン原計画!B38 -> 0 | C44: =01_ビジョン原計画!C38 -> 64500 | D44: =01_ビジョン原計画!D38 -> 75000 | E44: =01_ビジョン原計画!E38 -> 147700 | F44: =01_ビジョン原計画!F38 -> 222000 | G44: =01_ビジョン原計画!G38 -> 105000 | H44: =01_ビジョン原計画!H38 -> 105000 | I44: =01_ビジョン原計画!I38 -> 0 | ... K44: =01_ビジョン原計画!K38 -> 0
...

Sheet SIM_ビジョン_1%
A1: SIM_ビジョン_1%
A2: 単位：千円、比率は％。料金改定率はR11〜R15の総括原価回収を基礎に算定し、R11以降の給水収益へ反映。
A3: 区分 | B3: 令和7年度 | C3: 令和8年度 | D3: 令和9年度 | E3: 令和10年度 | F3: 令和11年度 | G3: 令和12年度 | H3: 令和13年度 | I3: 令和14年度 | J3: 令和15年度 | K3: 令和16年度
A4: 資産維持費率 | B4: 0.01
A5: 年額資産維持費（千円） | B5: =00_前提・検証!$B$2*$B$4 -> 164553.64
A6: 料金改定率（R11以降・試算） | B6: =MAX(0,(SUMPRODUCT((01_ビジョン原計画!F18:J18+01_ビジョン原計画!F28:J28-01_ビジョン原計画!F12:J12-01_ビジョン原計画!F8:J8-01_ビジョン原計画!F11:J11+$B$5)-01_ビジョン原計画!F7:J7)/SUM(01_ビジョン原計画!F7:J7))) -> 0.20162592
A8: 【収益的収入】
A9: 営業収益 | B9: =SUM(B10:B12) -> 1261575 | C9: =SUM(C10:C12) -> 1249336 | D9: =SUM(D10:D12) -> 1237293 | E9: =SUM(E10:E12) -> 1225373 | F9: =SUM(F10:F12) -> 1690486.2 | G9: =SUM(G10:G12) -> 1674039 | H9: =SUM(H10:H12) -> 1657757.3 | I9: =SUM(I10:I12) -> 1641640.8 | ... K9: =SUM(K10:K12) -> 1609897.7
A10: 給水収益（改定反映後） | B10: =01_ビジョン原計画!B7*IF(7>=11,1+$B$6,1) -> 1231181 | C10: =01_ビジョン原計画!C7*IF(8>=11,1+$B$6,1) -> 1218869 | D10: =01_ビジョン原計画!D7*IF(9>=11,1+$B$6,1) -> 1206680 | E10: =01_ビジョン原計画!E7*IF(10>=11,1+$B$6,1) -> 1194613 | F10: =01_ビジョン原計画!F7*IF(11>=11,1+$B$6,1) -> 1421122.1 | G10: =01_ビジョン原計画!G7*IF(12>=11,1+$B$6,1) -> 1406910.5 | H10: =01_ビジョン原計画!H7*IF(13>=11,1+$B$6,1) -> 1392840.6 | I10: =01_ビジョン原計画!I7*IF(14>=11,1+$B$6,1) -> 1378911.4 | J10: =01_ビジョン原計画!J7*IF(15>=11,1+$B$6,1) -> 1365121.5 | K10: =01_ビジョン原計画!K7*IF(16>=11,1+$B$6,1) -> 1351469.9
A11: うち料金改定増収 | B11: =B10-01_ビジョン原計画!B7 -> 0 | C11: =C10-01_ビジョン原計画!C7 -> 0 | D11: =D10-01_ビジョン原計画!D7 -> 0 | E11: =E10-01_ビジョン原計画!E7 -> 0 | F11: =F10-01_ビジョン原計画!F7 -> 238456.12 | G11: =G10-01_ビジョン原計画!G7 -> 236071.49 | H11: =H10-01_ビジョン原計画!H7 -> 233710.65 | I11: =I10-01_ビジョン原計画!I7 -> 231373.4 | ... K11: =K10-01_ビジョン原計画!K7 -> 226768.87
A12: その他営業収益 | B12: =01_ビジョン原計画!B8 -> 30394 | C12: =01_ビジョン原計画!C8 -> 30467 | D12: =01_ビジョン原計画!D8 -> 30613 | E12: =01_ビジョン原計画!E8 -> 30760 | F12: =01_ビジョン原計画!F8 -> 30908 | G12: =01_ビジョン原計画!G8 -> 31057 | H12: =01_ビジョン原計画!H8 -> 31206 | I12: =01_ビジョン原計画!I8 -> 31356 | ... K12: =01_ビジョン原計画!K8 -> 31659
A13: 営業外収益 | B13: =01_ビジョン原計画!B9 -> 354909 | C13: =01_ビジョン原計画!C9 -> 355137 | D13: =01_ビジョン原計画!D9 -> 348767 | E13: =01_ビジョン原計画!E9 -> 343130 | F13: =01_ビジョン原計画!F9 -> 336658 | G13: =01_ビジョン原計画!G9 -> 342879 | H13: =01_ビジョン原計画!H9 -> 342324 | I13: =01_ビジョン原計画!I9 -> 332258 | ... K13: =01_ビジョン原計画!K9 -> 307297
A14: 長期前受金戻入 | B14: =01_ビジョン原計画!B12 -> 281625 | C14: =01_ビジョン原計画!C12 -> 283979 | D14: =01_ビジョン原計画!D12 -> 279812 | E14: =01_ビジョン原計画!E12 -> 276390 | F14: =01_ビジョン原計画!F12 -> 272168 | G14: =01_ビジョン原計画!G12 -> 272926 | H14: =01_ビジョン原計画!H12 -> 274600 | I14: =01_ビジョン原計画!I12 -> 266588 | ... K14: =01_ビジョン原計画!K12 -> 245134
A15: 繰入金・負担金等 | B15: =01_ビジョン原計画!B11 -> 73283 | C15: =01_ビジョン原計画!C11 -> 71157 | D15: =01_ビジョン原計画!D11 -> 68955 | E15: =01_ビジョン原計画!E11 -> 66740 | F15: =01_ビジョン原計画!F11 -> 64490 | G15: =01_ビジョン原計画!G11 -> 62175 | H15: =01_ビジョン原計画!H11 -> 59946 | I15: =01_ビジョン原計画!I11 -> 57892 | ... K15: =01_ビジョン原計画!K11 -> 54385
A16: 特別利益 | B16: =01_ビジョン原計画!B14 -> 2576 | C16: =01_ビジョン原計画!C14 -> 0 | D16: =01_ビジョン原計画!D14 -> 0 | E16: =01_ビジョン原計画!E14 -> 0 | F16: =01_ビジョン原計画!F14 -> 0 | G16: =01_ビジョン原計画!G14 -> 0 | H16: =01_ビジョン原計画!H14 -> 0 | I16: =01_ビジョン原計画!I14 -> 0 | ... K16: =01_ビジョン原計画!K14 -> 0
A17: 収益的収入合計 | B17: =SUM(B9,B13,B16) -> 1619060 | C17: =SUM(C9,C13,C16) -> 1604473 | D17: =SUM(D9,D13,D16) -> 1586060 | E17: =SUM(E9,E13,E16) -> 1568503 | F17: =SUM(F9,F13,F16) -> 2027144.2 | G17: =SUM(G9,G13,G16) -> 2016918 | H17: =SUM(H9,H13,H16) -> 2000081.3 | I17: =SUM(I9,I13,I16) -> 1973898.8 | ... K17: =SUM(K9,K13,K16) -> 1917194.7
A19: 【収益的支出】
A20: 営業費用 | B20: =01_ビジョン原計画!B18 -> 1479507 | C20: =01_ビジョン原計画!C18 -> 1476545 | D20: =01_ビジョン原計画!D18 -> 1474501 | E20: =01_ビジョン原計画!E18 -> 1471288 | F20: =01_ビジョン原計画!F18 -> 1471712 | G20: =01_ビジョン原計画!G18 -> 1476923 | H20: =01_ビジョン原計画!H18 -> 1486420 | I20: =01_ビジョン原計画!I18 -> 1484101 | ... K20: =01_ビジョン原計画!K18 -> 1469682
A21: 減価償却費 | B21: =01_ビジョン原計画!B25 -> 755782 | C21: =01_ビジョン原計画!C25 -> 754743 | D21: =01_ビジョン原計画!D25 -> 752391 | E21: =01_ビジョン原計画!E25 -> 748869 | F21: =01_ビジョン原計画!F25 -> 748983 | G21: =01_ビジョン原計画!G25 -> 753884 | H21: =01_ビジョン原計画!H25 -> 763070 | I21: =01_ビジョン原計画!I25 -> 760439 | ... K21: =01_ビジョン原計画!K25 -> 745393
A22: 資産減耗・除却費 | B22: =01_ビジョン原計画!B26 -> 0 | C22: =01_ビジョン原計画!C26 -> 0 | D22: =01_ビジョン原計画!D26 -> 0 | E22: =01_ビジョン原計画!E26 -> 0 | F22: =01_ビジョン原計画!F26 -> 0 | G22: =01_ビジョン原計画!G26 -> 0 | H22: =01_ビジョン原計画!H26 -> 0 | I22: =01_ビジョン原計画!I26 -> 0 | ... K22: =01_ビジョン原計画!K26 -> 0
A23: 営業外費用 | B23: =01_ビジョン原計画!B28 -> 128495 | C23: =01_ビジョン原計画!C28 -> 120518 | D23: =01_ビジョン原計画!D28 -> 117139 | E23: =01_ビジョン原計画!E28 -> 115384 | F23: =01_ビジョン原計画!F28 -> 113787 | G23: =01_ビジョン原計画!G28 -> 110821 | H23: =01_ビジョン原計画!H28 -> 108565 | I23: =01_ビジョン原計画!I28 -> 107412 | ... K23: =01_ビジョン原計画!K28 -> 105117
A24: 支払利息 | B24: =01_ビジョン原計画!B29 -> 118910 | C24: =01_ビジョン原計画!C29 -> 111872 | D24: =01_ビジョン原計画!D29 -> 108458 | E24: =01_ビジョン原計画!E29 -> 106668 | F24: =01_ビジョン原計画!F29 -> 105071 | G24: =01_ビジョン原計画!G29 -> 102070 | H24: =01_ビジョン原計画!H29 -> 99779 | I24: =01_ビジョン原計画!I29 -> 98626 | ... K24: =01_ビジョン原計画!K29 -> 96331
A25: 特別損失 | B25: =01_ビジョン原計画!B31 -> 273 | C25: =01_ビジョン原計画!C31 -> 273 | D25: =01_ビジョン原計画!D31 -> 273 | E25: =01_ビジョン原計画!E31 -> 273 | F25: =01_ビジョン原計画!F31 -> 273 | G25: =01_ビジョン原計画!G31 -> 273 | H25: =01_ビジョン原計画!H31 -> 273 | I25: =01_ビジョン原計画!I31 -> 273 | ... K25: =01_ビジョン原計画!K31 -> 273
A26: 収益的支出合計 | B26: =SUM(B20,B23,B25) -> 1608275 | C26: =SUM(C20,C23,C25) -> 1597336 | D26: =SUM(D20,D23,D25) -> 1591913 | E26: =SUM(E20,E23,E25) -> 1586945 | F26: =SUM(F20,F23,F25) -> 1585772 | G26: =SUM(G20,G23,G25) -> 1588017 | H26: =SUM(H20,H23,H25) -> 1595258 | I26: =SUM(I20,I23,I25) -> 1591786 | ... K26: =SUM(K20,K23,K25) -> 1575072
A27: 経常損益 | B27: =SUM(B9,B13)-SUM(B20,B23) -> 8482 | C27: =SUM(C9,C13)-SUM(C20,C23) -> 7410 | D27: =SUM(D9,D13)-SUM(D20,D23) -> -5580 | E27: =SUM(E9,E13)-SUM(E20,E23) -> -18169 | F27: =SUM(F9,F13)-SUM(F20,F23) -> 441645.23 | G27: =SUM(G9,G13)-SUM(G20,G23) -> 429173.98 | H27: =SUM(H9,H13)-SUM(H20,H23) -> 405096.3 | I27: =SUM(I9,I13)-SUM(I20,I23) -> 382385.8 | ... K27: =SUM(K9,K13)-SUM(K20,K23) -> 342395.74
A28: 純損益 | B28: =B27+B16-B25 -> 10785 | C28: =C27+C16-C25 -> 7137 | D28: =D27+D16-D25 -> -5853 | E28: =E27+E16-E25 -> -18442 | F28: =F27+F16-F25 -> 441372.23 | G28: =G27+G16-G25 -> 428900.98 | H28: =H27+H16-H25 -> 404823.3 | I28: =I27+I16-I25 -> 382112.8 | ... K28: =K27+K16-K25 -> 342122.74
A30: 【経営指標】
A31: 経常収支比率 | B31: =IFERROR((SUM(B9,B13)/SUM(B20,B23))*100,0) -> 100.52749 | C31: =IFERROR((SUM(C9,C13)/SUM(C20,C23))*100,0) -> 100.46398 | D31: =IFERROR((SUM(D9,D13)/SUM(D20,D23))*100,0) -> 99.649418 | E31: =IFERROR((SUM(E9,E13)/SUM(E20,E23))*100,0) -> 98.854899 | F31: =IFERROR((SUM(F9,F13)/SUM(F20,F23))*100,0) -> 127.85528 | G31: =IFERROR((SUM(G9,G13)/SUM(G20,G23))*100,0) -> 127.03043 | H31: =IFERROR((SUM(H9,H13)/SUM(H20,H23))*100,0) -> 125.39813 | I31: =IFERROR((SUM(I9,I13)/SUM(I20,I23))*100,0) -> 124.02656 | ... K31: =IFERROR((SUM(K9,K13)/SUM(K20,K23))*100,0) -> 121.74219
A32: 料金回収率（通常） | B32: =IFERROR(B10/B34*100,0) -> 92.822855 | C32: =IFERROR(C10/C34*100,0) -> 92.824907 | D32: =IFERROR(D10/D34*100,0) -> 91.98462 | E32: =IFERROR(E10/E34*100,0) -> 91.172206 | F32: =IFERROR(F10/F34*100,0) -> 108.20746 | G32: =IFERROR(G10/G34*100,0) -> 107.0042 | H32: =IFERROR(H10/H34*100,0) -> 105.48746 | I32: =IFERROR(I10/I34*100,0) -> 104.07468 | ... K32: =IFERROR(K10/K34*100,0) -> 101.63988
A33: 資産維持費込料金回収率 | B33: =IFERROR(B10/B35*100,0) -> 82.57802 | C33: =IFERROR(C10/C35*100,0) -> 82.487679 | D33: =IFERROR(D10/D35*100,0) -> 81.732255 | E33: =IFERROR(E10/E35*100,0) -> 80.999738 | F33: =IFERROR(F10/F35*100,0) -> 96.159205 | G33: =IFERROR(G10/G35*100,0) -> 95.101897 | H33: =IFERROR(H10/H35*100,0) -> 93.797859 | I33: =IFERROR(I10/I35*100,0) -> 92.576783 | ... K33: =IFERROR(K10/K35*100,0) -> 90.446594
A34: 給水原価対象費用 | B34: =SUM(B20,B23)-B14 -> 1326377 | C34: =SUM(C20,C23)-C14 -> 1313084 | D34: =SUM(D20,D23)-D14 -> 1311828 | E34: =SUM(E20,E23)-E14 -> 1310282 | F34: =SUM(F20,F23)-F14 -> 1313331 | G34: =SUM(G20,G23)-G14 -> 1314818 | H34: =SUM(H20,H23)-H14 -> 1320385 | I34: =SUM(I20,I23)-I14 -> 1324925 | ... K34: =SUM(K20,K23)-K14 -> 1329665
A35: 給水原価対象費用＋資産維持費 | B35: =B34+$B$5 -> 1490930.6 | C35: =C34+$B$5 -> 1477637.6 | D35: =D34+$B$5 -> 1476381.6 | E35: =E34+$B$5 -> 1474835.6 | F35: =F34+$B$5 -> 1477884.6 | G35: =G34+$B$5 -> 1479371.6 | H35: =H34+$B$5 -> 1484938.6 | I35: =I34+$B$5 -> 1489478.6 | ... K35: =K34+$B$5 -> 1494218.6
A36: 総括原価回収率（参考） | B36: =IFERROR(B10/(B20+B23-B14-B12-B15+$B$5)*100,0) -> 88.749524 | C36: =IFERROR(C10/(C20+C23-C14-C12-C15+$B$5)*100,0) -> 88.579718 | D36: =IFERROR(D10/(D20+D23-D14-D12-D15+$B$5)*100,0) -> 87.642943 | E36: =IFERROR(E10/(E20+E23-E14-E12-E15+$B$5)*100,0) -> 86.733616 | F36: =IFERROR(F10/(F20+F23-F14-F12-F15+$B$5)*100,0) -> 102.79464 | G36: =IFERROR(G10/(G20+G23-G14-G12-G15+$B$5)*100,0) -> 101.49847 | H36: =IFERROR(H10/(H20+H23-H14-H12-H15+$B$5)*100,0) -> 99.932128 | I36: =IFERROR(I10/(I20+I23-I14-I12-I15+$B$5)*100,0) -> 98.477448 | ... K36: =IFERROR(K10/(K20+K23-K14-K12-K15+$B$5)*100,0) -> 95.973172
A37: 検証：資産維持費込<=通常 | B37: =IF(B33<=B32,"OK","要確認") -> OK | C37: =IF(C33<=C32,"OK","要確認") -> OK | D37: =IF(D33<=D32,"OK","要確認") -> OK | E37: =IF(E33<=E32,"OK","要確認") -> OK | F37: =IF(F33<=F32,"OK","要確認") -> OK | G37: =IF(G33<=G32,"OK","要確認") -> OK | H37: =IF(H33<=H32,"OK","要確認") -> OK | I37: =IF(I33<=I32,"OK","要確認") -> OK | ... K37: =IF(K33<=K32,"OK","要確認") -> OK
A39: 【資本的収入】
A40: 資本的収入 | B40: =01_ビジョン原計画!B34 -> 698941 | C40: =01_ビジョン原計画!C34 -> 664331 | D40: =01_ビジョン原計画!D34 -> 636408 | E40: =01_ビジョン原計画!E34 -> 715698 | F40: =01_ビジョン原計画!F34 -> 627649 | G40: =01_ビジョン原計画!G34 -> 570213 | H40: =01_ビジョン原計画!H34 -> 571338 | I40: =01_ビジョン原計画!I34 -> 536592 | ... K40: =01_ビジョン原計画!K34 -> 365000
A41: 企業債 | B41: =01_ビジョン原計画!B35 -> 329000 | C41: =01_ビジョン原計画!C35 -> 435000 | D41: =01_ビジョン原計画!D35 -> 399000 | E41: =01_ビジョン原計画!E35 -> 400000 | F41: =01_ビジョン原計画!F35 -> 232000 | G41: =01_ビジョン原計画!G35 -> 283000 | H41: =01_ビジョン原計画!H35 -> 286000 | I41: =01_ビジョン原計画!I35 -> 368000 | ... K41: =01_ビジョン原計画!K35 -> 230000
A42: 一般会計負担金 | B42: =01_ビジョン原計画!B36 -> 169041 | C42: =01_ビジョン原計画!C36 -> 164831 | D42: =01_ビジョン原計画!D36 -> 162408 | E42: =01_ビジョン原計画!E36 -> 167998 | F42: =01_ビジョン原計画!F36 -> 173649 | G42: =01_ビジョン原計画!G36 -> 182213 | H42: =01_ビジョン原計画!H36 -> 180338 | I42: =01_ビジョン原計画!I36 -> 168592 | ... K42: =01_ビジョン原計画!K36 -> 135000
A43: 一般会計出資金 | B43: =01_ビジョン原計画!B37 -> 0 | C43: =01_ビジョン原計画!C37 -> 0 | D43: =01_ビジョン原計画!D37 -> 0 | E43: =01_ビジョン原計画!E37 -> 0 | F43: =01_ビジョン原計画!F37 -> 0 | G43: =01_ビジョン原計画!G37 -> 0 | H43: =01_ビジョン原計画!H37 -> 0 | I43: =01_ビジョン原計画!I37 -> 0 | ... K43: =01_ビジョン原計画!K37 -> 0
A44: 国庫補助金 | B44: =01_ビジョン原計画!B38 -> 0 | C44: =01_ビジョン原計画!C38 -> 64500 | D44: =01_ビジョン原計画!D38 -> 75000 | E44: =01_ビジョン原計画!E38 -> 147700 | F44: =01_ビジョン原計画!F38 -> 222000 | G44: =01_ビジョン原計画!G38 -> 105000 | H44: =01_ビジョン原計画!H38 -> 105000 | I44: =01_ビジョン原計画!I38 -> 0 | ... K44: =01_ビジョン原計画!K38 -> 0
...

Sheet SIM_ビジョン_2%
A1: SIM_ビジョン_2%
A2: 単位：千円、比率は％。料金改定率はR11〜R15の総括原価回収を基礎に算定し、R11以降の給水収益へ反映。
A3: 区分 | B3: 令和7年度 | C3: 令和8年度 | D3: 令和9年度 | E3: 令和10年度 | F3: 令和11年度 | G3: 令和12年度 | H3: 令和13年度 | I3: 令和14年度 | J3: 令和15年度 | K3: 令和16年度
A4: 資産維持費率 | B4: 0.02
A5: 年額資産維持費（千円） | B5: =00_前提・検証!$B$2*$B$4 -> 329107.28
A6: 料金改定率（R11以降・試算） | B6: =MAX(0,(SUMPRODUCT((01_ビジョン原計画!F18:J18+01_ビジョン原計画!F28:J28-01_ビジョン原計画!F12:J12-01_ビジョン原計画!F8:J8-01_ビジョン原計画!F11:J11+$B$5)-01_ビジョン原計画!F7:J7)/SUM(01_ビジョン原計画!F7:J7))) -> 0.34357465
A8: 【収益的収入】
A9: 営業収益 | B9: =SUM(B10:B12) -> 1261575 | C9: =SUM(C10:C12) -> 1249336 | D9: =SUM(D10:D12) -> 1237293 | E9: =SUM(E10:E12) -> 1225373 | F9: =SUM(F10:F12) -> 2026242.1 | G9: =SUM(G10:G12) -> 2006437.2 | H9: =SUM(H10:H12) -> 1986831.4 | I9: =SUM(I10:I12) -> 1967423.9 | ... K9: =SUM(K10:K12) -> 1929197.5
A10: 給水収益（改定反映後） | B10: =01_ビジョン原計画!B7*IF(7>=11,1+$B$6,1) -> 1231181 | C10: =01_ビジョン原計画!C7*IF(8>=11,1+$B$6,1) -> 1218869 | D10: =01_ビジョン原計画!D7*IF(9>=11,1+$B$6,1) -> 1206680 | E10: =01_ビジョン原計画!E7*IF(10>=11,1+$B$6,1) -> 1194613 | F10: =01_ビジョン原計画!F7*IF(11>=11,1+$B$6,1) -> 1589000.1 | G10: =01_ビジョン原計画!G7*IF(12>=11,1+$B$6,1) -> 1573109.6 | H10: =01_ビジョン原計画!H7*IF(13>=11,1+$B$6,1) -> 1557377.7 | I10: =01_ビジョン原計画!I7*IF(14>=11,1+$B$6,1) -> 1541803 | J10: =01_ビジョン原計画!J7*IF(15>=11,1+$B$6,1) -> 1526384.1 | K10: =01_ビジョン原計画!K7*IF(16>=11,1+$B$6,1) -> 1511119.8
A11: うち料金改定増収 | B11: =B10-01_ビジョン原計画!B7 -> 0 | C11: =C10-01_ビジョン原計画!C7 -> 0 | D11: =D10-01_ビジョン原計画!D7 -> 0 | E11: =E10-01_ビジョン原計画!E7 -> 0 | F11: =F10-01_ビジョン原計画!F7 -> 406334.05 | G11: =G10-01_ビジョン原計画!G7 -> 402270.6 | H11: =H10-01_ビジョン原計画!H7 -> 398247.68 | I11: =I10-01_ビジョン原計画!I7 -> 394264.96 | ... K11: =K10-01_ビジョン原計画!K7 -> 386418.75
A12: その他営業収益 | B12: =01_ビジョン原計画!B8 -> 30394 | C12: =01_ビジョン原計画!C8 -> 30467 | D12: =01_ビジョン原計画!D8 -> 30613 | E12: =01_ビジョン原計画!E8 -> 30760 | F12: =01_ビジョン原計画!F8 -> 30908 | G12: =01_ビジョン原計画!G8 -> 31057 | H12: =01_ビジョン原計画!H8 -> 31206 | I12: =01_ビジョン原計画!I8 -> 31356 | ... K12: =01_ビジョン原計画!K8 -> 31659
A13: 営業外収益 | B13: =01_ビジョン原計画!B9 -> 354909 | C13: =01_ビジョン原計画!C9 -> 355137 | D13: =01_ビジョン原計画!D9 -> 348767 | E13: =01_ビジョン原計画!E9 -> 343130 | F13: =01_ビジョン原計画!F9 -> 336658 | G13: =01_ビジョン原計画!G9 -> 342879 | H13: =01_ビジョン原計画!H9 -> 342324 | I13: =01_ビジョン原計画!I9 -> 332258 | ... K13: =01_ビジョン原計画!K9 -> 307297
A14: 長期前受金戻入 | B14: =01_ビジョン原計画!B12 -> 281625 | C14: =01_ビジョン原計画!C12 -> 283979 | D14: =01_ビジョン原計画!D12 -> 279812 | E14: =01_ビジョン原計画!E12 -> 276390 | F14: =01_ビジョン原計画!F12 -> 272168 | G14: =01_ビジョン原計画!G12 -> 272926 | H14: =01_ビジョン原計画!H12 -> 274600 | I14: =01_ビジョン原計画!I12 -> 266588 | ... K14: =01_ビジョン原計画!K12 -> 245134
A15: 繰入金・負担金等 | B15: =01_ビジョン原計画!B11 -> 73283 | C15: =01_ビジョン原計画!C11 -> 71157 | D15: =01_ビジョン原計画!D11 -> 68955 | E15: =01_ビジョン原計画!E11 -> 66740 | F15: =01_ビジョン原計画!F11 -> 64490 | G15: =01_ビジョン原計画!G11 -> 62175 | H15: =01_ビジョン原計画!H11 -> 59946 | I15: =01_ビジョン原計画!I11 -> 57892 | ... K15: =01_ビジョン原計画!K11 -> 54385
A16: 特別利益 | B16: =01_ビジョン原計画!B14 -> 2576 | C16: =01_ビジョン原計画!C14 -> 0 | D16: =01_ビジョン原計画!D14 -> 0 | E16: =01_ビジョン原計画!E14 -> 0 | F16: =01_ビジョン原計画!F14 -> 0 | G16: =01_ビジョン原計画!G14 -> 0 | H16: =01_ビジョン原計画!H14 -> 0 | I16: =01_ビジョン原計画!I14 -> 0 | ... K16: =01_ビジョン原計画!K14 -> 0
A17: 収益的収入合計 | B17: =SUM(B9,B13,B16) -> 1619060 | C17: =SUM(C9,C13,C16) -> 1604473 | D17: =SUM(D9,D13,D16) -> 1586060 | E17: =SUM(E9,E13,E16) -> 1568503 | F17: =SUM(F9,F13,F16) -> 2362900.1 | G17: =SUM(G9,G13,G16) -> 2349316.2 | H17: =SUM(H9,H13,H16) -> 2329155.4 | I17: =SUM(I9,I13,I16) -> 2299681.9 | ... K17: =SUM(K9,K13,K16) -> 2236494.5
A19: 【収益的支出】
A20: 営業費用 | B20: =01_ビジョン原計画!B18 -> 1479507 | C20: =01_ビジョン原計画!C18 -> 1476545 | D20: =01_ビジョン原計画!D18 -> 1474501 | E20: =01_ビジョン原計画!E18 -> 1471288 | F20: =01_ビジョン原計画!F18 -> 1471712 | G20: =01_ビジョン原計画!G18 -> 1476923 | H20: =01_ビジョン原計画!H18 -> 1486420 | I20: =01_ビジョン原計画!I18 -> 1484101 | ... K20: =01_ビジョン原計画!K18 -> 1469682
A21: 減価償却費 | B21: =01_ビジョン原計画!B25 -> 755782 | C21: =01_ビジョン原計画!C25 -> 754743 | D21: =01_ビジョン原計画!D25 -> 752391 | E21: =01_ビジョン原計画!E25 -> 748869 | F21: =01_ビジョン原計画!F25 -> 748983 | G21: =01_ビジョン原計画!G25 -> 753884 | H21: =01_ビジョン原計画!H25 -> 763070 | I21: =01_ビジョン原計画!I25 -> 760439 | ... K21: =01_ビジョン原計画!K25 -> 745393
A22: 資産減耗・除却費 | B22: =01_ビジョン原計画!B26 -> 0 | C22: =01_ビジョン原計画!C26 -> 0 | D22: =01_ビジョン原計画!D26 -> 0 | E22: =01_ビジョン原計画!E26 -> 0 | F22: =01_ビジョン原計画!F26 -> 0 | G22: =01_ビジョン原計画!G26 -> 0 | H22: =01_ビジョン原計画!H26 -> 0 | I22: =01_ビジョン原計画!I26 -> 0 | ... K22: =01_ビジョン原計画!K26 -> 0
A23: 営業外費用 | B23: =01_ビジョン原計画!B28 -> 128495 | C23: =01_ビジョン原計画!C28 -> 120518 | D23: =01_ビジョン原計画!D28 -> 117139 | E23: =01_ビジョン原計画!E28 -> 115384 | F23: =01_ビジョン原計画!F28 -> 113787 | G23: =01_ビジョン原計画!G28 -> 110821 | H23: =01_ビジョン原計画!H28 -> 108565 | I23: =01_ビジョン原計画!I28 -> 107412 | ... K23: =01_ビジョン原計画!K28 -> 105117
A24: 支払利息 | B24: =01_ビジョン原計画!B29 -> 118910 | C24: =01_ビジョン原計画!C29 -> 111872 | D24: =01_ビジョン原計画!D29 -> 108458 | E24: =01_ビジョン原計画!E29 -> 106668 | F24: =01_ビジョン原計画!F29 -> 105071 | G24: =01_ビジョン原計画!G29 -> 102070 | H24: =01_ビジョン原計画!H29 -> 99779 | I24: =01_ビジョン原計画!I29 -> 98626 | ... K24: =01_ビジョン原計画!K29 -> 96331
A25: 特別損失 | B25: =01_ビジョン原計画!B31 -> 273 | C25: =01_ビジョン原計画!C31 -> 273 | D25: =01_ビジョン原計画!D31 -> 273 | E25: =01_ビジョン原計画!E31 -> 273 | F25: =01_ビジョン原計画!F31 -> 273 | G25: =01_ビジョン原計画!G31 -> 273 | H25: =01_ビジョン原計画!H31 -> 273 | I25: =01_ビジョン原計画!I31 -> 273 | ... K25: =01_ビジョン原計画!K31 -> 273
A26: 収益的支出合計 | B26: =SUM(B20,B23,B25) -> 1608275 | C26: =SUM(C20,C23,C25) -> 1597336 | D26: =SUM(D20,D23,D25) -> 1591913 | E26: =SUM(E20,E23,E25) -> 1586945 | F26: =SUM(F20,F23,F25) -> 1585772 | G26: =SUM(G20,G23,G25) -> 1588017 | H26: =SUM(H20,H23,H25) -> 1595258 | I26: =SUM(I20,I23,I25) -> 1591786 | ... K26: =SUM(K20,K23,K25) -> 1575072
A27: 経常損益 | B27: =SUM(B9,B13)-SUM(B20,B23) -> 8482 | C27: =SUM(C9,C13)-SUM(C20,C23) -> 7410 | D27: =SUM(D9,D13)-SUM(D20,D23) -> -5580 | E27: =SUM(E9,E13)-SUM(E20,E23) -> -18169 | F27: =SUM(F9,F13)-SUM(F20,F23) -> 777401.11 | G27: =SUM(G9,G13)-SUM(G20,G23) -> 761572.19 | H27: =SUM(H9,H13)-SUM(H20,H23) -> 734170.36 | I27: =SUM(I9,I13)-SUM(I20,I23) -> 708168.93 | ... K27: =SUM(K9,K13)-SUM(K20,K23) -> 661695.5
A28: 純損益 | B28: =B27+B16-B25 -> 10785 | C28: =C27+C16-C25 -> 7137 | D28: =D27+D16-D25 -> -5853 | E28: =E27+E16-E25 -> -18442 | F28: =F27+F16-F25 -> 777128.11 | G28: =G27+G16-G25 -> 761299.19 | H28: =H27+H16-H25 -> 733897.36 | I28: =I27+I16-I25 -> 707895.93 | ... K28: =K27+K16-K25 -> 661422.5
A30: 【経営指標】
A31: 経常収支比率 | B31: =IFERROR((SUM(B9,B13)/SUM(B20,B23))*100,0) -> 100.52749 | C31: =IFERROR((SUM(C9,C13)/SUM(C20,C23))*100,0) -> 100.46398 | D31: =IFERROR((SUM(D9,D13)/SUM(D20,D23))*100,0) -> 99.649418 | E31: =IFERROR((SUM(E9,E13)/SUM(E20,E23))*100,0) -> 98.854899 | F31: =IFERROR((SUM(F9,F13)/SUM(F20,F23))*100,0) -> 149.03195 | G31: =IFERROR((SUM(G9,G13)/SUM(G20,G23))*100,0) -> 147.96568 | H31: =IFERROR((SUM(H9,H13)/SUM(H20,H23))*100,0) -> 146.02992 | I31: =IFERROR((SUM(I9,I13)/SUM(I20,I23))*100,0) -> 144.49658 | ... K31: =IFERROR((SUM(K9,K13)/SUM(K20,K23))*100,0) -> 142.01777
A32: 料金回収率（通常） | B32: =IFERROR(B10/B34*100,0) -> 92.822855 | C32: =IFERROR(C10/C34*100,0) -> 92.824907 | D32: =IFERROR(D10/D34*100,0) -> 91.98462 | E32: =IFERROR(E10/E34*100,0) -> 91.172206 | F32: =IFERROR(F10/F34*100,0) -> 120.99007 | G32: =IFERROR(G10/G34*100,0) -> 119.64467 | H32: =IFERROR(H10/H34*100,0) -> 117.94876 | I32: =IFERROR(I10/I34*100,0) -> 116.36907 | ... K32: =IFERROR(K10/K34*100,0) -> 113.64665
A33: 資産維持費込料金回収率 | B33: =IFERROR(B10/B35*100,0) -> 74.369839 | C33: =IFERROR(C10/C35*100,0) -> 74.222109 | D33: =IFERROR(D10/D35*100,0) -> 73.536112 | E33: =IFERROR(E10/E35*100,0) -> 72.869392 | F33: =IFERROR(F10/F35*100,0) -> 96.746409 | G33: =IFERROR(G10/G35*100,0) -> 95.692281 | H33: =IFERROR(H10/H35*100,0) -> 94.415579 | I33: =IFERROR(I10/I35*100,0) -> 93.214805 | ... K33: =IFERROR(K10/K35*100,0) -> 91.098686
A34: 給水原価対象費用 | B34: =SUM(B20,B23)-B14 -> 1326377 | C34: =SUM(C20,C23)-C14 -> 1313084 | D34: =SUM(D20,D23)-D14 -> 1311828 | E34: =SUM(E20,E23)-E14 -> 1310282 | F34: =SUM(F20,F23)-F14 -> 1313331 | G34: =SUM(G20,G23)-G14 -> 1314818 | H34: =SUM(H20,H23)-H14 -> 1320385 | I34: =SUM(I20,I23)-I14 -> 1324925 | ... K34: =SUM(K20,K23)-K14 -> 1329665
A35: 給水原価対象費用＋資産維持費 | B35: =B34+$B$5 -> 1655484.3 | C35: =C34+$B$5 -> 1642191.3 | D35: =D34+$B$5 -> 1640935.3 | E35: =E34+$B$5 -> 1639389.3 | F35: =F34+$B$5 -> 1642438.3 | G35: =G34+$B$5 -> 1643925.3 | H35: =H34+$B$5 -> 1649492.3 | I35: =I34+$B$5 -> 1654032.3 | ... K35: =K34+$B$5 -> 1658772.3
A36: 総括原価回収率（参考） | B36: =IFERROR(B10/(B20+B23-B14-B12-B15+$B$5)*100,0) -> 79.338525 | C36: =IFERROR(C10/(C20+C23-C14-C12-C15+$B$5)*100,0) -> 79.118193 | D36: =IFERROR(D10/(D20+D23-D14-D12-D15+$B$5)*100,0) -> 78.286338 | E36: =IFERROR(E10/(E20+E23-E14-E12-E15+$B$5)*100,0) -> 77.477223 | F36: =IFERROR(F10/(F20+F23-F14-F12-F15+$B$5)*100,0) -> 102.71226 | G36: =IFERROR(G10/(G20+G23-G14-G12-G15+$B$5)*100,0) -> 101.44557 | H36: =IFERROR(H10/(H20+H23-H14-H12-H15+$B$5)*100,0) -> 99.938229 | I36: =IFERROR(I10/(I20+I23-I14-I12-I15+$B$5)*100,0) -> 98.531343 | ... K36: =IFERROR(K10/(K20+K23-K14-K12-K15+$B$5)*100,0) -> 96.082697
A37: 検証：資産維持費込<=通常 | B37: =IF(B33<=B32,"OK","要確認") -> OK | C37: =IF(C33<=C32,"OK","要確認") -> OK | D37: =IF(D33<=D32,"OK","要確認") -> OK | E37: =IF(E33<=E32,"OK","要確認") -> OK | F37: =IF(F33<=F32,"OK","要確認") -> OK | G37: =IF(G33<=G32,"OK","要確認") -> OK | H37: =IF(H33<=H32,"OK","要確認") -> OK | I37: =IF(I33<=I32,"OK","要確認") -> OK | ... K37: =IF(K33<=K32,"OK","要確認") -> OK
A39: 【資本的収入】
A40: 資本的収入 | B40: =01_ビジョン原計画!B34 -> 698941 | C40: =01_ビジョン原計画!C34 -> 664331 | D40: =01_ビジョン原計画!D34 -> 636408 | E40: =01_ビジョン原計画!E34 -> 715698 | F40: =01_ビジョン原計画!F34 -> 627649 | G40: =01_ビジョン原計画!G34 -> 570213 | H40: =01_ビジョン原計画!H34 -> 571338 | I40: =01_ビジョン原計画!I34 -> 536592 | ... K40: =01_ビジョン原計画!K34 -> 365000
A41: 企業債 | B41: =01_ビジョン原計画!B35 -> 329000 | C41: =01_ビジョン原計画!C35 -> 435000 | D41: =01_ビジョン原計画!D35 -> 399000 | E41: =01_ビジョン原計画!E35 -> 400000 | F41: =01_ビジョン原計画!F35 -> 232000 | G41: =01_ビジョン原計画!G35 -> 283000 | H41: =01_ビジョン原計画!H35 -> 286000 | I41: =01_ビジョン原計画!I35 -> 368000 | ... K41: =01_ビジョン原計画!K35 -> 230000
A42: 一般会計負担金 | B42: =01_ビジョン原計画!B36 -> 169041 | C42: =01_ビジョン原計画!C36 -> 164831 | D42: =01_ビジョン原計画!D36 -> 162408 | E42: =01_ビジョン原計画!E36 -> 167998 | F42: =01_ビジョン原計画!F36 -> 173649 | G42: =01_ビジョン原計画!G36 -> 182213 | H42: =01_ビジョン原計画!H36 -> 180338 | I42: =01_ビジョン原計画!I36 -> 168592 | ... K42: =01_ビジョン原計画!K36 -> 135000
A43: 一般会計出資金 | B43: =01_ビジョン原計画!B37 -> 0 | C43: =01_ビジョン原計画!C37 -> 0 | D43: =01_ビジョン原計画!D37 -> 0 | E43: =01_ビジョン原計画!E37 -> 0 | F43: =01_ビジョン原計画!F37 -> 0 | G43: =01_ビジョン原計画!G37 -> 0 | H43: =01_ビジョン原計画!H37 -> 0 | I43: =01_ビジョン原計画!I37 -> 0 | ... K43: =01_ビジョン原計画!K37 -> 0
A44: 国庫補助金 | B44: =01_ビジョン原計画!B38 -> 0 | C44: =01_ビジョン原計画!C38 -> 64500 | D44: =01_ビジョン原計画!D38 -> 75000 | E44: =01_ビジョン原計画!E38 -> 147700 | F44: =01_ビジョン原計画!F38 -> 222000 | G44: =01_ビジョン原計画!G38 -> 105000 | H44: =01_ビジョン原計画!H38 -> 105000 | I44: =01_ビジョン原計画!I38 -> 0 | ... K44: =01_ビジョン原計画!K38 -> 0
...

Sheet SIM_ビジョン_3%
A1: SIM_ビジョン_3%
A2: 単位：千円、比率は％。料金改定率はR11〜R15の総括原価回収を基礎に算定し、R11以降の給水収益へ反映。
A3: 区分 | B3: 令和7年度 | C3: 令和8年度 | D3: 令和9年度 | E3: 令和10年度 | F3: 令和11年度 | G3: 令和12年度 | H3: 令和13年度 | I3: 令和14年度 | J3: 令和15年度 | K3: 令和16年度
A4: 資産維持費率 | B4: 0.03
A5: 年額資産維持費（千円） | B5: =00_前提・検証!$B$2*$B$4 -> 493660.92
A6: 料金改定率（R11以降・試算） | B6: =MAX(0,(SUMPRODUCT((01_ビジョン原計画!F18:J18+01_ビジョン原計画!F28:J28-01_ビジョン原計画!F12:J12-01_ビジョン原計画!F8:J8-01_ビジョン原計画!F11:J11+$B$5)-01_ビジョン原計画!F7:J7)/SUM(01_ビジョン原計画!F7:J7))) -> 0.48552338
A8: 【収益的収入】
A9: 営業収益 | B9: =SUM(B10:B12) -> 1261575 | C9: =SUM(C10:C12) -> 1249336 | D9: =SUM(D10:D12) -> 1237293 | E9: =SUM(E10:E12) -> 1225373 | F9: =SUM(F10:F12) -> 2361998 | G9: =SUM(G10:G12) -> 2338835.4 | H9: =SUM(H10:H12) -> 2315905.4 | I9: =SUM(I10:I12) -> 2293207.1 | ... K9: =SUM(K10:K12) -> 2248497.3
A10: 給水収益（改定反映後） | B10: =01_ビジョン原計画!B7*IF(7>=11,1+$B$6,1) -> 1231181 | C10: =01_ビジョン原計画!C7*IF(8>=11,1+$B$6,1) -> 1218869 | D10: =01_ビジョン原計画!D7*IF(9>=11,1+$B$6,1) -> 1206680 | E10: =01_ビジョン原計画!E7*IF(10>=11,1+$B$6,1) -> 1194613 | F10: =01_ビジョン原計画!F7*IF(11>=11,1+$B$6,1) -> 1756878 | G10: =01_ビジョン原計画!G7*IF(12>=11,1+$B$6,1) -> 1739308.7 | H10: =01_ビジョン原計画!H7*IF(13>=11,1+$B$6,1) -> 1721914.7 | I10: =01_ビジョン原計画!I7*IF(14>=11,1+$B$6,1) -> 1704694.5 | J10: =01_ビジョン原計画!J7*IF(15>=11,1+$B$6,1) -> 1687646.7 | K10: =01_ビジョン原計画!K7*IF(16>=11,1+$B$6,1) -> 1670769.6
A11: うち料金改定増収 | B11: =B10-01_ビジョン原計画!B7 -> 0 | C11: =C10-01_ビジョン原計画!C7 -> 0 | D11: =D10-01_ビジョン原計画!D7 -> 0 | E11: =E10-01_ビジョン原計画!E7 -> 0 | F11: =F10-01_ビジョン原計画!F7 -> 574211.99 | G11: =G10-01_ビジョン原計画!G7 -> 568469.71 | H11: =H10-01_ビジョン原計画!H7 -> 562784.71 | I11: =I10-01_ビジョン原計画!I7 -> 557156.53 | ... K11: =K10-01_ビジョン原計画!K7 -> 546068.63
A12: その他営業収益 | B12: =01_ビジョン原計画!B8 -> 30394 | C12: =01_ビジョン原計画!C8 -> 30467 | D12: =01_ビジョン原計画!D8 -> 30613 | E12: =01_ビジョン原計画!E8 -> 30760 | F12: =01_ビジョン原計画!F8 -> 30908 | G12: =01_ビジョン原計画!G8 -> 31057 | H12: =01_ビジョン原計画!H8 -> 31206 | I12: =01_ビジョン原計画!I8 -> 31356 | ... K12: =01_ビジョン原計画!K8 -> 31659
A13: 営業外収益 | B13: =01_ビジョン原計画!B9 -> 354909 | C13: =01_ビジョン原計画!C9 -> 355137 | D13: =01_ビジョン原計画!D9 -> 348767 | E13: =01_ビジョン原計画!E9 -> 343130 | F13: =01_ビジョン原計画!F9 -> 336658 | G13: =01_ビジョン原計画!G9 -> 342879 | H13: =01_ビジョン原計画!H9 -> 342324 | I13: =01_ビジョン原計画!I9 -> 332258 | ... K13: =01_ビジョン原計画!K9 -> 307297
A14: 長期前受金戻入 | B14: =01_ビジョン原計画!B12 -> 281625 | C14: =01_ビジョン原計画!C12 -> 283979 | D14: =01_ビジョン原計画!D12 -> 279812 | E14: =01_ビジョン原計画!E12 -> 276390 | F14: =01_ビジョン原計画!F12 -> 272168 | G14: =01_ビジョン原計画!G12 -> 272926 | H14: =01_ビジョン原計画!H12 -> 274600 | I14: =01_ビジョン原計画!I12 -> 266588 | ... K14: =01_ビジョン原計画!K12 -> 245134
A15: 繰入金・負担金等 | B15: =01_ビジョン原計画!B11 -> 73283 | C15: =01_ビジョン原計画!C11 -> 71157 | D15: =01_ビジョン原計画!D11 -> 68955 | E15: =01_ビジョン原計画!E11 -> 66740 | F15: =01_ビジョン原計画!F11 -> 64490 | G15: =01_ビジョン原計画!G11 -> 62175 | H15: =01_ビジョン原計画!H11 -> 59946 | I15: =01_ビジョン原計画!I11 -> 57892 | ... K15: =01_ビジョン原計画!K11 -> 54385
A16: 特別利益 | B16: =01_ビジョン原計画!B14 -> 2576 | C16: =01_ビジョン原計画!C14 -> 0 | D16: =01_ビジョン原計画!D14 -> 0 | E16: =01_ビジョン原計画!E14 -> 0 | F16: =01_ビジョン原計画!F14 -> 0 | G16: =01_ビジョン原計画!G14 -> 0 | H16: =01_ビジョン原計画!H14 -> 0 | I16: =01_ビジョン原計画!I14 -> 0 | ... K16: =01_ビジョン原計画!K14 -> 0
A17: 収益的収入合計 | B17: =SUM(B9,B13,B16) -> 1619060 | C17: =SUM(C9,C13,C16) -> 1604473 | D17: =SUM(D9,D13,D16) -> 1586060 | E17: =SUM(E9,E13,E16) -> 1568503 | F17: =SUM(F9,F13,F16) -> 2698656 | G17: =SUM(G9,G13,G16) -> 2681714.4 | H17: =SUM(H9,H13,H16) -> 2658229.4 | I17: =SUM(I9,I13,I16) -> 2625465.1 | ... K17: =SUM(K9,K13,K16) -> 2555794.3
A19: 【収益的支出】
A20: 営業費用 | B20: =01_ビジョン原計画!B18 -> 1479507 | C20: =01_ビジョン原計画!C18 -> 1476545 | D20: =01_ビジョン原計画!D18 -> 1474501 | E20: =01_ビジョン原計画!E18 -> 1471288 | F20: =01_ビジョン原計画!F18 -> 1471712 | G20: =01_ビジョン原計画!G18 -> 1476923 | H20: =01_ビジョン原計画!H18 -> 1486420 | I20: =01_ビジョン原計画!I18 -> 1484101 | ... K20: =01_ビジョン原計画!K18 -> 1469682
A21: 減価償却費 | B21: =01_ビジョン原計画!B25 -> 755782 | C21: =01_ビジョン原計画!C25 -> 754743 | D21: =01_ビジョン原計画!D25 -> 752391 | E21: =01_ビジョン原計画!E25 -> 748869 | F21: =01_ビジョン原計画!F25 -> 748983 | G21: =01_ビジョン原計画!G25 -> 753884 | H21: =01_ビジョン原計画!H25 -> 763070 | I21: =01_ビジョン原計画!I25 -> 760439 | ... K21: =01_ビジョン原計画!K25 -> 745393
A22: 資産減耗・除却費 | B22: =01_ビジョン原計画!B26 -> 0 | C22: =01_ビジョン原計画!C26 -> 0 | D22: =01_ビジョン原計画!D26 -> 0 | E22: =01_ビジョン原計画!E26 -> 0 | F22: =01_ビジョン原計画!F26 -> 0 | G22: =01_ビジョン原計画!G26 -> 0 | H22: =01_ビジョン原計画!H26 -> 0 | I22: =01_ビジョン原計画!I26 -> 0 | ... K22: =01_ビジョン原計画!K26 -> 0
A23: 営業外費用 | B23: =01_ビジョン原計画!B28 -> 128495 | C23: =01_ビジョン原計画!C28 -> 120518 | D23: =01_ビジョン原計画!D28 -> 117139 | E23: =01_ビジョン原計画!E28 -> 115384 | F23: =01_ビジョン原計画!F28 -> 113787 | G23: =01_ビジョン原計画!G28 -> 110821 | H23: =01_ビジョン原計画!H28 -> 108565 | I23: =01_ビジョン原計画!I28 -> 107412 | ... K23: =01_ビジョン原計画!K28 -> 105117
A24: 支払利息 | B24: =01_ビジョン原計画!B29 -> 118910 | C24: =01_ビジョン原計画!C29 -> 111872 | D24: =01_ビジョン原計画!D29 -> 108458 | E24: =01_ビジョン原計画!E29 -> 106668 | F24: =01_ビジョン原計画!F29 -> 105071 | G24: =01_ビジョン原計画!G29 -> 102070 | H24: =01_ビジョン原計画!H29 -> 99779 | I24: =01_ビジョン原計画!I29 -> 98626 | ... K24: =01_ビジョン原計画!K29 -> 96331
A25: 特別損失 | B25: =01_ビジョン原計画!B31 -> 273 | C25: =01_ビジョン原計画!C31 -> 273 | D25: =01_ビジョン原計画!D31 -> 273 | E25: =01_ビジョン原計画!E31 -> 273 | F25: =01_ビジョン原計画!F31 -> 273 | G25: =01_ビジョン原計画!G31 -> 273 | H25: =01_ビジョン原計画!H31 -> 273 | I25: =01_ビジョン原計画!I31 -> 273 | ... K25: =01_ビジョン原計画!K31 -> 273
A26: 収益的支出合計 | B26: =SUM(B20,B23,B25) -> 1608275 | C26: =SUM(C20,C23,C25) -> 1597336 | D26: =SUM(D20,D23,D25) -> 1591913 | E26: =SUM(E20,E23,E25) -> 1586945 | F26: =SUM(F20,F23,F25) -> 1585772 | G26: =SUM(G20,G23,G25) -> 1588017 | H26: =SUM(H20,H23,H25) -> 1595258 | I26: =SUM(I20,I23,I25) -> 1591786 | ... K26: =SUM(K20,K23,K25) -> 1575072
A27: 経常損益 | B27: =SUM(B9,B13)-SUM(B20,B23) -> 8482 | C27: =SUM(C9,C13)-SUM(C20,C23) -> 7410 | D27: =SUM(D9,D13)-SUM(D20,D23) -> -5580 | E27: =SUM(E9,E13)-SUM(E20,E23) -> -18169 | F27: =SUM(F9,F13)-SUM(F20,F23) -> 1113157 | G27: =SUM(G9,G13)-SUM(G20,G23) -> 1093970.4 | H27: =SUM(H9,H13)-SUM(H20,H23) -> 1063244.4 | I27: =SUM(I9,I13)-SUM(I20,I23) -> 1033952.1 | ... K27: =SUM(K9,K13)-SUM(K20,K23) -> 980995.26
A28: 純損益 | B28: =B27+B16-B25 -> 10785 | C28: =C27+C16-C25 -> 7137 | D28: =D27+D16-D25 -> -5853 | E28: =E27+E16-E25 -> -18442 | F28: =F27+F16-F25 -> 1112884 | G28: =G27+G16-G25 -> 1093697.4 | H28: =H27+H16-H25 -> 1062971.4 | I28: =I27+I16-I25 -> 1033679.1 | ... K28: =K27+K16-K25 -> 980722.26
A30: 【経営指標】
